Workbook
Name Settings.AllowCalibrationUpdates: SETTINGS!$C$10
Name Settings.BloombergPCS: SETTINGS!$C$6
Name Settings.COB: SETTINGS!$C$4
Name Settings.CurveSide.MidBidAsk: SETTINGS!$C$7
Name Settings.EnableCurveChart: SETTINGS!$C$9
Name Settings.Futures.Convexity.HW1F.Vol: SETTINGS!$C$8
Name Settings.isCOBToday: SETTINGS!$C$3
Name Settings.SwapCurve.Interpolation: SETTINGS!$C$11

Sheet SETTINGS
U1: … Curve Display
B2: Settings | E2: AUD Curve Chart | N2: Curve Display Settings | Q2: {=IF(AND($C$9,'AUD CURVE'!$D$99),_xll.meLWOCurveForwardRatesTable($N$8,$O$8:$O$10,$O$3,$O$4,,,,$O$5),NA())} -> Fixing Dates | R2: AUDOIS | S2: AUD3ML | T2: AUD6ML
B3: isCOBToday | C3: =IF(ISBLANK(C5),TRUE,FALSE) -> TRUE | N3: Start | O3: 0Y | Q3: 43278 | R3: 0.015 | S3: 0.021153 | T3: 0.0223
B4: CloseOfBusiness (COB) | C4: =IF(Settings.isCOBToday,TODAY(),$C$5) -> 43278 | N4: Maturity | O4: 20Y | Q4: 43370 | R4: 0.014954485 | S4: 0.020788961 | T4: 0.021441746
B5: OverrideDate | N5: Frequency | O5: QUARTERLY | Q5: 43461 | R5: 0.015027709 | S5: 0.020491992 | T5: 0.021345432
B6: PricingSource (PCS) | C6: BGN | Q6: 43551 | R6: 0.015289466 | S6: 0.020367846 | T6: 0.02170144
B7: CurveSide (Bid-Offer) | C7: PX_MID | N7: CurveCollection | O7: CurveIndices | Q7: 43643 | R7: 0.015863105 | S7: 0.020419166 | T7: 0.022348053
B8: Futures.Convexity.HW1F.Vol (%) | C8: 0.02 | N8: AUDYC | O8: AUDOIS | Q8: 43735 | R8: 0.016600308 | S8: 0.020640007 | T8: 0.022948639
B9: EnableCurveChart | C9: TRUE | O9: AUD3ML | Q9: 43826 | R9: 0.017254182 | S9: 0.020977274 | T9: 0.023407493
B10: AllowCalibrationUpdates | C10: FALSE | O10: AUD6ML | Q10: 43917 | R10: 0.017790877 | S10: 0.021543652 | T10: 0.023729701
B11: SwapCurve.Interpolation | C11: SPLINE | Q11: 44011 | R11: 0.018316948 | S11: 0.02226326 | T11: 0.024042487
Q12: 44102 | R12: 0.018799749 | S12: 0.022913696 | T12: 0.024447276
Q13: 44193 | R13: 0.019285888 | S13: 0.023530049 | T13: 0.024953811
B14: Curve Data Monitor | Q14: 44284 | R14: 0.019831035 | S14: 0.024010958 | T14: 0.025531549
B15: Curve | C15: MissingDataPts | Q15: 44375 | R15: 0.020327109 | S15: 0.024418316 | T15: 0.026133814
B16: AUDOIS | C16: ='AUD CURVE TICKERS'!C4 -> 0 | Q16: 44466 | R16: 0.02083202 | S16: 0.02486447 | T16: 0.026720478
B17: AUD3ML | C17: ='AUD CURVE TICKERS'!F4 -> 0 | Q17: 44557 | R17: 0.021350917 | S17: 0.025367018 | T17: 0.027286785
B18: AUD6ML | C18: ='AUD CURVE TICKERS'!I4 -> 0 | Q18: 44648 | R18: 0.021884216 | S18: 0.025949751 | T18: 0.027832051
Q19: 44739 | R19: 0.022432355 | S19: 0.026564769 | T19: 0.028335252
B20: Fixing.Data | C20: ='AUD CURVE TICKERS'!F5 -> 0 | Q20: 44831 | R20: 0.022940234 | S20: 0.027123631 | T20: 0.02878062
B21: Futures.Data | C21: ='AUD CURVE TICKERS'!F6 -> 0 | Q21: 44922 | R21: 0.023333547 | S21: 0.027593418 | T21: 0.029163872
B22: Futures.Dates | C22: ='AUD CURVE TICKERS'!F7 -> 0 | Q22: 45012 | R22: 0.023613422 | S22: 0.027985809 | T22: 0.029495957
Q23: 45104 | R23: 0.023784712 | S23: 0.028308267 | T23: 0.029785106
Q24: 45196 | R24: 0.023918999 | S24: 0.028607558 | T24: 0.030025859
Q25: 45287 | R25: 0.024097479 | S25: 0.028820954 | T25: 0.030249303
Q26: 45378 | R26: 0.024255351 | S26: 0.029101383 | T26: 0.030492581
Q27: 45470 | R27: 0.024529527 | S27: 0.029389068 | T27: 0.030772257
Q28: 45562 | R28: 0.024848783 | S28: 0.029679871 | T28: 0.031086879
Q29: 45653 | R29: 0.025190074 | S29: 0.030083128 | T29: 0.031407979
Q30: 45743 | R30: 0.025623039 | S30: 0.030440108 | T30: 0.031705474
Q31: 45835 | R31: 0.02603979 | S31: 0.030788082 | T31: 0.031955201
Q32: 45929 | R32: 0.026416834 | S32: 0.031049469 | T32: 0.032123427
Q33: 46020 | R33: 0.026678602 | S33: 0.031184148 | T33: 0.032194169
Q34: 46108 | R34: 0.026829487 | S34: 0.03120182 | T34: 0.032187726
... Q83: 50584 | R83: 0.025420904 | S83: 0.030003636 | T83: 0.031180663
Q84: #N/A | R84: #N/A | S84: #N/A | T84: #N/A
Q85: #N/A | R85: #N/A | S85: #N/A | T85: #N/A
Q86: #N/A | R86: #N/A | S86: #N/A | T86: #N/A
Q87: #N/A | R87: #N/A | S87: #N/A | T87: #N/A
Q88: #N/A | R88: #N/A | S88: #N/A | T88: #N/A
...

Sheet AUD CURVE TICKERS
B2: Check for Missing Instrument Data
B4: AUDOIS | C4: =SUM(C5:C8) -> 0 | E4: AUD3ML | F4: =SUM(F5:F9) -> 0 | H4: AUD6ML | I4: =SUM(I5:I7) -> 0
B5: OIS.Outrights | C5: =COUNTA(B14:B36)-COUNT(J14:J36) -> 0 | E5: Swap3M.LiborFixings | F5: =COUNTA(B44:B66)-COUNT(J44:J66) -> 0 | H5: Swap6M.Fixings | I5: =F5 -> 0
B6: OIS.LiborOIS | C6: =COUNTA(L14:L36)-COUNT(T14:T36) -> 0 | E6: Swap3M.Futures | F6: =COUNTA(L44:L66)-COUNT(T44:T66) -> 0 | H6: Swap6M.FRAs | I6: =COUNTA(B74:B76)-COUNT(J74:J76) -> 0
B7: OIS.TenorBasis | C7: =COUNTA(AI44:AI66)-COUNT(AQ44:AQ66) -> 0 | E7: Swap3M.Futures.Dates | F7: =COUNTA(L44:L49)-COUNTA(V44:V49)+COUNTA(L44:L49)-COUNTA(W44:W49) -> 0 | H7: Swap6M.IRS | I7: =COUNTA(L74:L88)-COUNTA(T74:T88) -> 0
B8: OIS.IRS | C8: =COUNTA(Y44:Y66)-COUNT(AG44:AG66) -> 0 | E8: Swap3M.IRS | F8: =COUNTA(Y44:Y66)-COUNT(AG44:AG66) -> 0
E9: Swap3M.TenorBasis | F9: =COUNTA(AI44:AI66)-COUNT(AQ44:AQ66) -> 0
B12: OIS | L12: LIBOROISBASISSPREADS
B13: Term | C13: InstrumentID | D13: Broker | E13: Used | F13: Database | G13: Ticker | H13: Side | I13: Used | J13: Result | L13: Term | M13: InstrumentID | N13: Broker | O13: Used | P13: Database | Q13: Ticker | R13: Side | S13: Used | T13: Result
B14: ON | C14: RBACOR | E14: =IF(ISBLANK(D14),Settings.BloombergPCS,D14) -> BGN | F14: Index | G14: =C14&" "&E14&" "&F14 -> RBACOR BGN Index | H14: PX_MID | I14: =IF(ISBLANK(H14),Settings.CurveSide.MidBidAsk,'AUD CURVE TICKERS'!H14) -> PX_MID | J14: =IF(Settings.isCOBToday,_xll.BDP(G14,'AUD CURVE TICKERS'!I14),_xll.BDH(G14,'AUD CURVE TICKERS'!I14,Settings.COB,Settings.COB)) -> 1.5 | L14: 1Y | M14: ADBBCO1 | O14: =IF(ISBLANK(N14),Settings.BloombergPCS,N14) -> BGN | P14: Curncy | Q14: =M14&" "&O14&" "&P14 -> ADBBCO1 BGN Curncy | S14: =IF(ISBLANK(R14),Settings.CurveSide.MidBidAsk,'AUD CURVE TICKERS'!R14) -> PX_MID | T14: =IF(Settings.isCOBToday,_xll.BDP(Q14,'AUD CURVE TICKERS'!S14),_xll.BDH(Q14,'AUD CURVE TICKERS'!S14,Settings.COB,Settings.COB)) -> 51
B15: 1W | C15: ADSO1Z | E15: =IF(ISBLANK(D15),Settings.BloombergPCS,D15) -> BGN | F15: Curncy | G15: =C15&" "&E15&" "&F15 -> ADSO1Z BGN Curncy | I15: =IF(ISBLANK(H15),Settings.CurveSide.MidBidAsk,'AUD CURVE TICKERS'!H15) -> PX_MID | J15: =IF(Settings.isCOBToday,_xll.BDP(G15,'AUD CURVE TICKERS'!I15),_xll.BDH(G15,'AUD CURVE TICKERS'!I15,Settings.COB,Settings.COB)) -> 1.5 | L15: 2Y | M15: ADBBCO2 | O15: =IF(ISBLANK(N15),Settings.BloombergPCS,N15) -> BGN | P15: Curncy | Q15: =M15&" "&O15&" "&P15 -> ADBBCO2 BGN Curncy | S15: =IF(ISBLANK(R15),Settings.CurveSide.MidBidAsk,'AUD CURVE TICKERS'!R15) -> PX_MID | T15: =IF(Settings.isCOBToday,_xll.BDP(Q15,'AUD CURVE TICKERS'!S15),_xll.BDH(Q15,'AUD CURVE TICKERS'!S15,Settings.COB,Settings.COB)) -> 47.25
B16: 1M | C16: ADSOA | E16: =IF(ISBLANK(D16),Settings.BloombergPCS,D16) -> BGN | F16: Curncy | G16: =C16&" "&E16&" "&F16 -> ADSOA BGN Curncy | I16: =IF(ISBLANK(H16),Settings.CurveSide.MidBidAsk,'AUD CURVE TICKERS'!H16) -> PX_MID | J16: =IF(Settings.isCOBToday,_xll.BDP(G16,'AUD CURVE TICKERS'!I16),_xll.BDH(G16,'AUD CURVE TICKERS'!I16,Settings.COB,Settings.COB)) -> 1.499 | L16: 3Y | M16: ADBBCO3 | O16: =IF(ISBLANK(N16),Settings.BloombergPCS,N16) -> BGN | P16: Curncy | Q16: =M16&" "&O16&" "&P16 -> ADBBCO3 BGN Curncy | S16: =IF(ISBLANK(R16),Settings.CurveSide.MidBidAsk,'AUD CURVE TICKERS'!R16) -> PX_MID | T16: =IF(Settings.isCOBToday,_xll.BDP(Q16,'AUD CURVE TICKERS'!S16),_xll.BDH(Q16,'AUD CURVE TICKERS'!S16,Settings.COB,Settings.COB)) -> 43.75
B17: 2M | C17: ADSOB | E17: =IF(ISBLANK(D17),Settings.BloombergPCS,D17) -> BGN | F17: Curncy | G17: =C17&" "&E17&" "&F17 -> ADSOB BGN Curncy | I17: =IF(ISBLANK(H17),Settings.CurveSide.MidBidAsk,'AUD CURVE TICKERS'!H17) -> PX_MID | J17: =IF(Settings.isCOBToday,_xll.BDP(G17,'AUD CURVE TICKERS'!I17),_xll.BDH(G17,'AUD CURVE TICKERS'!I17,Settings.COB,Settings.COB)) -> 1.5 | L17: 4Y | M17: ADBBCO4 | O17: =IF(ISBLANK(N17),Settings.BloombergPCS,N17) -> BGN | P17: Curncy | Q17: =M17&" "&O17&" "&P17 -> ADBBCO4 BGN Curncy | S17: =IF(ISBLANK(R17),Settings.CurveSide.MidBidAsk,'AUD CURVE TICKERS'!R17) -> PX_MID | T17: =IF(Settings.isCOBToday,_xll.BDP(Q17,'AUD CURVE TICKERS'!S17),_xll.BDH(Q17,'AUD CURVE TICKERS'!S17,Settings.COB,Settings.COB)) -> 42.375
B18: 3M | C18: ADSOC | E18: =IF(ISBLANK(D18),Settings.BloombergPCS,D18) -> BGN | F18: Curncy | G18: =C18&" "&E18&" "&F18 -> ADSOC BGN Curncy | I18: =IF(ISBLANK(H18),Settings.CurveSide.MidBidAsk,'AUD CURVE TICKERS'!H18) -> PX_MID | J18: =IF(Settings.isCOBToday,_xll.BDP(G18,'AUD CURVE TICKERS'!I18),_xll.BDH(G18,'AUD CURVE TICKERS'!I18,Settings.COB,Settings.COB)) -> 1.5 | L18: 5Y | M18: ADBBCO5 | O18: =IF(ISBLANK(N18),Settings.BloombergPCS,N18) -> BGN | P18: Curncy | Q18: =M18&" "&O18&" "&P18 -> ADBBCO5 BGN Curncy | S18: =IF(ISBLANK(R18),Settings.CurveSide.MidBidAsk,'AUD CURVE TICKERS'!R18) -> PX_MID | T18: =IF(Settings.isCOBToday,_xll.BDP(Q18,'AUD CURVE TICKERS'!S18),_xll.BDH(Q18,'AUD CURVE TICKERS'!S18,Settings.COB,Settings.COB)) -> 42
B19: 4M | C19: ADSOD | E19: =IF(ISBLANK(D19),Settings.BloombergPCS,D19) -> BGN | F19: Curncy | G19: =C19&" "&E19&" "&F19 -> ADSOD BGN Curncy | I19: =IF(ISBLANK(H19),Settings.CurveSide.MidBidAsk,'AUD CURVE TICKERS'!H19) -> PX_MID | J19: =IF(Settings.isCOBToday,_xll.BDP(G19,'AUD CURVE TICKERS'!I19),_xll.BDH(G19,'AUD CURVE TICKERS'!I19,Settings.COB,Settings.COB)) -> 1.501 | L19: 6Y | M19: ADBBCO6 | O19: =IF(ISBLANK(N19),Settings.BloombergPCS,N19) -> BGN | P19: Curncy | Q19: =M19&" "&O19&" "&P19 -> ADBBCO6 BGN Curncy | S19: =IF(ISBLANK(R19),Settings.CurveSide.MidBidAsk,'AUD CURVE TICKERS'!R19) -> PX_MID | T19: =IF(Settings.isCOBToday,_xll.BDP(Q19,'AUD CURVE TICKERS'!S19),_xll.BDH(Q19,'AUD CURVE TICKERS'!S19,Settings.COB,Settings.COB)) -> 42.625
B20: 5M | C20: ADSOE | E20: =IF(ISBLANK(D20),Settings.BloombergPCS,D20) -> BGN | F20: Curncy | G20: =C20&" "&E20&" "&F20 -> ADSOE BGN Curncy | I20: =IF(ISBLANK(H20),Settings.CurveSide.MidBidAsk,'AUD CURVE TICKERS'!H20) -> PX_MID | J20: =IF(Settings.isCOBToday,_xll.BDP(G20,'AUD CURVE TICKERS'!I20),_xll.BDH(G20,'AUD CURVE TICKERS'!I20,Settings.COB,Settings.COB)) -> 1.5025 | L20: 7Y | M20: ADBBCO7 | O20: =IF(ISBLANK(N20),Settings.BloombergPCS,N20) -> BGN | P20: Curncy | Q20: =M20&" "&O20&" "&P20 -> ADBBCO7 BGN Curncy | S20: =IF(ISBLANK(R20),Settings.CurveSide.MidBidAsk,'AUD CURVE TICKERS'!R20) -> PX_MID | T20: =IF(Settings.isCOBToday,_xll.BDP(Q20,'AUD CURVE TICKERS'!S20),_xll.BDH(Q20,'AUD CURVE TICKERS'!S20,Settings.COB,Settings.COB)) -> 43.125
B21: 6M | C21: ADSOF | E21: =IF(ISBLANK(D21),Settings.BloombergPCS,D21) -> BGN | F21: Curncy | G21: =C21&" "&E21&" "&F21 -> ADSOF BGN Curncy | I21: =IF(ISBLANK(H21),Settings.CurveSide.MidBidAsk,'AUD CURVE TICKERS'!H21) -> PX_MID | J21: =IF(Settings.isCOBToday,_xll.BDP(G21,'AUD CURVE TICKERS'!I21),_xll.BDH(G21,'AUD CURVE TICKERS'!I21,Settings.COB,Settings.COB)) -> 1.504 | L21: 8Y | M21: ADBBCO8 | O21: =IF(ISBLANK(N21),Settings.BloombergPCS,N21) -> BGN | P21: Curncy | Q21: =M21&" "&O21&" "&P21 -> ADBBCO8 BGN Curncy | S21: =IF(ISBLANK(R21),Settings.CurveSide.MidBidAsk,'AUD CURVE TICKERS'!R21) -> PX_MID | T21: =IF(Settings.isCOBToday,_xll.BDP(Q21,'AUD CURVE TICKERS'!S21),_xll.BDH(Q21,'AUD CURVE TICKERS'!S21,Settings.COB,Settings.COB)) -> 43.25
B22: 9M | C22: ADSOI | E22: =IF(ISBLANK(D22),Settings.BloombergPCS,D22) -> BGN | F22: Curncy | G22: =C22&" "&E22&" "&F22 -> ADSOI BGN Curncy | I22: =IF(ISBLANK(H22),Settings.CurveSide.MidBidAsk,'AUD CURVE TICKERS'!H22) -> PX_MID | J22: =IF(Settings.isCOBToday,_xll.BDP(G22,'AUD CURVE TICKERS'!I22),_xll.BDH(G22,'AUD CURVE TICKERS'!I22,Settings.COB,Settings.COB)) -> 1.512 | L22: 9Y | M22: ADBBCO9 | O22: =IF(ISBLANK(N22),Settings.BloombergPCS,N22) -> BGN | P22: Curncy | Q22: =M22&" "&O22&" "&P22 -> ADBBCO9 BGN Curncy | S22: =IF(ISBLANK(R22),Settings.CurveSide.MidBidAsk,'AUD CURVE TICKERS'!R22) -> PX_MID | T22: =IF(Settings.isCOBToday,_xll.BDP(Q22,'AUD CURVE TICKERS'!S22),_xll.BDH(Q22,'AUD CURVE TICKERS'!S22,Settings.COB,Settings.COB)) -> 43.125
B23: 1Y | C23: ADSO1 | E23: =IF(ISBLANK(D23),Settings.BloombergPCS,D23) -> BGN | F23: Curncy | G23: =C23&" "&E23&" "&F23 -> ADSO1 BGN Curncy | I23: =IF(ISBLANK(H23),Settings.CurveSide.MidBidAsk,'AUD CURVE TICKERS'!H23) -> PX_MID | J23: =IF(Settings.isCOBToday,_xll.BDP(G23,'AUD CURVE TICKERS'!I23),_xll.BDH(G23,'AUD CURVE TICKERS'!I23,Settings.COB,Settings.COB)) -> 1.528 | L23: 10Y | M23: ADBBCO10 | O23: =IF(ISBLANK(N23),Settings.BloombergPCS,N23) -> BGN | P23: Curncy | Q23: =M23&" "&O23&" "&P23 -> ADBBCO10 BGN Curncy | S23: =IF(ISBLANK(R23),Settings.CurveSide.MidBidAsk,'AUD CURVE TICKERS'!R23) -> PX_MID | T23: =IF(Settings.isCOBToday,_xll.BDP(Q23,'AUD CURVE TICKERS'!S23),_xll.BDH(Q23,'AUD CURVE TICKERS'!S23,Settings.COB,Settings.COB)) -> 43.125
B24: 2Y | C24: ADSO2 | E24: =IF(ISBLANK(D24),Settings.BloombergPCS,D24) -> BGN | F24: Curncy | G24: =C24&" "&E24&" "&F24 -> ADSO2 BGN Curncy | I24: =IF(ISBLANK(H24),Settings.CurveSide.MidBidAsk,'AUD CURVE TICKERS'!H24) -> PX_MID | J24: =IF(Settings.isCOBToday,_xll.BDP(G24,'AUD CURVE TICKERS'!I24),_xll.BDH(G24,'AUD CURVE TICKERS'!I24,Settings.COB,Settings.COB)) -> 1.63 | L24: 15Y | M24: ADBBCO15 | O24: =IF(ISBLANK(N24),Settings.BloombergPCS,N24) -> BGN | P24: Curncy | Q24: =M24&" "&O24&" "&P24 -> ADBBCO15 BGN Curncy | S24: =IF(ISBLANK(R24),Settings.CurveSide.MidBidAsk,'AUD CURVE TICKERS'!R24) -> PX_MID | T24: =IF(Settings.isCOBToday,_xll.BDP(Q24,'AUD CURVE TICKERS'!S24),_xll.BDH(Q24,'AUD CURVE TICKERS'!S24,Settings.COB,Settings.COB)) -> 43.375
B25: 3Y | C25: ADSO3 | E25: =IF(ISBLANK(D25),Settings.BloombergPCS,D25) -> BGN | F25: Curncy | G25: =C25&" "&E25&" "&F25 -> ADSO3 BGN Curncy | I25: =IF(ISBLANK(H25),Settings.CurveSide.MidBidAsk,'AUD CURVE TICKERS'!H25) -> PX_MID | J25: =IF(Settings.isCOBToday,_xll.BDP(G25,'AUD CURVE TICKERS'!I25),_xll.BDH(G25,'AUD CURVE TICKERS'!I25,Settings.COB,Settings.COB)) -> 1.733 | L25: 20Y | M25: ADBBCO20 | O25: =IF(ISBLANK(N25),Settings.BloombergPCS,N25) -> BGN | P25: Curncy | Q25: =M25&" "&O25&" "&P25 -> ADBBCO20 BGN Curncy | S25: =IF(ISBLANK(R25),Settings.CurveSide.MidBidAsk,'AUD CURVE TICKERS'!R25) -> PX_MID | T25: =IF(Settings.isCOBToday,_xll.BDP(Q25,'AUD CURVE TICKERS'!S25),_xll.BDH(Q25,'AUD CURVE TICKERS'!S25,Settings.COB,Settings.COB)) -> 43.625
B26: 4Y | C26: ADSO4 | E26: =IF(ISBLANK(D26),Settings.BloombergPCS,D26) -> BGN | F26: Curncy | G26: =C26&" "&E26&" "&F26 -> ADSO4 BGN Curncy | I26: =IF(ISBLANK(H26),Settings.CurveSide.MidBidAsk,'AUD CURVE TICKERS'!H26) -> PX_MID | J26: =IF(Settings.isCOBToday,_xll.BDP(G26,'AUD CURVE TICKERS'!I26),_xll.BDH(G26,'AUD CURVE TICKERS'!I26,Settings.COB,Settings.COB)) -> 1.848 | L26: 25Y | M26: ADBBCO25 | O26: =IF(ISBLANK(N26),Settings.BloombergPCS,N26) -> BGN | P26: Curncy | Q26: =M26&" "&O26&" "&P26 -> ADBBCO25 BGN Curncy | S26: =IF(ISBLANK(R26),Settings.CurveSide.MidBidAsk,'AUD CURVE TICKERS'!R26) -> PX_MID | T26: =IF(Settings.isCOBToday,_xll.BDP(Q26,'AUD CURVE TICKERS'!S26),_xll.BDH(Q26,'AUD CURVE TICKERS'!S26,Settings.COB,Settings.COB)) -> 44
B27: 5Y | C27: ADSO5 | E27: =IF(ISBLANK(D27),Settings.BloombergPCS,D27) -> BGN | F27: Curncy | G27: =C27&" "&E27&" "&F27 -> ADSO5 BGN Curncy | I27: =IF(ISBLANK(H27),Settings.CurveSide.MidBidAsk,'AUD CURVE TICKERS'!H27) -> PX_MID | J27: =IF(Settings.isCOBToday,_xll.BDP(G27,'AUD CURVE TICKERS'!I27),_xll.BDH(G27,'AUD CURVE TICKERS'!I27,Settings.COB,Settings.COB)) -> 1.948 | L27: 30Y | M27: ADBBCO30 | O27: =IF(ISBLANK(N27),Settings.BloombergPCS,N27) -> BGN | P27: Curncy | Q27: =M27&" "&O27&" "&P27 -> ADBBCO30 BGN Curncy | S27: =IF(ISBLANK(R27),Settings.CurveSide.MidBidAsk,'AUD CURVE TICKERS'!R27) -> PX_MID | T27: =IF(Settings.isCOBToday,_xll.BDP(Q27,'AUD CURVE TICKERS'!S27),_xll.BDH(Q27,'AUD CURVE TICKERS'!S27,Settings.COB,Settings.COB)) -> 44.375
B28: 6Y | C28: ADSO6 | E28: =IF(ISBLANK(D28),Settings.BloombergPCS,D28) -> BGN | F28: Curncy | G28: =C28&" "&E28&" "&F28 -> ADSO6 BGN Curncy | I28: =IF(ISBLANK(H28),Settings.CurveSide.MidBidAsk,'AUD CURVE TICKERS'!H28) -> PX_MID | J28: =IF(Settings.isCOBToday,_xll.BDP(G28,'AUD CURVE TICKERS'!I28),_xll.BDH(G28,'AUD CURVE TICKERS'!I28,Settings.COB,Settings.COB)) -> 2.025
B29: 7Y | C29: ADSO7 | E29: =IF(ISBLANK(D29),Settings.BloombergPCS,D29) -> BGN | F29: Curncy | G29: =C29&" "&E29&" "&F29 -> ADSO7 BGN Curncy | I29: =IF(ISBLANK(H29),Settings.CurveSide.MidBidAsk,'AUD CURVE TICKERS'!H29) -> PX_MID | J29: =IF(Settings.isCOBToday,_xll.BDP(G29,'AUD CURVE TICKERS'!I29),_xll.BDH(G29,'AUD CURVE TICKERS'!I29,Settings.COB,Settings.COB)) -> 2.1015
B30: 8Y | C30: ADSO8 | E30: =IF(ISBLANK(D30),Settings.BloombergPCS,D30) -> BGN | F30: Curncy | G30: =C30&" "&E30&" "&F30 -> ADSO8 BGN Curncy | I30: =IF(ISBLANK(H30),Settings.CurveSide.MidBidAsk,'AUD CURVE TICKERS'!H30) -> PX_MID | J30: =IF(Settings.isCOBToday,_xll.BDP(G30,'AUD CURVE TICKERS'!I30),_xll.BDH(G30,'AUD CURVE TICKERS'!I30,Settings.COB,Settings.COB)) -> 2.163
B31: 9Y | C31: ADSO9 | E31: =IF(ISBLANK(D31),Settings.BloombergPCS,D31) -> BGN | F31: Curncy | G31: =C31&" "&E31&" "&F31 -> ADSO9 BGN Curncy | I31: =IF(ISBLANK(H31),Settings.CurveSide.MidBidAsk,'AUD CURVE TICKERS'!H31) -> PX_MID | J31: =IF(Settings.isCOBToday,_xll.BDP(G31,'AUD CURVE TICKERS'!I31),_xll.BDH(G31,'AUD CURVE TICKERS'!I31,Settings.COB,Settings.COB)) -> 2.225
B32: 10Y | C32: ADSO10 | E32: =IF(ISBLANK(D32),Settings.BloombergPCS,D32) -> BGN | F32: Curncy | G32: =C32&" "&E32&" "&F32 -> ADSO10 BGN Curncy | I32: =IF(ISBLANK(H32),Settings.CurveSide.MidBidAsk,'AUD CURVE TICKERS'!H32) -> PX_MID | J32: =IF(Settings.isCOBToday,_xll.BDP(G32,'AUD CURVE TICKERS'!I32),_xll.BDH(G32,'AUD CURVE TICKERS'!I32,Settings.COB,Settings.COB)) -> 2.285
B33: 15Y | C33: ADSO15 | E33: =IF(ISBLANK(D33),Settings.BloombergPCS,D33) -> BGN | F33: Curncy | G33: =C33&" "&E33&" "&F33 -> ADSO15 BGN Curncy | I33: =IF(ISBLANK(H33),Settings.CurveSide.MidBidAsk,'AUD CURVE TICKERS'!H33) -> PX_MID | J33: =IF(Settings.isCOBToday,_xll.BDP(G33,'AUD CURVE TICKERS'!I33),_xll.BDH(G33,'AUD CURVE TICKERS'!I33,Settings.COB,Settings.COB)) -> 2.46
B34: 20Y | C34: ADSO20 | E34: =IF(ISBLANK(D34),Settings.BloombergPCS,D34) -> BGN | F34: Curncy | G34: =C34&" "&E34&" "&F34 -> ADSO20 BGN Curncy | I34: =IF(ISBLANK(H34),Settings.CurveSide.MidBidAsk,'AUD CURVE TICKERS'!H34) -> PX_MID | J34: =IF(Settings.isCOBToday,_xll.BDP(G34,'AUD CURVE TICKERS'!I34),_xll.BDH(G34,'AUD CURVE TICKERS'!I34,Settings.COB,Settings.COB)) -> 2.461
B35: 25Y | C35: ADSO25 | E35: =IF(ISBLANK(D35),Settings.BloombergPCS,D35) -> BGN | F35: Curncy | G35: =C35&" "&E35&" "&F35 -> ADSO25 BGN Curncy | I35: =IF(ISBLANK(H35),Settings.CurveSide.MidBidAsk,'AUD CURVE TICKERS'!H35) -> PX_MID | J35: =IF(Settings.isCOBToday,_xll.BDP(G35,'AUD CURVE TICKERS'!I35),_xll.BDH(G35,'AUD CURVE TICKERS'!I35,Settings.COB,Settings.COB)) -> 2.508
B36: 30Y | C36: ADSO30 | E36: =IF(ISBLANK(D36),Settings.BloombergPCS,D36) -> BGN | F36: Curncy | G36: =C36&" "&E36&" "&F36 -> ADSO30 BGN Curncy | I36: =IF(ISBLANK(H36),Settings.CurveSide.MidBidAsk,'AUD CURVE TICKERS'!H36) -> PX_MID | J36: =IF(Settings.isCOBToday,_xll.BDP(G36,'AUD CURVE TICKERS'!I36),_xll.BDH(G36,'AUD CURVE TICKERS'!I36,Settings.COB,Settings.COB)) -> 2.404
A40: << AUDOIS
B42: LIBORFIXINGS | L42: FUTURES | V42: FUTURES.DATES | Y42: SWAPS | AI42: BASISSWAPS
B43: Term | C43: InstrumentID | D43: Broker | E43: Used | F43: Database | G43: Ticker | H43: Side | I43: Used | J43: Result | L43: Term | M43: InstrumentID | N43: Broker | O43: Used | P43: Database | Q43: Ticker | R43: Side | S43: Used | T43: Result | V43: StartDate | W43: EndDate | Y43: Term | Z43: InstrumentID | AA43: Broker | AB43: Used | AC43: Database | AD43: Ticker | AE43: Side | AF43: Used | AG43: Result | AI43: Term | AJ43: InstrumentID | AK43: Broker | AL43: Used | AM43: Database | AN43: Ticker | AO43: Side | AP43: Used | AQ43: Result
B44: 1M | C44: ADBB1M | E44: =IF(ISBLANK(D44),Settings.BloombergPCS,D44) | F44: Curncy | G44: =C44&" "&E44&" "&F44 -> ADBB1M Curncy | I44: =IF(ISBLANK(H44),Settings.CurveSide.MidBidAsk,'AUD CURVE TICKERS'!H44) -> PX_MID | J44: =IF(Settings.isCOBToday,_xll.BDP(G44,'AUD CURVE TICKERS'!I44),_xll.BDH(G44,'AUD CURVE TICKERS'!I44,Settings.COB,Settings.COB)) -> 2.01 | L44: IR1 | M44: IR1 | O44: =IF(ISBLANK(N44),Settings.BloombergPCS,N44) | P44: Comdty | Q44: =M44&" "&O44&" "&P44 -> IR1 Comdty | S44: =IF(ISBLANK(R44),Settings.CurveSide.MidBidAsk,'AUD CURVE TICKERS'!R44) -> PX_MID | T44: =IF(Settings.isCOBToday,_xll.BDP(Q44,'AUD CURVE TICKERS'!S44),_xll.BDH(Q44,'AUD CURVE TICKERS'!S44,Settings.COB,Settings.COB)) -> 98.015 | V44: =IF(Settings.isCOBToday,_xll.BDP(Q44,$V$51),_xll.BDH(Q44,$V$51,Settings.COB,Settings.COB)) -> 14/09/2018 | W44: =IF(Settings.isCOBToday,_xll.BDP(Q44,$V$52),_xll.BDH(Q44,$V$52,Settings.COB,Settings.COB)) -> 14/12/2018 | Y44: 1Y | Z44: ADSW1Q | AB44: =IF(ISBLANK(AA44),Settings.BloombergPCS,AA44) -> BGN | AC44: Curncy | AD44: =Z44&" "&AB44&" "&AC44 -> ADSW1Q BGN Curncy | AF44: =IF(ISBLANK(AE44),Settings.CurveSide.MidBidAsk,'AUD CURVE TICKERS'!AE44) -> PX_MID | AG44: =IF(Settings.isCOBToday,_xll.BDP(AD44,'AUD CURVE TICKERS'!AF44),_xll.BDH(AD44,'AUD CURVE TICKERS'!AF44,Settings.COB,Settings.COB)) -> 2.0295 | AI44: 1Y | AJ44: ADBBCF1 | AL44: =IF(ISBLANK(AK44),Settings.BloombergPCS,AK44) -> BGN | AM44: Curncy | AN44: =AJ44&" "&AL44&" "&AM44 -> ADBBCF1 BGN Curncy | AP44: =IF(ISBLANK(AO44),Settings.CurveSide.MidBidAsk,'AUD CURVE TICKERS'!AO44) -> PX_MID | AQ44: =IF(Settings.isCOBToday,_xll.BDP(AN44,'AUD CURVE TICKERS'!AP44),_xll.BDH(AN44,'AUD CURVE TICKERS'!AP44,Settings.COB,Settings.COB)) -> 14.75
B45: 3M | C45: ADBB3M | E45: =IF(ISBLANK(D45),Settings.BloombergPCS,D45) | F45: Curncy | G45: =C45&" "&E45&" "&F45 -> ADBB3M Curncy | I45: =IF(ISBLANK(H45),Settings.CurveSide.MidBidAsk,'AUD CURVE TICKERS'!H45) -> PX_MID | J45: =IF(Settings.isCOBToday,_xll.BDP(G45,'AUD CURVE TICKERS'!I45),_xll.BDH(G45,'AUD CURVE TICKERS'!I45,Settings.COB,Settings.COB)) -> 2.1153 | L45: IR2 | M45: IR2 | O45: =IF(ISBLANK(N45),Settings.BloombergPCS,N45) | P45: Comdty | Q45: =M45&" "&O45&" "&P45 -> IR2 Comdty | S45: =IF(ISBLANK(R45),Settings.CurveSide.MidBidAsk,'AUD CURVE TICKERS'!R45) -> PX_MID | T45: =IF(Settings.isCOBToday,_xll.BDP(Q45,'AUD CURVE TICKERS'!S45),_xll.BDH(Q45,'AUD CURVE TICKERS'!S45,Settings.COB,Settings.COB)) -> 98.005 | V45: =IF(Settings.isCOBToday,_xll.BDP(Q45,$V$51),_xll.BDH(Q45,$V$51,Settings.COB,Settings.COB)) -> 14/12/2018 | W45: =IF(Settings.isCOBToday,_xll.BDP(Q45,$V$52),_xll.BDH(Q45,$V$52,Settings.COB,Settings.COB)) -> 08/03/2019 | Y45: 2Y | Z45: ADSW2Q | AB45: =IF(ISBLANK(AA45),Settings.BloombergPCS,AA45) -> BGN | AC45: Curncy | AD45: =Z45&" "&AB45&" "&AC45 -> ADSW2Q BGN Curncy | AF45: =IF(ISBLANK(AE45),Settings.CurveSide.MidBidAsk,'AUD CURVE TICKERS'!AE45) -> PX_MID | AG45: =IF(Settings.isCOBToday,_xll.BDP(AD45,'AUD CURVE TICKERS'!AF45),_xll.BDH(AD45,'AUD CURVE TICKERS'!AF45,Settings.COB,Settings.COB)) -> 2.08 | AI45: 2Y | AJ45: ADBBCF2 | AL45: =IF(ISBLANK(AK45),Settings.BloombergPCS,AK45) -> BGN | AM45: Curncy | AN45: =AJ45&" "&AL45&" "&AM45 -> ADBBCF2 BGN Curncy | AP45: =IF(ISBLANK(AO45),Settings.CurveSide.MidBidAsk,'AUD CURVE TICKERS'!AO45) -> PX_MID | AQ45: =IF(Settings.isCOBToday,_xll.BDP(AN45,'AUD CURVE TICKERS'!AP45),_xll.BDH(AN45,'AUD CURVE TICKERS'!AP45,Settings.COB,Settings.COB)) -> 14.725
B46: 6M | C46: ADBB6M | E46: =IF(ISBLANK(D46),Settings.BloombergPCS,D46) | F46: Curncy | G46: =C46&" "&E46&" "&F46 -> ADBB6M Curncy | I46: =IF(ISBLANK(H46),Settings.CurveSide.MidBidAsk,'AUD CURVE TICKERS'!H46) -> PX_MID | J46: =IF(Settings.isCOBToday,_xll.BDP(G46,'AUD CURVE TICKERS'!I46),_xll.BDH(G46,'AUD CURVE TICKERS'!I46,Settings.COB,Settings.COB)) -> 2.23 | L46: IR3 | M46: IR3 | O46: =IF(ISBLANK(N46),Settings.BloombergPCS,N46) | P46: Comdty | Q46: =M46&" "&O46&" "&P46 -> IR3 Comdty | S46: =IF(ISBLANK(R46),Settings.CurveSide.MidBidAsk,'AUD CURVE TICKERS'!R46) -> PX_MID | T46: =IF(Settings.isCOBToday,_xll.BDP(Q46,'AUD CURVE TICKERS'!S46),_xll.BDH(Q46,'AUD CURVE TICKERS'!S46,Settings.COB,Settings.COB)) -> 97.975 | V46: =IF(Settings.isCOBToday,_xll.BDP(Q46,$V$51),_xll.BDH(Q46,$V$51,Settings.COB,Settings.COB)) -> 08/03/2019 | W46: =IF(Settings.isCOBToday,_xll.BDP(Q46,$V$52),_xll.BDH(Q46,$V$52,Settings.COB,Settings.COB)) -> 14/06/2019 | Y46: 3Y | Z46: ADSW3Q | AB46: =IF(ISBLANK(AA46),Settings.BloombergPCS,AA46) -> BGN | AC46: Curncy | AD46: =Z46&" "&AB46&" "&AC46 -> ADSW3Q BGN Curncy | AF46: =IF(ISBLANK(AE46),Settings.CurveSide.MidBidAsk,'AUD CURVE TICKERS'!AE46) -> PX_MID | AG46: =IF(Settings.isCOBToday,_xll.BDP(AD46,'AUD CURVE TICKERS'!AF46),_xll.BDH(AD46,'AUD CURVE TICKERS'!AF46,Settings.COB,Settings.COB)) -> 2.1575 | AI46: 3Y | AJ46: ADBBCF3 | AL46: =IF(ISBLANK(AK46),Settings.BloombergPCS,AK46) -> BGN | AM46: Curncy | AN46: =AJ46&" "&AL46&" "&AM46 -> ADBBCF3 BGN Curncy | AP46: =IF(ISBLANK(AO46),Settings.CurveSide.MidBidAsk,'AUD CURVE TICKERS'!AO46) -> PX_MID | AQ46: =IF(Settings.isCOBToday,_xll.BDP(AN46,'AUD CURVE TICKERS'!AP46),_xll.BDH(AN46,'AUD CURVE TICKERS'!AP46,Settings.COB,Settings.COB)) -> 14.5
L47: IR4 | M47: IR4 | O47: =IF(ISBLANK(N47),Settings.BloombergPCS,N47) | P47: Comdty | Q47: =M47&" "&O47&" "&P47 -> IR4 Comdty | S47: =IF(ISBLANK(R47),Settings.CurveSide.MidBidAsk,'AUD CURVE TICKERS'!R47) -> PX_MID | T47: =IF(Settings.isCOBToday,_xll.BDP(Q47,'AUD CURVE TICKERS'!S47),_xll.BDH(Q47,'AUD CURVE TICKERS'!S47,Settings.COB,Settings.COB)) -> 97.945 | V47: =IF(Settings.isCOBToday,_xll.BDP(Q47,$V$51),_xll.BDH(Q47,$V$51,Settings.COB,Settings.COB)) -> 14/06/2019 | W47: =IF(Settings.isCOBToday,_xll.BDP(Q47,$V$52),_xll.BDH(Q47,$V$52,Settings.COB,Settings.COB)) -> 13/09/2019 | Y47: 4Y | Z47: ADSW4 | AB47: =IF(ISBLANK(AA47),Settings.BloombergPCS,AA47) -> BGN | AC47: Curncy | AD47: =Z47&" "&AB47&" "&AC47 -> ADSW4 BGN Curncy | AF47: =IF(ISBLANK(AE47),Settings.CurveSide.MidBidAsk,'AUD CURVE TICKERS'!AE47) -> PX_MID | AG47: =IF(Settings.isCOBToday,_xll.BDP(AD47,'AUD CURVE TICKERS'!AF47),_xll.BDH(AD47,'AUD CURVE TICKERS'!AF47,Settings.COB,Settings.COB)) -> 2.39375 | AI47: 4Y | AJ47: ADBBCF4 | AL47: =IF(ISBLANK(AK47),Settings.BloombergPCS,AK47) -> BGN | AM47: Curncy | AN47: =AJ47&" "&AL47&" "&AM47 -> ADBBCF4 BGN Curncy | AP47: =IF(ISBLANK(AO47),Settings.CurveSide.MidBidAsk,'AUD CURVE TICKERS'!AO47) -> PX_MID | AQ47: =IF(Settings.isCOBToday,_xll.BDP(AN47,'AUD CURVE TICKERS'!AP47),_xll.BDH(AN47,'AUD CURVE TICKERS'!AP47,Settings.COB,Settings.COB)) -> 14.4
L48: IR5 | M48: IR5 | O48: =IF(ISBLANK(N48),Settings.BloombergPCS,N48) | P48: Comdty | Q48: =M48&" "&O48&" "&P48 -> IR5 Comdty | S48: =IF(ISBLANK(R48),Settings.CurveSide.MidBidAsk,'AUD CURVE TICKERS'!R48) -> PX_MID | T48: =IF(Settings.isCOBToday,_xll.BDP(Q48,'AUD CURVE TICKERS'!S48),_xll.BDH(Q48,'AUD CURVE TICKERS'!S48,Settings.COB,Settings.COB)) -> 97.895 | V48: =IF(Settings.isCOBToday,_xll.BDP(Q48,$V$51),_xll.BDH(Q48,$V$51,Settings.COB,Settings.COB)) -> 13/09/2019 | W48: =IF(Settings.isCOBToday,_xll.BDP(Q48,$V$52),_xll.BDH(Q48,$V$52,Settings.COB,Settings.COB)) -> 13/12/2019 | Y48: 5Y | Z48: ADSW5 | AB48: =IF(ISBLANK(AA48),Settings.BloombergPCS,AA48) -> BGN | AC48: Curncy | AD48: =Z48&" "&AB48&" "&AC48 -> ADSW5 BGN Curncy | AF48: =IF(ISBLANK(AE48),Settings.CurveSide.MidBidAsk,'AUD CURVE TICKERS'!AE48) -> PX_MID | AG48: =IF(Settings.isCOBToday,_xll.BDP(AD48,'AUD CURVE TICKERS'!AF48),_xll.BDH(AD48,'AUD CURVE TICKERS'!AF48,Settings.COB,Settings.COB)) -> 2.486 | AI48: 5Y | AJ48: ADBBCF5 | AL48: =IF(ISBLANK(AK48),Settings.BloombergPCS,AK48) -> BGN | AM48: Curncy | AN48: =AJ48&" "&AL48&" "&AM48 -> ADBBCF5 BGN Curncy | AP48: =IF(ISBLANK(AO48),Settings.CurveSide.MidBidAsk,'AUD CURVE TICKERS'!AO48) -> PX_MID | AQ48: =IF(Settings.isCOBToday,_xll.BDP(AN48,'AUD CURVE TICKERS'!AP48),_xll.BDH(AN48,'AUD CURVE TICKERS'!AP48,Settings.COB,Settings.COB)) -> 14.225
...

Sheet AUD CURVE
AP1: … Curve Generator Templtes
B2: AUD OIS | AB2: AUDOIS - GENERATOR TEMPLATE | AG2: AUD3ML - GENERATOR TEMPLATE | AL2: AUD6ML - GENERATOR TEMPLATE
C4: MARKETDATAPROPERTIES | F4: OIS | L4: OISFIXINGS | R4: LIBOROISBASISSPREADS | V4: SWAPS | AC4: CREATE GENERATOR | AH4: CREATE GENERATOR | AM4: CREATE GENERATOR
F5: Term | G5: Rate | H5: StartDate | I5: EndDate | J5: Use | L5: BaseDate | M5: Rate | O5: Libor-OIS Q | P5: Basis 3X6 | R5: Term | S5: Rate | V5: Term | W5: Rate | AC5: HandleName | AD5: AUD_OIS_CURVE_GENERATOR | AH5: HandleName | AI5: AUD_3ML_CURVE_GENERATOR | AM5: HandleName | AN5: AUD_6ML_CURVE_GENERATOR
C6: Currency | D6: AUD | F6: ='AUD CURVE TICKERS'!B14 -> ON | G6: ='AUD CURVE TICKERS'!J14% -> 0.015 | J6: TRUE | O6: ='AUD CURVE TICKERS'!T14/10000 -> 0.0051 | P6: ='AUD CURVE TICKERS'!AQ44/10000 -> 0.001475 | R6: ='AUD CURVE TICKERS'!L14 -> 1Y | S6: =O6 -> 0.0051 | T6: 3ML | V6: ='AUD CURVE TICKERS'!Y44 -> 1Y | W6: ='AUD CURVE TICKERS'!AG44% -> 0.020295 | AC6: Create Curve Generator | AD6: =_xll.meLWOCurveGeneratorCreate(AD5,AC8,AC9:AD15,AC18,AC19:AD35,AC38,AC39:AD40,AC44,AC45:AD51) -> AUD_OIS_CURVE_GENERATOR@1:38 | AH6: Create Curve Generator | AI6: =_xll.meLWOCurveGeneratorCreate(AI5,AH8,AH9:AI23,AH26,AH27:AI29,AH32,AH33:AI37,AH40,AH41:AI46,AH49,AH50:AI56,AH59,AH60:AI80,AH83,AH84:AI115) -> AUD_3ML_CURVE_GENERATOR@4:38 | AM6: Create Curve Generator | AN6: =_xll.meLWOCurveGeneratorCreate(AN5,AM8,AM9:AN23,AM26,AM27:AN29,AM32,AM33:AN37,AM40,AM41:AN46,AM49,AM50:AN56,AM59,AM60:AN73,AM83,AM84:AN84) -> AUD_6ML_CURVE_GENERATOR@7:38
C7: CurveType | D7: OIS | F7: ='AUD CURVE TICKERS'!B15 -> 1W | G7: ='AUD CURVE TICKERS'!J15% -> 0.015 | J7: TRUE | O7: ='AUD CURVE TICKERS'!T15/10000 -> 0.004725 | P7: ='AUD CURVE TICKERS'!AQ45/10000 -> 0.0014725 | R7: ='AUD CURVE TICKERS'!L15 -> 2Y | S7: =O7 -> 0.004725 | T7: 3ML | V7: ='AUD CURVE TICKERS'!Y45 -> 2Y | W7: ='AUD CURVE TICKERS'!AG45% -> 0.0208
C8: CurveIndexFrequency | D8: DAILY | F8: ='AUD CURVE TICKERS'!B16 -> 1M | G8: ='AUD CURVE TICKERS'!J16% -> 0.01499 | J8: TRUE | O8: ='AUD CURVE TICKERS'!T16/10000 -> 0.004375 | P8: ='AUD CURVE TICKERS'!AQ46/10000 -> 0.00145 | R8: ='AUD CURVE TICKERS'!L16 -> 3Y | S8: =O8 -> 0.004375 | T8: 3ML | V8: ='AUD CURVE TICKERS'!Y46 -> 3Y | W8: ='AUD CURVE TICKERS'!AG46% -> 0.021575 | AC8: CURVEPROPERTIES | AH8: CURVEPROPERTIES | AM8: CURVEPROPERTIES
C9: AsOfDate | D9: =Settings.COB -> 43278 | F9: ='AUD CURVE TICKERS'!B17 -> 2M | G9: ='AUD CURVE TICKERS'!J17% -> 0.015 | J9: TRUE | O9: ='AUD CURVE TICKERS'!T17/10000 -> 0.0042375 | P9: ='AUD CURVE TICKERS'!AQ47/10000 -> 0.00144 | R9: ='AUD CURVE TICKERS'!L17 -> 4Y | S9: =O9+P9 -> 0.0056775 | T9: 6ML | V9: ='AUD CURVE TICKERS'!Y47 -> 4Y | W9: ='AUD CURVE TICKERS'!AG47% -> 0.0239375 | AC9: CurveType | AD9: OIS | AH9: CurveType | AI9: SWAP | AM9: CurveType | AN9: SWAP
F10: ='AUD CURVE TICKERS'!B18 -> 3M | G10: ='AUD CURVE TICKERS'!J18% -> 0.015 | J10: TRUE | O10: ='AUD CURVE TICKERS'!T18/10000 -> 0.0042 | P10: ='AUD CURVE TICKERS'!AQ48/10000 -> 0.0014225 | R10: ='AUD CURVE TICKERS'!L18 -> 5Y | S10: =O10+P10 -> 0.0056225 | T10: 6ML | V10: ='AUD CURVE TICKERS'!Y48 -> 5Y | W10: ='AUD CURVE TICKERS'!AG48% -> 0.02486 | AC10: CurveIndexFrequency | AD10: DAILY | AH10: CurveIndexFrequency | AI10: QUARTERLY | AM10: CurveIndexFrequency | AN10: SEMI-ANNUAL
F11: ='AUD CURVE TICKERS'!B19 -> 4M | G11: ='AUD CURVE TICKERS'!J19% -> 0.01501 | J11: TRUE | O11: ='AUD CURVE TICKERS'!T19/10000 -> 0.0042625 | P11: ='AUD CURVE TICKERS'!AQ49/10000 -> 0.00139 | R11: ='AUD CURVE TICKERS'!L19 -> 6Y | S11: =O11+P11 -> 0.0056525 | T11: 6ML | V11: ='AUD CURVE TICKERS'!Y49 -> 6Y | W11: ='AUD CURVE TICKERS'!AG49% -> 0.025675 | AC11: StaticDataTable | AD11: OIS | AH11: StaticDataTable | AI11: STD | AM11: StaticDataTable | AN11: AUD6ML
C12: Create Market Data Handle | F12: ='AUD CURVE TICKERS'!B20 -> 5M | G12: ='AUD CURVE TICKERS'!J20% -> 0.015025 | J12: TRUE | O12: ='AUD CURVE TICKERS'!T20/10000 -> 0.0043125 | P12: ='AUD CURVE TICKERS'!AQ50/10000 -> 0.00135 | R12: ='AUD CURVE TICKERS'!L20 -> 7Y | S12: =O12+P12 -> 0.0056625 | T12: 6ML | V12: ='AUD CURVE TICKERS'!Y50 -> 7Y | W12: ='AUD CURVE TICKERS'!AG50% -> 0.0264 | AC12: IndexName | AD12: OIS:AUDOIS:AUDDF:AUDDF_AUDCSA:AUDDF_NOCSA | AH12: IndexName | AI12: STD:AUD3ML | AM12: IndexName | AN12: AUD6ML
C13: Handle Name | D13: AUD_OIS_CURVE_MARKETDATA | F13: ='AUD CURVE TICKERS'!B21 -> 6M | G13: ='AUD CURVE TICKERS'!J21% -> 0.01504 | J13: TRUE | O13: ='AUD CURVE TICKERS'!T21/10000 -> 0.004325 | P13: ='AUD CURVE TICKERS'!AQ51/10000 -> 0.0013 | R13: ='AUD CURVE TICKERS'!L21 -> 8Y | S13: =O13+P13 -> 0.005625 | T13: 6ML | V13: ='AUD CURVE TICKERS'!Y51 -> 8Y | W13: ='AUD CURVE TICKERS'!AG51% -> 0.02705 | AC13: Currency | AD13: AUD | AH13: Currency | AI13: AUD | AM13: Currency | AN13: AUD
C14: Market Data Handle | D14: =_xll.meLWOCurveMarketDataCreate(D13,C4,C6:D9,F4,F6:J31,L4,L6:M31,R4,R6:S31,V4,V6:W31) -> AUD_OIS_CURVE_MARKETDATA@2:37 | F14: ='AUD CURVE TICKERS'!B22 -> 9M | G14: ='AUD CURVE TICKERS'!J22% -> 0.01512 | J14: TRUE | O14: ='AUD CURVE TICKERS'!T22/10000 -> 0.0043125 | P14: ='AUD CURVE TICKERS'!AQ52/10000 -> 0.0012625 | R14: ='AUD CURVE TICKERS'!L22 -> 9Y | S14: =O14+P14 -> 0.005575 | T14: 6ML | V14: ='AUD CURVE TICKERS'!Y52 -> 9Y | W14: ='AUD CURVE TICKERS'!AG52% -> 0.027575 | AC14: interpolation | AD14: FN_SPLINEINTERPOLATION | AH14: interpolation | AI14: =IF(Settings.SwapCurve.Interpolation="LINEAR-SPLINE","FN_LINEARSPLINEINTERPOLATION","FN_SPLINEINTERPOLATION") -> FN_SPLINEINTERPOLATION | AM14: interpolation | AN14: =IF(Settings.SwapCurve.Interpolation="LINEAR-SPLINE","FN_LINEARSPLINEINTERPOLATION","FN_SPLINEINTERPOLATION") -> FN_SPLINEINTERPOLATION
F15: ='AUD CURVE TICKERS'!B23 -> 1Y | G15: ='AUD CURVE TICKERS'!J23% -> 0.01528 | J15: TRUE | O15: ='AUD CURVE TICKERS'!T23/10000 -> 0.0043125 | P15: ='AUD CURVE TICKERS'!AQ53/10000 -> 0.001225 | R15: ='AUD CURVE TICKERS'!L23 -> 10Y | S15: =O15+P15 -> 0.0055375 | T15: 6ML | V15: ='AUD CURVE TICKERS'!Y53 -> 10Y | W15: ='AUD CURVE TICKERS'!AG53% -> 0.028065 | AC15: yieldgen.interpolation | AD15: FN_SPLINEINTERPOLATION | AH15: yieldgen.interpolation | AI15: =IF(Settings.SwapCurve.Interpolation="LINEAR-SPLINE","FN_LINEARSPLINEINTERPOLATION","FN_SPLINEINTERPOLATION") -> FN_SPLINEINTERPOLATION | AM15: yieldgen.interpolation | AN15: =IF(Settings.SwapCurve.Interpolation="LINEAR-SPLINE","FN_LINEARSPLINEINTERPOLATION","FN_SPLINEINTERPOLATION") -> FN_SPLINEINTERPOLATION
F16: ='AUD CURVE TICKERS'!B24 -> 2Y | G16: ='AUD CURVE TICKERS'!J24% -> 0.0163 | J16: TRUE | O16: ='AUD CURVE TICKERS'!T24/10000 -> 0.0043375 | P16: ='AUD CURVE TICKERS'!AQ54/10000 -> 0.0011 | R16: ='AUD CURVE TICKERS'!L24 -> 15Y | S16: =O16+P16 -> 0.0054375 | T16: 6ML | V16: ='AUD CURVE TICKERS'!Y54 -> 15Y | W16: ='AUD CURVE TICKERS'!AG54% -> 0.02973 | AH16: isfrause | AI16: FALSE | AM16: isfraUse | AN16: TRUE
F17: ='AUD CURVE TICKERS'!B25 -> 3Y | G17: ='AUD CURVE TICKERS'!J25% -> 0.01733 | J17: TRUE | O17: ='AUD CURVE TICKERS'!T25/10000 -> 0.0043625 | P17: ='AUD CURVE TICKERS'!AQ55/10000 -> 0.001075 | R17: ='AUD CURVE TICKERS'!L25 -> 20Y | S17: =O17+P17 -> 0.0054375 | T17: 6ML | V17: ='AUD CURVE TICKERS'!Y55 -> 20Y | W17: ='AUD CURVE TICKERS'!AG55% -> 0.03025 | AH17: isfutureuse | AI17: TRUE | AM17: isfutureUse | AN17: FALSE
F18: ='AUD CURVE TICKERS'!B26 -> 4Y | G18: ='AUD CURVE TICKERS'!J26% -> 0.01848 | J18: TRUE | O18: ='AUD CURVE TICKERS'!T26/10000 -> 0.0044 | P18: ='AUD CURVE TICKERS'!AQ56/10000 -> 0.0011 | R18: ='AUD CURVE TICKERS'!L26 -> 25Y | S18: =O18+P18 -> 0.0055 | T18: 6ML | V18: ='AUD CURVE TICKERS'!Y56 -> 25Y | W18: ='AUD CURVE TICKERS'!AG56% -> 0.0302375 | AC18: OIS | AH18: future.interpolation | AI18: =IF(Settings.SwapCurve.Interpolation="LINEAR-SPLINE","FN_LINEARSPLINEINTERPOLATION","FN_LINEARINTERPOLATION") -> FN_LINEARINTERPOLATION | AM18: future.interpolation | AN18: =IF(Settings.SwapCurve.Interpolation="LINEAR-SPLINE","FN_LINEARSPLINEINTERPOLATION","FN_LINEARINTERPOLATION") -> FN_LINEARINTERPOLATION
C19: Curve Dictionary | F19: ='AUD CURVE TICKERS'!B27 -> 5Y | G19: ='AUD CURVE TICKERS'!J27% -> 0.01948 | J19: TRUE | O19: ='AUD CURVE TICKERS'!T27/10000 -> 0.0044375 | P19: ='AUD CURVE TICKERS'!AQ57/10000 -> 0.00114 | R19: ='AUD CURVE TICKERS'!L27 -> 30Y | S19: =O19+P19 -> 0.0055775 | T19: 6ML | V19: ='AUD CURVE TICKERS'!Y57 -> 30Y | W19: ='AUD CURVE TICKERS'!AG57% -> 0.0299625 | AC19: calendar | AD19: SYB:LNB | AH19: Frequency | AI19: SIMPLE | AM19: Frequency | AN19: SIMPLE
C20: Handle Name | D20: AUD_OIS_CURVE | F20: ='AUD CURVE TICKERS'!B28 -> 6Y | G20: ='AUD CURVE TICKERS'!J28% -> 0.02025 | J20: TRUE | AC20: daycount | AD20: ACT/365 | AH20: dfcurvename | AI20: OIS | AM20: dfcurvename | AN20: OIS
C21: Curve Generator | D21: =$AD$6 -> AUD_OIS_CURVE_GENERATOR@1:38 | F21: ='AUD CURVE TICKERS'!B29 -> 7Y | G21: ='AUD CURVE TICKERS'!J29% -> 0.021015 | J21: TRUE | AC21: frequency | AD21: ANNUAL | AH21: IsSwapTenorAdjust | AI21: TRUE | AM21: IsSwapTenorAdjust | AN21: FALSE
C22: Domestic Curve Collection | D22: AUDYC | F22: ='AUD CURVE TICKERS'!B30 -> 8Y | G22: ='AUD CURVE TICKERS'!J30% -> 0.02163 | J22: TRUE | AC22: generatemethod | AD22: DAILYCOMPOUNDING | AH22: TenorSwapName | AI22: 3M6MBasis | AM22: FastRebuild | AN22: TRUE
C23: Foreign Curve Collection | F23: ='AUD CURVE TICKERS'!B31 -> 9Y | G23: ='AUD CURVE TICKERS'!J31% -> 0.02225 | J23: TRUE | AC23: resetlag | AD23: 1D | AH23: FastRebuild | AI23: TRUE
F24: ='AUD CURVE TICKERS'!B32 -> 10Y | G24: ='AUD CURVE TICKERS'!J32% -> 0.02285 | J24: TRUE | AC24: firstrate | AD24: SHORTMARKET
F25: ='AUD CURVE TICKERS'!B33 -> 15Y | G25: ='AUD CURVE TICKERS'!J33% -> 0.0246 | J25: TRUE | AC25: slidingrule | AD25: MOD_FOLLOWING
C26: Curve Build | F26: ='AUD CURVE TICKERS'!B34 -> 20Y | G26: ='AUD CURVE TICKERS'!J34% -> 0.02461 | J26: TRUE | AC26: eomday | AD26: 31 | AH26: MONEYMARKET | AM26: MONEYMARKET
C27: Handle Name | D27: {=_xll.meLWOCurveCalibrate(D20,D21,D14,D22,D23)} -> AUD_OIS_CURVE@3:37 | F27: ='AUD CURVE TICKERS'!B35 -> 25Y | G27: ='AUD CURVE TICKERS'!J35% -> 0.02508 | J27: TRUE | AC27: iseomroll | AD27: TRUE | AH27: Calendar | AI27: SYB:LnB | AM27: Calendar | AN27: SYB:LnB
C28: Curve Collection | D28: AUDYC | F28: ='AUD CURVE TICKERS'!B36 -> 30Y | G28: ='AUD CURVE TICKERS'!J36% -> 0.02404 | J28: TRUE | AC28: shorttermconvention | AD28: ARITHMETICAVERAGE | AH28: DayCount | AI28: ACT/365 | AM28: DayCount | AN28: ACT/365
C29: Curve Index | D29: OIS:AUDOIS:AUDDF:AUDDF_AUDCSA:AUDDF_NOCSA | AC29: longtermconvention | AD29: LOBASIS | AH29: Slidingrule | AI29: FOLLOWING | AM29: Slidingrule | AN29: FOLLOWING
C30: Calibration Time Taken | D30: 0.01500 sec | AC30: longterm | AD30: 3Y
C31: Curve Loaded | D31: =LEFT($D$27,3)=LEFT($D$20,3) -> TRUE | AC31: longterm.generatemethod | AD31: NONE
AC32: Epsilon | AD32: 1e-10 | AH32: LIBORFIXINGS | AM32: LIBORFIXINGS
AC33: MaxLoop | AD33: 1000 | AH33: Calendar | AI33: SYB:LnB | AM33: Calendar | AN33: SYB:LnB
AC34: CompoundingMethod | AD34: GEOMETRIC | AH34: Daycount | AI34: ACT/365 | AM34: Daycount | AN34: ACT/365
B35: AUD 3ML | AC35: SmoothShortEnd | AD35: FALSE | AH35: Frequency | AI35: Simple | AM35: Frequency | AN35: Simple
AH36: Resetlag | AI36: 0 | AM36: Resetlag | AN36: 0
C37: MARKETDATAPROPERTIES | F37: LIBORFIXINGS | I37: FRAS | L37: FUTURES | R37: SWAPS | V37: BASISSWAPS | AH37: SlidingRule | AI37: MOD_FOLLOWING | AM37: SlidingRule | AN37: MOD_FOLLOWING
C38: Currency | D38: AUD | F38: Term | G38: Rate | I38: Term | J38: Rate | L38: Term | M38: StartDate | N38: EndDate | O38: Rate | P38: Volatility | R38: Term | S38: Rate | T38: Use | V38: Term | W38: Rate | X38: Use | AC38: LIBOROISBASIS | AD38: OIS FLOAT LEG CONVENTIONS
C39: CurveType | D39: SWAP | F39: ='AUD CURVE TICKERS'!B45 -> 3M | G39: ='AUD CURVE TICKERS'!J45% -> 0.021153 | L39: ='AUD CURVE TICKERS'!L44 -> IR1 | M39: ='AUD CURVE TICKERS'!V44 -> 14/09/2018 | N39: ='AUD CURVE TICKERS'!W44 -> 14/12/2018 | O39: ='AUD CURVE TICKERS'!T44 -> 98.015 | P39: =Settings.Futures.Convexity.HW1F.Vol -> 0.02 | R39: ='AUD CURVE TICKERS'!Y45 -> 2Y | S39: ='AUD CURVE TICKERS'!AG45% -> 0.0208 | T39: TRUE | V39: ='AUD CURVE TICKERS'!AI45 -> 2Y | W39: ='AUD CURVE TICKERS'!AQ45/10000 -> 0.0014725 | X39: TRUE | AC39: frequency | AD39: ANNUAL
C40: CurveIndexFrequency | D40: QUARTERLY | L40: ='AUD CURVE TICKERS'!L45 -> IR2 | M40: ='AUD CURVE TICKERS'!V45 -> 14/12/2018 | N40: ='AUD CURVE TICKERS'!W45 -> 08/03/2019 | O40: ='AUD CURVE TICKERS'!T45 -> 98.005 | P40: =Settings.Futures.Convexity.HW1F.Vol -> 0.02 | R40: ='AUD CURVE TICKERS'!Y46 -> 3Y | S40: ='AUD CURVE TICKERS'!AG46% -> 0.021575 | T40: TRUE | V40: ='AUD CURVE TICKERS'!AI46 -> 3Y | W40: ='AUD CURVE TICKERS'!AQ46/10000 -> 0.00145 | X40: TRUE | AC40: slidingRule | AD40: MOD_FOLLOWING | AH40: FRAS | AM40: FRAS
C41: AsOfDate | D41: =Settings.COB -> 43278 | L41: ='AUD CURVE TICKERS'!L46 -> IR3 | M41: ='AUD CURVE TICKERS'!V46 -> 08/03/2019 | N41: ='AUD CURVE TICKERS'!W46 -> 14/06/2019 | O41: ='AUD CURVE TICKERS'!T46 -> 97.975 | P41: =Settings.Futures.Convexity.HW1F.Vol -> 0.02 | R41: ='AUD CURVE TICKERS'!Y47 -> 4Y | S41: ='AUD CURVE TICKERS'!AG47% -> 0.0239375 | T41: TRUE | V41: ='AUD CURVE TICKERS'!AI47 -> 4Y | W41: ='AUD CURVE TICKERS'!AQ47/10000 -> 0.00144 | X41: TRUE | AH41: Calendar | AI41: SYB:LnB | AM41: Calendar | AN41: SYB:LnB
...

Sheet AUD REPRICING
B2: Trade Dates | E2: SWAPS: AUDOIS
C3: Unadjusted
B4: EffectiveDate | C4: MaturityDate | E4: EffectiveDate | F4: Maturity | G4: Generator | H4: PayRec | I4: Notional | J4: FixedRate | K4: Spread | M4: CreateSwap | N4: CurveCollection | O4: ParRate | P4: Curve | Q4: +/- (Bps)
B5: =_xll.meDateFromTenor(Settings.COB,E5,"MOD_FOLLOWING","SYB:LNB","") -> 43279 | C5: =_xll.meDateFromTenor(B5,F5,) -> 43286 | E5: 1D | F5: 1W | G5: AUD_OIS | H5: PAY | I5: 1000000 | J5: 0.01 | K5: 0 | L5: 1 | M5: =_xll.meLWOSwapCreateFromGenerator("AUDOIS"&L5,G5,H5,I5,B5,C5,J5,K5,,,,,Settings.AllowCalibrationUpdates) -> AUDOIS1@50:0 | N5: AUDYC | O5: =_xll.meLWOSwapParRate(M5,N5) -> 0.015 | P5: ='AUD CURVE'!G7 -> 0.015 | Q5: =(O5-P5)*10000 -> -5.9832139e-08
B6: =_xll.meDateFromTenor(Settings.COB,E6,"MOD_FOLLOWING","SYB:LNB","") -> 43279 | C6: =_xll.meDateFromTenor(B6,F6,) -> 43309 | E6: 1D | F6: 1M | G6: AUD_OIS | H6: PAY | I6: 1000000 | J6: 0.01 | K6: 0 | L6: 2 | M6: =_xll.meLWOSwapCreateFromGenerator("AUDOIS"&L6,G6,H6,I6,B6,C6,J6,K6,,,,,Settings.AllowCalibrationUpdates) -> AUDOIS2@55:0 | N6: AUDYC | O6: =_xll.meLWOSwapParRate(M6,N6) -> 0.01499 | P6: ='AUD CURVE'!G8 -> 0.01499 | Q6: =(O6-P6)*10000 -> 3.3002056e-08
B7: =_xll.meDateFromTenor(Settings.COB,E7,"MOD_FOLLOWING","SYB:LNB","") -> 43279 | C7: =_xll.meDateFromTenor(B7,F7,) -> 43340 | E7: 1D | F7: 2M | G7: AUD_OIS | H7: PAY | I7: 1000000 | J7: 0.01 | K7: 0 | L7: 3 | M7: =_xll.meLWOSwapCreateFromGenerator("AUDOIS"&L7,G7,H7,I7,B7,C7,J7,K7,,,,,Settings.AllowCalibrationUpdates) -> AUDOIS3@48:0 | N7: AUDYC | O7: =_xll.meLWOSwapParRate(M7,N7) -> 0.015 | P7: ='AUD CURVE'!G9 -> 0.015 | Q7: =(O7-P7)*10000 -> 1.9936761e-08
B8: =_xll.meDateFromTenor(Settings.COB,E8,"MOD_FOLLOWING","SYB:LNB","") -> 43279 | C8: =_xll.meDateFromTenor(B8,F8,) -> 43371 | E8: 1D | F8: 3M | G8: AUD_OIS | H8: PAY | I8: 1000000 | J8: 0.01 | K8: 0 | L8: 4 | M8: =_xll.meLWOSwapCreateFromGenerator("AUDOIS"&L8,G8,H8,I8,B8,C8,J8,K8,,,,,Settings.AllowCalibrationUpdates) -> AUDOIS4@51:0 | N8: AUDYC | O8: =_xll.meLWOSwapParRate(M8,N8) -> 0.015 | P8: ='AUD CURVE'!G10 -> 0.015 | Q8: =(O8-P8)*10000 -> 1.2570733e-07
B9: =_xll.meDateFromTenor(Settings.COB,E9,"MOD_FOLLOWING","SYB:LNB","") -> 43279 | C9: =_xll.meDateFromTenor(B9,F9,) -> 43401 | E9: 1D | F9: 4M | G9: AUD_OIS | H9: PAY | I9: 1000000 | J9: 0.01 | K9: 0 | L9: 5 | M9: =_xll.meLWOSwapCreateFromGenerator("AUDOIS"&L9,G9,H9,I9,B9,C9,J9,K9,,,,,Settings.AllowCalibrationUpdates) -> AUDOIS5@46:0 | N9: AUDYC | O9: =_xll.meLWOSwapParRate(M9,N9) -> 0.01501 | P9: ='AUD CURVE'!G11 -> 0.01501 | Q9: =(O9-P9)*10000 -> 1.2490413e-07
B10: =_xll.meDateFromTenor(Settings.COB,E10,"MOD_FOLLOWING","SYB:LNB","") -> 43279 | C10: =_xll.meDateFromTenor(B10,F10,) -> 43432 | E10: 1D | F10: 5M | G10: AUD_OIS | H10: PAY | I10: 1000000 | J10: 0.01 | K10: 0 | L10: 6 | M10: =_xll.meLWOSwapCreateFromGenerator("AUDOIS"&L10,G10,H10,I10,B10,C10,J10,K10,,,,,Settings.AllowCalibrationUpdates) -> AUDOIS6@59:0 | N10: AUDYC | O10: =_xll.meLWOSwapParRate(M10,N10) -> 0.015025 | P10: ='AUD CURVE'!G12 -> 0.015025 | Q10: =(O10-P10)*10000 -> 1.3737221e-07
B11: =_xll.meDateFromTenor(Settings.COB,E11,"MOD_FOLLOWING","SYB:LNB","") -> 43279 | C11: =_xll.meDateFromTenor(B11,F11,) -> 43462 | E11: 1D | F11: 6M | G11: AUD_OIS | H11: PAY | I11: 1000000 | J11: 0.01 | K11: 0 | L11: 7 | M11: =_xll.meLWOSwapCreateFromGenerator("AUDOIS"&L11,G11,H11,I11,B11,C11,J11,K11,,,,,Settings.AllowCalibrationUpdates) -> AUDOIS7@42:0 | N11: AUDYC | O11: =_xll.meLWOSwapParRate(M11,N11) -> 0.01504 | P11: ='AUD CURVE'!G13 -> 0.01504 | Q11: =(O11-P11)*10000 -> 1.6655214e-07
B12: =_xll.meDateFromTenor(Settings.COB,E12,"MOD_FOLLOWING","SYB:LNB","") -> 43279 | C12: =_xll.meDateFromTenor(B12,F12,) -> 43552 | E12: 1D | F12: 9M | G12: AUD_OIS | H12: PAY | I12: 1000000 | J12: 0.01 | K12: 0 | L12: 8 | M12: =_xll.meLWOSwapCreateFromGenerator("AUDOIS"&L12,G12,H12,I12,B12,C12,J12,K12,,,,,Settings.AllowCalibrationUpdates) -> AUDOIS8@58:0 | N12: AUDYC | O12: =_xll.meLWOSwapParRate(M12,N12) -> 0.01512 | P12: ='AUD CURVE'!G14 -> 0.01512 | Q12: =(O12-P12)*10000 -> 1.250965e-07
B13: =_xll.meDateFromTenor(Settings.COB,E13,"MOD_FOLLOWING","SYB:LNB","") -> 43279 | C13: =_xll.meDateFromTenor(B13,F13,) -> 43644 | E13: 1D | F13: 1Y | G13: AUD_OIS | H13: PAY | I13: 1000000 | J13: 0.01 | K13: 0 | L13: 9 | M13: =_xll.meLWOSwapCreateFromGenerator("AUDOIS"&L13,G13,H13,I13,B13,C13,J13,K13,,,,,Settings.AllowCalibrationUpdates) -> AUDOIS9@63:0 | N13: AUDYC | O13: =_xll.meLWOSwapParRate(M13,N13) -> 0.01528 | P13: ='AUD CURVE'!G15 -> 0.01528 | Q13: =(O13-P13)*10000 -> 1.3299362e-07
B14: =_xll.meDateFromTenor(Settings.COB,E14,"MOD_FOLLOWING","SYB:LNB","") -> 43279 | C14: =_xll.meDateFromTenor(B14,F14,) -> 44010 | E14: 1D | F14: 2Y | G14: AUD_OIS | H14: PAY | I14: 1000000 | J14: 0.01 | K14: 0 | L14: 10 | M14: =_xll.meLWOSwapCreateFromGenerator("AUDOIS"&L14,G14,H14,I14,B14,C14,J14,K14,,,,,Settings.AllowCalibrationUpdates) -> AUDOIS10@45:0 | N14: AUDYC | O14: =_xll.meLWOSwapParRate(M14,N14) -> 0.0163 | P14: ='AUD CURVE'!G16 -> 0.0163 | Q14: =(O14-P14)*10000 -> 1.0439639e-07
B17: Trade Dates | E17: SWAPS:AUD3ML/AUD6ML
C18: Unadjusted
B19: EffectiveDate | C19: MaturityDate | E19: EffectiveDate | F19: Maturity | G19: Generator | H19: PayRec | I19: Notional | J19: FixedRate | K19: Spread | M19: CreateSwap | N19: CurveCollection | O19: ParRate | P19: Curve | Q19: +/- (Bps)
B20: =_xll.meDateFromTenor(Settings.COB,E20,"MOD_FOLLOWING","SYB:LNB","") -> 43279 | C20: =_xll.meDateFromTenor(B20,F20,) -> 44010 | E20: 1D | F20: 2Y | G20: AUD_3ML | H20: PAY | I20: 1000000 | J20: 0.01 | K20: 0 | L20: 1 | M20: =_xll.meLWOSwapCreateFromGenerator("AUDIRS"&L20,G20,H20,I20,B20,C20,J20,K20,,,,,Settings.AllowCalibrationUpdates) -> AUDIRS1@54:0 | N20: AUDYC | O20: =_xll.meLWOSwapParRate(M20,N20) -> 0.0208 | P20: ='AUD CURVE'!S39 -> 0.0208 | Q20: =(O20-P20)*10000 -> -4.510281e-13
B21: =_xll.meDateFromTenor(Settings.COB,E21,"MOD_FOLLOWING","SYB:LNB","") -> 43279 | C21: =_xll.meDateFromTenor(B21,F21,) -> 44375 | E21: 1D | F21: 3Y | G21: AUD_3ML | H21: PAY | I21: 1000000 | J21: 0.01 | K21: 0 | L21: 2 | M21: =_xll.meLWOSwapCreateFromGenerator("AUDIRS"&L21,G21,H21,I21,B21,C21,J21,K21,,,,,Settings.AllowCalibrationUpdates) -> AUDIRS2@43:0 | N21: AUDYC | O21: =_xll.meLWOSwapParRate(M21,N21) -> 0.021575 | P21: ='AUD CURVE'!S40 -> 0.021575 | Q21: =(O21-P21)*10000 -> -1.7347235e-13
B22: =_xll.meDateFromTenor(Settings.COB,E22,"MOD_FOLLOWING","SYB:LNB","") -> 43279 | C22: =_xll.meDateFromTenor(B22,F22,) -> 43644 | E22: 1D | F22: 1Y | G22: AUD_6ML | H22: PAY | I22: 1000000 | J22: 0.01 | K22: 0 | L22: 3 | M22: =_xll.meLWOSwapCreateFromGenerator("AUDIRS"&L22,G22,H22,I22,B22,C22,J22,K22,,,,,Settings.AllowCalibrationUpdates) -> AUDIRS3@44:0 | N22: AUDYC | O22: =_xll.meLWOSwapParRate(M22,N22) -> 0.021825 | P22: ='AUD CURVE'!S73 -> 0.021825 | Q22: =(O22-P22)*10000 -> 1.179612e-12
B23: =_xll.meDateFromTenor(Settings.COB,E23,"MOD_FOLLOWING","SYB:LNB","") -> 43279 | C23: =_xll.meDateFromTenor(B23,F23,) -> 44010 | E23: 1D | F23: 2Y | G23: AUD_6ML | H23: PAY | I23: 1000000 | J23: 0.01 | K23: 0 | L23: 4 | M23: =_xll.meLWOSwapCreateFromGenerator("AUDIRS"&L23,G23,H23,I23,B23,C23,J23,K23,,,,,Settings.AllowCalibrationUpdates) -> AUDIRS4@66:0 | N23: AUDYC | O23: =_xll.meLWOSwapParRate(M23,N23) -> 0.02235 | P23: ='AUD CURVE'!S74 -> 0.02235 | Q23: =(O23-P23)*10000 -> 5.2041704e-13
B24: =_xll.meDateFromTenor(Settings.COB,E24,"MOD_FOLLOWING","SYB:LNB","") -> 43279 | C24: =_xll.meDateFromTenor(B24,F24,) -> 44375 | E24: 1D | F24: 3Y | G24: AUD_6ML | H24: PAY | I24: 1000000 | J24: 0.01 | K24: 0 | L24: 5 | M24: =_xll.meLWOSwapCreateFromGenerator("AUDIRS"&L24,G24,H24,I24,B24,C24,J24,K24,,,,,Settings.AllowCalibrationUpdates) -> AUDIRS5@53:0 | N24: AUDYC | O24: =_xll.meLWOSwapParRate(M24,N24) -> 0.02305 | P24: ='AUD CURVE'!S75 -> 0.02305 | Q24: =(O24-P24)*10000 -> 3.8163916e-13
B25: =_xll.meDateFromTenor(Settings.COB,E25,"MOD_FOLLOWING","SYB:LNB","") -> 43279 | C25: =_xll.meDateFromTenor(B25,F25,) -> 44740 | E25: 1D | F25: 4Y | G25: AUD_6ML | H25: PAY | I25: 1000000 | J25: 0.01 | K25: 0 | L25: 6 | M25: =_xll.meLWOSwapCreateFromGenerator("AUDIRS"&L25,G25,H25,I25,B25,C25,J25,K25,,,,,Settings.AllowCalibrationUpdates) -> AUDIRS6@41:0 | N25: AUDYC | O25: =_xll.meLWOSwapParRate(M25,N25) -> 0.0239375 | P25: ='AUD CURVE'!S76 -> 0.0239375 | Q25: =(O25-P25)*10000 -> 0
B26: =_xll.meDateFromTenor(Settings.COB,E26,"MOD_FOLLOWING","SYB:LNB","") -> 43279 | C26: =_xll.meDateFromTenor(B26,F26,) -> 45105 | E26: 1D | F26: 5Y | G26: AUD_6ML | H26: PAY | I26: 1000000 | J26: 0.01 | K26: 0 | L26: 7 | M26: =_xll.meLWOSwapCreateFromGenerator("AUDIRS"&L26,G26,H26,I26,B26,C26,J26,K26,,,,,Settings.AllowCalibrationUpdates) -> AUDIRS7@64:0 | N26: AUDYC | O26: =_xll.meLWOSwapParRate(M26,N26) -> 0.02486 | P26: ='AUD CURVE'!S77 -> 0.02486 | Q26: =(O26-P26)*10000 -> -1.0408341e-13
B27: =_xll.meDateFromTenor(Settings.COB,E27,"MOD_FOLLOWING","SYB:LNB","") -> 43279 | C27: =_xll.meDateFromTenor(B27,F27,) -> 45471 | E27: 1D | F27: 6Y | G27: AUD_6ML | H27: PAY | I27: 1000000 | J27: 0.01 | K27: 0 | L27: 8 | M27: =_xll.meLWOSwapCreateFromGenerator("AUDIRS"&L27,G27,H27,I27,B27,C27,J27,K27,,,,,Settings.AllowCalibrationUpdates) -> AUDIRS8@49:0 | N27: AUDYC | O27: =_xll.meLWOSwapParRate(M27,N27) -> 0.025675 | P27: ='AUD CURVE'!S78 -> 0.025675 | Q27: =(O27-P27)*10000 -> -2.0816682e-13
B28: =_xll.meDateFromTenor(Settings.COB,E28,"MOD_FOLLOWING","SYB:LNB","") -> 43279 | C28: =_xll.meDateFromTenor(B28,F28,) -> 45836 | E28: 1D | F28: 7Y | G28: AUD_6ML | H28: PAY | I28: 1000000 | J28: 0.01 | K28: 0 | L28: 9 | M28: =_xll.meLWOSwapCreateFromGenerator("AUDIRS"&L28,G28,H28,I28,B28,C28,J28,K28,,,,,Settings.AllowCalibrationUpdates) -> AUDIRS9@47:0 | N28: AUDYC | O28: =_xll.meLWOSwapParRate(M28,N28) -> 0.0264 | P28: ='AUD CURVE'!S79 -> 0.0264 | Q28: =(O28-P28)*10000 -> -3.469447e-14
B29: =_xll.meDateFromTenor(Settings.COB,E29,"MOD_FOLLOWING","SYB:LNB","") -> 43279 | C29: =_xll.meDateFromTenor(B29,F29,) -> 46201 | E29: 1D | F29: 8Y | G29: AUD_6ML | H29: PAY | I29: 1000000 | J29: 0.01 | K29: 0 | L29: 10 | M29: =_xll.meLWOSwapCreateFromGenerator("AUDIRS"&L29,G29,H29,I29,B29,C29,J29,K29,,,,,Settings.AllowCalibrationUpdates) -> AUDIRS10@60:0 | N29: AUDYC | O29: =_xll.meLWOSwapParRate(M29,N29) -> 0.02705 | P29: ='AUD CURVE'!S80 -> 0.02705 | Q29: =(O29-P29)*10000 -> 6.9388939e-14
B30: =_xll.meDateFromTenor(Settings.COB,E30,"MOD_FOLLOWING","SYB:LNB","") -> 43279 | C30: =_xll.meDateFromTenor(B30,F30,) -> 46566 | E30: 1D | F30: 9Y | G30: AUD_6ML | H30: PAY | I30: 1000000 | J30: 0.01 | K30: 0 | L30: 11 | M30: =_xll.meLWOSwapCreateFromGenerator("AUDIRS"&L30,G30,H30,I30,B30,C30,J30,K30,,,,,Settings.AllowCalibrationUpdates) -> AUDIRS11@65:0 | N30: AUDYC | O30: =_xll.meLWOSwapParRate(M30,N30) -> 0.027575 | P30: ='AUD CURVE'!S81 -> 0.027575 | Q30: =(O30-P30)*10000 -> -3.469447e-14
B31: =_xll.meDateFromTenor(Settings.COB,E31,"MOD_FOLLOWING","SYB:LNB","") -> 43279 | C31: =_xll.meDateFromTenor(B31,F31,) -> 46932 | E31: 1D | F31: 10Y | G31: AUD_6ML | H31: PAY | I31: 1000000 | J31: 0.01 | K31: 0 | L31: 12 | M31: =_xll.meLWOSwapCreateFromGenerator("AUDIRS"&L31,G31,H31,I31,B31,C31,J31,K31,,,,,Settings.AllowCalibrationUpdates) -> AUDIRS12@56:0 | N31: AUDYC | O31: =_xll.meLWOSwapParRate(M31,N31) -> 0.028065 | P31: ='AUD CURVE'!S82 -> 0.028065 | Q31: =(O31-P31)*10000 -> 6.9388939e-14
B32: =_xll.meDateFromTenor(Settings.COB,E32,"MOD_FOLLOWING","SYB:LNB","") -> 43279 | C32: =_xll.meDateFromTenor(B32,F32,) -> 47662 | E32: 1D | F32: 12Y | G32: AUD_6ML | H32: PAY | I32: 1000000 | J32: 0.01 | K32: 0 | L32: 13 | M32: =_xll.meLWOSwapCreateFromGenerator("AUDIRS"&L32,G32,H32,I32,B32,C32,J32,K32,,,,,Settings.AllowCalibrationUpdates) -> AUDIRS13@61:0 | N32: AUDYC | O32: =_xll.meLWOSwapParRate(M32,N32) -> 0.0289 | P32: ='AUD CURVE'!S83 -> 0.0289 | Q32: =(O32-P32)*10000 -> 3.469447e-14
B33: =_xll.meDateFromTenor(Settings.COB,E33,"MOD_FOLLOWING","SYB:LNB","") -> 43279 | C33: =_xll.meDateFromTenor(B33,F33,) -> 48758 | E33: 1D | F33: 15Y | G33: AUD_6ML | H33: PAY | I33: 1000000 | J33: 0.01 | K33: 0 | L33: 14 | M33: =_xll.meLWOSwapCreateFromGenerator("AUDIRS"&L33,G33,H33,I33,B33,C33,J33,K33,,,,,Settings.AllowCalibrationUpdates) -> AUDIRS14@40:0 | N33: AUDYC | O33: =_xll.meLWOSwapParRate(M33,N33) -> 0.02973 | P33: ='AUD CURVE'!S84 -> 0.02973 | Q33: =(O33-P33)*10000 -> -6.9388939e-14
... B35: =_xll.meDateFromTenor(Settings.COB,E35,"MOD_FOLLOWING","SYB:LNB","") -> 43279 | C35: =_xll.meDateFromTenor(B35,F35,) -> 52410 | E35: 1D | F35: 25Y | G35: AUD_6ML | H35: PAY | I35: 1000000 | J35: 0.01 | K35: 0 | L35: 16 | M35: =_xll.meLWOSwapCreateFromGenerator("AUDIRS"&L35,G35,H35,I35,B35,C35,J35,K35,,,,,Settings.AllowCalibrationUpdates) -> AUDIRS16@57:0 | N35: AUDYC | O35: =_xll.meLWOSwapParRate(M35,N35) -> 0.0302375 | P35: ='AUD CURVE'!S86 -> 0.0302375 | Q35: =(O35-P35)*10000 -> -3.469447e-14
B36: =_xll.meDateFromTenor(Settings.COB,E36,"MOD_FOLLOWING","SYB:LNB","") -> 43279 | C36: =_xll.meDateFromTenor(B36,F36,) -> 54237 | E36: 1D | F36: 30Y | G36: AUD_6ML | H36: PAY | I36: 1000000 | J36: 0.01 | K36: 0 | L36: 17 | M36: =_xll.meLWOSwapCreateFromGenerator("AUDIRS"&L36,G36,H36,I36,B36,C36,J36,K36,,,,,Settings.AllowCalibrationUpdates) -> AUDIRS17@52:0 | N36: AUDYC | O36: =_xll.meLWOSwapParRate(M36,N36) -> 0.029963068 | P36: ='AUD CURVE'!S87 -> 0.0299625 | Q36: =(O36-P36)*10000 -> 0.0056753827 | R36: *
M37: * Bug fix required for recalibration of final calibration instrument

Sheet SYNDICATE AUD IRS
N1: … BENCHMARK LEVEL | Z1: … FIXING INFO
B3: SETTLEMENT DATE | E3: BENCHMARK LEVEL | N3: SWAP
B4: AsOfDay | C4: =Settings.COB -> 43278 | J4: =$C$32 -> MID | N4: Handle Name | O4: AUD_SWAP
B5: ValuationLag | C5: 2D | E5: 3Y Bond Future | F5: Rate | G5: Bid | H5: Ask | I5: Mid | J5: Use | N5: Create Swap | O5: =IF('AUD CURVE'!$D$99,_xll.meLWOSwapCreate(O4,N8:P40),"#LOAD CURVE") -> AUD_SWAP@39:27
B6: BusDayAdjustment | C6: MOD_FOLLOWING | E6: YMA Comdty | F6: =(100-J6)% -> 0.020875 | G6: =_xll.BDP($E$6,$G$5) -> 97.91 | H6: =_xll.BDP($E$6,$H$5) -> 97.915 | I6: =AVERAGE(G6:H6) -> 97.9125 | J6: =IF($J$4="BID",G6,IF($J$4="ASK",H6,I6)) -> 97.9125
B7: Calendar | C7: SYB | J7: =$C$32 -> MID | N7: SWAP | O7: BOND LEG | P7: FUNDING LEG
B8: ValuationDate | C8: =_xll.meDateFromTenor(C4,C5,C6,C7) -> 43280 | E8: 10Y Bond Future | G8: Bid | H8: Ask | I8: Mid | J8: Use | N8: LegType | O8: Leg1:Fixed | P8: Leg2:Float
E9: XMA Comdty | F9: =(100-J9)% -> 0.026225 | G9: =_xll.BDP($E$9,$G$5) -> 97.375 | H9: =_xll.BDP($E$9,$H$5) -> 97.38 | I9: =AVERAGE(G9:H9) -> 97.3775 | J9: =IF($J$7="BID",G9,IF($J$7="ASK",H9,I9)) -> 97.3775 | N9: Notional | O9: =$C$12 -> 1000000 | P9: =$C$12 -> 1000000
B10: BOND SPECIFICATION | N10: NotionalExchange | O10: START_AND_END | P10: START_AND_END
B11: BondIdentifier | C11: MYNEWBOND | E11: Exchange for Physical, EFP | J11: =$C$32 -> MID | N11: PayReceive | O11: PAY | P11: RECEIVE | T11: RESET LOOKUP
B12: FaceValue | C12: 1000000 | E12: Tenor | F12: Ticker | G12: Bid | H12: Ask | I12: Mid | J12: Use | K12: SWP Q | L12: SWP S | N12: ForecastCurve | P12: =IF(P24="QUARTERLY","AUD3ML","AUD6ML") -> AUD3ML | T12: =IF(P24="QUARTERLY",X41,X42) -> ADBB3M CMPN Curncy
B13: BondAccrualFrequency | C13: SEMI-ANNUAL | E13: 1Y | F13: ADSF1Q WBCA Curncy | G13: =_xll.BDP($F13,$G$12) -> -5.75 | H13: =_xll.BDP($F13,$H$12) -> -5.75 | I13: =AVERAGE(G13:H13) -> -5.75 | J13: =IF($J$11="BID",G13,IF($J$11="ASK",H13,I13)) -> -5.75 | K13: =IF(COUNT($F$6,J13)=2,$F$6+J13/10000,"#WAIT: BBG") -> 0.0203 | L13: =IF(COUNT(K13,J31)=2,K13+J31/10000,"#WAIT: BBG") -> 0.021775 | N13: DiscountCurve | O13: AUDOIS | P13: AUDOIS | T13: PX_ASK
B14: BondPaymentFrequency | C14: SEMI-ANNUAL | E14: 2Y | F14: ADSF2Q IAUS Curncy | G14: =_xll.BDP($F14,$G$12) -> -3.75 | H14: =_xll.BDP($F14,$H$12) -> 1.25 | I14: =AVERAGE(G14:H14) -> -1.25 | J14: =IF($J$11="BID",G14,IF($J$11="ASK",H14,I14)) -> -1.25 | K14: =IF(COUNT($F$6,J14)=2,$F$6+J14/10000,"#WAIT: BBG") -> 0.02075 | L14: =IF(COUNT(K14,J32)=2,K14+J32/10000,"#WAIT: BBG") -> 0.0222125 | N14: Currency | O14: AUD | P14: AUD | T14: 2D
B15: Daycount | C15: ACT/ACT | E15: 3Y | F15: ADSF3Q IAUS Curncy | G15: =_xll.BDP($F15,$G$12) -> 4.25 | H15: =_xll.BDP($F15,$H$12) -> 9.25 | I15: =AVERAGE(G15:H15) -> 6.75 | J15: =IF($J$11="BID",G15,IF($J$11="ASK",H15,I15)) -> 6.75 | K15: =IF(COUNT($F$6,J15)=2,$F$6+J15/10000,"#WAIT: BBG") -> 0.02155 | L15: =IF(COUNT(K15,J33)=2,K15+J33/10000,"#WAIT: BBG") -> 0.0229875 | N15: Leverage | O15: 1 | P15: 1 | R15: RESET RATE | T15: =_xll.meDateFromTenor(P22,"-"&T14,"MOD_FOLLOWING","LNB:SYB") -> 43278
B16: ForwardStartTenor | E16: 4Y | F16: ADSF4 IAUS Curncy | G16: =_xll.BDP($F16,$G$12) -> 28 | H16: =_xll.BDP($F16,$H$12) -> 33 | I16: =AVERAGE(G16:H16) -> 30.5 | J16: =IF($J$11="BID",G16,IF($J$11="ASK",H16,I16)) -> 30.5 | K16: =IF(COUNT($F$6,J16)=2,$F$6+J16/10000,"#WAIT: BBG") -> 0.023925 | L16: =IF(COUNT(K16,J34)=2,K16+J34/10000,"#WAIT: BBG") -> 0.0253625 | N16: FixedRate | O16: 0 | R16: =IF(COUNT(T16)=1,T16%,"WAIT: BBG Data Loading") -> 0.021153 | T16: =_xll.BDH(T12,T13,T15,T15) -> 2.1153
B17: AccrualStartDate | C17: =IF(ISBLANK($C$16),C8,_xll.meDateFromTenor(Settings.COB,$C$16,$C$6,$C$7)) -> 43280 | E17: 5Y | F17: ADSF5 IAUS Curncy | G17: =_xll.BDP($F17,$G$12) -> 37.375 | H17: =_xll.BDP($F17,$H$12) -> 42.375 | I17: =AVERAGE(G17:H17) -> 39.875 | J17: =IF($J$11="BID",G17,IF($J$11="ASK",H17,I17)) -> 39.875 | K17: =IF(COUNT($F$6,J17)=2,$F$6+J17/10000,"#WAIT: BBG") -> 0.0248625 | L17: =IF(COUNT(K17,J35)=2,K17+J35/10000,"#WAIT: BBG") -> 0.0262875 | N17: FirstStubCurveIndex | P17: NATURAL
B18: MaturityOrTenor | C18: 10Y | E18: 6Y | F18: ADSF6 IAUS Curncy | G18: =_xll.BDP($F18,$G$12) -> -7.75 | H18: =_xll.BDP($F18,$H$12) -> -2.75 | I18: =AVERAGE(G18:H18) -> -5.25 | J18: =IF($J$11="BID",G18,IF($J$11="ASK",H18,I18)) -> -5.25 | K18: =IF(COUNT($F$6,J18)=2,$F$6+J18/10000,"#WAIT: BBG") -> 0.02035 | L18: =IF(COUNT(K18,J36)=2,K18+J36/10000,"#WAIT: BBG") -> 0.0217375 | N18: LastStubCurveIndex | P18: NATURAL | R18: FIXING OVERRIDE
E19: 7Y | F19: ADSF7 IAUS Curncy | G19: =_xll.BDP($F19,$G$12) -> -0.5 | H19: =_xll.BDP($F19,$H$12) -> 4.5 | I19: =AVERAGE(G19:H19) -> 2 | J19: =IF($J$11="BID",G19,IF($J$11="ASK",H19,I19)) -> 2 | K19: =IF(COUNT(L19,J37)=2,L19-J37/10000,"#WAIT: BBG") -> 0.0250875 | L19: =IF(COUNT($F$9,J19)=2,$F$9+J19/10000,"#WAIT: BBG") -> 0.026425 | N19: FirstFixing | P19: =IF(ISBLANK($R$19),"",$R$19)
B20: SWAP SPECIFICATION | E20: 8Y | F20: ADSF8 IAUS Curncy | G20: =_xll.BDP($F20,$G$12) -> 5.875 | H20: =_xll.BDP($F20,$H$12) -> 10.875 | I20: =AVERAGE(G20:H20) -> 8.375 | J20: =IF($J$11="BID",G20,IF($J$11="ASK",H20,I20)) -> 8.375 | K20: =IF(COUNT(L20,J38)=2,L20-J38/10000,"#WAIT: BBG") -> 0.0257625 | L20: =IF(COUNT($F$9,J20)=2,$F$9+J20/10000,"#WAIT: BBG") -> 0.0270625 | N20: LastFixing
