Workbook
Name allowTradeUpdates: [1]Settings!$K$4
Name enableCurveRepricing: [1]Settings!$M$4
Name Settings.COB: [1]Settings!$C$4

Sheet CZK SWAP 3M
C4: Create & Save Curve Generator | H4: MARKETDATAPROPERTIES | K4: LIBORFIXINGS | N4: FRAs | R4: SWAPS | V4: BASISSWAPS
C5: Enable | D5: TRUE | H5: Currency | I5: CZK | K5: Term | L5: Rate | N5: Term | O5: Rate | P5: Use | R5: Term | S5: Rate | T5: Use | V5: Term | W5: Rate | X5: Use
C6: Generator Filepath | D6: C:\Temp\CZK_SWAP_6M.JSON | H6: CurveType | I6: SWAP | K6: 3M | L6: 0.00855 | N6: 1x4 | O6: =S6 -> 0.0061375 | P6: TRUE | R6: 1Y | S6: 0.0061375 | T6: TRUE | U6: 3M | V6: 1Y | W6: 0.0010875 | X6: TRUE
C7: Create Curve Generator | D7: 1=IF(D5,meLWOCurveGeneratorCreate("CZK_SWAP_6M",C11,C12:D28,C30,C31:D34,C36,C37:D42,C44,C45:D49,C51,C52:D69,C71,C72:D104),"Disabled") | H7: CurveIndexFrequency | I7: SEMI-ANNUAL | K7: 6M | L7: 0.0088 | N7: 2x5 | O7: =S7 -> 0.0062 | P7: TRUE | R7: 2Y | S7: 0.0062 | T7: TRUE | U7: 6M | V7: 2Y | W7: 0.0010125 | X7: TRUE
C8: Save Curve Generator | H8: AsOfDate | I8: 43864 | N8: 3x6 | O8: =S8 -> 0.0062625 | P8: TRUE | R8: 3Y | S8: 0.0062625 | T8: TRUE | U8: 6M | V8: 3Y | W8: 0.0009375 | X8: TRUE
N9: 6x9 | O9: =S9 -> 0.0075 | P9: TRUE | R9: 4Y | S9: 0.0075 | T9: TRUE | U9: 6M | V9: 4Y | W9: 0.0008875 | X9: TRUE
N10: 9x12 | O10: =S10 -> 0.007975 | P10: TRUE | R10: 5Y | S10: 0.007975 | T10: TRUE | U10: 6M | V10: 5Y | W10: 0.0008375 | X10: TRUE
C11: CURVEPROPERTIES | R11: 6Y | S11: 0.008575 | T11: TRUE | U11: 6M | V11: 6Y | W11: 0.0007875 | X11: TRUE
C12: CurveType | D12: SWAP | H12: Create Market Data Handle | R12: 7Y | S12: 0.0091875 | T12: TRUE | U12: 6M | V12: 7Y | W12: 0.0007625 | X12: TRUE
C13: CurveIndexFrequency | D13: QUARTERLY | H13: Handle Name | I13: CZK_SWAP_6M_CURVE_MARKETDATA | R13: 8Y | S13: 0.0097875 | T13: TRUE | U13: 6M | V13: 8Y | W13: 0.000725 | X13: TRUE
C14: StaticDataTable | D14: STD | H14: Market Data Handle | I14: 1=meLWOCurveMarketDataCreate(I13,H4,H5:I10,K4,K6:L10,N4,N6:P11,R4,R6:T20,V4,V6:X20) | R14: 9Y | S14: 0.010375 | T14: TRUE | U14: 6M | V14: 9Y | W14: 0.0006875 | X14: TRUE
C15: IndexName | D15: STD:PRB3M | R15: 10Y | S15: 0.010925 | T15: TRUE | U15: 6M | V15: 10Y | W15: 0.0006625 | X15: TRUE
C16: Currency | D16: CZK | R16: 15Y | S16: 0.0131625 | T16: TRUE | U16: 6M | V16: 15Y | W16: 0.0006 | X16: TRUE
C17: interpolation | D17: SPLINE | R17: 20Y | S17: 0.0143125 | T17: TRUE | U17: 6M | V17: 20Y | W17: 0.0006125 | X17: TRUE
C18: yieldgen.interpolation | D18: SPLINE | R18: 25Y | S18: 0.014775 | T18: TRUE | U18: 6M | V18: 25Y | W18: 0.000625 | X18: TRUE
C19: future.interpolation | D19: LINEAR | H19: Curve Dictionary | R19: 30Y | S19: 0.0146375 | T19: TRUE | U19: 6M | V19: 30Y | W19: 0.00065 | X19: TRUE
C20: isfrause | D20: TRUE | H20: Handle Name | I20: CZK_SWAP_6M_CURVE | R20: 40Y | S20: 0.0146375 | T20: TRUE | U20: Extrapolation | V20: 40Y | W20: 0.00065 | X20: TRUE | Y20: Extrapolation
C21: isfutureuse | D21: FALSE | H21: Curve Generator | I21: =D7 -> 1=IF(D5,meLWOCurveGeneratorCreate("CZK_SWAP_6M",C11,C12:D28,C30,C31:D34,C36,C37:D42,C44,C45:D49,C51,C52:D69,C71,C72:D104),"Disabled")
C22: Frequency | D22: SIMPLE | H22: Domestic Curve Collection | I22: CZKYC
C23: AlwaysCalcJoinDate | D23: TRUE | H23: Foreign Curve Collection
C24: FastRebuild | D24: TRUE
C25: DfCurveName | D25: ITSELF
C26: IsSwapTenorAdjust | D26: TRUE | H26: Curve Build
C27: TenorSwapName | D27: 3M6MBasis | H27: Handle Name | I27: 1=meLWOCurveCalibrate(I20,I21,I14,I22,I23)
H28: Curve Collection | I28: 1=meLWOCurveCalibrate(I20,I21,I14,I22,I23)
H29: Curve Index | I29: 1=meLWOCurveCalibrate(I20,I21,I14,I22,I23)
C30: MONEYMARKET | H30: Calibration Time Taken | I30: 1=meLWOCurveCalibrate(I20,I21,I14,I22,I23)
C31: calendar | D31: PRB | H31: Curve Loaded | I31: =_xll.meLWOExists(I27,"CURVE") -> FALSE
C32: daycount | D32: ACT/360
C33: slidingrule | D33: FOLLOWING | H33: #Error: Swap Curves with Tenor Basis instruments are only supported using the STD staticDataTable keyword. Please check the 'IsTenorSwapAdjust' and StaticDataTable / MarketData parameter settings.
C36: LIBORFIXINGS
C37: calendar | D37: PRB
C38: daycount | D38: ACT/360
C39: frequency | D39: simple
C40: resetlag | D40: 2D
C41: slidingrule | D41: MOD_FOLLOWING
C44: FRAS
C45: Calendar | D45: PRB
C46: DayCount | D46: ACT/360
C47: ResetLag | D47: 2D
...

Sheet CZK_DATA
B2: CASH DEPO | F2: SWAPS | J2: 3X6 BASIS
B3: 6M | C3: PRIB06M Index | D3: =_xll.BDP(C3,"PX_LAST")% -> 0.0037 | F3: 1Y | G3: CKSW1 BGN Curncy | H3: =_xll.BDP(G3,"PX_LAST")% -> 0.0024 | J3: 1Y | K3: CKBSV1 BGN Curncy | L3: =_xll.BDP(K3,"PX_LAST")%/100 -> 0.0005935
F4: 2Y | G4: CKSW2 BGN Curncy | H4: =_xll.BDP(G4,"PX_LAST")% -> 0.0030505 | J4: 2Y | K4: CKBSV2 BGN Curncy | L4: =_xll.BDP(K4,"PX_LAST")%/100 -> 0.000656
B5: FRAS | F5: 3Y | G5: CKSW3 BGN Curncy | H5: =_xll.BDP(G5,"PX_LAST")% -> 0.00355 | J5: 3Y | K5: CKBSV3 BGN Curncy | L5: =_xll.BDP(K5,"PX_LAST")%/100 -> 0.0006575
B6: 1X7 | C6: CKFR0AG CMPN Curncy | D6: =_xll.BDP(C6,"PX_LAST")% -> 0.00318 | F6: 4Y | G6: CKSW4 BGN Curncy | H6: =_xll.BDP(G6,"PX_LAST")% -> 0.004 | J6: 4Y | K6: CKBSV4 BGN Curncy | L6: =_xll.BDP(K6,"PX_LAST")%/100 -> 0.000751
B7: 2X8 | C7: CKFR0BH CMPN Curncy | D7: =_xll.BDP(C7,"PX_LAST")% -> 0.00263 | F7: 5Y | G7: CKSW5 BGN Curncy | H7: =_xll.BDP(G7,"PX_LAST")% -> 0.004425 | J7: 5Y | K7: CKBSV5 BGN Curncy | L7: =_xll.BDP(K7,"PX_LAST")%/100 -> 0.00075
B8: 3X9 | C8: CKFR0CI CMPN Curncy | D8: =_xll.BDP(C8,"PX_LAST")% -> 0.00255 | F8: 6Y | G8: CKSW6 BGN Curncy | H8: =_xll.BDP(G8,"PX_LAST")% -> 0.0047 | J8: 6Y | K8: CKBSV6 BGN Curncy | L8: =_xll.BDP(K8,"PX_LAST")%/100 -> 0.000775
B9: 4X10 | C9: CKFR0DJ CMPN Curncy | D9: =_xll.BDP(C9,"PX_LAST")% -> 0.0023 | F9: 7Y | G9: CKSW7 BGN Curncy | H9: =_xll.BDP(G9,"PX_LAST")% -> 0.00505 | J9: 7Y | K9: CKBSV7 BGN Curncy | L9: =_xll.BDP(K9,"PX_LAST")%/100 -> 0.0008425
B10: 5X11 | C10: CKFR0EK CMPN Curncy | D10: =_xll.BDP(C10,"PX_LAST")% -> 0.00235 | F10: 8Y | G10: CKSW8 BGN Curncy | H10: =_xll.BDP(G10,"PX_LAST")% -> 0.0054313 | J10: 8Y | K10: CKBSV8 BGN Curncy | L10: =_xll.BDP(K10,"PX_LAST")%/100 -> 0.0009375
B11: 6X12 | C11: CKFR0F1 CMPN Curncy | D11: =_xll.BDP(C11,"PX_LAST")% -> 0.0024 | F11: 9Y | G11: CKSW9 BGN Curncy | H11: =_xll.BDP(G11,"PX_LAST")% -> 0.0057 | J11: 9Y | K11: CKBSV9 BGN Curncy | L11: =_xll.BDP(K11,"PX_LAST")%/100 -> 0.000944
B12: 7X13 | C12: CKFR011F CMPN Curncy | D12: =_xll.BDP(C12,"PX_LAST")% -> 0.00273 | F12: 10Y | G12: CKSW10 BGN Curncy | H12: =_xll.BDP(G12,"PX_LAST")% -> 0.006 | J12: 10Y | K12: CKBSV10 BGN Curncy | L12: =_xll.BDP(K12,"PX_LAST")%/100 -> 0.0009
F13: 12Y | G13: CKSW12 BGN Curncy | H13: =_xll.BDP(G13,"PX_LAST")% -> 0.00655 | J13: 12Y | K13: CKBSV12 BGN Curncy | L13: =L12 -> 0.0009 | M13: Extrapolated
F14: 15Y | G14: CKSW15 BGN Curncy | H14: =_xll.BDP(G14,"PX_LAST")% -> 0.00725 | J14: 15Y | K14: CKBSV15 BGN Curncy | L14: =L13 -> 0.0009 | M14: Extrapolated
F15: 20Y | G15: CKSW20 BGN Curncy | H15: =_xll.BDP(G15,"PX_LAST")% -> 0.00795 | J15: 20Y | K15: CKBSV20 BGN Curncy | L15: =L14 -> 0.0009 | M15: Extrapolated
F16: 30Y | G16: CKSW30 BGN Curncy | H16: =_xll.BDP(G16,"PX_LAST")% -> 0.00895 | J16: 30Y | K16: CKBSV30 BGN Curncy | L16: =L15 -> 0.0009 | M16: Extrapolated

Sheet CZK SWAP 6M
C4: Create & Save Curve Generator | H4: MARKETDATAPROPERTIES | K4: LIBORFIXINGS | N4: FRAs | R4: SWAPS | V4: BASISSWAPS
C5: Enable | D5: TRUE | H5: Currency | I5: CZK | K5: Term | L5: Rate | N5: Term | O5: Rate | P5: Use | R5: Term | S5: Rate | T5: Use | V5: Term | W5: Rate | X5: Use
C6: Generator Filepath | D6: C:\Temp\CZK_SWAP_6M.JSON | H6: CurveType | I6: SWAP | K6: =CZK_DATA!B3 -> 6M | L6: =CZK_DATA!D3 -> 0.0037 | N6: =CZK_DATA!B6 -> 1X7 | O6: =CZK_DATA!D6 -> 0.00318 | P6: TRUE | R6: =CZK_DATA!F3 -> 1Y | S6: =CZK_DATA!H3 -> 0.0024 | T6: TRUE | U6: 3M | V6: =R6 -> 1Y | W6: =CZK_DATA!L3 -> 0.0005935 | X6: TRUE | Y6: Basis Needed
C7: Create Curve Generator | D7: =IF(D5,_xll.meLWOCurveGeneratorCreate("CZK_SWAP_6M",C11,C12:D28,C30,C31:D33,C36,C37:D41,C44,C45:D48,C51,C52:D68,C71,C72:D103),"Disabled") -> CZK_SWAP_6M@3:22 | H7: CurveIndexFrequency | I7: SEMI-ANNUAL | N7: =CZK_DATA!B7 -> 2X8 | O7: =CZK_DATA!D7 -> 0.00263 | P7: TRUE | R7: =CZK_DATA!F4 -> 2Y | S7: =CZK_DATA!H4 -> 0.0030505 | T7: TRUE | U7: 6M | V7: =R7 -> 2Y | W7: 0 | X7: TRUE | Y7: Basis Not Required
C8: Save Curve Generator | H8: AsOfDate | I8: =TODAY() -> 43964 | N8: =CZK_DATA!B8 -> 3X9 | O8: =CZK_DATA!D8 -> 0.00255 | P8: TRUE | R8: =CZK_DATA!F5 -> 3Y | S8: =CZK_DATA!H5 -> 0.00355 | T8: TRUE | U8: 6M | V8: =R8 -> 3Y | W8: 0 | X8: TRUE | Y8: Basis Not Required
N9: =CZK_DATA!B9 -> 4X10 | O9: =CZK_DATA!D9 -> 0.0023 | P9: TRUE | R9: =CZK_DATA!F6 -> 4Y | S9: =CZK_DATA!H6 -> 0.004 | T9: TRUE | U9: 6M | V9: =R9 -> 4Y | W9: 0 | X9: TRUE | Y9: Basis Not Required
N10: =CZK_DATA!B10 -> 5X11 | O10: =CZK_DATA!D10 -> 0.00235 | P10: TRUE | R10: =CZK_DATA!F7 -> 5Y | S10: =CZK_DATA!H7 -> 0.004425 | T10: TRUE | U10: 6M | V10: =R10 -> 5Y | W10: 0 | X10: TRUE | Y10: Basis Not Required
C11: CURVEPROPERTIES | R11: =CZK_DATA!F8 -> 6Y | S11: =CZK_DATA!H8 -> 0.0047 | T11: TRUE | U11: 6M | V11: =R11 -> 6Y | W11: 0 | X11: TRUE | Y11: Basis Not Required
C12: CurveType | D12: SWAP | H12: Create Market Data Handle | R12: =CZK_DATA!F9 -> 7Y | S12: =CZK_DATA!H9 -> 0.00505 | T12: TRUE | U12: 6M | V12: =R12 -> 7Y | W12: 0 | X12: TRUE | Y12: Basis Not Required
C13: CurveIndexFrequency | D13: SEMI-ANNUAL | H13: Handle Name | I13: CZK_SWAP_6M_CURVE_MARKETDATA | R13: =CZK_DATA!F10 -> 8Y | S13: =CZK_DATA!H10 -> 0.0054313 | T13: TRUE | U13: 6M | V13: =R13 -> 8Y | W13: 0 | X13: TRUE | Y13: Basis Not Required
C14: StaticDataTable | D14: STD | H14: Market Data Handle | I14: =_xll.meLWOCurveMarketDataCreate(I13,H4,H5:I10,K4,K6:L7,N4,N6:P10,R4,R6:T20,V4,V6:X20) -> CZK_SWAP_6M_CURVE_MARKETDATA@1:43 | R14: =CZK_DATA!F11 -> 9Y | S14: =CZK_DATA!H11 -> 0.0057 | T14: TRUE | U14: 6M | V14: =R14 -> 9Y | W14: 0 | X14: TRUE | Y14: Basis Not Required
C15: IndexName | D15: STD:PRB6M | R15: =CZK_DATA!F12 -> 10Y | S15: =CZK_DATA!H12 -> 0.006 | T15: TRUE | U15: 6M | V15: =R15 -> 10Y | W15: 0 | X15: TRUE | Y15: Basis Not Required
C16: Currency | D16: CZK | R16: =CZK_DATA!F13 -> 12Y | S16: =CZK_DATA!H13 -> 0.00655 | T16: TRUE | U16: 6M | V16: =R16 -> 12Y | W16: 0 | X16: TRUE | Y16: Basis Not Required
C17: interpolation | D17: FN_LINEARSPLINEINTERPOLATION | R17: =CZK_DATA!F14 -> 15Y | S17: =CZK_DATA!H14 -> 0.00725 | T17: TRUE | U17: 6M | V17: =R17 -> 15Y | W17: 0 | X17: TRUE | Y17: Basis Not Required
C18: yieldgen.interpolation | D18: FN_LINEARSPLINEINTERPOLATION | R18: =CZK_DATA!F15 -> 20Y | S18: =CZK_DATA!H15 -> 0.00795 | T18: TRUE | U18: 6M | V18: =R18 -> 20Y | W18: 0 | X18: TRUE | Y18: Basis Not Required
C19: future.interpolation | D19: FN_LINEARSPLINEINTERPOLATION | H19: Curve Dictionary | R19: =CZK_DATA!F16 -> 30Y | S19: =CZK_DATA!H16 -> 0.00895 | T19: TRUE | U19: 6M | V19: =R19 -> 30Y | W19: 0 | X19: TRUE | Y19: Basis Not Required
C20: isfrause | D20: TRUE | H20: Handle Name | I20: CZK_SWAP_6M_CURVE | R20: 40Y | S20: =S19 -> 0.00895 | T20: TRUE | U20: 6M | V20: =R20 -> 40Y | W20: 0 | X20: TRUE | Y20: Basis Not Required
C21: isfutureuse | D21: FALSE | H21: Curve Generator | I21: =D7 -> CZK_SWAP_6M@3:22
C22: Frequency | D22: SIMPLE | H22: Domestic Curve Collection | I22: CZKYC
C23: AlwaysCalcJoinDate | D23: FALSE | H23: Foreign Curve Collection
C24: FastRebuild | D24: TRUE
C25: DfCurveName | D25: ITSELF
C26: IsSwapTenorAdjust | D26: TRUE | H26: Curve Build
C27: TenorSwapName | D27: 3M6MBasis | H27: Handle Name | I27: {=_xll.meLWOCurveCalibrate(I20,I21,I14,I22,I23)} -> CZK_SWAP_6M_CURVE@2:32
H28: Curve Collection | I28: CZKYC
H29: Curve Index | I29: STD:PRB6M
C30: MONEYMARKET | H30: Calibration Time Taken | I30: 0.00500 sec
C31: calendar | D31: PRB | H31: Curve Loaded | I31: =_xll.meLWOExists(I27,"CURVE") -> TRUE
C32: daycount | D32: ACT/360
C33: slidingrule | D33: FOLLOWING
C36: LIBORFIXINGS
C37: calendar | D37: PRB
C38: daycount | D38: ACT/360
C39: frequency | D39: simple
C40: resetlag | D40: 2
C41: slidingrule | D41: MOD_FOLLOWING
C44: FRAS
C45: Calendar | D45: PRB
C46: DayCount | D46: ACT/360
C47: ResetLag | D47: 2
...

Sheet CZK_CHART
B2: {=_xll.meLWOCurveForwardRatesTable("CZKYC","PRB6M")} -> Fixing Dates | C2: PRB6M
B3: 43964 | C3: 0.0037000756
B4: 43997 | C4: 0.00318
B5: 44025 | C5: 0.0026666667
B6: 44056 | C6: 0.002559697
B7: 44088 | C7: 0.0023086207
B8: 44117 | C8: 0.0023466667
B9: 44148 | C9: 0.0022715304
B10: 44179 | C10: 0.0023544257
B11: 44209 | C11: 0.0024519395
B12: 44242 | C12: 0.0025592047
B13: 44270 | C13: 0.0026502176
B14: 44299 | C14: 0.0027444809
... B123: 47616 | C123: 0.0091622118
B124: #N/A | C124: #N/A
B125: #N/A | C125: #N/A
B126: #N/A | C126: #N/A
B127: #N/A | C127: #N/A
B128: #N/A | C128: #N/A
B129: #N/A | C129: #N/A
B130: #N/A | C130: #N/A
B131: #N/A | C131: #N/A
B132: #N/A | C132: #N/A
B133: #N/A | C133: #N/A
B134: #N/A | C134: #N/A
B135: #N/A | C135: #N/A
... B149: #N/A | C149: #N/A

Sheet CZK
B2: Trade Dates | F2: SWAPS: PRB6M | N2: Trade Booking & Pricing | R2: Curve Calibration Check
D3: Unadjusted Date ! | H3: Swap Template
B4: EffectiveDate | C4: Calendar | D4: MaturityDate | F4: EffectiveDate | G4: Maturity | H4: Generator | I4: PayRec | J4: Notional | K4: FixedRate | L4: Spread | N4: CreateSwap | O4: CurveCollection | P4: ParRate | R4: Term | S4: Rate | T4: +/- Bps
B5: =_xll.meDateFromTenor(TODAY(),F5,"MOD_FOLLOWING",$C5,"") -> 43964 | C5: PRB | D5: =_xll.meDateFromTenor(B5,G5,) -> 44694 | F5: 0D | G5: ='CZK SWAP 6M'!R7 -> 2Y | H5: =$B$19 -> CZK_6M@5:8 | I5: PAY | J5: 1000000 | K5: 0.01 | L5: 0 | M5: 27 | N5: =_xll.meLWOSwapCreateFromGenerator("CZK_SWAP"&M5,H5,I5,J5,B5,D5,K5,L5) -> CZK_SWAP27@6:8 | O5: CZKYC | P5: =_xll.meLWOSwapParRate(N5,O5) -> 0.0030505 | R5: ='CZK SWAP 6M'!R7 -> 2Y | S5: ='CZK SWAP 6M'!S7 -> 0.0030505 | T5: =ABS(P5-S5)*10000 -> 4.8138576e-13
B6: =_xll.meDateFromTenor(TODAY(),F6,"MOD_FOLLOWING",$C6,"") -> 43964 | C6: PRB | D6: =_xll.meDateFromTenor(B6,G6,) -> 45059 | F6: 0D | G6: ='CZK SWAP 6M'!R8 -> 3Y | H6: =$B$19 -> CZK_6M@5:8 | I6: PAY | J6: 1000000 | K6: 0.01 | L6: 0 | M6: 28 | N6: =_xll.meLWOSwapCreateFromGenerator("CZK_SWAP"&M6,H6,I6,J6,B6,D6,K6,L6) -> CZK_SWAP28@7:7 | O6: CZKYC | P6: =_xll.meLWOSwapParRate(N6,O6) -> 0.00355 | R6: ='CZK SWAP 6M'!R8 -> 3Y | S6: ='CZK SWAP 6M'!S8 -> 0.00355 | T6: =ABS(P6-S6)*10000 -> 5.3776428e-13
B7: =_xll.meDateFromTenor(TODAY(),F7,"MOD_FOLLOWING",$C7,"") -> 43964 | C7: PRB | D7: =_xll.meDateFromTenor(B7,G7,) -> 45425 | F7: 0D | G7: ='CZK SWAP 6M'!R9 -> 4Y | H7: =$B$19 -> CZK_6M@5:8 | I7: PAY | J7: 1000000 | K7: 0.01 | L7: 0 | M7: 29 | N7: =_xll.meLWOSwapCreateFromGenerator("CZK_SWAP"&M7,H7,I7,J7,B7,D7,K7,L7) -> CZK_SWAP29@8:7 | O7: CZKYC | P7: =_xll.meLWOSwapParRate(N7,O7) -> 0.004 | R7: ='CZK SWAP 6M'!R9 -> 4Y | S7: ='CZK SWAP 6M'!S9 -> 0.004 | T7: =ABS(P7-S7)*10000 -> 1.1275703e-13
B8: =_xll.meDateFromTenor(TODAY(),F8,"MOD_FOLLOWING",$C8,"") -> 43964 | C8: PRB | D8: =_xll.meDateFromTenor(B8,G8,) -> 45790 | F8: 0D | G8: ='CZK SWAP 6M'!R10 -> 5Y | H8: =$B$19 -> CZK_6M@5:8 | I8: PAY | J8: 1000000 | K8: 0.01 | L8: 0 | M8: 30 | N8: =_xll.meLWOSwapCreateFromGenerator("CZK_SWAP"&M8,H8,I8,J8,B8,D8,K8,L8) -> CZK_SWAP30@9:7 | O8: CZKYC | P8: =_xll.meLWOSwapParRate(N8,O8) -> 0.004425 | R8: ='CZK SWAP 6M'!R10 -> 5Y | S8: ='CZK SWAP 6M'!S10 -> 0.004425 | T8: =ABS(P8-S8)*10000 -> 1.1275703e-13
B9: =_xll.meDateFromTenor(TODAY(),F9,"MOD_FOLLOWING",$C9,"") -> 43964 | C9: PRB | D9: =_xll.meDateFromTenor(B9,G9,) -> 46155 | F9: 0D | G9: ='CZK SWAP 6M'!R11 -> 6Y | H9: =$B$19 -> CZK_6M@5:8 | I9: PAY | J9: 1000000 | K9: 0.01 | L9: 0 | M9: 31 | N9: =_xll.meLWOSwapCreateFromGenerator("CZK_SWAP"&M9,H9,I9,J9,B9,D9,K9,L9) -> CZK_SWAP31@10:7 | O9: CZKYC | P9: =_xll.meLWOSwapParRate(N9,O9) -> 0.0047 | R9: ='CZK SWAP 6M'!R11 -> 6Y | S9: ='CZK SWAP 6M'!S11 -> 0.0047 | T9: =ABS(P9-S9)*10000 -> 8.6736174e-14
B10: =_xll.meDateFromTenor(TODAY(),F10,"MOD_FOLLOWING",$C10,"") -> 43964 | C10: PRB | D10: =_xll.meDateFromTenor(B10,G10,) -> 46520 | F10: 0D | G10: ='CZK SWAP 6M'!R12 -> 7Y | H10: =$B$19 -> CZK_6M@5:8 | I10: PAY | J10: 1000000 | K10: 0.01 | L10: 0 | M10: 32 | N10: =_xll.meLWOSwapCreateFromGenerator("CZK_SWAP"&M10,H10,I10,J10,B10,D10,K10,L10) -> CZK_SWAP32@11:7 | O10: CZKYC | P10: =_xll.meLWOSwapParRate(N10,O10) -> 0.00505 | R10: ='CZK SWAP 6M'!R12 -> 7Y | S10: ='CZK SWAP 6M'!S12 -> 0.00505 | T10: =ABS(P10-S10)*10000 -> 1.3010426e-13
B11: =_xll.meDateFromTenor(TODAY(),F11,"MOD_FOLLOWING",$C11,"") -> 43964 | C11: PRB | D11: =_xll.meDateFromTenor(B11,G11,) -> 46886 | F11: 0D | G11: ='CZK SWAP 6M'!R13 -> 8Y | H11: =$B$19 -> CZK_6M@5:8 | I11: PAY | J11: 1000000 | K11: 0.01 | L11: 0 | M11: 33 | N11: =_xll.meLWOSwapCreateFromGenerator("CZK_SWAP"&M11,H11,I11,J11,B11,D11,K11,L11) -> CZK_SWAP33@12:7 | O11: CZKYC | P11: =_xll.meLWOSwapParRate(N11,O11) -> 0.0054313 | R11: ='CZK SWAP 6M'!R13 -> 8Y | S11: ='CZK SWAP 6M'!S13 -> 0.0054313 | T11: =ABS(P11-S11)*10000 -> 9.5409791e-14
B12: =_xll.meDateFromTenor(TODAY(),F12,"MOD_FOLLOWING",$C12,"") -> 43964 | C12: PRB | D12: =_xll.meDateFromTenor(B12,G12,) -> 47251 | F12: 0D | G12: ='CZK SWAP 6M'!R14 -> 9Y | H12: =$B$19 -> CZK_6M@5:8 | I12: PAY | J12: 1000000 | K12: 0.01 | L12: 0 | M12: 34 | N12: =_xll.meLWOSwapCreateFromGenerator("CZK_SWAP"&M12,H12,I12,J12,B12,D12,K12,L12) -> CZK_SWAP34@13:7 | O12: CZKYC | P12: =_xll.meLWOSwapParRate(N12,O12) -> 0.0057 | R12: ='CZK SWAP 6M'!R14 -> 9Y | S12: ='CZK SWAP 6M'!S14 -> 0.0057 | T12: =ABS(P12-S12)*10000 -> 5.2041704e-14
B13: =_xll.meDateFromTenor(TODAY(),F13,"MOD_FOLLOWING",$C13,"") -> 43964 | C13: PRB | D13: =_xll.meDateFromTenor(B13,G13,) -> 47616 | F13: 0D | G13: ='CZK SWAP 6M'!R15 -> 10Y | H13: =$B$19 -> CZK_6M@5:8 | I13: PAY | J13: 1000000 | K13: 0.01 | L13: 0 | M13: 35 | N13: =_xll.meLWOSwapCreateFromGenerator("CZK_SWAP"&M13,H13,I13,J13,B13,D13,K13,L13) -> CZK_SWAP35@14:7 | O13: CZKYC | P13: =_xll.meLWOSwapParRate(N13,O13) -> 0.006 | R13: ='CZK SWAP 6M'!R15 -> 10Y | S13: ='CZK SWAP 6M'!S15 -> 0.006 | T13: =ABS(P13-S13)*10000 -> 3.469447e-14
B14: =_xll.meDateFromTenor(TODAY(),F14,"MOD_FOLLOWING",$C14,"") -> 43964 | C14: PRB | D14: =_xll.meDateFromTenor(B14,G14,) -> 48347 | F14: 0D | G14: ='CZK SWAP 6M'!R16 -> 12Y | H14: =$B$19 -> CZK_6M@5:8 | I14: PAY | J14: 1000000 | K14: 0.01 | L14: 0 | M14: 36 | N14: =_xll.meLWOSwapCreateFromGenerator("CZK_SWAP"&M14,H14,I14,J14,B14,D14,K14,L14) -> CZK_SWAP36@15:7 | O14: CZKYC | P14: =_xll.meLWOSwapParRate(N14,O14) -> 0.00655 | R14: ='CZK SWAP 6M'!R16 -> 12Y | S14: ='CZK SWAP 6M'!S16 -> 0.00655 | T14: =ABS(P14-S14)*10000 -> 0
B15: =_xll.meDateFromTenor(TODAY(),F15,"MOD_FOLLOWING",$C15,"") -> 43964 | C15: PRB | D15: =_xll.meDateFromTenor(B15,G15,) -> 49442 | F15: 0D | G15: ='CZK SWAP 6M'!R17 -> 15Y | H15: =$B$19 -> CZK_6M@5:8 | I15: PAY | J15: 1000000 | K15: 0.01 | L15: 0 | M15: 37 | N15: =_xll.meLWOSwapCreateFromGenerator("CZK_SWAP"&M15,H15,I15,J15,B15,D15,K15,L15) -> CZK_SWAP37@16:7 | O15: CZKYC | P15: =_xll.meLWOSwapParRate(N15,O15) -> 0.00725 | R15: ='CZK SWAP 6M'!R17 -> 15Y | S15: ='CZK SWAP 6M'!S17 -> 0.00725 | T15: =ABS(P15-S15)*10000 -> 7.8062556e-14
B16: =_xll.meDateFromTenor(TODAY(),F16,"MOD_FOLLOWING",$C16,"") -> 43964 | C16: PRB | D16: =_xll.meDateFromTenor(B16,G16,) -> 51269 | F16: 0D | G16: ='CZK SWAP 6M'!R18 -> 20Y | H16: =$B$19 -> CZK_6M@5:8 | I16: PAY | J16: 1000000 | K16: 0.01 | L16: 0 | M16: 38 | N16: =_xll.meLWOSwapCreateFromGenerator("CZK_SWAP"&M16,H16,I16,J16,B16,D16,K16,L16) -> CZK_SWAP38@17:7 | O16: CZKYC | P16: =_xll.meLWOSwapParRate(N16,O16) -> 0.00795 | R16: ='CZK SWAP 6M'!R18 -> 20Y | S16: ='CZK SWAP 6M'!S18 -> 0.00795 | T16: =ABS(P16-S16)*10000 -> 3.469447e-14
B18: SWAP GENERATOR
B19: =_xll.meLWOSwapGeneratorCreate("CZK_6M",B21:D46) -> CZK_6M@5:8
B21: LEGTYPE | C21: Leg1:Fixed | D21: Leg2:Float
B22: LEVERAGE | C22: 1 | D22: 1
B23: FORECASTCURVE | D23: PRB6M
B24: COMPOUNDMETHOD
B25: NOTIONALEXCHANGE | C25: NONE | D25: NONE
B26: DISCOUNTCURVE | C26: PRB6M | D26: PRB6M
B27: VALUATIONCURRENCY | C27: CZK | D27: CZK
B28: CURRENCY | C28: CZK | D28: CZK
B29: ACCRUALFREQUENCY | C29: ANNUAL | D29: SEMI-ANNUAL
B30: ACCRUALBUSINESSDAYADJUSTMENT | C30: MOD_FOLLOWING | D30: MOD_FOLLOWING
B31: ACCRUALCALENDAR | C31: PRB | D31: PRB
B32: ACCRUALDAYCOUNT | C32: ACT/360 | D32: ACT/360
B33: PAYMENTFREQUENCY | C33: ANNUAL | D33: SEMI-ANNUAL
B34: PAYMENTBUSINESSDAYADJUSTMENT | C34: MOD_FOLLOWING | D34: MOD_FOLLOWING
B35: PAYMENTCALENDAR | C35: PRB | D35: PRB
B36: PAYMENTLAG | C36: 0D | D36: 0D
B37: FIRSTSTUBDATE
B38: LASTSTUBDATE
B39: ROLLDAY | C39: NORMAL | D39: NORMAL
B40: STUBTYPE | C40: SHORTSTART | D40: SHORTSTART
B41: FIXINGBUSINESSDAYADJUSTMENT | D41: MOD_FOLLOWING
B42: FIXINGCALENDAR | D42: PRB
B43: FIXINGLAG | D43: 0D
...
