Workbook
Name Settings.AllowCalibrationUpdates: SETTINGS!$C$10
Name Settings.BloombergPCS: SETTINGS!$C$6
Name Settings.COB: SETTINGS!$C$4
Name Settings.CurveSide.MidBidAsk: SETTINGS!$C$7
Name Settings.EnableCurveChart: SETTINGS!$C$9
Name Settings.Futures.Convexity.HW1F.Vol: SETTINGS!$C$8
Name Settings.isCOBToday: SETTINGS!$C$3
Name Settings.SwapCurve.Interpolation: SETTINGS!$C$11

Sheet SETTINGS
U1: … Curve Display
B2: Settings | E2: AUD Curve Chart | N2: Curve Display Settings | Q2: Curve Forward Rates
B3: isCOBToday | C3: =IF(ISBLANK(C5),TRUE,FALSE) -> TRUE | N3: Start | O3: 0Y | Q3: {=IF(AND($C$9,'AUD CURVE'!$D$99),_xll.meLWOCurveForwardRatesTable($N$8,$O$8:$O$10,$O$3,$O$4,,,,$O$5),NA())} -> Fixing Dates | R3: AUDOIS | S3: AUD3ML | T3: AUD6ML
B4: CloseOfBusiness (COB) | C4: =IF(Settings.isCOBToday,TODAY(),$C$5) -> 43420 | N4: Maturity | O4: 20Y | Q4: 43420 | R4: 0.015 | S4: 0.0193 | T4: 0.0211
B5: OverrideDate | N5: Frequency | O5: QUARTERLY | Q5: 43514 | R5: 0.014991402 | S5: 0.019657708 | T5: 0.021297863
B6: PricingSource (PCS) | C6: IAUS | Q6: 43601 | R6: 0.015262621 | S6: 0.020097695 | T6: 0.021765164
B7: CurveSide (Bid-Offer) | C7: PX_MID | N7: CurveCollection | O7: CurveIndices | Q7: 43693 | R7: 0.015595062 | S7: 0.02057507 | T7: 0.022448271
B8: Futures.Convexity.HW1F.Vol (%) | C8: 0.02 | N8: AUDYC | O8: AUDOIS | Q8: 43787 | R8: 0.016418902 | S8: 0.021052197 | T8: 0.023074495
B9: EnableCurveChart | C9: TRUE | O9: AUD3ML | Q9: 43878 | R9: 0.017205574 | S9: 0.021528665 | T9: 0.023520048
B10: AllowCalibrationUpdates | C10: FALSE | O10: AUD6ML | Q10: 43969 | R10: 0.017935832 | S10: 0.022064813 | T10: 0.02392398
B11: SwapCurve.Interpolation | C11: SPLINE | Q11: 44060 | R11: 0.018564484 | S11: 0.022613546 | T11: 0.024414994
Q12: 44151 | R12: 0.019089888 | S12: 0.023207109 | T12: 0.024953311
Q13: 44243 | R13: 0.019607841 | S13: 0.023763348 | T13: 0.025475295
B14: Curve Data Monitor | Q14: 44333 | R14: 0.020039445 | S14: 0.024258928 | T14: 0.025953367
B15: Curve | C15: MissingDataPts | Q15: 44424 | R15: 0.020450783 | S15: 0.024707461 | T15: 0.026411531
B16: AUDOIS | C16: ='AUD CURVE TICKERS'!C4 -> 0 | Q16: 44516 | R16: 0.020840571 | S16: 0.025134804 | T16: 0.026870268
B17: AUD3ML | C17: ='AUD CURVE TICKERS'!F4 -> 0 | Q17: 44608 | R17: 0.021230641 | S17: 0.025556314 | T17: 0.027342381
B18: AUD6ML | C18: ='AUD CURVE TICKERS'!I4 -> 0 | Q18: 44697 | R18: 0.021637086 | S18: 0.025996521 | T18: 0.027799109
Q19: 44789 | R19: 0.02208804 | S19: 0.026477839 | T19: 0.028255959
B20: Fixing.Data | C20: ='AUD CURVE TICKERS'!F5 -> 0 | Q20: 44881 | R20: 0.022571081 | S20: 0.02696377 | T20: 0.028709833
B21: Futures.Data | C21: ='AUD CURVE TICKERS'!F6 -> 0 | Q21: 44973 | R21: 0.023067413 | S21: 0.027456374 | T21: 0.029172752
B22: Futures.Dates | C22: ='AUD CURVE TICKERS'!F7 -> 0 | Q22: 45062 | R22: 0.023537866 | S22: 0.027948809 | T22: 0.029604279
Q23: 45154 | R23: 0.024013946 | S23: 0.028440777 | T23: 0.030005313
Q24: 45246 | R24: 0.024479452 | S24: 0.028886286 | T24: 0.030370082
Q25: 45338 | R25: 0.024852543 | S25: 0.029283025 | T25: 0.030714707
Q26: 45428 | R26: 0.025219487 | S26: 0.029653994 | T26: 0.031034126
Q27: 45520 | R27: 0.025552655 | S27: 0.029969344 | T27: 0.031341253
Q28: 45614 | R28: 0.025825835 | S28: 0.030287836 | T28: 0.031636237
Q29: 45705 | R29: 0.026153314 | S29: 0.030589208 | T29: 0.031905952
Q30: 45793 | R30: 0.026436616 | S30: 0.030880712 | T30: 0.032152163
Q31: 45887 | R31: 0.026761274 | S31: 0.031204067 | T31: 0.032398987
Q32: 45978 | R32: 0.027113881 | S32: 0.031525144 | T32: 0.032622724
Q33: 46069 | R33: 0.027448383 | S33: 0.031791249 | T33: 0.032830187
Q34: 46160 | R34: 0.027708589 | S34: 0.0320122 | T34: 0.033010771
... Q84: 50725 | R84: 0.027429509 | S84: 0.031920567 | T84: 0.033170299
Q85: #N/A | R85: #N/A | S85: #N/A | T85: #N/A
Q86: #N/A | R86: #N/A | S86: #N/A | T86: #N/A
Q87: #N/A | R87: #N/A | S87: #N/A | T87: #N/A
Q88: #N/A | R88: #N/A | S88: #N/A | T88: #N/A
Q89: #N/A | R89: #N/A | S89: #N/A | T89: #N/A
...

Sheet AUD CURVE TICKERS
B2: Check for Missing Instrument Data
B4: AUDOIS | C4: =SUM(C5:C8) -> 0 | E4: AUD3ML | F4: =SUM(F5:F9) -> 0 | H4: AUD6ML | I4: =SUM(I5:I7) -> 0
B5: OIS.Outrights | C5: =COUNTA(B15:B37)-COUNT(J15:J37) -> 0 | E5: Swap3M.LiborFixings | F5: =COUNTA(B45:B67)-COUNT(J45:J67) -> 0 | H5: Swap6M.Fixings | I5: =F5 -> 0
B6: OIS.LiborOIS | C6: =COUNTA(L15:L37)-COUNT(T15:T37) -> 0 | E6: Swap3M.Futures | F6: =COUNTA(L45:L67)-COUNT(T45:T67) -> 0 | H6: Swap6M.FRAs | I6: =COUNTA(B75:B77)-COUNT(J75:J77) -> 0
B7: OIS.TenorBasis | C7: =COUNTA(AI45:AI67)-COUNT(AQ45:AQ67) -> 0 | E7: Swap3M.Futures.Dates | F7: =COUNTA(L45:L50)-COUNTA(V45:V50)+COUNTA(L45:L50)-COUNTA(W45:W50) -> 0 | H7: Swap6M.IRS | I7: =COUNTA(L75:L89)-COUNTA(T75:T89) -> 0
B8: OIS.IRS | C8: =COUNTA(Y45:Y67)-COUNT(AG45:AG67) -> 0 | E8: Swap3M.IRS | F8: =COUNTA(Y45:Y67)-COUNT(AG45:AG67) -> 0
E9: Swap3M.TenorBasis | F9: =COUNTA(AI45:AI67)-COUNT(AQ45:AQ67) -> 0
B13: OIS | L13: LIBOROISBASISSPREADS
B14: Term | C14: InstrumentID | D14: Broker | E14: Used | F14: Database | G14: Ticker | H14: Side | I14: Used | J14: Result | L14: Term | M14: InstrumentID | N14: Broker | O14: Used | P14: Database | Q14: Ticker | R14: Side | S14: Used | T14: Result
B15: ON | C15: RBACOR | E15: =IF(ISBLANK(D15),Settings.BloombergPCS,D15) -> IAUS | F15: Index | G15: =C15&" "&E15&" "&F15 -> RBACOR IAUS Index | H15: PX_MID | I15: =IF(ISBLANK(H15),Settings.CurveSide.MidBidAsk,'AUD CURVE TICKERS'!H15) -> PX_MID | J15: =IF(Settings.isCOBToday,_xll.BDP(G15,'AUD CURVE TICKERS'!I15),_xll.BDH(G15,'AUD CURVE TICKERS'!I15,Settings.COB,Settings.COB)) -> 1.5 | L15: 1Y | M15: ADBBCO1 | O15: =IF(ISBLANK(N15),Settings.BloombergPCS,N15) -> IAUS | P15: Curncy | Q15: =M15&" "&O15&" "&P15 -> ADBBCO1 IAUS Curncy | S15: =IF(ISBLANK(R15),Settings.CurveSide.MidBidAsk,'AUD CURVE TICKERS'!R15) -> PX_MID | T15: =IF(Settings.isCOBToday,_xll.BDP(Q15,'AUD CURVE TICKERS'!S15),_xll.BDH(Q15,'AUD CURVE TICKERS'!S15,Settings.COB,Settings.COB)) -> 43.5
B16: 1W | C16: ADSO1Z | E16: =IF(ISBLANK(D16),Settings.BloombergPCS,D16) -> IAUS | F16: Curncy | G16: =C16&" "&E16&" "&F16 -> ADSO1Z IAUS Curncy | I16: =IF(ISBLANK(H16),Settings.CurveSide.MidBidAsk,'AUD CURVE TICKERS'!H16) -> PX_MID | J16: =IF(Settings.isCOBToday,_xll.BDP(G16,'AUD CURVE TICKERS'!I16),_xll.BDH(G16,'AUD CURVE TICKERS'!I16,Settings.COB,Settings.COB)) -> 1.5 | L16: 2Y | M16: ADBBCO2 | O16: =IF(ISBLANK(N16),Settings.BloombergPCS,N16) -> IAUS | P16: Curncy | Q16: =M16&" "&O16&" "&P16 -> ADBBCO2 IAUS Curncy | S16: =IF(ISBLANK(R16),Settings.CurveSide.MidBidAsk,'AUD CURVE TICKERS'!R16) -> PX_MID | T16: =IF(Settings.isCOBToday,_xll.BDP(Q16,'AUD CURVE TICKERS'!S16),_xll.BDH(Q16,'AUD CURVE TICKERS'!S16,Settings.COB,Settings.COB)) -> 42.25
B17: 1M | C17: ADSOA | E17: =IF(ISBLANK(D17),Settings.BloombergPCS,D17) -> IAUS | F17: Curncy | G17: =C17&" "&E17&" "&F17 -> ADSOA IAUS Curncy | I17: =IF(ISBLANK(H17),Settings.CurveSide.MidBidAsk,'AUD CURVE TICKERS'!H17) -> PX_MID | J17: =IF(Settings.isCOBToday,_xll.BDP(G17,'AUD CURVE TICKERS'!I17),_xll.BDH(G17,'AUD CURVE TICKERS'!I17,Settings.COB,Settings.COB)) -> 1.5 | L17: 3Y | M17: ADBBCO3 | O17: =IF(ISBLANK(N17),Settings.BloombergPCS,N17) -> IAUS | P17: Curncy | Q17: =M17&" "&O17&" "&P17 -> ADBBCO3 IAUS Curncy | S17: =IF(ISBLANK(R17),Settings.CurveSide.MidBidAsk,'AUD CURVE TICKERS'!R17) -> PX_MID | T17: =IF(Settings.isCOBToday,_xll.BDP(Q17,'AUD CURVE TICKERS'!S17),_xll.BDH(Q17,'AUD CURVE TICKERS'!S17,Settings.COB,Settings.COB)) -> 41.5
B18: 2M | C18: ADSOB | E18: =IF(ISBLANK(D18),Settings.BloombergPCS,D18) -> IAUS | F18: Curncy | G18: =C18&" "&E18&" "&F18 -> ADSOB IAUS Curncy | I18: =IF(ISBLANK(H18),Settings.CurveSide.MidBidAsk,'AUD CURVE TICKERS'!H18) -> PX_MID | J18: =IF(Settings.isCOBToday,_xll.BDP(G18,'AUD CURVE TICKERS'!I18),_xll.BDH(G18,'AUD CURVE TICKERS'!I18,Settings.COB,Settings.COB)) -> 1.5 | L18: 4Y | M18: ADBBCO4 | O18: =IF(ISBLANK(N18),Settings.BloombergPCS,N18) -> IAUS | P18: Curncy | Q18: =M18&" "&O18&" "&P18 -> ADBBCO4 IAUS Curncy | S18: =IF(ISBLANK(R18),Settings.CurveSide.MidBidAsk,'AUD CURVE TICKERS'!R18) -> PX_MID | T18: =IF(Settings.isCOBToday,_xll.BDP(Q18,'AUD CURVE TICKERS'!S18),_xll.BDH(Q18,'AUD CURVE TICKERS'!S18,Settings.COB,Settings.COB)) -> 41.5
B19: 3M | C19: ADSOC | E19: =IF(ISBLANK(D19),Settings.BloombergPCS,D19) -> IAUS | F19: Curncy | G19: =C19&" "&E19&" "&F19 -> ADSOC IAUS Curncy | I19: =IF(ISBLANK(H19),Settings.CurveSide.MidBidAsk,'AUD CURVE TICKERS'!H19) -> PX_MID | J19: =IF(Settings.isCOBToday,_xll.BDP(G19,'AUD CURVE TICKERS'!I19),_xll.BDH(G19,'AUD CURVE TICKERS'!I19,Settings.COB,Settings.COB)) -> 1.5005 | L19: 5Y | M19: ADBBCO5 | O19: =IF(ISBLANK(N19),Settings.BloombergPCS,N19) -> IAUS | P19: Curncy | Q19: =M19&" "&O19&" "&P19 -> ADBBCO5 IAUS Curncy | S19: =IF(ISBLANK(R19),Settings.CurveSide.MidBidAsk,'AUD CURVE TICKERS'!R19) -> PX_MID | T19: =IF(Settings.isCOBToday,_xll.BDP(Q19,'AUD CURVE TICKERS'!S19),_xll.BDH(Q19,'AUD CURVE TICKERS'!S19,Settings.COB,Settings.COB)) -> 41.5
B20: 4M | C20: ADSOD | E20: =IF(ISBLANK(D20),Settings.BloombergPCS,D20) -> IAUS | F20: Curncy | G20: =C20&" "&E20&" "&F20 -> ADSOD IAUS Curncy | I20: =IF(ISBLANK(H20),Settings.CurveSide.MidBidAsk,'AUD CURVE TICKERS'!H20) -> PX_MID | J20: =IF(Settings.isCOBToday,_xll.BDP(G20,'AUD CURVE TICKERS'!I20),_xll.BDH(G20,'AUD CURVE TICKERS'!I20,Settings.COB,Settings.COB)) -> 1.502 | L20: 6Y | M20: ADBBCO6 | O20: =IF(ISBLANK(N20),Settings.BloombergPCS,N20) -> IAUS | P20: Curncy | Q20: =M20&" "&O20&" "&P20 -> ADBBCO6 IAUS Curncy | S20: =IF(ISBLANK(R20),Settings.CurveSide.MidBidAsk,'AUD CURVE TICKERS'!R20) -> PX_MID | T20: =IF(Settings.isCOBToday,_xll.BDP(Q20,'AUD CURVE TICKERS'!S20),_xll.BDH(Q20,'AUD CURVE TICKERS'!S20,Settings.COB,Settings.COB)) -> 41.625
B21: 5M | C21: ADSOE | E21: =IF(ISBLANK(D21),Settings.BloombergPCS,D21) -> IAUS | F21: Curncy | G21: =C21&" "&E21&" "&F21 -> ADSOE IAUS Curncy | I21: =IF(ISBLANK(H21),Settings.CurveSide.MidBidAsk,'AUD CURVE TICKERS'!H21) -> PX_MID | J21: =IF(Settings.isCOBToday,_xll.BDP(G21,'AUD CURVE TICKERS'!I21),_xll.BDH(G21,'AUD CURVE TICKERS'!I21,Settings.COB,Settings.COB)) -> 1.50375 | L21: 7Y | M21: ADBBCO7 | O21: =IF(ISBLANK(N21),Settings.BloombergPCS,N21) -> IAUS | P21: Curncy | Q21: =M21&" "&O21&" "&P21 -> ADBBCO7 IAUS Curncy | S21: =IF(ISBLANK(R21),Settings.CurveSide.MidBidAsk,'AUD CURVE TICKERS'!R21) -> PX_MID | T21: =IF(Settings.isCOBToday,_xll.BDP(Q21,'AUD CURVE TICKERS'!S21),_xll.BDH(Q21,'AUD CURVE TICKERS'!S21,Settings.COB,Settings.COB)) -> 41.75
B22: 6M | C22: ADSOF | E22: =IF(ISBLANK(D22),Settings.BloombergPCS,D22) -> IAUS | F22: Curncy | G22: =C22&" "&E22&" "&F22 -> ADSOF IAUS Curncy | I22: =IF(ISBLANK(H22),Settings.CurveSide.MidBidAsk,'AUD CURVE TICKERS'!H22) -> PX_MID | J22: =IF(Settings.isCOBToday,_xll.BDP(G22,'AUD CURVE TICKERS'!I22),_xll.BDH(G22,'AUD CURVE TICKERS'!I22,Settings.COB,Settings.COB)) -> 1.508 | L22: 8Y | M22: ADBBCO8 | O22: =IF(ISBLANK(N22),Settings.BloombergPCS,N22) -> IAUS | P22: Curncy | Q22: =M22&" "&O22&" "&P22 -> ADBBCO8 IAUS Curncy | S22: =IF(ISBLANK(R22),Settings.CurveSide.MidBidAsk,'AUD CURVE TICKERS'!R22) -> PX_MID | T22: =IF(Settings.isCOBToday,_xll.BDP(Q22,'AUD CURVE TICKERS'!S22),_xll.BDH(Q22,'AUD CURVE TICKERS'!S22,Settings.COB,Settings.COB)) -> 41.75
B23: 9M | C23: ADSOI | E23: =IF(ISBLANK(D23),Settings.BloombergPCS,D23) -> IAUS | F23: Curncy | G23: =C23&" "&E23&" "&F23 -> ADSOI IAUS Curncy | I23: =IF(ISBLANK(H23),Settings.CurveSide.MidBidAsk,'AUD CURVE TICKERS'!H23) -> PX_MID | J23: =IF(Settings.isCOBToday,_xll.BDP(G23,'AUD CURVE TICKERS'!I23),_xll.BDH(G23,'AUD CURVE TICKERS'!I23,Settings.COB,Settings.COB)) -> 1.5225 | L23: 9Y | M23: ADBBCO9 | O23: =IF(ISBLANK(N23),Settings.BloombergPCS,N23) -> IAUS | P23: Curncy | Q23: =M23&" "&O23&" "&P23 -> ADBBCO9 IAUS Curncy | S23: =IF(ISBLANK(R23),Settings.CurveSide.MidBidAsk,'AUD CURVE TICKERS'!R23) -> PX_MID | T23: =IF(Settings.isCOBToday,_xll.BDP(Q23,'AUD CURVE TICKERS'!S23),_xll.BDH(Q23,'AUD CURVE TICKERS'!S23,Settings.COB,Settings.COB)) -> 41.75
B24: 1Y | C24: ADSO1 | E24: =IF(ISBLANK(D24),Settings.BloombergPCS,D24) -> IAUS | F24: Curncy | G24: =C24&" "&E24&" "&F24 -> ADSO1 IAUS Curncy | I24: =IF(ISBLANK(H24),Settings.CurveSide.MidBidAsk,'AUD CURVE TICKERS'!H24) -> PX_MID | J24: =IF(Settings.isCOBToday,_xll.BDP(G24,'AUD CURVE TICKERS'!I24),_xll.BDH(G24,'AUD CURVE TICKERS'!I24,Settings.COB,Settings.COB)) -> 1.5475 | L24: 10Y | M24: ADBBCO10 | O24: =IF(ISBLANK(N24),Settings.BloombergPCS,N24) -> IAUS | P24: Curncy | Q24: =M24&" "&O24&" "&P24 -> ADBBCO10 IAUS Curncy | S24: =IF(ISBLANK(R24),Settings.CurveSide.MidBidAsk,'AUD CURVE TICKERS'!R24) -> PX_MID | T24: =IF(Settings.isCOBToday,_xll.BDP(Q24,'AUD CURVE TICKERS'!S24),_xll.BDH(Q24,'AUD CURVE TICKERS'!S24,Settings.COB,Settings.COB)) -> 41.625
B25: 2Y | C25: ADSO2 | E25: =IF(ISBLANK(D25),Settings.BloombergPCS,D25) -> IAUS | F25: Curncy | G25: =C25&" "&E25&" "&F25 -> ADSO2 IAUS Curncy | I25: =IF(ISBLANK(H25),Settings.CurveSide.MidBidAsk,'AUD CURVE TICKERS'!H25) -> PX_MID | J25: =IF(Settings.isCOBToday,_xll.BDP(G25,'AUD CURVE TICKERS'!I25),_xll.BDH(G25,'AUD CURVE TICKERS'!I25,Settings.COB,Settings.COB)) -> 1.675 | L25: 15Y | M25: ADBBCO15 | O25: =IF(ISBLANK(N25),Settings.BloombergPCS,N25) -> IAUS | P25: Curncy | Q25: =M25&" "&O25&" "&P25 -> ADBBCO15 IAUS Curncy | S25: =IF(ISBLANK(R25),Settings.CurveSide.MidBidAsk,'AUD CURVE TICKERS'!R25) -> PX_MID | T25: =IF(Settings.isCOBToday,_xll.BDP(Q25,'AUD CURVE TICKERS'!S25),_xll.BDH(Q25,'AUD CURVE TICKERS'!S25,Settings.COB,Settings.COB)) -> 42
B26: 3Y | C26: ADSO3 | E26: =IF(ISBLANK(D26),Settings.BloombergPCS,D26) -> IAUS | F26: Curncy | G26: =C26&" "&E26&" "&F26 -> ADSO3 IAUS Curncy | I26: =IF(ISBLANK(H26),Settings.CurveSide.MidBidAsk,'AUD CURVE TICKERS'!H26) -> PX_MID | J26: =IF(Settings.isCOBToday,_xll.BDP(G26,'AUD CURVE TICKERS'!I26),_xll.BDH(G26,'AUD CURVE TICKERS'!I26,Settings.COB,Settings.COB)) -> 1.785 | L26: 20Y | M26: ADBBCO20 | O26: =IF(ISBLANK(N26),Settings.BloombergPCS,N26) -> IAUS | P26: Curncy | Q26: =M26&" "&O26&" "&P26 -> ADBBCO20 IAUS Curncy | S26: =IF(ISBLANK(R26),Settings.CurveSide.MidBidAsk,'AUD CURVE TICKERS'!R26) -> PX_MID | T26: =IF(Settings.isCOBToday,_xll.BDP(Q26,'AUD CURVE TICKERS'!S26),_xll.BDH(Q26,'AUD CURVE TICKERS'!S26,Settings.COB,Settings.COB)) -> 42.25
B27: 4Y | C27: ADSO4 | E27: =IF(ISBLANK(D27),Settings.BloombergPCS,D27) -> IAUS | F27: Curncy | G27: =C27&" "&E27&" "&F27 -> ADSO4 IAUS Curncy | I27: =IF(ISBLANK(H27),Settings.CurveSide.MidBidAsk,'AUD CURVE TICKERS'!H27) -> PX_MID | J27: =IF(Settings.isCOBToday,_xll.BDP(G27,'AUD CURVE TICKERS'!I27),_xll.BDH(G27,'AUD CURVE TICKERS'!I27,Settings.COB,Settings.COB)) -> 1.883 | L27: 25Y | M27: ADBBCO25 | O27: =IF(ISBLANK(N27),Settings.BloombergPCS,N27) -> IAUS | P27: Curncy | Q27: =M27&" "&O27&" "&P27 -> ADBBCO25 IAUS Curncy | S27: =IF(ISBLANK(R27),Settings.CurveSide.MidBidAsk,'AUD CURVE TICKERS'!R27) -> PX_MID | T27: =IF(Settings.isCOBToday,_xll.BDP(Q27,'AUD CURVE TICKERS'!S27),_xll.BDH(Q27,'AUD CURVE TICKERS'!S27,Settings.COB,Settings.COB)) -> 42.625
B28: 5Y | C28: ADSO5 | E28: =IF(ISBLANK(D28),Settings.BloombergPCS,D28) -> IAUS | F28: Curncy | G28: =C28&" "&E28&" "&F28 -> ADSO5 IAUS Curncy | I28: =IF(ISBLANK(H28),Settings.CurveSide.MidBidAsk,'AUD CURVE TICKERS'!H28) -> PX_MID | J28: =IF(Settings.isCOBToday,_xll.BDP(G28,'AUD CURVE TICKERS'!I28),_xll.BDH(G28,'AUD CURVE TICKERS'!I28,Settings.COB,Settings.COB)) -> 1.978 | L28: 30Y | M28: ADBBCO30 | O28: =IF(ISBLANK(N28),Settings.BloombergPCS,N28) -> IAUS | P28: Curncy | Q28: =M28&" "&O28&" "&P28 -> ADBBCO30 IAUS Curncy | S28: =IF(ISBLANK(R28),Settings.CurveSide.MidBidAsk,'AUD CURVE TICKERS'!R28) -> PX_MID | T28: =IF(Settings.isCOBToday,_xll.BDP(Q28,'AUD CURVE TICKERS'!S28),_xll.BDH(Q28,'AUD CURVE TICKERS'!S28,Settings.COB,Settings.COB)) -> 43
B29: 6Y | C29: ADSO6 | E29: =IF(ISBLANK(D29),Settings.BloombergPCS,D29) -> IAUS | F29: Curncy | G29: =C29&" "&E29&" "&F29 -> ADSO6 IAUS Curncy | I29: =IF(ISBLANK(H29),Settings.CurveSide.MidBidAsk,'AUD CURVE TICKERS'!H29) -> PX_MID | J29: =IF(Settings.isCOBToday,_xll.BDP(G29,'AUD CURVE TICKERS'!I29),_xll.BDH(G29,'AUD CURVE TICKERS'!I29,Settings.COB,Settings.COB)) -> 2.063
B30: 7Y | C30: ADSO7 | E30: =IF(ISBLANK(D30),Settings.BloombergPCS,D30) -> IAUS | F30: Curncy | G30: =C30&" "&E30&" "&F30 -> ADSO7 IAUS Curncy | I30: =IF(ISBLANK(H30),Settings.CurveSide.MidBidAsk,'AUD CURVE TICKERS'!H30) -> PX_MID | J30: =IF(Settings.isCOBToday,_xll.BDP(G30,'AUD CURVE TICKERS'!I30),_xll.BDH(G30,'AUD CURVE TICKERS'!I30,Settings.COB,Settings.COB)) -> 2.148
B31: 8Y | C31: ADSO8 | E31: =IF(ISBLANK(D31),Settings.BloombergPCS,D31) -> IAUS | F31: Curncy | G31: =C31&" "&E31&" "&F31 -> ADSO8 IAUS Curncy | I31: =IF(ISBLANK(H31),Settings.CurveSide.MidBidAsk,'AUD CURVE TICKERS'!H31) -> PX_MID | J31: =IF(Settings.isCOBToday,_xll.BDP(G31,'AUD CURVE TICKERS'!I31),_xll.BDH(G31,'AUD CURVE TICKERS'!I31,Settings.COB,Settings.COB)) -> 2.215
B32: 9Y | C32: ADSO9 | E32: =IF(ISBLANK(D32),Settings.BloombergPCS,D32) -> IAUS | F32: Curncy | G32: =C32&" "&E32&" "&F32 -> ADSO9 IAUS Curncy | I32: =IF(ISBLANK(H32),Settings.CurveSide.MidBidAsk,'AUD CURVE TICKERS'!H32) -> PX_MID | J32: =IF(Settings.isCOBToday,_xll.BDP(G32,'AUD CURVE TICKERS'!I32),_xll.BDH(G32,'AUD CURVE TICKERS'!I32,Settings.COB,Settings.COB)) -> 2.28
B33: 10Y | C33: ADSO10 | E33: =IF(ISBLANK(D33),Settings.BloombergPCS,D33) -> IAUS | F33: Curncy | G33: =C33&" "&E33&" "&F33 -> ADSO10 IAUS Curncy | I33: =IF(ISBLANK(H33),Settings.CurveSide.MidBidAsk,'AUD CURVE TICKERS'!H33) -> PX_MID | J33: =IF(Settings.isCOBToday,_xll.BDP(G33,'AUD CURVE TICKERS'!I33),_xll.BDH(G33,'AUD CURVE TICKERS'!I33,Settings.COB,Settings.COB)) -> 2.348
B34: 15Y | C34: ADSO15 | E34: =IF(ISBLANK(D34),Settings.BloombergPCS,D34) -> IAUS | F34: Curncy | G34: =C34&" "&E34&" "&F34 -> ADSO15 IAUS Curncy | I34: =IF(ISBLANK(H34),Settings.CurveSide.MidBidAsk,'AUD CURVE TICKERS'!H34) -> PX_MID | J34: =IF(Settings.isCOBToday,_xll.BDP(G34,'AUD CURVE TICKERS'!I34),_xll.BDH(G34,'AUD CURVE TICKERS'!I34,Settings.COB,Settings.COB)) -> 2.548
B35: 20Y | C35: ADSO20 | E35: =IF(ISBLANK(D35),Settings.BloombergPCS,D35) -> IAUS | F35: Curncy | G35: =C35&" "&E35&" "&F35 -> ADSO20 IAUS Curncy | I35: =IF(ISBLANK(H35),Settings.CurveSide.MidBidAsk,'AUD CURVE TICKERS'!H35) -> PX_MID | J35: =IF(Settings.isCOBToday,_xll.BDP(G35,'AUD CURVE TICKERS'!I35),_xll.BDH(G35,'AUD CURVE TICKERS'!I35,Settings.COB,Settings.COB)) -> 2.615
B36: 25Y | C36: ADSO25 | E36: =IF(ISBLANK(D36),Settings.BloombergPCS,D36) -> IAUS | F36: Curncy | G36: =C36&" "&E36&" "&F36 -> ADSO25 IAUS Curncy | I36: =IF(ISBLANK(H36),Settings.CurveSide.MidBidAsk,'AUD CURVE TICKERS'!H36) -> PX_MID | J36: =IF(Settings.isCOBToday,_xll.BDP(G36,'AUD CURVE TICKERS'!I36),_xll.BDH(G36,'AUD CURVE TICKERS'!I36,Settings.COB,Settings.COB)) -> 2.62
B37: 30Y | C37: ADSO30 | E37: =IF(ISBLANK(D37),Settings.BloombergPCS,D37) -> IAUS | F37: Curncy | G37: =C37&" "&E37&" "&F37 -> ADSO30 IAUS Curncy | I37: =IF(ISBLANK(H37),Settings.CurveSide.MidBidAsk,'AUD CURVE TICKERS'!H37) -> PX_MID | J37: =IF(Settings.isCOBToday,_xll.BDP(G37,'AUD CURVE TICKERS'!I37),_xll.BDH(G37,'AUD CURVE TICKERS'!I37,Settings.COB,Settings.COB)) -> 2.583
A40: << AUDOIS
B43: LIBORFIXINGS | L43: FUTURES | V43: FUTURES.DATES | Y43: SWAPS | AI43: BASISSWAPS
B44: Term | C44: InstrumentID | D44: Broker | E44: Used | F44: Database | G44: Ticker | H44: Side | I44: Used | J44: Result | L44: Term | M44: InstrumentID | N44: Broker | O44: Used | P44: Database | Q44: Ticker | R44: Side | S44: Used | T44: Result | V44: StartDate | W44: EndDate | Y44: Term | Z44: InstrumentID | AA44: Broker | AB44: Used | AC44: Database | AD44: Ticker | AE44: Side | AF44: Used | AG44: Result | AI44: Term | AJ44: InstrumentID | AK44: Broker | AL44: Used | AM44: Database | AN44: Ticker | AO44: Side | AP44: Used | AQ44: Result
B45: 1M | C45: ADBB1M | E45: =IF(ISBLANK(D45),Settings.BloombergPCS,D45) | F45: Curncy | G45: =C45&" "&E45&" "&F45 -> ADBB1M Curncy | H45: PX_ASK | I45: =IF(ISBLANK(H45),Settings.CurveSide.MidBidAsk,'AUD CURVE TICKERS'!H45) -> PX_ASK | J45: =IF(Settings.isCOBToday,_xll.BDP(G45,'AUD CURVE TICKERS'!I45),_xll.BDH(G45,'AUD CURVE TICKERS'!I45,Settings.COB,Settings.COB)) -> 1.86 | L45: IR1 | M45: IR1 | O45: =IF(ISBLANK(N45),Settings.BloombergPCS,N45) | P45: Comdty | Q45: =M45&" "&O45&" "&P45 -> IR1 Comdty | S45: =IF(ISBLANK(R45),Settings.CurveSide.MidBidAsk,'AUD CURVE TICKERS'!R45) -> PX_MID | T45: =IF(Settings.isCOBToday,_xll.BDP(Q45,'AUD CURVE TICKERS'!S45),_xll.BDH(Q45,'AUD CURVE TICKERS'!S45,Settings.COB,Settings.COB)) -> 98.025 | V45: =IF(Settings.isCOBToday,_xll.BDP(Q45,$V$52),_xll.BDH(Q45,$V$52,Settings.COB,Settings.COB)) -> 14/12/2018 | W45: =IF(Settings.isCOBToday,_xll.BDP(Q45,$V$53),_xll.BDH(Q45,$V$53,Settings.COB,Settings.COB)) -> 08/03/2019 | Y45: 1Y | Z45: ADSW1Q | AB45: =IF(ISBLANK(AA45),Settings.BloombergPCS,AA45) -> IAUS | AC45: Curncy | AD45: =Z45&" "&AB45&" "&AC45 -> ADSW1Q IAUS Curncy | AF45: =IF(ISBLANK(AE45),Settings.CurveSide.MidBidAsk,'AUD CURVE TICKERS'!AE45) -> PX_MID | AG45: =IF(Settings.isCOBToday,_xll.BDP(AD45,'AUD CURVE TICKERS'!AF45),_xll.BDH(AD45,'AUD CURVE TICKERS'!AF45,Settings.COB,Settings.COB)) -> 1.9775 | AI45: 1Y | AJ45: ADBBCF1 | AL45: =IF(ISBLANK(AK45),Settings.BloombergPCS,AK45) -> IAUS | AM45: Curncy | AN45: =AJ45&" "&AL45&" "&AM45 -> ADBBCF1 IAUS Curncy | AP45: =IF(ISBLANK(AO45),Settings.CurveSide.MidBidAsk,'AUD CURVE TICKERS'!AO45) -> PX_MID | AQ45: =IF(Settings.isCOBToday,_xll.BDP(AN45,'AUD CURVE TICKERS'!AP45),_xll.BDH(AN45,'AUD CURVE TICKERS'!AP45,Settings.COB,Settings.COB)) -> 16.125
B46: 3M | C46: ADBB3M | E46: =IF(ISBLANK(D46),Settings.BloombergPCS,D46) | F46: Curncy | G46: =C46&" "&E46&" "&F46 -> ADBB3M Curncy | H46: PX_ASK | I46: =IF(ISBLANK(H46),Settings.CurveSide.MidBidAsk,'AUD CURVE TICKERS'!H46) -> PX_ASK | J46: =IF(Settings.isCOBToday,_xll.BDP(G46,'AUD CURVE TICKERS'!I46),_xll.BDH(G46,'AUD CURVE TICKERS'!I46,Settings.COB,Settings.COB)) -> 1.93 | L46: IR2 | M46: IR2 | O46: =IF(ISBLANK(N46),Settings.BloombergPCS,N46) | P46: Comdty | Q46: =M46&" "&O46&" "&P46 -> IR2 Comdty | S46: =IF(ISBLANK(R46),Settings.CurveSide.MidBidAsk,'AUD CURVE TICKERS'!R46) -> PX_MID | T46: =IF(Settings.isCOBToday,_xll.BDP(Q46,'AUD CURVE TICKERS'!S46),_xll.BDH(Q46,'AUD CURVE TICKERS'!S46,Settings.COB,Settings.COB)) -> 98.045 | V46: =IF(Settings.isCOBToday,_xll.BDP(Q46,$V$52),_xll.BDH(Q46,$V$52,Settings.COB,Settings.COB)) -> 08/03/2019 | W46: =IF(Settings.isCOBToday,_xll.BDP(Q46,$V$53),_xll.BDH(Q46,$V$53,Settings.COB,Settings.COB)) -> 14/06/2019 | Y46: 2Y | Z46: ADSW2Q | AB46: =IF(ISBLANK(AA46),Settings.BloombergPCS,AA46) -> IAUS | AC46: Curncy | AD46: =Z46&" "&AB46&" "&AC46 -> ADSW2Q IAUS Curncy | AF46: =IF(ISBLANK(AE46),Settings.CurveSide.MidBidAsk,'AUD CURVE TICKERS'!AE46) -> PX_MID | AG46: =IF(Settings.isCOBToday,_xll.BDP(AD46,'AUD CURVE TICKERS'!AF46),_xll.BDH(AD46,'AUD CURVE TICKERS'!AF46,Settings.COB,Settings.COB)) -> 2.08625 | AI46: 2Y | AJ46: ADBBCF2 | AL46: =IF(ISBLANK(AK46),Settings.BloombergPCS,AK46) -> IAUS | AM46: Curncy | AN46: =AJ46&" "&AL46&" "&AM46 -> ADBBCF2 IAUS Curncy | AP46: =IF(ISBLANK(AO46),Settings.CurveSide.MidBidAsk,'AUD CURVE TICKERS'!AO46) -> PX_MID | AQ46: =IF(Settings.isCOBToday,_xll.BDP(AN46,'AUD CURVE TICKERS'!AP46),_xll.BDH(AN46,'AUD CURVE TICKERS'!AP46,Settings.COB,Settings.COB)) -> 15.625
B47: 6M | C47: ADBB6M | E47: =IF(ISBLANK(D47),Settings.BloombergPCS,D47) | F47: Curncy | G47: =C47&" "&E47&" "&F47 -> ADBB6M Curncy | H47: PX_ASK | I47: =IF(ISBLANK(H47),Settings.CurveSide.MidBidAsk,'AUD CURVE TICKERS'!H47) -> PX_ASK | J47: =IF(Settings.isCOBToday,_xll.BDP(G47,'AUD CURVE TICKERS'!I47),_xll.BDH(G47,'AUD CURVE TICKERS'!I47,Settings.COB,Settings.COB)) -> 2.11 | L47: IR3 | M47: IR3 | O47: =IF(ISBLANK(N47),Settings.BloombergPCS,N47) | P47: Comdty | Q47: =M47&" "&O47&" "&P47 -> IR3 Comdty | S47: =IF(ISBLANK(R47),Settings.CurveSide.MidBidAsk,'AUD CURVE TICKERS'!R47) -> PX_MID | T47: =IF(Settings.isCOBToday,_xll.BDP(Q47,'AUD CURVE TICKERS'!S47),_xll.BDH(Q47,'AUD CURVE TICKERS'!S47,Settings.COB,Settings.COB)) -> 98.005 | V47: =IF(Settings.isCOBToday,_xll.BDP(Q47,$V$52),_xll.BDH(Q47,$V$52,Settings.COB,Settings.COB)) -> 14/06/2019 | W47: =IF(Settings.isCOBToday,_xll.BDP(Q47,$V$53),_xll.BDH(Q47,$V$53,Settings.COB,Settings.COB)) -> 13/09/2019 | Y47: 3Y | Z47: ADSW3Q | AB47: =IF(ISBLANK(AA47),Settings.BloombergPCS,AA47) -> IAUS | AC47: Curncy | AD47: =Z47&" "&AB47&" "&AC47 -> ADSW3Q IAUS Curncy | AF47: =IF(ISBLANK(AE47),Settings.CurveSide.MidBidAsk,'AUD CURVE TICKERS'!AE47) -> PX_MID | AG47: =IF(Settings.isCOBToday,_xll.BDP(AD47,'AUD CURVE TICKERS'!AF47),_xll.BDH(AD47,'AUD CURVE TICKERS'!AF47,Settings.COB,Settings.COB)) -> 2.18875 | AI47: 3Y | AJ47: ADBBCF3 | AL47: =IF(ISBLANK(AK47),Settings.BloombergPCS,AK47) -> IAUS | AM47: Curncy | AN47: =AJ47&" "&AL47&" "&AM47 -> ADBBCF3 IAUS Curncy | AP47: =IF(ISBLANK(AO47),Settings.CurveSide.MidBidAsk,'AUD CURVE TICKERS'!AO47) -> PX_MID | AQ47: =IF(Settings.isCOBToday,_xll.BDP(AN47,'AUD CURVE TICKERS'!AP47),_xll.BDH(AN47,'AUD CURVE TICKERS'!AP47,Settings.COB,Settings.COB)) -> 15.125
L48: IR4 | M48: IR4 | O48: =IF(ISBLANK(N48),Settings.BloombergPCS,N48) | P48: Comdty | Q48: =M48&" "&O48&" "&P48 -> IR4 Comdty | S48: =IF(ISBLANK(R48),Settings.CurveSide.MidBidAsk,'AUD CURVE TICKERS'!R48) -> PX_MID | T48: =IF(Settings.isCOBToday,_xll.BDP(Q48,'AUD CURVE TICKERS'!S48),_xll.BDH(Q48,'AUD CURVE TICKERS'!S48,Settings.COB,Settings.COB)) -> 97.935 | V48: =IF(Settings.isCOBToday,_xll.BDP(Q48,$V$52),_xll.BDH(Q48,$V$52,Settings.COB,Settings.COB)) -> 13/09/2019 | W48: =IF(Settings.isCOBToday,_xll.BDP(Q48,$V$53),_xll.BDH(Q48,$V$53,Settings.COB,Settings.COB)) -> 13/12/2019 | Y48: 4Y | Z48: ADSW4 | AB48: =IF(ISBLANK(AA48),Settings.BloombergPCS,AA48) -> IAUS | AC48: Curncy | AD48: =Z48&" "&AB48&" "&AC48 -> ADSW4 IAUS Curncy | AF48: =IF(ISBLANK(AE48),Settings.CurveSide.MidBidAsk,'AUD CURVE TICKERS'!AE48) -> PX_MID | AG48: =IF(Settings.isCOBToday,_xll.BDP(AD48,'AUD CURVE TICKERS'!AF48),_xll.BDH(AD48,'AUD CURVE TICKERS'!AF48,Settings.COB,Settings.COB)) -> 2.44 | AI48: 4Y | AJ48: ADBBCF4 | AL48: =IF(ISBLANK(AK48),Settings.BloombergPCS,AK48) -> IAUS | AM48: Curncy | AN48: =AJ48&" "&AL48&" "&AM48 -> ADBBCF4 IAUS Curncy | AP48: =IF(ISBLANK(AO48),Settings.CurveSide.MidBidAsk,'AUD CURVE TICKERS'!AO48) -> PX_MID | AQ48: =IF(Settings.isCOBToday,_xll.BDP(AN48,'AUD CURVE TICKERS'!AP48),_xll.BDH(AN48,'AUD CURVE TICKERS'!AP48,Settings.COB,Settings.COB)) -> 15
L49: IR5 | M49: IR5 | O49: =IF(ISBLANK(N49),Settings.BloombergPCS,N49) | P49: Comdty | Q49: =M49&" "&O49&" "&P49 -> IR5 Comdty | S49: =IF(ISBLANK(R49),Settings.CurveSide.MidBidAsk,'AUD CURVE TICKERS'!R49) -> PX_MID | T49: =IF(Settings.isCOBToday,_xll.BDP(Q49,'AUD CURVE TICKERS'!S49),_xll.BDH(Q49,'AUD CURVE TICKERS'!S49,Settings.COB,Settings.COB)) -> 97.875 | V49: =IF(Settings.isCOBToday,_xll.BDP(Q49,$V$52),_xll.BDH(Q49,$V$52,Settings.COB,Settings.COB)) -> 13/12/2019 | W49: =IF(Settings.isCOBToday,_xll.BDP(Q49,$V$53),_xll.BDH(Q49,$V$53,Settings.COB,Settings.COB)) -> 13/03/2020 | Y49: 5Y | Z49: ADSW5 | AB49: =IF(ISBLANK(AA49),Settings.BloombergPCS,AA49) -> IAUS | AC49: Curncy | AD49: =Z49&" "&AB49&" "&AC49 -> ADSW5 IAUS Curncy | AF49: =IF(ISBLANK(AE49),Settings.CurveSide.MidBidAsk,'AUD CURVE TICKERS'!AE49) -> PX_MID | AG49: =IF(Settings.isCOBToday,_xll.BDP(AD49,'AUD CURVE TICKERS'!AF49),_xll.BDH(AD49,'AUD CURVE TICKERS'!AF49,Settings.COB,Settings.COB)) -> 2.53125 | AI49: 5Y | AJ49: ADBBCF5 | AL49: =IF(ISBLANK(AK49),Settings.BloombergPCS,AK49) -> IAUS | AM49: Curncy | AN49: =AJ49&" "&AL49&" "&AM49 -> ADBBCF5 IAUS Curncy | AP49: =IF(ISBLANK(AO49),Settings.CurveSide.MidBidAsk,'AUD CURVE TICKERS'!AO49) -> PX_MID | AQ49: =IF(Settings.isCOBToday,_xll.BDP(AN49,'AUD CURVE TICKERS'!AP49),_xll.BDH(AN49,'AUD CURVE TICKERS'!AP49,Settings.COB,Settings.COB)) -> 14.75
...

Sheet AUD CURVE
AP1: … Curve Generator Templtes
B2: AUD OIS | AB2: AUDOIS - GENERATOR TEMPLATE | AG2: AUD3ML - GENERATOR TEMPLATE | AL2: AUD6ML - GENERATOR TEMPLATE
C4: MARKETDATAPROPERTIES | F4: OIS | L4: OISFIXINGS | R4: LIBOROISBASISSPREADS | V4: SWAPS | AC4: CREATE GENERATOR | AH4: CREATE GENERATOR | AM4: CREATE GENERATOR
F5: Term | G5: Rate | H5: StartDate | I5: EndDate | J5: Use | L5: BaseDate | M5: Rate | O5: Libor-OIS Q | P5: Basis 3X6 | R5: Term | S5: Rate | V5: Term | W5: Rate | AC5: HandleName | AD5: AUD_OIS_CURVE_GENERATOR | AH5: HandleName | AI5: AUD_3ML_CURVE_GENERATOR | AM5: HandleName | AN5: AUD_6ML_CURVE_GENERATOR
C6: Currency | D6: AUD | F6: ='AUD CURVE TICKERS'!B15 -> ON | G6: ='AUD CURVE TICKERS'!J15% -> 0.015 | J6: TRUE | O6: ='AUD CURVE TICKERS'!T15/10000 -> 0.00435 | P6: ='AUD CURVE TICKERS'!AQ45/10000 -> 0.0016125 | R6: ='AUD CURVE TICKERS'!L15 -> 1Y | S6: =O6 -> 0.00435 | T6: 3ML | V6: ='AUD CURVE TICKERS'!Y45 -> 1Y | W6: ='AUD CURVE TICKERS'!AG45% -> 0.019775 | AC6: Create Curve Generator | AD6: =_xll.meLWOCurveGeneratorCreate(AD5,AC8,AC9:AD15,AC18,AC19:AD35,AC38,AC39:AD40,AC44,AC45:AD51) -> AUD_OIS_CURVE_GENERATOR@5:3 | AH6: Create Curve Generator | AI6: =_xll.meLWOCurveGeneratorCreate(AI5,AH8,AH9:AI23,AH26,AH27:AI29,AH32,AH33:AI37,AH40,AH41:AI46,AH49,AH50:AI56,AH59,AH60:AI80,AH83,AH84:AI115) -> AUD_3ML_CURVE_GENERATOR@1:3 | AM6: Create Curve Generator | AN6: =_xll.meLWOCurveGeneratorCreate(AN5,AM8,AM9:AN23,AM26,AM27:AN29,AM32,AM33:AN37,AM40,AM41:AN46,AM59,AM60:AN73) -> AUD_6ML_CURVE_GENERATOR@2:3
C7: CurveType | D7: OIS | F7: ='AUD CURVE TICKERS'!B16 -> 1W | G7: ='AUD CURVE TICKERS'!J16% -> 0.015 | J7: TRUE | O7: ='AUD CURVE TICKERS'!T16/10000 -> 0.004225 | P7: ='AUD CURVE TICKERS'!AQ46/10000 -> 0.0015625 | R7: ='AUD CURVE TICKERS'!L16 -> 2Y | S7: =O7 -> 0.004225 | T7: 3ML | V7: ='AUD CURVE TICKERS'!Y46 -> 2Y | W7: ='AUD CURVE TICKERS'!AG46% -> 0.0208625
C8: CurveIndexFrequency | D8: DAILY | F8: ='AUD CURVE TICKERS'!B17 -> 1M | G8: ='AUD CURVE TICKERS'!J17% -> 0.015 | J8: TRUE | O8: ='AUD CURVE TICKERS'!T17/10000 -> 0.00415 | P8: ='AUD CURVE TICKERS'!AQ47/10000 -> 0.0015125 | R8: ='AUD CURVE TICKERS'!L17 -> 3Y | S8: =O8 -> 0.00415 | T8: 3ML | V8: ='AUD CURVE TICKERS'!Y47 -> 3Y | W8: ='AUD CURVE TICKERS'!AG47% -> 0.0218875 | AC8: CURVEPROPERTIES | AH8: CURVEPROPERTIES | AM8: CURVEPROPERTIES
C9: AsOfDate | D9: =Settings.COB -> 43420 | F9: ='AUD CURVE TICKERS'!B18 -> 2M | G9: ='AUD CURVE TICKERS'!J18% -> 0.015 | J9: TRUE | O9: ='AUD CURVE TICKERS'!T18/10000 -> 0.00415 | P9: ='AUD CURVE TICKERS'!AQ48/10000 -> 0.0015 | R9: ='AUD CURVE TICKERS'!L18 -> 4Y | S9: =O9+P9 -> 0.00565 | T9: 6ML | V9: ='AUD CURVE TICKERS'!Y48 -> 4Y | W9: ='AUD CURVE TICKERS'!AG48% -> 0.0244 | AC9: CurveType | AD9: OIS | AH9: CurveType | AI9: SWAP | AM9: CurveType | AN9: SWAP
F10: ='AUD CURVE TICKERS'!B19 -> 3M | G10: ='AUD CURVE TICKERS'!J19% -> 0.015005 | J10: TRUE | O10: ='AUD CURVE TICKERS'!T19/10000 -> 0.00415 | P10: ='AUD CURVE TICKERS'!AQ49/10000 -> 0.001475 | R10: ='AUD CURVE TICKERS'!L19 -> 5Y | S10: =O10+P10 -> 0.005625 | T10: 6ML | V10: ='AUD CURVE TICKERS'!Y49 -> 5Y | W10: ='AUD CURVE TICKERS'!AG49% -> 0.0253125 | AC10: CurveIndexFrequency | AD10: DAILY | AH10: CurveIndexFrequency | AI10: QUARTERLY | AM10: CurveIndexFrequency | AN10: SEMI-ANNUAL
F11: ='AUD CURVE TICKERS'!B20 -> 4M | G11: ='AUD CURVE TICKERS'!J20% -> 0.01502 | J11: TRUE | O11: ='AUD CURVE TICKERS'!T20/10000 -> 0.0041625 | P11: ='AUD CURVE TICKERS'!AQ50/10000 -> 0.001425 | R11: ='AUD CURVE TICKERS'!L20 -> 6Y | S11: =O11+P11 -> 0.0055875 | T11: 6ML | V11: ='AUD CURVE TICKERS'!Y50 -> 6Y | W11: ='AUD CURVE TICKERS'!AG50% -> 0.0261625 | AC11: StaticDataTable | AD11: OIS | AH11: StaticDataTable | AI11: STD | AM11: StaticDataTable | AN11: AUD6ML
C12: Create Market Data Handle | F12: ='AUD CURVE TICKERS'!B21 -> 5M | G12: ='AUD CURVE TICKERS'!J21% -> 0.0150375 | J12: TRUE | O12: ='AUD CURVE TICKERS'!T21/10000 -> 0.004175 | P12: ='AUD CURVE TICKERS'!AQ51/10000 -> 0.001375 | R12: ='AUD CURVE TICKERS'!L21 -> 7Y | S12: =O12+P12 -> 0.00555 | T12: 6ML | V12: ='AUD CURVE TICKERS'!Y51 -> 7Y | W12: ='AUD CURVE TICKERS'!AG51% -> 0.026925 | AC12: IndexName | AD12: OIS:AUDOIS:AUDDF:AUDDF_AUDCSA:AUDDF_NOCSA | AH12: IndexName | AI12: STD:AUD3ML | AM12: IndexName | AN12: AUD6ML
C13: Handle Name | D13: AUD_OIS_CURVE_MARKETDATA | F13: ='AUD CURVE TICKERS'!B22 -> 6M | G13: ='AUD CURVE TICKERS'!J22% -> 0.01508 | J13: TRUE | O13: ='AUD CURVE TICKERS'!T22/10000 -> 0.004175 | P13: ='AUD CURVE TICKERS'!AQ52/10000 -> 0.0013125 | R13: ='AUD CURVE TICKERS'!L22 -> 8Y | S13: =O13+P13 -> 0.0054875 | T13: 6ML | V13: ='AUD CURVE TICKERS'!Y52 -> 8Y | W13: ='AUD CURVE TICKERS'!AG52% -> 0.0276 | AC13: Currency | AD13: AUD | AH13: Currency | AI13: AUD | AM13: Currency | AN13: AUD
C14: Market Data Handle | D14: =_xll.meLWOCurveMarketDataCreate(D13,C4,C6:D9,F4,F6:J31,L4,L6:M31,R4,R6:S31,V4,V6:W31) -> AUD_OIS_CURVE_MARKETDATA@63:3 | F14: ='AUD CURVE TICKERS'!B23 -> 9M | G14: ='AUD CURVE TICKERS'!J23% -> 0.015225 | J14: TRUE | O14: ='AUD CURVE TICKERS'!T23/10000 -> 0.004175 | P14: ='AUD CURVE TICKERS'!AQ53/10000 -> 0.0012625 | R14: ='AUD CURVE TICKERS'!L23 -> 9Y | S14: =O14+P14 -> 0.0054375 | T14: 6ML | V14: ='AUD CURVE TICKERS'!Y53 -> 9Y | W14: ='AUD CURVE TICKERS'!AG53% -> 0.0281875 | AC14: interpolation | AD14: FN_SPLINEINTERPOLATION | AH14: interpolation | AI14: =IF(Settings.SwapCurve.Interpolation="LINEAR-SPLINE","FN_LINEARSPLINEINTERPOLATION","FN_SPLINEINTERPOLATION") -> FN_SPLINEINTERPOLATION | AM14: interpolation | AN14: =IF(Settings.SwapCurve.Interpolation="LINEAR-SPLINE","FN_LINEARSPLINEINTERPOLATION","FN_SPLINEINTERPOLATION") -> FN_SPLINEINTERPOLATION
F15: ='AUD CURVE TICKERS'!B24 -> 1Y | G15: ='AUD CURVE TICKERS'!J24% -> 0.015475 | J15: TRUE | O15: ='AUD CURVE TICKERS'!T24/10000 -> 0.0041625 | P15: ='AUD CURVE TICKERS'!AQ54/10000 -> 0.0012 | R15: ='AUD CURVE TICKERS'!L24 -> 10Y | S15: =O15+P15 -> 0.0053625 | T15: 6ML | V15: ='AUD CURVE TICKERS'!Y54 -> 10Y | W15: ='AUD CURVE TICKERS'!AG54% -> 0.0287125 | AC15: yieldgen.interpolation | AD15: FN_SPLINEINTERPOLATION | AH15: yieldgen.interpolation | AI15: =IF(Settings.SwapCurve.Interpolation="LINEAR-SPLINE","FN_LINEARSPLINEINTERPOLATION","FN_SPLINEINTERPOLATION") -> FN_SPLINEINTERPOLATION | AM15: yieldgen.interpolation | AN15: =IF(Settings.SwapCurve.Interpolation="LINEAR-SPLINE","FN_LINEARSPLINEINTERPOLATION","FN_SPLINEINTERPOLATION") -> FN_SPLINEINTERPOLATION
F16: ='AUD CURVE TICKERS'!B25 -> 2Y | G16: ='AUD CURVE TICKERS'!J25% -> 0.01675 | J16: TRUE | O16: ='AUD CURVE TICKERS'!T25/10000 -> 0.0042 | P16: ='AUD CURVE TICKERS'!AQ55/10000 -> 0.00105 | R16: ='AUD CURVE TICKERS'!L25 -> 15Y | S16: =O16+P16 -> 0.00525 | T16: 6ML | V16: ='AUD CURVE TICKERS'!Y55 -> 15Y | W16: ='AUD CURVE TICKERS'!AG55% -> 0.0305875 | AH16: isfrause | AI16: FALSE | AM16: isfraUse | AN16: TRUE
F17: ='AUD CURVE TICKERS'!B26 -> 3Y | G17: ='AUD CURVE TICKERS'!J26% -> 0.01785 | J17: TRUE | O17: ='AUD CURVE TICKERS'!T26/10000 -> 0.004225 | P17: ='AUD CURVE TICKERS'!AQ56/10000 -> 0.0010375 | R17: ='AUD CURVE TICKERS'!L26 -> 20Y | S17: =O17+P17 -> 0.0052625 | T17: 6ML | V17: ='AUD CURVE TICKERS'!Y56 -> 20Y | W17: ='AUD CURVE TICKERS'!AG56% -> 0.0312625 | AH17: isfutureuse | AI17: TRUE | AM17: isfutureUse | AN17: FALSE
F18: ='AUD CURVE TICKERS'!B27 -> 4Y | G18: ='AUD CURVE TICKERS'!J27% -> 0.01883 | J18: TRUE | O18: ='AUD CURVE TICKERS'!T27/10000 -> 0.0042625 | P18: ='AUD CURVE TICKERS'!AQ57/10000 -> 0.0010625 | R18: ='AUD CURVE TICKERS'!L27 -> 25Y | S18: =O18+P18 -> 0.005325 | T18: 6ML | V18: ='AUD CURVE TICKERS'!Y57 -> 25Y | W18: ='AUD CURVE TICKERS'!AG57% -> 0.0313625 | AC18: OIS | AH18: future.interpolation | AI18: =IF(Settings.SwapCurve.Interpolation="LINEAR-SPLINE","FN_LINEARSPLINEINTERPOLATION","FN_LINEARINTERPOLATION") -> FN_LINEARINTERPOLATION | AM18: future.interpolation | AN18: =IF(Settings.SwapCurve.Interpolation="LINEAR-SPLINE","FN_LINEARSPLINEINTERPOLATION","FN_LINEARINTERPOLATION") -> FN_LINEARINTERPOLATION
C19: Curve Dictionary | F19: ='AUD CURVE TICKERS'!B28 -> 5Y | G19: ='AUD CURVE TICKERS'!J28% -> 0.01978 | J19: TRUE | O19: ='AUD CURVE TICKERS'!T28/10000 -> 0.0043 | P19: ='AUD CURVE TICKERS'!AQ58/10000 -> 0.0010625 | R19: ='AUD CURVE TICKERS'!L28 -> 30Y | S19: =O19+P19 -> 0.0053625 | T19: 6ML | V19: ='AUD CURVE TICKERS'!Y58 -> 30Y | W19: ='AUD CURVE TICKERS'!AG58% -> 0.0310375 | AC19: calendar | AD19: SYB:LNB | AH19: Frequency | AI19: SIMPLE | AM19: Frequency | AN19: SIMPLE
C20: Handle Name | D20: AUD_OIS_CURVE | F20: ='AUD CURVE TICKERS'!B29 -> 6Y | G20: ='AUD CURVE TICKERS'!J29% -> 0.02063 | J20: TRUE | R20: 40Y | S20: =S19 -> 0.0053625 | T20: Extrapolation | V20: 40Y | W20: =W19 -> 0.0310375 | X20: Extrapolation | AC20: daycount | AD20: ACT/365 | AH20: dfcurvename | AI20: OIS | AM20: dfcurvename | AN20: OIS
C21: Curve Generator | D21: =$AD$6 -> AUD_OIS_CURVE_GENERATOR@5:3 | F21: ='AUD CURVE TICKERS'!B30 -> 7Y | G21: ='AUD CURVE TICKERS'!J30% -> 0.02148 | J21: TRUE | R21: 50Y | S21: =S20 -> 0.0053625 | T21: Extrapolation | V21: 50Y | W21: =W20 -> 0.0310375 | X21: Extrapolation | AC21: frequency | AD21: ANNUAL | AH21: IsSwapTenorAdjust | AI21: TRUE | AM21: IsSwapTenorAdjust | AN21: FALSE
C22: Domestic Curve Collection | D22: AUDYC | F22: ='AUD CURVE TICKERS'!B31 -> 8Y | G22: ='AUD CURVE TICKERS'!J31% -> 0.02215 | J22: TRUE | AC22: generatemethod | AD22: DAILYCOMPOUNDING | AH22: TenorSwapName | AI22: 3M6MBasis | AM22: FastRebuild | AN22: TRUE
C23: Foreign Curve Collection | F23: ='AUD CURVE TICKERS'!B32 -> 9Y | G23: ='AUD CURVE TICKERS'!J32% -> 0.0228 | J23: TRUE | AC23: resetlag | AD23: 1D | AH23: FastRebuild | AI23: TRUE
F24: ='AUD CURVE TICKERS'!B33 -> 10Y | G24: ='AUD CURVE TICKERS'!J33% -> 0.02348 | J24: TRUE | AC24: firstrate | AD24: SHORTMARKET
F25: ='AUD CURVE TICKERS'!B34 -> 15Y | G25: ='AUD CURVE TICKERS'!J34% -> 0.02548 | J25: TRUE | AC25: slidingrule | AD25: MOD_FOLLOWING
C26: Curve Build | F26: ='AUD CURVE TICKERS'!B35 -> 20Y | G26: ='AUD CURVE TICKERS'!J35% -> 0.02615 | J26: TRUE | AC26: eomday | AD26: 31 | AH26: MONEYMARKET | AM26: MONEYMARKET
C27: Handle Name | D27: {=_xll.meLWOCurveCalibrate(D20,D21,D14,D22,D23)} -> AUD_OIS_CURVE@64:3 | F27: ='AUD CURVE TICKERS'!B36 -> 25Y | G27: ='AUD CURVE TICKERS'!J36% -> 0.0262 | J27: TRUE | AC27: iseomroll | AD27: TRUE | AH27: Calendar | AI27: SYB:LnB | AM27: Calendar | AN27: SYB:LnB
C28: Curve Collection | D28: AUDYC | F28: ='AUD CURVE TICKERS'!B37 -> 30Y | G28: ='AUD CURVE TICKERS'!J37% -> 0.02583 | J28: TRUE | AC28: shorttermconvention | AD28: ARITHMETICAVERAGE | AH28: DayCount | AI28: ACT/365 | AM28: DayCount | AN28: ACT/365
C29: Curve Index | D29: OIS:AUDOIS:AUDDF:AUDDF_AUDCSA:AUDDF_NOCSA | AC29: longtermconvention | AD29: LOBASIS | AH29: Slidingrule | AI29: FOLLOWING | AM29: Slidingrule | AN29: FOLLOWING
C30: Calibration Time Taken | D30: 0.01500 sec | AC30: longterm | AD30: 3Y
C31: Curve Loaded | D31: =LEFT($D$27,3)=LEFT($D$20,3) -> TRUE | AC31: longterm.generatemethod | AD31: NONE
AC32: Epsilon | AD32: 1e-10 | AH32: LIBORFIXINGS | AM32: LIBORFIXINGS
AC33: MaxLoop | AD33: 1000 | AH33: Calendar | AI33: SYB:LnB | AM33: Calendar | AN33: SYB:LnB
AC34: CompoundingMethod | AD34: GEOMETRIC | AH34: Daycount | AI34: ACT/365 | AM34: Daycount | AN34: ACT/365
B35: AUD 3ML | AC35: SmoothShortEnd | AD35: FALSE | AH35: Frequency | AI35: Simple | AM35: Frequency | AN35: Simple
AH36: Resetlag | AI36: 0 | AM36: Resetlag | AN36: 0
C37: MARKETDATAPROPERTIES | F37: LIBORFIXINGS | I37: FRAS | L37: FUTURES | R37: SWAPS | V37: BASISSWAPS | AH37: SlidingRule | AI37: MOD_FOLLOWING | AM37: SlidingRule | AN37: MOD_FOLLOWING
C38: Currency | D38: AUD | F38: Term | G38: Rate | I38: Term | J38: Rate | L38: Term | M38: StartDate | N38: EndDate | O38: Rate | P38: Volatility | R38: Term | S38: Rate | T38: Use | V38: Term | W38: Rate | X38: Use | AC38: LIBOROISBASIS | AD38: OIS FLOAT LEG CONVENTIONS
C39: CurveType | D39: SWAP | F39: ='AUD CURVE TICKERS'!B46 -> 3M | G39: ='AUD CURVE TICKERS'!J46% -> 0.0193 | L39: ='AUD CURVE TICKERS'!L45 -> IR1 | M39: ='AUD CURVE TICKERS'!V45 -> 14/12/2018 | N39: ='AUD CURVE TICKERS'!W45 -> 08/03/2019 | O39: ='AUD CURVE TICKERS'!T45 -> 98.025 | P39: =Settings.Futures.Convexity.HW1F.Vol -> 0.02 | R39: ='AUD CURVE TICKERS'!Y46 -> 2Y | S39: ='AUD CURVE TICKERS'!AG46% -> 0.0208625 | T39: TRUE | V39: ='AUD CURVE TICKERS'!AI46 -> 2Y | W39: ='AUD CURVE TICKERS'!AQ46/10000 -> 0.0015625 | X39: TRUE | AC39: frequency | AD39: ANNUAL
C40: CurveIndexFrequency | D40: QUARTERLY | L40: ='AUD CURVE TICKERS'!L46 -> IR2 | M40: ='AUD CURVE TICKERS'!V46 -> 08/03/2019 | N40: ='AUD CURVE TICKERS'!W46 -> 14/06/2019 | O40: ='AUD CURVE TICKERS'!T46 -> 98.045 | P40: =Settings.Futures.Convexity.HW1F.Vol -> 0.02 | R40: ='AUD CURVE TICKERS'!Y47 -> 3Y | S40: ='AUD CURVE TICKERS'!AG47% -> 0.0218875 | T40: TRUE | V40: ='AUD CURVE TICKERS'!AI47 -> 3Y | W40: ='AUD CURVE TICKERS'!AQ47/10000 -> 0.0015125 | X40: TRUE | AC40: slidingRule | AD40: MOD_FOLLOWING | AH40: FRAS | AM40: FRAS
C41: AsOfDate | D41: =Settings.COB -> 43420 | L41: ='AUD CURVE TICKERS'!L47 -> IR3 | M41: ='AUD CURVE TICKERS'!V47 -> 14/06/2019 | N41: ='AUD CURVE TICKERS'!W47 -> 13/09/2019 | O41: ='AUD CURVE TICKERS'!T47 -> 98.005 | P41: =Settings.Futures.Convexity.HW1F.Vol -> 0.02 | R41: ='AUD CURVE TICKERS'!Y48 -> 4Y | S41: ='AUD CURVE TICKERS'!AG48% -> 0.0244 | T41: TRUE | V41: ='AUD CURVE TICKERS'!AI48 -> 4Y | W41: ='AUD CURVE TICKERS'!AQ48/10000 -> 0.0015 | X41: TRUE | AH41: Calendar | AI41: SYB:LnB | AM41: Calendar | AN41: SYB:LnB
...

Sheet AUD REPRICING
B2: Trade Dates | E2: SWAPS: AUDOIS
C3: Unadjusted
B4: EffectiveDate | C4: MaturityDate | E4: EffectiveDate | F4: Maturity | G4: Generator | H4: PayRec | I4: Notional | J4: FixedRate | K4: Spread | M4: CreateSwap | N4: CurveCollection | O4: ParRate | P4: Curve | Q4: +/- (Bps)
B5: =_xll.meDateFromTenor(Settings.COB,E5,"MOD_FOLLOWING","SYB:LNB","") -> 43423 | C5: =_xll.meDateFromTenor(B5,F5,) -> 43430 | E5: 1D | F5: 1W | G5: AUD_OIS | H5: PAY | I5: 1000000 | J5: 0.01 | K5: 0 | L5: 1 | M5: =_xll.meLWOSwapCreateFromGenerator("AUDOIS"&L5,G5,H5,I5,B5,C5,J5,K5,,,,,Settings.AllowCalibrationUpdates) -> AUDOIS1@15:0 | N5: AUDYC | O5: =_xll.meLWOSwapParRate(M5,N5) -> 0.015 | P5: ='AUD CURVE'!G7 -> 0.015 | Q5: =(O5-P5)*10000 -> -1.0533383e-07
B6: =_xll.meDateFromTenor(Settings.COB,E6,"MOD_FOLLOWING","SYB:LNB","") -> 43423 | C6: =_xll.meDateFromTenor(B6,F6,) -> 43453 | E6: 1D | F6: 1M | G6: AUD_OIS | H6: PAY | I6: 1000000 | J6: 0.01 | K6: 0 | L6: 2 | M6: =_xll.meLWOSwapCreateFromGenerator("AUDOIS"&L6,G6,H6,I6,B6,C6,J6,K6,,,,,Settings.AllowCalibrationUpdates) -> AUDOIS2@27:0 | N6: AUDYC | O6: =_xll.meLWOSwapParRate(M6,N6) -> 0.015 | P6: ='AUD CURVE'!G8 -> 0.015 | Q6: =(O6-P6)*10000 -> -8.2899486e-08
B7: =_xll.meDateFromTenor(Settings.COB,E7,"MOD_FOLLOWING","SYB:LNB","") -> 43423 | C7: =_xll.meDateFromTenor(B7,F7,) -> 43484 | E7: 1D | F7: 2M | G7: AUD_OIS | H7: PAY | I7: 1000000 | J7: 0.01 | K7: 0 | L7: 3 | M7: =_xll.meLWOSwapCreateFromGenerator("AUDOIS"&L7,G7,H7,I7,B7,C7,J7,K7,,,,,Settings.AllowCalibrationUpdates) -> AUDOIS3@12:0 | N7: AUDYC | O7: =_xll.meLWOSwapParRate(M7,N7) -> 0.015 | P7: ='AUD CURVE'!G9 -> 0.015 | Q7: =(O7-P7)*10000 -> -5.9754892e-08
B8: =_xll.meDateFromTenor(Settings.COB,E8,"MOD_FOLLOWING","SYB:LNB","") -> 43423 | C8: =_xll.meDateFromTenor(B8,F8,) -> 43515 | E8: 1D | F8: 3M | G8: AUD_OIS | H8: PAY | I8: 1000000 | J8: 0.01 | K8: 0 | L8: 4 | M8: =_xll.meLWOSwapCreateFromGenerator("AUDOIS"&L8,G8,H8,I8,B8,C8,J8,K8,,,,,Settings.AllowCalibrationUpdates) -> AUDOIS4@25:0 | N8: AUDYC | O8: =_xll.meLWOSwapParRate(M8,N8) -> 0.015005 | P8: ='AUD CURVE'!G10 -> 0.015005 | Q8: =(O8-P8)*10000 -> -2.4258217e-08
B9: =_xll.meDateFromTenor(Settings.COB,E9,"MOD_FOLLOWING","SYB:LNB","") -> 43423 | C9: =_xll.meDateFromTenor(B9,F9,) -> 43543 | E9: 1D | F9: 4M | G9: AUD_OIS | H9: PAY | I9: 1000000 | J9: 0.01 | K9: 0 | L9: 5 | M9: =_xll.meLWOSwapCreateFromGenerator("AUDOIS"&L9,G9,H9,I9,B9,C9,J9,K9,,,,,Settings.AllowCalibrationUpdates) -> AUDOIS5@4:0 | N9: AUDYC | O9: =_xll.meLWOSwapParRate(M9,N9) -> 0.01502 | P9: ='AUD CURVE'!G11 -> 0.01502 | Q9: =(O9-P9)*10000 -> 7.4772202e-08
B10: =_xll.meDateFromTenor(Settings.COB,E10,"MOD_FOLLOWING","SYB:LNB","") -> 43423 | C10: =_xll.meDateFromTenor(B10,F10,) -> 43574 | E10: 1D | F10: 5M | G10: AUD_OIS | H10: PAY | I10: 1000000 | J10: 0.01 | K10: 0 | L10: 6 | M10: =_xll.meLWOSwapCreateFromGenerator("AUDOIS"&L10,G10,H10,I10,B10,C10,J10,K10,,,,,Settings.AllowCalibrationUpdates) -> AUDOIS6@29:0 | N10: AUDYC | O10: =_xll.meLWOSwapParRate(M10,N10) -> 0.0150375 | P10: ='AUD CURVE'!G12 -> 0.0150375 | Q10: =(O10-P10)*10000 -> -6.97074e-08
B11: =_xll.meDateFromTenor(Settings.COB,E11,"MOD_FOLLOWING","SYB:LNB","") -> 43423 | C11: =_xll.meDateFromTenor(B11,F11,) -> 43604 | E11: 1D | F11: 6M | G11: AUD_OIS | H11: PAY | I11: 1000000 | J11: 0.01 | K11: 0 | L11: 7 | M11: =_xll.meLWOSwapCreateFromGenerator("AUDOIS"&L11,G11,H11,I11,B11,C11,J11,K11,,,,,Settings.AllowCalibrationUpdates) -> AUDOIS7@3:0 | N11: AUDYC | O11: =_xll.meLWOSwapParRate(M11,N11) -> 0.01508 | P11: ='AUD CURVE'!G13 -> 0.01508 | Q11: =(O11-P11)*10000 -> -1.0074407e-09
B12: =_xll.meDateFromTenor(Settings.COB,E12,"MOD_FOLLOWING","SYB:LNB","") -> 43423 | C12: =_xll.meDateFromTenor(B12,F12,) -> 43696 | E12: 1D | F12: 9M | G12: AUD_OIS | H12: PAY | I12: 1000000 | J12: 0.01 | K12: 0 | L12: 8 | M12: =_xll.meLWOSwapCreateFromGenerator("AUDOIS"&L12,G12,H12,I12,B12,C12,J12,K12,,,,,Settings.AllowCalibrationUpdates) -> AUDOIS8@22:0 | N12: AUDYC | O12: =_xll.meLWOSwapParRate(M12,N12) -> 0.015225 | P12: ='AUD CURVE'!G14 -> 0.015225 | Q12: =(O12-P12)*10000 -> 2.8729987e-08
B13: =_xll.meDateFromTenor(Settings.COB,E13,"MOD_FOLLOWING","SYB:LNB","") -> 43423 | C13: =_xll.meDateFromTenor(B13,F13,) -> 43788 | E13: 1D | F13: 1Y | G13: AUD_OIS | H13: PAY | I13: 1000000 | J13: 0.01 | K13: 0 | L13: 9 | M13: =_xll.meLWOSwapCreateFromGenerator("AUDOIS"&L13,G13,H13,I13,B13,C13,J13,K13,,,,,Settings.AllowCalibrationUpdates) -> AUDOIS9@26:0 | N13: AUDYC | O13: =_xll.meLWOSwapParRate(M13,N13) -> 0.015475 | P13: ='AUD CURVE'!G15 -> 0.015475 | Q13: =(O13-P13)*10000 -> -1.2136124e-07
B14: =_xll.meDateFromTenor(Settings.COB,E14,"MOD_FOLLOWING","SYB:LNB","") -> 43423 | C14: =_xll.meDateFromTenor(B14,F14,) -> 44154 | E14: 1D | F14: 2Y | G14: AUD_OIS | H14: PAY | I14: 1000000 | J14: 0.01 | K14: 0 | L14: 10 | M14: =_xll.meLWOSwapCreateFromGenerator("AUDOIS"&L14,G14,H14,I14,B14,C14,J14,K14,,,,,Settings.AllowCalibrationUpdates) -> AUDOIS10@11:0 | N14: AUDYC | O14: =_xll.meLWOSwapParRate(M14,N14) -> 0.01675 | P14: ='AUD CURVE'!G16 -> 0.01675 | Q14: =(O14-P14)*10000 -> -1.7674414e-07
B17: Trade Dates | E17: SWAPS:AUD3ML/AUD6ML
C18: Unadjusted
B19: EffectiveDate | C19: MaturityDate | E19: EffectiveDate | F19: Maturity | G19: Generator | H19: PayRec | I19: Notional | J19: FixedRate | K19: Spread | M19: CreateSwap | N19: CurveCollection | O19: ParRate | P19: Curve | Q19: +/- (Bps)
B20: =_xll.meDateFromTenor(Settings.COB,E20,"MOD_FOLLOWING","SYB:LNB","") -> 43423 | C20: =_xll.meDateFromTenor(B20,F20,) -> 44154 | E20: 1D | F20: 2Y | G20: AUD_3ML | H20: PAY | I20: 1000000 | J20: 0.01 | K20: 0 | L20: 1 | M20: =_xll.meLWOSwapCreateFromGenerator("AUDIRS"&L20,G20,H20,I20,B20,C20,J20,K20,,,,,Settings.AllowCalibrationUpdates) -> AUDIRS1@6:0 | N20: AUDYC | O20: =_xll.meLWOSwapParRate(M20,N20) -> 0.0208625 | P20: ='AUD CURVE'!S39 -> 0.0208625 | Q20: =(O20-P20)*10000 -> 3.1225023e-13
B21: =_xll.meDateFromTenor(Settings.COB,E21,"MOD_FOLLOWING","SYB:LNB","") -> 43423 | C21: =_xll.meDateFromTenor(B21,F21,) -> 44519 | E21: 1D | F21: 3Y | G21: AUD_3ML | H21: PAY | I21: 1000000 | J21: 0.01 | K21: 0 | L21: 2 | M21: =_xll.meLWOSwapCreateFromGenerator("AUDIRS"&L21,G21,H21,I21,B21,C21,J21,K21,,,,,Settings.AllowCalibrationUpdates) -> AUDIRS2@30:0 | N21: AUDYC | O21: =_xll.meLWOSwapParRate(M21,N21) -> 0.0218875 | P21: ='AUD CURVE'!S40 -> 0.0218875 | Q21: =(O21-P21)*10000 -> -6.9388939e-14
B22: =_xll.meDateFromTenor(Settings.COB,E22,"MOD_FOLLOWING","SYB:LNB","") -> 43423 | C22: =_xll.meDateFromTenor(B22,F22,) -> 43788 | E22: 1D | F22: 1Y | G22: AUD_6ML | H22: PAY | I22: 1000000 | J22: 0.01 | K22: 0 | L22: 3 | M22: =_xll.meLWOSwapCreateFromGenerator("AUDIRS"&L22,G22,H22,I22,B22,C22,J22,K22,,,,,Settings.AllowCalibrationUpdates) -> AUDIRS3@18:0 | N22: AUDYC | O22: =_xll.meLWOSwapParRate(M22,N22) -> 0.02145 | P22: ='AUD CURVE'!S73 -> 0.02145 | Q22: =(O22-P22)*10000 -> 1.700029e-12
B23: =_xll.meDateFromTenor(Settings.COB,E23,"MOD_FOLLOWING","SYB:LNB","") -> 43423 | C23: =_xll.meDateFromTenor(B23,F23,) -> 44154 | E23: 1D | F23: 2Y | G23: AUD_6ML | H23: PAY | I23: 1000000 | J23: 0.01 | K23: 0 | L23: 4 | M23: =_xll.meLWOSwapCreateFromGenerator("AUDIRS"&L23,G23,H23,I23,B23,C23,J23,K23,,,,,Settings.AllowCalibrationUpdates) -> AUDIRS4@13:0 | N23: AUDYC | O23: =_xll.meLWOSwapParRate(M23,N23) -> 0.02247 | P23: ='AUD CURVE'!S74 -> 0.02247 | Q23: =(O23-P23)*10000 -> 4.510281e-13
B24: =_xll.meDateFromTenor(Settings.COB,E24,"MOD_FOLLOWING","SYB:LNB","") -> 43423 | C24: =_xll.meDateFromTenor(B24,F24,) -> 44519 | E24: 1D | F24: 3Y | G24: AUD_6ML | H24: PAY | I24: 1000000 | J24: 0.01 | K24: 0 | L24: 5 | M24: =_xll.meLWOSwapCreateFromGenerator("AUDIRS"&L24,G24,H24,I24,B24,C24,J24,K24,,,,,Settings.AllowCalibrationUpdates) -> AUDIRS5@7:0 | N24: AUDYC | O24: =_xll.meLWOSwapParRate(M24,N24) -> 0.02345 | P24: ='AUD CURVE'!S75 -> 0.02345 | Q24: =(O24-P24)*10000 -> 1.5265567e-12
B25: =_xll.meDateFromTenor(Settings.COB,E25,"MOD_FOLLOWING","SYB:LNB","") -> 43423 | C25: =_xll.meDateFromTenor(B25,F25,) -> 44884 | E25: 1D | F25: 4Y | G25: AUD_6ML | H25: PAY | I25: 1000000 | J25: 0.01 | K25: 0 | L25: 6 | M25: =_xll.meLWOSwapCreateFromGenerator("AUDIRS"&L25,G25,H25,I25,B25,C25,J25,K25,,,,,Settings.AllowCalibrationUpdates) -> AUDIRS6@8:0 | N25: AUDYC | O25: =_xll.meLWOSwapParRate(M25,N25) -> 0.0244 | P25: ='AUD CURVE'!S76 -> 0.0244 | Q25: =(O25-P25)*10000 -> 1.3530843e-12
B26: =_xll.meDateFromTenor(Settings.COB,E26,"MOD_FOLLOWING","SYB:LNB","") -> 43423 | C26: =_xll.meDateFromTenor(B26,F26,) -> 45249 | E26: 1D | F26: 5Y | G26: AUD_6ML | H26: PAY | I26: 1000000 | J26: 0.01 | K26: 0 | L26: 7 | M26: =_xll.meLWOSwapCreateFromGenerator("AUDIRS"&L26,G26,H26,I26,B26,C26,J26,K26,,,,,Settings.AllowCalibrationUpdates) -> AUDIRS7@19:0 | N26: AUDYC | O26: =_xll.meLWOSwapParRate(M26,N26) -> 0.0253125 | P26: ='AUD CURVE'!S77 -> 0.0253125 | Q26: =(O26-P26)*10000 -> 1.7694179e-12
B27: =_xll.meDateFromTenor(Settings.COB,E27,"MOD_FOLLOWING","SYB:LNB","") -> 43423 | C27: =_xll.meDateFromTenor(B27,F27,) -> 45615 | E27: 1D | F27: 6Y | G27: AUD_6ML | H27: PAY | I27: 1000000 | J27: 0.01 | K27: 0 | L27: 8 | M27: =_xll.meLWOSwapCreateFromGenerator("AUDIRS"&L27,G27,H27,I27,B27,C27,J27,K27,,,,,Settings.AllowCalibrationUpdates) -> AUDIRS8@9:0 | N27: AUDYC | O27: =_xll.meLWOSwapParRate(M27,N27) -> 0.0261625 | P27: ='AUD CURVE'!S78 -> 0.0261625 | Q27: =(O27-P27)*10000 -> 1.4571677e-12
B28: =_xll.meDateFromTenor(Settings.COB,E28,"MOD_FOLLOWING","SYB:LNB","") -> 43423 | C28: =_xll.meDateFromTenor(B28,F28,) -> 45980 | E28: 1D | F28: 7Y | G28: AUD_6ML | H28: PAY | I28: 1000000 | J28: 0.01 | K28: 0 | L28: 9 | M28: =_xll.meLWOSwapCreateFromGenerator("AUDIRS"&L28,G28,H28,I28,B28,C28,J28,K28,,,,,Settings.AllowCalibrationUpdates) -> AUDIRS9@28:0 | N28: AUDYC | O28: =_xll.meLWOSwapParRate(M28,N28) -> 0.026925 | P28: ='AUD CURVE'!S79 -> 0.026925 | Q28: =(O28-P28)*10000 -> 1.4571677e-12
B29: =_xll.meDateFromTenor(Settings.COB,E29,"MOD_FOLLOWING","SYB:LNB","") -> 43423 | C29: =_xll.meDateFromTenor(B29,F29,) -> 46345 | E29: 1D | F29: 8Y | G29: AUD_6ML | H29: PAY | I29: 1000000 | J29: 0.01 | K29: 0 | L29: 10 | M29: =_xll.meLWOSwapCreateFromGenerator("AUDIRS"&L29,G29,H29,I29,B29,C29,J29,K29,,,,,Settings.AllowCalibrationUpdates) -> AUDIRS10@16:0 | N29: AUDYC | O29: =_xll.meLWOSwapParRate(M29,N29) -> 0.0276 | P29: ='AUD CURVE'!S80 -> 0.0276 | Q29: =(O29-P29)*10000 -> 1.0408341e-12
B30: =_xll.meDateFromTenor(Settings.COB,E30,"MOD_FOLLOWING","SYB:LNB","") -> 43423 | C30: =_xll.meDateFromTenor(B30,F30,) -> 46710 | E30: 1D | F30: 9Y | G30: AUD_6ML | H30: PAY | I30: 1000000 | J30: 0.01 | K30: 0 | L30: 11 | M30: =_xll.meLWOSwapCreateFromGenerator("AUDIRS"&L30,G30,H30,I30,B30,C30,J30,K30,,,,,Settings.AllowCalibrationUpdates) -> AUDIRS11@17:0 | N30: AUDYC | O30: =_xll.meLWOSwapParRate(M30,N30) -> 0.0281875 | P30: ='AUD CURVE'!S81 -> 0.0281875 | Q30: =(O30-P30)*10000 -> 1.1449175e-12
B31: =_xll.meDateFromTenor(Settings.COB,E31,"MOD_FOLLOWING","SYB:LNB","") -> 43423 | C31: =_xll.meDateFromTenor(B31,F31,) -> 47076 | E31: 1D | F31: 10Y | G31: AUD_6ML | H31: PAY | I31: 1000000 | J31: 0.01 | K31: 0 | L31: 12 | M31: =_xll.meLWOSwapCreateFromGenerator("AUDIRS"&L31,G31,H31,I31,B31,C31,J31,K31,,,,,Settings.AllowCalibrationUpdates) -> AUDIRS12@24:0 | N31: AUDYC | O31: =_xll.meLWOSwapParRate(M31,N31) -> 0.0287125 | P31: ='AUD CURVE'!S82 -> 0.0287125 | Q31: =(O31-P31)*10000 -> 1.0408341e-12
B32: =_xll.meDateFromTenor(Settings.COB,E32,"MOD_FOLLOWING","SYB:LNB","") -> 43423 | C32: =_xll.meDateFromTenor(B32,F32,) -> 47806 | E32: 1D | F32: 12Y | G32: AUD_6ML | H32: PAY | I32: 1000000 | J32: 0.01 | K32: 0 | L32: 13 | M32: =_xll.meLWOSwapCreateFromGenerator("AUDIRS"&L32,G32,H32,I32,B32,C32,J32,K32,,,,,Settings.AllowCalibrationUpdates) -> AUDIRS13@10:0 | N32: AUDYC | O32: =_xll.meLWOSwapParRate(M32,N32) -> 0.0296375 | P32: ='AUD CURVE'!S83 -> 0.0296375 | Q32: =(O32-P32)*10000 -> 1.0755286e-12
B33: =_xll.meDateFromTenor(Settings.COB,E33,"MOD_FOLLOWING","SYB:LNB","") -> 43423 | C33: =_xll.meDateFromTenor(B33,F33,) -> 48902 | E33: 1D | F33: 15Y | G33: AUD_6ML | H33: PAY | I33: 1000000 | J33: 0.01 | K33: 0 | L33: 14 | M33: =_xll.meLWOSwapCreateFromGenerator("AUDIRS"&L33,G33,H33,I33,B33,C33,J33,K33,,,,,Settings.AllowCalibrationUpdates) -> AUDIRS14@23:0 | N33: AUDYC | O33: =_xll.meLWOSwapParRate(M33,N33) -> 0.0305875 | P33: ='AUD CURVE'!S84 -> 0.0305875 | Q33: =(O33-P33)*10000 -> 1.110223e-12
... B36: =_xll.meDateFromTenor(Settings.COB,E36,"MOD_FOLLOWING","SYB:LNB","") -> 43423 | C36: =_xll.meDateFromTenor(B36,F36,) -> 54381 | E36: 1D | F36: 30Y | G36: AUD_6ML | H36: PAY | I36: 1000000 | J36: 0.01 | K36: 0 | L36: 17 | M36: =_xll.meLWOSwapCreateFromGenerator("AUDIRS"&L36,G36,H36,I36,B36,C36,J36,K36,,,,,Settings.AllowCalibrationUpdates) -> AUDIRS17@20:0 | N36: AUDYC | O36: =_xll.meLWOSwapParRate(M36,N36) -> 0.0310375 | P36: ='AUD CURVE'!S87 -> 0.0310375 | Q36: =(O36-P36)*10000 -> 5.8980598e-13

Sheet SYNDICATE AUD IRS
N1: … BENCHMARK LEVEL | Z1: … FIXING INFO
B3: SETTLEMENT DATE | E3: BENCHMARK LEVEL | N3: SWAP
B4: AsOfDay | C4: =Settings.COB -> 43420 | J4: =$C$32 -> MID | N4: Handle Name | O4: AUD_SWAP
B5: ValuationLag | C5: 2D | E5: 3Y Bond Future | F5: Rate | G5: Bid | H5: Ask | I5: Mid | J5: Use | N5: Create Swap | O5: =IF('AUD CURVE'!$D$99,_xll.meLWOSwapCreate(O4,N8:P40),"#LOAD CURVE") -> AUD_SWAP@68:3
B6: BusDayAdjustment | C6: MOD_FOLLOWING | E6: YMA Comdty | F6: =(100-J6)% -> 0.021725 | G6: =_xll.BDP($E$6,$G$5) -> 97.825 | H6: =_xll.BDP($E$6,$H$5) -> 97.83 | I6: =AVERAGE(G6:H6) -> 97.8275 | J6: =IF($J$4="BID",G6,IF($J$4="ASK",H6,I6)) -> 97.8275
B7: Calendar | C7: SYB | J7: =$C$32 -> MID | N7: SWAP | O7: BOND LEG | P7: FUNDING LEG
B8: ValuationDate | C8: =_xll.meDateFromTenor(C4,C5,C6,C7) -> 43424 | E8: 10Y Bond Future | G8: Bid | H8: Ask | I8: Mid | J8: Use | N8: LegType | O8: Leg1:Fixed | P8: Leg2:Float | R8: FULL FIRST RESET RATE
E9: XMA Comdty | F9: =(100-J9)% -> 0.027025 | G9: =_xll.BDP($E$9,$G$5) -> 97.295 | H9: =_xll.BDP($E$9,$H$5) -> 97.3 | I9: =AVERAGE(G9:H9) -> 97.2975 | J9: =IF($J$7="BID",G9,IF($J$7="ASK",H9,I9)) -> 97.2975 | N9: Notional | O9: =$C$12 -> 1000000 | P9: =$C$12 -> 1000000 | R9: =IF(COUNT(T16)=1,T16%,"#ERROR: BBG DATA") -> 0.0193
B10: BOND SPECIFICATION | N10: NotionalExchange | O10: START_AND_END | P10: START_AND_END
B11: BondIdentifier | C11: MYNEWBOND | E11: Exchange for Physical, EFP | J11: =$C$32 -> MID | N11: PayReceive | O11: PAY | P11: RECEIVE | R11: FRONT STUB RATE | T11: RESET LOOKUP
B12: FaceValue | C12: 1000000 | E12: Tenor | F12: Ticker | G12: Bid | H12: Ask | I12: Mid | J12: Use | K12: SWP Q | L12: SWP S | N12: ForecastCurve | P12: =IF(P24="QUARTERLY","AUD3ML","AUD6ML") -> AUD3ML | R12: =IF(U22<C4,"RESET REQUIRED",IF('AUD CURVE'!$D$99,_xll.meProductSwapStubRate($X$22:$X$24,$Y$22:$Y$24,,$T$22:$U$34),"#LOAD CURVE")) -> 0.0193 | T12: =IF(P24="QUARTERLY",X40,X41) -> ADBB3M Curncy
B13: BondAccrualFrequency | C13: SEMI-ANNUAL | E13: 1Y | F13: ADSF1Q WBCA Curncy | G13: =_xll.BDP($F13,$G$12) -> -17.75 | H13: =_xll.BDP($F13,$H$12) -> -17.75 | I13: =AVERAGE(G13:H13) -> -17.75 | J13: =IF($J$11="BID",G13,IF($J$11="ASK",H13,I13)) -> -17.75 | K13: =IF(COUNT($F$6,J13)=2,$F$6+J13/10000,"#WAIT: BBG") -> 0.01995 | L13: =IF(COUNT(K13,J31)=2,K13+J31/10000,"#WAIT: BBG") -> 0.0215625 | N13: DiscountCurve | O13: AUDOIS | P13: AUDOIS | T13: PX_ASK
B14: BondPaymentFrequency | C14: SEMI-ANNUAL | E14: 2Y | F14: ADSF2Q IAUS Curncy | G14: =_xll.BDP($F14,$G$12) -> -9.625 | H14: =_xll.BDP($F14,$H$12) -> -4.625 | I14: =AVERAGE(G14:H14) -> -7.125 | J14: =IF($J$11="BID",G14,IF($J$11="ASK",H14,I14)) -> -7.125 | K14: =IF(COUNT($F$6,J14)=2,$F$6+J14/10000,"#WAIT: BBG") -> 0.0210125 | L14: =IF(COUNT(K14,J32)=2,K14+J32/10000,"#WAIT: BBG") -> 0.022575 | N14: Currency | O14: AUD | P14: AUD | T14: 2D
B15: Daycount | C15: ACT/ACT | E15: 3Y | F15: ADSF3Q IAUS Curncy | G15: =_xll.BDP($F15,$G$12) -> 1.125 | H15: =_xll.BDP($F15,$H$12) -> 5.125 | I15: =AVERAGE(G15:H15) -> 3.125 | J15: =IF($J$11="BID",G15,IF($J$11="ASK",H15,I15)) -> 3.125 | K15: =IF(COUNT($F$6,J15)=2,$F$6+J15/10000,"#WAIT: BBG") -> 0.0220375 | L15: =IF(COUNT(K15,J33)=2,K15+J33/10000,"#WAIT: BBG") -> 0.02355 | N15: Leverage | O15: 1 | P15: 1 | T15: =_xll.meDateFromTenor(P22,"-"&T14,"MOD_FOLLOWING","LNB:SYB") -> 43420
B16: ForwardStartTenor | E16: 4Y | F16: ADSF4 IAUS Curncy | G16: =_xll.BDP($F16,$G$12) -> 25.75 | H16: =_xll.BDP($F16,$H$12) -> 30.75 | I16: =AVERAGE(G16:H16) -> 28.25 | J16: =IF($J$11="BID",G16,IF($J$11="ASK",H16,I16)) -> 28.25 | K16: =IF(COUNT($F$6,J16)=2,$F$6+J16/10000,"#WAIT: BBG") -> 0.02455 | L16: =IF(COUNT(K16,J34)=2,K16+J34/10000,"#WAIT: BBG") -> 0.02605 | N16: FixedRate | O16: 0 | T16: =_xll.BDH(T12,T13,T15,T15) -> 1.93
B17: AccrualStartDate | C17: =IF(ISBLANK($C$16),C8,_xll.meDateFromTenor(Settings.COB,$C$16,$C$6,$C$7)) -> 43424 | E17: 5Y | F17: ADSF5 IAUS Curncy | G17: =_xll.BDP($F17,$G$12) -> 34.875 | H17: =_xll.BDP($F17,$H$12) -> 39.875 | I17: =AVERAGE(G17:H17) -> 37.375 | J17: =IF($J$11="BID",G17,IF($J$11="ASK",H17,I17)) -> 37.375 | K17: =IF(COUNT($F$6,J17)=2,$F$6+J17/10000,"#WAIT: BBG") -> 0.0254625 | L17: =IF(COUNT(K17,J35)=2,K17+J35/10000,"#WAIT: BBG") -> 0.0269375 | N17: FirstStubCurveIndex | P17: NATURAL
B18: MaturityOrTenor | C18: 10Y | E18: 6Y | F18: ADSF6 IAUS Curncy | G18: =_xll.BDP($F18,$G$12) -> -9.625 | H18: =_xll.BDP($F18,$H$12) -> -4.625 | I18: =AVERAGE(G18:H18) -> -7.125 | J18: =IF($J$11="BID",G18,IF($J$11="ASK",H18,I18)) -> -7.125 | K18: =IF(COUNT($F$6,J18)=2,$F$6+J18/10000,"#WAIT: BBG") -> 0.0210125 | L18: =IF(COUNT(K18,J36)=2,K18+J36/10000,"#WAIT: BBG") -> 0.0224375 | N18: LastStubCurveIndex | P18: NATURAL | R18: FIRST FLOAT RESET
E19: 7Y | F19: ADSF7 IAUS Curncy | G19: =_xll.BDP($F19,$G$12) -> -2 | H19: =_xll.BDP($F19,$H$12) -> 3 | I19: =AVERAGE(G19:H19) -> 0.5 | J19: =IF($J$11="BID",G19,IF($J$11="ASK",H19,I19)) -> 0.5 | K19: =IF(COUNT(L19,J37)=2,L19-J37/10000,"#WAIT: BBG") -> 0.0257 | L19: =IF(COUNT($F$9,J19)=2,$F$9+J19/10000,"#WAIT: BBG") -> 0.027075 | N19: FirstFixing | P19: =IF(ISBLANK($R$19),"",$R$19) -> 0.0193 | R19: =IF(ISBLANK($R$22),IF($C$23,$R$9,$R$12),$R$22) -> 0.0193
B20: SWAP SPECIFICATION | E20: 8Y | F20: ADSF8 IAUS Curncy | G20: =_xll.BDP($F20,$G$12) -> 4.75 | H20: =_xll.BDP($F20,$H$12) -> 9.75 | I20: =AVERAGE(G20:H20) -> 7.25 | J20: =IF($J$11="BID",G20,IF($J$11="ASK",H20,I20)) -> 7.25 | K20: =IF(COUNT(L20,J38)=2,L20-J38/10000,"#WAIT: BBG") -> 0.0264375 | L20: =IF(COUNT($F$9,J20)=2,$F$9+J20/10000,"#WAIT: BBG") -> 0.02775 | N20: LastFixing
