Workbook
Name Tranches: Tranches!$B$22:OFFSET(Tranches!$B$22,Tranches!$B$19-1,0)
Name Triggers: Triggers!$B$22:OFFSET(Triggers!$B$22,Triggers!$B$19-1,0)

Sheet Loans Data
I2: Loan Data with added columns
B3: Name | C3: df40kloans | I3: Name | J3: df40kLoans2
B4: Loans File | C4: X:\Secure\DIR_MLib_Analytics\Examples\StructuredCredit\1.5bil_saved_partial.csv | I4: CreateFromBlock | J4: =_xll.mscDataFrameCreateFromBlock(J3,B9:Z9,B10:Z209) -> DF40KLOANS2:0
B5: Load Tape | C5: =_xll.mscDataFrameCreateFromFilename(C3,C4) -> DF40KLOANS:0 | I5: Update LOAN_TYPE | J5: =AA8 -> DF40KLOANS2:1
AA7: Update Loan Type Column
B8: Display | AA8: =_xll.mscDataFrameAddColumn(J4,AA9,AA10:AA209) -> DF40KLOANS2:1
B9: {=_xll.mscDataFrameDisplay(C5)} | C9: ID | D9: UNNAMED: 0 | E9: LOAN_ID | F9: OBLIGOR_ID | G9: EAD | H9: RATING | I9: INDUSTRY | J9: CURRENCY | K9: LOAN_TYPE | L9: MATURITY | M9: REG_MATURITY | N9: PD_REGULATORY | O9: LGD | P9: RW | Q9: EL | R9: CAPITAL | S9: KIRB | T9: PEAD | U9: CEAD | V9: MATURITY_DATE | W9: MATURITY_MONTH | X9: RATE | Y9: FREQ | Z9: PDP | AA9: LOAN_TYPE
B10: 0 | C10: 18588 | D10: 18587 | E10: 18588 | F10: 9254 | G10: 67737.6 | H10: CCC | I10: Ind06 | J10: USD | K10: Lev | L10: 7.8381113 | M10: 5 | N10: 0.20494 | O10: 0.4 | P10: 2.3521922 | Q10: 0.081976 | R10: 0.18817538 | S10: 0.27015138 | T10: 67737.6 | U10: 67737.6 | V10: 2026-08-31 | W10: =L10*12 -> 94.057335 | X10: 0.5 | Y10: 1 | Z10: =N10 -> 0.20494 | AA10: 0
B11: 1 | C11: 14606 | D11: 14605 | E11: 14606 | F11: 7290 | G11: 26055.01 | H11: CCC | I11: Ind06 | J11: USD | K11: ShipFin | L11: 5.9893432 | M11: 5 | N11: 0.20494 | O11: 0.4 | P11: 2.3521922 | Q11: 0.081976 | R11: 0.18817538 | S11: 0.27015138 | T11: 26055.01 | U11: 93792.61 | V11: 2024-08-31 | W11: =L11*12 -> 71.872119 | X11: 0.5 | Y11: 1 | Z11: =N11 -> 0.20494 | AA11: 0
B12: 2 | C12: 14614 | D12: 14613 | E12: 14614 | F12: 7294 | G12: 47668.96 | H12: CCC | I12: Ind06 | J12: USD | K12: ShipFin | L12: 5.0242908 | M12: 5 | N12: 0.20494 | O12: 0.4 | P12: 2.3521922 | Q12: 0.081976 | R12: 0.18817538 | S12: 0.27015138 | T12: 47668.96 | U12: 141461.57 | V12: 2024-07-31 | W12: =L12*12 -> 60.291489 | X12: 0.5 | Y12: 1 | Z12: =N12 -> 0.20494 | AA12: 0
B13: 3 | C13: 14615 | D13: 14614 | E13: 14615 | F13: 7295 | G13: 3811.72 | H13: CCC | I13: Ind06 | J13: USD | K13: ShipFin | L13: 7.2126824 | M13: 5 | N13: 0.20494 | O13: 0.4 | P13: 2.3521922 | Q13: 0.081976 | R13: 0.18817538 | S13: 0.27015138 | T13: 3811.72 | U13: 145273.29 | V13: 2026-07-31 | W13: =L13*12 -> 86.552189 | X13: 0.5 | Y13: 1 | Z13: =N13 -> 0.20494 | AA13: 0
B14: 4 | C14: 14618 | D14: 14617 | E14: 14618 | F14: 7297 | G14: 73469.06 | H14: CCC | I14: Ind06 | J14: USD | K14: ShipFin | L14: 5.1893732 | M14: 5 | N14: 0.20494 | O14: 0.4 | P14: 2.3521922 | Q14: 0.081976 | R14: 0.18817538 | S14: 0.27015138 | T14: 73469.06 | U14: 218742.35 | V14: 2024-07-31 | W14: =L14*12 -> 62.272478 | X14: 0.5 | Y14: 1 | Z14: =N14 -> 0.20494 | AA14: 0
B15: 5 | C15: 14619 | D15: 14618 | E15: 14619 | F15: 7298 | G15: 57115.17 | H15: CCC | I15: Ind06 | J15: USD | K15: ShipFin | L15: 7.6658895 | M15: 5 | N15: 0.20494 | O15: 0.4 | P15: 2.3521922 | Q15: 0.081976 | R15: 0.18817538 | S15: 0.27015138 | T15: 57115.17 | U15: 275857.52 | V15: 2026-08-31 | W15: =L15*12 -> 91.990674 | X15: 0.5 | Y15: 1 | Z15: =N15 -> 0.20494 | AA15: 0
B16: 6 | C16: 14621 | D16: 14620 | E16: 14621 | F16: 7299 | G16: 29793.59 | H16: CCC | I16: Ind06 | J16: USD | K16: ShipFin | L16: 5.2331041 | M16: 5 | N16: 0.20494 | O16: 0.4 | P16: 2.3521922 | Q16: 0.081976 | R16: 0.18817538 | S16: 0.27015138 | T16: 29793.59 | U16: 305651.11 | V16: 2024-07-31 | W16: =L16*12 -> 62.797249 | X16: 0.5 | Y16: 1 | Z16: =N16 -> 0.20494 | AA16: 0
B17: 7 | C17: 14622 | D17: 14621 | E17: 14622 | F17: 7300 | G17: 50340.96 | H17: CCC | I17: Ind06 | J17: USD | K17: ShipFin | L17: 7.1406577 | M17: 5 | N17: 0.20494 | O17: 0.4 | P17: 2.3521922 | Q17: 0.081976 | R17: 0.18817538 | S17: 0.27015138 | T17: 50340.96 | U17: 355992.07 | V17: 2026-07-31 | W17: =L17*12 -> 85.687893 | X17: 0.5 | Y17: 1 | Z17: =N17 -> 0.20494 | AA17: 0
B18: 8 | C18: 14624 | D18: 14623 | E18: 14624 | F18: 7301 | G18: 25618.76 | H18: CCC | I18: Ind06 | J18: USD | K18: ShipFin | L18: 7.5985786 | M18: 5 | N18: 0.20494 | O18: 0.4 | P18: 2.3521922 | Q18: 0.081976 | R18: 0.18817538 | S18: 0.27015138 | T18: 25618.76 | U18: 381610.83 | V18: 2026-08-31 | W18: =L18*12 -> 91.182944 | X18: 0.5 | Y18: 1 | Z18: =N18 -> 0.20494 | AA18: 0
B19: 9 | C19: 14625 | D19: 14624 | E19: 14625 | F19: 7301 | G19: 17043.65 | H19: CCC | I19: Ind06 | J19: USD | K19: ShipFin | L19: 6.1199304 | M19: 5 | N19: 0.20494 | O19: 0.4 | P19: 2.3521922 | Q19: 0.081976 | R19: 0.18817538 | S19: 0.27015138 | T19: 17043.65 | U19: 398654.48 | V19: 2025-07-31 | W19: =L19*12 -> 73.439165 | X19: 0.5 | Y19: 1 | Z19: =N19 -> 0.20494 | AA19: 0
B20: 10 | C20: 14627 | D20: 14626 | E20: 14627 | F20: 7302 | G20: 36732.97 | H20: CCC | I20: Ind06 | J20: USD | K20: ShipFin | L20: 7.2653775 | M20: 5 | N20: 0.20494 | O20: 0.4 | P20: 2.3521922 | Q20: 0.081976 | R20: 0.18817538 | S20: 0.27015138 | T20: 36732.97 | U20: 435387.45 | V20: 2026-07-31 | W20: =L20*12 -> 87.18453 | X20: 0.5 | Y20: 1 | Z20: =N20 -> 0.20494 | AA20: 0
B21: 11 | C21: 14629 | D21: 14628 | E21: 14629 | F21: 7303 | G21: 60748.3 | H21: CCC | I21: Ind06 | J21: USD | K21: ShipFin | L21: 9.760178 | M21: 5 | N21: 0.20494 | O21: 0.4 | P21: 2.3521922 | Q21: 0.081976 | R21: 0.18817538 | S21: 0.27015138 | T21: 60748.3 | U21: 496135.75 | V21: 2028-08-31 | W21: =L21*12 -> 117.12214 | X21: 0.5 | Y21: 1 | Z21: =N21 -> 0.20494 | AA21: 0
... B209: 199 | C209: 14971 | D209: 14970 | E209: 14971 | F209: 7476 | G209: 5198.13 | H209: CCC | I209: Ind06 | J209: USD | K209: ShipFin | L209: 5.8937822 | M209: 5 | N209: 0.20494 | O209: 0.4 | P209: 2.3521922 | Q209: 0.081976 | R209: 0.18817538 | S209: 0.27015138 | T209: 5198.13 | U209: 7966109.2 | V209: 2024-08-31 | W209: =L209*12 -> 70.725386 | X209: 0.5 | Y209: 1 | Z209: =N209 -> 0.20494 | AA209: 0
B210: #N/A | C210: #N/A | D210: #N/A | E210: #N/A | F210: #N/A | G210: #N/A | H210: #N/A | I210: #N/A | J210: #N/A | K210: #N/A | L210: #N/A | M210: #N/A | N210: #N/A | O210: #N/A | P210: #N/A | Q210: #N/A | R210: #N/A | S210: #N/A | T210: #N/A | U210: #N/A | V210: #N/A | W210: =L210*12 -> #N/A | X210: 0.5 | Y210: 1 | Z210: =N210 -> #N/A | AA210: 0
B211: #N/A | C211: #N/A | D211: #N/A | E211: #N/A | F211: #N/A | G211: #N/A | H211: #N/A | I211: #N/A | J211: #N/A | K211: #N/A | L211: #N/A | M211: #N/A | N211: #N/A | O211: #N/A | P211: #N/A | Q211: #N/A | R211: #N/A | S211: #N/A | T211: #N/A | U211: #N/A | V211: #N/A | W211: =L211*12 -> #N/A | X211: 0.5 | Y211: 1 | Z211: =N211 -> #N/A | AA211: 0
B212: #N/A | C212: #N/A | D212: #N/A | E212: #N/A | F212: #N/A | G212: #N/A | H212: #N/A | I212: #N/A | J212: #N/A | K212: #N/A | L212: #N/A | M212: #N/A | N212: #N/A | O212: #N/A | P212: #N/A | Q212: #N/A | R212: #N/A | S212: #N/A | T212: #N/A | U212: #N/A | V212: #N/A | W212: =L212*12 -> #N/A | X212: 0.5 | Y212: 1 | Z212: =N212 -> #N/A | AA212: 0
B213: #N/A | C213: #N/A | D213: #N/A | E213: #N/A | F213: #N/A | G213: #N/A | H213: #N/A | I213: #N/A | J213: #N/A | K213: #N/A | L213: #N/A | M213: #N/A | N213: #N/A | O213: #N/A | P213: #N/A | Q213: #N/A | R213: #N/A | S213: #N/A | T213: #N/A | U213: #N/A | V213: #N/A | W213: =L213*12 -> #N/A | X213: 0.5 | Y213: 1 | Z213: =N213 -> #N/A | AA213: 0
B214: #N/A | C214: #N/A | D214: #N/A | E214: #N/A | F214: #N/A | G214: #N/A | H214: #N/A | I214: #N/A | J214: #N/A | K214: #N/A | L214: #N/A | M214: #N/A | N214: #N/A | O214: #N/A | P214: #N/A | Q214: #N/A | R214: #N/A | S214: #N/A | T214: #N/A | U214: #N/A | V214: #N/A | W214: =L214*12 -> #N/A | X214: 0.5 | Y214: 1 | Z214: =N214 -> #N/A | AA214: 0
B215: #N/A | C215: #N/A | D215: #N/A | E215: #N/A | F215: #N/A | G215: #N/A | H215: #N/A | I215: #N/A | J215: #N/A | K215: #N/A | L215: #N/A | M215: #N/A | N215: #N/A | O215: #N/A | P215: #N/A | Q215: #N/A | R215: #N/A | S215: #N/A | T215: #N/A | U215: #N/A | V215: #N/A | W215: =L215*12 -> #N/A | X215: 0.5 | Y215: 1 | Z215: =N215 -> #N/A | AA215: 0

Sheet Portfolio
C3: name | D3: MyPortfolio
C4: Create Portfolio | D4: =_xll.mscLoanPortfolioCreate(D3) -> MYPORTFOLIO:0
C6: DataFrame | D6: ='Loans Data'!J5 -> DF40KLOANS2:1
C7: Set Tape | D7: =_xll.mscLoanPortfolioSetPortfolioTape(D4,D6) -> MYPORTFOLIO:1
C9: ProjectLoans | D9: =_xll.mscLoanPortfolioProjectLoans(D7) -> MYPORTFOLIO:2
C14: LoanProjection | D14: {=_xll.mscLoanPortfolioGetLoanProjection(D9, 0)} -> Period | E14: BalanceStart | F14: DefaultBalance | G14: LossGivenLoss | H14: SeverityRecovered | I14: Prepayment | J14: BalanceAfterDefaultAndPrepayment | K14: LoanPayment | L14: InterestComponent | M14: PrincipalComponent | N14: BalanceEnd | O14: SeverityRecoveredNoLag | P14: RiskWeight | Q14: KirbAmount
D15: 1 | E15: 7966109.2 | F15: 150798.51 | G15: 60319.405 | H15: 90479.107 | I15: 0 | J15: 7815310.7 | K15: 337858.04 | L15: 331921.22 | M15: 12220.093 | N15: 7803090.6 | O15: 90479.107 | P15: 2.3521922 | Q15: 0.27015138
D16: 2 | E16: 7803090.6 | F16: 147712.57 | G16: 59085.028 | H16: 88627.541 | I16: 0 | J16: 7655378 | K16: 331462.38 | L16: 325128.77 | M16: 12488.298 | N16: 7642889.7 | O16: 88627.541 | P16: 2.3521922 | Q16: 0.27015138
D17: 3 | E17: 7642889.7 | F17: 144679.97 | G17: 57871.986 | H17: 86807.979 | I17: 0 | J17: 7498209.7 | K17: 325187.8 | L17: 318453.74 | M17: 12762.39 | N17: 7485447.3 | O17: 86807.979 | P17: 2.3521922 | Q17: 0.27015138
D18: 4 | E18: 7485447.3 | F18: 141699.58 | G18: 56679.832 | H18: 85019.748 | I18: 0 | J18: 7343747.8 | K18: 319031.99 | L18: 311893.64 | M18: 13042.498 | N18: 7330705.3 | O18: 85019.748 | P18: 2.3521922 | Q18: 0.27015138
D19: 5 | E19: 7330705.3 | F19: 138770.31 | G19: 55508.124 | H19: 83262.187 | I19: 0 | J19: 7191935 | K19: 312992.71 | L19: 305446.05 | M19: 13328.754 | N19: 7178606.2 | O19: 83262.187 | P19: 2.3521922 | Q19: 0.27015138
D20: 6 | E20: 7178606.2 | F20: 135891.07 | G20: 54356.43 | H20: 81534.645 | I20: 0 | J20: 7042715.1 | K20: 307067.76 | L20: 299108.59 | M20: 13621.292 | N20: 7029093.8 | O20: 81534.645 | P20: 2.3521922 | Q20: 0.27015138
D21: 7 | E21: 7029093.8 | F21: 133060.8 | G21: 53224.322 | H21: 79836.483 | I21: 0 | J21: 6896033 | K21: 301254.96 | L21: 292878.91 | M21: 13920.251 | N21: 6882112.8 | O21: 79836.483 | P21: 2.3521922 | Q21: 0.27015138
D22: 8 | E22: 6882112.8 | F22: 130278.45 | G22: 52111.381 | H22: 78167.071 | I22: 0 | J22: 6751834.3 | K22: 295552.2 | L22: 286754.7 | M22: 14225.771 | N22: 6737608.6 | O22: 78167.071 | P22: 2.3521922 | Q22: 0.27015138
D23: 9 | E23: 6737608.6 | F23: 127542.99 | G23: 51017.194 | H23: 76525.791 | I23: 0 | J23: 6610065.6 | K23: 289957.4 | L23: 280733.69 | M23: 14537.997 | N23: 6595527.6 | O23: 76525.791 | P23: 2.3521922 | Q23: 0.27015138
D24: 10 | E24: 6595527.6 | F24: 124853.39 | G24: 49941.357 | H24: 74912.035 | I24: 0 | J24: 6470674.2 | K24: 284468.5 | L24: 274813.65 | M24: 14857.076 | N24: 6455817.1 | O24: 74912.035 | P24: 2.3521922 | Q24: 0.27015138
D25: 11 | E25: 6455817.1 | F25: 122208.67 | G25: 48883.468 | H25: 73325.203 | I25: 0 | J25: 6333608.4 | K25: 279083.51 | L25: 268992.38 | M25: 15183.158 | N25: 6318425.3 | O25: 73325.203 | P25: 2.3521922 | Q25: 0.27015138
D26: 12 | E26: 6318425.3 | F26: 119607.84 | G26: 47843.137 | H26: 71764.706 | I26: 0 | J26: 6198817.4 | K26: 273800.46 | L26: 263267.72 | M26: 15516.396 | N26: 6183301 | O26: 71764.706 | P26: 2.3521922 | Q26: 0.27015138
... D133: 119 | E133: 901.96222 | F133: 17.074152 | G133: 6.8296609 | H133: 10.244491 | I133: 0 | J133: 884.88807 | K133: 921.75841 | L133: 37.581759 | M133: 884.88807 | N133: 1.6164847e-12 | O133: 10.244491 | P133: 2.3521922 | Q133: 0.27015138
D134: #N/A | E134: #N/A | F134: #N/A | G134: #N/A | H134: #N/A | I134: #N/A | J134: #N/A | K134: #N/A | L134: #N/A | M134: #N/A | N134: #N/A | O134: #N/A | P134: #N/A | Q134: #N/A
D135: #N/A | E135: #N/A | F135: #N/A | G135: #N/A | H135: #N/A | I135: #N/A | J135: #N/A | K135: #N/A | L135: #N/A | M135: #N/A | N135: #N/A | O135: #N/A | P135: #N/A | Q135: #N/A
D136: #N/A | E136: #N/A | F136: #N/A | G136: #N/A | H136: #N/A | I136: #N/A | J136: #N/A | K136: #N/A | L136: #N/A | M136: #N/A | N136: #N/A | O136: #N/A | P136: #N/A | Q136: #N/A
D137: #N/A | E137: #N/A | F137: #N/A | G137: #N/A | H137: #N/A | I137: #N/A | J137: #N/A | K137: #N/A | L137: #N/A | M137: #N/A | N137: #N/A | O137: #N/A | P137: #N/A | Q137: #N/A
D138: #N/A | E138: #N/A | F138: #N/A | G138: #N/A | H138: #N/A | I138: #N/A | J138: #N/A | K138: #N/A | L138: #N/A | M138: #N/A | N138: #N/A | O138: #N/A | P138: #N/A | Q138: #N/A
D139: #N/A | E139: #N/A | F139: #N/A | G139: #N/A | H139: #N/A | I139: #N/A | J139: #N/A | K139: #N/A | L139: #N/A | M139: #N/A | N139: #N/A | O139: #N/A | P139: #N/A | Q139: #N/A
D140: #N/A | E140: #N/A | F140: #N/A | G140: #N/A | H140: #N/A | I140: #N/A | J140: #N/A | K140: #N/A | L140: #N/A | M140: #N/A | N140: #N/A | O140: #N/A | P140: #N/A | Q140: #N/A
D141: #N/A | E141: #N/A | F141: #N/A | G141: #N/A | H141: #N/A | I141: #N/A | J141: #N/A | K141: #N/A | L141: #N/A | M141: #N/A | N141: #N/A | O141: #N/A | P141: #N/A | Q141: #N/A
D142: #N/A | E142: #N/A | F142: #N/A | G142: #N/A | H142: #N/A | I142: #N/A | J142: #N/A | K142: #N/A | L142: #N/A | M142: #N/A | N142: #N/A | O142: #N/A | P142: #N/A | Q142: #N/A
D143: #N/A | E143: #N/A | F143: #N/A | G143: #N/A | H143: #N/A | I143: #N/A | J143: #N/A | K143: #N/A | L143: #N/A | M143: #N/A | N143: #N/A | O143: #N/A | P143: #N/A | Q143: #N/A
D144: #N/A | E144: #N/A | F144: #N/A | G144: #N/A | H144: #N/A | I144: #N/A | J144: #N/A | K144: #N/A | L144: #N/A | M144: #N/A | N144: #N/A | O144: #N/A | P144: #N/A | Q144: #N/A
D145: #N/A | E145: #N/A | F145: #N/A | G145: #N/A | H145: #N/A | I145: #N/A | J145: #N/A | K145: #N/A | L145: #N/A | M145: #N/A | N145: #N/A | O145: #N/A | P145: #N/A | Q145: #N/A
... D386: #N/A | E386: #N/A | F386: #N/A | G386: #N/A | H386: #N/A | I386: #N/A | J386: #N/A | K386: #N/A | L386: #N/A | M386: #N/A | N386: #N/A | O386: #N/A | P386: #N/A | Q386: #N/A

Sheet Tranches
B2: TrancheDefinitions | K2: SyntheticExcessSpread
B3: Name | C3: Equity | E3: Name | F3: Mezz | H3: Name | I3: Senior | K3: Name | L3: Synthetic_XS
B4: SeniorityRank | C4: 1 | E4: SeniorityRank | F4: 2 | H4: SeniorityRank | I4: 3 | K4: Periods | L4: 200
B5: TrancheSize | C5: 2000000 | E5: TrancheSize | F5: 2000000 | H5: TrancheSize | I5: 3000000 | K5: ResetFrequency | L5: 1
B6: TranchePayType | C6: Sequential | E6: TranchePayType | F6: Sequential | H6: TranchePayType | I6: Sequential | K6: UseOrLose | L6: FALSE
B7: CouponType | C7: NONE | E7: CouponType | F7: NONE | H7: CouponType | I7: NONE | K7: CreateSyntheticExcessSpread | L7: =_xll.mscSyntheticExcessSpreadCreate(L3,K4:L6) -> SYNTHETIC_XS:2
B8: CouponRate | C8: 500 | D8: bp | E8: CouponRate | F8: 500 | G8: bp | H8: CouponRate | I8: 500 | J8: bp
B9: CouponFloor | C9: NONE | E9: CouponFloor | F9: NONE | H9: CouponFloor | I9: NONE
B10: CouponFrequency | C10: MONTHLY | E10: CouponFrequency | F10: MONTHLY | H10: CouponFrequency | I10: MONTHLY | K10: Level | L10: 2000000
B11: CurveCollection | C11: EURYC | E11: CurveCollection | F11: EURYC | H11: CurveCollection | I11: EURYC | K11: ActivePeriod | L11: 100
B12: ResetCurve | C12: EUR3ML | E12: ResetCurve | F12: EUR3ML | H12: ResetCurve | I12: EUR3ML | K12: SetThreshold | L12: =_xll.mscSyntheticExcessSpreadSetThreshold(L7,L10,L11) -> SYNTHETIC_XS:3
B13: DiscountMargin | C13: 0 | E13: DiscountMargin | F13: 0 | H13: DiscountMargin | I13: 0
B14: FixingTable | E14: FixingTable | H14: FixingTable
B15: CreateTranche | C15: =_xll.mscTrancheDefinitionCreate(C3,B5:C14) -> EQUITY:1 | E15: CreateTranche | F15: =_xll.mscTrancheDefinitionCreate(F3,E5:F14) -> MEZZ:1 | H15: CreateTranche | I15: =_xll.mscTrancheDefinitionCreate(I3,H5:I14) -> SENIOR:1
B18: Number of Tranches
B19: =COUNTA(B22:B25) -> 3
B21: Tranches
B22: =C15 -> EQUITY:1
B23: =F15 -> MEZZ:1
B24: =I15 -> SENIOR:1

Sheet Triggers
B2: Trigger Definitions
B3: CreditHandle | C3: Trigger1 | E3: CreditHandle | F3: Trigger2 | I3: CreditHandle | J3: Trigger3
B4: Periods | C4: 200 | E4: Periods | F4: 200 | I4: Periods | J4: 200
B5: CreateTrigger | C5: =_xll.mscTriggerCreate(C3,C4) -> TRIGGER1:2 | E5: CreateTrigger | F5: =_xll.mscTriggerCreate(F3,F4) -> TRIGGER2:2 | I5: CreateTrigger | J5: =_xll.mscTriggerCreate(J3,J4) -> TRIGGER3:2
B7: Threshold | C7: 10000 | E7: Threshold | F7: 20000 | H7: period | I7: threshold | J7: active
B8: ActivePeriod | C8: 100 | E8: ActivePeriodStart | F8: 50 | H8: 1 | I8: 10000 | J8: TRUE
B9: SetThreshold | C9: =_xll.mscTriggerSetThreshold(C5,C7,C8) -> TRIGGER1:3 | E9: ActivePeriodEnd | F9: 100 | H9: 2 | I9: 10100 | J9: TRUE
E10: SetThresholdRange | F10: =_xll.mscTriggerSetThresholdRange(F5,F7,F8,F9) -> TRIGGER2:3 | H10: 3 | I10: 10200 | J10: TRUE
H11: 4 | I11: 10300 | J11: TRUE
H12: 5 | I12: 10400 | J12: TRUE
H13: 6 | I13: 10500 | J13: TRUE
H14: 7 | I14: 10600 | J14: TRUE
H15: 8 | I15: 10700 | J15: TRUE
H16: 9 | I16: 10800 | J16: TRUE
H17: 10 | I17: 10900 | J17: TRUE
B18: Number of Triggers | H18: 11 | I18: 11000 | J18: TRUE
B19: =COUNTA(B22:B25) -> 3 | H19: 12 | I19: 11100 | J19: TRUE
H20: 13 | I20: 11200 | J20: TRUE
B21: Triggers | H21: 14 | I21: 11300 | J21: TRUE
B22: =C9 -> TRIGGER1:3 | H22: 15 | I22: 11400 | J22: TRUE
B23: =F10 -> TRIGGER2:3 | H23: 16 | I23: 11500 | J23: TRUE
B24: =J28 -> TRIGGER3:3 | H24: 17 | I24: 11600 | J24: TRUE
H25: 18 | I25: 11700 | J25: TRUE
H26: 19 | I26: 11800 | J26: TRUE
H27: 20 | I27: 11900 | J27: TRUE
I28: SetThresholdVector | J28: =_xll.mscTriggerSetThresholdVector(J5,I8:I27,J8:J27) -> TRIGGER3:3

Sheet CashflowEngine
B2: CashflowEngine
B3: CreditHandle | C3: CapitalStructure
B4: CashflowEngine | C4: =_xll.mscCashflowEngineCreate(C3) -> CAPITALSTRUCTURE:4
B6: Configuration | E6: Tranches | G6: Triggers
B7: LoanPortfolio | C7: =Portfolio!D9 -> MYPORTFOLIO:2 | E7: {=_xll.meUtilityResize(Tranches,8,1)} -> EQUITY:1 | G7: {=_xll.meUtilityResize(Triggers,8,1)} -> TRIGGER1:3
B8: KIRB | C8: 0.07 | E8: MEZZ:1 | G8: TRIGGER2:3
B9: ELGD | C9: 0.4 | E9: SENIOR:1 | G9: TRIGGER3:3
B10: RegulatoryCapitalMaturity | C10: 50
B11: DiversityMetric | C11: 500
B12: SupervisoryType | C12: IRBA
B13: PoolType | C13: RETAIL
B14: EffectiveDate | C14: =TODAY() -> 43858
B15: MaturityDate | C15: =C14+3000 -> 46858
B16: ReinvestmentEndDate | C16: =C15 -> 46858 | E16: SyntheticExcessSpread
B17: ReinvestmentEndPeriod | C17: 0 | E17: =Tranches!L12 -> SYNTHETIC_XS:3
B18: Configure | C18: =_xll.mscCashflowEngineConfigure(C4,C7,B8:C17,E7:E14,G7:G14) -> CAPITALSTRUCTURE:5
B20: Set Synthetic XS | C20: =_xll.mscCashflowEngineSetSyntheticExcessSpread(C18,E17) -> CAPITALSTRUCTURE:6
B22: Evaluate | C22: =_xll.mscCashflowEngineEvaluate(C20) -> CAPITALSTRUCTURE:7
B25: Tranche PV Parameters
B26: ValuationDate | C26: =C14 -> 43858
B27: CallPeriod | C27: 98
B28: Interest Rate | C28: 0.01
B30: Tranche | C30: PV
B31: {=_xll.meUtilityResize(Tranches,8,1)} -> EQUITY:1 | C31: =_xll.mscTrancheCalculatePV(B31,$C$22,$C$26,$C$27,$C$28) -> 58067.673
B32: MEZZ:1 | C32: =_xll.mscTrancheCalculatePV(B32,$C$22,$C$26,$C$27,$C$28) -> 269903.46
B33: SENIOR:1 | C33: =_xll.mscTrancheCalculatePV(B33,$C$22,$C$26,$C$27,$C$28) -> 3163667.1

Sheet LiabilityFlows
B2: ResultsHandle | C2: LiabilityFlows
B3: LiabilityFlows | C3: =_xll.mscCashflowEngineLiabilityFlows(C2,CashflowEngine!C22) -> LIABILITYFLOWS:2
R4: =NA() -> #N/A
B5: Display
B6: {=_xll.mscDataFrameDisplay(C3)} -> Period | C6: PoolBalanceStart | D6: PoolBalanceEnd | E6: PrincipalComponent | F6: ReinvestmentBalance | G6: SeverityRecovered | H6: Prepayment | I6: LossGivenLoss | J6: InterestComponent | K6: CumulativeDefaults | L6: CumulativeLoss | M6: CumulativeRecovery | N6: EQUITYFixingDate | O6: EQUITYAccrualStartDate | P6: EQUITYAccrualEndDate | Q6: EQUITYPaymentDate | R6: EQUITYBalanceStart | S6: EQUITYBalanceEnd | T6: EQUITYLossAllocated | U6: EQUITYPrincipalAllocated | V6: EQUITYPrincipalPayment | W6: EQUITYAttachmentPoint | X6: EQUITYDetachmentPoint | Y6: EQUITYCoupon | Z6: EQUITYCouponRate | AA6: EQUITYPayType | AB6: EQUITYCouponYearFraction | AC6: EQUITYResetRate | AD6: EQUITYResetDate | AE6: EQUITYDiscountFactorRiskless | AF6: EQUITYDiscountFactorDiscountMargin | AG6: EQUITYRiskWeight | AH6: EQUITYPVRiskless | AI6: EQUITYPVDiscountMargin | AJ6: EQUITYAverageBalance | AK6: MEZZFixingDate | AL6: MEZZAccrualStartDate | AM6: MEZZAccrualEndDate | AN6: MEZZPaymentDate | AO6: MEZZBalanceStart | AP6: MEZZBalanceEnd | AQ6: MEZZLossAllocated | AR6: MEZZPrincipalAllocated | AS6: MEZZPrincipalPayment | AT6: MEZZAttachmentPoint | AU6: MEZZDetachmentPoint | AV6: MEZZCoupon | AW6: MEZZCouponRate | AX6: MEZZPayType | AY6: MEZZCouponYearFraction | AZ6: MEZZResetRate | BA6: MEZZResetDate | BB6: MEZZDiscountFactorRiskless | BC6: MEZZDiscountFactorDiscountMargin | BD6: MEZZRiskWeight | BE6: MEZZPVRiskless | BF6: MEZZPVDiscountMargin | BG6: MEZZAverageBalance | BH6: SENIORFixingDate | BI6: SENIORAccrualStartDate | BJ6: SENIORAccrualEndDate | BK6: SENIORPaymentDate | BL6: SENIORBalanceStart | BM6: SENIORBalanceEnd | BN6: SENIORLossAllocated | BO6: SENIORPrincipalAllocated | BP6: SENIORPrincipalPayment | BQ6: SENIORAttachmentPoint | BR6: SENIORDetachmentPoint | BS6: SENIORCoupon | BT6: SENIORCouponRate | BU6: SENIORPayType | BV6: SENIORCouponYearFraction | BW6: SENIORResetRate | BX6: SENIORResetDate | BY6: SENIORDiscountFactorRiskless | BZ6: SENIORDiscountFactorDiscountMargin | CA6: SENIORRiskWeight | CB6: SENIORPVRiskless | CC6: SENIORPVDiscountMargin | CD6: SENIORAverageBalance | CE6: #N/A | CF6: #N/A | CG6: #N/A | CH6: #N/A | CI6: #N/A | CJ6: #N/A | CK6: #N/A | CL6: #N/A | CM6: #N/A | CN6: #N/A
B7: 0 | C7: 7966109.2 | D7: 7803090.6 | E7: 12220.093 | F7: 0 | G7: 90479.107 | H7: 0 | I7: 150798.51 | J7: 331921.22 | K7: 150798.51 | L7: 150798.51 | M7: 90479.107 | N7: 43858 | O7: 43858 | P7: 43878 | Q7: 43878 | R7: 2000000 | S7: 1849201.5 | T7: 150798.51 | U7: 0 | V7: 0 | W7: 0 | X7: 0.23698321 | Y7: 5179.2051 | Z7: 0.046612846 | AA7: SEQUENTIAL | AB7: 0.055555556 | AC7: -0.0033871537 | AD7: 43858 | AE7: 1.0026404 | AF7: 1.0026404 | AG7: 0 | AH7: 5192.8805 | AI7: 5192.8805 | AJ7: 2000000 | AK7: 43858 | AL7: 43858 | AM7: 43878 | AN7: 43878 | AO7: 2000000 | AP7: 2000000 | AQ7: 0 | AR7: 0 | AS7: 0 | AT7: 0.23698321 | AU7: 0.49329192 | AV7: 5179.2051 | AW7: 0.046612846 | AX7: SEQUENTIAL | AY7: 0.055555556 | AZ7: -0.0033871537 | BA7: 43858 | BB7: 1.0026404 | BC7: 1.0026404 | BD7: 0 | BE7: 5192.8805 | BF7: 5192.8805 | BG7: 2000000 | BH7: 43858 | BI7: 43858 | BJ7: 43878 | BK7: 43878 | BL7: 3000000 | BM7: 2897300.8 | BN7: 0 | BO7: 102699.2 | BP7: 102699.2 | BQ7: 0.49329192 | BR7: 0.86459362 | BS7: 7768.8077 | BT7: 0.046612846 | BU7: SEQUENTIAL | BV7: 0.055555556 | BW7: -0.0033871537 | BX7: 43858 | BY7: 1.0026404 | BZ7: 1.0026404 | CA7: 0 | CB7: 110759.69 | CC7: 110759.69 | CD7: 3000000 | CE7: #N/A | CF7: #N/A | CG7: #N/A | CH7: #N/A | CI7: #N/A | CJ7: #N/A | CK7: #N/A | CL7: #N/A | CM7: #N/A | CN7: #N/A
B8: 1 | C8: 7803090.6 | D8: 7642889.7 | E8: 12488.298 | F8: 0 | G8: 88627.541 | H8: 0 | I8: 147712.57 | J8: 325128.77 | K8: 298511.08 | L8: 298511.08 | M8: 179106.65 | N8: 43878 | O8: 43878 | P8: 43906 | Q8: 43906 | R8: 1849201.5 | S8: 1701488.9 | T8: 147712.57 | U8: 0 | V8: 0 | W8: 0 | X8: 0.22262377 | Y8: 6705.5071 | Z8: 0.046622103 | AA8: SEQUENTIAL | AB8: 0.077777778 | AC8: -0.0033778966 | AD8: 43878 | AE8: 1.0029062 | AF8: 1.0029062 | AG8: 0 | AH8: 6724.9947 | AI8: 6724.9947 | AJ8: 1849201.5 | AK8: 43878 | AL8: 43878 | AM8: 43906 | AN8: 43906 | AO8: 2000000 | AP8: 2000000 | AQ8: 0 | AR8: 0 | AS8: 0 | AT8: 0.22262377 | AU8: 0.4843049 | AV8: 7252.3272 | AW8: 0.046622103 | AX8: SEQUENTIAL | AY8: 0.077777778 | AZ8: -0.0033778966 | BA8: 43878 | BB8: 1.0029062 | BC8: 1.0029062 | BD8: 0 | BE8: 7273.404 | BF8: 7273.404 | BG8: 2000000 | BH8: 43878 | BI8: 43878 | BJ8: 43906 | BK8: 43906 | BL8: 2897300.8 | BM8: 2796185 | BN8: 0 | BO8: 101115.84 | BP8: 101115.84 | BQ8: 0.4843049 | BR8: 0.85015932 | BS8: 10506.087 | BT8: 0.046622103 | BU8: SEQUENTIAL | BV8: 0.077777778 | BW8: -0.0033778966 | BX8: 43878 | BY8: 1.0029062 | BZ8: 1.0029062 | CA8: 0 | CB8: 111946.32 | CC8: 111946.32 | CD8: 2897300.8 | CE8: #N/A | CF8: #N/A | CG8: #N/A | CH8: #N/A | CI8: #N/A | CJ8: #N/A | CK8: #N/A | CL8: #N/A | CM8: #N/A | CN8: #N/A
B9: 2 | C9: 7642889.7 | D9: 7485447.3 | E9: 12762.39 | F9: 0 | G9: 86807.979 | H9: 0 | I9: 144679.97 | J9: 318453.74 | K9: 443191.05 | L9: 443191.05 | M9: 265914.63 | N9: 43906 | O9: 43906 | P9: 43936 | Q9: 43936 | R9: 1701488.9 | S9: 1556809 | T9: 144679.97 | U9: 0 | V9: 0 | W9: 0 | X9: 0.20797808 | Y9: 6612.7934 | Z9: 0.046637695 | AA9: SEQUENTIAL | AB9: 0.083333333 | AC9: -0.0033623052 | AD9: 43906 | AE9: 1.0031878 | AF9: 1.0031878 | AG9: 0 | AH9: 6633.8736 | AI9: 6633.8736 | AJ9: 1701488.9 | AK9: 43906 | AL9: 43906 | AM9: 43936 | AN9: 43936 | AO9: 2000000 | AP9: 2000000 | AQ9: 0 | AR9: 0 | AS9: 0 | AT9: 0.20797808 | AU9: 0.47516318 | AV9: 7772.9491 | AW9: 0.046637695 | AX9: SEQUENTIAL | AY9: 0.083333333 | AZ9: -0.0033623052 | BA9: 43906 | BB9: 1.0031878 | BC9: 1.0031878 | BD9: 0 | BE9: 7797.7276 | BF9: 7797.7276 | BG9: 2000000 | BH9: 43906 | BI9: 43906 | BJ9: 43936 | BK9: 43936 | BL9: 2796185 | BM9: 2696614.6 | BN9: 0 | BO9: 99570.37 | BP9: 99570.37 | BQ9: 0.47516318 | BR9: 0.8354108 | BS9: 10867.302 | BT9: 0.046637695 | BU9: SEQUENTIAL | BV9: 0.083333333 | BW9: -0.0033623052 | BX9: 43906 | BY9: 1.0031878 | BZ9: 1.0031878 | CA9: 0 | CB9: 110789.72 | CC9: 110789.72 | CD9: 2796185 | CE9: #N/A | CF9: #N/A | CG9: #N/A | CH9: #N/A | CI9: #N/A | CJ9: #N/A | CK9: #N/A | CL9: #N/A | CM9: #N/A | CN9: #N/A
B10: 3 | C10: 7485447.3 | D10: 7330705.3 | E10: 13042.498 | F10: 0 | G10: 85019.748 | H10: 0 | I10: 141699.58 | J10: 311893.64 | K10: 584890.63 | L10: 584890.63 | M10: 350934.38 | N10: 43936 | O10: 43936 | P10: 43966 | Q10: 43966 | R10: 1556809 | S10: 1415109.4 | T10: 141699.58 | U10: 0 | V10: 0 | W10: 0 | X10: 0.19303864 | Y10: 6058.6017 | Z10: 0.046700155 | AA10: SEQUENTIAL | AB10: 0.083333333 | AC10: -0.0032998447 | AD10: 43936 | AE10: 1.0034691 | AF10: 1.0034691 | AG10: 0 | AH10: 6079.6198 | AI10: 6079.6198 | AJ10: 1556809 | AK10: 43936 | AL10: 43936 | AM10: 43966 | AN10: 43966 | AO10: 2000000 | AP10: 2000000 | AQ10: 0 | AR10: 0 | AS10: 0 | AT10: 0.19303864 | AU10: 0.46586369 | AV10: 7783.3592 | AW10: 0.046700155 | AX10: SEQUENTIAL | AY10: 0.083333333 | AZ10: -0.0032998447 | BA10: 43936 | BB10: 1.0034691 | BC10: 1.0034691 | BD10: 0 | BE10: 7810.3608 | BF10: 7810.3608 | BG10: 2000000 | BH10: 43936 | BI10: 43936 | BJ10: 43966 | BK10: 43966 | BL10: 2696614.6 | BM10: 2598552.3 | BN10: 0 | BO10: 98062.246 | BP10: 98062.246 | BQ10: 0.46586369 | BR10: 0.82033877 | BS10: 10494.36 | BT10: 0.046700155 | BU10: SEQUENTIAL | BV10: 0.083333333 | BW10: -0.0032998447 | BX10: 43936 | BY10: 1.0034691 | BZ10: 1.0034691 | CA10: 0 | CB10: 108933.2 | CC10: 108933.2 | CD10: 2696614.6 | CE10: #N/A | CF10: #N/A | CG10: #N/A | CH10: #N/A | CI10: #N/A | CJ10: #N/A | CK10: #N/A | CL10: #N/A | CM10: #N/A | CN10: #N/A
B11: 4 | C11: 7330705.3 | D11: 7178606.2 | E11: 13328.754 | F11: 0 | G11: 83262.187 | H11: 0 | I11: 138770.31 | J11: 305446.05 | K11: 723660.94 | L11: 723660.94 | M11: 434196.56 | N11: 43966 | O11: 43966 | P11: 43997 | Q11: 43997 | R11: 1415109.4 | S11: 1276339.1 | T11: 138770.31 | U11: 0 | V11: 0 | W11: 0 | X11: 0.17779762 | Y11: 5698.7335 | Z11: 0.046765884 | AA11: SEQUENTIAL | AB11: 0.086111111 | AC11: -0.003234116 | AD11: 43966 | AE11: 1.0037596 | AF11: 1.0037596 | AG11: 0 | AH11: 5720.1586 | AI11: 5720.1586 | AJ11: 1415109.4 | AK11: 43966 | AL11: 43966 | AM11: 43997 | AN11: 43997 | AO11: 2000000 | AP11: 2000000 | AQ11: 0 | AR11: 0 | AS11: 0 | AT11: 0.17779762 | AU11: 0.45640323 | AV11: 8054.1245 | AW11: 0.046765884 | AX11: SEQUENTIAL | AY11: 0.086111111 | AZ11: -0.003234116 | BA11: 43966 | BB11: 1.0037596 | BC11: 1.0037596 | BD11: 0 | BE11: 8084.4049 | BF11: 8084.4049 | BG11: 2000000 | BH11: 43966 | BI11: 43966 | BJ11: 43997 | BK11: 43997 | BL11: 2598552.3 | BM11: 2501961.4 | BN11: 0 | BO11: 96590.941 | BP11: 96590.941 | BQ11: 0.45640323 | BR11: 0.80493348 | BS11: 10464.532 | BT11: 0.046765884 | BU11: SEQUENTIAL | BV11: 0.086111111 | BW11: -0.003234116 | BX11: 43966 | BY11: 1.0037596 | BZ11: 1.0037596 | CA11: 0 | CB11: 107457.96 | CC11: 107457.96 | CD11: 2598552.3 | CE11: #N/A | CF11: #N/A | CG11: #N/A | CH11: #N/A | CI11: #N/A | CJ11: #N/A | CK11: #N/A | CL11: #N/A | CM11: #N/A | CN11: #N/A
B12: 5 | C12: 7178606.2 | D12: 7029093.8 | E12: 13621.292 | F12: 0 | G12: 81534.645 | H12: 0 | I12: 135891.07 | J12: 299108.59 | K12: 859552.01 | L12: 859552.01 | M12: 515731.21 | N12: 43997 | O12: 43997 | P12: 44027 | Q12: 44027 | R12: 1276339.1 | S12: 1140448 | T12: 135891.07 | U12: 0 | V12: 0 | W12: 0 | X12: 0.1622468 | Y12: 4982.3313 | Z12: 0.046843333 | AA12: SEQUENTIAL | AB12: 0.083333333 | AC12: -0.0031566673 | AD12: 43997 | AE12: 1.0040302 | AF12: 1.0040302 | AG12: 0 | AH12: 5002.4109 | AI12: 5002.4109 | AJ12: 1276339.1 | AK12: 43997 | AL12: 43997 | AM12: 44027 | AN12: 44027 | AO12: 2000000 | AP12: 2000000 | AQ12: 0 | AR12: 0 | AS12: 0 | AT12: 0.1622468 | AU12: 0.4467785 | AV12: 7807.2221 | AW12: 0.046843333 | AX12: SEQUENTIAL | AY12: 0.083333333 | AZ12: -0.0031566673 | BA12: 43997 | BB12: 1.0040302 | BC12: 1.0040302 | BD12: 0 | BE12: 7838.6865 | BF12: 7838.6865 | BG12: 2000000 | BH12: 43997 | BI12: 43997 | BJ12: 44027 | BK12: 44027 | BL12: 2501961.4 | BM12: 2406805.5 | BN12: 0 | BO12: 95155.937 | BP12: 95155.937 | BQ12: 0.4467785 | BR12: 0.78918472 | BS12: 9766.6842 | BT12: 0.046843333 | BU12: SEQUENTIAL | BV12: 0.083333333 | BW12: -0.0031566673 | BX12: 43997 | BY12: 1.0040302 | BZ12: 1.0040302 | CA12: 0 | CB12: 105345.48 | CC12: 105345.48 | CD12: 2501961.4 | CE12: #N/A | CF12: #N/A | CG12: #N/A | CH12: #N/A | CI12: #N/A | CJ12: #N/A | CK12: #N/A | CL12: #N/A | CM12: #N/A | CN12: #N/A
B13: 6 | C13: 7029093.8 | D13: 6882112.8 | E13: 13920.251 | F13: 0 | G13: 79836.483 | H13: 0 | I13: 133060.8 | J13: 292878.91 | K13: 992612.82 | L13: 992612.82 | M13: 595567.69 | N13: 44027 | O13: 44027 | P13: 44060 | Q13: 44060 | R13: 1140448 | S13: 1007387.2 | T13: 133060.8 | U13: 0 | V13: 0 | W13: 0 | X13: 0.1463776 | Y13: 4905.7384 | Z13: 0.046926424 | AA13: SEQUENTIAL | AB13: 0.091666667 | AC13: -0.0030735761 | AD13: 44027 | AE13: 1.004317 | AF13: 1.004317 | AG13: 0 | AH13: 4926.9165 | AI13: 4926.9165 | AJ13: 1140448 | AK13: 44027 | AL13: 44027 | AM13: 44060 | AN13: 44060 | AO13: 2000000 | AP13: 2000000 | AQ13: 0 | AR13: 0 | AS13: 0 | AT13: 0.1463776 | AU13: 0.43698604 | AV13: 8603.1777 | AW13: 0.046926424 | AX13: SEQUENTIAL | AY13: 0.091666667 | AZ13: -0.0030735761 | BA13: 44027 | BB13: 1.004317 | BC13: 1.004317 | BD13: 0 | BE13: 8640.3178 | BF13: 8640.3178 | BG13: 2000000 | BH13: 44027 | BI13: 44027 | BJ13: 44060 | BK13: 44060 | BL13: 2406805.5 | BM13: 2313048.7 | BN13: 0 | BO13: 93756.734 | BP13: 93756.734 | BQ13: 0.43698604 | BR13: 0.77308177 | BS13: 10353.088 | BT13: 0.046926424 | BU13: SEQUENTIAL | BV13: 0.091666667 | BW13: -0.0030735761 | BX13: 44027 | BY13: 1.004317 | BZ13: 1.004317 | CA13: 0 | CB13: 104559.27 | CC13: 104559.27 | CD13: 2406805.5 | CE13: #N/A | CF13: #N/A | CG13: #N/A | CH13: #N/A | CI13: #N/A | CJ13: #N/A | CK13: #N/A | CL13: #N/A | CM13: #N/A | CN13: #N/A
B14: 7 | C14: 6882112.8 | D14: 6737608.6 | E14: 14225.771 | F14: 0 | G14: 78167.071 | H14: 0 | I14: 130278.45 | J14: 286754.7 | K14: 1122891.3 | L14: 1122891.3 | M14: 673734.76 | N14: 44060 | O14: 44060 | P14: 44089 | Q14: 44089 | R14: 1007387.2 | S14: 877108.73 | T14: 130278.45 | U14: 0 | V14: 0 | W14: 0 | X14: 0.13018102 | Y14: 3815.4368 | Z14: 0.047016722 | AA14: SEQUENTIAL | AB14: 0.080555556 | AC14: -0.0029832777 | AD14: 44060 | AE14: 1.004564 | AF14: 1.004564 | AG14: 0 | AH14: 3832.8506 | AI14: 3832.8506 | AJ14: 1007387.2 | AK14: 44060 | AL14: 44060 | AM14: 44089 | AN14: 44089 | AO14: 2000000 | AP14: 2000000 | AQ14: 0 | AR14: 0 | AS14: 0 | AT14: 0.13018102 | AU14: 0.42702225 | AV14: 7574.9164 | AW14: 0.047016722 | AX14: SEQUENTIAL | AY14: 0.080555556 | AZ14: -0.0029832777 | BA14: 44060 | BB14: 1.004564 | BC14: 1.004564 | BD14: 0 | BE14: 7609.4885 | BF14: 7609.4885 | BG14: 2000000 | BH14: 44060 | BI14: 44060 | BJ14: 44089 | BK14: 44089 | BL14: 2313048.7 | BM14: 2220655.9 | BN14: 0 | BO14: 92392.842 | BP14: 92392.842 | BQ14: 0.42702225 | BR14: 0.75661336 | BS14: 8760.5754 | BT14: 0.047016722 | BU14: SEQUENTIAL | BV14: 0.080555556 | BW14: -0.0029832777 | BX14: 44060 | BY14: 1.004564 | BZ14: 1.004564 | CA14: 0 | CB14: 101615.09 | CC14: 101615.09 | CD14: 2313048.7 | CE14: #N/A | CF14: #N/A | CG14: #N/A | CH14: #N/A | CI14: #N/A | CJ14: #N/A | CK14: #N/A | CL14: #N/A | CM14: #N/A | CN14: #N/A
B15: 8 | C15: 6737608.6 | D15: 6595527.6 | E15: 14537.997 | F15: 0 | G15: 76525.791 | H15: 0 | I15: 127542.99 | J15: 280733.69 | K15: 1250434.3 | L15: 1250434.3 | M15: 750260.55 | N15: 44089 | O15: 44089 | P15: 44119 | Q15: 44119 | R15: 877108.73 | S15: 749565.75 | T15: 127542.99 | U15: 0 | V15: 0 | W15: 0 | X15: 0.11364758 | Y15: 3442.2554 | Z15: 0.047094577 | AA15: SEQUENTIAL | AB15: 0.083333333 | AC15: -0.0029054235 | AD15: 44089 | AE15: 1.0048147 | AF15: 1.0048147 | AG15: 0 | AH15: 3458.8286 | AI15: 3458.8286 | AJ15: 877108.73 | AK15: 44089 | AL15: 44089 | AM15: 44119 | AN15: 44119 | AO15: 2000000 | AP15: 2000000 | AQ15: 0 | AR15: 0 | AS15: 0 | AT15: 0.11364758 | AU15: 0.41688337 | AV15: 7849.0961 | AW15: 0.047094577 | AX15: SEQUENTIAL | AY15: 0.083333333 | AZ15: -0.0029054235 | BA15: 44089 | BB15: 1.0048147 | BC15: 1.0048147 | BD15: 0 | BE15: 7886.8867 | BF15: 7886.8867 | BG15: 2000000 | BH15: 44089 | BI15: 44089 | BJ15: 44119 | BK15: 44119 | BL15: 2220655.9 | BM15: 2129592.1 | BN15: 0 | BO15: 91063.789 | BP15: 91063.789 | BQ15: 0.41688337 | BR15: 0.73976764 | BS15: 8715.0707 | BT15: 0.047094577 | BU15: SEQUENTIAL | BV15: 0.083333333 | BW15: -0.0029054235 | BX15: 44089 | BY15: 1.0048147 | BZ15: 1.0048147 | CA15: 0 | CB15: 100259.26 | CC15: 100259.26 | CD15: 2220655.9 | CE15: #N/A | CF15: #N/A | CG15: #N/A | CH15: #N/A | CI15: #N/A | CJ15: #N/A | CK15: #N/A | CL15: #N/A | CM15: #N/A | CN15: #N/A
B16: 9 | C16: 6595527.6 | D16: 6455817.1 | E16: 14857.076 | F16: 0 | G16: 74912.035 | H16: 0 | I16: 124853.39 | J16: 274813.65 | K16: 1375287.6 | L16: 1375287.6 | M16: 825172.59 | N16: 44119 | O16: 44119 | P16: 44151 | Q16: 44151 | R16: 749565.75 | S16: 624712.35 | T16: 124853.39 | U16: 0 | V16: 0 | W16: 0 | X16: 0.096767356 | Y16: 3143.1694 | Z16: 0.047174856 | AA16: SEQUENTIAL | AB16: 0.088888889 | AC16: -0.0028251438 | AD16: 44119 | AE16: 1.0050753 | AF16: 1.0050753 | AG16: 0 | AH16: 3159.1219 | AI16: 3159.1219 | AJ16: 749565.75 | AK16: 44119 | AL16: 44119 | AM16: 44151 | AN16: 44151 | AO16: 2000000 | AP16: 2000000 | AQ16: 0 | AR16: 0 | AS16: 0 | AT16: 0.096767356 | AU16: 0.40656548 | AV16: 8386.6411 | AW16: 0.047174856 | AX16: SEQUENTIAL | AY16: 0.088888889 | AZ16: -0.0028251438 | BA16: 44119 | BB16: 1.0050753 | BC16: 1.0050753 | BD16: 0 | BE16: 8429.2056 | BF16: 8429.2056 | BG16: 2000000 | BH16: 44119 | BI16: 44119 | BJ16: 44151 | BK16: 44151 | BL16: 2129592.1 | BM16: 2039823 | BN16: 0 | BO16: 89769.111 | BP16: 89769.111 | BQ16: 0.40656548 | BR16: 0.72253214 | BS16: 8930.0623 | BT16: 0.047174856 | BU16: SEQUENTIAL | BV16: 0.088888889 | BW16: -0.0028251438 | BX16: 44119 | BY16: 1.0050753 | BZ16: 1.0050753 | CA16: 0 | CB16: 99200.098 | CC16: 99200.098 | CD16: 2129592.1 | CE16: #N/A | CF16: #N/A | CG16: #N/A | CH16: #N/A | CI16: #N/A | CJ16: #N/A | CK16: #N/A | CL16: #N/A | CM16: #N/A | CN16: #N/A
B17: 10 | C17: 6455817.1 | D17: 6318425.3 | E17: 15183.158 | F17: 0 | G17: 73325.203 | H17: 0 | I17: 122208.67 | J17: 268992.38 | K17: 1497496.3 | L17: 1497496.3 | M17: 898497.79 | N17: 44151 | O17: 44151 | P17: 44180 | Q17: 44180 | R17: 624712.35 | S17: 502503.68 | T17: 122208.67 | U17: 0 | V17: 0 | W17: 0 | X17: 0.079529893 | Y17: 2378.4207 | Z17: 0.047262107 | AA17: SEQUENTIAL | AB17: 0.080555556 | AC17: -0.002737893 | AD17: 44151 | AE17: 1.0053046 | AF17: 1.0053046 | AG17: 0 | AH17: 2391.0371 | AI17: 2391.0371 | AJ17: 624712.35 | AK17: 44151 | AL17: 44151 | AM17: 44180 | AN17: 44180 | AO17: 2000000 | AP17: 2000000 | AQ17: 0 | AR17: 0 | AS17: 0 | AT17: 0.079529893 | AU17: 0.39606446 | AV17: 7614.4506 | AW17: 0.047262107 | AX17: SEQUENTIAL | AY17: 0.080555556 | AZ17: -0.002737893 | BA17: 44151 | BB17: 1.0053046 | BC17: 1.0053046 | BD17: 0 | BE17: 7654.8418 | BF17: 7654.8418 | BG17: 2000000 | BH17: 44151 | BI17: 44151 | BJ17: 44180 | BK17: 44180 | BL17: 2039823 | BM17: 1951314.6 | BN17: 0 | BO17: 88508.36 | BP17: 88508.36 | BQ17: 0.39606446 | BR17: 0.70489372 | BS17: 7766.0657 | BT17: 0.047262107 | BU17: SEQUENTIAL | BV17: 0.080555556 | BW17: -0.002737893 | BX17: 44151 | BY17: 1.0053046 | BZ17: 1.0053046 | CA17: 0 | CB17: 96785.118 | CC17: 96785.118 | CD17: 2039823 | CE17: #N/A | CF17: #N/A | CG17: #N/A | CH17: #N/A | CI17: #N/A | CJ17: #N/A | CK17: #N/A | CL17: #N/A | CM17: #N/A | CN17: #N/A
B18: 11 | C18: 6318425.3 | D18: 6183301 | E18: 15516.396 | F18: 0 | G18: 71764.706 | H18: 0 | I18: 119607.84 | J18: 263267.72 | K18: 1617104.2 | L18: 1617104.2 | M18: 970262.5 | N18: 44180 | O18: 44180 | P18: 44211 | Q18: 44211 | R18: 502503.68 | S18: 382895.84 | T18: 119607.84 | U18: 0 | V18: 0 | W18: 0 | X18: 0.061924179 | Y18: 2048.6371 | Z18: 0.047344179 | AA18: SEQUENTIAL | AB18: 0.086111111 | AC18: -0.0026558211 | AD18: 44180 | AE18: 1.0055421 | AF18: 1.0055421 | AG18: 0 | AH18: 2059.9908 | AI18: 2059.9908 | AJ18: 502503.68 | AK18: 44180 | AL18: 44180 | AM18: 44211 | AN18: 44211 | AO18: 2000000 | AP18: 2000000 | AQ18: 0 | AR18: 0 | AS18: 0 | AT18: 0.061924179 | AU18: 0.385376 | AV18: 8153.7197 | AW18: 0.047344179 | AX18: SEQUENTIAL | AY18: 0.086111111 | AZ18: -0.0026558211 | BA18: 44180 | BB18: 1.0055421 | BC18: 1.0055421 | BD18: 0 | BE18: 8198.9084 | BF18: 8198.9084 | BG18: 2000000 | BH18: 44180 | BI18: 44180 | BJ18: 44211 | BK18: 44211 | BL18: 1951314.6 | BM18: 1864033.5 | BN18: 0 | BO18: 87281.102 | BP18: 87281.102 | BQ18: 0.385376 | BR18: 0.68683853 | BS18: 7955.2363 | BT18: 0.047344179 | BU18: SEQUENTIAL | BV18: 0.086111111 | BW18: -0.0026558211 | BX18: 44180 | BY18: 1.0055421 | BZ18: 1.0055421 | CA18: 0 | CB18: 95764.147 | CC18: 95764.147 | CD18: 1951314.6 | CE18: #N/A | CF18: #N/A | CG18: #N/A | CH18: #N/A | CI18: #N/A | CJ18: #N/A | CK18: #N/A | CL18: #N/A | CM18: #N/A | CN18: #N/A
... B105: 98 | C105: 121254.03 | D105: 109323.05 | E105: 9635.6471 | F105: 0 | G105: 1377.2039 | H105: 0 | I105: 2295.3399 | J105: 5052.2515 | K105: 5425235.3 | L105: 5425235.3 | M105: 3255141.2 | N105: 46827 | O105: 46827 | P105: 46861 | Q105: 46861 | R105: 0 | S105: 0 | T105: 0 | U105: 0 | V105: 0 | W105: 0 | X105: 0 | Y105: 0 | Z105: 0.060674319 | AA105: SEQUENTIAL | AB105: 0.094444444 | AC105: 0.010674319 | AD105: 46827 | AE105: 0.97795407 | AF105: 0.97795407 | AG105: 0 | AH105: 0 | AI105: 0 | AJ105: 0 | AK105: 46827 | AL105: 46827 | AM105: 46861 | AN105: 46861 | AO105: 0 | AP105: 0 | AQ105: 0 | AR105: 0 | AS105: 0 | AT105: 0 | AU105: 0 | AV105: 0 | AW105: 0.060674319 | AX105: SEQUENTIAL | AY105: 0.094444444 | AZ105: 0.010674319 | BA105: 46827 | BB105: 0.97795407 | BC105: 0.97795407 | BD105: 0 | BE105: 0 | BF105: 0 | BG105: 0 | BH105: 46827 | BI105: 46827 | BJ105: 46861 | BK105: 46861 | BL105: 0 | BM105: 0 | BN105: 0 | BO105: 0 | BP105: 0 | BQ105: 0 | BR105: 0 | BS105: 0 | BT105: 0.060674319 | BU105: SEQUENTIAL | BV105: 0.094444444 | BW105: 0.010674319 | BX105: 46827 | BY105: 0.97795407 | BZ105: 0.97795407 | CA105: 0 | CB105: 0 | CC105: 0 | CD105: 0 | CE105: #N/A | CF105: #N/A | CG105: #N/A | CH105: #N/A | CI105: #N/A | CJ105: #N/A | CK105: #N/A | CL105: #N/A | CM105: #N/A | CN105: #N/A
B106: #N/A | C106: #N/A | D106: #N/A | E106: #N/A | F106: #N/A | G106: #N/A | H106: #N/A | I106: #N/A | J106: #N/A | K106: #N/A | L106: #N/A | M106: #N/A | N106: #N/A | O106: #N/A | P106: #N/A | Q106: #N/A | R106: #N/A | S106: #N/A | T106: #N/A | U106: #N/A | V106: #N/A | W106: #N/A | X106: #N/A | Y106: #N/A | Z106: #N/A | AA106: #N/A | AB106: #N/A | AC106: #N/A | AD106: #N/A | AE106: #N/A | AF106: #N/A | AG106: #N/A | AH106: #N/A | AI106: #N/A | AJ106: #N/A | AK106: #N/A | AL106: #N/A | AM106: #N/A | AN106: #N/A | AO106: #N/A | AP106: #N/A | AQ106: #N/A | AR106: #N/A | AS106: #N/A | AT106: #N/A | AU106: #N/A | AV106: #N/A | AW106: #N/A | AX106: #N/A | AY106: #N/A | AZ106: #N/A | BA106: #N/A | BB106: #N/A | BC106: #N/A | BD106: #N/A | BE106: #N/A | BF106: #N/A | BG106: #N/A | BH106: #N/A | BI106: #N/A | BJ106: #N/A | BK106: #N/A | BL106: #N/A | BM106: #N/A | BN106: #N/A | BO106: #N/A | BP106: #N/A | BQ106: #N/A | BR106: #N/A | BS106: #N/A | BT106: #N/A | BU106: #N/A | BV106: #N/A | BW106: #N/A | BX106: #N/A | BY106: #N/A | BZ106: #N/A | CA106: #N/A | CB106: #N/A | CC106: #N/A | CD106: #N/A | CE106: #N/A | CF106: #N/A | CG106: #N/A | CH106: #N/A | CI106: #N/A | CJ106: #N/A | CK106: #N/A | CL106: #N/A | CM106: #N/A | CN106: #N/A
B107: #N/A | C107: #N/A | D107: #N/A | E107: #N/A | F107: #N/A | G107: #N/A | H107: #N/A | I107: #N/A | J107: #N/A | K107: #N/A | L107: #N/A | M107: #N/A | N107: #N/A | O107: #N/A | P107: #N/A | Q107: #N/A | R107: #N/A | S107: #N/A | T107: #N/A | U107: #N/A | V107: #N/A | W107: #N/A | X107: #N/A | Y107: #N/A | Z107: #N/A | AA107: #N/A | AB107: #N/A | AC107: #N/A | AD107: #N/A | AE107: #N/A | AF107: #N/A | AG107: #N/A | AH107: #N/A | AI107: #N/A | AJ107: #N/A | AK107: #N/A | AL107: #N/A | AM107: #N/A | AN107: #N/A | AO107: #N/A | AP107: #N/A | AQ107: #N/A | AR107: #N/A | AS107: #N/A | AT107: #N/A | AU107: #N/A | AV107: #N/A | AW107: #N/A | AX107: #N/A | AY107: #N/A | AZ107: #N/A | BA107: #N/A | BB107: #N/A | BC107: #N/A | BD107: #N/A | BE107: #N/A | BF107: #N/A | BG107: #N/A | BH107: #N/A | BI107: #N/A | BJ107: #N/A | BK107: #N/A | BL107: #N/A | BM107: #N/A | BN107: #N/A | BO107: #N/A | BP107: #N/A | BQ107: #N/A | BR107: #N/A | BS107: #N/A | BT107: #N/A | BU107: #N/A | BV107: #N/A | BW107: #N/A | BX107: #N/A | BY107: #N/A | BZ107: #N/A | CA107: #N/A | CB107: #N/A | CC107: #N/A | CD107: #N/A | CE107: #N/A | CF107: #N/A | CG107: #N/A | CH107: #N/A | CI107: #N/A | CJ107: #N/A | CK107: #N/A | CL107: #N/A | CM107: #N/A | CN107: #N/A
B108: #N/A | C108: #N/A | D108: #N/A | E108: #N/A | F108: #N/A | G108: #N/A | H108: #N/A | I108: #N/A | J108: #N/A | K108: #N/A | L108: #N/A | M108: #N/A | N108: #N/A | O108: #N/A | P108: #N/A | Q108: #N/A | R108: #N/A | S108: #N/A | T108: #N/A | U108: #N/A | V108: #N/A | W108: #N/A | X108: #N/A | Y108: #N/A | Z108: #N/A | AA108: #N/A | AB108: #N/A | AC108: #N/A | AD108: #N/A | AE108: #N/A | AF108: #N/A | AG108: #N/A | AH108: #N/A | AI108: #N/A | AJ108: #N/A | AK108: #N/A | AL108: #N/A | AM108: #N/A | AN108: #N/A | AO108: #N/A | AP108: #N/A | AQ108: #N/A | AR108: #N/A | AS108: #N/A | AT108: #N/A | AU108: #N/A | AV108: #N/A | AW108: #N/A | AX108: #N/A | AY108: #N/A | AZ108: #N/A | BA108: #N/A | BB108: #N/A | BC108: #N/A | BD108: #N/A | BE108: #N/A | BF108: #N/A | BG108: #N/A | BH108: #N/A | BI108: #N/A | BJ108: #N/A | BK108: #N/A | BL108: #N/A | BM108: #N/A | BN108: #N/A | BO108: #N/A | BP108: #N/A | BQ108: #N/A | BR108: #N/A | BS108: #N/A | BT108: #N/A | BU108: #N/A | BV108: #N/A | BW108: #N/A | BX108: #N/A | BY108: #N/A | BZ108: #N/A | CA108: #N/A | CB108: #N/A | CC108: #N/A | CD108: #N/A | CE108: #N/A | CF108: #N/A | CG108: #N/A | CH108: #N/A | CI108: #N/A | CJ108: #N/A | CK108: #N/A | CL108: #N/A | CM108: #N/A | CN108: #N/A
B109: #N/A | C109: #N/A | D109: #N/A | E109: #N/A | F109: #N/A | G109: #N/A | H109: #N/A | I109: #N/A | J109: #N/A | K109: #N/A | L109: #N/A | M109: #N/A | N109: #N/A | O109: #N/A | P109: #N/A | Q109: #N/A | R109: #N/A | S109: #N/A | T109: #N/A | U109: #N/A | V109: #N/A | W109: #N/A | X109: #N/A | Y109: #N/A | Z109: #N/A | AA109: #N/A | AB109: #N/A | AC109: #N/A | AD109: #N/A | AE109: #N/A | AF109: #N/A | AG109: #N/A | AH109: #N/A | AI109: #N/A | AJ109: #N/A | AK109: #N/A | AL109: #N/A | AM109: #N/A | AN109: #N/A | AO109: #N/A | AP109: #N/A | AQ109: #N/A | AR109: #N/A | AS109: #N/A | AT109: #N/A | AU109: #N/A | AV109: #N/A | AW109: #N/A | AX109: #N/A | AY109: #N/A | AZ109: #N/A | BA109: #N/A | BB109: #N/A | BC109: #N/A | BD109: #N/A | BE109: #N/A | BF109: #N/A | BG109: #N/A | BH109: #N/A | BI109: #N/A | BJ109: #N/A | BK109: #N/A | BL109: #N/A | BM109: #N/A | BN109: #N/A | BO109: #N/A | BP109: #N/A | BQ109: #N/A | BR109: #N/A | BS109: #N/A | BT109: #N/A | BU109: #N/A | BV109: #N/A | BW109: #N/A | BX109: #N/A | BY109: #N/A | BZ109: #N/A | CA109: #N/A | CB109: #N/A | CC109: #N/A | CD109: #N/A | CE109: #N/A | CF109: #N/A | CG109: #N/A | CH109: #N/A | CI109: #N/A | CJ109: #N/A | CK109: #N/A | CL109: #N/A | CM109: #N/A | CN109: #N/A
B110: #N/A | C110: #N/A | D110: #N/A | E110: #N/A | F110: #N/A | G110: #N/A | H110: #N/A | I110: #N/A | J110: #N/A | K110: #N/A | L110: #N/A | M110: #N/A | N110: #N/A | O110: #N/A | P110: #N/A | Q110: #N/A | R110: #N/A | S110: #N/A | T110: #N/A | U110: #N/A | V110: #N/A | W110: #N/A | X110: #N/A | Y110: #N/A | Z110: #N/A | AA110: #N/A | AB110: #N/A | AC110: #N/A | AD110: #N/A | AE110: #N/A | AF110: #N/A | AG110: #N/A | AH110: #N/A | AI110: #N/A | AJ110: #N/A | AK110: #N/A | AL110: #N/A | AM110: #N/A | AN110: #N/A | AO110: #N/A | AP110: #N/A | AQ110: #N/A | AR110: #N/A | AS110: #N/A | AT110: #N/A | AU110: #N/A | AV110: #N/A | AW110: #N/A | AX110: #N/A | AY110: #N/A | AZ110: #N/A | BA110: #N/A | BB110: #N/A | BC110: #N/A | BD110: #N/A | BE110: #N/A | BF110: #N/A | BG110: #N/A | BH110: #N/A | BI110: #N/A | BJ110: #N/A | BK110: #N/A | BL110: #N/A | BM110: #N/A | BN110: #N/A | BO110: #N/A | BP110: #N/A | BQ110: #N/A | BR110: #N/A | BS110: #N/A | BT110: #N/A | BU110: #N/A | BV110: #N/A | BW110: #N/A | BX110: #N/A | BY110: #N/A | BZ110: #N/A | CA110: #N/A | CB110: #N/A | CC110: #N/A | CD110: #N/A | CE110: #N/A | CF110: #N/A | CG110: #N/A | CH110: #N/A | CI110: #N/A | CJ110: #N/A | CK110: #N/A | CL110: #N/A | CM110: #N/A | CN110: #N/A
B111: #N/A | C111: #N/A | D111: #N/A | E111: #N/A | F111: #N/A | G111: #N/A | H111: #N/A | I111: #N/A | J111: #N/A | K111: #N/A | L111: #N/A | M111: #N/A | N111: #N/A | O111: #N/A | P111: #N/A | Q111: #N/A | R111: #N/A | S111: #N/A | T111: #N/A | U111: #N/A | V111: #N/A | W111: #N/A | X111: #N/A | Y111: #N/A | Z111: #N/A | AA111: #N/A | AB111: #N/A | AC111: #N/A | AD111: #N/A | AE111: #N/A | AF111: #N/A | AG111: #N/A | AH111: #N/A | AI111: #N/A | AJ111: #N/A | AK111: #N/A | AL111: #N/A | AM111: #N/A | AN111: #N/A | AO111: #N/A | AP111: #N/A | AQ111: #N/A | AR111: #N/A | AS111: #N/A | AT111: #N/A | AU111: #N/A | AV111: #N/A | AW111: #N/A | AX111: #N/A | AY111: #N/A | AZ111: #N/A | BA111: #N/A | BB111: #N/A | BC111: #N/A | BD111: #N/A | BE111: #N/A | BF111: #N/A | BG111: #N/A | BH111: #N/A | BI111: #N/A | BJ111: #N/A | BK111: #N/A | BL111: #N/A | BM111: #N/A | BN111: #N/A | BO111: #N/A | BP111: #N/A | BQ111: #N/A | BR111: #N/A | BS111: #N/A | BT111: #N/A | BU111: #N/A | BV111: #N/A | BW111: #N/A | BX111: #N/A | BY111: #N/A | BZ111: #N/A | CA111: #N/A | CB111: #N/A | CC111: #N/A | CD111: #N/A | CE111: #N/A | CF111: #N/A | CG111: #N/A | CH111: #N/A | CI111: #N/A | CJ111: #N/A | CK111: #N/A | CL111: #N/A | CM111: #N/A | CN111: #N/A
B112: #N/A | C112: #N/A | D112: #N/A | E112: #N/A | F112: #N/A | G112: #N/A | H112: #N/A | I112: #N/A | J112: #N/A | K112: #N/A | L112: #N/A | M112: #N/A | N112: #N/A | O112: #N/A | P112: #N/A | Q112: #N/A | R112: #N/A | S112: #N/A | T112: #N/A | U112: #N/A | V112: #N/A | W112: #N/A | X112: #N/A | Y112: #N/A | Z112: #N/A | AA112: #N/A | AB112: #N/A | AC112: #N/A | AD112: #N/A | AE112: #N/A | AF112: #N/A | AG112: #N/A | AH112: #N/A | AI112: #N/A | AJ112: #N/A | AK112: #N/A | AL112: #N/A | AM112: #N/A | AN112: #N/A | AO112: #N/A | AP112: #N/A | AQ112: #N/A | AR112: #N/A | AS112: #N/A | AT112: #N/A | AU112: #N/A | AV112: #N/A | AW112: #N/A | AX112: #N/A | AY112: #N/A | AZ112: #N/A | BA112: #N/A | BB112: #N/A | BC112: #N/A | BD112: #N/A | BE112: #N/A | BF112: #N/A | BG112: #N/A | BH112: #N/A | BI112: #N/A | BJ112: #N/A | BK112: #N/A | BL112: #N/A | BM112: #N/A | BN112: #N/A | BO112: #N/A | BP112: #N/A | BQ112: #N/A | BR112: #N/A | BS112: #N/A | BT112: #N/A | BU112: #N/A | BV112: #N/A | BW112: #N/A | BX112: #N/A | BY112: #N/A | BZ112: #N/A | CA112: #N/A | CB112: #N/A | CC112: #N/A | CD112: #N/A | CE112: #N/A | CF112: #N/A | CG112: #N/A | CH112: #N/A | CI112: #N/A | CJ112: #N/A | CK112: #N/A | CL112: #N/A | CM112: #N/A | CN112: #N/A
B113: #N/A | C113: #N/A | D113: #N/A | E113: #N/A | F113: #N/A | G113: #N/A | H113: #N/A | I113: #N/A | J113: #N/A | K113: #N/A | L113: #N/A | M113: #N/A | N113: #N/A | O113: #N/A | P113: #N/A | Q113: #N/A | R113: #N/A | S113: #N/A | T113: #N/A | U113: #N/A | V113: #N/A | W113: #N/A | X113: #N/A | Y113: #N/A | Z113: #N/A | AA113: #N/A | AB113: #N/A | AC113: #N/A | AD113: #N/A | AE113: #N/A | AF113: #N/A | AG113: #N/A | AH113: #N/A | AI113: #N/A | AJ113: #N/A | AK113: #N/A | AL113: #N/A | AM113: #N/A | AN113: #N/A | AO113: #N/A | AP113: #N/A | AQ113: #N/A | AR113: #N/A | AS113: #N/A | AT113: #N/A | AU113: #N/A | AV113: #N/A | AW113: #N/A | AX113: #N/A | AY113: #N/A | AZ113: #N/A | BA113: #N/A | BB113: #N/A | BC113: #N/A | BD113: #N/A | BE113: #N/A | BF113: #N/A | BG113: #N/A | BH113: #N/A | BI113: #N/A | BJ113: #N/A | BK113: #N/A | BL113: #N/A | BM113: #N/A | BN113: #N/A | BO113: #N/A | BP113: #N/A | BQ113: #N/A | BR113: #N/A | BS113: #N/A | BT113: #N/A | BU113: #N/A | BV113: #N/A | BW113: #N/A | BX113: #N/A | BY113: #N/A | BZ113: #N/A | CA113: #N/A | CB113: #N/A | CC113: #N/A | CD113: #N/A | CE113: #N/A | CF113: #N/A | CG113: #N/A | CH113: #N/A | CI113: #N/A | CJ113: #N/A | CK113: #N/A | CL113: #N/A | CM113: #N/A | CN113: #N/A
B114: #N/A | C114: #N/A | D114: #N/A | E114: #N/A | F114: #N/A | G114: #N/A | H114: #N/A | I114: #N/A | J114: #N/A | K114: #N/A | L114: #N/A | M114: #N/A | N114: #N/A | O114: #N/A | P114: #N/A | Q114: #N/A | R114: #N/A | S114: #N/A | T114: #N/A | U114: #N/A | V114: #N/A | W114: #N/A | X114: #N/A | Y114: #N/A | Z114: #N/A | AA114: #N/A | AB114: #N/A | AC114: #N/A | AD114: #N/A | AE114: #N/A | AF114: #N/A | AG114: #N/A | AH114: #N/A | AI114: #N/A | AJ114: #N/A | AK114: #N/A | AL114: #N/A | AM114: #N/A | AN114: #N/A | AO114: #N/A | AP114: #N/A | AQ114: #N/A | AR114: #N/A | AS114: #N/A | AT114: #N/A | AU114: #N/A | AV114: #N/A | AW114: #N/A | AX114: #N/A | AY114: #N/A | AZ114: #N/A | BA114: #N/A | BB114: #N/A | BC114: #N/A | BD114: #N/A | BE114: #N/A | BF114: #N/A | BG114: #N/A | BH114: #N/A | BI114: #N/A | BJ114: #N/A | BK114: #N/A | BL114: #N/A | BM114: #N/A | BN114: #N/A | BO114: #N/A | BP114: #N/A | BQ114: #N/A | BR114: #N/A | BS114: #N/A | BT114: #N/A | BU114: #N/A | BV114: #N/A | BW114: #N/A | BX114: #N/A | BY114: #N/A | BZ114: #N/A | CA114: #N/A | CB114: #N/A | CC114: #N/A | CD114: #N/A | CE114: #N/A | CF114: #N/A | CG114: #N/A | CH114: #N/A | CI114: #N/A | CJ114: #N/A | CK114: #N/A | CL114: #N/A | CM114: #N/A | CN114: #N/A
B115: #N/A | C115: #N/A | D115: #N/A | E115: #N/A | F115: #N/A | G115: #N/A | H115: #N/A | I115: #N/A | J115: #N/A | K115: #N/A | L115: #N/A | M115: #N/A | N115: #N/A | O115: #N/A | P115: #N/A | Q115: #N/A | R115: #N/A | S115: #N/A | T115: #N/A | U115: #N/A | V115: #N/A | W115: #N/A | X115: #N/A | Y115: #N/A | Z115: #N/A | AA115: #N/A | AB115: #N/A | AC115: #N/A | AD115: #N/A | AE115: #N/A | AF115: #N/A | AG115: #N/A | AH115: #N/A | AI115: #N/A | AJ115: #N/A | AK115: #N/A | AL115: #N/A | AM115: #N/A | AN115: #N/A | AO115: #N/A | AP115: #N/A | AQ115: #N/A | AR115: #N/A | AS115: #N/A | AT115: #N/A | AU115: #N/A | AV115: #N/A | AW115: #N/A | AX115: #N/A | AY115: #N/A | AZ115: #N/A | BA115: #N/A | BB115: #N/A | BC115: #N/A | BD115: #N/A | BE115: #N/A | BF115: #N/A | BG115: #N/A | BH115: #N/A | BI115: #N/A | BJ115: #N/A | BK115: #N/A | BL115: #N/A | BM115: #N/A | BN115: #N/A | BO115: #N/A | BP115: #N/A | BQ115: #N/A | BR115: #N/A | BS115: #N/A | BT115: #N/A | BU115: #N/A | BV115: #N/A | BW115: #N/A | BX115: #N/A | BY115: #N/A | BZ115: #N/A | CA115: #N/A | CB115: #N/A | CC115: #N/A | CD115: #N/A | CE115: #N/A | CF115: #N/A | CG115: #N/A | CH115: #N/A | CI115: #N/A | CJ115: #N/A | CK115: #N/A | CL115: #N/A | CM115: #N/A | CN115: #N/A
B116: #N/A | C116: #N/A | D116: #N/A | E116: #N/A | F116: #N/A | G116: #N/A | H116: #N/A | I116: #N/A | J116: #N/A | K116: #N/A | L116: #N/A | M116: #N/A | N116: #N/A | O116: #N/A | P116: #N/A | Q116: #N/A | R116: #N/A | S116: #N/A | T116: #N/A | U116: #N/A | V116: #N/A | W116: #N/A | X116: #N/A | Y116: #N/A | Z116: #N/A | AA116: #N/A | AB116: #N/A | AC116: #N/A | AD116: #N/A | AE116: #N/A | AF116: #N/A | AG116: #N/A | AH116: #N/A | AI116: #N/A | AJ116: #N/A | AK116: #N/A | AL116: #N/A | AM116: #N/A | AN116: #N/A | AO116: #N/A | AP116: #N/A | AQ116: #N/A | AR116: #N/A | AS116: #N/A | AT116: #N/A | AU116: #N/A | AV116: #N/A | AW116: #N/A | AX116: #N/A | AY116: #N/A | AZ116: #N/A | BA116: #N/A | BB116: #N/A | BC116: #N/A | BD116: #N/A | BE116: #N/A | BF116: #N/A | BG116: #N/A | BH116: #N/A | BI116: #N/A | BJ116: #N/A | BK116: #N/A | BL116: #N/A | BM116: #N/A | BN116: #N/A | BO116: #N/A | BP116: #N/A | BQ116: #N/A | BR116: #N/A | BS116: #N/A | BT116: #N/A | BU116: #N/A | BV116: #N/A | BW116: #N/A | BX116: #N/A | BY116: #N/A | BZ116: #N/A | CA116: #N/A | CB116: #N/A | CC116: #N/A | CD116: #N/A | CE116: #N/A | CF116: #N/A | CG116: #N/A | CH116: #N/A | CI116: #N/A | CJ116: #N/A | CK116: #N/A | CL116: #N/A | CM116: #N/A | CN116: #N/A
B117: #N/A | C117: #N/A | D117: #N/A | E117: #N/A | F117: #N/A | G117: #N/A | H117: #N/A | I117: #N/A | J117: #N/A | K117: #N/A | L117: #N/A | M117: #N/A | N117: #N/A | O117: #N/A | P117: #N/A | Q117: #N/A | R117: #N/A | S117: #N/A | T117: #N/A | U117: #N/A | V117: #N/A | W117: #N/A | X117: #N/A | Y117: #N/A | Z117: #N/A | AA117: #N/A | AB117: #N/A | AC117: #N/A | AD117: #N/A | AE117: #N/A | AF117: #N/A | AG117: #N/A | AH117: #N/A | AI117: #N/A | AJ117: #N/A | AK117: #N/A | AL117: #N/A | AM117: #N/A | AN117: #N/A | AO117: #N/A | AP117: #N/A | AQ117: #N/A | AR117: #N/A | AS117: #N/A | AT117: #N/A | AU117: #N/A | AV117: #N/A | AW117: #N/A | AX117: #N/A | AY117: #N/A | AZ117: #N/A | BA117: #N/A | BB117: #N/A | BC117: #N/A | BD117: #N/A | BE117: #N/A | BF117: #N/A | BG117: #N/A | BH117: #N/A | BI117: #N/A | BJ117: #N/A | BK117: #N/A | BL117: #N/A | BM117: #N/A | BN117: #N/A | BO117: #N/A | BP117: #N/A | BQ117: #N/A | BR117: #N/A | BS117: #N/A | BT117: #N/A | BU117: #N/A | BV117: #N/A | BW117: #N/A | BX117: #N/A | BY117: #N/A | BZ117: #N/A | CA117: #N/A | CB117: #N/A | CC117: #N/A | CD117: #N/A | CE117: #N/A | CF117: #N/A | CG117: #N/A | CH117: #N/A | CI117: #N/A | CJ117: #N/A | CK117: #N/A | CL117: #N/A | CM117: #N/A | CN117: #N/A
... B121: #N/A | C121: #N/A | D121: #N/A | E121: #N/A | F121: #N/A | G121: #N/A | H121: #N/A | I121: #N/A | J121: #N/A | K121: #N/A | L121: #N/A | M121: #N/A | N121: #N/A | O121: #N/A | P121: #N/A | Q121: #N/A | R121: #N/A | S121: #N/A | T121: #N/A | U121: #N/A | V121: #N/A | W121: #N/A | X121: #N/A | Y121: #N/A | Z121: #N/A | AA121: #N/A | AB121: #N/A | AC121: #N/A | AD121: #N/A | AE121: #N/A | AF121: #N/A | AG121: #N/A | AH121: #N/A | AI121: #N/A | AJ121: #N/A | AK121: #N/A | AL121: #N/A | AM121: #N/A | AN121: #N/A | AO121: #N/A | AP121: #N/A | AQ121: #N/A | AR121: #N/A | AS121: #N/A | AT121: #N/A | AU121: #N/A | AV121: #N/A | AW121: #N/A | AX121: #N/A | AY121: #N/A | AZ121: #N/A | BA121: #N/A | BB121: #N/A | BC121: #N/A | BD121: #N/A | BE121: #N/A | BF121: #N/A | BG121: #N/A | BH121: #N/A | BI121: #N/A | BJ121: #N/A | BK121: #N/A | BL121: #N/A | BM121: #N/A | BN121: #N/A | BO121: #N/A | BP121: #N/A | BQ121: #N/A | BR121: #N/A | BS121: #N/A | BT121: #N/A | BU121: #N/A | BV121: #N/A | BW121: #N/A | BX121: #N/A | BY121: #N/A | BZ121: #N/A | CA121: #N/A | CB121: #N/A | CC121: #N/A | CD121: #N/A | CE121: #N/A | CF121: #N/A | CG121: #N/A | CH121: #N/A | CI121: #N/A | CJ121: #N/A | CK121: #N/A | CL121: #N/A | CM121: #N/A | CN121: #N/A

Sheet TranchePV
C2: =CashflowEngine!E7 -> EQUITY:1 | D2: =CashflowEngine!E8 -> MEZZ:1 | E2: =CashflowEngine!E9 -> SENIOR:1 | H2: Tranche PV Parameters
B3: CallPeriod | C3: PV | D3: PV | E3: PV | H3: ValuationDate | I3: =CashflowEngine!C26 -> 43858
B4: 0 | C4: =_xll.mscTrancheCalculatePV(C$2,$I$5,$I$3,$B4,$I$4) -> 1849201.5 | D4: =_xll.mscTrancheCalculatePV(D$2,$I$5,$I$3,$B4,$I$4) -> 2000000 | E4: =_xll.mscTrancheCalculatePV(E$2,$I$5,$I$3,$B4,$I$4) -> 2897300.8 | H4: Interest Rate | I4: 0.01
B5: 1 | C5: =_xll.mscTrancheCalculatePV($C$2,$I$5,$I$3,B5,$I$4) -> 1705257.8 | D5: =_xll.mscTrancheCalculatePV(D$2,$I$5,$I$3,$B5,$I$4) -> 2003521.5 | E5: =_xll.mscTrancheCalculatePV(E$2,$I$5,$I$3,$B5,$I$4) -> 2904335.3 | H5: CashflowEngine | I5: =CashflowEngine!C22 -> CAPITALSTRUCTURE:7
B6: 2 | C6: =_xll.mscTrancheCalculatePV($C$2,$I$5,$I$3,B6,$I$4) -> 1566108.5 | D6: =_xll.mscTrancheCalculatePV(D$2,$I$5,$I$3,$B6,$I$4) -> 2009111.5 | E6: =_xll.mscTrancheCalculatePV(E$2,$I$5,$I$3,$B6,$I$4) -> 2914143.7
B7: 3 | C7: =_xll.mscTrancheCalculatePV($C$2,$I$5,$I$3,B7,$I$4) -> 1430074.5 | D7: =_xll.mscTrancheCalculatePV(D$2,$I$5,$I$3,$B7,$I$4) -> 2015216.6 | E7: =_xll.mscTrancheCalculatePV(E$2,$I$5,$I$3,$B7,$I$4) -> 2924348.4
B8: 4 | C8: =_xll.mscTrancheCalculatePV($C$2,$I$5,$I$3,B8,$I$4) -> 1296637.3 | D8: =_xll.mscTrancheCalculatePV(D$2,$I$5,$I$3,$B8,$I$4) -> 2021327 | E8: =_xll.mscTrancheCalculatePV(E$2,$I$5,$I$3,$B8,$I$4) -> 2934215.7
B9: 5 | C9: =_xll.mscTrancheCalculatePV($C$2,$I$5,$I$3,B9,$I$4) -> 1165933.9 | D9: =_xll.mscTrancheCalculatePV(D$2,$I$5,$I$3,$B9,$I$4) -> 2027702.3 | E9: =_xll.mscTrancheCalculatePV(E$2,$I$5,$I$3,$B9,$I$4) -> 2944087.5
B10: 6 | C10: =_xll.mscTrancheCalculatePV($C$2,$I$5,$I$3,B10,$I$4) -> 1037553.8 | D10: =_xll.mscTrancheCalculatePV(D$2,$I$5,$I$3,$B10,$I$4) -> 2033826.4 | E10: =_xll.mscTrancheCalculatePV(E$2,$I$5,$I$3,$B10,$I$4) -> 2953298
B11: 7 | C11: =_xll.mscTrancheCalculatePV($C$2,$I$5,$I$3,B11,$I$4) -> 912079.94 | D11: =_xll.mscTrancheCalculatePV(D$2,$I$5,$I$3,$B11,$I$4) -> 2040737.4 | E11: =_xll.mscTrancheCalculatePV(E$2,$I$5,$I$3,$B11,$I$4) -> 2963125.4
B12: 8 | C12: =_xll.mscTrancheCalculatePV($C$2,$I$5,$I$3,B12,$I$4) -> 788450.78 | D12: =_xll.mscTrancheCalculatePV(D$2,$I$5,$I$3,$B12,$I$4) -> 2046620.3 | E12: =_xll.mscTrancheCalculatePV(E$2,$I$5,$I$3,$B12,$I$4) -> 2971401.7
B13: 9 | C13: =_xll.mscTrancheCalculatePV($C$2,$I$5,$I$3,B13,$I$4) -> 667328 | D13: =_xll.mscTrancheCalculatePV(D$2,$I$5,$I$3,$B13,$I$4) -> 2052770.8 | E13: =_xll.mscTrancheCalculatePV(E$2,$I$5,$I$3,$B13,$I$4) -> 2979665.7
B14: 10 | C14: =_xll.mscTrancheCalculatePV($C$2,$I$5,$I$3,B14,$I$4) -> 548734.34 | D14: =_xll.mscTrancheCalculatePV(D$2,$I$5,$I$3,$B14,$I$4) -> 2059449.7 | E14: =_xll.mscTrancheCalculatePV(E$2,$I$5,$I$3,$B14,$I$4) -> 2988175.5
B15: 11 | C15: =_xll.mscTrancheCalculatePV($C$2,$I$5,$I$3,B15,$I$4) -> 432158.22 | D15: =_xll.mscTrancheCalculatePV(D$2,$I$5,$I$3,$B15,$I$4) -> 2065357.3 | E15: =_xll.mscTrancheCalculatePV(E$2,$I$5,$I$3,$B15,$I$4) -> 2995562.3
B16: 12 | C16: =_xll.mscTrancheCalculatePV($C$2,$I$5,$I$3,B16,$I$4) -> 317982.74 | D16: =_xll.mscTrancheCalculatePV(D$2,$I$5,$I$3,$B16,$I$4) -> 2071794.3 | E16: =_xll.mscTrancheCalculatePV(E$2,$I$5,$I$3,$B16,$I$4) -> 3003168.4
B17: 13 | C17: =_xll.mscTrancheCalculatePV($C$2,$I$5,$I$3,B17,$I$4) -> 206007.11 | D17: =_xll.mscTrancheCalculatePV(D$2,$I$5,$I$3,$B17,$I$4) -> 2078241.7 | E17: =_xll.mscTrancheCalculatePV(E$2,$I$5,$I$3,$B17,$I$4) -> 3010467.8
... B102: 98 | C102: =_xll.mscTrancheCalculatePV($C$2,$I$5,$I$3,B102,$I$4) -> 58067.673 | D102: =_xll.mscTrancheCalculatePV(D$2,$I$5,$I$3,$B102,$I$4) -> 269903.46 | E102: =_xll.mscTrancheCalculatePV(E$2,$I$5,$I$3,$B102,$I$4) -> 3163667.1

Sheet Tranche DiscountMargin PV
C2: =CashflowEngine!E7 -> EQUITY:1 | D2: =CashflowEngine!E8 -> MEZZ:1 | E2: =CashflowEngine!E9 -> SENIOR:1 | H2: Tranche PV Parameters
B3: CallPeriod | C3: PV | D3: PV | E3: PV | H3: ValuationDate | I3: =CashflowEngine!C26 -> 43858
