Workbook
Name allowTradeUpdates: [1]Settings!$K$4
Name areAUDCSACurvesLoaded: '[1]AUD CSA CURVES'!$I$32
Name areEURCSACurvesLoaded: '[1]EUR CSA CURVES'!$I$32
Name areGBPCSACurvesLoaded: '[1]GBP CSA CURVES'!$I$32
Name areJPYCSACurvesLoaded: '[1]JPY CSA CURVES LCH'!$I$32
Name areUSDCSACurvesLoaded: '[1]USD CSA CURVES'!$I$32
Name AUDSwaps.Results.AUD3MLandAUD6ML: '[1]AUD SWAPS'!$T$39:$T$53
Name AUDSwaps.Results.OIS: '[1]AUD SWAPS'!$T$6:$T$15
Name AUDSwaps.Results.XCCY: '[1]AUD SWAPS'!$T$59:$T$73
Name COB: SETTINGS!$B$3
Name Curve.BuildProperties: '[1]EUR OIS'!$C$17:$D$21
Name Curve.CollectionName: '[1]EUR OIS'!$D$8
Name Curve.MarketDataSource: ESTR_SOFR_XCCY_CURVE!#REF!
Name Curve.MarketDataTable: '[1]EUR OIS'!$D$9
Name Curve.OISIndexName: '[1]EUR OIS'!$D$10
Name CURVE_GENERATOR_EONIA: SETTINGS!$K$5
Name CURVE_GENERATOR_ESTR: SETTINGS!$P$5
Name CurveBuildProperties: ESTR_SOFR_XCCY_CURVE!#REF!
Name CurveCollection: ESTR_SOFR_XCCY_CURVE!#REF!
Name enableCTDCurves: [1]Settings!$I$4
Name enableCurveRepricing: [1]Settings!$M$4
Name enableGlobalCalibration: [1]Settings!$E$4
Name EURSwaps.Results.EUR12ML: '[1]EUR SWAPS'!$T$99:$T$112
Name EURSwaps.Results.EUR1ML: '[1]EUR SWAPS'!$T$78:$T$92
Name EURSwaps.Results.EUR3ML: '[1]EUR SWAPS'!$T$56:$T$72
Name EURSwaps.Results.EUR6ML: '[1]EUR SWAPS'!$T$36:$T$50
Name EURSwaps.Results.LIBOROIS: '[1]EUR SWAPS'!$T$15:$T$30
Name EURSwaps.Results.OIS: '[1]EUR SWAPS'!$T$6:$T$9
Name EURSwaps.Results.XCCY: '[1]EUR SWAPS'!$T$118:$T$132
Name FRA.Conventions: '[1]EUR SWAP 6ML'!$C$47:$D$60
Name FRA.MarketDataX3: '[1]EUR SWAP 6ML'!$F$48:$G$60
Name FRA.MarketDataX6: '[1]EUR SWAP 6ML'!$I$48:$J$60
Name Futures.Conventions: '[1]EUR SWAP 6ML'!$C$68:$D$81
Name Futures.MarketData: '[1]EUR SWAP 6ML'!$F$69:$J$81
Name GBPSwaps.Results.GBP12ML: '[1]GBP SWAPS'!$T$98:$T$111
Name GBPSwaps.Results.GBP1ML: '[1]GBP SWAPS'!$T$77:$T$91
Name GBPSwaps.Results.GBP3ML: '[1]GBP SWAPS'!$T$39:$T$51
Name GBPSwaps.Results.GBP6ML: '[1]GBP SWAPS'!$T$57:$T$71
Name GBPSwaps.Results.LIBOROIS: '[1]GBP SWAPS'!$T$27:$T$34
Name GBPSwaps.Results.OIS: '[1]GBP SWAPS'!$T$6:$T$21
Name GBPSwaps.Results.XCCY: '[1]GBP SWAPS'!$T$117:$T$131
Name IndexName: ESTR_SOFR_XCCY_CURVE!#REF!
Name isAUD3MLLoaded: '[1]AUD SWAP 3ML'!$U$31
Name isAudCtdCurveLoaded: '[1]AUD CSA CURVES'!$W$6
Name isAUDOISLoaded: '[1]AUD OIS'!$W$31
Name isAUDXccyLoaded: '[1]AUD XCCY BASIS'!$M$24
Name isEUR3MLLoaded: '[1]EUR SWAP 3ML'!$U$32
Name isEUR6MLLoaded: '[1]EUR SWAP 6ML'!$U$32
Name isEurCtdCurveLoaded: '[1]EUR CSA CURVES'!$W$6
Name isEUROISLoaded: '[1]EUR OIS'!$W$32
Name isEURXccyLoaded: ESTR_SOFR_XCCY_CURVE!$F$24
Name isGBP3MLLoaded: '[1]GBP SWAP 3ML'!$U$32
Name isGBP6MLLoaded: '[1]GBP BASIS 6ML'!$L$25
Name isGbpCtdCurveLoaded: '[1]GBP CSA CURVES'!$W$6
Name isGBPOISLoaded: '[1]GBP OIS'!$W$32
Name isGBPXccyLoaded: '[1]GBP XCCY BASIS'!$M$24
Name isJpyCtdCurveLoaded: '[1]JPY CSA CURVES LCH'!$W$6
Name isJPYJSCC6MLLoaded: '[1]JPY SWAP 6ML JSCC'!$U$32
Name isJPYJSCC6MLLoaded_TiborSwapCurve: '[1]JPY SWAP 6ML JSCC'!$W$32
Name isJPYJSCCOISLoaded: '[1]JPY OIS JSCC'!$Y$33

Sheet SETTINGS
B2: VALUATION DATE | D2: INSTRUMENT TICKERS | I2: CURVE: EONIA | N2: CURVE: ESTR | S2: SWAP: EONIA | Y2: SWAP: ESTR
B3: 43798
D4: EONIA | G4: ESTR | J4: EUR EONIA CURVE GENERATOR TEMPLATE | O4: EUR ESTR CURVE GENERATOR TEMPLATE | T4: EUR EONIA CURVE GENERATOR TEMPLATE | Z4: EUR ESTR CURVE GENERATOR TEMPLATE
C5: 1D | D5: EONIA Index | F5: 1D | G5: ESTRON Index | J5: Create Template | K5: =_xll.meLWOCurveGeneratorCreate(K6,J9,J10:K17,J19,J20:K37) -> EUR_EONIA_CURVE_GENERATOR@3:2 | O5: Create Template | P5: =_xll.meLWOCurveGeneratorCreate(P6,O9,O10:P17,O19,O20:P37) -> EUR_ESTR_CURVE_GENERATOR@2:2 | T5: Create Template | U5: =_xll.meLWOSwapGeneratorCreate(U6,T10:V37) -> EUR_EONIA_SWAP@4:2 | Z5: Create Template | AA5: =_xll.meLWOSwapGeneratorCreate(AA6,Z10:AB37) -> EUR_ESTR_SWAP@1:2
C6: 2W | D6: EUSWE2Z BGN Curncy | F6: 2W | G6: EESWE2Z BGN Curncy | J6: Object Name | K6: EUR_EONIA_CURVE_GENERATOR | O6: Object Name | P6: EUR_ESTR_CURVE_GENERATOR | T6: Object Name | U6: EUR_EONIA_SWAP | Z6: Object Name | AA6: EUR_ESTR_SWAP
C7: 1M | D7: EUSWEA BGN Curncy | F7: 1M | G7: EESWEA BGN Curncy
C8: 2M | D8: EUSWEB BGN Curncy | F8: 2M | G8: EESWEB BGN Curncy
C9: 3M | D9: EUSWEC BGN Curncy | F9: 3M | G9: EESWEC BGN Curncy | J9: CURVEPROPERTIES | O9: CURVEPROPERTIES
C10: 4M | D10: EUSWED BGN Curncy | F10: 4M | G10: EESWED BGN Curncy | J10: CurveType | K10: OIS | O10: CurveType | P10: ARR | T10: LEGTYPE | U10: Leg1:Fixed | V10: Leg2:Float | Z10: LEGTYPE | AA10: Leg1:Fixed | AB10: Leg2:Float
C11: 5M | D11: EUSWEE BGN Curncy | F11: 5M | G11: EESWEE BGN Curncy | J11: CurveIndexFrequency | K11: DAILY | O11: CurveIndexFrequency | P11: DAILY | T11: LEVERAGE | U11: 1 | V11: 1 | Z11: LEVERAGE | AA11: 1 | AB11: 1
C12: 6M | D12: EUSWEF BGN Curncy | F12: 6M | G12: EESWEF BGN Curncy | J12: StaticDataTable | K12: OIS | O12: StaticDataTable | P12: ARR | T12: FORECASTCURVE | V12: EONIA | Z12: FORECASTCURVE | AB12: ESTR
C13: 7M | D13: EUSWEG BGN Curncy | F13: 7M | G13: EESWEG BGN Curncy | J13: IndexName | K13: EONIA | O13: IndexName | P13: ESTR | T13: DISCOUNTCURVE | U13: EONIA | V13: EONIA | Z13: DISCOUNTCURVE | AA13: ESTR | AB13: ESTR
C14: 8M | D14: EUSWEH BGN Curncy | F14: 8M | G14: EESWEH BGN Curncy | J14: Currency | K14: EUR | O14: Currency | P14: EUR | T14: COMPOUNDMETHOD | U14: NONE | V14: GEOMETRIC | Z14: COMPOUNDMETHOD | AA14: NONE | AB14: GEOMETRIC
C15: 9M | D15: EUSWEI BGN Curncy | F15: 9M | G15: EESWEI BGN Curncy | J15: interpolation | K15: FN_SPLINEINTERPOLATION | O15: interpolation | P15: FN_SPLINEINTERPOLATION | T15: NOTIONALEXCHANGE | U15: NONE | V15: NONE | Z15: NOTIONALEXCHANGE | AA15: NONE | AB15: NONE
C16: 10M | D16: EUSWEJ BGN Curncy | F16: 10M | G16: EESWEJ BGN Curncy | J16: yieldgen.interpolation | K16: FN_SPLINEINTERPOLATION | O16: yieldgen.interpolation | P16: FN_SPLINEINTERPOLATION | T16: VALUATIONCURRENCY | U16: EUR | V16: EUR | Z16: VALUATIONCURRENCY | AA16: EUR | AB16: EUR
C17: 11M | D17: EUSWEK BGN Curncy | F17: 11M | G17: EESWEK BGN Curncy | J17: dfCurveName | K17: ESTR | T17: CURRENCY | U17: EUR | V17: EUR | Z17: CURRENCY | AA17: EUR | AB17: EUR
C18: 1Y | D18: EUSWE1 BGN Curncy | F18: 1Y | G18: EESWE1 BGN Curncy | T18: ACCRUALFREQUENCY | U18: ANNUAL | V18: ANNUAL | Z18: ACCRUALFREQUENCY | AA18: ANNUAL | AB18: ANNUAL
C19: 18M | D19: EUSWE1F BGN Curncy | F19: 18M | G19: EESWE1F BGN Curncy | J19: OIS | O19: OIS | T19: ACCRUALBUSINESSDAYADJUSTMENT | U19: MOD_FOLLOWING | V19: MOD_FOLLOWING | Z19: ACCRUALBUSINESSDAYADJUSTMENT | AA19: MOD_FOLLOWING | AB19: MOD_FOLLOWING
C20: 2Y | D20: EUSWE2 BGN Curncy | F20: 2Y | G20: EUSA2 BGN Curncy | J20: calendar | K20: TGT | O20: calendar | P20: TGT | T20: ACCRUALCALENDAR | U20: TGT | V20: TGT | Z20: ACCRUALCALENDAR | AA20: TGT | AB20: TGT
C21: 3Y | D21: EUSWE3 BGN Curncy | F21: 3Y | G21: EUSA3 BGN Curncy | J21: daycount | K21: ACT/360 | O21: daycount | P21: ACT/360 | T21: ACCRUALDAYCOUNT | U21: ACT/360 | V21: ACT/360 | Z21: ACCRUALDAYCOUNT | AA21: ACT/360 | AB21: ACT/360
C22: 4Y | D22: EUSWE4 BGN Curncy | F22: 4Y | G22: EUSA4 BGN Curncy | J22: frequency | K22: ANNUAL | O22: frequency | P22: ANNUAL | T22: PAYMENTFREQUENCY | Z22: PAYMENTFREQUENCY
C23: 5Y | D23: EUSWE5 BGN Curncy | F23: 5Y | G23: EUSA5 BGN Curncy | J23: generatemethod | K23: DAILYCOMPOUNDING | O23: generatemethod | P23: DAILYCOMPOUNDING | T23: PAYMENTBUSINESSDAYADJUSTMENT | U23: MOD_FOLLOWING | V23: MOD_FOLLOWING | Z23: PAYMENTBUSINESSDAYADJUSTMENT | AA23: MOD_FOLLOWING | AB23: MOD_FOLLOWING
C24: 6Y | D24: EUSWE6 BGN Curncy | F24: 6Y | G24: EUSA6 BGN Curncy | J24: resetlag | K24: 2D | O24: resetlag | P24: 2D | T24: PAYMENTCALENDAR | U24: TGT | V24: TGT | Z24: PAYMENTCALENDAR | AA24: TGT | AB24: TGT
C25: 7Y | D25: EUSWE7 BGN Curncy | F25: 7Y | G25: EUSA7 BGN Curncy | J25: firstrate | K25: SHORTMARKET | O25: firstrate | P25: SHORTMARKET | T25: PAYMENTLAG | U25: 0D | V25: 0D | Z25: PAYMENTLAG | AA25: 0D | AB25: 0D
C26: 8Y | D26: EUSWE8 BGN Curncy | F26: 8Y | G26: EUSA8 BGN Curncy | J26: slidingrule | K26: MOD_FOLLOWING | O26: slidingrule | P26: MOD_FOLLOWING | T26: FIRSTSTUBDATE | Z26: FIRSTSTUBDATE
C27: 9Y | D27: EUSWE9 BGN Curncy | F27: 9Y | G27: EUSA9 BGN Curncy | J27: eomday | K27: 31 | O27: eomday | P27: 31 | T27: LASTSTUBDATE | Z27: LASTSTUBDATE
C28: 10Y | D28: EUSWE10 BGN Curncy | F28: 10Y | G28: EUSA10 BGN Curncy | J28: iseomroll | K28: TRUE | O28: iseomroll | P28: TRUE | T28: ROLLDAY | U28: NORMAL | V28: NORMAL | Z28: ROLLDAY | AA28: NORMAL | AB28: NORMAL
C29: 11Y | D29: EUSWE11 BGN Curncy | F29: 11Y | G29: EUSA11 BGN Curncy | J29: shorttermconvention | K29: ARITHMETICAVERAGE | O29: shorttermconvention | P29: ARITHMETICAVERAGE | T29: STUBTYPE | U29: SHORTSTART | V29: SHORTSTART | Z29: STUBTYPE | AA29: SHORTSTART | AB29: SHORTSTART
C30: 12Y | D30: EUSWE12 BGN Curncy | F30: 12Y | G30: EUSA12 BGN Curncy | J30: longtermconvention | K30: NONE | O30: longtermconvention | P30: NONE | T30: FIXINGBUSINESSDAYADJUSTMENT | V30: MOD_FOLLOWING | Z30: FIXINGBUSINESSDAYADJUSTMENT | AB30: MOD_FOLLOWING
C31: 15Y | D31: EUSWE15 BGN Curncy | F31: 15Y | G31: EUSA15 BGN Curncy | J31: longterm | K31: 100Y | O31: longterm | P31: 100Y | T31: FIXINGCALENDAR | V31: TGT | Z31: FIXINGCALENDAR | AB31: TGT
C32: 20Y | D32: EUSWE20 BGN Curncy | F32: 20Y | G32: EUSA20 BGN Curncy | J32: longterm.generatemethod | K32: NONE | O32: longterm.generatemethod | P32: NONE | T32: FIXINGLAG | V32: 0D | Z32: FIXINGLAG | AB32: 0D
C33: 25Y | D33: EUSWE25 BGN Curncy | F33: 25Y | G33: EUSA25 BGN Curncy | J33: Epsilon | K33: 0.0000000001 | O33: Epsilon | P33: 0.0000000001 | T33: FIXINGADVANCEORARREAR | Z33: FIXINGADVANCEORARREAR
C34: 30Y | D34: EUSWE30 BGN Curncy | F34: 30Y | G34: EUSA30 BGN Curncy | J34: MaxLoop | K34: 1000 | O34: MaxLoop | P34: 1000 | T34: FIRSTSTUBCURVEINDEX | V34: NATURAL | Z34: FIRSTSTUBCURVEINDEX | AB34: NATURAL
C35: 40Y | D35: EUSWE40 BGN Curncy | F35: 40Y | G35: EUSA40 BGN Curncy | J35: CompoundingMethod | K35: GEOMETRIC | O35: CompoundingMethod | P35: GEOMETRIC | T35: LASTSTUBCURVEINDEX | V35: NATURAL | Z35: LASTSTUBCURVEINDEX | AB35: NATURAL
C36: 50Y | D36: EUSWE50 BGN Curncy | F36: 50Y | G36: EUSA50 BGN Curncy | J36: SmoothShortEnd | K36: TRUE | O36: SmoothShortEnd | P36: TRUE

Sheet USD_SOFR_CURVE
B3: Curve Generator Handle | C3: =_xll.meLWOCurveGeneratorCreate("USD_SOFR",B5,B6:C13,B15,B16:C30) -> USD_SOFR@5:1 | F3: MARKETDATAPROPERTIES | I3: OIS
I4: Term | J4: Rate | K4: StartDate | L4: EndDate | M4: Volatility
B5: CURVEPROPERTIES | F5: Currency | G5: USD | I5: ON | J5: 0.0157
B6: CurveType | C6: ARR | F6: CurveType | G6: ARR | I6: 1W | J6: 0.0155
B7: CurveIndexFrequency | C7: DAILY | F7: CurveIndexFrequency | G7: DAILY | I7: FUTURE1 | J7: 98.45 | K7: =_xll.meDateIMMNext($G$8) -> 43817 | L7: =_xll.meDateIMMNext(K7) -> 43908 | M7: 0 | N7: SOFR FUTURE
B8: StaticDataTable | C8: ARR | F8: AsOfDate | G8: =COB -> 43798 | I8: FUTURE2 | J8: 98.48464 | K8: =L7 -> 43908 | L8: =_xll.meDateIMMNext(K8) -> 43999 | M8: 0 | N8: SOFR FUTURE
B9: IndexName | C9: SOFR | I9: FUTURE3 | J9: 98.51928 | K9: =L8 -> 43999 | L9: =_xll.meDateIMMNext(K9) -> 44090 | M9: 0 | N9: SOFR FUTURE
B10: Currency | C10: USD | I10: FUTURE4 | J10: 98.55392 | K10: =L9 -> 44090 | L10: =_xll.meDateIMMNext(K10) -> 44181 | M10: 0 | N10: SOFR FUTURE
B11: interpolation | C11: FN_LINEARSPLINEINTERPOLATION | F11: Create Market Data Handle | I11: 2Y | J11: 0.0144608
B12: yieldgen.interpolation | C12: FN_LINEARSPLINEINTERPOLATION | F12: Handle Name | G12: USD_OIS_CURVE_MARKETDATA | I12: 5Y | J12: 0.0147765
B13: InterpolationJoinDate | C13: =L9 -> 44090 | F13: Market Data Handle | G13: =_xll.meLWOCurveMarketDataCreate(G12,F3,F5:G8,I3,I5:M30) -> USD_OIS_CURVE_MARKETDATA@6:1 | I13: 7Y | J13: 0.0153018
I14: 10Y | J14: 0.0161845
B15: OIS | I15: 12Y | J15: 0.0166681
B16: calendar | C16: NYB | I16: 15Y | J16: 0.017191
B17: daycount | C17: ACT/360 | I17: 20Y | J17: 0.0177368
B18: frequency | C18: ANNUAL | F18: Curve Dictionary | I18: 25Y | J18: 0.017928
B19: generatemethod | C19: DAILYCOMPOUNDING | F19: Handle Name | G19: CURVE_USDSOFR | I19: 30Y | J19: 0.0179398
B20: resetlag | C20: 2D | F20: Curve Generator | G20: =C3 -> USD_SOFR@5:1 | I20: 40Y | J20: 0.0177338
B21: firstrate | C21: SHORTMARKET | F21: Domestic Curve Collection | G21: USDYC | I21: 50Y | J21: 0.0173572
B22: slidingrule | C22: MOD_FOLLOWING | F22: Foreign Curve Collection
B23: eomday | C23: 31
B24: iseomroll | C24: TRUE
B25: shorttermconvention | C25: ARITHMETICAVERAGE
B26: longterm.generatemethod | C26: NONE | F26: Curve Build
B27: Epsilon | C27: 1e-10 | F27: Handle Name | G27: {=_xll.meLWOCurveCalibrate(G19,G20,G13,G21,G22)} -> CURVE_USDSOFR@7:1
B28: MaxLoop | C28: 1000 | F28: Curve Collection | G28: USDYC
B29: CompoundingMethod | C29: ARITHMETIC | F29: Curve Index | G29: ARR:SOFR
B30: SmoothShortEnd | C30: FALSE | F30: Calibration Time Taken | G30: 1.08200 sec
F31: Curve Loaded | G31: =_xll.meLWOExists(G27,"CURVE") -> TRUE

Sheet USD_FEDFUNDS_RFR_DISCOUTING
B3: Curve Generator Handle | C3: =_xll.meLWOCurveGeneratorCreate("USD_FEDFUNDS_WITH_RFR_DF",B5,B6:C13,B15,B16:C30) -> USD_FEDFUNDS_WITH_RFR_DF@8:1 | F3: MARKETDATAPROPERTIES | I3: OIS
I4: Term | J4: Rate | K4: StartDate | L4: EndDate | M4: Volatility
B5: CURVEPROPERTIES | F5: Currency | G5: USD | I5: ON | J5: 0.0155
B6: CurveType | C6: OIS | F6: CurveType | G6: OIS | I6: 1W | J6: 0.0156546
B7: CurveIndexFrequency | C7: DAILY | F7: CurveIndexFrequency | G7: DAILY | I7: MPC1 | J7: 0.0152 | K7: =USD_SOFR_CURVE!K7 -> 43817 | L7: =USD_SOFR_CURVE!L7 -> 43908 | N7: FED FUND MPC SWAP
B8: StaticDataTable | C8: OIS | F8: AsOfDate | G8: =COB -> 43798 | I8: MPC2 | J8: 0.0148 | K8: =USD_SOFR_CURVE!K8 -> 43908 | L8: =USD_SOFR_CURVE!L8 -> 43999 | N8: FED FUND MPC SWAP
B9: IndexName | C9: FEDFUNDS | I9: MPC3 | J9: 0.0145 | K9: =USD_SOFR_CURVE!K9 -> 43999 | L9: =USD_SOFR_CURVE!L9 -> 44090 | N9: FED FUND MPC SWAP
B10: Currency | C10: USD | I10: MPC4 | J10: 0.01435 | K10: =USD_SOFR_CURVE!K10 -> 44090 | L10: =USD_SOFR_CURVE!L10 -> 44181 | N10: FED FUND MPC SWAP
B11: interpolation | C11: FN_SPLINEINTERPOLATION | F11: Create Market Data Handle | I11: 2Y | J11: 0.01433
B12: yieldgen.interpolation | C12: FN_SPLINEINTERPOLATION | F12: Handle Name | G12: USD_OIS_CURVE_MARKETDATA | I12: 5Y | J12: 0.0145344
B13: dfCurveName | C13: SOFR | F13: Market Data Handle | G13: =_xll.meLWOCurveMarketDataCreate(G12,F3,F5:G8,I3,I5:M30) -> USD_OIS_CURVE_MARKETDATA@9:1 | I13: 7Y | J13: 0.0150851
I14: 10Y | J14: 0.0159844
B15: OIS | I15: 12Y | J15: 0.0164793
B16: calendar | C16: NYB | I16: 15Y | J16: 0.0170123
B17: daycount | C17: ACT/360 | I17: 20Y | J17: 0.0175687
B18: frequency | C18: ANNUAL | F18: Curve Dictionary | I18: 25Y | J18: 0.013831423
B19: generatemethod | C19: DAILYCOMPOUNDING | F19: Handle Name | G19: CURVE_USDOIS | I19: 30Y | J19: 0.0177902
B20: resetlag | C20: 2D | F20: Curve Generator | G20: =C3 -> USD_FEDFUNDS_WITH_RFR_DF@8:1 | I20: 40Y | J20: 0.01757776
B21: firstrate | C21: SHORTMARKET | F21: Domestic Curve Collection | G21: USDYC | I21: 50Y | J21: 0.0172051
B22: slidingrule | C22: MOD_FOLLOWING | F22: Foreign Curve Collection
B23: eomday | C23: 31
B24: iseomroll | C24: TRUE
B25: shorttermconvention | C25: ARITHMETICAVERAGE
B26: longterm.generatemethod | C26: NONE | F26: Curve Build
B27: Epsilon | C27: 1e-10 | F27: Handle Name | G27: {=IF(USD_SOFR_CURVE!$G$31,_xll.meLWOCurveCalibrate(G19,G20,G13,G21,G22),"LOAD USD SOFR CURVE")} -> CURVE_USDOIS@10:1
B28: MaxLoop | C28: 1000 | F28: Curve Collection | G28: USDYC
B29: CompoundingMethod | C29: ARITHMETIC | F29: Curve Index | G29: OIS:FEDFUNDS
B30: SmoothShortEnd | C30: FALSE | F30: Calibration Time Taken | G30: 0.98000 sec
F31: Curve Loaded | G31: =_xll.meLWOExists(G27,"CURVE") -> TRUE

Sheet USD_FORWARDS
B2: CurveCollection | C2: USDYC | E2: {=_xll.meLWOCurveForwardRatesTable(C2,C3:C4)} -> Fixing Dates | F2: SOFR | G2: FEDFUNDS
B3: CurveIndex | C3: SOFR | E3: 43798 | F3: 0.0157 | G3: 0.0155
C4: FEDFUNDS | E4: 43829 | F4: 0.015454321 | G4: 0.0152
E5: 43859 | F5: 0.015340123 | G5: 0.0152
E6: 43889 | F6: 0.015225925 | G6: 0.0152
E7: 43920 | F7: 0.015107921 | G7: 0.0148
E8: 43950 | F8: 0.014993723 | G8: 0.0148
E9: 43980 | F9: 0.014879525 | G9: 0.0148
E10: 44011 | F10: 0.014761521 | G10: 0.0145
E11: 44041 | F11: 0.014647323 | G11: 0.0145
E12: 44074 | F12: 0.014521705 | G12: 0.0145
E13: 44103 | F13: 0.01448584 | G13: 0.01435
E14: 44133 | F14: 0.014486311 | G14: 0.01435
E15: 44165 | F15: 0.014415499 | G15: 0.01435
E16: 44194 | F16: 0.01431687 | G16: 0.014294877
... E123: 47451 | F123: 0.019197654 | G123: 0.019141594
E124: #N/A | F124: #N/A | G124: #N/A
E125: #N/A | F125: #N/A | G125: #N/A
E126: #N/A | F126: #N/A | G126: #N/A
E127: #N/A | F127: #N/A | G127: #N/A
E128: #N/A | F128: #N/A | G128: #N/A
E129: #N/A | F129: #N/A | G129: #N/A
E130: #N/A | F130: #N/A | G130: #N/A

Sheet EUR_ESTR_CURVE
C4: MARKETDATAPROPERTIES | F4: OIS
F5: Term | G5: Rate | H5: StartDate | I5: EndDate | J5: Use
C6: Currency | D6: EUR | F6: 1D | G6: -0.00531 | J6: TRUE
C7: CurveType | D7: ARR | F7: 2W | G7: -0.00531 | J7: TRUE
C8: CurveIndexFrequency | D8: DAILY | F8: 1M | G8: -0.00532 | J8: TRUE
C9: AsOfDate | D9: =COB -> 43798 | F9: 2M | G9: -0.005315 | J9: TRUE
F10: 3M | G10: -0.00535 | J10: TRUE
F11: 4M | G11: -0.005379 | J11: TRUE
C12: Create Market Data Handle | F12: 5M | G12: -0.005405 | J12: TRUE
C13: Handle Name | D13: EUR_ESTR_CURVE_MARKETDATA | F13: 6M | G13: -0.005434 | J13: TRUE
C14: Market Data Handle | D14: =_xll.meLWOCurveMarketDataCreate(D13,C4,C6:D9,F4,F6:J38) -> EUR_ESTR_CURVE_MARKETDATA@11:1 | F14: 7M | G14: -0.00546 | J14: TRUE
F15: 8M | G15: -0.00549 | J15: TRUE
C16: Curve Dictionary | F16: 9M | G16: -0.005515 | J16: TRUE
C17: Handle Name | D17: EUR_ESTR_CURVE | F17: 10M | G17: -0.005544 | J17: TRUE
C18: Curve Generator | D18: =CURVE_GENERATOR_ESTR -> EUR_ESTR_CURVE_GENERATOR@2:2 | F18: 11M | G18: -0.005565 | J18: TRUE
C19: Domestic Curve Collection | D19: EURYC | F19: 1Y | G19: -0.00559 | J19: TRUE
C20: Foreign Curve Collection | F20: 18M | G20: -0.00569 | J20: TRUE
F21: 2Y | G21: -0.005723 | J21: TRUE
C22: Curve Build | F22: 3Y | G22: -0.005612 | J22: TRUE
C23: Handle Name | D23: {=IF(USD_SOFR_CURVE!$G$31,_xll.meLWOCurveCalibrate(D17,D18,D14,D19,D20),"LOAD USD SOFR CURVE")} -> EUR_ESTR_CURVE@12:1 | F23: 4Y | G23: -0.005343 | J23: TRUE
C24: Curve Collection | D24: EURYC | F24: 5Y | G24: -0.004962 | J24: TRUE
C25: Curve Index | D25: ARR:ESTR | F25: 6Y | G25: -0.004471 | J25: TRUE
C26: Calibration Time Taken | D26: 2.10600 sec | F26: 7Y | G26: -0.003945 | J26: TRUE
C27: Curve Loaded | D27: =_xll.meLWOExists(D23,"CURVE") -> TRUE | F27: 8Y | G27: -0.00335 | J27: TRUE
F28: 9Y | G28: -0.00274 | J28: TRUE
F29: 10Y | G29: -0.00214 | J29: TRUE
F30: 11Y | G30: -0.001555 | J30: TRUE
F31: 12Y | G31: -0.001007 | J31: TRUE
F32: 15Y | G32: 0.000445 | J32: TRUE
F33: 20Y | G33: 0.00184 | J33: TRUE
F34: 25Y | G34: 0.00232 | J34: TRUE
F35: 30Y | G35: 0.002355 | J35: TRUE
F36: 40Y | G36: 0.001987 | J36: TRUE
F37: 50Y | G37: 0.00148 | J37: TRUE

Sheet EUR_EONIA_RFR_DISCOUNTING
D4: MARKETDATAPROPERTIES | G4: OIS | N4: EONIA = ESTR + 8.5 BPS
G5: Term | H5: Rate | I5: StartDate | J5: EndDate | K5: Use
D6: Currency | E6: EUR | G6: =SETTINGS!C5 -> 1D | H6: =_xll.BDP(SETTINGS!D5,"PX_LAST")% -> -0.00446 | K6: TRUE | N6: =EUR_ESTR_CURVE!F6 -> 1D | O6: =EUR_ESTR_CURVE!G6 -> -0.00531 | P6: =H6-O6 -> 0.00085
D7: CurveType | E7: OIS | G7: =SETTINGS!C6 -> 2W | H7: =_xll.BDP(SETTINGS!D6,"PX_LAST")% -> -0.00446 | K7: TRUE | N7: =EUR_ESTR_CURVE!F7 -> 2W | O7: =EUR_ESTR_CURVE!G7 -> -0.00531 | P7: =H7-O7 -> 0.00085
D8: CurveIndexFrequency | E8: DAILY | G8: =SETTINGS!C7 -> 1M | H8: =_xll.BDP(SETTINGS!D7,"PX_LAST")% -> -0.00447 | K8: TRUE | N8: =EUR_ESTR_CURVE!F8 -> 1M | O8: =EUR_ESTR_CURVE!G8 -> -0.00532 | P8: =H8-O8 -> 0.00085
D9: AsOfDate | E9: =COB -> 43798 | G9: =SETTINGS!C8 -> 2M | H9: =_xll.BDP(SETTINGS!D8,"PX_LAST")% -> -0.004477 | K9: TRUE | N9: =EUR_ESTR_CURVE!F9 -> 2M | O9: =EUR_ESTR_CURVE!G9 -> -0.005315 | P9: =H9-O9 -> 0.000838
G10: =SETTINGS!C9 -> 3M | H10: =_xll.BDP(SETTINGS!D9,"PX_LAST")% -> -0.0045 | K10: TRUE | N10: =EUR_ESTR_CURVE!F10 -> 3M | O10: =EUR_ESTR_CURVE!G10 -> -0.00535 | P10: =H10-O10 -> 0.00085
G11: =SETTINGS!C10 -> 4M | H11: =_xll.BDP(SETTINGS!D10,"PX_LAST")% -> -0.004527 | K11: TRUE | N11: =EUR_ESTR_CURVE!F11 -> 4M | O11: =EUR_ESTR_CURVE!G11 -> -0.005379 | P11: =H11-O11 -> 0.000852
D12: Create Market Data Handle | G12: =SETTINGS!C11 -> 5M | H12: =_xll.BDP(SETTINGS!D11,"PX_LAST")% -> -0.004555 | K12: TRUE | N12: =EUR_ESTR_CURVE!F12 -> 5M | O12: =EUR_ESTR_CURVE!G12 -> -0.005405 | P12: =H12-O12 -> 0.00085
D13: Handle Name | E13: EUR_EONIA_CURVE_MARKETDATA | G13: =SETTINGS!C12 -> 6M | H13: =_xll.BDP(SETTINGS!D12,"PX_LAST")% -> -0.004576 | K13: TRUE | N13: =EUR_ESTR_CURVE!F13 -> 6M | O13: =EUR_ESTR_CURVE!G13 -> -0.005434 | P13: =H13-O13 -> 0.000858
D14: Market Data Handle | E14: =_xll.meLWOCurveMarketDataCreate(E13,D4,D6:E9,G4,G6:K39) -> EUR_EONIA_CURVE_MARKETDATA@13:1 | G14: =SETTINGS!C13 -> 7M | H14: =_xll.BDP(SETTINGS!D13,"PX_LAST")% -> -0.004603 | K14: TRUE | N14: =EUR_ESTR_CURVE!F14 -> 7M | O14: =EUR_ESTR_CURVE!G14 -> -0.00546 | P14: =H14-O14 -> 0.000857
G15: =SETTINGS!C14 -> 8M | H15: =_xll.BDP(SETTINGS!D14,"PX_LAST")% -> -0.004632 | K15: TRUE | N15: =EUR_ESTR_CURVE!F15 -> 8M | O15: =EUR_ESTR_CURVE!G15 -> -0.00549 | P15: =H15-O15 -> 0.000858
G16: =SETTINGS!C15 -> 9M | H16: =_xll.BDP(SETTINGS!D15,"PX_LAST")% -> -0.004657 | K16: TRUE | N16: =EUR_ESTR_CURVE!F16 -> 9M | O16: =EUR_ESTR_CURVE!G16 -> -0.005515 | P16: =H16-O16 -> 0.000858
G17: =SETTINGS!C16 -> 10M | H17: =_xll.BDP(SETTINGS!D16,"PX_LAST")% -> -0.00468 | K17: TRUE | N17: =EUR_ESTR_CURVE!F17 -> 10M | O17: =EUR_ESTR_CURVE!G17 -> -0.005544 | P17: =H17-O17 -> 0.000864
G18: =SETTINGS!C17 -> 11M | H18: =_xll.BDP(SETTINGS!D17,"PX_LAST")% -> -0.004701 | K18: TRUE | N18: =EUR_ESTR_CURVE!F18 -> 11M | O18: =EUR_ESTR_CURVE!G18 -> -0.005565 | P18: =H18-O18 -> 0.000864
G19: =SETTINGS!C18 -> 1Y | H19: =_xll.BDP(SETTINGS!D18,"PX_LAST")% -> -0.00473 | K19: TRUE | N19: =EUR_ESTR_CURVE!F19 -> 1Y | O19: =EUR_ESTR_CURVE!G19 -> -0.00559 | P19: =H19-O19 -> 0.00086
D20: Curve Dictionary | G20: =SETTINGS!C19 -> 18M | H20: =_xll.BDP(SETTINGS!D19,"PX_LAST")% -> -0.004824 | K20: TRUE | N20: =EUR_ESTR_CURVE!F20 -> 18M | O20: =EUR_ESTR_CURVE!G20 -> -0.00569 | P20: =H20-O20 -> 0.000866
D21: Handle Name | E21: EUR_EONIA_CURVE | G21: =SETTINGS!C20 -> 2Y | H21: =_xll.BDP(SETTINGS!D20,"PX_LAST")% -> -0.004851 | K21: TRUE | N21: =EUR_ESTR_CURVE!F21 -> 2Y | O21: =EUR_ESTR_CURVE!G21 -> -0.005723 | P21: =H21-O21 -> 0.000872
D22: Curve Generator | E22: =CURVE_GENERATOR_EONIA -> EUR_EONIA_CURVE_GENERATOR@3:2 | G22: =SETTINGS!C21 -> 3Y | H22: =_xll.BDP(SETTINGS!D21,"PX_LAST")% -> -0.004741 | K22: TRUE | N22: =EUR_ESTR_CURVE!F22 -> 3Y | O22: =EUR_ESTR_CURVE!G22 -> -0.005612 | P22: =H22-O22 -> 0.000871
D23: Domestic Curve Collection | E23: EURYC | G23: =SETTINGS!C22 -> 4Y | H23: =_xll.BDP(SETTINGS!D22,"PX_LAST")% -> -0.00447 | K23: TRUE | N23: =EUR_ESTR_CURVE!F23 -> 4Y | O23: =EUR_ESTR_CURVE!G23 -> -0.005343 | P23: =H23-O23 -> 0.000873
D24: Foreign Curve Collection | G24: =SETTINGS!C23 -> 5Y | H24: =_xll.BDP(SETTINGS!D23,"PX_LAST")% -> -0.004092 | K24: TRUE | N24: =EUR_ESTR_CURVE!F24 -> 5Y | O24: =EUR_ESTR_CURVE!G24 -> -0.004962 | P24: =H24-O24 -> 0.00087
G25: =SETTINGS!C24 -> 6Y | H25: =_xll.BDP(SETTINGS!D24,"PX_LAST")% -> -0.003608 | K25: TRUE | N25: =EUR_ESTR_CURVE!F25 -> 6Y | O25: =EUR_ESTR_CURVE!G25 -> -0.004471 | P25: =H25-O25 -> 0.000863
G26: =SETTINGS!C25 -> 7Y | H26: =_xll.BDP(SETTINGS!D25,"PX_LAST")% -> -0.00308 | K26: TRUE | N26: =EUR_ESTR_CURVE!F26 -> 7Y | O26: =EUR_ESTR_CURVE!G26 -> -0.003945 | P26: =H26-O26 -> 0.000865
D27: Curve Build | G27: =SETTINGS!C26 -> 8Y | H27: =_xll.BDP(SETTINGS!D26,"PX_LAST")% -> -0.002491 | K27: TRUE | N27: =EUR_ESTR_CURVE!F27 -> 8Y | O27: =EUR_ESTR_CURVE!G27 -> -0.00335 | P27: =H27-O27 -> 0.000859
D28: Handle Name | E28: {=IF(EUR_ESTR_CURVE!$D$27,_xll.meLWOCurveCalibrate(E21,E22,E14,E23,E24),"LOAD EONIA CURVE")} -> EUR_EONIA_CURVE@14:1 | G28: =SETTINGS!C27 -> 9Y | H28: =_xll.BDP(SETTINGS!D27,"PX_LAST")% -> -0.001894 | K28: TRUE | N28: =EUR_ESTR_CURVE!F28 -> 9Y | O28: =EUR_ESTR_CURVE!G28 -> -0.00274 | P28: =H28-O28 -> 0.000846
D29: Curve Collection | E29: EURYC | G29: =SETTINGS!C28 -> 10Y | H29: =_xll.BDP(SETTINGS!D28,"PX_LAST")% -> -0.001301 | K29: TRUE | N29: =EUR_ESTR_CURVE!F29 -> 10Y | O29: =EUR_ESTR_CURVE!G29 -> -0.00214 | P29: =H29-O29 -> 0.000839
D30: Curve Index | E30: OIS:EONIA | G30: =SETTINGS!C29 -> 11Y | H30: =_xll.BDP(SETTINGS!D29,"PX_LAST")% -> -0.000717 | K30: TRUE | N30: =EUR_ESTR_CURVE!F30 -> 11Y | O30: =EUR_ESTR_CURVE!G30 -> -0.001555 | P30: =H30-O30 -> 0.000838
D31: Calibration Time Taken | E31: 2.27300 sec | G31: =SETTINGS!C30 -> 12Y | H31: =_xll.BDP(SETTINGS!D30,"PX_LAST")% -> -0.000167 | K31: TRUE | N31: =EUR_ESTR_CURVE!F31 -> 12Y | O31: =EUR_ESTR_CURVE!G31 -> -0.001007 | P31: =H31-O31 -> 0.00084
D32: Curve Loaded | E32: =_xll.meLWOExists(E28,"CURVE") -> TRUE | G32: =SETTINGS!C31 -> 15Y | H32: =_xll.BDP(SETTINGS!D31,"PX_LAST")% -> 0.00127 | K32: TRUE | N32: =EUR_ESTR_CURVE!F32 -> 15Y | O32: =EUR_ESTR_CURVE!G32 -> 0.000445 | P32: =H32-O32 -> 0.000825
G33: =SETTINGS!C32 -> 20Y | H33: =_xll.BDP(SETTINGS!D32,"PX_LAST")% -> 0.002675 | K33: TRUE | N33: =EUR_ESTR_CURVE!F33 -> 20Y | O33: =EUR_ESTR_CURVE!G33 -> 0.00184 | P33: =H33-O33 -> 0.000835
G34: =SETTINGS!C33 -> 25Y | H34: =_xll.BDP(SETTINGS!D33,"PX_LAST")% -> 0.00315 | K34: TRUE | N34: =EUR_ESTR_CURVE!F34 -> 25Y | O34: =EUR_ESTR_CURVE!G34 -> 0.00232 | P34: =H34-O34 -> 0.00083
G35: =SETTINGS!C34 -> 30Y | H35: =_xll.BDP(SETTINGS!D34,"PX_LAST")% -> 0.003177 | K35: TRUE | N35: =EUR_ESTR_CURVE!F35 -> 30Y | O35: =EUR_ESTR_CURVE!G35 -> 0.002355 | P35: =H35-O35 -> 0.000822
G36: =SETTINGS!C35 -> 40Y | H36: =_xll.BDP(SETTINGS!D35,"PX_LAST")% -> 0.002832 | K36: TRUE | N36: =EUR_ESTR_CURVE!F36 -> 40Y | O36: =EUR_ESTR_CURVE!G36 -> 0.001987 | P36: =H36-O36 -> 0.000845
G37: =SETTINGS!C36 -> 50Y | H37: =_xll.BDP(SETTINGS!D36,"PX_LAST")% -> 0.00233 | K37: TRUE | N37: =EUR_ESTR_CURVE!F37 -> 50Y | O37: =EUR_ESTR_CURVE!G37 -> 0.00148 | P37: =H37-O37 -> 0.00085

Sheet EUR FORWARDS
B2: CurveCollection | C2: EURYC | E2: {=_xll.meLWOCurveForwardRatesTable(C2,C3:C4)} -> Fixing Dates | F2: EONIA | G2: ESTR
B3: CurveIndex | C3: EONIA | E3: 43798 | F3: -0.0044599447 | G3: -0.0053099217
C4: ESTR | E4: 43829 | F4: -0.0044828281 | G4: -0.0053285471
E5: 43859 | F5: -0.0045016588 | G5: -0.0053372258
E6: 43889 | F6: -0.0045793314 | G6: -0.0054637484
E7: 43920 | F7: -0.0046389778 | G7: -0.0054826165
E8: 43950 | F8: -0.0046822879 | G8: -0.0055464098
E9: 43980 | F9: -0.0047163147 | G9: -0.0056126432
E10: 44011 | F10: -0.0048132211 | G10: -0.0056645609
E11: 44041 | F11: -0.0048582691 | G11: -0.0057278962
E12: 44074 | F12: -0.0048803114 | G12: -0.0057674319
E13: 44103 | F13: -0.0049034164 | G13: -0.0058285866
E14: 44133 | F14: -0.0049848392 | G14: -0.0058323825
E15: 44165 | F15: -0.0051020876 | G15: -0.0059239411
E16: 44194 | F16: -0.0050653441 | G16: -0.0059130275
... E123: 47451 | F123: 0.00462463 | G123: 0.0038265067
E124: #N/A | F124: #N/A | G124: #N/A
E125: #N/A | F125: #N/A | G125: #N/A
E126: #N/A | F126: #N/A | G126: #N/A
E127: #N/A | F127: #N/A | G127: #N/A
E128: #N/A | F128: #N/A | G128: #N/A
E129: #N/A | F129: #N/A | G129: #N/A
E130: #N/A | F130: #N/A | G130: #N/A

Sheet ESTR_SOFR_XCCY_CURVE
B2: Curve Generator Handle | C2: =_xll.meLWOCurveGeneratorCreate("ESTR_SOFR_XCCY",B4,B5:C16,B18,B19:C57,B59,B60:C68) -> ESTR_SOFR_XCCY@15:8 | E2: MARKETDATAPROPERTIES | H2: FXSPOTS | L2: XCCYSWAPS
E3: Currency | F3: EUR | H3: Ccy1 | I3: Ccy2 | J3: Rate | L3: Term | M3: Rate
B4: CURVEPROPERTIES | E4: CurveType | F4: XCCYBASIS | H4: EUR | I4: USD | J4: 1.10055 | L4: 1Y | M4: -0.0011
B5: CurveType | C5: XCCYBASIS | E5: CurveIndexFrequency | F5: QUARTERLY | L5: 2Y | M5: -0.001175
B6: CurveIndexFrequency | C6: QUARTERLY | E6: AsOfDate | F6: =COB -> 43798 | L6: 3Y | M6: -0.0012125
B7: StaticDataTable | C7: XccyBasis | H7: FXFWDS | L7: 4Y | M7: -0.0012625
B8: IndexName | C8: ESTRDF_SOFRCSA | E8: CREATE MARKET DATA HANDLE | H8: Term | I8: Rate | L8: 5Y | M8: -0.0013125
B9: Currency | C9: EUR | E9: Handle Name | F9: EUR_XCCYBASIS_MARKETDATA | H9: ON | I9: 1.948 | L9: 6Y | M9: -0.001375
B10: interpolation | C10: FN_SPLINEINTERPOLATION | E10: Market Data Handle | F10: =_xll.meLWOCurveMarketDataCreate(F9,E2,E3:F6,H2,H4:J4,H7,H9:I23,L2,L4:M23) -> EUR_XCCYBASIS_MARKETDATA@16:8 | H10: TN | I10: 0.65 | L10: 7Y | M10: -0.0014375
B11: yieldgen.interpolation | C11: FN_SPLINEINTERPOLATION | H11: 1W | I11: 4.63 | L11: 8Y | M11: -0.0014875
B12: basis.interpolation | C12: FN_SPLINEINTERPOLATION | H12: 2W | I12: 9.31 | L12: 9Y | M12: -0.0015125
B13: isFwdBasis | C13: FALSE | E13: CURVE DICTIONARY | H13: 3W | I13: 14.02 | L13: 10Y | M13: -0.0015375
B14: isRenotionalAdjust | C14: TRUE | E14: HandleName | F14: EUR_XCCY_CURVE | H14: 1M | I14: 27.49 | L14: 12Y | M14: -0.0015
B15: isFwdFX | C15: FALSE | E15: CurveGenerator | F15: =$C$2 -> ESTR_SOFR_XCCY@15:8 | H15: 2M | I15: 49 | L15: 15Y | M15: -0.0013125
B16: isFraUse | C16: FALSE | E16: DomesticCurve | F16: EURYC | H16: 3M | I16: 69 | L16: 20Y | M16: -0.0007625
E17: ForeignCurve | F17: USDYC | H17: 4M | I17: 90.65 | L17: 25Y | M17: -0.0002375
B18: XCCYSWAPS | H18: 5M | I18: 111.65 | L18: 30Y | M18: 0.00015
B19: MarketName | C19: XccyBasis | E19: CREATE CURVE HANDLE | H19: 6M | I19: 131.85 | L19: 40Y | M19: 0.00015
B20: isleg1spread | C20: TRUE | E20: Handle Name | F20: {=IF(EUR_ESTR_CURVE!$D$27,_xll.meLWOCurveCalibrate($F$14,$F$15,$F$10,$F$16,$F$17),"LOAD ESTR CURVE")} -> EUR_XCCY_CURVE@17:8 | H20: 9M | I20: 193.54 | L20: 50Y | M20: 0.00015
B21: leg1cashlet.calendar | C21: TGT:NYB | E21: Curve Collection | F21: EURYC
B22: leg1cashlet.daycount | C22: ACT/360 | E22: Curve Index | F22: XccyBasis:ESTRDF_SOFRCSA
B23: leg1cashlet.frequency | C23: QUARTERLY | E23: Calibration Time Taken | F23: 0.37700 sec
B24: leg1cashlet.slidingrule | C24: MOD_FOLLOWING | E24: IsCurveLoaded | F24: TRUE
B25: leg1cashlet.spotlag | C25: 2D
B26: leg1forecast | C26: ESTR
B27: leg1discount | C27: ESTR
B28: leg1index.accessary | C28: 3M
B29: leg1index.daycount | C29: ACT/360
B30: leg1index.fixing.calendar | C30: TGT:NYB
B31: leg1index.frequency | C31: SIMPLE
B32: leg1index.payment.calendar | C32: TGT:NYB
B33: leg1index.resetlag | C33: 0
B34: leg1index.slidingrule | C34: MOD_FOLLOWING
B35: leg2cashlet.calendar | C35: TGT:NYB
B36: leg2cashlet.daycount | C36: ACT/360
B37: leg2cashlet.frequency | C37: QUARTERLY
B38: leg2cashlet.slidingrule | C38: MOD_FOLLOWING
B39: leg2cashlet.spotlag | C39: 2D
B40: leg2forecast | C40: AGAINST:SOFR
B41: leg2Discount | C41: AGAINST:SOFR
...

Sheet ESTR_DISCOUNT_FACTORS
B2: CurveCollection | C2: EURYC | E2: {=_xll.meLWOCurveDiscountFactorsTable(C2,C3:C4,"0D","30Y",,,,"QUARTERLY")} -> Payment Dates | F2: ESTR | G2: ESTRDF_SOFRCSA
B3: CurveIndex | C3: ESTR | E3: 43798 | F3: 1 | G3: 1
C4: ESTRDF_SOFRCSA | E4: 43889 | F4: 1.0013525 | G4: 1.0016636
E5: 43980 | F5: 1.0027509 | G5: 1.0033425
E6: 44074 | F6: 1.0042416 | G6: 1.0051063
E7: 44165 | F7: 1.0057253 | G7: 1.0068554
E8: 44253 | F8: 1.0071791 | G8: 1.0085927
E9: 44347 | F9: 1.0087298 | G9: 1.0104806
E10: 44438 | F10: 1.0102308 | G10: 1.0123165
E11: 44529 | F11: 1.0117171 | G11: 1.0141369
E12: 44620 | F12: 1.0131714 | G12: 1.0159222
E13: 44711 | F13: 1.014586 | G13: 1.0176679
E14: 44802 | F14: 1.0159557 | G14: 1.0193732
E15: 44894 | F15: 1.0172899 | G15: 1.0210557
E16: 44985 | F16: 1.0185547 | G16: 1.0226772
... E123: 54756 | F123: 0.92951815 | G123: 0.92365779
E124: #N/A | F124: #N/A | G124: #N/A
E125: #N/A | F125: #N/A | G125: #N/A
E126: #N/A | F126: #N/A | G126: #N/A
E127: #N/A | F127: #N/A | G127: #N/A
E128: #N/A | F128: #N/A | G128: #N/A
E129: #N/A | F129: #N/A | G129: #N/A
E130: #N/A | F130: #N/A | G130: #N/A

Sheet ESTR_SOFR_XCCY
E1: ...TradeDates
B3: Trade Dates | F3: XCCY: ESTRDF_SOFRCSA
D4: Unadjusted Date ! | H4: Swap Template
B5: EffectiveDate | C5: Calendar | D5: MaturityDate | F5: EffectiveDate | G5: Maturity | H5: Generator | I5: PayRec | J5: Notional | K5: Leg 1 Spread | L5: Leg 2 Spread | N5: Create Xccy Swap | O5: ParSpread | P5: CurveSpread | Q5: +/- | S5: Xccy Properties | V5: =_xll.meLWOSwapGeneratorCreate("ESTR_USDSOFR_XCCY",V7:X41) -> ESTR_USDSOFR_XCCY@18:13
B6: =_xll.meDateFromTenor(COB,F6,"MOD_FOLLOWING",$C6,"") -> 43802 | C6: TGT:NYB | D6: =_xll.meDateFromTenor(B6,G6,) -> 44168 | E6: 1 | F6: 2D | G6: =ESTR_SOFR_XCCY_CURVE!L4 -> 1Y | H6: =$V$5 -> ESTR_USDSOFR_XCCY@18:13 | I6: PAY | J6: 1000000 | K6: 0 | L6: 0 | N6: =_xll.meLWOXccySwapCreateFromGenerator("ESTR_SOFR_XCCY_"&$G6,$H6,I6,J6,B6,D6,K6,L6,,,,,$T$7,$T$14,$T$6,$T$8) -> ESTR_SOFR_XCCY_1Y@19:13 | O6: =_xll.meLWOXccySwapParSpread(N6,$S$12:$T$14,,"Leg1:Float") -> -11 | P6: =ESTR_SOFR_XCCY_CURVE!M4*10000 -> -11 | Q6: =O6-P6 -> 1.9568347e-11 | S6: MTM | T6: TRUE
B7: =_xll.meDateFromTenor(COB,F7,"MOD_FOLLOWING",$C7,"") -> 43802 | C7: TGT:NYB | D7: =_xll.meDateFromTenor(B7,G7,) -> 44533 | E7: =E6+1 -> 2 | F7: 2D | G7: =ESTR_SOFR_XCCY_CURVE!L5 -> 2Y | H7: =$V$5 -> ESTR_USDSOFR_XCCY@18:13 | I7: PAY | J7: 1000000 | K7: 0 | L7: 0 | N7: =_xll.meLWOXccySwapCreateFromGenerator("ESTR_SOFR_XCCY_"&$G7,$H7,I7,J7,B7,D7,K7,L7,,,,,$T$7,$T$14,$T$6,$T$8) -> ESTR_SOFR_XCCY_2Y@20:13 | O7: =_xll.meLWOXccySwapParSpread(N7,$S$12:$T$14,,"Leg1:Float") -> -11.75 | P7: =ESTR_SOFR_XCCY_CURVE!M5*10000 -> -11.75 | Q7: =O7-P7 -> 2.9022118e-11 | S7: ValuationCurrency | T7: USD | V7: LEGTYPE | W7: Leg1:FLOAT | X7: Leg2:FLOAT
B8: =_xll.meDateFromTenor(COB,F8,"MOD_FOLLOWING",$C8,"") -> 43802 | C8: TGT:NYB | D8: =_xll.meDateFromTenor(B8,G8,) -> 44898 | E8: =E7+1 -> 3 | F8: 2D | G8: =ESTR_SOFR_XCCY_CURVE!L6 -> 3Y | H8: =$V$5 -> ESTR_USDSOFR_XCCY@18:13 | I8: PAY | J8: 1000000 | K8: 0 | L8: 0 | N8: =_xll.meLWOXccySwapCreateFromGenerator("ESTR_SOFR_XCCY_"&$G8,$H8,I8,J8,B8,D8,K8,L8,,,,,$T$7,$T$14,$T$6,$T$8) -> ESTR_SOFR_XCCY_3Y@21:13 | O8: =_xll.meLWOXccySwapParSpread(N8,$S$12:$T$14,,"Leg1:Float") -> -12.123741 | P8: =ESTR_SOFR_XCCY_CURVE!M6*10000 -> -12.125 | Q8: =O8-P8 -> 0.0012590071 | S8: NotionalFxResetLeg | T8: Leg2:Float | V8: LEVERAGE | W8: 1 | X8: 1
B9: =_xll.meDateFromTenor(COB,F9,"MOD_FOLLOWING",$C9,"") -> 43802 | C9: TGT:NYB | D9: =_xll.meDateFromTenor(B9,G9,) -> 45263 | E9: =E8+1 -> 4 | F9: 2D | G9: =ESTR_SOFR_XCCY_CURVE!L7 -> 4Y | H9: =$V$5 -> ESTR_USDSOFR_XCCY@18:13 | I9: PAY | J9: 1000000 | K9: 0 | L9: 0 | N9: =_xll.meLWOXccySwapCreateFromGenerator("ESTR_SOFR_XCCY_"&$G9,$H9,I9,J9,B9,D9,K9,L9,,,,,$T$7,$T$14,$T$6,$T$8) -> ESTR_SOFR_XCCY_4Y@22:13 | O9: =_xll.meLWOXccySwapParSpread(N9,$S$12:$T$14,,"Leg1:Float") -> -12.620065 | P9: =ESTR_SOFR_XCCY_CURVE!M7*10000 -> -12.625 | Q9: =O9-P9 -> 0.0049353816 | V9: FORECASTCURVE | W9: ESTR | X9: SOFR
B10: =_xll.meDateFromTenor(COB,F10,"MOD_FOLLOWING",$C10,"") -> 43802 | C10: TGT:NYB | D10: =_xll.meDateFromTenor(B10,G10,) -> 45629 | E10: =E9+1 -> 5 | F10: 2D | G10: =ESTR_SOFR_XCCY_CURVE!L8 -> 5Y | H10: =$V$5 -> ESTR_USDSOFR_XCCY@18:13 | I10: PAY | J10: 1000000 | K10: 0 | L10: 0 | N10: =_xll.meLWOXccySwapCreateFromGenerator("ESTR_SOFR_XCCY_"&$G10,$H10,I10,J10,B10,D10,K10,L10,,,,,$T$7,$T$14,$T$6,$T$8) -> ESTR_SOFR_XCCY_5Y@23:59 | O10: =_xll.meLWOXccySwapParSpread(N10,$S$12:$T$14,,"Leg1:Float") -> -13.120366 | P10: =ESTR_SOFR_XCCY_CURVE!M8*10000 -> -13.125 | Q10: =O10-P10 -> 0.0046335991 | V10: COMPOUNDMETHOD
B11: =_xll.meDateFromTenor(COB,F11,"MOD_FOLLOWING",$C11,"") -> 43802 | C11: TGT:NYB | D11: =_xll.meDateFromTenor(B11,G11,) -> 45994 | E11: =E10+1 -> 6 | F11: 2D | G11: =ESTR_SOFR_XCCY_CURVE!L9 -> 6Y | H11: =$V$5 -> ESTR_USDSOFR_XCCY@18:13 | I11: PAY | J11: 1000000 | K11: 0 | L11: 0 | N11: =_xll.meLWOXccySwapCreateFromGenerator("ESTR_SOFR_XCCY_"&$G11,$H11,I11,J11,B11,D11,K11,L11,,,,,$T$7,$T$14,$T$6,$T$8) -> ESTR_SOFR_XCCY_6Y@24:13 | O11: =_xll.meLWOXccySwapParSpread(N11,$S$12:$T$14,,"Leg1:Float") -> -13.746149 | P11: =ESTR_SOFR_XCCY_CURVE!M9*10000 -> -13.75 | Q11: =O11-P11 -> 0.0038513027 | S11: Xccy Valuation Settings | V11: NOTIONALEXCHANGE | W11: START_AND_END | X11: START_AND_END
B12: =_xll.meDateFromTenor(COB,F12,"MOD_FOLLOWING",$C12,"") -> 43802 | C12: TGT:NYB | D12: =_xll.meDateFromTenor(B12,G12,) -> 46359 | E12: =E11+1 -> 7 | F12: 2D | G12: =ESTR_SOFR_XCCY_CURVE!L10 -> 7Y | H12: =$V$5 -> ESTR_USDSOFR_XCCY@18:13 | I12: PAY | J12: 1000000 | K12: 0 | L12: 0 | N12: =_xll.meLWOXccySwapCreateFromGenerator("ESTR_SOFR_XCCY_"&$G12,$H12,I12,J12,B12,D12,K12,L12,,,,,$T$7,$T$14,$T$6,$T$8) -> ESTR_SOFR_XCCY_7Y@25:13 | O12: =_xll.meLWOXccySwapParSpread(N12,$S$12:$T$14,,"Leg1:Float") -> -14.371706 | P12: =ESTR_SOFR_XCCY_CURVE!M10*10000 -> -14.375 | Q12: =O12-P12 -> 0.0032935283 | S12: Leg1:Float | T12: EURYC | V12: DISCOUNTCURVE | W12: ESTRDF_SOFRCSA | X12: SOFR
B13: =_xll.meDateFromTenor(COB,F13,"MOD_FOLLOWING",$C13,"") -> 43802 | C13: TGT:NYB | D13: =_xll.meDateFromTenor(B13,G13,) -> 46724 | E13: =E12+1 -> 8 | F13: 2D | G13: =ESTR_SOFR_XCCY_CURVE!L11 -> 8Y | H13: =$V$5 -> ESTR_USDSOFR_XCCY@18:13 | I13: PAY | J13: 1000000 | K13: 0 | L13: 0 | N13: =_xll.meLWOXccySwapCreateFromGenerator("ESTR_SOFR_XCCY_"&$G13,$H13,I13,J13,B13,D13,K13,L13,,,,,$T$7,$T$14,$T$6,$T$8) -> ESTR_SOFR_XCCY_8Y@26:13 | O13: =_xll.meLWOXccySwapParSpread(N13,$S$12:$T$14,,"Leg1:Float") -> -14.872124 | P13: =ESTR_SOFR_XCCY_CURVE!M11*10000 -> -14.875 | Q13: =O13-P13 -> 0.002876264 | S13: Leg2:Float | T13: USDYC | V13: VALUATIONCURRENCY | W13: EUR | X13: USD
B14: =_xll.meDateFromTenor(COB,F14,"MOD_FOLLOWING",$C14,"") -> 43802 | C14: TGT:NYB | D14: =_xll.meDateFromTenor(B14,G14,) -> 47090 | E14: =E13+1 -> 9 | F14: 2D | G14: =ESTR_SOFR_XCCY_CURVE!L12 -> 9Y | H14: =$V$5 -> ESTR_USDSOFR_XCCY@18:13 | I14: PAY | J14: 1000000 | K14: 0 | L14: 0 | N14: =_xll.meLWOXccySwapCreateFromGenerator("ESTR_SOFR_XCCY_"&$G14,$H14,I14,J14,B14,D14,K14,L14,,,,,$T$7,$T$14,$T$6,$T$8) -> ESTR_SOFR_XCCY_9Y@27:13 | O14: =_xll.meLWOXccySwapParSpread(N14,$S$12:$T$14,,"Leg1:Float") -> -15.122101 | P14: =ESTR_SOFR_XCCY_CURVE!M12*10000 -> -15.125 | Q14: =O14-P14 -> 0.0028988994 | S14: FXSPOT | T14: =ESTR_SOFR_XCCY_CURVE!J4 -> 1.10055 | U14: EUR/USD | V14: CURRENCY | W14: EUR | X14: USD
B15: =_xll.meDateFromTenor(COB,F15,"MOD_FOLLOWING",$C15,"") -> 43802 | C15: TGT:NYB | D15: =_xll.meDateFromTenor(B15,G15,) -> 47455 | E15: =E14+1 -> 10 | F15: 2D | G15: =ESTR_SOFR_XCCY_CURVE!L13 -> 10Y | H15: =$V$5 -> ESTR_USDSOFR_XCCY@18:13 | I15: PAY | J15: 1000000 | K15: 0 | L15: 0 | N15: =_xll.meLWOXccySwapCreateFromGenerator("ESTR_SOFR_XCCY_"&$G15,$H15,I15,J15,B15,D15,K15,L15,,,,,$T$7,$T$14,$T$6,$T$8) -> ESTR_SOFR_XCCY_10Y@28:13 | O15: =_xll.meLWOXccySwapParSpread(N15,$S$12:$T$14,,"Leg1:Float") -> -15.371915 | P15: =ESTR_SOFR_XCCY_CURVE!M13*10000 -> -15.375 | Q15: =O15-P15 -> 0.0030854082 | V15: ACCRUALFREQUENCY | W15: QUARTERLY | X15: QUARTERLY
B16: =_xll.meDateFromTenor(COB,F16,"MOD_FOLLOWING",$C16,"") -> 43802 | C16: TGT:NYB | D16: =_xll.meDateFromTenor(B16,G16,) -> 48185 | E16: =E15+1 -> 11 | F16: 2D | G16: =ESTR_SOFR_XCCY_CURVE!L14 -> 12Y | H16: =$V$5 -> ESTR_USDSOFR_XCCY@18:13 | I16: PAY | J16: 1000000 | K16: 0 | L16: 0 | N16: =_xll.meLWOXccySwapCreateFromGenerator("ESTR_SOFR_XCCY_"&$G16,$H16,I16,J16,B16,D16,K16,L16,,,,,$T$7,$T$14,$T$6,$T$8) -> ESTR_SOFR_XCCY_12Y@29:13 | O16: =_xll.meLWOXccySwapParSpread(N16,$S$12:$T$14,,"Leg1:Float") -> -14.99727 | P16: =ESTR_SOFR_XCCY_CURVE!M14*10000 -> -15 | Q16: =O16-P16 -> 0.0027303088 | V16: ACCRUALBUSINESSDAYADJUSTMENT | W16: MOD_FOLLOWING | X16: MOD_FOLLOWING
B17: =_xll.meDateFromTenor(COB,F17,"MOD_FOLLOWING",$C17,"") -> 43802 | C17: TGT:NYB | D17: =_xll.meDateFromTenor(B17,G17,) -> 49281 | E17: =E16+1 -> 12 | F17: 2D | G17: =ESTR_SOFR_XCCY_CURVE!L15 -> 15Y | H17: =$V$5 -> ESTR_USDSOFR_XCCY@18:13 | I17: PAY | J17: 1000000 | K17: 0 | L17: 0 | N17: =_xll.meLWOXccySwapCreateFromGenerator("ESTR_SOFR_XCCY_"&$G17,$H17,I17,J17,B17,D17,K17,L17,,,,,$T$7,$T$14,$T$6,$T$8) -> ESTR_SOFR_XCCY_15Y@30:13 | O17: =_xll.meLWOXccySwapParSpread(N17,$S$12:$T$14,,"Leg1:Float") -> -13.122294 | P17: =ESTR_SOFR_XCCY_CURVE!M15*10000 -> -13.125 | Q17: =O17-P17 -> 0.0027058565 | V17: ACCRUALCALENDAR | W17: TGT:NYB | X17: TGT:NYB
B18: =_xll.meDateFromTenor(COB,F18,"MOD_FOLLOWING",$C18,"") -> 43802 | C18: TGT:NYB | D18: =_xll.meDateFromTenor(B18,G18,) -> 51107 | E18: =E17+1 -> 13 | F18: 2D | G18: =ESTR_SOFR_XCCY_CURVE!L16 -> 20Y | H18: =$V$5 -> ESTR_USDSOFR_XCCY@18:13 | I18: PAY | J18: 1000000 | K18: 0 | L18: 0 | N18: =_xll.meLWOXccySwapCreateFromGenerator("ESTR_SOFR_XCCY_"&$G18,$H18,I18,J18,B18,D18,K18,L18,,,,,$T$7,$T$14,$T$6,$T$8) -> ESTR_SOFR_XCCY_20Y@31:13 | O18: =_xll.meLWOXccySwapParSpread(N18,$S$12:$T$14,,"Leg1:Float") -> -7.6227724 | P18: =ESTR_SOFR_XCCY_CURVE!M16*10000 -> -7.625 | Q18: =O18-P18 -> 0.0022275776 | V18: ACCRUALDAYCOUNT | W18: ACT/360 | X18: ACT/360
B19: =_xll.meDateFromTenor(COB,F19,"MOD_FOLLOWING",$C19,"") -> 43802 | C19: TGT:NYB | D19: =_xll.meDateFromTenor(B19,G19,) -> 52934 | E19: =E18+1 -> 14 | F19: 2D | G19: =ESTR_SOFR_XCCY_CURVE!L17 -> 25Y | H19: =$V$5 -> ESTR_USDSOFR_XCCY@18:13 | I19: PAY | J19: 1000000 | K19: 0 | L19: 0 | N19: =_xll.meLWOXccySwapCreateFromGenerator("ESTR_SOFR_XCCY_"&$G19,$H19,I19,J19,B19,D19,K19,L19,,,,,$T$7,$T$14,$T$6,$T$8) -> ESTR_SOFR_XCCY_25Y@32:13 | O19: =_xll.meLWOXccySwapParSpread(N19,$S$12:$T$14,,"Leg1:Float") -> -2.3731161 | P19: =ESTR_SOFR_XCCY_CURVE!M17*10000 -> -2.375 | Q19: =O19-P19 -> 0.0018839345 | V19: PAYMENTFREQUENCY
B20: =_xll.meDateFromTenor(COB,F20,"MOD_FOLLOWING",$C20,"") -> 43802 | C20: TGT:NYB | D20: =_xll.meDateFromTenor(B20,G20,) -> 54760 | E20: =E19+1 -> 15 | F20: 2D | G20: =ESTR_SOFR_XCCY_CURVE!L18 -> 30Y | H20: =$V$5 -> ESTR_USDSOFR_XCCY@18:13 | I20: PAY | J20: 1000000 | K20: 0 | L20: 0 | N20: =_xll.meLWOXccySwapCreateFromGenerator("ESTR_SOFR_XCCY_"&$G20,$H20,I20,J20,B20,D20,K20,L20,,,,,$T$7,$T$14,$T$6,$T$8) -> ESTR_SOFR_XCCY_30Y@33:13 | O20: =_xll.meLWOXccySwapParSpread(N20,$S$12:$T$14,,"Leg1:Float") -> 1.5017235 | P20: =ESTR_SOFR_XCCY_CURVE!M18*10000 -> 1.5 | Q20: =O20-P20 -> 0.0017234544 | V20: PAYMENTBUSINESSDAYADJUSTMENT | W20: MOD_FOLLOWING | X20: MOD_FOLLOWING
V21: PAYMENTCALENDAR | W21: TGT:NYB | X21: TGT:NYB
V22: PAYMENTLAG | W22: 0D | X22: 0D
V23: FIRSTSTUBDATE
V24: LASTSTUBDATE
V25: ROLLDAY | W25: NORMAL | X25: NORMAL
V26: STUBTYPE | W26: ShortStart | X26: ShortStart
V27: FIXINGBUSINESSDAYADJUSTMENT | W27: MOD_FOLLOWING | X27: MOD_FOLLOWING
V28: FIXINGCALENDAR | W28: TGT:NYB | X28: TGT:NYB
V29: FIXINGLAG | W29: 0D | X29: 0D
V30: FIXINGADVANCEORARREAR
V31: ISFWDINTER
V32: FIRSTSTUBCURVEINDEX | W32: NATURAL | X32: NATURAL
V33: LASTSTUBCURVEINDEX | W33: NATURAL | X33: NATURAL
V34: CMSGENERATOR1
V35: CMSINDEXMATURITY1
V36: CMSGENERATOR2
V37: CMSINDEXMATURITY2
V38: PAYMENTTRIGGER
V39: CALCULATIONTYPE
V40: EXDIVIDENDTENOR
V41: EXDIVIDENDBUSINESSDAYADJUSTMENT

Sheet EONIA_EQ_ESTR_PLUS_8.5
L2: EONIA-ESTR SPREAD
L3: 8.5
B4: Trade Dates | F4: ESTR IMPLIED PAR RATES | N4: Trade Booking & Pricing
D5: Unadjusted Date ! | H5: Swap Template
B6: EffectiveDate | C6: Calendar | D6: MaturityDate | F6: EffectiveDate | G6: Maturity | H6: Generator | I6: PayRec | J6: Notional | K6: FixedRate | L6: Libor Spread (Bps) | N6: CreateSwap | O6: CurveCollection | P6: ParRate
B7: =_xll.meDateFromTenor(COB,F7,"MOD_FOLLOWING",C7,"") -> 43802 | C7: TGT | D7: =_xll.meDateFromTenor(B7,G7,) -> 43985 | F7: 2D | G7: 6M | H7: =SWAP_GENERATOR_ESTR -> EUR_ESTR_SWAP@3:9 | I7: RECEIVE | J7: 1000000 | K7: 0 | L7: =$L$3 -> 8.5 | M7: 1 | N7: =_xll.meLWOSwapCreateFromGenerator("EONIA_IMPLIED_PAR_RATE_"&G7,H7,I7,J7,B7,D7,K7,L7) -> EONIA_IMPLIED_PAR_RATE_6M@88:4 | O7: EURYC | P7: =_xll.meLWOSwapParRate(N7,O7) -> -0.0045861411
B8: =_xll.meDateFromTenor(COB,F8,"MOD_FOLLOWING",C8,"") -> 43802 | C8: TGT | D8: =_xll.meDateFromTenor(B8,G8,) -> 44168 | F8: 2D | G8: 1Y | H8: =SWAP_GENERATOR_ESTR -> EUR_ESTR_SWAP@3:9 | I8: RECEIVE | J8: 1000000 | K8: 0 | L8: =$L$3 -> 8.5 | M8: 2 | N8: =_xll.meLWOSwapCreateFromGenerator("EONIA_IMPLIED_PAR_RATE_"&G8,H8,I8,J8,B8,D8,K8,L8) -> EONIA_IMPLIED_PAR_RATE_1Y@85:4 | O8: EURYC | P8: =_xll.meLWOSwapParRate(N8,O8) -> -0.0047444419
B9: =_xll.meDateFromTenor(COB,F9,"MOD_FOLLOWING",C9,"") -> 43802 | C9: TGT | D9: =_xll.meDateFromTenor(B9,G9,) -> 44533 | F9: 2D | G9: 2Y | H9: =SWAP_GENERATOR_ESTR -> EUR_ESTR_SWAP@3:9 | I9: RECEIVE | J9: 1000000 | K9: 0 | L9: =$L$3 -> 8.5 | M9: 3 | N9: =_xll.meLWOSwapCreateFromGenerator("EONIA_IMPLIED_PAR_RATE_"&G9,H9,I9,J9,B9,D9,K9,L9) -> EONIA_IMPLIED_PAR_RATE_2Y@94:4 | O9: EURYC | P9: =_xll.meLWOSwapParRate(N9,O9) -> -0.0048775499
B10: =_xll.meDateFromTenor(COB,F10,"MOD_FOLLOWING",C10,"") -> 43802 | C10: TGT | D10: =_xll.meDateFromTenor(B10,G10,) -> 44898 | F10: 2D | G10: 3Y | H10: =SWAP_GENERATOR_ESTR -> EUR_ESTR_SWAP@3:9 | I10: RECEIVE | J10: 1000000 | K10: 0 | L10: =$L$3 -> 8.5 | M10: 4 | N10: =_xll.meLWOSwapCreateFromGenerator("EONIA_IMPLIED_PAR_RATE_"&G10,H10,I10,J10,B10,D10,K10,L10) -> EONIA_IMPLIED_PAR_RATE_3Y@86:4 | O10: EURYC | P10: =_xll.meLWOSwapParRate(N10,O10) -> -0.0047664606
B11: =_xll.meDateFromTenor(COB,F11,"MOD_FOLLOWING",C11,"") -> 43802 | C11: TGT | D11: =_xll.meDateFromTenor(B11,G11,) -> 45263 | F11: 2D | G11: 4Y | H11: =SWAP_GENERATOR_ESTR -> EUR_ESTR_SWAP@3:9 | I11: RECEIVE | J11: 1000000 | K11: 0 | L11: =$L$3 -> 8.5 | M11: 5 | N11: =_xll.meLWOSwapCreateFromGenerator("EONIA_IMPLIED_PAR_RATE_"&G11,H11,I11,J11,B11,D11,K11,L11) -> EONIA_IMPLIED_PAR_RATE_4Y@83:4 | O11: EURYC | P11: =_xll.meLWOSwapParRate(N11,O11) -> -0.0044972245
B12: =_xll.meDateFromTenor(COB,F12,"MOD_FOLLOWING",C12,"") -> 43802 | C12: TGT | D12: =_xll.meDateFromTenor(B12,G12,) -> 45629 | F12: 2D | G12: 5Y | H12: =SWAP_GENERATOR_ESTR -> EUR_ESTR_SWAP@3:9 | I12: RECEIVE | J12: 1000000 | K12: 0 | L12: =$L$3 -> 8.5 | M12: 6 | N12: =_xll.meLWOSwapCreateFromGenerator("EONIA_IMPLIED_PAR_RATE_"&G12,H12,I12,J12,B12,D12,K12,L12) -> EONIA_IMPLIED_PAR_RATE_5Y@92:4 | O12: EURYC | P12: =_xll.meLWOSwapParRate(N12,O12) -> -0.0041158963
B13: =_xll.meDateFromTenor(COB,F13,"MOD_FOLLOWING",C13,"") -> 43802 | C13: TGT | D13: =_xll.meDateFromTenor(B13,G13,) -> 45994 | F13: 2D | G13: 6Y | H13: =SWAP_GENERATOR_ESTR -> EUR_ESTR_SWAP@3:9 | I13: RECEIVE | J13: 1000000 | K13: 0 | L13: =$L$3 -> 8.5 | M13: 7 | N13: =_xll.meLWOSwapCreateFromGenerator("EONIA_IMPLIED_PAR_RATE_"&G13,H13,I13,J13,B13,D13,K13,L13) -> EONIA_IMPLIED_PAR_RATE_6Y@91:4 | O13: EURYC | P13: =_xll.meLWOSwapParRate(N13,O13) -> -0.0036244743
B14: =_xll.meDateFromTenor(COB,F14,"MOD_FOLLOWING",C14,"") -> 43802 | C14: TGT | D14: =_xll.meDateFromTenor(B14,G14,) -> 46359 | F14: 2D | G14: 7Y | H14: =SWAP_GENERATOR_ESTR -> EUR_ESTR_SWAP@3:9 | I14: RECEIVE | J14: 1000000 | K14: 0 | L14: =$L$3 -> 8.5 | M14: 8 | N14: =_xll.meLWOSwapCreateFromGenerator("EONIA_IMPLIED_PAR_RATE_"&G14,H14,I14,J14,B14,D14,K14,L14) -> EONIA_IMPLIED_PAR_RATE_7Y@98:4 | O14: EURYC | P14: =_xll.meLWOSwapParRate(N14,O14) -> -0.0030980226
B15: =_xll.meDateFromTenor(COB,F15,"MOD_FOLLOWING",C15,"") -> 43802 | C15: TGT | D15: =_xll.meDateFromTenor(B15,G15,) -> 46724 | F15: 2D | G15: 8Y | H15: =SWAP_GENERATOR_ESTR -> EUR_ESTR_SWAP@3:9 | I15: RECEIVE | J15: 1000000 | K15: 0 | L15: =$L$3 -> 8.5 | M15: 9 | N15: =_xll.meLWOSwapCreateFromGenerator("EONIA_IMPLIED_PAR_RATE_"&G15,H15,I15,J15,B15,D15,K15,L15) -> EONIA_IMPLIED_PAR_RATE_8Y@93:4 | O15: EURYC | P15: =_xll.meLWOSwapParRate(N15,O15) -> -0.0025025118
B16: =_xll.meDateFromTenor(COB,F16,"MOD_FOLLOWING",C16,"") -> 43802 | C16: TGT | D16: =_xll.meDateFromTenor(B16,G16,) -> 47090 | F16: 2D | G16: 9Y | H16: =SWAP_GENERATOR_ESTR -> EUR_ESTR_SWAP@3:9 | I16: RECEIVE | J16: 1000000 | K16: 0 | L16: =$L$3 -> 8.5 | M16: 9 | N16: =_xll.meLWOSwapCreateFromGenerator("EONIA_IMPLIED_PAR_RATE_"&G16,H16,I16,J16,B16,D16,K16,L16) -> EONIA_IMPLIED_PAR_RATE_9Y@89:4 | O16: EURYC | P16: =_xll.meLWOSwapParRate(N16,O16) -> -0.001891987
B17: =_xll.meDateFromTenor(COB,F17,"MOD_FOLLOWING",C17,"") -> 43802 | C17: TGT | D17: =_xll.meDateFromTenor(B17,G17,) -> 47455 | F17: 2D | G17: 10Y | H17: =SWAP_GENERATOR_ESTR -> EUR_ESTR_SWAP@3:9 | I17: RECEIVE | J17: 1000000 | K17: 0 | L17: =$L$3 -> 8.5 | M17: 9 | N17: =_xll.meLWOSwapCreateFromGenerator("EONIA_IMPLIED_PAR_RATE_"&G17,H17,I17,J17,B17,D17,K17,L17) -> EONIA_IMPLIED_PAR_RATE_10Y@84:4 | O17: EURYC | P17: =_xll.meLWOSwapParRate(N17,O17) -> -0.0012914731
B18: =_xll.meDateFromTenor(COB,F18,"MOD_FOLLOWING",C18,"") -> 43802 | C18: TGT | D18: =_xll.meDateFromTenor(B18,G18,) -> 49281 | F18: 2D | G18: 15Y | H18: =SWAP_GENERATOR_ESTR -> EUR_ESTR_SWAP@3:9 | I18: RECEIVE | J18: 1000000 | K18: 0 | L18: =$L$3 -> 8.5 | M18: 9 | N18: =_xll.meLWOSwapCreateFromGenerator("EONIA_IMPLIED_PAR_RATE_"&G18,H18,I18,J18,B18,D18,K18,L18) -> EONIA_IMPLIED_PAR_RATE_15Y@90:4 | O18: EURYC | P18: =_xll.meLWOSwapParRate(N18,O18) -> 0.0012957466
... B20: =_xll.meDateFromTenor(COB,F20,"MOD_FOLLOWING",C20,"") -> 43802 | C20: TGT | D20: =_xll.meDateFromTenor(B20,G20,) -> 54760 | F20: 2D | G20: 30Y | H20: =SWAP_GENERATOR_ESTR -> EUR_ESTR_SWAP@3:9 | I20: RECEIVE | J20: 1000000 | K20: 0 | L20: =$L$3 -> 8.5 | M20: 10 | N20: =_xll.meLWOSwapCreateFromGenerator("EONIA_IMPLIED_PAR_RATE_"&G20,H20,I20,J20,B20,D20,K20,L20) -> EONIA_IMPLIED_PAR_RATE_30Y@97:4 | O20: EURYC | P20: =_xll.meLWOSwapParRate(N20,O20) -> 0.0032073854
