Workbook
Name COB: 'USD OIS'!$D$9

Sheet Raw Schedule
A1: 1000000 | I1: =MAX(F2:F161) -> 6.9071928e+08
C2: 43738 | D2: 43769 | E2: 38.892061 | F2: =E2*$A$1 -> 38892061 | G2: =D2-C2 -> 31
C3: 43769 | D3: 43799 | E3: 53.628705 | F3: =E3*$A$1 -> 53628705 | G3: =D3-C3 -> 30
C4: 43799 | D4: 43830 | E4: 68.386301 | F4: =E4*$A$1 -> 68386301 | G4: =D4-C4 -> 31
C5: 43830 | D5: 43861 | E5: 90.04852 | F5: =E5*$A$1 -> 90048520 | G5: =D5-C5 -> 31
C6: 43861 | D6: 43890 | E6: 111.76176 | F6: =E6*$A$1 -> 1.1176176e+08 | G6: =D6-C6 -> 29
C7: 43890 | D7: 43921 | E7: 133.48442 | F7: =E7*$A$1 -> 1.3348442e+08 | G7: =D7-C7 -> 31
C8: 43921 | D8: 43951 | E8: 159.45191 | F8: =E8*$A$1 -> 1.5945191e+08 | G8: =D8-C8 -> 30
C9: 43951 | D9: 43982 | E9: 179.26001 | F9: =E9*$A$1 -> 1.7926001e+08 | G9: =D9-C9 -> 31
C10: 43982 | D10: 44012 | E10: 204.39172 | F10: =E10*$A$1 -> 2.0439172e+08 | G10: =D10-C10 -> 30
C11: 44012 | D11: 44043 | E11: 227.8119 | F11: =E11*$A$1 -> 2.278119e+08 | G11: =D11-C11 -> 31
C12: 44043 | D12: 44074 | E12: 254.13395 | F12: =E12*$A$1 -> 2.5413395e+08 | G12: =D12-C12 -> 31
C13: 44074 | D13: 44104 | E13: 279.79136 | F13: =E13*$A$1 -> 2.7979136e+08 | G13: =D13-C13 -> 30
... C50: 45869 | D50: 45961 | E50: 529.33385 | F50: =E50*$A$1 -> 5.2933385e+08 | G50: =D50-C50 -> 92
C51: 45961 | D51: 46053 | E51: 0 | F51: =E51*$A$1 -> 0
C52: 46053 | D52: 46142 | E52: 0 | F52: =E52*$A$1 -> 0
C53: 46142 | D53: 46234 | E53: 0 | F53: =E53*$A$1 -> 0
C54: 46234 | D54: 46326 | E54: 0 | F54: =E54*$A$1 -> 0
C55: 46326 | D55: 46418 | E55: 0 | F55: =E55*$A$1 -> 0
C56: 46418 | D56: 46507 | E56: 0 | F56: =E56*$A$1 -> 0
C57: 46507 | D57: 46599 | E57: 0 | F57: =E57*$A$1 -> 0
C58: 46599 | D58: 46691 | E58: 0 | F58: =E58*$A$1 -> 0
C59: 46691 | D59: 46783 | E59: 0 | F59: =E59*$A$1 -> 0
C60: 46783 | D60: 46873 | E60: 0 | F60: =E60*$A$1 -> 0
C61: 46873 | D61: 46965 | E61: 0 | F61: =E61*$A$1 -> 0
C62: 46965 | D62: 47057 | E62: 0 | F62: =E62*$A$1 -> 0
... C161: 56004 | D161: 56096 | E161: 0 | F161: =E161*$A$1 -> 0

Sheet USD OIS
C4: MARKETDATAPROPERTIES | F4: OIS | L4: LIBOROISBASISSPREADS | O4: SWAPS
F5: Term | G5: Rate | H5: StartDate | I5: EndDate | J5: Use | L5: Term | M5: Rate | O5: Term | P5: Rate
C6: Currency | D6: USD | F6: ON | G6: 0.0182 | J6: TRUE | L6: 1Y | M6: 0.0030125 | O6: 1Y | P6: 0.017402
C7: CurveType | D7: OIS | F7: 1W | G7: 0.0184 | J7: TRUE | L7: 2Y | M7: 0.00275625 | O7: 2Y | P7: 0.015759
C8: CurveIndexFrequency | D8: DAILY | F8: 2W | G8: 0.0184 | J8: TRUE | L8: 3Y | M8: 0.0025875 | O8: 3Y | P8: 0.01506
C9: AsOfDate | D9: 43734 | F9: 3W | G9: 0.01786 | J9: TRUE | L9: 4Y | M9: 0.002525 | O9: 4Y | P9: 0.014768
F10: 1M | G10: 0.01734 | J10: TRUE | L10: 5Y | M10: 0.0025 | O10: 5Y | P10: 0.014693
F11: 2M | G11: 0.016876 | J11: TRUE | L11: 7Y | M11: 0.00245 | O11: 7Y | P11: 0.014999
C12: Create Market Data Handle | F12: 3M | G12: 0.016367 | J12: TRUE | L12: 10Y | M12: 0.0024 | O12: 10Y | P12: 0.015763
C13: Handle Name | D13: USD_OIS_CURVE_MARKETDATA | F13: 4M | G13: 0.015896 | J13: TRUE | L13: 12Y | M13: 0.002363 | O13: 12Y | P13: 0.016223
C14: Market Data Handle | D14: =_xll.meLWOCurveMarketDataCreate(D13,C4,C6:D9,F4,F6:J31,L4,L6:M31,O4,O6:P31) -> USD_OIS_CURVE_MARKETDATA@6:3 | F14: 5M | G14: 0.015641 | J14: TRUE | L14: 15Y | M14: 0.0023625 | O14: 15Y | P14: 0.016742
F15: 6M | G15: 0.015298 | J15: TRUE | L15: 20Y | M15: 0.002325 | O15: 20Y | P15: 0.017287
F16: 9M | G16: 0.014678 | J16: TRUE | L16: 25Y | M16: 0.0023375 | O16: 25Y | P16: 0.017479
F17: 1Y | G17: 0.014195 | J17: TRUE | L17: 30Y | M17: 0.0023625 | O17: 30Y | P17: 0.017557
F18: 2Y | G18: 0.01285 | J18: TRUE
C19: Curve Dictionary | F19: 3Y | G19: 0.012285 | J19: TRUE
C20: Handle Name | D20: USD_OIS_CURVE | F20: 4Y | G20: 0.012065 | J20: TRUE
C21: Curve Generator | D21: USD_OIS | F21: 5Y | G21: 0.012035 | J21: TRUE
C22: Domestic Curve Collection | D22: USDYC
C23: Foreign Curve Collection
C27: Curve Build
C28: Handle Name | D28: {=_xll.meLWOCurveCalibrate(D20,D21,D14,D22,D23)} -> USD_OIS_CURVE@7:3
C29: Curve Collection | D29: USDYC
C30: Curve Index | D30: OIS:USDOIS:USDDF:USDDF_USDCSA:USDDF_NOCSA
C31: Calibration Time Taken | D31: 0.01500 sec
C32: Curve Loaded | D32: =_xll.meLWOExists(D28,"CURVE") -> TRUE

Sheet USD SWAP 3ML
C4: MARKETDATAPROPERTIES | F4: LIBORFIXINGS | I4: FUTURES | O4: SWAPS
C5: Currency | D5: USD | F5: Term | G5: Rate | I5: Term | J5: StartDate | K5: EndDate | L5: Rate | M5: Volatility | O5: Term | P5: Rate | Q5: Use
C6: CurveType | D6: SWAP | F6: 1M | G6: 0.0192125 | I6: ED1 Comdty | J6: 43817 | K6: 43908 | L6: 98.13 | M6: 0.0145 | O6: 3Y | P6: 0.01506 | Q6: TRUE
C7: CurveIndexFrequency | D7: QUARTERLY | F7: 3M | G7: 0.0198613 | I7: ED2 Comdty | J7: 43908 | K7: 43999 | L7: 98.375 | M7: 0.0145 | O7: 4Y | P7: 0.014768 | Q7: TRUE
C8: AsOfDate | D8: =COB -> 43734 | F8: 6M | G8: 0.019355 | I8: ED3 Comdty | J8: 43999 | K8: 44090 | L8: 98.48 | M8: 0.0145 | O8: 5Y | P8: 0.014693 | Q8: TRUE
F9: 12M | G9: 0.01896 | I9: ED4 Comdty | J9: 44090 | K9: 44181 | L9: 98.545 | M9: 0.0145 | O9: 7Y | P9: 0.014999 | Q9: TRUE
I10: ED5 Comdty | J10: 44181 | K10: 44272 | L10: 98.555 | M10: 0.0145 | O10: 8Y | P10: 0.015243 | Q10: TRUE
I11: ED6 Comdty | J11: 44272 | K11: 44363 | L11: 98.635 | M11: 0.0145 | O11: 9Y | P11: 0.015504 | Q11: TRUE
C12: Create Market Data Handle | I12: ED7 Comdty | J12: 44363 | K12: 44454 | L12: 98.645 | M12: 0.0145 | O12: 10Y | P12: 0.015763 | Q12: TRUE
C13: Handle Name | D13: USD_SWAP_3M_CURVE_MARKETDATA | I13: ED8 Comdty | J13: 44454 | K13: 44545 | L13: 98.655 | M13: 0.0145 | O13: 12Y | P13: 0.016223 | Q13: TRUE
C14: Market Data Handle | D14: =_xll.meLWOCurveMarketDataCreate(D13,C4,C5:D10,F4,F6:G10,I4,I6:M31,O4,O6:Q31) -> USD_SWAP_3M_CURVE_MARKETDATA@1:3 | O14: 15Y | P14: 0.016742 | Q14: TRUE
O15: 20Y | P15: 0.017287 | Q15: TRUE
O16: 25Y | P16: 0.017479 | Q16: TRUE
O17: 30Y | P17: 0.017557 | Q17: TRUE
C20: Curve Dictionary
C21: Handle Name | D21: USD_SWAP_3M_CURVE
C22: Curve Generator | D22: USD_SWAP_3M
C23: Domestic Curve Collection | D23: USDYC
C24: Foreign Curve Collection
C27: Curve Build
C28: Handle Name | D28: {=IF('USD OIS'!$D$32,_xll.meLWOCurveCalibrate(D21,D22,D14,D23,D24),"LOAD USDOIS CURVE")} -> USD_SWAP_3M_CURVE@12:3
C29: Curve Collection | D29: USDYC
C30: Curve Index | D30: STD:USD3ML
C31: Calibration Time Taken | D31: 0.00700 sec
C32: Curve Loaded | D32: =_xll.meLWOExists(D28,"CURVE") -> TRUE

Sheet USD BASIS 6ML
B2: meCurveCalibrateBasis
K3: MARKETDATAPROPERTIES | N3: BASISSWAPS
D4: meCurveCalibrateBasis | E4: 1=IF(AND(isUSD3MLLoaded),meCurveCalibrateBasis(CurveCollection,StaticDataTable,IndexName,CurveBuildProperties,TenorBasisConventions,TenorBasisMarketData),"Please load curve dependencies") | K4: Currency | L4: USD | N4: Term | O4: Rate
D5: Curve Loaded | E5: =LEFT(E4,5)=CurveCollection -> #NAME? | K5: CurveType | L5: TENORBASIS | N5: 1Y | O5: 0.0007125
K6: CurveIndexFrequency | L6: SEMI-ANNUAL | N6: 2Y | O6: 0.0006625
K7: AsOfDate | L7: =COB -> 43734 | N7: 3Y | O7: 0.000675
D8: Curve Names | N8: 4Y | O8: 0.0007
D9: CurveCollection | E9: USDYC | K9: CREATE MARKET DATA HANDLE | N9: 5Y | O9: 0.000725
D10: StaticDataTable | E10: 3M6MBasis | K10: Handle Name | L10: USD_BASIS_3X6_MARKETDATA | N10: 6Y | O10: 0.0007625
D11: IndexName(s) | E11: 3M6MBasis:USD6ML | K11: Market Data Handle | L11: =_xll.meLWOCurveMarketDataCreate(L10,K3,K4:L7,N3,N5:O24) -> USD_BASIS_3X6_MARKETDATA@5:3 | N11: 7Y | O11: 0.0008
N12: 8Y | O12: 0.000825
N13: 9Y | O13: 0.00085
K14: CURVE DICTIONARY | N14: 10Y | O14: 0.000875
B15: Curve Build Properties | K15: HandleName | L15: USD_BASIS_6M_CURVE | N15: 12Y | O15: 0.0009125
K16: CurveGenerator | L16: USD_BASIS_3X6 | N16: 15Y | O16: 0.00095
D17: Curve Build Properties | K17: DomesticCurve | L17: USDYC | N17: 20Y | O17: 0.0009875
D18: AsOfDate | E18: =Settings.COB -> #NAME? | K18: ForeignCurve | N18: 25Y | O18: 0.0010125
D19: Currency | E19: USD | N19: 30Y | O19: 0.001025
D20: interpolation | E20: FN_SPLINEINTERPOLATION | K20: CREATE CURVE HANDLE
D21: yieldgen.interpolation | E21: FN_SPLINEINTERPOLATION | K21: Handle Name | L21: {=IF('USD SWAP 3ML'!$D$32,_xll.meLWOCurveCalibrate($L$15,$L$16,$L$11,$L$17,$L$18),"LOAD USD3ML CURVE")} -> USD_BASIS_6M_CURVE@13:3
D22: basis.interpolation | E22: FN_SPLINEINTERPOLATION | K22: Curve Collection | L22: USDYC
D23: isFwdBasis | E23: FALSE | K23: Curve Index | L23: 3M6MBasis:USD6ML
D24: dfCurveName | E24: OIS | K24: Calibration Time Taken | L24: 0.00800 sec
K25: IsCurveLoaded | L25: =_xll.meLWOExists(L21,"CURVE") -> TRUE
B32: Tenor Basis Swaps
D34: Tenor Basis Conventions ( 3 X 6 ) | G34: Tenor Basis Spreads ( 3 X 6 )
D35: MarketName | E35: 3M6MBasis | G35: Term | H35: Rate
C36: Known Leg | D36: IsLeg1Spread | E36: FALSE | G36: 1Y | H36: 0.0007125
D37: Leg1cashlet.calendar | E37: LNB:NYB | G37: 2Y | H37: 0.0006625
D38: Leg1cashlet.daycount | E38: ACT/360 | G38: 3Y | H38: 0.000675
D39: Leg1cashlet.frequency | E39: SEMI-ANNUAL | G39: 4Y | H39: 0.0007
D40: Leg1cashlet.slidingrule | E40: MOD_FOLLOWING | G40: 5Y | H40: 0.000725
D41: Leg1cashlet.spotlag | E41: 2 | G41: 6Y | H41: 0.0007625
D42: Leg1discount | E42: OIS | G42: 7Y | H42: 0.0008
D43: Leg1forecast | E43: STD | G43: 8Y | H43: 0.000825
D44: Leg1index.accessary | E44: 6M | G44: 9Y | H44: 0.00085
D45: Leg1index.daycount | E45: ACT/360 | G45: 10Y | H45: 0.000875
D46: Leg1index.fixing.calendar | E46: LNB:NYB | G46: 12Y | H46: 0.0009125
D47: Leg1index.frequency | E47: SIMPLE | G47: 15Y | H47: 0.00095
D48: Leg1index.payment.calendar | E48: LNB:NYB | G48: 20Y | H48: 0.0009875
...

Sheet USD BASIS 1ML
B2: meCurveCalibrateBasis
K3: MARKETDATAPROPERTIES | N3: BASISSWAPS
D4: meCurveCalibrateBasis | E4: 1=IF(AND(isUSD3MLLoaded),meCurveCalibrateBasis(CurveCollection,StaticDataTable,IndexName,CurveBuildProperties,TenorBasisConventions,TenorBasisMarketData),"Please load curve dependencies") | K4: Currency | L4: USD | N4: Term | O4: Rate
D5: Curve Loaded | E5: =LEFT(E4,5)=CurveCollection -> #NAME? | K5: CurveType | L5: TENORBASIS | N5: 1Y | O5: 0.0015625
K6: CurveIndexFrequency | L6: MONTHLY | N6: 2Y | O6: 0.0013375
K7: AsOfDate | L7: =COB -> 43734 | N7: 3Y | O7: 0.0012125
D8: Curve Names | N8: 4Y | O8: 0.00115
D9: CurveCollection | E9: USDYC | K9: CREATE MARKET DATA HANDLE | N9: 5Y | O9: 0.001125
D10: StaticDataTable | E10: 1M3MBasis | K10: Handle Name | L10: USD_BASIS_1X3_MARKETDATA | N10: 6Y | O10: 0.0011125
D11: IndexName(s) | E11: 1M3MBasis:USD1ML | K11: Market Data Handle | L11: =_xll.meLWOCurveMarketDataCreate(L10,K3,K4:L7,N3,N5:O24) -> USD_BASIS_1X3_MARKETDATA@2:3 | N11: 7Y | O11: 0.0011
N12: 8Y | O12: 0.0011
N13: 9Y | O13: 0.0010875
K14: CURVE DICTIONARY | N14: 10Y | O14: 0.0010875
B15: Curve Build Properties | K15: HandleName | L15: USD_BASIS_1M_CURVE | N15: 12Y | O15: 0.0010875
K16: CurveGenerator | L16: USD_BASIS_1X3 | N16: 15Y | O16: 0.001075
D17: Curve Build Properties | K17: DomesticCurve | L17: USDYC | N17: 20Y | O17: 0.001075
D18: AsOfDate | E18: =Settings.COB -> #NAME? | K18: ForeignCurve | N18: 25Y | O18: 0.0010625
D19: Currency | E19: USD | N19: 30Y | O19: 0.0010625
D20: interpolation | E20: FN_SPLINEINTERPOLATION | K20: CREATE CURVE HANDLE
D21: yieldgen.interpolation | E21: FN_SPLINEINTERPOLATION | K21: Handle Name | L21: {=IF('USD BASIS 6ML'!$L$25,_xll.meLWOCurveCalibrate($L$15,$L$16,$L$11,$L$17,$L$18),"LOAD USD6ML Curve")} -> USD_BASIS_1M_CURVE@14:3
D22: basis.interpolation | E22: FN_SPLINEINTERPOLATION | K22: Curve Collection | L22: USDYC
D23: isFwdBasis | E23: FALSE | K23: Curve Index | L23: 1M3MBasis:USD1ML
D24: dfCurveName | E24: OIS | K24: Calibration Time Taken | L24: 0.02500 sec
K25: IsCurveLoaded | L25: =_xll.meLWOExists(L21,"CURVE") -> TRUE
B32: Tenor Basis Swaps
D34: Tenor Basis Conventions ( 1 X 3 ) | G34: Tenor Basis Spreads ( 1 X 3 )
D35: MarketName | E35: 1M3MBasis | G35: Term | H35: Rate
C36: Known Leg | D36: IsLeg1Spread | E36: FALSE | G36: 1Y | H36: 0.0015625
D37: Leg1cashlet.calendar | E37: LNB:NYB | G37: 2Y | H37: 0.0013375
D38: Leg1cashlet.daycount | E38: ACT/360 | G38: 3Y | H38: 0.0012125
D39: Leg1cashlet.frequency | E39: QUARTERLY | G39: 4Y | H39: 0.00115
D40: Leg1cashlet.slidingrule | E40: MOD_FOLLOWING | G40: 5Y | H40: 0.001125
D41: Leg1cashlet.spotlag | E41: 2 | G41: 6Y | H41: 0.0011125
D42: Leg1discount | E42: OIS | G42: 7Y | H42: 0.0011
D43: Leg1forecast | E43: USD3ML | G43: 8Y | H43: 0.0011
D44: Leg1index.accessary | E44: 3M | G44: 9Y | H44: 0.0010875
D45: Leg1index.daycount | E45: ACT/360 | G45: 10Y | H45: 0.0010875
D46: Leg1index.fixing.calendar | E46: LNB:NYB | G46: 12Y | H46: 0.0010875
D47: Leg1index.frequency | E47: SIMPLE | G47: 15Y | H47: 0.001075
D48: Leg1index.payment.calendar | E48: LNB:NYB | G48: 20Y | H48: 0.001075
...

Sheet USD BASIS 12ML
B2: meCurveCalibrateBasis
K3: MARKETDATAPROPERTIES | N3: BASISSWAPS
D4: meCurveCalibrateBasis | E4: 1=IF(AND(isUSD3MLLoaded),meCurveCalibrateBasis(CurveCollection,StaticDataTable,IndexName,CurveBuildProperties,TenorBasisConventions,TenorBasisMarketData),"Please load curve dependencies") | K4: Currency | L4: USD | N4: Term | O4: Rate
D5: Curve Loaded | E5: =LEFT(E4,5)=CurveCollection -> #NAME? | K5: CurveType | L5: TENORBASIS | N5: 1Y | O5: 0.00185
K6: CurveIndexFrequency | L6: ANNUAL | N6: 2Y | O6: 0.0021
K7: AsOfDate | L7: =COB -> 43734 | N7: 3Y | O7: 0.0020625
D8: Curve Names | N8: 4Y | O8: 0.0019625
D9: CurveCollection | E9: USDYC | K9: CREATE MARKET DATA HANDLE | N9: 5Y | O9: 0.0019625
D10: StaticDataTable | E10: 3M12MBasis | K10: Handle Name | L10: USD_BASIS_3X12_MARKETDATA | N10: 7Y | O10: 0.001975
D11: IndexName(s) | E11: 3M12MBasis:USD12ML | K11: Market Data Handle | L11: =_xll.meLWOCurveMarketDataCreate(L10,K3,K4:L7,N3,N5:O24) -> USD_BASIS_3X12_MARKETDATA@4:3 | N11: 10Y | O11: 0.002
N12: 12Y | O12: 0.002
N13: 15Y | O13: 0.0019625
K14: CURVE DICTIONARY | N14: 20Y | O14: 0.0020875
B15: Curve Build Properties | K15: HandleName | L15: USD_BASIS_12M_CURVE | N15: 25Y | O15: 0.00215
K16: CurveGenerator | L16: USD_BASIS_3X12 | N16: 30Y | O16: 0.002275
D17: Curve Build Properties | K17: DomesticCurve | L17: USDYC
D18: AsOfDate | E18: =Settings.COB -> #NAME? | K18: ForeignCurve
D19: Currency | E19: USD
D20: interpolation | E20: FN_SPLINEINTERPOLATION | K20: CREATE CURVE HANDLE
D21: yieldgen.interpolation | E21: FN_SPLINEINTERPOLATION | K21: Handle Name | L21: {=IF('USD BASIS 1ML'!$L$25,_xll.meLWOCurveCalibrate($L$15,$L$16,$L$11,$L$17,$L$18),"LOAD USD1ML Curve")} -> USD_BASIS_12M_CURVE@15:3
D22: basis.interpolation | E22: FN_SPLINEINTERPOLATION | K22: Curve Collection | L22: USDYC
D23: isFwdBasis | E23: FALSE | K23: Curve Index | L23: 3M12MBasis:USD12ML
D24: dfCurveName | E24: OIS | K24: Calibration Time Taken | L24: 0.00700 sec
K25: IsCurveLoaded | L25: =_xll.meLWOExists(L21,"CURVE") -> TRUE
B32: Tenor Basis Swaps
D34: Tenor Basis Conventions ( 3 X 12 ) | G34: Tenor Basis Spreads ( 3 X 12 )
D35: MarketName | E35: 3M12MBasis | G35: Term | H35: Rate
C36: Known Leg | D36: IsLeg1Spread | E36: FALSE | G36: 1Y | H36: 0.00185
D37: Leg1cashlet.calendar | E37: LNB:NYB | G37: 2Y | H37: 0.0021
D38: Leg1cashlet.daycount | E38: ACT/360 | G38: 3Y | H38: 0.0020625
D39: Leg1cashlet.frequency | E39: ANNUAL | G39: 4Y | H39: 0.0019625
D40: Leg1cashlet.slidingrule | E40: MOD_FOLLOWING | G40: 5Y | H40: 0.0019625
D41: Leg1cashlet.spotlag | E41: 2 | G41: 7Y | H41: 0.001975
D42: Leg1discount | E42: OIS | G42: 10Y | H42: 0.002
D43: Leg1forecast | E43: STD | G43: 12Y | H43: 0.002
D44: Leg1index.accessary | E44: 12M | G44: 15Y | H44: 0.0019625
D45: Leg1index.daycount | E45: ACT/360 | G45: 20Y | H45: 0.0020875
D46: Leg1index.fixing.calendar | E46: LNB:NYB | G46: 25Y | H46: 0.00215
D47: Leg1index.frequency | E47: SIMPLE | G47: 30Y | H47: 0.002275
D48: Leg1index.payment.calendar | E48: LNB:NYB
...

Sheet Fixing Table
B2: CreateFixingTable | C2: =_xll.meLWOFixingTableCreate(C6,C7,C8,B12:B15,C12:C15) -> USD3M_FIXINGS@3:3
B5: Fixing Table & Index Information
B6: TableName | C6: =C7&C8&"_FIXINGS" -> USD3M_FIXINGS
B7: Currency | C7: USD
B8: CurveTenor | C8: 3M
B11: FixingDate | C11: FixingValue
B12: 43734 | C12: 0.0210438

Sheet Fixed Schedule
E2: Create Schedule | J2: PaymentLag
E3: =_xll.meLWOScheduleCreateBespokeFromCashflows("FIXED_SCHEDULE",$B$6:$C$11,E6:$L$55) -> FIXED_SCHEDULE@8:7 | J3: 2D
B5: Schedule Properties | E5: Trade Information
B6: ScheduleType | C6: FIXED | E6: Notional | F6: Leverage | G6: FixedRate | H6: AccrualStart | I6: AccrualEnd | J6: PaymentDate | K6: CouponMultiplier | L6: AccrualDaycount
B7: PayReceive | C7: PAY | E7: ='Raw Schedule'!F2 -> 38892061 | F7: 1 | G7: 0.01 | H7: ='Raw Schedule'!C2 -> 43738 | I7: ='Raw Schedule'!D2 -> 43769 | J7: =_xll.meDateFromTenor(I7,$J$3,"MOD_FOLLOWING","NYB") -> 43773 | K7: 1 | L7: ACT/360
B8: NotionalExchange | C8: NONE | E8: ='Raw Schedule'!F3 -> 53628705 | F8: 1 | G8: 0.01 | H8: ='Raw Schedule'!C3 -> 43769 | I8: ='Raw Schedule'!D3 -> 43799 | J8: =_xll.meDateFromTenor(I8,$J$3,"MOD_FOLLOWING","NYB") -> 43802 | K8: 1 | L8: ACT/360
E9: ='Raw Schedule'!F4 -> 68386301 | F9: 1 | G9: 0.01 | H9: ='Raw Schedule'!C4 -> 43799 | I9: ='Raw Schedule'!D4 -> 43830 | J9: =_xll.meDateFromTenor(I9,$J$3,"MOD_FOLLOWING","NYB") -> 43833 | K9: 1 | L9: ACT/360
E10: ='Raw Schedule'!F5 -> 90048520 | F10: 1 | G10: 0.01 | H10: ='Raw Schedule'!C5 -> 43830 | I10: ='Raw Schedule'!D5 -> 43861 | J10: =_xll.meDateFromTenor(I10,$J$3,"MOD_FOLLOWING","NYB") -> 43865 | K10: 1 | L10: ACT/360
E11: ='Raw Schedule'!F6 -> 1.1176176e+08 | F11: 1 | G11: 0.01 | H11: ='Raw Schedule'!C6 -> 43861 | I11: ='Raw Schedule'!D6 -> 43890 | J11: =_xll.meDateFromTenor(I11,$J$3,"MOD_FOLLOWING","NYB") -> 43893 | K11: 1 | L11: ACT/360
E12: ='Raw Schedule'!F7 -> 1.3348442e+08 | F12: 1 | G12: 0.01 | H12: ='Raw Schedule'!C7 -> 43890 | I12: ='Raw Schedule'!D7 -> 43921 | J12: =_xll.meDateFromTenor(I12,$J$3,"MOD_FOLLOWING","NYB") -> 43923 | K12: 1 | L12: ACT/360
E13: ='Raw Schedule'!F8 -> 1.5945191e+08 | F13: 1 | G13: 0.01 | H13: ='Raw Schedule'!C8 -> 43921 | I13: ='Raw Schedule'!D8 -> 43951 | J13: =_xll.meDateFromTenor(I13,$J$3,"MOD_FOLLOWING","NYB") -> 43955 | K13: 1 | L13: ACT/360
E14: ='Raw Schedule'!F9 -> 1.7926001e+08 | F14: 1 | G14: 0.01 | H14: ='Raw Schedule'!C9 -> 43951 | I14: ='Raw Schedule'!D9 -> 43982 | J14: =_xll.meDateFromTenor(I14,$J$3,"MOD_FOLLOWING","NYB") -> 43984 | K14: 1 | L14: ACT/360
E15: ='Raw Schedule'!F10 -> 2.0439172e+08 | F15: 1 | G15: 0.01 | H15: ='Raw Schedule'!C10 -> 43982 | I15: ='Raw Schedule'!D10 -> 44012 | J15: =_xll.meDateFromTenor(I15,$J$3,"MOD_FOLLOWING","NYB") -> 44014 | K15: 1 | L15: ACT/360
E16: ='Raw Schedule'!F11 -> 2.278119e+08 | F16: 1 | G16: 0.01 | H16: ='Raw Schedule'!C11 -> 44012 | I16: ='Raw Schedule'!D11 -> 44043 | J16: =_xll.meDateFromTenor(I16,$J$3,"MOD_FOLLOWING","NYB") -> 44047 | K16: 1 | L16: ACT/360
E17: ='Raw Schedule'!F12 -> 2.5413395e+08 | F17: 1 | G17: 0.01 | H17: ='Raw Schedule'!C12 -> 44043 | I17: ='Raw Schedule'!D12 -> 44074 | J17: =_xll.meDateFromTenor(I17,$J$3,"MOD_FOLLOWING","NYB") -> 44076 | K17: 1 | L17: ACT/360
E18: ='Raw Schedule'!F13 -> 2.7979136e+08 | F18: 1 | G18: 0.01 | H18: ='Raw Schedule'!C13 -> 44074 | I18: ='Raw Schedule'!D13 -> 44104 | J18: =_xll.meDateFromTenor(I18,$J$3,"MOD_FOLLOWING","NYB") -> 44106 | K18: 1 | L18: ACT/360
E19: ='Raw Schedule'!F14 -> 3.0341184e+08 | F19: 1 | G19: 0.01 | H19: ='Raw Schedule'!C14 -> 44104 | I19: ='Raw Schedule'!D14 -> 44135 | J19: =_xll.meDateFromTenor(I19,$J$3,"MOD_FOLLOWING","NYB") -> 44138 | K19: 1 | L19: ACT/360
E20: ='Raw Schedule'!F15 -> 3.2713729e+08 | F20: 1 | G20: 0.01 | H20: ='Raw Schedule'!C15 -> 44135 | I20: ='Raw Schedule'!D15 -> 44165 | J20: =_xll.meDateFromTenor(I20,$J$3,"MOD_FOLLOWING","NYB") -> 44167 | K20: 1 | L20: ACT/360
... E55: ='Raw Schedule'!F50 -> 5.2933385e+08 | F55: 1 | G55: 0.01 | H55: ='Raw Schedule'!C50 -> 45869 | I55: ='Raw Schedule'!D50 -> 45961 | J55: =_xll.meDateFromTenor(I55,$J$3,"MOD_FOLLOWING","NYB") -> 45965 | K55: 1 | L55: ACT/360

Sheet Float Schedule
E2: Create Schedule | G2: Float Spread (Bps) | I2: FixingLag | L2: PaymentLag
E3: =_xll.meLWOScheduleCreateBespokeFromCashflows("FLOAT_SCHEDULE",$B$6:$C$11,E6:$N$55) -> FLOAT_SCHEDULE@9:4 | G3: 0 | I3: -2D | L3: 2D
B5: Schedule Properties | E5: Trade Information | G5: Basis Points | H5: Rate or Index | I5: Float Schedule
B6: ScheduleType | C6: FLOAT | E6: Notional | F6: Leverage | G6: FloatSpread | H6: ForecastCurve | I6: FixingDate | J6: AccrualStart | K6: AccrualEnd | L6: PaymentDate | M6: CouponMultiplier | N6: AccrualDaycount
B7: PayReceive | C7: RECEIVE | E7: ='Raw Schedule'!F2 -> 38892061 | F7: 1 | G7: =$G$3 -> 0 | H7: USD1ML | I7: =_xll.meDateFromTenor(J7,$I$3,$C$9,$C$10) -> 43734 | J7: ='Raw Schedule'!C2 -> 43738 | K7: ='Raw Schedule'!D2 -> 43769 | L7: =_xll.meDateFromTenor(K7,$L$3,"MOD_FOLLOWING","NYB") -> 43773 | M7: 1 | N7: ACT/360
B8: NotionalExchange | C8: NONE | E8: ='Raw Schedule'!F3 -> 53628705 | F8: 1 | G8: =$G$3 -> 0 | H8: USD1ML | I8: =_xll.meDateFromTenor(J8,$I$3,$C$9,$C$10) -> 43767 | J8: ='Raw Schedule'!C3 -> 43769 | K8: ='Raw Schedule'!D3 -> 43799 | L8: =_xll.meDateFromTenor(K8,$L$3,"MOD_FOLLOWING","NYB") -> 43802 | M8: 1 | N8: ACT/360
B9: FixingBusinessDayAdjustment | C9: PRECEDING | E9: ='Raw Schedule'!F4 -> 68386301 | F9: 1 | G9: =$G$3 -> 0 | H9: USD1ML | I9: =_xll.meDateFromTenor(J9,$I$3,$C$9,$C$10) -> 43796 | J9: ='Raw Schedule'!C4 -> 43799 | K9: ='Raw Schedule'!D4 -> 43830 | L9: =_xll.meDateFromTenor(K9,$L$3,"MOD_FOLLOWING","NYB") -> 43833 | M9: 1 | N9: ACT/360
B10: FixingCalendar | C10: NYB | E10: ='Raw Schedule'!F5 -> 90048520 | F10: 1 | G10: =$G$3 -> 0 | H10: USD3ML | I10: =_xll.meDateFromTenor(J10,$I$3,$C$9,$C$10) -> 43826 | J10: ='Raw Schedule'!C5 -> 43830 | K10: ='Raw Schedule'!D5 -> 43861 | L10: =_xll.meDateFromTenor(K10,$L$3,"MOD_FOLLOWING","NYB") -> 43865 | M10: 1 | N10: ACT/360
E11: ='Raw Schedule'!F6 -> 1.1176176e+08 | F11: 1 | G11: =$G$3 -> 0 | H11: USD3ML | I11: =_xll.meDateFromTenor(J11,$I$3,$C$9,$C$10) -> 43859 | J11: ='Raw Schedule'!C6 -> 43861 | K11: ='Raw Schedule'!D6 -> 43890 | L11: =_xll.meDateFromTenor(K11,$L$3,"MOD_FOLLOWING","NYB") -> 43893 | M11: 1 | N11: ACT/360
E12: ='Raw Schedule'!F7 -> 1.3348442e+08 | F12: 1 | G12: =$G$3 -> 0 | H12: USD3ML | I12: =_xll.meDateFromTenor(J12,$I$3,$C$9,$C$10) -> 43888 | J12: ='Raw Schedule'!C7 -> 43890 | K12: ='Raw Schedule'!D7 -> 43921 | L12: =_xll.meDateFromTenor(K12,$L$3,"MOD_FOLLOWING","NYB") -> 43923 | M12: 1 | N12: ACT/360
E13: ='Raw Schedule'!F8 -> 1.5945191e+08 | F13: 1 | G13: =$G$3 -> 0 | H13: USD3ML | I13: =_xll.meDateFromTenor(J13,$I$3,$C$9,$C$10) -> 43917 | J13: ='Raw Schedule'!C8 -> 43921 | K13: ='Raw Schedule'!D8 -> 43951 | L13: =_xll.meDateFromTenor(K13,$L$3,"MOD_FOLLOWING","NYB") -> 43955 | M13: 1 | N13: ACT/360
E14: ='Raw Schedule'!F9 -> 1.7926001e+08 | F14: 1 | G14: =$G$3 -> 0 | H14: USD3ML | I14: =_xll.meDateFromTenor(J14,$I$3,$C$9,$C$10) -> 43949 | J14: ='Raw Schedule'!C9 -> 43951 | K14: ='Raw Schedule'!D9 -> 43982 | L14: =_xll.meDateFromTenor(K14,$L$3,"MOD_FOLLOWING","NYB") -> 43984 | M14: 1 | N14: ACT/360
E15: ='Raw Schedule'!F10 -> 2.0439172e+08 | F15: 1 | G15: =$G$3 -> 0 | H15: USD3ML | I15: =_xll.meDateFromTenor(J15,$I$3,$C$9,$C$10) -> 43979 | J15: ='Raw Schedule'!C10 -> 43982 | K15: ='Raw Schedule'!D10 -> 44012 | L15: =_xll.meDateFromTenor(K15,$L$3,"MOD_FOLLOWING","NYB") -> 44014 | M15: 1 | N15: ACT/360
E16: ='Raw Schedule'!F11 -> 2.278119e+08 | F16: 1 | G16: =$G$3 -> 0 | H16: USD3ML | I16: =_xll.meDateFromTenor(J16,$I$3,$C$9,$C$10) -> 44008 | J16: ='Raw Schedule'!C11 -> 44012 | K16: ='Raw Schedule'!D11 -> 44043 | L16: =_xll.meDateFromTenor(K16,$L$3,"MOD_FOLLOWING","NYB") -> 44047 | M16: 1 | N16: ACT/360
E17: ='Raw Schedule'!F12 -> 2.5413395e+08 | F17: 1 | G17: =$G$3 -> 0 | H17: USD3ML | I17: =_xll.meDateFromTenor(J17,$I$3,$C$9,$C$10) -> 44041 | J17: ='Raw Schedule'!C12 -> 44043 | K17: ='Raw Schedule'!D12 -> 44074 | L17: =_xll.meDateFromTenor(K17,$L$3,"MOD_FOLLOWING","NYB") -> 44076 | M17: 1 | N17: ACT/360
E18: ='Raw Schedule'!F13 -> 2.7979136e+08 | F18: 1 | G18: =$G$3 -> 0 | H18: USD3ML | I18: =_xll.meDateFromTenor(J18,$I$3,$C$9,$C$10) -> 44070 | J18: ='Raw Schedule'!C13 -> 44074 | K18: ='Raw Schedule'!D13 -> 44104 | L18: =_xll.meDateFromTenor(K18,$L$3,"MOD_FOLLOWING","NYB") -> 44106 | M18: 1 | N18: ACT/360
E19: ='Raw Schedule'!F14 -> 3.0341184e+08 | F19: 1 | G19: =$G$3 -> 0 | H19: USD3ML | I19: =_xll.meDateFromTenor(J19,$I$3,$C$9,$C$10) -> 44102 | J19: ='Raw Schedule'!C14 -> 44104 | K19: ='Raw Schedule'!D14 -> 44135 | L19: =_xll.meDateFromTenor(K19,$L$3,"MOD_FOLLOWING","NYB") -> 44138 | M19: 1 | N19: ACT/360
E20: ='Raw Schedule'!F15 -> 3.2713729e+08 | F20: 1 | G20: =$G$3 -> 0 | H20: USD3ML | I20: =_xll.meDateFromTenor(J20,$I$3,$C$9,$C$10) -> 44133 | J20: ='Raw Schedule'!C15 -> 44135 | K20: ='Raw Schedule'!D15 -> 44165 | L20: =_xll.meDateFromTenor(K20,$L$3,"MOD_FOLLOWING","NYB") -> 44167 | M20: 1 | N20: ACT/360
E21: ='Raw Schedule'!F16 -> 3.6193169e+08 | F21: 1 | G21: =$G$3 -> 0 | H21: USD3ML | I21: =_xll.meDateFromTenor(J21,$I$3,$C$9,$C$10) -> 44160 | J21: ='Raw Schedule'!C16 -> 44165 | K21: ='Raw Schedule'!D16 -> 44196 | L21: =_xll.meDateFromTenor(K21,$L$3,"MOD_FOLLOWING","NYB") -> 44201 | M21: 1 | N21: ACT/360
E22: ='Raw Schedule'!F17 -> 3.9822079e+08 | F22: 1 | G22: =$G$3 -> 0 | H22: USD3ML | I22: =_xll.meDateFromTenor(J22,$I$3,$C$9,$C$10) -> 44194 | J22: ='Raw Schedule'!C17 -> 44196 | K22: ='Raw Schedule'!D17 -> 44227 | L22: =_xll.meDateFromTenor(K22,$L$3,"MOD_FOLLOWING","NYB") -> 44229 | M22: 1 | N22: ACT/360
... E55: ='Raw Schedule'!F50 -> 5.2933385e+08 | F55: 1 | G55: =$G$3 -> 0 | H55: USD6ML | I55: =_xll.meDateFromTenor(J55,$I$3,$C$9,$C$10) -> 45867 | J55: ='Raw Schedule'!C50 -> 45869 | K55: ='Raw Schedule'!D50 -> 45961 | L55: =_xll.meDateFromTenor(K55,$L$3,"MOD_FOLLOWING","NYB") -> 45965 | M55: 1 | N55: ACT/360

Sheet Create Trade & Price
B2: CUSTOM ROLLERCOASTER SWAP | E2: FIXED LEG | H2: FLOAT LEG
B3: Create Swap | C3: =_xll.meLWOSwapCreateFromLegs("ROLLERCOASTER",C5:C6) -> ROLLERCOASTER@16:2 | E3: Create Fixed Leg | F3: =_xll.meLWOLegCreateFromSchedule("FIXED_LEG",F7,E8:F11) -> FIXED_LEG@10:2 | H3: Create Float Leg | I3: =_xll.meLWOLegCreateFromSchedule("FLOAT_LEG",I7,H8:I11) -> FLOAT_LEG@11:2
E4: Curve | F4: USDYC | H4: Curve | I4: USDYC
B5: TradeLegs | C5: =F3 -> FIXED_LEG@10:2
C6: =I3 -> FLOAT_LEG@11:2
E7: FloatSchedule | F7: ='Fixed Schedule'!$E$3 -> FIXED_SCHEDULE@8:7 | H7: FloatSchedule | I7: ='Float Schedule'!$E$3 -> FLOAT_SCHEDULE@9:4
E8: LegType | F8: LEG1:FIXED | H8: LegType | I8: LEG2:FLOAT
E9: DiscountCurve | F9: USDOIS | H9: ForecastCurve | I9: USD1ML:USD3ML:USD6ML | J9: *
E10: Currency | F10: USD | H10: DiscountCurve | I10: USDOIS
H11: Currency | I11: USD
H12: * List all Curve Indices Here (Needed for Risk Calculation)
B14: Price Trade | E14: Price Fixed Leg | H14: Price Float Leg
B15: Trade PV | C15: =_xll.meLWOSwapPV(C3,$F$4) -> 13033394 | E15: Fixed Leg PV | F15: =_xll.meLWOLegPV(F3,F4) -> -28188829 | H15: Float Leg PV | I15: =_xll.meLWOLegPV(I3,I4,I5) -> 41222223
B17: Display Float Cashflows
B18: {=_xll.meLWOLegDisplayCashflows(I3,I4,I5)} -> FixingDate | C18: AccrualStart | D18: AccrualEnd | E18: AccrualDays | F18: AccrualYearFractions | G18: PaymentDate | H18: Notional | I18: NotionalExchange | J18: Leverage | K18: FloatSpread | L18: FloatRate | M18: Coupon | N18: DiscountFactor | O18: CouponPV | P18: #N/A
B19: 43734 | C19: 43738 | D19: 43769 | E19: 31 | F19: 0.086111111 | G19: 43773 | H19: 38892061 | I19: 0 | J19: 1 | K19: 0 | L19: 0.019300504 | M19: 64638.132 | N19: 0.99812896 | O19: 64517.192 | P19: #N/A
B20: 43767 | C20: 43769 | D20: 43799 | E20: 30 | F20: 0.083333333 | G20: 43802 | H20: 53628705 | I20: 0 | J20: 1 | K20: 0 | L20: 0.01851467 | M20: 82743.146 | N20: 0.99681689 | O20: 82479.765 | P20: #N/A
B21: 43796 | C21: 43799 | D21: 43830 | E21: 31 | F21: 0.086111111 | G21: 43833 | H21: 68386301 | I21: 0 | J21: 1 | K21: 0 | L21: 0.017752163 | M21: 104539.3 | N21: 0.99551673 | O21: 104070.62 | P21: #N/A
B22: 43826 | C22: 43830 | D22: 43861 | E22: 31 | F22: 0.086111111 | G22: 43865 | H22: 90048520 | I22: 0 | J22: 1 | K22: 0 | L22: 0.018443955 | M22: 143017.71 | N22: 0.99423967 | O22: 142193.89 | P22: #N/A
B23: 43859 | C23: 43861 | D23: 43890 | E23: 29 | F23: 0.080555556 | G23: 43893 | H23: 1.1176176e+08 | I23: 0 | J23: 1 | K23: 0 | L23: 0.017546644 | M23: 157972.97 | N23: 0.99312731 | O23: 156887.27 | P23: #N/A
B24: 43888 | C24: 43890 | D24: 43921 | E24: 31 | F24: 0.086111111 | G24: 43923 | H24: 1.3348442e+08 | I24: 0 | J24: 1 | K24: 0 | L24: 0.01675812 | M24: 192626.08 | N24: 0.9920145 | O24: 191087.86 | P24: #N/A
B25: 43917 | C25: 43921 | D25: 43951 | E25: 30 | F25: 0.083333333 | G25: 43955 | H25: 1.5945191e+08 | I25: 0 | J25: 1 | K25: 0 | L25: 0.016099387 | M25: 213923.18 | N25: 0.99083252 | O25: 211962.04 | P25: #N/A
B26: 43949 | C26: 43951 | D26: 43982 | E26: 31 | F26: 0.086111111 | G26: 43984 | H26: 1.7926001e+08 | I26: 0 | J26: 1 | K26: 0 | L26: 0.015718373 | M26: 242633.19 | N26: 0.98976439 | O26: 240149.69 | P26: #N/A
B27: 43979 | C27: 43982 | D27: 44012 | E27: 30 | F27: 0.083333333 | G27: 44014 | H27: 2.0439172e+08 | I27: 0 | J27: 1 | K27: 0 | L27: 0.015363849 | M27: 261686.96 | N27: 0.98868066 | O27: 258724.83 | P27: #N/A
B28: 44008 | C28: 44012 | D28: 44043 | E28: 31 | F28: 0.086111111 | G28: 44047 | H28: 2.278119e+08 | I28: 0 | J28: 1 | K28: 0 | L28: 0.01505408 | M28: 295317.92 | N28: 0.98752864 | O28: 291634.91 | P28: #N/A
B29: 44041 | C29: 44043 | D29: 44074 | E29: 31 | F29: 0.086111111 | G29: 44076 | H29: 2.5413395e+08 | I29: 0 | J29: 1 | K29: 0 | L29: 0.014801027 | M29: 323902.08 | N29: 0.98654774 | O29: 319544.86 | P29: #N/A
B30: 44070 | C30: 44074 | D30: 44104 | E30: 30 | F30: 0.083333333 | G30: 44106 | H30: 2.7979136e+08 | I30: 0 | J30: 1 | K30: 0 | L30: 0.014580605 | M30: 339960.62 | N30: 0.98555778 | O30: 335050.83 | P30: #N/A
... B67: 45867 | C67: 45869 | D67: 45961 | E67: 92 | F67: 0.25555556 | G67: 45965 | H67: 5.2933385e+08 | I67: 0 | J67: 1 | K67: 0 | L67: 0.016718045 | M67: 2261520.3 | N67: 0.9278526 | O67: 2098357.5 | P67: #N/A
B68: #N/A | C68: #N/A | D68: #N/A | E68: #N/A | F68: #N/A | G68: #N/A | H68: #N/A | I68: #N/A | J68: #N/A | K68: #N/A | L68: #N/A | M68: #N/A | N68: #N/A | O68: #N/A | P68: #N/A
B69: #N/A | C69: #N/A | D69: #N/A | E69: #N/A | F69: #N/A | G69: #N/A | H69: #N/A | I69: #N/A | J69: #N/A | K69: #N/A | L69: #N/A | M69: #N/A | N69: #N/A | O69: #N/A | P69: #N/A
B70: #N/A | C70: #N/A | D70: #N/A | E70: #N/A | F70: #N/A | G70: #N/A | H70: #N/A | I70: #N/A | J70: #N/A | K70: #N/A | L70: #N/A | M70: #N/A | N70: #N/A | O70: #N/A | P70: #N/A
B71: #N/A | C71: #N/A | D71: #N/A | E71: #N/A | F71: #N/A | G71: #N/A | H71: #N/A | I71: #N/A | J71: #N/A | K71: #N/A | L71: #N/A | M71: #N/A | N71: #N/A | O71: #N/A | P71: #N/A

Sheet Risk
B2: Trade Specification
B3: ='Create Trade & Price'!$C$3 -> ROLLERCOASTER@16:2
B4: ='USD OIS'!$D$22 -> USDYC
B6: Risk
B7: {=_xll.meLWOSwapDeltaLadder($B$3,$B$4)} -> USD : Pillars | C7: USD : Total | D7: USD : Pillars | E7: USD : Total | F7: USD : Pillars | G7: USD : Total | H7: USD : Pillars | I7: USD : Total | J7: #N/A
B8: USDYC.1M3MBASIS.LIBOR.1M | C8: 966.63137 | D8: USDYC.3M6MBASIS.LIBOR.6M | E8: 452.39109 | F8: USDYC.OIS.OUTRIGHTOISSWAP.ON | G8: -16.316705 | H8: USDYC.STD.O_N | I8: -0.67851692 | J8: #N/A
B9: USDYC.1M3MBASIS.BASISRATE.1Y | C9: -589.60351 | D9: USDYC.3M6MBASIS.BASISRATE.1Y | E9: -1960.9996 | F9: USDYC.OIS.OUTRIGHTOISSWAP.1W | G9: -0.22417083 | H9: USDYC.STD.T_N | I9: -2.4980105 | J9: #N/A
B10: USDYC.1M3MBASIS.BASISRATE.2Y | C10: 270.57852 | D10: USDYC.3M6MBASIS.BASISRATE.2Y | E10: 10661.564 | F10: USDYC.OIS.OUTRIGHTOISSWAP.2W | G10: -1.3796091 | H10: USDYC.STD.LIBOR.1M | I10: -0.25678501 | J10: #N/A
B11: USDYC.1M3MBASIS.BASISRATE.3Y | C11: -108.89367 | D11: USDYC.3M6MBASIS.BASISRATE.3Y | E11: -150837.97 | F11: USDYC.OIS.OUTRIGHTOISSWAP.3W | G11: -1.2168802 | H11: USDYC.STD.LIBOR.3M | I11: -16844.817 | J11: #N/A
B12: USDYC.1M3MBASIS.BASISRATE.4Y | C12: 38.991237 | D12: USDYC.3M6MBASIS.BASISRATE.4Y | E12: -38250.167 | F12: USDYC.OIS.OUTRIGHTOISSWAP.1M | G12: -1.9554839 | H12: USDYC.STD.LIBOR.6M | I12: -1.8684573 | J12: #N/A
B13: USDYC.1M3MBASIS.BASISRATE.5Y | C13: -13.003124 | D13: USDYC.3M6MBASIS.BASISRATE.5Y | E13: -3649.4879 | F13: USDYC.OIS.OUTRIGHTOISSWAP.2M | G13: -0.56083687 | H13: USDYC.STD.LIBOR.12M | I13: -1.8710986 | J13: #N/A
B14: USDYC.1M3MBASIS.BASISRATE.6Y | C14: 4.229454 | D14: USDYC.3M6MBASIS.BASISRATE.6Y | E14: 276201.71 | F14: USDYC.OIS.OUTRIGHTOISSWAP.3M | G14: 81.537224 | H14: USDYC.STD.FUTURE.ED1 COMDTY.20191218.20200318 | I14: -13143.261 | J14: #N/A
B15: USDYC.1M3MBASIS.BASISRATE.7Y | C15: -1.3198182 | D15: USDYC.3M6MBASIS.BASISRATE.7Y | E15: 82322.253 | F15: USDYC.OIS.OUTRIGHTOISSWAP.4M | G15: -5.4478705 | H15: USDYC.STD.FUTURE.ED2 COMDTY.20200318.20200617 | I15: -12983.128 | J15: #N/A
B16: USDYC.1M3MBASIS.BASISRATE.8Y | C16: 0.40727407 | D16: USDYC.3M6MBASIS.BASISRATE.8Y | E16: -23240.022 | F16: USDYC.OIS.OUTRIGHTOISSWAP.5M | G16: 1.1509296 | H16: USDYC.STD.FUTURE.ED3 COMDTY.20200617.20200916 | I16: -11145.036 | J16: #N/A
B17: USDYC.1M3MBASIS.BASISRATE.9Y | C17: -0.11191219 | D17: USDYC.3M6MBASIS.BASISRATE.9Y | E17: 6886.1312 | F17: USDYC.OIS.OUTRIGHTOISSWAP.6M | G17: -102.81031 | H17: USDYC.STD.FUTURE.ED4 COMDTY.20200916.20201216 | I17: -8981.9956 | J17: #N/A
B18: USDYC.1M3MBASIS.BASISRATE.10Y | C18: 0.03413111 | D18: USDYC.3M6MBASIS.BASISRATE.10Y | E18: -1657.6757 | F18: USDYC.OIS.OUTRIGHTOISSWAP.9M | G18: 190.62875 | H18: USDYC.STD.FUTURE.ED5 COMDTY.20201216.20210317 | I18: -6773.2776 | J18: #N/A
B19: USDYC.1M3MBASIS.BASISRATE.12Y | C19: 0.0018171966 | D19: USDYC.3M6MBASIS.BASISRATE.12Y | E19: 188.92804 | F19: USDYC.OIS.BASISRATE.1Y | G19: 219.94227 | H19: USDYC.STD.FUTURE.ED6 COMDTY.20210317.20210616 | I19: -4774.5746 | J19: #N/A
... B23: USDYC.1M3MBASIS.BASISRATE.30Y | C23: 0.0090390444 | D23: USDYC.3M6MBASIS.BASISRATE.30Y | E23: 0.30245483 | F23: USDYC.OIS.BASISRATE.3Y | G23: 1060.0154 | H23: USDYC.STD.3MLIBORSWAP.4Y | I23: -52818.644 | J23: #N/A
F24: USDYC.OIS.3MLIBORSWAP.3Y | G24: 41803.832 | H24: USDYC.STD.3MLIBORSWAP.5Y | I24: 153877.73 | J24: #N/A
F25: USDYC.OIS.BASISRATE.4Y | G25: 585.88586 | H25: USDYC.STD.3MLIBORSWAP.7Y | I25: 321708.59 | J25: #N/A
F26: USDYC.OIS.3MLIBORSWAP.4Y | G26: -53396.456 | H26: USDYC.STD.3MLIBORSWAP.8Y | I26: -138418.36 | J26: #N/A
F27: USDYC.OIS.BASISRATE.5Y | G27: 2869.3311 | H27: USDYC.STD.3MLIBORSWAP.9Y | I27: 40985.317 | J27: #N/A
F28: USDYC.OIS.3MLIBORSWAP.5Y | G28: 151053.28 | H28: USDYC.STD.3MLIBORSWAP.10Y | I28: -9848.382 | J28: #N/A
F29: USDYC.OIS.BASISRATE.7Y | G29: 914.32564 | H29: USDYC.STD.3MLIBORSWAP.12Y | I29: 1141.2269 | J29: #N/A
F30: USDYC.OIS.3MLIBORSWAP.7Y | G30: 320807.05 | H30: USDYC.STD.3MLIBORSWAP.15Y | I30: -201.13051 | J30: #N/A
F31: USDYC.OIS.BASISRATE.10Y | G31: -120.01152 | H31: USDYC.STD.3MLIBORSWAP.20Y | I31: 33.068273 | J31: #N/A
F32: USDYC.OIS.3MLIBORSWAP.10Y | G32: -9730.1004 | H32: USDYC.STD.3MLIBORSWAP.25Y | I32: -12.435081 | J32: #N/A
F33: USDYC.OIS.BASISRATE.12Y | G33: 38.4541 | H33: USDYC.STD.3MLIBORSWAP.30Y | I33: 8.4395684 | J33: #N/A
F34: USDYC.OIS.3MLIBORSWAP.12Y | G34: 1100.4323 | J34: #N/A
F35: USDYC.OIS.BASISRATE.15Y | G35: -4.8461657 | J35: #N/A
F36: USDYC.OIS.3MLIBORSWAP.15Y | G36: -198.31774 | J36: #N/A
F37: USDYC.OIS.BASISRATE.20Y | G37: 1.2542527 | J37: #N/A
F38: USDYC.OIS.3MLIBORSWAP.20Y | G38: 34.82555 | J38: #N/A
F39: USDYC.OIS.BASISRATE.25Y | G39: -0.01549162 | J39: #N/A
F40: USDYC.OIS.3MLIBORSWAP.25Y | G40: -24.449228 | J40: #N/A
F41: USDYC.OIS.BASISRATE.30Y | G41: 2.6627395 | J41: #N/A
F42: USDYC.OIS.3MLIBORSWAP.30Y | G42: 0.53372197 | J42: #N/A
B43: #N/A | C43: #N/A | D43: #N/A | E43: #N/A | F43: #N/A | G43: #N/A | H43: #N/A | I43: #N/A | J43: #N/A
B44: #N/A | C44: #N/A | D44: #N/A | E44: #N/A | F44: #N/A | G44: #N/A | H44: #N/A | I44: #N/A | J44: #N/A
B45: #N/A | C45: #N/A | D45: #N/A | E45: #N/A | F45: #N/A | G45: #N/A | H45: #N/A | I45: #N/A | J45: #N/A
...

Sheet Hard-Coded Results
B2: #4 Price
B3: Trade Leg PV | C3: 43782264
B5: #5 Display Cashflows
B6: FixingDate | C6: AccrualStart | D6: AccrualEnd | E6: AccrualDays | F6: AccrualYearFractions | G6: PaymentDate | H6: Notional | I6: NotionalExchange | J6: Leverage | K6: FloatSpread | L6: FloatRate | M6: Coupon | N6: DiscountFactor | O6: CouponPV
B7: 43734 | C7: 43738 | D7: 43769 | E7: 31 | F7: 0.086111111 | G7: 43773 | H7: 38892061 | I7: 0 | J7: 1 | K7: 0 | L7: 0.021550006 | M7: 72171.801 | N7: 0.99749943 | O7: 71991.331
B8: 43767 | C8: 43769 | D8: 43799 | E8: 30 | F8: 0.083333333 | G8: 43802 | H8: 53628705 | I8: 0 | J8: 1 | K8: 0 | L8: 0.021047887 | M8: 94064.243 | N8: 0.99608186 | O8: 93695.686
B9: 43796 | C9: 43799 | D9: 43830 | E9: 31 | F9: 0.086111111 | G9: 43833 | H9: 68386301 | I9: 0 | J9: 1 | K9: 0 | L9: 0.020606631 | M9: 121348.75 | N9: 0.99459605 | O9: 120692.99
B10: 43826 | C10: 43830 | D10: 43861 | E10: 31 | F10: 0.086111111 | G10: 43865 | H10: 90048520 | I10: 0 | J10: 1 | K10: 0 | L10: 0.019993824 | M10: 155035.67 | N10: 0.99315744 | O10: 153974.83
B11: 43859 | C11: 43861 | D11: 43890 | E11: 29 | F11: 0.080555556 | G11: 43893 | H11: 1.1176176e+08 | I11: 0 | J11: 1 | K11: 0 | L11: 0.018914379 | M11: 170286.73 | N11: 0.99194886 | O11: 168915.73
B12: 43888 | C12: 43890 | D12: 43921 | E12: 31 | F12: 0.086111111 | G12: 43923 | H12: 1.3348442e+08 | I12: 0 | J12: 1 | K12: 0 | L12: 0.017965776 | M12: 206507.46 | N12: 0.99067255 | O12: 204581.28
B13: 43917 | C13: 43921 | D13: 43951 | E13: 30 | F13: 0.083333333 | G13: 43955 | H13: 1.5945191e+08 | I13: 0 | J13: 1 | K13: 0 | L13: 0.017161054 | M13: 228030.24 | N13: 0.98938436 | O13: 225609.56
B14: 43949 | C14: 43951 | D14: 43982 | E14: 31 | F14: 0.086111111 | G14: 43984 | H14: 1.7926001e+08 | I14: 0 | J14: 1 | K14: 0 | L14: 0.016756226 | M14: 258653.77 | N14: 0.98825864 | O14: 255616.82
B15: 43979 | C15: 43982 | D15: 44012 | E15: 30 | F15: 0.083333333 | G15: 44014 | H15: 2.0439172e+08 | I15: 0 | J15: 1 | K15: 0 | L15: 0.016376699 | M15: 278938.46 | N15: 0.98710789 | O15: 275342.36
B16: 44008 | C16: 44012 | D16: 44043 | E16: 31 | F16: 0.086111111 | G16: 44047 | H16: 2.278119e+08 | I16: 0 | J16: 1 | K16: 0 | L16: 0.016037066 | M16: 314601.29 | N16: 0.98584228 | O16: 310147.25
B17: 44041 | C17: 44043 | D17: 44074 | E17: 31 | F17: 0.086111111 | G17: 44076 | H17: 2.5413395e+08 | I17: 0 | J17: 1 | K17: 0 | L17: 0.015749988 | M17: 344668.91 | N17: 0.98473751 | O17: 339408.4
B18: 44070 | C18: 44074 | D18: 44104 | E18: 30 | F18: 0.083333333 | G18: 44106 | H18: 2.7979136e+08 | I18: 0 | J18: 1 | K18: 0 | L18: 0.015497707 | M18: 361343.72 | N18: 0.98361074 | O18: 355421.57
... B55: 45867 | C55: 45869 | D55: 45961 | E55: 92 | F55: 0.25555556 | G55: 45965 | H55: 5.2933385e+08 | I55: 0 | J55: 1 | K55: 0 | L55: 0.017258305 | M55: 2334603.4 | N55: 0.92229015 | O55: 2153181.7
