Workbook
Name allowTradeUpdates: [1]Settings!$K$4
Name CurveCollection: 'OIS - USDOIS'!$D$8
Name CurveCollection: 'SWAP - USD3ML'!$D$9
Name enableCurveRepricing: [1]Settings!$M$4
Name enableGlobalCalibration: [1]Settings!$E$4
Name isUSD3MLLoaded: '[1]USD SWAP 3ML'!$U$32
Name Settings.COB: [1]Settings!$C$4
Name Settings.PulseFrequency: [1]Settings!$O$2

Sheet OIS - USDOIS
C3: MARKETDATAPROPERTIES | F3: OIS | L3: LIBOROISBASISSPREADS | O3: SWAPS
F4: Term | G4: Rate | H4: StartDate | I4: EndDate | J4: Use | L4: Term | M4: Rate | O4: Term | P4: Rate
C5: Currency | D5: USD | F5: ON | G5: 0.0155 | J5: TRUE | L5: 1Y | M5: 0.00253125 | O5: 1Y | P5: 0.017244
C6: CurveType | D6: OIS | F6: 1W | G6: 0.01541 | J6: TRUE | L6: 2Y | M6: 0.00240625 | O6: 2Y | P6: 0.016133
C7: CurveIndexFrequency | D7: DAILY | F7: 2W | G7: 0.01554 | J7: TRUE | L7: 3Y | M7: 0.0023375 | O7: 3Y | P7: 0.015848
C8: AsOfDate | D8: 43812 | F8: 3W | G8: 0.01567 | J8: TRUE | L8: 4Y | M8: 0.0022875 | O8: 4Y | P8: 0.01584
F9: 1M | G9: 0.01563 | J9: TRUE | L9: 5Y | M9: 0.002275 | O9: 5Y | P9: 0.015964
F10: 2M | G10: 0.01557 | J10: TRUE | L10: 7Y | M10: 0.00224375 | O10: 7Y | P10: 0.016361
C11: Create Market Data Handle | F11: 3M | G11: 0.015548 | J11: TRUE | L11: 10Y | M11: 0.002225 | O11: 10Y | P11: 0.017186
C12: Handle Name | D12: USD_OIS_CURVE_MARKETDATA | F12: 4M | G12: 0.015442 | J12: TRUE | L12: 12Y | M12: 0.002213 | O12: 12Y | P12: 0.017693
C13: Market Data Handle | D13: =_xll.meLWOCurveMarketDataCreate(D12,C3,C5:D8,F3,F5:J26,L3,L5:M26,O3,O5:P26) -> USD_OIS_CURVE_MARKETDATA@2:0 | F13: 5M | G13: 0.015325 | J13: TRUE | L13: 15Y | M13: 0.002225 | O13: 15Y | P13: 0.018256
F14: 6M | G14: 0.015225 | J14: TRUE | L14: 20Y | M14: 0.0022125 | O14: 20Y | P14: 0.018835
F15: 9M | G15: 0.014889 | J15: TRUE | L15: 25Y | M15: 0.00221875 | O15: 25Y | P15: 0.019031
C16: Curve Dictionary | F16: 1Y | G16: 0.014496 | J16: TRUE | L16: 30Y | M16: 0.002225 | O16: 30Y | P16: 0.019067
C17: Handle Name | D17: USD_OIS_CURVE | F17: 2Y | G17: 0.01354 | J17: TRUE
C18: Curve Generator | D18: =C31 -> USD_OIS_WITH_RISK@1:0 | F18: 3Y | G18: 0.01334 | J18: TRUE
C19: Domestic Curve Collection | D19: USDYC | F19: 4Y | G19: 0.01337 | J19: TRUE
C20: Foreign Curve Collection | F20: 5Y | G20: 0.01353 | J20: TRUE
C22: Curve Build
C23: Handle Name | D23: {=_xll.meLWOCurveCalibrate(D17,D18,D13,D19,D20)} -> USD_OIS_CURVE@3:0
C24: Curve Collection | D24: USDYC
C25: Curve Index | D25: OIS:USDOIS
C26: Calibration Time Taken | D26: 0.77000 sec
C27: Curve Loaded | D27: =_xll.meLWOExists(D23,"CURVE") -> TRUE
C30: Create Curve Generator | D30: JacobianBuildFrequency | F30: Flat-Shift Curve
C31: =_xll.meLWOCurveGeneratorCreate("USD_OIS_WITH_RISK",C33,C34:D44,C46,C47:D63,C65,C66:D69,C71,C72:D75) -> USD_OIS_WITH_RISK@1:0 | D31: ONCE | F31: 1=meLWOCurveBumpAll(D23,0.01%,TRUE)
C33: CURVEPROPERTIES
C34: CurveType | D34: OIS
C35: CurveIndexFrequency | D35: DAILY
C36: StaticDataTable | D36: OIS
C37: IndexName | D37: OIS:USDOIS
C38: Currency | D38: USD
C39: interpolation | D39: FN_SPLINEINTERPOLATION
C40: yieldgen.interpolation | D40: FN_SPLINEINTERPOLATION
C41: JacobianBuildFrequency | D41: =D31 -> ONCE
C42: JacobianShiftType | D42: PERTURBED
C43: JacobianGradientShiftSize | D43: 0.0001
C44: JacobianMarketDataShiftSize | D44: 0.0001
C46: OIS
C47: calendar | D47: NYB
...

Sheet SWAP - USD3ML
C3: MARKETDATAPROPERTIES | F3: LIBORFIXINGS | I3: FUTURES | O3: SWAPS
C4: Currency | D4: USD | F4: Term | G4: Rate | I4: Term | J4: StartDate | K4: EndDate | L4: Rate | M4: Volatility | O4: Term | P4: Rate | Q4: Use
C5: CurveType | D5: SWAP | F5: 1M | G5: 0.0173975 | I5: ED1 Comdty | J5: 43817 | K5: 43908 | L5: 98.105 | M5: 0.0145 | O5: 3Y | P5: 0.015848 | Q5: TRUE
C6: CurveIndexFrequency | D6: QUARTERLY | F6: 3M | G6: 0.0189363 | I6: ED2 Comdty | J6: 43908 | K6: 43999 | L6: 98.29 | M6: 0.0145 | O6: 4Y | P6: 0.01584 | Q6: TRUE
C7: AsOfDate | D7: 43812 | F7: 6M | G7: 0.0188638 | I7: ED3 Comdty | J7: 43999 | K7: 44090 | L7: 98.385 | M7: 0.0145 | O7: 5Y | P7: 0.015964 | Q7: TRUE
F8: 12M | G8: 0.0193288 | I8: ED4 Comdty | J8: 44090 | K8: 44181 | L8: 98.46 | M8: 0.0145 | O8: 7Y | P8: 0.016361 | Q8: TRUE
I9: ED5 Comdty | J9: 44181 | K9: 44272 | L9: 98.465 | M9: 0.0145 | O9: 8Y | P9: 0.016623 | Q9: TRUE
I10: ED6 Comdty | J10: 44272 | K10: 44363 | L10: 98.535 | M10: 0.0145 | O10: 9Y | P10: 0.016902 | Q10: TRUE
C11: Create Market Data Handle | I11: ED7 Comdty | J11: 44363 | K11: 44454 | L11: 98.535 | M11: 0.0145 | O11: 10Y | P11: 0.017186 | Q11: TRUE
C12: Handle Name | D12: USD_SWAP_3M_CURVE_MARKETDATA | I12: ED8 Comdty | J12: 44454 | K12: 44545 | L12: 98.535 | M12: 0.0145 | O12: 12Y | P12: 0.017693 | Q12: TRUE
C13: Market Data Handle | D13: =_xll.meLWOCurveMarketDataCreate(D12,C3,C4:D9,F3,F5:G9,I3,I5:M27,O3,O5:Q27) -> USD_SWAP_3M_CURVE_MARKETDATA@5:0 | O13: 15Y | P13: 0.018256 | Q13: TRUE
O14: 20Y | P14: 0.018835 | Q14: TRUE
O15: 25Y | P15: 0.019031 | Q15: TRUE
C16: Curve Dictionary | O16: 30Y | P16: 0.019067 | Q16: TRUE
C17: Handle Name | D17: USD_SWAP_3M_CURVE
C18: Curve Generator | D18: =C32 -> USD_SWAP_3M_WITH_RISK@4:0
C19: Domestic Curve Collection | D19: USDYC
C20: Foreign Curve Collection
C23: Curve Build
C24: Handle Name | D24: {=IF('OIS - USDOIS'!$D$27,_xll.meLWOCurveCalibrate(D17,D18,D13,D19,D20),"#LOAD OIS CURVE")} -> USD_SWAP_3M_CURVE@6:0
C25: Curve Collection | D25: USDYC
C26: Curve Index | D26: STD:USD3ML
C27: Calibration Time Taken | D27: 0.25100 sec
C28: Curve Loaded | D28: =_xll.meLWOExists(D24,"CURVE") -> TRUE
C31: Create Curve Generator | D31: JacobianBuildFrequency | F31: Flat-Shift Curve
C32: =_xll.meLWOCurveGeneratorCreate("USD_SWAP_3M_WITH_RISK",C34,C35:D52,C54,C55:D57,C59,C60:D64,C66,C67:D67,C69,C70:D76,C78,C79:D91) -> USD_SWAP_3M_WITH_RISK@4:0 | D32: ONCE | F32: 1=meLWOCurveBumpAll(D24,0.01%,TRUE)
C34: CURVEPROPERTIES
C35: CurveType | D35: SWAP
C36: CurveIndexFrequency | D36: QUARTERLY
C37: StaticDataTable | D37: STD
C38: IndexName | D38: STD:USD3ML
C39: Currency | D39: USD
C40: interpolation | D40: FN_LINEARSPLINEINTERPOLATION
C41: yieldgen.interpolation | D41: FN_LINEARSPLINEINTERPOLATION
C42: future.interpolation | D42: FN_LINEARSPLINEINTERPOLATION
C43: isfrause | D43: FALSE
C44: isfutureuse | D44: TRUE
C45: Frequency | D45: SIMPLE
C46: dfcurvename | D46: OIS
... C48: FastRebuild | D48: TRUE
...

Sheet BASIS - USD6ML
B2: MARKETDATAPROPERTIES | E2: BASISSWAPS
B3: Currency | C3: USD | E3: Term | F3: Rate
B4: CurveType | C4: TENORBASIS | E4: 1Y | F4: 0.0006625
B5: CurveIndexFrequency | C5: SEMI-ANNUAL | E5: 2Y | F5: 0.0006125
B6: AsOfDate | C6: 43812 | E6: 3Y | F6: 0.0005875
E7: 4Y | F7: 0.000625
B8: CREATE MARKET DATA HANDLE | E8: 5Y | F8: 0.00065
B9: Handle Name | C9: USD_BASIS_3X6_MARKETDATA | E9: 6Y | F9: 0.000675
B10: Market Data Handle | C10: =_xll.meLWOCurveMarketDataCreate(C9,B2,B3:C6,E2,E4:F23) -> USD_BASIS_3X6_MARKETDATA@8:0 | E10: 7Y | F10: 0.0007
E11: 8Y | F11: 0.000725
E12: 9Y | F12: 0.0007375
B13: CURVE DICTIONARY | E13: 10Y | F13: 0.0007625
B14: HandleName | C14: USD_BASIS_6M_CURVE | E14: 12Y | F14: 0.0008
B15: CurveGenerator | C15: =B28 -> USD_BASIS_3X6_WITH_RISK@7:0 | E15: 15Y | F15: 0.0008375
B16: DomesticCurve | C16: USDYC | E16: 20Y | F16: 0.0008625
B17: ForeignCurve | E17: 25Y | F17: 0.0008875
E18: 30Y | F18: 0.0009
B19: CREATE CURVE HANDLE
B20: Handle Name | C20: {=IF('SWAP - USD3ML'!$D$28,_xll.meLWOCurveCalibrate(C14,C15,C10,C16,C17),"#LOAD SWAP CURVE")} -> USD_BASIS_6M_CURVE@9:0
B21: Curve Collection | C21: USDYC
B22: Curve Index | C22: 3M6MBasis:USD6ML
B23: Calibration Time Taken | C23: 0.14800 sec
B24: IsCurveLoaded | C24: =_xll.meLWOExists(C20,"CURVE") -> TRUE
B27: Create Curve Generator | C27: JacobianBuildFrequency
B28: =_xll.meLWOCurveGeneratorCreate("USD_BASIS_3X6_WITH_RISK",B30,B31:C44,B46,B47:C52,B55,B56:C97) -> USD_BASIS_3X6_WITH_RISK@7:0 | C28: ONCE
B30: CURVEPROPERTIES
B31: Currency | C31: USD
B32: CurveType | C32: TENORBASIS
B33: CurveIndexFrequency | C33: SEMI-ANNUAL
B34: StaticDataTable | C34: 3M6MBasis
B35: IndexName | C35: 3M6MBasis:USD6ML
B36: interpolation | C36: FN_SPLINEINTERPOLATION
B37: yieldgen.interpolation | C37: FN_SPLINEINTERPOLATION
B38: basis.interpolation | C38: FN_SPLINEINTERPOLATION
B39: isFwdBasis | C39: FALSE
B40: dfCurveName | C40: OIS
B41: JacobianBuildFrequency | C41: =C28 -> ONCE
B42: JacobianShiftType | C42: PERTURBED
B43: JacobianGradientShiftSize | C43: 0.0001
B44: JacobianMarketDataShiftSize | C44: 0.0001
...

Sheet JACOBIAN - OIS USDOIS
C2: CurveResults | F2: Select Curve Index | I2: Select Risk Type
B3: CurveCollection | C3: USDYC | F3: USDOIS | I3: Discount_Factors
B4: CurveIndex | C4: USDOIS | F4: USD3ML | I4: Forward_Rates
B5: RiskType | C5: =I3 -> Discount_Factors | F5: USD6ML
B7: {=_xll.meUtilityResize(_xll.meCurveResultsJacobianDisplay(C3,C4,C5),8000,50)} -> RiskType | C7: DISCOUNT_FACTORS
B8: ShiftType | C8: PERTURBED
B9: GradientShiftSize | C9: 0.0001
B11: OutrightInstrument | C11: TRUE | D11: TRUE | E11: TRUE | F11: TRUE | G11: TRUE | H11: TRUE | I11: TRUE | J11: TRUE | K11: TRUE | L11: TRUE | M11: TRUE | N11: TRUE | O11: TRUE | P11: TRUE | Q11: TRUE | R11: TRUE | S11: FALSE | T11: FALSE | U11: FALSE | V11: FALSE | W11: FALSE | X11: FALSE | Y11: FALSE | Z11: FALSE | AA11: FALSE | AB11: FALSE | AC11: FALSE | AD11: FALSE | AE11: TRUE | AF11: TRUE | AG11: TRUE | AH11: TRUE | AI11: TRUE | AJ11: TRUE | AK11: TRUE | AL11: TRUE | AM11: TRUE | AN11: TRUE | AO11: TRUE | AP11: TRUE
B12: MarketDataShiftSize | C12: 0.0001 | D12: 0.0001 | E12: 0.0001 | F12: 0.0001 | G12: 0.0001 | H12: 0.0001 | I12: 0.0001 | J12: 0.0001 | K12: 0.0001 | L12: 0.0001 | M12: 0.0001 | N12: 0.0001 | O12: 0.0001 | P12: 0.0001 | Q12: 0.0001 | R12: 0.0001 | S12: 0.0001 | T12: 0.0001 | U12: 0.0001 | V12: 0.0001 | W12: 0.0001 | X12: 0.0001 | Y12: 0.0001 | Z12: 0.0001 | AA12: 0.0001 | AB12: 0.0001 | AC12: 0.0001 | AD12: 0.0001 | AE12: 0.0001 | AF12: 0.0001 | AG12: 0.0001 | AH12: 0.0001 | AI12: 0.0001 | AJ12: 0.0001 | AK12: 0.0001 | AL12: 0.0001 | AM12: 0.0001 | AN12: 0.0001 | AO12: 0.0001 | AP12: 0.0001
C14: Instrument
B15: PaymentDate | C15: OIS_ON | D15: OIS_1W | E15: OIS_2W | F15: OIS_3W | G15: OIS_1M | H15: OIS_2M | I15: OIS_3M | J15: OIS_4M | K15: OIS_5M | L15: OIS_6M | M15: OIS_9M | N15: OIS_1Y | O15: OIS_2Y | P15: OIS_3Y | Q15: OIS_4Y | R15: OIS_5Y | S15: LIBOROIS_1Y | T15: LIBOROIS_2Y | U15: LIBOROIS_3Y | V15: LIBOROIS_4Y | W15: LIBOROIS_5Y | X15: LIBOROIS_7Y | Y15: LIBOROIS_10Y | Z15: LIBOROIS_12Y | AA15: LIBOROIS_15Y | AB15: LIBOROIS_20Y | AC15: LIBOROIS_25Y | AD15: LIBOROIS_30Y | AE15: SWAP_1Y | AF15: SWAP_2Y | AG15: SWAP_3Y | AH15: SWAP_4Y | AI15: SWAP_5Y | AJ15: SWAP_7Y | AK15: SWAP_10Y | AL15: SWAP_12Y | AM15: SWAP_15Y | AN15: SWAP_20Y | AO15: SWAP_25Y | AP15: SWAP_30Y
B16: 43812 | C16: 0 | D16: 0 | E16: 0 | F16: 0 | G16: 0 | H16: 0 | I16: 0 | J16: 0 | K16: 0 | L16: 0 | M16: 0 | N16: 0 | O16: 0 | P16: 0 | Q16: 0 | R16: 0 | S16: 0 | T16: 0 | U16: 0 | V16: 0 | W16: 0 | X16: 0 | Y16: 0 | Z16: 0 | AA16: 0 | AB16: 0 | AC16: 0 | AD16: 0 | AE16: 0 | AF16: 0 | AG16: 0 | AH16: 0 | AI16: 0 | AJ16: 0 | AK16: 0 | AL16: 0 | AM16: 0 | AN16: 0 | AO16: 0 | AP16: 0
B17: 43815 | C17: -8.331174e-07 | D17: 0 | E17: 0 | F17: 0 | G17: 0 | H17: 0 | I17: 0 | J17: 0 | K17: 0 | L17: 0 | M17: 0 | N17: 0 | O17: 0 | P17: 0 | Q17: 0 | R17: 0 | S17: 0 | T17: 0 | U17: 0 | V17: 0 | W17: 0 | X17: 0 | Y17: 0 | Z17: 0 | AA17: 0 | AB17: 0 | AC17: 0 | AD17: 0 | AE17: 0 | AF17: 0 | AG17: 0 | AH17: 0 | AI17: 0 | AJ17: 0 | AK17: 0 | AL17: 0 | AM17: 0 | AN17: 0 | AO17: 0 | AP17: 0
B18: 43816 | C18: -1.1107992e-06 | D18: 0 | E18: 0 | F18: 0 | G18: 0 | H18: 0 | I18: 0 | J18: 0 | K18: 0 | L18: 0 | M18: 0 | N18: 0 | O18: 0 | P18: 0 | Q18: 0 | R18: 0 | S18: 0 | T18: 0 | U18: 0 | V18: 0 | W18: 0 | X18: 0 | Y18: 0 | Z18: 0 | AA18: 0 | AB18: 0 | AC18: 0 | AD18: 0 | AE18: 0 | AF18: 0 | AG18: 0 | AH18: 0 | AI18: 0 | AJ18: 0 | AK18: 0 | AL18: 0 | AM18: 0 | AN18: 0 | AO18: 0 | AP18: 0
B19: 43823 | C19: -1.1104665e-06 | D19: -1.9429413e-06 | E19: 0 | F19: 0 | G19: 0 | H19: 0 | I19: 0 | J19: 0 | K19: 0 | L19: 0 | M19: 0 | N19: 0 | O19: 0 | P19: 0 | Q19: 0 | R19: 0 | S19: 0 | T19: 0 | U19: 0 | V19: 0 | W19: 0 | X19: 0 | Y19: 0 | Z19: 0 | AA19: 0 | AB19: 0 | AC19: 0 | AD19: 0 | AE19: 0 | AF19: 0 | AG19: 0 | AH19: 0 | AI19: 0 | AJ19: 0 | AK19: 0 | AL19: 0 | AM19: 0 | AN19: 0 | AO19: 0 | AP19: 0
B20: 43830 | C20: -1.1101283e-06 | D20: 0 | E20: -3.8835088e-06 | F20: 1.110223e-15 | G20: 1.110223e-15 | H20: 1.110223e-15 | I20: 1.110223e-15 | J20: 1.110223e-15 | K20: 1.110223e-15 | L20: 1.110223e-15 | M20: 1.110223e-15 | N20: 1.110223e-15 | O20: 1.110223e-15 | P20: 1.110223e-15 | Q20: 1.110223e-15 | R20: 1.110223e-15 | S20: 1.110223e-15 | T20: 1.110223e-15 | U20: 1.110223e-15 | V20: 1.110223e-15 | W20: 1.110223e-15 | X20: 1.110223e-15 | Y20: 1.110223e-15 | Z20: 1.110223e-15 | AA20: 1.110223e-15 | AB20: 1.110223e-15 | AC20: 1.110223e-15 | AD20: 1.110223e-15 | AE20: 1.110223e-15 | AF20: 1.110223e-15 | AG20: 1.110223e-15 | AH20: 1.110223e-15 | AI20: 1.110223e-15 | AJ20: 1.110223e-15 | AK20: 1.110223e-15 | AL20: 1.110223e-15 | AM20: 1.110223e-15 | AN20: 1.110223e-15 | AO20: 1.110223e-15 | AP20: 1.110223e-15
B21: 43837 | C21: -1.1097848e-06 | D21: 0 | E21: 0 | F21: -5.821647e-06 | G21: 0 | H21: 0 | I21: 0 | J21: 0 | K21: 0 | L21: 0 | M21: 0 | N21: 0 | O21: 0 | P21: 0 | Q21: 0 | R21: 0 | S21: 0 | T21: 0 | U21: 0 | V21: 0 | W21: 0 | X21: 0 | Y21: 0 | Z21: 0 | AA21: 0 | AB21: 0 | AC21: 0 | AD21: 0 | AE21: 0 | AF21: 0 | AG21: 0 | AH21: 0 | AI21: 0 | AJ21: 0 | AK21: 0 | AL21: 0 | AM21: 0 | AN21: 0 | AO21: 0 | AP21: 0
B22: 43847 | C22: -1.1093062e-06 | D22: 0 | E22: 0 | F22: 0 | G22: -8.5864255e-06 | H22: 0 | I22: 0 | J22: 0 | K22: 0 | L22: 0 | M22: 0 | N22: 0 | O22: 0 | P22: 0 | Q22: 0 | R22: 0 | S22: 0 | T22: 0 | U22: 0 | V22: 0 | W22: 0 | X22: 0 | Y22: 0 | Z22: 0 | AA22: 0 | AB22: 0 | AC22: 0 | AD22: 0 | AE22: 0 | AF22: 0 | AG22: 0 | AH22: 0 | AI22: 0 | AJ22: 0 | AK22: 0 | AL22: 0 | AM22: 0 | AN22: 0 | AO22: 0 | AP22: 0
B23: 43879 | C23: -1.1077808e-06 | D23: 0 | E23: 0 | F23: 0 | G23: 0 | H23: -1.7401721e-05 | I23: 0 | J23: 0 | K23: 0 | L23: 0 | M23: 0 | N23: 0 | O23: 0 | P23: 0 | Q23: 0 | R23: 0 | S23: 0 | T23: 0 | U23: 0 | V23: 0 | W23: 0 | X23: 0 | Y23: 0 | Z23: 0 | AA23: 0 | AB23: 0 | AC23: 0 | AD23: 0 | AE23: 0 | AF23: 0 | AG23: 0 | AH23: 0 | AI23: 0 | AJ23: 0 | AK23: 0 | AL23: 0 | AM23: 0 | AN23: 0 | AO23: 0 | AP23: 0
B24: 43907 | C24: -1.1064507e-06 | D24: 0 | E24: 0 | F24: 0 | G24: 0 | H24: 0 | I24: -2.50753e-05 | J24: 0 | K24: 0 | L24: 0 | M24: 0 | N24: 0 | O24: 0 | P24: 0 | Q24: 0 | R24: 0 | S24: 0 | T24: 0 | U24: 0 | V24: 0 | W24: 0 | X24: 0 | Y24: 0 | Z24: 0 | AA24: 0 | AB24: 0 | AC24: 0 | AD24: 0 | AE24: 0 | AF24: 0 | AG24: 0 | AH24: 0 | AI24: 0 | AJ24: 0 | AK24: 0 | AL24: 0 | AM24: 0 | AN24: 0 | AO24: 0 | AP24: 0
B25: 43938 | C25: -1.1050165e-06 | D25: 0 | E25: 0 | F25: 0 | G25: 0 | H25: 0 | I25: 0 | J25: -3.3530059e-05 | K25: 0 | L25: 0 | M25: 0 | N25: 0 | O25: 0 | P25: 0 | Q25: 0 | R25: 0 | S25: 0 | T25: 0 | U25: 0 | V25: 0 | W25: 0 | X25: 0 | Y25: 0 | Z25: 0 | AA25: 0 | AB25: 0 | AC25: 0 | AD25: 0 | AE25: 0 | AF25: 0 | AG25: 0 | AH25: 0 | AI25: 0 | AJ25: 0 | AK25: 0 | AL25: 0 | AM25: 0 | AN25: 0 | AO25: 0 | AP25: 0
B26: 43969 | C26: -1.1036113e-06 | D26: 0 | E26: 0 | F26: 0 | G26: 0 | H26: 0 | I26: 0 | J26: 0 | K26: -4.1942751e-05 | L26: 0 | M26: 0 | N26: 0 | O26: 0 | P26: 0 | Q26: 0 | R26: 0 | S26: 0 | T26: 0 | U26: 0 | V26: 0 | W26: 0 | X26: 0 | Y26: 0 | Z26: 0 | AA26: 0 | AB26: 0 | AC26: 0 | AD26: 0 | AE26: 0 | AF26: 0 | AG26: 0 | AH26: 0 | AI26: 0 | AJ26: 0 | AK26: 0 | AL26: 0 | AM26: 0 | AN26: 0 | AO26: 0 | AP26: 0
B27: 43999 | C27: -1.1022683e-06 | D27: 0 | E27: 0 | F27: 0 | G27: 0 | H27: 0 | I27: 0 | J27: 0 | K27: 0 | L27: -5.0044394e-05 | M27: 0 | N27: 0 | O27: 0 | P27: 0 | Q27: 0 | R27: 0 | S27: 0 | T27: 0 | U27: 0 | V27: 0 | W27: 0 | X27: 0 | Y27: 0 | Z27: 0 | AA27: 0 | AB27: 0 | AC27: 0 | AD27: 0 | AE27: 0 | AF27: 0 | AG27: 0 | AH27: 0 | AI27: 0 | AJ27: 0 | AK27: 0 | AL27: 0 | AM27: 0 | AN27: 0 | AO27: 0 | AP27: 0
... B145: 54774 | C145: -6.6910172e-07 | D145: 5.6263216e-11 | E145: -2.2415314e-10 | F145: 5.8956529e-10 | G145: -7.5881301e-10 | H145: 1.7172438e-09 | I145: -1.4341182e-08 | J145: 2.0986853e-08 | K145: -8.0803323e-08 | L145: 4.0502177e-07 | M145: -2.8272556e-07 | N145: 2.5246472e-13 | O145: 2.5246472e-13 | P145: 2.5246472e-13 | Q145: 2.5246472e-13 | R145: 2.5246472e-13 | S145: -9.9259637e-07 | T145: -2.5560528e-06 | U145: -2.677517e-06 | V145: -4.4297228e-06 | W145: -6.5936639e-06 | X145: -2.2588039e-05 | Y145: -3.0019169e-05 | Z145: -2.3730925e-05 | AA145: -8.1054769e-05 | AB145: -0.00011844587 | AC145: -0.00018501325 | AD145: 0.0023190658 | AE145: 9.7437469e-07 | AF145: 2.5131976e-06 | AG145: 2.6341534e-06 | AH145: 4.3580579e-06 | AI145: 6.4811767e-06 | AJ145: 2.2219376e-05 | AK145: 2.9522628e-05 | AL145: 2.3313756e-05 | AM145: 7.9706503e-05 | AN145: 0.0001164641 | AO145: 0.0001819822 | AP145: -0.0022798143

Sheet JACOBIAN - SWAP USD3ML
C2: CurveResults | F2: Select Curve Index | I2: Select Risk Type
B3: CurveCollection | C3: USDYC | F3: USDOIS | I3: Discount_Factors
B4: CurveIndex | C4: =F4 -> USD3ML | F4: USD3ML | I4: Forward_Rates
B5: RiskType | C5: =I4 -> Forward_Rates | F5: USD6ML
B7: {=_xll.meUtilityResize(_xll.meCurveResultsJacobianDisplay(C3,C4,C5),8000,50)} -> RiskType | C7: FORWARD_RATES
B8: ShiftType | C8: PERTURBED
B9: GradientShiftSize | C9: 0.0001
B11: OutrightInstrument | C11: TRUE | D11: TRUE | E11: TRUE | F11: TRUE | G11: TRUE | H11: TRUE | I11: TRUE | J11: TRUE | K11: TRUE | L11: TRUE | M11: TRUE | N11: TRUE | O11: TRUE | P11: TRUE | Q11: TRUE | R11: TRUE | S11: TRUE | T11: TRUE | U11: TRUE | V11: TRUE | W11: TRUE | X11: TRUE | Y11: TRUE | Z11: TRUE
B12: MarketDataShiftSize | C12: 0.0001 | D12: 0.0001 | E12: 0.0001 | F12: 0.0001 | G12: 0.0001 | H12: 0.0001 | I12: 0.0001 | J12: 0.0001 | K12: 0.0001 | L12: 0.0001 | M12: 0.0001 | N12: 0.0001 | O12: 0.0001 | P12: 0.0001 | Q12: 0.0001 | R12: 0.0001 | S12: 0.0001 | T12: 0.0001 | U12: 0.0001 | V12: 0.0001 | W12: 0.0001 | X12: 0.0001 | Y12: 0.0001 | Z12: 0.0001
C14: Instrument
B15: FixingDate | C15: LIBORFIXING_1M | D15: LIBORFIXING_3M | E15: LIBORFIXING_6M | F15: LIBORFIXING_12M | G15: ED1 Comdty | H15: ED2 Comdty | I15: ED3 Comdty | J15: ED4 Comdty | K15: ED5 Comdty | L15: ED6 Comdty | M15: ED7 Comdty | N15: ED8 Comdty | O15: SWAP_3Y | P15: SWAP_4Y | Q15: SWAP_5Y | R15: SWAP_7Y | S15: SWAP_8Y | T15: SWAP_9Y | U15: SWAP_10Y | V15: SWAP_12Y | W15: SWAP_15Y | X15: SWAP_20Y | Y15: SWAP_25Y | Z15: SWAP_30Y
B16: 43812 | C16: 4.416036e-06 | D16: 9.9998269e-05 | E16: 0 | F16: 0 | G16: -4.4154092e-06 | H16: 0 | I16: 0 | J16: 0 | K16: 0 | L16: 0 | M16: 0 | N16: 0 | O16: 0 | P16: 0 | Q16: 0 | R16: 0 | S16: 0 | T16: 0 | U16: 0 | V16: 0 | W16: 0 | X16: 0 | Y16: 0 | Z16: 0
B17: 43815 | C17: 1.1041031e-06 | D17: 9.9999567e-05 | E17: 0 | F17: 0 | G17: -1.1040418e-06 | H17: 0 | I17: 0 | J17: 0 | K17: 0 | L17: 0 | M17: 0 | N17: 0 | O17: 0 | P17: 0 | Q17: 0 | R17: 0 | S17: 0 | T17: 0 | U17: 0 | V17: 0 | W17: 0 | X17: 0 | Y17: 0 | Z17: 0
B18: 43816 | C18: 0 | D18: 0.0001 | E18: 0 | F18: 0 | G18: 0 | H18: 0 | I18: 0 | J18: 0 | K18: 0 | L18: 0 | M18: 0 | N18: 0 | O18: 0 | P18: 0 | Q18: 0 | R18: 0 | S18: 0 | T18: 0 | U18: 0 | V18: 0 | W18: 0 | X18: 0 | Y18: 0 | Z18: 0
B19: 43817 | C19: 0 | D19: 0 | E19: 0 | F19: 0 | G19: 0.0001 | H19: 0 | I19: 0 | J19: 0 | K19: 0 | L19: 0 | M19: 0 | N19: 0 | O19: 0 | P19: 0 | Q19: 0 | R19: 0 | S19: 0 | T19: 0 | U19: 0 | V19: 0 | W19: 0 | X19: 0 | Y19: 0 | Z19: 0
B20: 43907 | C20: -8.7083118e-16 | D20: -1.6899091e-10 | E20: 0 | F20: 0 | G20: 1.0863215e-06 | H20: 9.8918238e-05 | I20: 0 | J20: 0 | K20: 0 | L20: 0 | M20: 0 | N20: 0 | O20: 0 | P20: 0 | Q20: 0 | R20: 0 | S20: 0 | T20: 0 | U20: 0 | V20: 0 | W20: 0 | X20: 0 | Y20: 0 | Z20: 0
B21: 43908 | C21: 8.6736174e-16 | D21: 8.6736174e-16 | E21: 0 | F21: 0 | G21: 8.6736174e-16 | H21: 9.8917452e-05 | I21: 1.0828838e-06 | J21: 0 | K21: 0 | L21: 0 | M21: 0 | N21: 0 | O21: 0 | P21: 0 | Q21: 0 | R21: 0 | S21: 0 | T21: 0 | U21: 0 | V21: 0 | W21: 0 | X21: 0 | Y21: 0 | Z21: 0
B22: 43999 | C22: 0 | D22: 0 | E22: 0 | F22: 0 | G22: -8.7083118e-16 | H22: 0 | I22: 9.8917245e-05 | J22: 1.087205e-06 | K22: 0 | L22: 0 | M22: 0 | N22: 0 | O22: 0 | P22: 0 | Q22: 0 | R22: 0 | S22: 0 | T22: 0 | U22: 0 | V22: 0 | W22: 0 | X22: 0 | Y22: 0 | Z22: 0
B23: 44090 | C23: 0 | D23: 0 | E23: 0 | F23: 0 | G23: 0 | H23: 0 | I23: 0 | J23: 0.0001 | K23: 0 | L23: 0 | M23: 0 | N23: 0 | O23: 0 | P23: 0 | Q23: 0 | R23: 0 | S23: 0 | T23: 0 | U23: 0 | V23: 0 | W23: 0 | X23: 0 | Y23: 0 | Z23: 0
B24: 44091 | C24: 0 | D24: 0 | E24: 0 | F24: 0 | G24: 0 | H24: 0 | I24: 8.795048e-16 | J24: 9.8901058e-05 | K24: 1.098915e-06 | L24: 0 | M24: 0 | N24: 0 | O24: 0 | P24: 0 | Q24: 0 | R24: 0 | S24: 0 | T24: 0 | U24: 0 | V24: 0 | W24: 0 | X24: 0 | Y24: 0 | Z24: 0
B25: 44181 | C25: 0 | D25: 0 | E25: 0 | F25: 0 | G25: 0 | H25: 0 | I25: 0 | J25: 0 | K25: 9.9991564e-05 | L25: 0 | M25: 0 | N25: 0 | O25: 0 | P25: 0 | Q25: 0 | R25: 0 | S25: 0 | T25: 0 | U25: 0 | V25: 0 | W25: 0 | X25: 0 | Y25: 0 | Z25: 0
B26: 44182 | C26: 0 | D26: 0 | E26: 0 | F26: 0 | G26: 0 | H26: 0 | I26: 0 | J26: 0 | K26: 9.9995766e-05 | L26: 0 | M26: 0 | N26: 0 | O26: 0 | P26: 0 | Q26: 0 | R26: 0 | S26: 0 | T26: 0 | U26: 0 | V26: 0 | W26: 0 | X26: 0 | Y26: 0 | Z26: 0
B27: 44272 | C27: 0 | D27: 0 | E27: 0 | F27: 0 | G27: 0 | H27: 0 | I27: 0 | J27: 0 | K27: 0 | L27: 9.8916989e-05 | M27: 1.0870066e-06 | N27: 0 | O27: 0 | P27: 0 | Q27: 0 | R27: 0 | S27: 0 | T27: 0 | U27: 0 | V27: 0 | W27: 0 | X27: 0 | Y27: 0 | Z27: 0
... B145: 54774 | C145: -4.3343107e-13 | D145: 4.3343107e-11 | E145: -6.3939964e-12 | F145: -4.3165471e-13 | G145: 3.8191672e-14 | H145: 4.2395421e-11 | I145: 3.6421532e-11 | J145: 3.6362913e-11 | K145: 3.6296299e-11 | L145: 3.6163073e-11 | M145: 3.5847769e-11 | N145: 7.9841911e-11 | O145: -1.9360256e-09 | P145: 9.3655892e-09 | Q145: -2.3340476e-08 | R145: 2.0591269e-07 | S145: -1.07273e-06 | T145: 4.6657562e-06 | U145: -1.0407226e-05 | V145: 2.3046742e-05 | W145: -5.530219e-05 | X145: 0.00022034889 | Y145: -0.001038606 | Z145: 0.00095705483

Sheet JACOBIAN - BASIS USD6ML
C2: CurveResults | F2: Select Curve Index | I2: Select Risk Type
B3: CurveCollection | C3: USDYC | F3: USDOIS | I3: Discount_Factors
B4: CurveIndex | C4: =F5 -> USD6ML | F4: USD3ML | I4: Forward_Rates
B5: RiskType | C5: =I4 -> Forward_Rates | F5: USD6ML
B7: {=_xll.meUtilityResize(_xll.meCurveResultsJacobianDisplay(C3,C4,C5),8000,50)} -> RiskType | C7: FORWARD_RATES
B8: ShiftType | C8: PERTURBED
B9: GradientShiftSize | C9: 0.0001
B11: OutrightInstrument | C11: FALSE | D11: FALSE | E11: FALSE | F11: FALSE | G11: FALSE | H11: FALSE | I11: FALSE | J11: FALSE | K11: FALSE | L11: FALSE | M11: FALSE | N11: FALSE | O11: FALSE | P11: FALSE | Q11: FALSE
B12: MarketDataShiftSize | C12: 0.0001 | D12: 0.0001 | E12: 0.0001 | F12: 0.0001 | G12: 0.0001 | H12: 0.0001 | I12: 0.0001 | J12: 0.0001 | K12: 0.0001 | L12: 0.0001 | M12: 0.0001 | N12: 0.0001 | O12: 0.0001 | P12: 0.0001 | Q12: 0.0001
C14: Instrument
B15: FixingDate | C15: BASIS_1Y | D15: BASIS_2Y | E15: BASIS_3Y | F15: BASIS_4Y | G15: BASIS_5Y | H15: BASIS_6Y | I15: BASIS_7Y | J15: BASIS_8Y | K15: BASIS_9Y | L15: BASIS_10Y | M15: BASIS_12Y | N15: BASIS_15Y | O15: BASIS_20Y | P15: BASIS_25Y | Q15: BASIS_30Y
B16: 43812 | C16: -3.6702795e-06 | D16: 2.8416085e-07 | E16: -1.1443964e-07 | F16: 4.1386738e-08 | G16: -1.3918968e-08 | H16: 4.5017222e-09 | I16: -1.4142464e-09 | J16: 4.3410507e-10 | K16: -1.2850175e-10 | L16: 3.119062e-11 | M16: -3.6463818e-12 | N16: -4.5671557e-12 | O16: -1.1752752e-13 | P16: 4.0616815e-14 | Q16: -7.7785001e-15
B17: 43816 | C17: 4.3715032e-16 | D17: 0 | E17: -4.3715032e-16 | F17: 0 | G17: 0 | H17: 0 | I17: 0 | J17: 0 | K17: 0 | L17: 0 | M17: 0 | N17: -5.1355621e-12 | O17: 0 | P17: 0 | Q17: 0
B18: 43999 | C18: 0.00020110596 | D18: 0 | E18: 0 | F18: 0 | G18: 0 | H18: 0 | I18: 0 | J18: 0 | K18: 0 | L18: 0 | M18: 0 | N18: -3.3677922e-13 | O18: 0 | P18: 0 | Q18: 0
B19: 44182 | C19: -4.2041555e-05 | D19: 0.00022564516 | E19: -7.0643349e-05 | F19: 2.5545083e-05 | G19: -8.5915037e-06 | H19: 2.7787368e-06 | I19: -8.7295475e-07 | J19: 2.6795268e-07 | K19: -7.9320356e-08 | L19: 1.9250615e-08 | M19: -2.2524615e-09 | N19: 4.0057891e-10 | O19: -7.3385693e-11 | P19: 2.3507349e-11 | Q19: -7.3519212e-12
B20: 44364 | C20: -0.00016158893 | D20: 0.00017827793 | E20: 7.0704227e-05 | F20: -2.5567118e-05 | G20: 8.5988844e-06 | H20: -2.7811202e-06 | I20: 8.7370163e-07 | J20: -2.6820381e-07 | K20: 7.9375119e-08 | L20: -1.9284649e-08 | M20: 2.2413053e-09 | N20: -4.0522383e-10 | O20: 6.5603042e-11 | P20: -3.726156e-11 | Q20: -1.3227452e-11
B21: 44547 | C21: -3.6872773e-05 | D21: -0.00015762469 | E21: 0.00036411921 | F21: -0.00010458994 | G21: 3.5177304e-05 | H21: -1.1377234e-05 | I21: 3.5742259e-06 | J21: -1.097147e-06 | K21: 3.2474132e-07 | L21: -7.8855532e-08 | M21: 9.1969373e-09 | N21: -1.6481502e-09 | O21: 2.8445378e-10 | P21: -1.2258546e-10 | Q21: -1.2572363e-11
B22: 44729 | C22: 3.6517356e-05 | D22: -0.0002489017 | E22: 0.00024382471 | F22: 0.00010358182 | G22: -3.4838226e-05 | H22: 1.1267558e-05 | I22: -3.5397572e-06 | J22: 1.08658e-06 | K22: -3.2161993e-07 | L22: 7.8091949e-08 | M22: -9.1010123e-09 | N22: 1.6320765e-09 | O22: -2.8305531e-10 | P22: 1.3276342e-10 | Q22: 3.6697138e-12
B23: 44914 | C23: 9.7496633e-06 | D23: -5.2682796e-05 | E23: -0.0002497186 | F23: 0.00049458215 | G23: -0.00013184159 | H23: 4.2642287e-05 | I23: -1.3396135e-05 | J23: 4.1121336e-06 | K23: -1.2171356e-06 | L23: 2.9553347e-07 | M23: -3.4447876e-08 | N23: 6.1815766e-09 | O23: -1.0572607e-09 | P23: 4.8109824e-10 | Q23: 4.5444967e-11
B24: 45096 | C24: -9.8167228e-06 | D24: 5.3045287e-05 | E24: -0.0003713523 | F24: 0.00032588799 | G24: 0.00013274833 | H24: -4.2935424e-05 | I24: 1.3488468e-05 | J24: -4.1403579e-06 | K24: 1.2256624e-06 | L24: -2.9759836e-07 | M24: 3.4789229e-08 | N24: -6.1719167e-09 | O24: 1.1814099e-09 | P24: -4.4807131e-10 | Q24: 1.4366999e-10
B25: 45278 | C25: -2.6236094e-06 | D25: 1.4175699e-05 | E25: -7.866526e-05 | F25: -0.00033273529 | G25: 0.0006199382 | H25: -0.00015853043 | I25: 4.9804872e-05 | J25: -1.5287979e-05 | K25: 4.525351e-06 | L25: -1.0987698e-06 | M25: 1.2819748e-07 | N25: -2.2912098e-08 | O25: 4.0397928e-09 | P25: -1.799472e-09 | Q25: 1.6280704e-10
B26: 45279 | C26: -2.5699785e-06 | D26: 1.3885898e-05 | E26: -7.7057173e-05 | F26: -0.00033565928 | G26: 0.0006213169 | H26: -0.0001582848 | I26: 4.9727684e-05 | J26: -1.5264289e-05 | K26: 4.5183375e-06 | L26: -1.0970666e-06 | M26: 1.2799717e-07 | N26: -2.2877279e-08 | O26: 4.0311544e-09 | P26: -1.7983167e-09 | Q26: 1.6151889e-10
B27: 45460 | C27: 2.6276838e-06 | D27: -1.4199708e-05 | E27: 7.8796231e-05 | F27: -0.00049773363 | G27: 0.00041063028 | H27: 0.00015879541 | I27: -4.9888668e-05 | J27: 1.5312997e-05 | K27: -4.5330487e-06 | L27: 1.1008098e-06 | M27: -1.2905339e-07 | N27: 2.2690612e-08 | O27: -4.9983956e-09 | P27: 1.1088171e-09 | Q27: -4.6161501e-10
... B87: 54774 | C87: 8.1246218e-11 | D87: -1.4610335e-10 | E87: 7.421593e-10 | F87: -2.9538398e-09 | G87: 1.3248723e-08 | H87: -6.0095119e-08 | I87: 2.6339626e-07 | J87: -1.1226934e-06 | K87: 4.7810825e-06 | L87: -1.0641485e-05 | M87: 2.355226e-05 | N87: -5.6521984e-05 | O87: 0.000225311 | P87: -0.0010667234 | Q87: 0.00098471341

Sheet PRICING
B2: Trade Dates | F2: SWAPS: USD3ML | N2: Trade Booking & Pricing | R2: Curve Calibration Check
D3: Unadjusted Date ! | H3: Swap Template
B4: EffectiveDate | C4: Calendar | D4: MaturityDate | F4: EffectiveDate | G4: Maturity | H4: Generator | I4: PayRec | J4: Notional | K4: FixedRate | L4: Spread | N4: CreateSwap | O4: CurveCollection | P4: ParRate % | R4: Term | S4: Rate % | T4: +/- Bps
B5: =_xll.meDateFromTenor('SWAP - USD3ML'!$D$7,F5,"MOD_FOLLOWING",C5,"") -> 43816 | C5: NYB:LNB | D5: =_xll.meDateFromTenor(B5,G5) -> 44912 | F5: 2D | G5: ='SWAP - USD3ML'!O5 -> 3Y | H5: USD_3ML | I5: PAY | J5: 1000000 | K5: 0.01 | L5: 0 | N5: =_xll.meLWOSwapCreateFromGenerator(H5&"_"&G5,H5,I5,J5,B5,D5,K5,L5) -> USD_3ML_3Y@11:1 | O5: USDYC | P5: =_xll.meLWOSwapParRate(N5,O5) -> 0.015848 | R5: ='SWAP - USD3ML'!O5 -> 3Y | S5: ='SWAP - USD3ML'!P5 -> 0.015848 | T5: =(P5-S5)*10000 -> 2.7686187e-11
B6: =_xll.meDateFromTenor('SWAP - USD3ML'!$D$7,F6,"MOD_FOLLOWING",C6,"") -> 43816 | C6: NYB:LNB | D6: =_xll.meDateFromTenor(B6,G6) -> 45277 | F6: 2D | G6: ='SWAP - USD3ML'!O6 -> 4Y | H6: USD_3ML | I6: PAY | J6: 1000000 | K6: 0.01 | L6: 0 | N6: =_xll.meLWOSwapCreateFromGenerator(H6&"_"&G6,H6,I6,J6,B6,D6,K6,L6) -> USD_3ML_4Y@12:1 | O6: USDYC | P6: =_xll.meLWOSwapParRate(N6,O6) -> 0.01584 | R6: ='SWAP - USD3ML'!O6 -> 4Y | S6: ='SWAP - USD3ML'!P6 -> 0.01584 | T6: =(P6-S6)*10000 -> -4.6091603e-10
B7: =_xll.meDateFromTenor('SWAP - USD3ML'!$D$7,F7,"MOD_FOLLOWING",C7,"") -> 43816 | C7: NYB:LNB | D7: =_xll.meDateFromTenor(B7,G7) -> 45643 | F7: 2D | G7: ='SWAP - USD3ML'!O7 -> 5Y | H7: USD_3ML | I7: PAY | J7: 1000000 | K7: 0.01 | L7: 0 | N7: =_xll.meLWOSwapCreateFromGenerator(H7&"_"&G7,H7,I7,J7,B7,D7,K7,L7) -> USD_3ML_5Y@13:1 | O7: USDYC | P7: =_xll.meLWOSwapParRate(N7,O7) -> 0.015964 | R7: ='SWAP - USD3ML'!O7 -> 5Y | S7: ='SWAP - USD3ML'!P7 -> 0.015964 | T7: =(P7-S7)*10000 -> 1.0935697e-10
B8: =_xll.meDateFromTenor('SWAP - USD3ML'!$D$7,F8,"MOD_FOLLOWING",C8,"") -> 43816 | C8: NYB:LNB | D8: =_xll.meDateFromTenor(B8,G8) -> 46373 | F8: 2D | G8: ='SWAP - USD3ML'!O8 -> 7Y | H8: USD_3ML | I8: PAY | J8: 1000000 | K8: 0.01 | L8: 0 | N8: =_xll.meLWOSwapCreateFromGenerator(H8&"_"&G8,H8,I8,J8,B8,D8,K8,L8) -> USD_3ML_7Y@14:1 | O8: USDYC | P8: =_xll.meLWOSwapParRate(N8,O8) -> 0.016361 | R8: ='SWAP - USD3ML'!O8 -> 7Y | S8: ='SWAP - USD3ML'!P8 -> 0.016361 | T8: =(P8-S8)*10000 -> -4.7024884e-10
B9: =_xll.meDateFromTenor('SWAP - USD3ML'!$D$7,F9,"MOD_FOLLOWING",C9,"") -> 43816 | C9: NYB:LNB | D9: =_xll.meDateFromTenor(B9,G9) -> 46738 | F9: 2D | G9: ='SWAP - USD3ML'!O9 -> 8Y | H9: USD_3ML | I9: PAY | J9: 1000000 | K9: 0.01 | L9: 0 | N9: =_xll.meLWOSwapCreateFromGenerator(H9&"_"&G9,H9,I9,J9,B9,D9,K9,L9) -> USD_3ML_8Y@15:1 | O9: USDYC | P9: =_xll.meLWOSwapParRate(N9,O9) -> 0.016623 | R9: ='SWAP - USD3ML'!O9 -> 8Y | S9: ='SWAP - USD3ML'!P9 -> 0.016623 | T9: =(P9-S9)*10000 -> 2.3757038e-09
B10: =_xll.meDateFromTenor('SWAP - USD3ML'!$D$7,F10,"MOD_FOLLOWING",C10,"") -> 43816 | C10: NYB:LNB | D10: =_xll.meDateFromTenor(B10,G10) -> 47104 | F10: 2D | G10: ='SWAP - USD3ML'!O10 -> 9Y | H10: USD_3ML | I10: PAY | J10: 1000000 | K10: 0.01 | L10: 0 | N10: =_xll.meLWOSwapCreateFromGenerator(H10&"_"&G10,H10,I10,J10,B10,D10,K10,L10) -> USD_3ML_9Y@16:1 | O10: USDYC | P10: =_xll.meLWOSwapParRate(N10,O10) -> 0.016902 | R10: ='SWAP - USD3ML'!O10 -> 9Y | S10: ='SWAP - USD3ML'!P10 -> 0.016902 | T10: =(P10-S10)*10000 -> 3.2174263e-09
B11: =_xll.meDateFromTenor('SWAP - USD3ML'!$D$7,F11,"MOD_FOLLOWING",C11,"") -> 43816 | C11: NYB:LNB | D11: =_xll.meDateFromTenor(B11,G11) -> 47469 | F11: 2D | G11: ='SWAP - USD3ML'!O11 -> 10Y | H11: USD_3ML | I11: PAY | J11: 1000000 | K11: 0.01 | L11: 0 | N11: =_xll.meLWOSwapCreateFromGenerator(H11&"_"&G11,H11,I11,J11,B11,D11,K11,L11) -> USD_3ML_10Y@17:1 | O11: USDYC | P11: =_xll.meLWOSwapParRate(N11,O11) -> 0.017186 | R11: ='SWAP - USD3ML'!O11 -> 10Y | S11: ='SWAP - USD3ML'!P11 -> 0.017186 | T11: =(P11-S11)*10000 -> 3.0593236e-09
B12: =_xll.meDateFromTenor('SWAP - USD3ML'!$D$7,F12,"MOD_FOLLOWING",C12,"") -> 43816 | C12: NYB:LNB | D12: =_xll.meDateFromTenor(B12,G12) -> 48199 | F12: 2D | G12: ='SWAP - USD3ML'!O12 -> 12Y | H12: USD_3ML | I12: PAY | J12: 1000000 | K12: 0.01 | L12: 0 | N12: =_xll.meLWOSwapCreateFromGenerator(H12&"_"&G12,H12,I12,J12,B12,D12,K12,L12) -> USD_3ML_12Y@18:1 | O12: USDYC | P12: =_xll.meLWOSwapParRate(N12,O12) -> 0.017693 | R12: ='SWAP - USD3ML'!O12 -> 12Y | S12: ='SWAP - USD3ML'!P12 -> 0.017693 | T12: =(P12-S12)*10000 -> 1.2448376e-09
B13: =_xll.meDateFromTenor('SWAP - USD3ML'!$D$7,F13,"MOD_FOLLOWING",C13,"") -> 43816 | C13: NYB:LNB | D13: =_xll.meDateFromTenor(B13,G13) -> 49295 | F13: 2D | G13: ='SWAP - USD3ML'!O13 -> 15Y | H13: USD_3ML | I13: PAY | J13: 1000000 | K13: 0.01 | L13: 0 | N13: =_xll.meLWOSwapCreateFromGenerator(H13&"_"&G13,H13,I13,J13,B13,D13,K13,L13) -> USD_3ML_15Y@19:1 | O13: USDYC | P13: =_xll.meLWOSwapParRate(N13,O13) -> 0.018256 | R13: ='SWAP - USD3ML'!O13 -> 15Y | S13: ='SWAP - USD3ML'!P13 -> 0.018256 | T13: =(P13-S13)*10000 -> 1.866042e-09
B14: =_xll.meDateFromTenor('SWAP - USD3ML'!$D$7,F14,"MOD_FOLLOWING",C14,"") -> 43816 | C14: NYB:LNB | D14: =_xll.meDateFromTenor(B14,G14) -> 51121 | F14: 2D | G14: ='SWAP - USD3ML'!O14 -> 20Y | H14: USD_3ML | I14: PAY | J14: 1000000 | K14: 0.01 | L14: 0 | N14: =_xll.meLWOSwapCreateFromGenerator(H14&"_"&G14,H14,I14,J14,B14,D14,K14,L14) -> USD_3ML_20Y@20:1 | O14: USDYC | P14: =_xll.meLWOSwapParRate(N14,O14) -> 0.018835 | R14: ='SWAP - USD3ML'!O14 -> 20Y | S14: ='SWAP - USD3ML'!P14 -> 0.018835 | T14: =(P14-S14)*10000 -> 2.1785698e-09
B17: Trade Dates | F17: BASIS: USD6ML | N17: Trade Booking & Pricing | R17: Curve Calibration Check
D18: Unadjusted Date ! | H18: Swap Template
B19: EffectiveDate | C19: Calendar | D19: MaturityDate | F19: EffectiveDate | G19: Maturity | H19: Generator | I19: PayRec | J19: Notional | K19: Leg 1 Spread | L19: Leg 2 Spread | N19: CreateSwap | O19: CurveCollection | P19: Spread bps | R19: Term | S19: Spread bps | T19: +/- Bps
B20: =_xll.meDateFromTenor('BASIS - USD6ML'!$C$6,F20,"MOD_FOLLOWING",C20,"") -> 43816 | C20: NYB:LNB | D20: =_xll.meDateFromTenor(B20,G20) -> 44182 | F20: 2D | G20: ='BASIS - USD6ML'!E4 -> 1Y | H20: USD_BASIS_3X6 | I20: PAY | J20: 1000000 | K20: 0 | L20: 0 | N20: =_xll.meLWOSwapCreateFromGenerator(H20&"_"&G20,H20,I20,J20,B20,D20,K20,L20) -> USD_BASIS_3X6_1Y@10:1 | O20: USDYC | P20: =_xll.meLWOSwapParSpread(N20,O20) -> 6.625 | R20: ='BASIS - USD6ML'!E4 -> 1Y | S20: ='BASIS - USD6ML'!F4*10000 -> 6.625 | T20: =P20-S20 -> 2.7399929e-08
B21: =_xll.meDateFromTenor('BASIS - USD6ML'!$C$6,F21,"MOD_FOLLOWING",C21,"") -> 43816 | C21: NYB:LNB | D21: =_xll.meDateFromTenor(B21,G21) -> 44547 | F21: 2D | G21: ='BASIS - USD6ML'!E5 -> 2Y | H21: USD_BASIS_3X6 | I21: PAY | J21: 1000000 | K21: 0 | L21: 0 | N21: =_xll.meLWOSwapCreateFromGenerator(H21&"_"&G21,H21,I21,J21,B21,D21,K21,L21) -> USD_BASIS_3X6_2Y@21:1 | O21: USDYC | P21: =_xll.meLWOSwapParSpread(N21,O21) -> 6.125 | R21: ='BASIS - USD6ML'!E5 -> 2Y | S21: ='BASIS - USD6ML'!F5*10000 -> 6.125 | T21: =P21-S21 -> 2.4443427e-08
B22: =_xll.meDateFromTenor('BASIS - USD6ML'!$C$6,F22,"MOD_FOLLOWING",C22,"") -> 43816 | C22: NYB:LNB | D22: =_xll.meDateFromTenor(B22,G22) -> 44912 | F22: 2D | G22: ='BASIS - USD6ML'!E6 -> 3Y | H22: USD_BASIS_3X6 | I22: PAY | J22: 1000000 | K22: 0 | L22: 0 | N22: =_xll.meLWOSwapCreateFromGenerator(H22&"_"&G22,H22,I22,J22,B22,D22,K22,L22) -> USD_BASIS_3X6_3Y@22:1 | O22: USDYC | P22: =_xll.meLWOSwapParSpread(N22,O22) -> 5.875 | R22: ='BASIS - USD6ML'!E6 -> 3Y | S22: ='BASIS - USD6ML'!F6*10000 -> 5.875 | T22: =P22-S22 -> 1.6689734e-08
B23: =_xll.meDateFromTenor('BASIS - USD6ML'!$C$6,F23,"MOD_FOLLOWING",C23,"") -> 43816 | C23: NYB:LNB | D23: =_xll.meDateFromTenor(B23,G23) -> 45277 | F23: 2D | G23: ='BASIS - USD6ML'!E7 -> 4Y | H23: USD_BASIS_3X6 | I23: PAY | J23: 1000000 | K23: 0 | L23: 0 | N23: =_xll.meLWOSwapCreateFromGenerator(H23&"_"&G23,H23,I23,J23,B23,D23,K23,L23) -> USD_BASIS_3X6_4Y@23:1 | O23: USDYC | P23: =_xll.meLWOSwapParSpread(N23,O23) -> 6.2499999 | R23: ='BASIS - USD6ML'!E7 -> 4Y | S23: ='BASIS - USD6ML'!F7*10000 -> 6.25 | T23: =P23-S23 -> -5.0713627e-08
B24: =_xll.meDateFromTenor('BASIS - USD6ML'!$C$6,F24,"MOD_FOLLOWING",C24,"") -> 43816 | C24: NYB:LNB | D24: =_xll.meDateFromTenor(B24,G24) -> 45643 | F24: 2D | G24: ='BASIS - USD6ML'!E8 -> 5Y | H24: USD_BASIS_3X6 | I24: PAY | J24: 1000000 | K24: 0 | L24: 0 | N24: =_xll.meLWOSwapCreateFromGenerator(H24&"_"&G24,H24,I24,J24,B24,D24,K24,L24) -> USD_BASIS_3X6_5Y@24:1 | O24: USDYC | P24: =_xll.meLWOSwapParSpread(N24,O24) -> 6.5000002 | R24: ='BASIS - USD6ML'!E8 -> 5Y | S24: ='BASIS - USD6ML'!F8*10000 -> 6.5 | T24: =P24-S24 -> 2.1099966e-07
B25: =_xll.meDateFromTenor('BASIS - USD6ML'!$C$6,F25,"MOD_FOLLOWING",C25,"") -> 43816 | C25: NYB:LNB | D25: =_xll.meDateFromTenor(B25,G25) -> 46008 | F25: 2D | G25: ='BASIS - USD6ML'!E9 -> 6Y | H25: USD_BASIS_3X6 | I25: PAY | J25: 1000000 | K25: 0 | L25: 0 | N25: =_xll.meLWOSwapCreateFromGenerator(H25&"_"&G25,H25,I25,J25,B25,D25,K25,L25) -> USD_BASIS_3X6_6Y@25:1 | O25: USDYC | P25: =_xll.meLWOSwapParSpread(N25,O25) -> 6.7500001 | R25: ='BASIS - USD6ML'!E9 -> 6Y | S25: ='BASIS - USD6ML'!F9*10000 -> 6.75 | T25: =P25-S25 -> 1.3375299e-07
B26: =_xll.meDateFromTenor('BASIS - USD6ML'!$C$6,F26,"MOD_FOLLOWING",C26,"") -> 43816 | C26: NYB:LNB | D26: =_xll.meDateFromTenor(B26,G26) -> 46373 | F26: 2D | G26: ='BASIS - USD6ML'!E10 -> 7Y | H26: USD_BASIS_3X6 | I26: PAY | J26: 1000000 | K26: 0 | L26: 0 | N26: =_xll.meLWOSwapCreateFromGenerator(H26&"_"&G26,H26,I26,J26,B26,D26,K26,L26) -> USD_BASIS_3X6_7Y@26:1 | O26: USDYC | P26: =_xll.meLWOSwapParSpread(N26,O26) -> 7.0000002 | R26: ='BASIS - USD6ML'!E10 -> 7Y | S26: ='BASIS - USD6ML'!F10*10000 -> 7 | T26: =P26-S26 -> 1.9191615e-07
B27: =_xll.meDateFromTenor('BASIS - USD6ML'!$C$6,F27,"MOD_FOLLOWING",C27,"") -> 43816 | C27: NYB:LNB | D27: =_xll.meDateFromTenor(B27,G27) -> 46738 | F27: 2D | G27: ='BASIS - USD6ML'!E11 -> 8Y | H27: USD_BASIS_3X6 | I27: PAY | J27: 1000000 | K27: 0 | L27: 0 | N27: =_xll.meLWOSwapCreateFromGenerator(H27&"_"&G27,H27,I27,J27,B27,D27,K27,L27) -> USD_BASIS_3X6_8Y@27:1 | O27: USDYC | P27: =_xll.meLWOSwapParSpread(N27,O27) -> 7.2500002 | R27: ='BASIS - USD6ML'!E11 -> 8Y | S27: ='BASIS - USD6ML'!F11*10000 -> 7.25 | T27: =P27-S27 -> 1.6002734e-07
B28: =_xll.meDateFromTenor('BASIS - USD6ML'!$C$6,F28,"MOD_FOLLOWING",C28,"") -> 43816 | C28: NYB:LNB | D28: =_xll.meDateFromTenor(B28,G28) -> 47104 | F28: 2D | G28: ='BASIS - USD6ML'!E12 -> 9Y | H28: USD_BASIS_3X6 | I28: PAY | J28: 1000000 | K28: 0 | L28: 0 | N28: =_xll.meLWOSwapCreateFromGenerator(H28&"_"&G28,H28,I28,J28,B28,D28,K28,L28) -> USD_BASIS_3X6_9Y@28:1 | O28: USDYC | P28: =_xll.meLWOSwapParSpread(N28,O28) -> 7.3750004 | R28: ='BASIS - USD6ML'!E12 -> 9Y | S28: ='BASIS - USD6ML'!F12*10000 -> 7.375 | T28: =P28-S28 -> 3.7336453e-07
B29: =_xll.meDateFromTenor('BASIS - USD6ML'!$C$6,F29,"MOD_FOLLOWING",C29,"") -> 43816 | C29: NYB:LNB | D29: =_xll.meDateFromTenor(B29,G29) -> 47469 | F29: 2D | G29: ='BASIS - USD6ML'!E13 -> 10Y | H29: USD_BASIS_3X6 | I29: PAY | J29: 1000000 | K29: 0 | L29: 0 | N29: =_xll.meLWOSwapCreateFromGenerator(H29&"_"&G29,H29,I29,J29,B29,D29,K29,L29) -> USD_BASIS_3X6_10Y@29:1 | O29: USDYC | P29: =_xll.meLWOSwapParSpread(N29,O29) -> 7.6250002 | R29: ='BASIS - USD6ML'!E13 -> 10Y | S29: ='BASIS - USD6ML'!F13*10000 -> 7.625 | T29: =P29-S29 -> 1.8212381e-07
B30: =_xll.meDateFromTenor('BASIS - USD6ML'!$C$6,F30,"MOD_FOLLOWING",C30,"") -> 43816 | C30: NYB:LNB | D30: =_xll.meDateFromTenor(B30,G30) -> 48199 | F30: 2D | G30: ='BASIS - USD6ML'!E14 -> 12Y | H30: USD_BASIS_3X6 | I30: PAY | J30: 1000000 | K30: 0 | L30: 0 | N30: =_xll.meLWOSwapCreateFromGenerator(H30&"_"&G30,H30,I30,J30,B30,D30,K30,L30) -> USD_BASIS_3X6_12Y@30:1 | O30: USDYC | P30: =_xll.meLWOSwapParSpread(N30,O30) -> 8.0000002 | R30: ='BASIS - USD6ML'!E14 -> 12Y | S30: ='BASIS - USD6ML'!F14*10000 -> 8 | T30: =P30-S30 -> 1.8401619e-07
B31: =_xll.meDateFromTenor('BASIS - USD6ML'!$C$6,F31,"MOD_FOLLOWING",C31,"") -> 43816 | C31: NYB:LNB | D31: =_xll.meDateFromTenor(B31,G31) -> 49295 | F31: 2D | G31: ='BASIS - USD6ML'!E15 -> 15Y | H31: USD_BASIS_3X6 | I31: PAY | J31: 1000000 | K31: 0 | L31: 0 | N31: =_xll.meLWOSwapCreateFromGenerator(H31&"_"&G31,H31,I31,J31,B31,D31,K31,L31) -> USD_BASIS_3X6_15Y@31:1 | O31: USDYC | P31: =_xll.meLWOSwapParSpread(N31,O31) -> 8.3750001 | R31: ='BASIS - USD6ML'!E15 -> 15Y | S31: ='BASIS - USD6ML'!F15*10000 -> 8.375 | T31: =P31-S31 -> 6.9950159e-08
... B34: =_xll.meDateFromTenor('BASIS - USD6ML'!$C$6,F34,"MOD_FOLLOWING",C34,"") -> 43816 | C34: NYB:LNB | D34: =_xll.meDateFromTenor(B34,G34) -> 54774 | F34: 2D | G34: ='BASIS - USD6ML'!E18 -> 30Y | H34: USD_BASIS_3X6 | I34: PAY | J34: 1000000 | K34: 0 | L34: 0 | N34: =_xll.meLWOSwapCreateFromGenerator(H34&"_"&G34,H34,I34,J34,B34,D34,K34,L34) -> USD_BASIS_3X6_30Y@34:1 | O34: USDYC | P34: =_xll.meLWOSwapParSpread(N34,O34) -> 9.0000001 | R34: ='BASIS - USD6ML'!E18 -> 30Y | S34: ='BASIS - USD6ML'!F18*10000 -> 9 | T34: =P34-S34 -> 6.6681054e-08

Sheet RISK - SWAP USD3ML
W1: … Cashflows | AH1: .. DF Risk Totals | AO1: .. Forward Risk Totals | CG1: … DF Jacobian All Instruments | DZ1: … DF Jacobian Outrights Only | FC1: … Forward Rate Jacobian Outrights Only | FH1: Enable
CK2: Discount Risk | DZ2: Discount Factor Risk Buckets | ED2: Forward Rate Risk | FC2: Forward Rate Risk Buckets | FH2: TRUE
X3: Total DiscFact Risk | Y3: =SUMPRODUCT(Y7:Y136,AB7:AB136) -> -6.7664009 | AH3: Total Libor Risk | AI3: =SUMPRODUCT(AI7:AI136,AP7:AP136) -> 481.64251 | AR3: Discount Risk: Includes Risk to Non-Outrights | CK3: Total Risk | CL3: =SUM(CL4:DY4) -> -6.7664009 | ED3: Total Risk | EE3: =SUM(EE4:FR4) -> 481.64251
AR4: Bucketed Risk | AS4: {=MMULT(TRANSPOSE($Y$7:$Y$136),AS7:CF136)} -> -0.031913443 | AT4: -6.5722291e-05 | AU4: 0.0002628138 | AV4: -0.00069229569 | AW4: 0.00089110526 | AX4: -0.0020152631 | AY4: -0.11351084 | AZ4: -0.024630204 | BA4: 0.09482396 | BB4: -0.10450109 | BC4: -0.0065064534 | BD4: 1.7487222e-09 | BE4: 1.7487222e-09 | BF4: 1.7487222e-09 | BG4: 1.7487222e-09 | BH4: 1.7487222e-09 | BI4: 0.45074544 | BJ4: 0.95997654 | BK4: 1.5504902 | BL4: 2.6747167 | BM4: 1.1157576 | BN4: -0.073304232 | BO4: 0.014632148 | BP4: -0.0051258172 | BQ4: 0.00072807748 | BR4: -0.00010865311 | BS4: 2.7860562e-05 | BT4: -4.7351929e-06 | BU4: -0.44245873 | BV4: -0.94384686 | BW4: -1.5251596 | BX4: -2.6317589 | BY4: -1.097486 | BZ4: 0.072154335 | CA4: -0.01440296 | CB4: 0.0050480074 | CC4: -0.00071711095 | CD4: 0.00010705657 | CE4: -2.746692e-05 | CF4: 4.674435e-06 | CK4: Bucketed Risk | CL4: {=MMULT(TRANSPOSE($Y$7:$Y$136),CL7:DY136)} -> -0.031913443 | CM4: -6.5722291e-05 | CN4: 0.0002628138 | CO4: -0.00069229569 | CP4: 0.00089110526 | CQ4: -0.0020152631 | CR4: -0.11351084 | CS4: -0.024630204 | CT4: 0.09482396 | CU4: -0.10450109 | CV4: -0.0065064534 | CW4: 1.7487222e-09 | CX4: 1.7487222e-09 | CY4: 1.7487222e-09 | CZ4: 1.7487222e-09 | DA4: 1.7487222e-09 | DB4: 0 | DC4: 0 | DD4: 0 | DE4: 0 | DF4: 0 | DG4: 0 | DH4: 0 | DI4: 0 | DJ4: 0 | DK4: 0 | DL4: 0 | DM4: 0 | DN4: -0.44245873 | DO4: -0.94384686 | DP4: -1.5251596 | DQ4: -2.6317589 | DR4: -1.097486 | DS4: 0.072154335 | DT4: -0.01440296 | DU4: 0.0050480074 | DV4: -0.00071711095 | DW4: 0.00010705657 | DX4: -2.746692e-05 | DY4: 4.674435e-06 | EA4: Analytical Risk | ED4: Bucketed Risk | EE4: {=MMULT(TRANSPOSE(AI7:AI136),EE7:FB136)} -> 1.4946485e-06 | EF4: -25.174459 | EG4: 2.8845701e-05 | EH4: 1.4923469e-06 | EI4: 24.89905 | EJ4: -0.00021360723 | EK4: 0.27457112 | EL4: 6.5228962e-06 | EM4: 6.3238446e-06 | EN4: 6.3788171e-06 | EO4: 4.4750215e-06 | EP4: 1.1979127e-05 | EQ4: -3.8531254e-05 | ER4: -1.5316435e-05 | ES4: 481.6435 | ET4: -5.9088752e-06 | EU4: 1.8769179e-05 | EV4: 1.0697891e-05 | EW4: 2.0927676e-05 | EX4: 8.3948983e-07 | EY4: 9.2639151e-07 | EZ4: 6.4801422e-07 | FA4: -9.2939276e-07 | FB4: 1.7864985e-06 | FD4: Analytical Risk | FH4: Numerical Risk
B5: Trade Details | F5: Cashflows | V5: AnnuityLet | X5: Coupon Mapping | AA5: RiskTotals - Discount Factor | AH5: Annuity Mapping | AO5: RiskTotals - Forward Rates | AR5: Jacobian USDOIS Discount Factors | EA5: Bucketed Discount Risk | FD5: Bucketed Forward Risk | FH5: {=IF($FH$2=TRUE,_xll.meLWOSwapDeltaLadder(C6,C7),"#DISABLED")} -> USD : Pillars | FI5: USD : Total | FJ5: USD : Pillars | FK5: USD : Total | FL5: #N/A
B6: Trade | C6: =PRICING!N7 -> USD_3ML_5Y@13:1 | F6: {=_xll.meUtilityResize(_xll.meLWOSwapDisplayCashflows(C6,C7),50,50)} -> Leg1:Fixed Leg Schedule & Cashflows | X6: =AR6 -> PaymentDate | AA6: PaymentDate | AB6: RiskTotal | AD6: PaymentDate | AE6: RiskTotal | AF6: Check | AH6: FixingDate | AK6: FixingDate | AL6: RiskTotal | AM6: Check | AO6: FixingDate | AP6: RiskTotal | AR6: ='JACOBIAN - OIS USDOIS'!B15 -> PaymentDate | AS6: ='JACOBIAN - OIS USDOIS'!C15 -> OIS_ON | AT6: ='JACOBIAN - OIS USDOIS'!D15 -> OIS_1W | AU6: ='JACOBIAN - OIS USDOIS'!E15 -> OIS_2W | AV6: ='JACOBIAN - OIS USDOIS'!F15 -> OIS_3W | AW6: ='JACOBIAN - OIS USDOIS'!G15 -> OIS_1M | AX6: ='JACOBIAN - OIS USDOIS'!H15 -> OIS_2M | AY6: ='JACOBIAN - OIS USDOIS'!I15 -> OIS_3M | ... CF6: ='JACOBIAN - OIS USDOIS'!AP15 -> SWAP_30Y | CK6: =AR6 -> PaymentDate | CL6: =AS6 -> OIS_ON | CM6: =AT6 -> OIS_1W | CN6: =AU6 -> OIS_2W | CO6: =AV6 -> OIS_3W | CP6: =AW6 -> OIS_1M | CQ6: =AX6 -> OIS_2M | CR6: =AY6 -> OIS_3M | ... DY6: =CF6 -> SWAP_30Y | EA6: {=TRANSPOSE(CL6:DY6)} -> OIS_ON | EB6: {=TRANSPOSE(AS4:CF4)} -> -0.031913443 | ED6: ='JACOBIAN - SWAP USD3ML'!B15 -> FixingDate | EE6: ='JACOBIAN - SWAP USD3ML'!C15 -> LIBORFIXING_1M | EF6: ='JACOBIAN - SWAP USD3ML'!D15 -> LIBORFIXING_3M | EG6: ='JACOBIAN - SWAP USD3ML'!E15 -> LIBORFIXING_6M | EH6: ='JACOBIAN - SWAP USD3ML'!F15 -> LIBORFIXING_12M | EI6: ='JACOBIAN - SWAP USD3ML'!G15 -> ED1 Comdty | EJ6: ='JACOBIAN - SWAP USD3ML'!H15 -> ED2 Comdty | EK6: ='JACOBIAN - SWAP USD3ML'!I15 -> ED3 Comdty | ... FB6: ='JACOBIAN - SWAP USD3ML'!Z15 -> SWAP_30Y | FD6: {=TRANSPOSE(EE6:FB6)} -> LIBORFIXING_1M | FE6: {=TRANSPOSE(EE4:FB4)} -> 1.4946485e-06 | FF6: Numerical Risk | FH6: USDYC.OIS.OUTRIGHTOISSWAP.ON | FI6: -0.024322464 | FJ6: USDYC.STD.O_N | FK6: 0.00759088 | FL6: #N/A
B7: CurveCollection | C7: =PRICING!O7 -> USDYC | F7: AccrualStart | G7: AccrualEnd | H7: AccrualDays | I7: AccrualYearFractions | J7: PaymentDate | K7: Notional | L7: NotionalExchange | M7: Leverage | N7: FixedRate | O7: Coupon | P7: DiscountFactor | Q7: CouponPV | X7: =AR7 -> 43812 | Y7: 0 | AA7: =CK7 -> 43812 | AB7: =SUM(CL7:DY7) -> 0 | AD7: {=_xll.meCurveResultsJacobianRiskTotals("USDYC","USDOIS","DISCOUNT_FACTORS")} -> 43812 | AE7: 0 | AF7: =ABS(AE7-AB7)<0.0000000000000001 -> TRUE | AH7: =AO7 -> 43812 | AI7: 0 | AK7: {=_xll.meCurveResultsJacobianRiskTotals("USDYC","USD3ML","FORWARD_RATES")} -> 43812 | AL7: 9.9998896e-05 | AM7: =ABS(AP7-AL7)<0.0000000000000001 -> TRUE | AO7: =ED7 -> 43812 | AP7: =SUM(EE7:FB7) -> 9.9998896e-05 | AR7: ='JACOBIAN - OIS USDOIS'!B16 -> 43812 | AS7: ='JACOBIAN - OIS USDOIS'!C16 -> 0 | AT7: ='JACOBIAN - OIS USDOIS'!D16 -> 0 | AU7: ='JACOBIAN - OIS USDOIS'!E16 -> 0 | AV7: ='JACOBIAN - OIS USDOIS'!F16 -> 0 | AW7: ='JACOBIAN - OIS USDOIS'!G16 -> 0 | AX7: ='JACOBIAN - OIS USDOIS'!H16 -> 0 | AY7: ='JACOBIAN - OIS USDOIS'!I16 -> 0 | ... CF7: ='JACOBIAN - OIS USDOIS'!AP16 -> 0 | CK7: =AR7 -> 43812 | CL7: =AS7 -> 0 | CM7: =AT7 -> 0 | CN7: =AU7 -> 0 | CO7: =AV7 -> 0 | CP7: =AW7 -> 0 | CQ7: =AX7 -> 0 | CR7: =AY7 -> 0 | ... DA7: =BH7 -> 0 | DB7: 0 | DC7: 0 | DD7: 0 | DE7: 0 | DF7: 0 | DG7: 0 | DH7: 0 | DI7: 0 | DJ7: 0 | DK7: 0 | DL7: 0 | DM7: 0 | DN7: =BU7 -> 0 | DO7: =BV7 -> 0 | DP7: =BW7 -> 0 | DQ7: =BX7 -> 0 | DR7: =BY7 -> 0 | DS7: =BZ7 -> 0 | DT7: =CA7 -> 0 | DU7: =CB7 -> 0 | ... DY7: =CF7 -> 0 | EA7: OIS_1W | EB7: -6.5722291e-05 | ED7: ='JACOBIAN - SWAP USD3ML'!B16 -> 43812 | EE7: ='JACOBIAN - SWAP USD3ML'!C16 -> 4.416036e-06 | EF7: ='JACOBIAN - SWAP USD3ML'!D16 -> 9.9998269e-05 | EG7: ='JACOBIAN - SWAP USD3ML'!E16 -> 0 | EH7: ='JACOBIAN - SWAP USD3ML'!F16 -> 0 | EI7: ='JACOBIAN - SWAP USD3ML'!G16 -> -4.4154092e-06 | EJ7: ='JACOBIAN - SWAP USD3ML'!H16 -> 0 | EK7: ='JACOBIAN - SWAP USD3ML'!I16 -> 0 | ... FB7: ='JACOBIAN - SWAP USD3ML'!Z16 -> 0 | FD7: LIBORFIXING_3M | FE7: -25.174459 | FF7: 0 | FH7: USDYC.OIS.OUTRIGHTOISSWAP.1W | FI7: 0.0075395685 | FJ7: USDYC.STD.T_N | FK7: 0.0075909251 | FL7: #N/A
F8: 43816 | G8: 43999 | H8: 183 | I8: 0.5 | J8: 43999 | K8: -1000000 | L8: 0 | M8: 1 | N8: 0.01 | O8: -5000 | P8: 0.99214919 | Q8: -4960.7459 | V8: =K8*I8*P8 -> -496074.59 | X8: =AR8 -> 43815 | Y8: 0 | AA8: =CK8 -> 43815 | AB8: =SUM(CL8:DY8) -> -8.331174e-07 | AD8: 43815 | AE8: -8.331174e-07 | AF8: =ABS(AE8-AB8)<0.0000000000000001 -> TRUE | AH8: =AO8 -> 43815 | AI8: 0 | AK8: 43815 | AL8: 9.9999628e-05 | AM8: =ABS(AP8-AL8)<0.0000000000000001 -> TRUE | AO8: =ED8 -> 43815 | AP8: =SUM(EE8:FB8) -> 9.9999628e-05 | AR8: ='JACOBIAN - OIS USDOIS'!B17 -> 43815 | AS8: ='JACOBIAN - OIS USDOIS'!C17 -> -8.331174e-07 | AT8: ='JACOBIAN - OIS USDOIS'!D17 -> 0 | AU8: ='JACOBIAN - OIS USDOIS'!E17 -> 0 | AV8: ='JACOBIAN - OIS USDOIS'!F17 -> 0 | AW8: ='JACOBIAN - OIS USDOIS'!G17 -> 0 | AX8: ='JACOBIAN - OIS USDOIS'!H17 -> 0 | AY8: ='JACOBIAN - OIS USDOIS'!I17 -> 0 | ... CF8: ='JACOBIAN - OIS USDOIS'!AP17 -> 0 | CK8: =AR8 -> 43815 | CL8: =AS8 -> -8.331174e-07 | CM8: =AT8 -> 0 | CN8: =AU8 -> 0 | CO8: =AV8 -> 0 | CP8: =AW8 -> 0 | CQ8: =AX8 -> 0 | CR8: =AY8 -> 0 | ... DA8: =BH8 -> 0 | DB8: 0 | DC8: 0 | DD8: 0 | DE8: 0 | DF8: 0 | DG8: 0 | DH8: 0 | DI8: 0 | DJ8: 0 | DK8: 0 | DL8: 0 | DM8: 0 | DN8: =BU8 -> 0 | DO8: =BV8 -> 0 | DP8: =BW8 -> 0 | DQ8: =BX8 -> 0 | DR8: =BY8 -> 0 | DS8: =BZ8 -> 0 | DT8: =CA8 -> 0 | DU8: =CB8 -> 0 | ... DY8: =CF8 -> 0 | EA8: OIS_2W | EB8: 0.0002628138 | ED8: ='JACOBIAN - SWAP USD3ML'!B17 -> 43815 | EE8: ='JACOBIAN - SWAP USD3ML'!C17 -> 1.1041031e-06 | EF8: ='JACOBIAN - SWAP USD3ML'!D17 -> 9.9999567e-05 | EG8: ='JACOBIAN - SWAP USD3ML'!E17 -> 0 | EH8: ='JACOBIAN - SWAP USD3ML'!F17 -> 0 | EI8: ='JACOBIAN - SWAP USD3ML'!G17 -> -1.1040418e-06 | EJ8: ='JACOBIAN - SWAP USD3ML'!H17 -> 0 | EK8: ='JACOBIAN - SWAP USD3ML'!I17 -> 0 | ... FB8: ='JACOBIAN - SWAP USD3ML'!Z17 -> 0 | FD8: LIBORFIXING_6M | FE8: 2.8845701e-05 | FH8: USDYC.OIS.OUTRIGHTOISSWAP.2W | FI8: 0.0077943951 | FJ8: USDYC.STD.LIBOR.1M | FK8: 0.0075910095 | FL8: #N/A
B9: Swap Calculations | F9: 43999 | G9: 44182 | H9: 183 | I9: 0.5 | J9: 44182 | K9: -1000000 | L9: 0 | M9: 1 | N9: 0.01 | O9: -5000 | P9: 0.98532697 | Q9: -4926.6349 | V9: =K9*I9*P9 -> -492663.49 | X9: =AR9 -> 43816 | Y9: 0 | AA9: =CK9 -> 43816 | AB9: =SUM(CL9:DY9) -> -1.1107992e-06 | AD9: 43816 | AE9: -1.1107992e-06 | AF9: =ABS(AE9-AB9)<0.0000000000000001 -> TRUE | AH9: =AO9 -> 43816 | AI9: 0 | AK9: 43816 | AL9: 0.0001 | AM9: =ABS(AP9-AL9)<0.0000000000000001 -> TRUE | AO9: =ED9 -> 43816 | AP9: =SUM(EE9:FB9) -> 0.0001 | AR9: ='JACOBIAN - OIS USDOIS'!B18 -> 43816 | AS9: ='JACOBIAN - OIS USDOIS'!C18 -> -1.1107992e-06 | AT9: ='JACOBIAN - OIS USDOIS'!D18 -> 0 | AU9: ='JACOBIAN - OIS USDOIS'!E18 -> 0 | AV9: ='JACOBIAN - OIS USDOIS'!F18 -> 0 | AW9: ='JACOBIAN - OIS USDOIS'!G18 -> 0 | AX9: ='JACOBIAN - OIS USDOIS'!H18 -> 0 | AY9: ='JACOBIAN - OIS USDOIS'!I18 -> 0 | ... CF9: ='JACOBIAN - OIS USDOIS'!AP18 -> 0 | CK9: =AR9 -> 43816 | CL9: =AS9 -> -1.1107992e-06 | CM9: =AT9 -> 0 | CN9: =AU9 -> 0 | CO9: =AV9 -> 0 | CP9: =AW9 -> 0 | CQ9: =AX9 -> 0 | CR9: =AY9 -> 0 | ... DA9: =BH9 -> 0 | DB9: 0 | DC9: 0 | DD9: 0 | DE9: 0 | DF9: 0 | DG9: 0 | DH9: 0 | DI9: 0 | DJ9: 0 | DK9: 0 | DL9: 0 | DM9: 0 | DN9: =BU9 -> 0 | DO9: =BV9 -> 0 | DP9: =BW9 -> 0 | DQ9: =BX9 -> 0 | DR9: =BY9 -> 0 | DS9: =BZ9 -> 0 | DT9: =CA9 -> 0 | DU9: =CB9 -> 0 | ... DY9: =CF9 -> 0 | EA9: OIS_3W | EB9: -0.00069229569 | ED9: ='JACOBIAN - SWAP USD3ML'!B18 -> 43816 | EE9: ='JACOBIAN - SWAP USD3ML'!C18 -> 0 | EF9: ='JACOBIAN - SWAP USD3ML'!D18 -> 0.0001 | EG9: ='JACOBIAN - SWAP USD3ML'!E18 -> 0 | EH9: ='JACOBIAN - SWAP USD3ML'!F18 -> 0 | EI9: ='JACOBIAN - SWAP USD3ML'!G18 -> 0 | EJ9: ='JACOBIAN - SWAP USD3ML'!H18 -> 0 | EK9: ='JACOBIAN - SWAP USD3ML'!I18 -> 0 | ... FB9: ='JACOBIAN - SWAP USD3ML'!Z18 -> 0 | FD9: LIBORFIXING_12M | FE9: 1.4923469e-06 | FF9: Numerical Risk | FH9: USDYC.OIS.OUTRIGHTOISSWAP.3W | FI9: 0.0070533562 | FJ9: USDYC.STD.LIBOR.3M | FK9: 0.0075824195 | FL9: #N/A
B10: PV | C10: =_xll.meLWOSwapPV(C6,C7) -> 28725.216 | F10: 44182 | G10: 44364 | H10: 182 | I10: 0.5 | J10: 44364 | K10: -1000000 | L10: 0 | M10: 1 | N10: 0.01 | O10: -5000 | P10: 0.97912715 | Q10: -4895.6357 | V10: =K10*I10*P10 -> -489563.57 | X10: =AR10 -> 43823 | Y10: 0 | AA10: =CK10 -> 43823 | AB10: =SUM(CL10:DY10) -> -3.0534078e-06 | AD10: 43823 | AE10: -3.0534078e-06 | AF10: =ABS(AE10-AB10)<0.0000000000000001 -> TRUE | AH10: =AO10 -> 43817 | AI10: =V20 -> 251744.85 | AK10: 43817 | AL10: 0.0001 | AM10: =ABS(AP10-AL10)<0.0000000000000001 -> TRUE | AO10: =ED10 -> 43817 | AP10: =SUM(EE10:FB10) -> 0.0001 | AR10: ='JACOBIAN - OIS USDOIS'!B19 -> 43823 | AS10: ='JACOBIAN - OIS USDOIS'!C19 -> -1.1104665e-06 | AT10: ='JACOBIAN - OIS USDOIS'!D19 -> -1.9429413e-06 | AU10: ='JACOBIAN - OIS USDOIS'!E19 -> 0 | AV10: ='JACOBIAN - OIS USDOIS'!F19 -> 0 | AW10: ='JACOBIAN - OIS USDOIS'!G19 -> 0 | AX10: ='JACOBIAN - OIS USDOIS'!H19 -> 0 | AY10: ='JACOBIAN - OIS USDOIS'!I19 -> 0 | ... CF10: ='JACOBIAN - OIS USDOIS'!AP19 -> 0 | CK10: =AR10 -> 43823 | CL10: =AS10 -> -1.1104665e-06 | CM10: =AT10 -> -1.9429413e-06 | CN10: =AU10 -> 0 | CO10: =AV10 -> 0 | CP10: =AW10 -> 0 | CQ10: =AX10 -> 0 | CR10: =AY10 -> 0 | ... DA10: =BH10 -> 0 | DB10: 0 | DC10: 0 | DD10: 0 | DE10: 0 | DF10: 0 | DG10: 0 | DH10: 0 | DI10: 0 | DJ10: 0 | DK10: 0 | DL10: 0 | DM10: 0 | DN10: =BU10 -> 0 | DO10: =BV10 -> 0 | DP10: =BW10 -> 0 | DQ10: =BX10 -> 0 | DR10: =BY10 -> 0 | DS10: =BZ10 -> 0 | DT10: =CA10 -> 0 | DU10: =CB10 -> 0 | ... DY10: =CF10 -> 0 | EA10: OIS_1M | EB10: 0.00089110526 | ED10: ='JACOBIAN - SWAP USD3ML'!B19 -> 43817 | EE10: ='JACOBIAN - SWAP USD3ML'!C19 -> 0 | EF10: ='JACOBIAN - SWAP USD3ML'!D19 -> 0 | EG10: ='JACOBIAN - SWAP USD3ML'!E19 -> 0 | EH10: ='JACOBIAN - SWAP USD3ML'!F19 -> 0 | EI10: ='JACOBIAN - SWAP USD3ML'!G19 -> 0.0001 | EJ10: ='JACOBIAN - SWAP USD3ML'!H19 -> 0 | EK10: ='JACOBIAN - SWAP USD3ML'!I19 -> 0 | ... FB10: ='JACOBIAN - SWAP USD3ML'!Z19 -> 0 | FD10: ED1 Comdty | FE10: 24.89905 | FF10: 0 | FH10: USDYC.OIS.OUTRIGHTOISSWAP.1M | FI10: 0.0082824692 | FJ10: USDYC.STD.LIBOR.6M | FK10: 0.0075996097 | FL10: #N/A
B11: Annuity | C11: =_xll.meLWOSwapAnnuity(C6,C7,"Leg1:Fixed") -> 4816434.7 | F11: 44364 | G11: 44547 | H11: 183 | I11: 0.5 | J11: 44547 | K11: -1000000 | L11: 0 | M11: 1 | N11: 0.01 | O11: -5000 | P11: 0.9729382 | Q11: -4864.691 | V11: =K11*I11*P11 -> -486469.1 | X11: =AR11 -> 43830 | Y11: 0 | AA11: =CK11 -> 43830 | AB11: =SUM(CL11:DY11) -> -4.9936371e-06 | AD11: 43830 | AE11: -4.9936371e-06 | AF11: =ABS(AE11-AB11)<0.0000000000000001 -> TRUE | AH11: =AO11 -> 43907 | AI11: 0 | AK11: 43907 | AL11: 0.00010000439 | AM11: =ABS(AP11-AL11)<0.0000000000000001 -> TRUE | AO11: =ED11 -> 43907 | AP11: =SUM(EE11:FB11) -> 0.00010000439 | AR11: ='JACOBIAN - OIS USDOIS'!B20 -> 43830 | AS11: ='JACOBIAN - OIS USDOIS'!C20 -> -1.1101283e-06 | AT11: ='JACOBIAN - OIS USDOIS'!D20 -> 0 | AU11: ='JACOBIAN - OIS USDOIS'!E20 -> -3.8835088e-06 | AV11: ='JACOBIAN - OIS USDOIS'!F20 -> 1.110223e-15 | AW11: ='JACOBIAN - OIS USDOIS'!G20 -> 1.110223e-15 | AX11: ='JACOBIAN - OIS USDOIS'!H20 -> 1.110223e-15 | AY11: ='JACOBIAN - OIS USDOIS'!I20 -> 1.110223e-15 | ... CF11: ='JACOBIAN - OIS USDOIS'!AP20 -> 1.110223e-15 | CK11: =AR11 -> 43830 | CL11: =AS11 -> -1.1101283e-06 | CM11: =AT11 -> 0 | CN11: =AU11 -> -3.8835088e-06 | CO11: =AV11 -> 1.110223e-15 | CP11: =AW11 -> 1.110223e-15 | CQ11: =AX11 -> 1.110223e-15 | CR11: =AY11 -> 1.110223e-15 | ... DA11: =BH11 -> 1.110223e-15 | DB11: 0 | DC11: 0 | DD11: 0 | DE11: 0 | DF11: 0 | DG11: 0 | DH11: 0 | DI11: 0 | DJ11: 0 | DK11: 0 | DL11: 0 | DM11: 0 | DN11: =BU11 -> 1.110223e-15 | DO11: =BV11 -> 1.110223e-15 | DP11: =BW11 -> 1.110223e-15 | DQ11: =BX11 -> 1.110223e-15 | DR11: =BY11 -> 1.110223e-15 | DS11: =BZ11 -> 1.110223e-15 | DT11: =CA11 -> 1.110223e-15 | DU11: =CB11 -> 1.110223e-15 | ... DY11: =CF11 -> 1.110223e-15 | EA11: OIS_2M | EB11: -0.0020152631 | ED11: ='JACOBIAN - SWAP USD3ML'!B20 -> 43907 | EE11: ='JACOBIAN - SWAP USD3ML'!C20 -> -8.7083118e-16 | EF11: ='JACOBIAN - SWAP USD3ML'!D20 -> -1.6899091e-10 | EG11: ='JACOBIAN - SWAP USD3ML'!E20 -> 0 | EH11: ='JACOBIAN - SWAP USD3ML'!F20 -> 0 | EI11: ='JACOBIAN - SWAP USD3ML'!G20 -> 1.0863215e-06 | EJ11: ='JACOBIAN - SWAP USD3ML'!H20 -> 9.8918238e-05 | EK11: ='JACOBIAN - SWAP USD3ML'!I20 -> 0 | ... FB11: ='JACOBIAN - SWAP USD3ML'!Z20 -> 0 | FD11: ED2 Comdty | FE11: -0.00021360723 | FH11: USDYC.OIS.OUTRIGHTOISSWAP.2M | FI11: 0.0060264349 | FJ11: USDYC.STD.LIBOR.12M | FK11: 0.0075909469 | FL11: #N/A
B12: PV01 | C12: =_xll.meLWOSwapPV01(C6,C7) -> 481.64347 | F12: 44547 | G12: 44729 | H12: 182 | I12: 0.5 | J12: 44729 | K12: -1000000 | L12: 0 | M12: 1 | N12: 0.01 | O12: -5000 | P12: 0.96672676 | Q12: -4833.6338 | V12: =K12*I12*P12 -> -483363.38 | X12: =AR12 -> 43837 | Y12: 0 | AA12: =CK12 -> 43837 | AB12: =SUM(CL12:DY12) -> -6.9314318e-06 | AD12: 43837 | AE12: -6.9314318e-06 | AF12: =ABS(AE12-AB12)<0.0000000000000001 -> TRUE | AH12: =AO12 -> 43908 | AI12: =V21 -> 253549.24 | AK12: 43908 | AL12: 0.00010000034 | AM12: =ABS(AP12-AL12)<0.0000000000000001 -> TRUE | AO12: =ED12 -> 43908 | AP12: =SUM(EE12:FB12) -> 0.00010000034 | AR12: ='JACOBIAN - OIS USDOIS'!B21 -> 43837 | AS12: ='JACOBIAN - OIS USDOIS'!C21 -> -1.1097848e-06 | AT12: ='JACOBIAN - OIS USDOIS'!D21 -> 0 | AU12: ='JACOBIAN - OIS USDOIS'!E21 -> 0 | AV12: ='JACOBIAN - OIS USDOIS'!F21 -> -5.821647e-06 | AW12: ='JACOBIAN - OIS USDOIS'!G21 -> 0 | AX12: ='JACOBIAN - OIS USDOIS'!H21 -> 0 | AY12: ='JACOBIAN - OIS USDOIS'!I21 -> 0 | ... CF12: ='JACOBIAN - OIS USDOIS'!AP21 -> 0 | CK12: =AR12 -> 43837 | CL12: =AS12 -> -1.1097848e-06 | CM12: =AT12 -> 0 | CN12: =AU12 -> 0 | CO12: =AV12 -> -5.821647e-06 | CP12: =AW12 -> 0 | CQ12: =AX12 -> 0 | CR12: =AY12 -> 0 | ... DA12: =BH12 -> 0 | DB12: 0 | DC12: 0 | DD12: 0 | DE12: 0 | DF12: 0 | DG12: 0 | DH12: 0 | DI12: 0 | DJ12: 0 | DK12: 0 | DL12: 0 | DM12: 0 | DN12: =BU12 -> 0 | DO12: =BV12 -> 0 | DP12: =BW12 -> 0 | DQ12: =BX12 -> 0 | DR12: =BY12 -> 0 | DS12: =BZ12 -> 0 | DT12: =CA12 -> 0 | DU12: =CB12 -> 0 | ... DY12: =CF12 -> 0 | EA12: OIS_3M | EB12: -0.11351084 | ED12: ='JACOBIAN - SWAP USD3ML'!B21 -> 43908 | EE12: ='JACOBIAN - SWAP USD3ML'!C21 -> 8.6736174e-16 | EF12: ='JACOBIAN - SWAP USD3ML'!D21 -> 8.6736174e-16 | EG12: ='JACOBIAN - SWAP USD3ML'!E21 -> 0 | EH12: ='JACOBIAN - SWAP USD3ML'!F21 -> 0 | EI12: ='JACOBIAN - SWAP USD3ML'!G21 -> 8.6736174e-16 | EJ12: ='JACOBIAN - SWAP USD3ML'!H21 -> 9.8917452e-05 | EK12: ='JACOBIAN - SWAP USD3ML'!I21 -> 1.0828838e-06 | ... FB12: ='JACOBIAN - SWAP USD3ML'!Z21 -> 0 | FD12: ED3 Comdty | FE12: 0.27457112 | FH12: USDYC.OIS.OUTRIGHTOISSWAP.3M | FI12: 0.012500594 | FJ12: USDYC.STD.FUTURE.ED1 COMDTY.20191218.20200318 | FK12: 0.0075908232 | FL12: #N/A
