Workbook
Name AsOfDate: 'EUR OIS'!$D$9
Name doesExistEUR12M: 'EUR SWAP 12M'!$D$32
Name doesExistEUR1M: 'EUR SWAP 1M'!$D$32
Name doesExistEUR3M: 'EUR SWAP 3M'!$D$32
Name doesExistEUR6M: 'EUR SWAP 6M'!$D$32
Name doesExistEUROIS: 'EUR OIS'!$D$32
Name EURSwaps.Results.EUR12ML: SWAPS!$T$69:$T$82
Name EURSwaps.Results.EUR1ML: SWAPS!$T$48:$T$62
Name EURSwaps.Results.EUR3ML: SWAPS!$T$26:$T$42
Name EURSwaps.Results.EUR6ML: SWAPS!$T$6:$T$20
Name Template.Swap.EUR.12M: 'SWAP TEMPLATES'!$N$3
Name Template.Swap.EUR.1M: 'SWAP TEMPLATES'!$J$3
Name Template.Swap.EUR.3M: 'SWAP TEMPLATES'!$B$3
Name Template.Swap.EUR.6M: 'SWAP TEMPLATES'!$F$3
Name Templates.EUR.12M: 'CURVE TEMPLATES'!$R$3
Name Templates.EUR.1M: 'CURVE TEMPLATES'!$N$3
Name Templates.EUR.3M: 'CURVE TEMPLATES'!$F$3
Name Templates.EUR.6M: 'CURVE TEMPLATES'!$J$3
Name Templates.EUR.OIS: 'CURVE TEMPLATES'!$B$3

Sheet CURVE TEMPLATES
B2: EUR_OIS | F2: EUR_SWAP_3M | J2: EUR_SWAP_6M | N2: EUR_SWAP_1M | R2: EUR_SWAP_12M
B3: =_xll.meLWOCurveGeneratorCreate(B2,B6,B7:C13,B15,B16:C32,B34,B35:C38,B40,B41:C44) -> EUR_OIS:1 | F3: =_xll.meLWOCurveGeneratorCreate(F2,F6,F7:G20,F22,F23:G25,F27,F28:G32,F34,F35:G40,F42,F43:G49,F51,F52:G65) -> EUR_SWAP_3M:1 | J3: =_xll.meLWOCurveGeneratorCreate(J2,J6,J7:K20,J22,J23:K25,J27,J28:K32,J34,J35:K40,J42,J43:K43,J45,J46:K59) -> EUR_SWAP_6M:1 | N3: =_xll.meLWOCurveGeneratorCreate(N2,N6,N7:O20,N22,N23:O25,N27,N28:O32,N34,N35:O40,N42,N43:O49,N51,N52:O65) -> EUR_SWAP_1M:1 | R3: =_xll.meLWOCurveGeneratorCreate(R2,R6,R7:S20,R22,R23:S25,R27,R28:S32,R34,R35:S40,R42,R43:S49,R51,R52:S65) -> EUR_SWAP_12M:1
B6: CURVEPROPERTIES | F6: CURVEPROPERTIES | J6: CURVEPROPERTIES | N6: CURVEPROPERTIES | R6: CURVEPROPERTIES
B7: CurveType | C7: OIS | F7: CurveType | G7: SWAP | J7: CurveType | K7: SWAP | N7: CurveType | O7: SWAP | R7: CurveType | S7: SWAP
B8: CurveIndexFrequency | C8: DAILY | F8: CurveIndexFrequency | G8: QUARTERLY | J8: CurveIndexFrequency | K8: SEMI-ANNUAL | N8: CurveIndexFrequency | O8: MONTHLY | R8: CurveIndexFrequency | S8: ANNUAL
B9: StaticDataTable | C9: OIS | F9: StaticDataTable | G9: STD | J9: StaticDataTable | K9: EUR6ML | N9: StaticDataTable | O9: EUR1ML | R9: StaticDataTable | S9: EUR12ML
B10: IndexName | C10: OIS:EUROIS:EURDF:EURDF_EURCSA:EURDF_NOCSA | F10: IndexName | G10: STD:EUR3ML | J10: IndexName | K10: EUR6ML | N10: IndexName | O10: EUR1ML | R10: IndexName | S10: EUR12ML
B11: Currency | C11: EUR | F11: Currency | G11: EUR | J11: Currency | K11: EUR | N11: Currency | O11: EUR | R11: Currency | S11: EUR
B12: interpolation | C12: FN_SPLINEINTERPOLATION | F12: interpolation | G12: FN_LINEARSPLINEINTERPOLATION | J12: interpolation | K12: fn_LinearSplineInterpolation | N12: interpolation | O12: FN_LINEARSPLINEINTERPOLATION | R12: interpolation | S12: FN_LINEARSPLINEINTERPOLATION
B13: yieldgen.interpolation | C13: FN_SPLINEINTERPOLATION | F13: yieldgen.interpolation | G13: FN_LINEARSPLINEINTERPOLATION | J13: yieldgen.interpolation | K13: fn_LinearSplineInterpolation | N13: yieldgen.interpolation | O13: FN_LINEARSPLINEINTERPOLATION | R13: yieldgen.interpolation | S13: FN_LINEARSPLINEINTERPOLATION
F14: isfrause | G14: FALSE | J14: future.interpolation | K14: fn_LinearSplineInterpolation | N14: isfrause | O14: FALSE | R14: isfrause | S14: FALSE
B15: OIS | F15: isfutureuse | G15: TRUE | J15: isfrause | K15: TRUE | N15: isfutureuse | O15: FALSE | R15: isfutureuse | S15: FALSE
B16: calendar | C16: TGT | F16: future.interpolation | G16: FN_LINEARSPLINEINTERPOLATION | J16: isfutureuse | K16: FALSE | N16: future.interpolation | O16: FN_LINEARSPLINEINTERPOLATION | R16: future.interpolation | S16: FN_LINEARSPLINEINTERPOLATION
B17: daycount | C17: ACT/360 | F17: dfcurvename | G17: OIS | J17: Frequency | K17: SIMPLE | N17: dfcurvename | O17: OIS | R17: dfcurvename | S17: OIS
B18: frequency | C18: ANNUAL | F18: Frequency | G18: SIMPLE | J18: dfcurvename | K18: OIS | N18: Frequency | O18: SIMPLE | R18: Frequency | S18: SIMPLE
B19: generatemethod | C19: DAILYCOMPOUNDING | F19: AlwaysCalcJoinDate | G19: TRUE | J19: AlwaysCalcJoinDate | K19: TRUE | N19: AlwaysCalcJoinDate | O19: TRUE | R19: AlwaysCalcJoinDate | S19: TRUE
B20: resetlag | C20: 2D | F20: FastRebuild | G20: TRUE | J20: FastRebuild | K20: TRUE | N20: FastRebuild | O20: TRUE | R20: FastRebuild | S20: TRUE
B21: firstrate | C21: SHORTMARKET
B22: slidingrule | C22: MOD_FOLLOWING | F22: MONEYMARKET | J22: MONEYMARKET | N22: MONEYMARKET | R22: MONEYMARKET
B23: eomday | C23: 31 | F23: Calendar | G23: TGT | J23: Calendar | K23: TGT | N23: Calendar | O23: TGT | R23: Calendar | S23: TGT
B24: iseomroll | C24: TRUE | F24: DayCount | G24: ACT/360 | J24: DayCount | K24: ACT/360 | N24: DayCount | O24: ACT/360 | R24: DayCount | S24: ACT/360
B25: shorttermconvention | C25: ARITHMETICAVERAGE | F25: Slidingrule | G25: FOLLOWING | J25: Slidingrule | K25: FOLLOWING | N25: Slidingrule | O25: FOLLOWING | R25: Slidingrule | S25: FOLLOWING
B26: longtermconvention | C26: LOBASIS
B27: longterm | C27: 3Y | F27: LIBORFIXINGS | J27: LIBORFIXINGS | N27: LIBORFIXINGS | R27: LIBORFIXINGS
B28: longterm.generatemethod | C28: NONE | F28: Calendar | G28: TGT | J28: Calendar | K28: TGT | N28: Calendar | O28: TGT | R28: Calendar | S28: TGT
B29: Epsilon | C29: 1e-10 | F29: Daycount | G29: ACT/360 | J29: Daycount | K29: ACT/360 | N29: Daycount | O29: ACT/360 | R29: Daycount | S29: ACT/360
B30: MaxLoop | C30: 1000 | F30: Frequency | G30: Simple | J30: Frequency | K30: Simple | N30: Frequency | O30: Simple | R30: Frequency | S30: Simple
B31: CompoundingMethod | C31: GEOMETRIC | F31: Resetlag | G31: 2 | J31: Resetlag | K31: 2 | N31: Resetlag | O31: 2 | R31: Resetlag | S31: 2
B32: SmoothShortEnd | C32: TRUE | F32: SlidingRule | G32: MOD_FOLLOWING | J32: SlidingRule | K32: MOD_FOLLOWING | N32: SlidingRule | O32: MOD_FOLLOWING | R32: SlidingRule | S32: MOD_FOLLOWING
B34: LIBOROISBASIS | D34: OIS FLOAT LEG CONVENTIONS | F34: FRAS | J34: FRAS | N34: FRAS | R34: FRAS
B35: Calendar | C35: TGT | F35: Calendar | G35: TGT | J35: Calendar | K35: TGT | N35: Calendar | O35: TGT | R35: Calendar | S35: TGT
B36: Daycount | C36: ACT/360 | F36: DayCount | G36: ACT/360 | J36: DayCount | K36: ACT/360 | N36: DayCount | O36: ACT/360 | R36: DayCount | S36: ACT/360
B37: Frequency | C37: QUARTERLY | F37: ResetLag | G37: 2 | J37: ResetLag | K37: 2 | N37: ResetLag | O37: 2 | R37: ResetLag | S37: 2
B38: SlidingRule | C38: MOD_FOLLOWING | F38: SlidingRule | G38: MOD_FOLLOWING | J38: SlidingRule | K38: MOD_FOLLOWING | N38: SlidingRule | O38: MOD_FOLLOWING | R38: SlidingRule | S38: MOD_FOLLOWING
F39: ApplyTension | G39: TRUE | J39: ApplyTension | K39: TRUE | N39: ApplyTension | O39: TRUE | R39: ApplyTension | S39: TRUE
B40: SWAPS | D40: LIBOR SWAP CONVENTIONS - FIXED LEG | F40: TensionGap | G40: 2 | J40: TensionGap | K40: 2 | N40: TensionGap | O40: 2 | R40: TensionGap | S40: 2
B41: calendar | C41: TGT
B42: daycountfix | C42: 30/360 | F42: FUTURES | J42: FUTURES | N42: FUTURES | R42: FUTURES
B43: frequencyfix | C43: ANNUAL | F43: calendar | G43: TGT | J43: calendar | K43: TGT | N43: calendar | O43: TGT | R43: calendar | S43: TGT
B44: slidingrule | C44: MOD_FOLLOWING | F44: daycount | G44: ACT/360 | N44: daycount | O44: ACT/360 | R44: daycount | S44: ACT/360
...

Sheet SWAP TEMPLATES
B2: EUR_SWAP_3ML | F2: EUR_SWAP_6ML | J2: EUR_SWAP_1ML | N2: EUR_SWAP_12ML
B3: =_xll.meLWOSwapGeneratorCreate(B2,B6:D31) -> EUR_SWAP_3ML:1 | F3: =_xll.meLWOSwapGeneratorCreate(F2,F6:H31) -> EUR_SWAP_6ML:1 | J3: =_xll.meLWOSwapGeneratorCreate(J2,J6:L31) -> EUR_SWAP_1ML:1 | N3: =_xll.meLWOSwapGeneratorCreate(N2,N6:P31) -> EUR_SWAP_12ML:1
B6: LEGTYPE | C6: Leg1:Fixed | D6: Leg2:Float | F6: LEGTYPE | G6: Leg1:Fixed | H6: Leg2:Float | J6: LEGTYPE | K6: Leg1:Fixed | L6: Leg2:Float | N6: LEGTYPE | O6: Leg1:Fixed | P6: Leg2:Float
B7: LEVERAGE | C7: 1 | D7: 1 | F7: LEVERAGE | G7: 1 | H7: 1 | J7: LEVERAGE | K7: 1 | L7: 1 | N7: LEVERAGE | O7: 1 | P7: 1
B8: FORECASTCURVE | D8: EUR3ML | F8: FORECASTCURVE | H8: EUR6ML | J8: FORECASTCURVE | L8: EUR1ML | N8: FORECASTCURVE | P8: EUR12ML
B9: COMPOUNDMETHOD | C9: NONE | D9: NONE | F9: COMPOUNDMETHOD | G9: NONE | H9: GEOMETRIC | J9: COMPOUNDMETHOD | K9: NONE | L9: NONE | N9: COMPOUNDMETHOD | O9: NONE | P9: NONE
B10: NOTIONALEXCHANGE | C10: NONE | D10: NONE | F10: NOTIONALEXCHANGE | G10: NONE | H10: NONE | J10: NOTIONALEXCHANGE | K10: NONE | L10: NONE | N10: NOTIONALEXCHANGE | O10: NONE | P10: NONE
B11: DISCOUNTCURVE | C11: EUROIS | D11: EUROIS | F11: DISCOUNTCURVE | G11: EUROIS | H11: EUROIS | J11: DISCOUNTCURVE | K11: EUROIS | L11: EUROIS | N11: DISCOUNTCURVE | O11: EUROIS | P11: EUROIS
B12: VALUATIONCURRENCY | C12: EUR | D12: EUR | F12: VALUATIONCURRENCY | G12: EUR | H12: EUR | J12: VALUATIONCURRENCY | K12: EUR | L12: EUR | N12: VALUATIONCURRENCY | O12: EUR | P12: EUR
B13: CURRENCY | C13: EUR | D13: EUR | F13: CURRENCY | G13: EUR | H13: EUR | J13: CURRENCY | K13: EUR | L13: EUR | N13: CURRENCY | O13: EUR | P13: EUR
B14: ACCRUALFREQUENCY | C14: Annual | D14: Quarterly | F14: ACCRUALFREQUENCY | G14: Annual | H14: Semi-Annual | J14: ACCRUALFREQUENCY | K14: Annual | L14: MONTHLY | N14: ACCRUALFREQUENCY | O14: Annual | P14: ANNUAL
B15: ACCRUALBUSINESSDAYADJUSTMENT | C15: MOD_FOLLOWING | D15: MOD_FOLLOWING | F15: ACCRUALBUSINESSDAYADJUSTMENT | G15: MOD_FOLLOWING | H15: MOD_FOLLOWING | J15: ACCRUALBUSINESSDAYADJUSTMENT | K15: MOD_FOLLOWING | L15: MOD_FOLLOWING | N15: ACCRUALBUSINESSDAYADJUSTMENT | O15: MOD_FOLLOWING | P15: MOD_FOLLOWING
B16: ACCRUALCALENDAR | C16: TGT | D16: TGT | F16: ACCRUALCALENDAR | G16: TGT | H16: TGT | J16: ACCRUALCALENDAR | K16: TGT | L16: TGT | N16: ACCRUALCALENDAR | O16: TGT | P16: TGT
B17: ACCRUALDAYCOUNT | C17: 30/360 | D17: ACT/360 | F17: ACCRUALDAYCOUNT | G17: 30/360 | H17: ACT/360 | J17: ACCRUALDAYCOUNT | K17: 30/360 | L17: ACT/360 | N17: ACCRUALDAYCOUNT | O17: 30/360 | P17: ACT/360
B18: PAYMENTFREQUENCY | F18: PAYMENTFREQUENCY | J18: PAYMENTFREQUENCY | N18: PAYMENTFREQUENCY
B19: PAYMENTBUSINESSDAYADJUSTMENT | C19: MOD_FOLLOWING | D19: MOD_FOLLOWING | F19: PAYMENTBUSINESSDAYADJUSTMENT | G19: MOD_FOLLOWING | H19: MOD_FOLLOWING | J19: PAYMENTBUSINESSDAYADJUSTMENT | K19: MOD_FOLLOWING | L19: MOD_FOLLOWING | N19: PAYMENTBUSINESSDAYADJUSTMENT | O19: MOD_FOLLOWING | P19: MOD_FOLLOWING
B20: PAYMENTCALENDAR | C20: TGT | D20: TGT | F20: PAYMENTCALENDAR | G20: TGT | H20: TGT | J20: PAYMENTCALENDAR | K20: TGT | L20: TGT | N20: PAYMENTCALENDAR | O20: TGT | P20: TGT
B21: PAYMENTLAG | C21: 0D | D21: 0D | F21: PAYMENTLAG | G21: 0D | H21: 0D | J21: PAYMENTLAG | K21: 0D | L21: 0D | N21: PAYMENTLAG | O21: 0D | P21: 0D
B22: FIRSTSTUBDATE | F22: FIRSTSTUBDATE | J22: FIRSTSTUBDATE | N22: FIRSTSTUBDATE
B23: LASTSTUBDATE | F23: LASTSTUBDATE | J23: LASTSTUBDATE | N23: LASTSTUBDATE
B24: ROLLDAY | C24: NORMAL | D24: NORMAL | F24: ROLLDAY | G24: NORMAL | H24: NORMAL | J24: ROLLDAY | K24: NORMAL | L24: NORMAL | N24: ROLLDAY | O24: NORMAL | P24: NORMAL
B25: STUBTYPE | C25: ShortStart | D25: ShortStart | F25: STUBTYPE | G25: ShortStart | H25: ShortStart | J25: STUBTYPE | K25: ShortStart | L25: ShortStart | N25: STUBTYPE | O25: ShortStart | P25: ShortStart
B26: FIXINGBUSINESSDAYADJUSTMENT | D26: MOD_FOLLOWING | F26: FIXINGBUSINESSDAYADJUSTMENT | H26: MOD_FOLLOWING | J26: FIXINGBUSINESSDAYADJUSTMENT | L26: MOD_FOLLOWING | N26: FIXINGBUSINESSDAYADJUSTMENT | P26: MOD_FOLLOWING
B27: FIXINGCALENDAR | D27: TGT | F27: FIXINGCALENDAR | H27: TGT | J27: FIXINGCALENDAR | L27: TGT | N27: FIXINGCALENDAR | P27: TGT
B28: FIXINGLAG | D28: 0D | F28: FIXINGLAG | H28: 0D | J28: FIXINGLAG | L28: 0D | N28: FIXINGLAG | P28: 0D
B29: FIXINGADVANCEORARREAR | F29: FIXINGADVANCEORARREAR | J29: FIXINGADVANCEORARREAR | N29: FIXINGADVANCEORARREAR
B30: FIRSTSTUBCURVEINDEX | D30: NATURAL | F30: FIRSTSTUBCURVEINDEX | H30: NATURAL | J30: FIRSTSTUBCURVEINDEX | L30: NATURAL | N30: FIRSTSTUBCURVEINDEX | P30: NATURAL
B31: LASTSTUBCURVEINDEX | D31: NATURAL | F31: LASTSTUBCURVEINDEX | H31: NATURAL | J31: LASTSTUBCURVEINDEX | L31: NATURAL | N31: LASTSTUBCURVEINDEX | P31: NATURAL

Sheet EUR OIS
C4: MARKETDATAPROPERTIES | F4: OIS | L4: LIBOROISBASISSPREADS | O4: SWAPS
F5: Term | G5: Rate | H5: StartDate | I5: EndDate | J5: Use | L5: Term | M5: Rate | O5: Term | P5: Rate
C6: Currency | D6: EUR | F6: ON | G6: -0.00458 | J6: TRUE | L6: 1Y | M6: 0.00091 | O6: 1Y | P6: -0.00399
C7: CurveType | D7: OIS | F7: ECB1 | G7: -0.00464 | H7: 44034 | I7: 44089 | J7: TRUE | L7: 2Y | M7: 0.00089 | O7: 2Y | P7: -0.00402
C8: CurveIndexFrequency | D8: DAILY | F8: ECB2 | G8: -0.00475 | H8: 44090 | I8: 44138 | J8: TRUE | L8: 3Y | M8: 0.00092 | O8: 3Y | P8: -0.00385
C9: AsOfDate | D9: =TODAY() -> 43987 | F9: ECB3 | G9: -0.00484 | H9: 44139 | I9: 44180 | J9: TRUE | L9: 4Y | M9: 0.00093 | O9: 4Y | P9: -0.00356
F10: ECB4 | G10: -0.00488 | H10: 44181 | I10: 44222 | J10: TRUE | L10: 5Y | M10: 0.00095 | O10: 5Y | P10: -0.0032
L11: 6Y | M11: 0.00096 | O11: 6Y | P11: -0.00278
C12: Create Market Data Handle | L12: 7Y | M12: 0.00097 | O12: 7Y | P12: -0.00232
C13: Handle Name | D13: EUR_OIS_CURVE_MARKETDATA | L13: 8Y | M13: 0.00098 | O13: 8Y | P13: -0.00185
C14: Market Data Handle | D14: =_xll.meLWOCurveMarketDataCreate(D13,C4,C6:D9,F4,F6:J31,L4,L6:M31,O4,O6:P31) -> EUR_OIS_CURVE_MARKETDATA:0 | L14: 9Y | M14: 0.00099 | O14: 9Y | P14: -0.00135
L15: 10Y | M15: 0.00099 | O15: 10Y | P15: -0.00087
L16: 11Y | M16: 0.00099 | O16: 11Y | P16: -0.00042
L17: 12Y | M17: 0.00099 | O17: 12Y | P17: 3e-05
L18: 15Y | M18: 0.00098 | O18: 15Y | P18: 0.00112
L19: 20Y | M19: 0.00097 | O19: 20Y | P19: 0.00199
C20: Curve Dictionary | L20: 25Y | M20: 0.00096 | O20: 25Y | P20: 0.00207
C21: Handle Name | D21: EUR_OIS_CURVE | L21: 30Y | M21: 0.00095 | O21: 30Y | P21: 0.00183
C22: Curve Generator | D22: =Templates.EUR.OIS -> EUR_OIS:1 | L22: 31Y | M22: 0.00095 | O22: 31Y | P22: 0.00183
C23: Domestic Curve Collection | D23: EURYC
C24: Foreign Curve Collection
C27: Curve Build
C28: Handle Name | D28: {=_xll.meLWOCurveCalibrate(D21,D22,D14,D23,D24)} -> EUR_OIS_CURVE:0
C29: Curve Collection | D29: EURYC
C30: Curve Index | D30: OIS:EUROIS:EURDF:EURDF_EURCSA:EURDF_NOCSA
C31: Calibration Time Taken | D31: 0.01700 sec
C32: Curve Loaded | D32: =_xll.meLWOExists(D28,"Curve") -> TRUE

Sheet EUR SWAP 3M
C4: MARKETDATAPROPERTIES | F4: LIBORFIXINGS | I4: FUTURES | O4: SWAPS
C5: Currency | D5: EUR | F5: Term | G5: Rate | I5: Term | J5: StartDate | K5: EndDate | L5: Rate | M5: Volatility | O5: Term | P5: Rate | Q5: Use
C6: CurveType | D6: SWAP | F6: 3M | G6: -0.0035471 | I6: ER1 | J6: =_xll.meDateIMMNext(D8) -> 44090 | K6: =_xll.meDateIMMNext(J6) -> 44181 | L6: 100.37 | M6: 0.005 | O6: 3Y | P6: -0.00385 | Q6: TRUE
C7: CurveIndexFrequency | D7: QUARTERLY | I7: ER2 | J7: =_xll.meDateIMMNext(J6) -> 44181 | K7: =_xll.meDateIMMNext(J7) -> 44272 | L7: 100.405 | M7: 0.005 | O7: 4Y | P7: -0.00356 | Q7: TRUE
C8: AsOfDate | D8: =AsOfDate -> 43987 | I8: ER3 | J8: =_xll.meDateIMMNext(J7) -> 44272 | K8: =_xll.meDateIMMNext(J8) -> 44363 | L8: 100.405 | M8: 0.005 | O8: 5Y | P8: -0.0032 | Q8: TRUE
I9: ER4 | J9: =_xll.meDateIMMNext(J8) -> 44363 | K9: =_xll.meDateIMMNext(J9) -> 44454 | L9: 100.415 | M9: 0.005 | O9: 6Y | P9: -0.00278 | Q9: TRUE
O10: 7Y | P10: -0.00232 | Q10: TRUE
O11: 8Y | P11: -0.00185 | Q11: TRUE
C12: Create Market Data Handle | O12: 9Y | P12: -0.00135 | Q12: TRUE
C13: Handle Name | D13: EUR_SWAP_3M_CURVE_MARKETDATA | O13: 10Y | P13: -0.00087 | Q13: TRUE
C14: Market Data Handle | D14: =_xll.meLWOCurveMarketDataCreate(D13,C4,C5:D10,F4,F6:G10,I4,I6:M31,O4,O6:Q31) -> EUR_SWAP_3M_CURVE_MARKETDATA:1 | O14: 11Y | P14: -0.00042 | Q14: TRUE
O15: 12Y | P15: 3e-05 | Q15: TRUE
O16: 15Y | P16: 0.00112 | Q16: TRUE
O17: 20Y | P17: 0.00199 | Q17: TRUE
O18: 25Y | P18: 0.00207 | Q18: TRUE
O19: 30Y | P19: 0.00183 | Q19: TRUE
C20: Curve Dictionary | O20: 31Y | P20: 0.00183 | Q20: TRUE
C21: Handle Name | D21: EUR_SWAP_3M_CURVE
C22: Curve Generator | D22: =Templates.EUR.3M -> EUR_SWAP_3M:1
C23: Domestic Curve Collection | D23: EURYC
C24: Foreign Curve Collection
C27: Curve Build
C28: Handle Name | D28: {=IF(doesExistEUROIS,_xll.meLWOCurveCalibrate(D21,D22,D14,D23,D24),"LOAD EUROIS")} -> EUR_SWAP_3M_CURVE:1
C29: Curve Collection | D29: EURYC
C30: Curve Index | D30: STD:EUR3ML
C31: Calibration Time Taken | D31: 0.01000 sec
C32: Curve Loaded | D32: =_xll.meLWOExists(D28,"Curve") -> TRUE

Sheet EUR SWAP 6M
C4: MARKETDATAPROPERTIES | F4: LIBORFIXINGS | I4: FRAS | L4: SWAPS
C5: Currency | D5: EUR | F5: Term | G5: Rate | I5: Term | J5: Rate | L5: Term | M5: Rate | N5: Use
C6: CurveType | D6: SWAP | F6: 6M | G6: -0.0023857 | I6: 1X7 | J6: -0.00256 | L6: 2Y | M6: -0.0031 | N6: TRUE
C7: CurveIndexFrequency | D7: SEMI-ANNUAL | I7: 2X8 | J7: -0.00283 | L7: 3Y | M7: -0.00294 | N7: TRUE
C8: AsOfDate | D8: =AsOfDate -> 43987 | I8: 3X9 | J8: -0.00303 | L8: 4Y | M8: -0.00274 | N8: TRUE
I9: 4X10 | J9: -0.00314 | L9: 5Y | M9: -0.00244 | N9: TRUE
I10: 5X11 | J10: -0.00322 | L10: 6Y | M10: -0.00206 | N10: TRUE
I11: 6X12 | J11: -0.0033 | L11: 7Y | M11: -0.00164 | N11: TRUE
C12: Create Market Data Handle | L12: 8Y | M12: -0.00121 | N12: TRUE
C13: Handle Name | D13: EUR_SWAP_6M_CURVE_MARKETDATA | L13: 9Y | M13: -0.00077 | N13: TRUE
C14: Market Data Handle | D14: =_xll.meLWOCurveMarketDataCreate(D13,C4,C5:D10,F4,F6:G10,I4,I6:J31,L4,L6:N31) -> EUR_SWAP_6M_CURVE_MARKETDATA:1 | L14: 10Y | M14: -0.00034 | N14: TRUE
L15: 11Y | M15: 6e-05 | N15: TRUE
L16: 12Y | M16: 0.00046 | N16: TRUE
L17: 15Y | M17: 0.00143 | N17: TRUE
L18: 20Y | M18: 0.00218 | N18: TRUE
L19: 25Y | M19: 0.00218 | N19: TRUE
C20: Curve Dictionary | L20: 30Y | M20: 0.00189 | N20: TRUE
C21: Handle Name | D21: EUR_SWAP_6M_CURVE | L21: 31Y | M21: 0.00189 | N21: TRUE
C22: Curve Generator | D22: =Templates.EUR.6M -> EUR_SWAP_6M:1
C23: Domestic Curve Collection | D23: EURYC
C24: Foreign Curve Collection
C27: Curve Build
C28: Handle Name | D28: {=IF(doesExistEUR3M,_xll.meLWOCurveCalibrate(D21,D22,D14,D23,D24),"LOAD EUR3M")} -> EUR_SWAP_6M_CURVE:1
C29: Curve Collection | D29: EURYC
C30: Curve Index | D30: EUR6ML
C31: Calibration Time Taken | D31: 0.00800 sec
C32: Curve Loaded | D32: =_xll.meLWOExists(D28,"Curve") -> TRUE

Sheet EUR SWAP 1M
C4: MARKETDATAPROPERTIES | F4: LIBORFIXINGS | I4: SWAPS
C5: Currency | D5: EUR | F5: Term | G5: Rate | I5: Term | J5: Rate | K5: Use
C6: CurveType | D6: SWAP | F6: 1M | G6: -0.0043014 | I6: 1Y | J6: -0.00465 | K6: TRUE
C7: CurveIndexFrequency | D7: MONTHLY | I7: 2Y | J7: -0.00455 | K7: TRUE
C8: AsOfDate | D8: =AsOfDate -> 43987 | I8: 3Y | J8: -0.00435 | K8: TRUE
I9: 4Y | J9: -0.00406 | K9: TRUE
I10: 5Y | J10: -0.0037 | K10: TRUE
I11: 6Y | J11: -0.00328 | K11: TRUE
C12: Create Market Data Handle | I12: 7Y | J12: -0.00282 | K12: TRUE
C13: Handle Name | D13: EUR_SWAP_1M_CURVE_MARKETDATA | I13: 8Y | J13: -0.00235 | K13: TRUE
C14: Market Data Handle | D14: =_xll.meLWOCurveMarketDataCreate(D13,C4,C5:D10,F4,F6:G10,I4,I6:K31) -> EUR_SWAP_1M_CURVE_MARKETDATA:0 | I14: 9Y | J14: -0.00185 | K14: TRUE
I15: 10Y | J15: -0.00137 | K15: TRUE
I16: 11Y | J16: -0.00092 | K16: TRUE
I17: 12Y | J17: -0.00047 | K17: TRUE
I18: 15Y | J18: 0.00062 | K18: TRUE
I19: 20Y | J19: 0.00149 | K19: TRUE
C20: Curve Dictionary | I20: 25Y | J20: 0.00157 | K20: TRUE
C21: Handle Name | D21: EUR_SWAP_1M_CURVE | I21: 30Y | J21: 0.00133 | K21: TRUE
C22: Curve Generator | D22: =Templates.EUR.1M -> EUR_SWAP_1M:1 | I22: 31Y | J22: 0.00133 | K22: TRUE
C23: Domestic Curve Collection | D23: EURYC
C24: Foreign Curve Collection
C27: Curve Build
C28: Handle Name | D28: {=IF(doesExistEUR6M,_xll.meLWOCurveCalibrate(D21,D22,D14,D23,D24),"LOAD EUR6M")} -> EUR_SWAP_1M_CURVE:1
C29: Curve Collection | D29: EURYC
C30: Curve Index | D30: EUR1ML
C31: Calibration Time Taken | D31: 0.01800 sec
C32: Curve Loaded | D32: =_xll.meLWOExists(D28,"Curve") -> TRUE

Sheet EUR SWAP 12M
C4: MARKETDATAPROPERTIES | F4: LIBORFIXINGS | I4: SWAPS
C5: Currency | D5: EUR | F5: Term | G5: Rate | I5: Term | J5: Rate | K5: Use
C6: CurveType | D6: SWAP | F6: 12M | G6: -0.001 | I6: 2Y | J6: -0.002 | K6: TRUE
C7: CurveIndexFrequency | D7: ANNUAL | I7: 3Y | J7: -0.00205 | K7: TRUE
C8: AsOfDate | D8: =AsOfDate -> 43987 | I8: 4Y | J8: -0.00176 | K8: TRUE
I9: 5Y | J9: -0.0014 | K9: TRUE
I10: 6Y | J10: -0.00098 | K10: TRUE
I11: 7Y | J11: -0.00052 | K11: TRUE
C12: Create Market Data Handle | I12: 8Y | J12: -5e-05 | K12: TRUE
C13: Handle Name | D13: EUR_SWAP_12M_CURVE_MARKETDATA | I13: 9Y | J13: 0.00045 | K13: TRUE
C14: Market Data Handle | D14: =_xll.meLWOCurveMarketDataCreate(D13,C4,C5:D10,F4,F6:G10,I4,I6:K31) -> EUR_SWAP_12M_CURVE_MARKETDATA:1 | I14: 10Y | J14: 0.00093 | K14: TRUE
I15: 11Y | J15: 0.00138 | K15: TRUE
I16: 12Y | J16: 0.00183 | K16: TRUE
I17: 15Y | J17: 0.00292 | K17: TRUE
I18: 20Y | J18: 0.00379 | K18: TRUE
I19: 25Y | J19: 0.00387 | K19: TRUE
C20: Curve Dictionary | I20: 30Y | J20: 0.00363 | K20: TRUE
C21: Handle Name | D21: EUR_SWAP_12M_CURVE | I21: 31Y | J21: 0.00363 | K21: TRUE
C22: Curve Generator | D22: =Templates.EUR.12M -> EUR_SWAP_12M:1
C23: Domestic Curve Collection | D23: EURYC
C24: Foreign Curve Collection
C27: Curve Build
C28: Handle Name | D28: {=IF(doesExistEUR1M,_xll.meLWOCurveCalibrate(D21,D22,D14,D23,D24),"LOAD EUR1M")} -> EUR_SWAP_12M_CURVE:1
C29: Curve Collection | D29: EURYC
C30: Curve Index | D30: EUR12ML
C31: Calibration Time Taken | D31: 0.00700 sec
C32: Curve Loaded | D32: =_xll.meLWOExists(D28,"Curve") -> TRUE

Sheet CHART
E2: {=_xll.meLWOCurveForwardRatesTable(C3,C5:C9,,"30Y",,,,$C$11)} -> Fixing Dates | F2: EUROIS | G2: EUR1ML | H2: EUR3ML | I2: EUR6ML | J2: EUR12ML
B3: Curve Collection | C3: EURYC | E3: 43987 | F3: -0.00458 | G3: -0.0043014 | H3: -0.0035408893 | I3: -0.00236246 | J3: -0.001
E4: 44081 | F4: -0.00464 | G4: -0.0045423393 | H4: -0.0036868413 | I4: -0.0030166667 | J4: -0.0016412976
B5: Curve Index | C5: EUROIS | E5: 44172 | F5: -0.00484 | G5: -0.0046886661 | H5: -0.004019874 | I5: -0.0032946667 | J5: -0.0022251722
C6: EUR1ML | E6: 44260 | F6: -0.0049101062 | G6: -0.00471566 | H6: -0.0040591399 | I6: -0.0033481914 | J6: -0.0026667922
C7: EUR3ML | E7: 44354 | F7: -0.0049536123 | G7: -0.004626168 | H7: -0.004155914 | I7: -0.0034008657 | J7: -0.0029373881
C8: EUR6ML | E8: 44445 | F8: -0.004960127 | G8: -0.0044971673 | H8: -0.0041277762 | I8: -0.0033021585 | J8: -0.0029561024
C9: EUR12ML | E9: 44536 | F9: -0.0049319734 | G9: -0.0043775358 | H9: -0.004040838 | I9: -0.0031621308 | J9: -0.002781227
E10: 44627 | F10: -0.0048700633 | G10: -0.0042650372 | H10: -0.0039280688 | I10: -0.002960864 | J10: -0.0024829701
B11: Periodicity | C11: QUARTERLY | E11: 44718 | F11: -0.0047753151 | G11: -0.004160955 | H11: -0.0037921806 | I11: -0.002744998 | J11: -0.0021315396
E12: 44809 | F12: -0.0046486446 | G12: -0.0040447121 | H12: -0.0036331061 | I12: -0.00256983 | J12: -0.0017869738
E13: 44900 | F13: -0.0044909531 | G13: -0.0039035048 | H13: -0.003450218 | I13: -0.0024438458 | J13: -0.0014643975
E14: 44991 | F14: -0.0043032059 | G14: -0.0037357195 | H14: -0.0032396883 | I14: -0.0023566291 | J14: -0.0011665422
E15: 45082 | F15: -0.0040861315 | G15: -0.0035471589 | H15: -0.0030086391 | I15: -0.0022704488 | J15: -0.00089613848
E16: 45174 | F16: -0.003850626 | G16: -0.0033422183 | H16: -0.0027805468 | I16: -0.0021445434 | J16: -0.00065115841
E17: 45265 | F17: -0.0036214324 | G17: -0.0031316274 | H17: -0.0025560855 | I17: -0.0019716591 | J17: -0.00042719356
E18: 45356 | F18: -0.0034050188 | G18: -0.0029156647 | H18: -0.0023345542 | I18: -0.0017524262 | J18: -0.00020892687
E19: 45448 | F19: -0.0032083482 | G19: -0.002692078 | H19: -0.0021137438 | I19: -0.0015023905 | J19: 1.8707772e-05
E20: 45540 | F20: -0.0030169715 | G20: -0.0024590274 | H20: -0.0018843144 | I20: -0.0012442301 | J20: 0.00026382856
E21: 45631 | F21: -0.002804026 | G21: -0.0022164604 | H21: -0.0016428885 | I21: -0.00098415802 | J21: 0.00052273758
E22: 45721 | F22: -0.0025660801 | G22: -0.0019675942 | H22: -0.0013895195 | I22: -0.00072160775 | J22: 0.00079099188
E23: 45813 | F23: -0.0022907508 | G23: -0.001703562 | H23: -0.0011194936 | I23: -0.00045144195 | J23: 0.0010737248
... E93: 52205 | F93: 0.001483099 | G93: 0.0018958788 | H93: 0.0023441809 | I93: 0.0020565146 | J93: 0.0039087261

Sheet SWAPS
E1: … Dates
B3: Trade Dates | F3: SWAPS: EUR6ML | N3: Trade Booking & Pricing | R3: Curve Calibration Check
D4: Unadjusted Date ! | H4: Swap Template
B5: EffectiveDate | C5: Calendar | D5: MaturityDate | F5: EffectiveDate | G5: Maturity | H5: Generator | I5: PayRec | J5: Notional | K5: FixedRate | L5: Spread | N5: CreateSwap | O5: CurveCollection | P5: ParRate | R5: Term | S5: Rate | T5: +/- Bps
B6: =_xll.meDateFromTenor(AsOfDate,F6,"MOD_FOLLOWING",$C6,"") -> 43991 | C6: =VLOOKUP("PAYMENTCALENDAR",_xll.meLWOSwapGeneratorDisplay($H6),2,FALSE) -> TGT | D6: =_xll.meDateFromTenor(B6,G6,) -> 44721 | F6: 2D | G6: =R6 -> 2Y | H6: =Template.Swap.EUR.6M -> EUR_SWAP_6ML:1 | I6: PAY | J6: 1000000 | K6: 0.01 | L6: 0 | N6: =_xll.meLWOSwapCreateFromGenerator("EUR6M_"&G6,H6,I6,J6,B6,D6,K6,L6) -> EUR6M_2Y:1 | O6: EURYC | P6: =_xll.meLWOSwapParRate(N6,O6) -> -0.0031 | R6: ='EUR SWAP 6M'!L6 -> 2Y | S6: ='EUR SWAP 6M'!M6 -> -0.0031 | T6: =ABS(P6-S6)*100000 -> 4.6932944e-10
B7: =_xll.meDateFromTenor(AsOfDate,F7,"MOD_FOLLOWING",$C7,"") -> 43991 | C7: =C6 -> TGT | D7: =_xll.meDateFromTenor(B7,G7,) -> 45086 | F7: 2D | G7: =R7 -> 3Y | H7: =Template.Swap.EUR.6M -> EUR_SWAP_6ML:1 | I7: PAY | J7: 1000000 | K7: 0.01 | L7: 0 | N7: =_xll.meLWOSwapCreateFromGenerator("EUR6M_"&G7,H7,I7,J7,B7,D7,K7,L7) -> EUR6M_3Y:1 | O7: EURYC | P7: =_xll.meLWOSwapParRate(N7,O7) -> -0.00294 | R7: ='EUR SWAP 6M'!L7 -> 3Y | S7: ='EUR SWAP 6M'!M7 -> -0.00294 | T7: =ABS(P7-S7)*100000 -> 3.6359804e-10
B8: =_xll.meDateFromTenor(AsOfDate,F8,"MOD_FOLLOWING",$C8,"") -> 43991 | C8: =C7 -> TGT | D8: =_xll.meDateFromTenor(B8,G8,) -> 45452 | F8: 2D | G8: =R8 -> 4Y | H8: =Template.Swap.EUR.6M -> EUR_SWAP_6ML:1 | I8: PAY | J8: 1000000 | K8: 0.01 | L8: 0 | N8: =_xll.meLWOSwapCreateFromGenerator("EUR6M_"&G8,H8,I8,J8,B8,D8,K8,L8) -> EUR6M_4Y:1 | O8: EURYC | P8: =_xll.meLWOSwapParRate(N8,O8) -> -0.00274 | R8: ='EUR SWAP 6M'!L8 -> 4Y | S8: ='EUR SWAP 6M'!M8 -> -0.00274 | T8: =ABS(P8-S8)*100000 -> 4.7592139e-10
B9: =_xll.meDateFromTenor(AsOfDate,F9,"MOD_FOLLOWING",$C9,"") -> 43991 | C9: =C8 -> TGT | D9: =_xll.meDateFromTenor(B9,G9,) -> 45817 | F9: 2D | G9: =R9 -> 5Y | H9: =Template.Swap.EUR.6M -> EUR_SWAP_6ML:1 | I9: PAY | J9: 1000000 | K9: 0.01 | L9: 0 | N9: =_xll.meLWOSwapCreateFromGenerator("EUR6M_"&G9,H9,I9,J9,B9,D9,K9,L9) -> EUR6M_5Y:1 | O9: EURYC | P9: =_xll.meLWOSwapParRate(N9,O9) -> -0.00244 | R9: ='EUR SWAP 6M'!L9 -> 5Y | S9: ='EUR SWAP 6M'!M9 -> -0.00244 | T9: =ABS(P9-S9)*100000 -> 4.6837534e-12
B10: =_xll.meDateFromTenor(AsOfDate,F10,"MOD_FOLLOWING",$C10,"") -> 43991 | C10: =C9 -> TGT | D10: =_xll.meDateFromTenor(B10,G10,) -> 46182 | F10: 2D | G10: =R10 -> 6Y | H10: =Template.Swap.EUR.6M -> EUR_SWAP_6ML:1 | I10: PAY | J10: 1000000 | K10: 0.01 | L10: 0 | N10: =_xll.meLWOSwapCreateFromGenerator("EUR6M_"&G10,H10,I10,J10,B10,D10,K10,L10) -> EUR6M_6Y:1 | O10: EURYC | P10: =_xll.meLWOSwapParRate(N10,O10) -> -0.00206 | R10: ='EUR SWAP 6M'!L10 -> 6Y | S10: ='EUR SWAP 6M'!M10 -> -0.00206 | T10: =ABS(P10-S10)*100000 -> 5.1738128e-11
B11: =_xll.meDateFromTenor(AsOfDate,F11,"MOD_FOLLOWING",$C11,"") -> 43991 | C11: =C10 -> TGT | D11: =_xll.meDateFromTenor(B11,G11,) -> 46547 | F11: 2D | G11: =R11 -> 7Y | H11: =Template.Swap.EUR.6M -> EUR_SWAP_6ML:1 | I11: PAY | J11: 1000000 | K11: 0.01 | L11: 0 | N11: =_xll.meLWOSwapCreateFromGenerator("EUR6M_"&G11,H11,I11,J11,B11,D11,K11,L11) -> EUR6M_7Y:1 | O11: EURYC | P11: =_xll.meLWOSwapParRate(N11,O11) -> -0.00164 | R11: ='EUR SWAP 6M'!L11 -> 7Y | S11: ='EUR SWAP 6M'!M11 -> -0.00164 | T11: =ABS(P11-S11)*100000 -> 1.8680803e-10
B12: =_xll.meDateFromTenor(AsOfDate,F12,"MOD_FOLLOWING",$C12,"") -> 43991 | C12: =C11 -> TGT | D12: =_xll.meDateFromTenor(B12,G12,) -> 46913 | F12: 2D | G12: =R12 -> 8Y | H12: =Template.Swap.EUR.6M -> EUR_SWAP_6ML:1 | I12: PAY | J12: 1000000 | K12: 0.01 | L12: 0 | N12: =_xll.meLWOSwapCreateFromGenerator("EUR6M_"&G12,H12,I12,J12,B12,D12,K12,L12) -> EUR6M_8Y:1 | O12: EURYC | P12: =_xll.meLWOSwapParRate(N12,O12) -> -0.00121 | R12: ='EUR SWAP 6M'!L12 -> 8Y | S12: ='EUR SWAP 6M'!M12 -> -0.00121 | T12: =ABS(P12-S12)*100000 -> 2.1632002e-10
B13: =_xll.meDateFromTenor(AsOfDate,F13,"MOD_FOLLOWING",$C13,"") -> 43991 | C13: =C12 -> TGT | D13: =_xll.meDateFromTenor(B13,G13,) -> 47278 | F13: 2D | G13: =R13 -> 9Y | H13: =Template.Swap.EUR.6M -> EUR_SWAP_6ML:1 | I13: PAY | J13: 1000000 | K13: 0.01 | L13: 0 | N13: =_xll.meLWOSwapCreateFromGenerator("EUR6M_"&G13,H13,I13,J13,B13,D13,K13,L13) -> EUR6M_9Y:1 | O13: EURYC | P13: =_xll.meLWOSwapParRate(N13,O13) -> -0.00077 | R13: ='EUR SWAP 6M'!L13 -> 9Y | S13: ='EUR SWAP 6M'!M13 -> -0.00077 | T13: =ABS(P13-S13)*100000 -> 4.0139333e-10
B14: =_xll.meDateFromTenor(AsOfDate,F14,"MOD_FOLLOWING",$C14,"") -> 43991 | C14: =C13 -> TGT | D14: =_xll.meDateFromTenor(B14,G14,) -> 47643 | F14: 2D | G14: =R14 -> 10Y | H14: =Template.Swap.EUR.6M -> EUR_SWAP_6ML:1 | I14: PAY | J14: 1000000 | K14: 0.01 | L14: 0 | N14: =_xll.meLWOSwapCreateFromGenerator("EUR6M_"&G14,H14,I14,J14,B14,D14,K14,L14) -> EUR6M_10Y:1 | O14: EURYC | P14: =_xll.meLWOSwapParRate(N14,O14) -> -0.00034 | R14: ='EUR SWAP 6M'!L14 -> 10Y | S14: ='EUR SWAP 6M'!M14 -> -0.00034 | T14: =ABS(P14-S14)*100000 -> 6.3718562e-10
B15: =_xll.meDateFromTenor(AsOfDate,F15,"MOD_FOLLOWING",$C15,"") -> 43991 | C15: =C14 -> TGT | D15: =_xll.meDateFromTenor(B15,G15,) -> 48008 | F15: 2D | G15: =R15 -> 11Y | H15: =Template.Swap.EUR.6M -> EUR_SWAP_6ML:1 | I15: PAY | J15: 1000000 | K15: 0.01 | L15: 0 | N15: =_xll.meLWOSwapCreateFromGenerator("EUR6M_"&G15,H15,I15,J15,B15,D15,K15,L15) -> EUR6M_11Y:1 | O15: EURYC | P15: =_xll.meLWOSwapParRate(N15,O15) -> 6e-05 | R15: ='EUR SWAP 6M'!L15 -> 11Y | S15: ='EUR SWAP 6M'!M15 -> 6e-05 | T15: =ABS(P15-S15)*100000 -> 1.0017784e-09
B16: =_xll.meDateFromTenor(AsOfDate,F16,"MOD_FOLLOWING",$C16,"") -> 43991 | C16: =C15 -> TGT | D16: =_xll.meDateFromTenor(B16,G16,) -> 48374 | F16: 2D | G16: =R16 -> 12Y | H16: =Template.Swap.EUR.6M -> EUR_SWAP_6ML:1 | I16: PAY | J16: 1000000 | K16: 0.01 | L16: 0 | N16: =_xll.meLWOSwapCreateFromGenerator("EUR6M_"&G16,H16,I16,J16,B16,D16,K16,L16) -> EUR6M_12Y:1 | O16: EURYC | P16: =_xll.meLWOSwapParRate(N16,O16) -> 0.00046 | R16: ='EUR SWAP 6M'!L16 -> 12Y | S16: ='EUR SWAP 6M'!M16 -> 0.00046 | T16: =ABS(P16-S16)*100000 -> 1.1054037e-09
B17: =_xll.meDateFromTenor(AsOfDate,F17,"MOD_FOLLOWING",$C17,"") -> 43991 | C17: =C16 -> TGT | D17: =_xll.meDateFromTenor(B17,G17,) -> 49469 | F17: 2D | G17: =R17 -> 15Y | H17: =Template.Swap.EUR.6M -> EUR_SWAP_6ML:1 | I17: PAY | J17: 1000000 | K17: 0.01 | L17: 0 | N17: =_xll.meLWOSwapCreateFromGenerator("EUR6M_"&G17,H17,I17,J17,B17,D17,K17,L17) -> EUR6M_15Y:1 | O17: EURYC | P17: =_xll.meLWOSwapParRate(N17,O17) -> 0.00143 | R17: ='EUR SWAP 6M'!L17 -> 15Y | S17: ='EUR SWAP 6M'!M17 -> 0.00143 | T17: =ABS(P17-S17)*100000 -> 6.3532079e-10
B18: =_xll.meDateFromTenor(AsOfDate,F18,"MOD_FOLLOWING",$C18,"") -> 43991 | C18: =C17 -> TGT | D18: =_xll.meDateFromTenor(B18,G18,) -> 51296 | F18: 2D | G18: =R18 -> 20Y | H18: =Template.Swap.EUR.6M -> EUR_SWAP_6ML:1 | I18: PAY | J18: 1000000 | K18: 0.01 | L18: 0 | N18: =_xll.meLWOSwapCreateFromGenerator("EUR6M_"&G18,H18,I18,J18,B18,D18,K18,L18) -> EUR6M_20Y:1 | O18: EURYC | P18: =_xll.meLWOSwapParRate(N18,O18) -> 0.00218 | R18: ='EUR SWAP 6M'!L18 -> 20Y | S18: ='EUR SWAP 6M'!M18 -> 0.00218 | T18: =ABS(P18-S18)*100000 -> 4.0896106e-11
... B20: =_xll.meDateFromTenor(AsOfDate,F20,"MOD_FOLLOWING",$C20,"") -> 43991 | C20: =C19 -> TGT | D20: =_xll.meDateFromTenor(B20,G20,) -> 54948 | F20: 2D | G20: =R20 -> 30Y | H20: =Template.Swap.EUR.6M -> EUR_SWAP_6ML:1 | I20: PAY | J20: 1000000 | K20: 0.01 | L20: 0 | N20: =_xll.meLWOSwapCreateFromGenerator("EUR6M_"&G20,H20,I20,J20,B20,D20,K20,L20) -> EUR6M_30Y:1 | O20: EURYC | P20: =_xll.meLWOSwapParRate(N20,O20) -> 0.00189 | R20: ='EUR SWAP 6M'!L20 -> 30Y | S20: ='EUR SWAP 6M'!M20 -> 0.00189 | T20: =ABS(P20-S20)*100000 -> 3.1094918e-11
B23: Trade Dates | F23: SWAP: EUR3ML | N23: Trade Booking & Pricing | R23: Curve Calibration Check
D24: Unadjusted Date ! | H24: Swap Template
B25: EffectiveDate | C25: Calendar | D25: MaturityDate | F25: EffectiveDate | G25: Maturity | H25: Generator | I25: PayRec | J25: Notional | K25: Leg 1 Spread | L25: Leg 2 Spread | N25: CreateSwap | O25: CurveCollection | P25: ParRate | R25: Term | S25: Rate | T25: +/- Bps
B26: =_xll.meDateFromTenor(AsOfDate,F26,"MOD_FOLLOWING",$C26,"") -> 43991 | C26: =VLOOKUP("PAYMENTCALENDAR",_xll.meLWOSwapGeneratorDisplay($H26),2,FALSE) -> TGT | D26: =_xll.meDateFromTenor(B26,G26,) -> 45086 | F26: 2D | G26: =R26 -> 3Y | H26: =Template.Swap.EUR.3M -> EUR_SWAP_3ML:1 | I26: PAY | J26: 1000000 | K26: 0 | L26: 0 | N26: =_xll.meLWOSwapCreateFromGenerator("EUR3M_"&G26,H26,I26,J26,B26,D26,K26,L26) -> EUR3M_3Y:1 | O26: EURYC | P26: =_xll.meLWOSwapParRate(N26,O26) -> -0.00385 | R26: ='EUR SWAP 3M'!O6 -> 3Y | S26: ='EUR SWAP 3M'!P6 -> -0.00385 | T26: =ABS(P26-S26)*100000 -> 1.0231833e-09
B27: =_xll.meDateFromTenor(AsOfDate,F27,"MOD_FOLLOWING",$C27,"") -> 43991 | C27: =C26 -> TGT | D27: =_xll.meDateFromTenor(B27,G27,) -> 45452 | F27: 2D | G27: =R27 -> 4Y | H27: =Template.Swap.EUR.3M -> EUR_SWAP_3ML:1 | I27: PAY | J27: 1000000 | K27: 0 | L27: 0 | N27: =_xll.meLWOSwapCreateFromGenerator("EUR3M_"&G27,H27,I27,J27,B27,D27,K27,L27) -> EUR3M_4Y:1 | O27: EURYC | P27: =_xll.meLWOSwapParRate(N27,O27) -> -0.00356 | R27: ='EUR SWAP 3M'!O7 -> 4Y | S27: ='EUR SWAP 3M'!P7 -> -0.00356 | T27: =ABS(P27-S27)*100000 -> 4.1663721e-10
B28: =_xll.meDateFromTenor(AsOfDate,F28,"MOD_FOLLOWING",$C28,"") -> 43991 | C28: =C27 -> TGT | D28: =_xll.meDateFromTenor(B28,G28,) -> 45817 | F28: 2D | G28: =R28 -> 5Y | H28: =Template.Swap.EUR.3M -> EUR_SWAP_3ML:1 | I28: PAY | J28: 1000000 | K28: 0 | L28: 0 | N28: =_xll.meLWOSwapCreateFromGenerator("EUR3M_"&G28,H28,I28,J28,B28,D28,K28,L28) -> EUR3M_5Y:1 | O28: EURYC | P28: =_xll.meLWOSwapParRate(N28,O28) -> -0.0032 | R28: ='EUR SWAP 3M'!O8 -> 5Y | S28: ='EUR SWAP 3M'!P8 -> -0.0032 | T28: =ABS(P28-S28)*100000 -> 5.8850494e-11
B29: =_xll.meDateFromTenor(AsOfDate,F29,"MOD_FOLLOWING",$C29,"") -> 43991 | C29: =C28 -> TGT | D29: =_xll.meDateFromTenor(B29,G29,) -> 46182 | F29: 2D | G29: =R29 -> 6Y | H29: =Template.Swap.EUR.3M -> EUR_SWAP_3ML:1 | I29: PAY | J29: 1000000 | K29: 0 | L29: 0 | N29: =_xll.meLWOSwapCreateFromGenerator("EUR3M_"&G29,H29,I29,J29,B29,D29,K29,L29) -> EUR3M_6Y:1 | O29: EURYC | P29: =_xll.meLWOSwapParRate(N29,O29) -> -0.00278 | R29: ='EUR SWAP 3M'!O9 -> 6Y | S29: ='EUR SWAP 3M'!P9 -> -0.00278 | T29: =ABS(P29-S29)*100000 -> 1.2763228e-10
B30: =_xll.meDateFromTenor(AsOfDate,F30,"MOD_FOLLOWING",$C30,"") -> 43991 | C30: =C29 -> TGT | D30: =_xll.meDateFromTenor(B30,G30,) -> 46547 | F30: 2D | G30: =R30 -> 7Y | H30: =Template.Swap.EUR.3M -> EUR_SWAP_3ML:1 | I30: PAY | J30: 1000000 | K30: 0 | L30: 0 | N30: =_xll.meLWOSwapCreateFromGenerator("EUR3M_"&G30,H30,I30,J30,B30,D30,K30,L30) -> EUR3M_7Y:1 | O30: EURYC | P30: =_xll.meLWOSwapParRate(N30,O30) -> -0.00232 | R30: ='EUR SWAP 3M'!O10 -> 7Y | S30: ='EUR SWAP 3M'!P10 -> -0.00232 | T30: =ABS(P30-S30)*100000 -> 9.4204158e-10
B31: =_xll.meDateFromTenor(AsOfDate,F31,"MOD_FOLLOWING",$C31,"") -> 43991 | C31: =C30 -> TGT | D31: =_xll.meDateFromTenor(B31,G31,) -> 46913 | F31: 2D | G31: =R31 -> 8Y | H31: =Template.Swap.EUR.3M -> EUR_SWAP_3ML:1 | I31: PAY | J31: 1000000 | K31: 0 | L31: 0 | N31: =_xll.meLWOSwapCreateFromGenerator("EUR3M_"&G31,H31,I31,J31,B31,D31,K31,L31) -> EUR3M_8Y:1 | O31: EURYC | P31: =_xll.meLWOSwapParRate(N31,O31) -> -0.00185 | R31: ='EUR SWAP 3M'!O11 -> 8Y | S31: ='EUR SWAP 3M'!P11 -> -0.00185 | T31: =ABS(P31-S31)*100000 -> 5.048479e-10
B32: =_xll.meDateFromTenor(AsOfDate,F32,"MOD_FOLLOWING",$C32,"") -> 43991 | C32: =C31 -> TGT | D32: =_xll.meDateFromTenor(B32,G32,) -> 47278 | F32: 2D | G32: =R32 -> 9Y | H32: =Template.Swap.EUR.3M -> EUR_SWAP_3ML:1 | I32: PAY | J32: 1000000 | K32: 0 | L32: 0 | N32: =_xll.meLWOSwapCreateFromGenerator("EUR3M_"&G32,H32,I32,J32,B32,D32,K32,L32) -> EUR3M_9Y:1 | O32: EURYC | P32: =_xll.meLWOSwapParRate(N32,O32) -> -0.00135 | R32: ='EUR SWAP 3M'!O12 -> 9Y | S32: ='EUR SWAP 3M'!P12 -> -0.00135 | T32: =ABS(P32-S32)*100000 -> 1.5419523e-10
B33: =_xll.meDateFromTenor(AsOfDate,F33,"MOD_FOLLOWING",$C33,"") -> 43991 | C33: =C32 -> TGT | D33: =_xll.meDateFromTenor(B33,G33,) -> 47643 | F33: 2D | G33: =R33 -> 10Y | H33: =Template.Swap.EUR.3M -> EUR_SWAP_3ML:1 | I33: PAY | J33: 1000000 | K33: 0 | L33: 0 | N33: =_xll.meLWOSwapCreateFromGenerator("EUR3M_"&G33,H33,I33,J33,B33,D33,K33,L33) -> EUR3M_10Y:1 | O33: EURYC | P33: =_xll.meLWOSwapParRate(N33,O33) -> -0.00087 | R33: ='EUR SWAP 3M'!O13 -> 10Y | S33: ='EUR SWAP 3M'!P13 -> -0.00087 | T33: =ABS(P33-S33)*100000 -> 1.9016906e-11
B34: =_xll.meDateFromTenor(AsOfDate,F34,"MOD_FOLLOWING",$C34,"") -> 43991 | C34: =C33 -> TGT | D34: =_xll.meDateFromTenor(B34,G34,) -> 48008 | F34: 2D | G34: =R34 -> 11Y | H34: =Template.Swap.EUR.3M -> EUR_SWAP_3ML:1 | I34: PAY | J34: 1000000 | K34: 0 | L34: 0 | N34: =_xll.meLWOSwapCreateFromGenerator("EUR3M_"&G34,H34,I34,J34,B34,D34,K34,L34) -> EUR3M_11Y:1 | O34: EURYC | P34: =_xll.meLWOSwapParRate(N34,O34) -> -0.00042 | R34: ='EUR SWAP 3M'!O14 -> 11Y | S34: ='EUR SWAP 3M'!P14 -> -0.00042 | T34: =ABS(P34-S34)*100000 -> 1.5333329e-10
B35: =_xll.meDateFromTenor(AsOfDate,F35,"MOD_FOLLOWING",$C35,"") -> 43991 | C35: =C34 -> TGT | D35: =_xll.meDateFromTenor(B35,G35,) -> 48374 | F35: 2D | G35: =R35 -> 12Y | H35: =Template.Swap.EUR.3M -> EUR_SWAP_3ML:1 | I35: PAY | J35: 1000000 | K35: 0 | L35: 0 | N35: =_xll.meLWOSwapCreateFromGenerator("EUR3M_"&G35,H35,I35,J35,B35,D35,K35,L35) -> EUR3M_12Y:1 | O35: EURYC | P35: =_xll.meLWOSwapParRate(N35,O35) -> 3e-05 | R35: ='EUR SWAP 3M'!O15 -> 12Y | S35: ='EUR SWAP 3M'!P15 -> 3e-05 | T35: =ABS(P35-S35)*100000 -> 8.3663477e-10
B36: =_xll.meDateFromTenor(AsOfDate,F36,"MOD_FOLLOWING",$C36,"") -> 43991 | C36: =C35 -> TGT | D36: =_xll.meDateFromTenor(B36,G36,) -> 49469 | F36: 2D | G36: =R36 -> 15Y | H36: =Template.Swap.EUR.3M -> EUR_SWAP_3ML:1 | I36: PAY | J36: 1000000 | K36: 0 | L36: 0 | N36: =_xll.meLWOSwapCreateFromGenerator("EUR3M_"&G36,H36,I36,J36,B36,D36,K36,L36) -> EUR3M_15Y:1 | O36: EURYC | P36: =_xll.meLWOSwapParRate(N36,O36) -> 0.00112 | R36: ='EUR SWAP 3M'!O16 -> 15Y | S36: ='EUR SWAP 3M'!P16 -> 0.00112 | T36: =ABS(P36-S36)*100000 -> 9.0665322e-10
B37: =_xll.meDateFromTenor(AsOfDate,F37,"MOD_FOLLOWING",$C37,"") -> 43991 | C37: =C36 -> TGT | D37: =_xll.meDateFromTenor(B37,G37,) -> 51296 | F37: 2D | G37: =R37 -> 20Y | H37: =Template.Swap.EUR.3M -> EUR_SWAP_3ML:1 | I37: PAY | J37: 1000000 | K37: 0 | L37: 0 | N37: =_xll.meLWOSwapCreateFromGenerator("EUR3M_"&G37,H37,I37,J37,B37,D37,K37,L37) -> EUR3M_20Y:1 | O37: EURYC | P37: =_xll.meLWOSwapParRate(N37,O37) -> 0.00199 | R37: ='EUR SWAP 3M'!O17 -> 20Y | S37: ='EUR SWAP 3M'!P17 -> 0.00199 | T37: =ABS(P37-S37)*100000 -> 9.3449554e-10
B38: =_xll.meDateFromTenor(AsOfDate,F38,"MOD_FOLLOWING",$C38,"") -> 43991 | C38: =C37 -> TGT | D38: =_xll.meDateFromTenor(B38,G38,) -> 53122 | F38: 2D | G38: =R38 -> 25Y | H38: =Template.Swap.EUR.3M -> EUR_SWAP_3ML:1 | I38: PAY | J38: 1000000 | K38: 0 | L38: 0 | N38: =_xll.meLWOSwapCreateFromGenerator("EUR3M_"&G38,H38,I38,J38,B38,D38,K38,L38) -> EUR3M_25Y:1 | O38: EURYC | P38: =_xll.meLWOSwapParRate(N38,O38) -> 0.00207 | R38: ='EUR SWAP 3M'!O18 -> 25Y | S38: ='EUR SWAP 3M'!P18 -> 0.00207 | T38: =ABS(P38-S38)*100000 -> 3.6429193e-11
B39: =_xll.meDateFromTenor(AsOfDate,F39,"MOD_FOLLOWING",$C39,"") -> 43991 | C39: =C38 -> TGT | D39: =_xll.meDateFromTenor(B39,G39,) -> 54948 | F39: 2D | G39: =R39 -> 30Y | H39: =Template.Swap.EUR.3M -> EUR_SWAP_3ML:1 | I39: PAY | J39: 1000000 | K39: 0 | L39: 0 | N39: =_xll.meLWOSwapCreateFromGenerator("EUR3M_"&G39,H39,I39,J39,B39,D39,K39,L39) -> EUR3M_30Y:1 | O39: EURYC | P39: =_xll.meLWOSwapParRate(N39,O39) -> 0.00183 | R39: ='EUR SWAP 3M'!O19 -> 30Y | S39: ='EUR SWAP 3M'!P19 -> 0.00183 | T39: =ABS(P39-S39)*100000 -> 5.8390792e-10
B45: Trade Dates | F45: SWAP: EUR1ML | N45: Trade Booking & Pricing | R45: Curve Calibration Check
D46: Unadjusted Date ! | H46: Swap Template
B47: EffectiveDate | C47: Calendar | D47: MaturityDate | F47: EffectiveDate | G47: Maturity | H47: Generator | I47: PayRec | J47: Notional | K47: Leg 1 Spread | L47: Leg 2 Spread | N47: CreateSwap | O47: CurveCollection | P47: Spread | R47: Term | S47: Rate | T47: +/- Bps
B48: =_xll.meDateFromTenor(AsOfDate,F48,"MOD_FOLLOWING",$C48,"") -> 43991 | C48: =VLOOKUP("PAYMENTCALENDAR",_xll.meLWOSwapGeneratorDisplay($H48),2,FALSE) -> TGT | D48: =_xll.meDateFromTenor(B48,G48,) -> 44356 | F48: 2D | G48: =R48 -> 1Y | H48: =Template.Swap.EUR.1M -> EUR_SWAP_1ML:1 | I48: PAY | J48: 1000000 | K48: 0 | L48: 0 | N48: =_xll.meLWOSwapCreateFromGenerator("EUR1M_"&G48,H48,I48,J48,B48,D48,K48,L48) -> EUR1M_1Y:1 | O48: EURYC | P48: =_xll.meLWOSwapParRate(N48,O48) -> -0.00465 | R48: ='EUR SWAP 1M'!I6 -> 1Y | S48: ='EUR SWAP 1M'!J6 -> -0.00465 | T48: =ABS(P48-S48)*100000 -> 5.976903e-09
B49: =_xll.meDateFromTenor(AsOfDate,F49,"MOD_FOLLOWING",$C49,"") -> 43991 | C49: =C48 -> TGT | D49: =_xll.meDateFromTenor(B49,G49,) -> 44721 | F49: 2D | G49: =R49 -> 2Y | H49: =Template.Swap.EUR.1M -> EUR_SWAP_1ML:1 | I49: PAY | J49: 1000000 | K49: 0 | L49: 0 | N49: =_xll.meLWOSwapCreateFromGenerator("EUR1M_"&G49,H49,I49,J49,B49,D49,K49,L49) -> EUR1M_2Y:1 | O49: EURYC | P49: =_xll.meLWOSwapParRate(N49,O49) -> -0.00455 | R49: ='EUR SWAP 1M'!I7 -> 2Y | S49: ='EUR SWAP 1M'!J7 -> -0.00455 | T49: =ABS(P49-S49)*100000 -> 9.9720579e-10
...
