Workbook

Sheet GBP GLOBAL CURVE
C4: GLOBAL CURVE ENGINE | H4: MARKETDATAPROPERTIES | N4: OIS | T4: LIBOROISBASISSPREADS
C5: Key | D5: Value | H5: Key | I5: Value | N5: Term | O5: Rate | P5: StartDate | Q5: EndDate | R5: Use | T5: Term | U5: Rate
C6: CurveName | D6: GBP_CURVE | H6: Currency | I6: GBP | N6: ON | O6: 0.007104 | R6: TRUE | T6: 1Y | U6: 0.00115
C7: CurveCollection | D7: GBPYC | H7: CurveType | I7: OIS | N7: 1W | O7: 0.00691 | R7: TRUE | T7: 2Y | U7: 0.0012
C8: CurveObject | D8: =_xll.meLWOCurveEngineCalibrate(D6,D7,C12:D15,D19,D26,D20,D27,D21,D28,D22,D29,D23,D30) -> GBP_CURVE@22:16 | H8: CurveIndexFrequency | I8: DAILY | N8: 1M | O8: 0.006 | R8: TRUE | T8: 3Y | U8: 0.00126
H9: AsOfDate | I9: 43854 | N9: 2M | O9: 0.00587 | R9: TRUE | T9: 4Y | U9: 0.0013
N10: 3M | O10: 0.0057 | R10: TRUE | T10: 5Y | U10: 0.00132
C11: CURVE ENGINE PARAMETERS | N11: 4M | O11: 0.00552 | R11: TRUE | T11: 7Y | U11: 0.00137
C12: FastRebuild | D12: TRUE | H12: Create Market Data Handle | N12: 5M | O12: 0.00537 | R12: TRUE | T12: 10Y | U12: 0.00141
C13: Epsilon | D13: 1e-09 | H13: Handle Name | I13: GBP_OIS_MARKETDATA | N13: 6M | O13: 0.00524 | R13: TRUE | T13: 15Y | U13: 0.00145
C14: GradientEpsilon | D14: 1e-15 | H14: Market Data Handle | I14: =_xll.meLWOCurveMarketDataCreate(I13,H4,H6:I9,N4,N6:R20,T4,T6:U20) -> GBP_OIS_MARKETDATA@3:16 | N14: 7M | O14: 0.00511 | R14: TRUE | T14: 20Y | U14: 0.00147
C15: Delta | D15: 1e-10 | N15: 8M | O15: 0.00498 | R15: TRUE | T15: 30Y | U15: 0.00149
N16: 9M | O16: 0.00487 | R16: TRUE | T16: 40Y | U16: 0.00149
N17: 10M | O17: 0.00479 | R17: TRUE | T17: 50Y | U17: 0.00149
C18: CURVE GENERATORS | N18: 11M | O18: 0.00471 | R18: TRUE | T18: 51Y | U18: =U17 -> 0.00149
C19: OIS | D19: GBP_OIS
C20: 1ML | D20: GBP_BASIS_1X3
C21: 3ML | D21: GBP_SWAP_3M
C22: 6ML | D22: GBP_BASIS_3X6
C23: 12ML | D23: GBP_BASIS_6X12
C25: CURVE MARKET DATA | H25: MARKETDATAPROPERTIES | K25: LIBORFIXINGS | N25: FUTURES | T25: SWAPS
C26: OIS | D26: =I14 -> GBP_OIS_MARKETDATA@3:16 | H26: Key | I26: Value | K26: Term | L26: Rate | N26: Term | O26: StartDate | P26: EndDate | Q26: Rate | R26: Volatility | T26: Term | U26: Rate | V26: Use
C27: 1ML | D27: =I57 -> GBP_1M_MARKETDATA@1:16 | H27: Currency | I27: GBP | K27: 1M | L27: 0.0063063 | N27: L 1 Comdty | O27: 43908 | P27: 43999 | Q27: 99.385 | R27: 0.016 | T27: 2Y | U27: 0.00543 | V27: TRUE
C28: 3ML | D28: =I35 -> GBP_3M_MARKETDATA@2:16 | H28: CurveType | I28: SWAP | K28: 3M | L28: 0.0069075 | N28: L 2 Comdty | O28: 43999 | P28: 44090 | Q28: 99.46 | R28: 0.016 | T28: 3Y | U28: 0.00548 | V28: TRUE
C29: 6ML | D29: =I108 -> GBP_6M_MARKETDATA@5:0 | H29: CurveIndexFrequency | I29: QUARTERLY | K29: 6M | L29: 0.007475 | N29: L 3 Comdty | O29: 44090 | P29: 44181 | Q29: 99.495 | R29: 0.016 | T29: 4Y | U29: 0.00562 | V29: TRUE
C30: 12ML | D30: =I82 -> GBP_12M_MARKETDATA@4:16 | H30: AsOfDate | I30: =$I$9 -> 43854 | K30: 12M | L30: 0.0080438 | N30: L 4 Comdty | O30: 44181 | P30: 44272 | Q30: 99.485 | R30: 0.016 | T30: 5Y | U30: 0.00576 | V30: TRUE
T31: 6Y | U31: 0.00593 | V31: TRUE
T32: 7Y | U32: 0.00611 | V32: TRUE
H33: Create Market Data Handle | T33: 8Y | U33: 0.00631 | V33: TRUE
H34: Handle Name | I34: GBP_3M_MARKETDATA | T34: 10Y | U34: 0.00673 | V34: TRUE
H35: Market Data Handle | I35: =_xll.meLWOCurveMarketDataCreate(I34,H25,H27:I31,K25,K27:L31,N25,N27:R42,T25,T27:V42) -> GBP_3M_MARKETDATA@2:16 | T35: 12Y | U35: 0.00712 | V35: TRUE
T36: 15Y | U36: 0.00753 | V36: TRUE
T37: 20Y | U37: 0.0078 | V37: TRUE
T38: 25Y | U38: 0.00782 | V38: TRUE
T39: 30Y | U39: 0.00774 | V39: TRUE
T40: 40Y | U40: 0.00774 | V40: TRUE
T41: 50Y | U41: 0.00774 | V41: TRUE
T42: 51Y | U42: =U41 -> 0.00774 | V42: TRUE
H47: MARKETDATAPROPERTIES | N47: BASISSWAPS
H48: Key | I48: Value | N48: Term | O48: Rate
...

Sheet DISPLAY_CURVE
B2: Forward Curve Display Settings | E2: CurveIndices
B3: CurveCollection | C3: GBPYC | E3: GBPOIS
B4: Start | C4: 0Y | E4: GBP1ML
B5: End | C5: 30Y | E5: GBP3ML
B6: Periodicity | C6: MONTHLY | E6: GBP6ML
E7: GBP12ML
B9: {=_xll.meLWOCurveForwardRatesTable($C$3,$E$3:$E$7,C4,C5,,,,C6)} -> Fixing Dates | C9: GBPOIS | D9: GBP1ML | E9: GBP3ML | F9: GBP6ML | G9: GBP12ML
B10: 43854 | C10: 0.0070310227 | D10: 0.0063063 | E10: 0.0069075 | F10: 0.007475 | G10: 0.0080438
B11: 43885 | C11: 0.0055214585 | D11: 0.0059928305 | E11: 0.0064683654 | F11: 0.0072402981 | G11: 0.0078671955
B12: 43914 | C12: 0.0056493783 | D12: 0.0056425265 | E12: 0.006104587 | F12: 0.0069674754 | G12: 0.0076818843
B13: 43945 | C13: 0.0051357654 | D13: 0.0053123931 | E13: 0.0059084148 | F13: 0.0066603493 | G13: 0.0074552604
B14: 43977 | C14: 0.0048360334 | D14: 0.0050207505 | E14: 0.0055879787 | F14: 0.0063548927 | G14: 0.0072274794
B15: 44006 | C15: 0.0046410763 | D15: 0.0047902878 | E15: 0.0053499658 | F15: 0.0061004296 | G15: 0.0070105317
B16: 44036 | C16: 0.0044605502 | D16: 0.0045790769 | E16: 0.0052740527 | F16: 0.0058745114 | G16: 0.0067825818
B17: 44067 | C17: 0.0041797102 | D17: 0.0044015128 | E17: 0.0051038799 | F17: 0.0057142672 | G17: 0.0065699297
B18: 44098 | C18: 0.0040132517 | D18: 0.0042596686 | E18: 0.0049951137 | F18: 0.0056143789 | G18: 0.0063672578
B19: 44130 | C19: 0.0040355246 | D19: 0.0041563324 | E19: 0.0050650784 | F19: 0.0055612301 | G19: 0.0061825426
B20: 44159 | C20: 0.0039380539 | D20: 0.0040962308 | E20: 0.005040997 | F20: 0.005548251 | G20: 0.0060428212
B21: 44189 | C21: 0.0038924015 | D21: 0.0040672642 | E21: 0.0050339102 | F21: 0.0055602632 | G21: 0.0059321041
... B370: 54812 | C370: 0.0059967382 | D370: 0.00649211 | E370: 0.0073768226 | F370: 0.0084085794 | G370: 0.0092083606
B371: #N/A | C371: #N/A | D371: #N/A | E371: #N/A | F371: #N/A | G371: #N/A
B372: #N/A | C372: #N/A | D372: #N/A | E372: #N/A | F372: #N/A | G372: #N/A
B373: #N/A | C373: #N/A | D373: #N/A | E373: #N/A | F373: #N/A | G373: #N/A
B374: #N/A | C374: #N/A | D374: #N/A | E374: #N/A | F374: #N/A | G374: #N/A
B375: #N/A | C375: #N/A | D375: #N/A | E375: #N/A | F375: #N/A | G375: #N/A
B376: #N/A | C376: #N/A | D376: #N/A | E376: #N/A | F376: #N/A | G376: #N/A
B377: #N/A | C377: #N/A | D377: #N/A | E377: #N/A | F377: #N/A | G377: #N/A
B378: #N/A | C378: #N/A | D378: #N/A | E378: #N/A | F378: #N/A | G378: #N/A
B379: #N/A | C379: #N/A | D379: #N/A | E379: #N/A | F379: #N/A | G379: #N/A
B380: #N/A | C380: #N/A | D380: #N/A | E380: #N/A | F380: #N/A | G380: #N/A
B381: #N/A | C381: #N/A | D381: #N/A | E381: #N/A | F381: #N/A | G381: #N/A
B382: #N/A | C382: #N/A | D382: #N/A | E382: #N/A | F382: #N/A | G382: #N/A
... B501: #N/A | C501: #N/A | D501: #N/A | E501: #N/A | F501: #N/A | G501: #N/A

Sheet PRICING
B2: Trade Dates | F2: SWAPS: GBP3ML | N2: Trade Booking & Pricing | S2: Curve Calibration / Repricing Check
D3: Unadjusted Date ! | H3: Swap Template
B4: EffectiveDate | C4: Calendar | D4: MaturityDate | F4: EffectiveLag | G4: Maturity | H4: Generator | I4: PayRec | J4: Notional | K4: FixedRate | L4: Spread | N4: CreateSwap | O4: CurveCollection | P4: PV | Q4: ParRate
B5: =_xll.meDateFromTenor('GBP GLOBAL CURVE'!$I$9,F5,"MOD_FOLLOWING",C5) -> 43854 | C5: =VLOOKUP("PAYMENTCALENDAR",_xll.meLWOSwapGeneratorDisplay($H5),2,FALSE) -> LNB | D5: =_xll.meDateFromTenor(B5,G5,) -> 44036 | F5: 0D | G5: 6M | H5: GBP_3ML | I5: PAY | J5: 1000000 | K5: 0.01 | L5: 0 | M5: 1 | N5: =_xll.meLWOSwapCreateFromGenerator("GBPSWAP"&M5&"_"&G5,$H5,$I5,$J5,$B$8,$G5,$K5,$L5) -> GBPSWAP1_6M@18:11 | O5: GBPYC | P5: =_xll.meLWOSwapPV(N5,O5) -> -1784.389 | Q5: =_xll.meLWOSwapParRate(N5,O5) -> 0.0064120675 | S5: Futures to 1Y then Swaps from 2Y inclusive
B6: =_xll.meDateFromTenor('GBP GLOBAL CURVE'!$I$9,F6,"MOD_FOLLOWING",C6) -> 43854 | C6: =VLOOKUP("PAYMENTCALENDAR",_xll.meLWOSwapGeneratorDisplay($H6),2,FALSE) -> LNB | D6: =_xll.meDateFromTenor(B6,G6,) -> 44128 | F6: 0D | G6: 9M | H6: GBP_3ML | I6: PAY | J6: 1000000 | K6: 0.01 | L6: 0 | M6: 2 | N6: =_xll.meLWOSwapCreateFromGenerator("GBPSWAP"&M6&"_"&G6,$H6,$I6,$J6,$B$8,$G6,$K6,$L6) -> GBPSWAP2_9M@20:11 | O6: GBPYC | P6: =_xll.meLWOSwapPV(N6,O6) -> -2997.3257 | Q6: =_xll.meLWOSwapParRate(N6,O6) -> 0.0060245083
B7: =_xll.meDateFromTenor('GBP GLOBAL CURVE'!$I$9,F7,"MOD_FOLLOWING",C7) -> 43854 | C7: =VLOOKUP("PAYMENTCALENDAR",_xll.meLWOSwapGeneratorDisplay($H7),2,FALSE) -> LNB | D7: =_xll.meDateFromTenor(B7,G7,) -> 44220 | F7: 0D | G7: 1Y | H7: GBP_3ML | I7: PAY | J7: 1000000 | K7: 0.01 | L7: 0 | M7: 3 | N7: =_xll.meLWOSwapCreateFromGenerator("GBPSWAP"&M7&"_"&G7,$H7,$I7,$J7,$B$8,$G7,$K7,$L7) -> GBPSWAP3_1Y@9:11 | O7: GBPYC | P7: =_xll.meLWOSwapPV(N7,O7) -> -4219.1335 | Q7: =_xll.meLWOSwapParRate(N7,O7) -> 0.0057885525 | S7: Tenor | T7: ParRate | U7: +/- Bps
B8: =_xll.meDateFromTenor('GBP GLOBAL CURVE'!$I$9,F8,"MOD_FOLLOWING",C8) -> 43854 | C8: =VLOOKUP("PAYMENTCALENDAR",_xll.meLWOSwapGeneratorDisplay($H8),2,FALSE) -> LNB | D8: =_xll.meDateFromTenor(B8,G8,) -> 44585 | F8: 0D | G8: 2Y | H8: GBP_3ML | I8: PAY | J8: 1000000 | K8: 0.01 | L8: 0 | M8: 4 | N8: =_xll.meLWOSwapCreateFromGenerator("GBPSWAP"&M8&"_"&G8,$H8,$I8,$J8,$B$8,$G8,$K8,$L8) -> GBPSWAP4_2Y@21:11 | O8: GBPYC | P8: =_xll.meLWOSwapPV(N8,O8) -> -9101.7287 | Q8: =_xll.meLWOSwapParRate(N8,O8) -> 0.00543 | S8: ='GBP GLOBAL CURVE'!T27 -> 2Y | T8: ='GBP GLOBAL CURVE'!U27 -> 0.00543 | U8: =ABS(Q8-T8)*10000 -> 2.6020852e-13
B9: =_xll.meDateFromTenor('GBP GLOBAL CURVE'!$I$9,F9,"MOD_FOLLOWING",C9) -> 43854 | C9: =C8 -> LNB | D9: =_xll.meDateFromTenor(B9,G9,) -> 44950 | F9: 0D | G9: 3Y | H9: GBP_3ML | I9: PAY | J9: 1000000 | K9: 0.01 | L9: 0 | M9: 5 | N9: =_xll.meLWOSwapCreateFromGenerator("GBPSWAP"&M9&"_"&G9,$H9,$I9,$J9,$B$8,$G9,$K9,$L9) -> GBPSWAP5_3Y@14:11 | O9: GBPYC | P9: =_xll.meLWOSwapPV(N9,O9) -> -13470.144 | Q9: =_xll.meLWOSwapParRate(N9,O9) -> 0.00548 | S9: ='GBP GLOBAL CURVE'!T28 -> 3Y | T9: ='GBP GLOBAL CURVE'!U28 -> 0.00548 | U9: =ABS(Q9-T9)*10000 -> 2.8622937e-13
B10: =_xll.meDateFromTenor('GBP GLOBAL CURVE'!$I$9,F10,"MOD_FOLLOWING",C10) -> 43854 | C10: =C9 -> LNB | D10: =_xll.meDateFromTenor(B10,G10,) -> 45315 | F10: 0D | G10: 4Y | H10: GBP_3ML | I10: PAY | J10: 1000000 | K10: 0.01 | L10: 0 | M10: 6 | N10: =_xll.meLWOSwapCreateFromGenerator("GBPSWAP"&M10&"_"&G10,$H10,$I10,$J10,$B$8,$G10,$K10,$L10) -> GBPSWAP6_4Y@13:11 | O10: GBPYC | P10: =_xll.meLWOSwapPV(N10,O10) -> -17362.997 | Q10: =_xll.meLWOSwapParRate(N10,O10) -> 0.00562 | S10: ='GBP GLOBAL CURVE'!T29 -> 4Y | T10: ='GBP GLOBAL CURVE'!U29 -> 0.00562 | U10: =ABS(Q10-T10)*10000 -> 6.0715322e-14
B11: =_xll.meDateFromTenor('GBP GLOBAL CURVE'!$I$9,F11,"MOD_FOLLOWING",C11) -> 43854 | C11: =C10 -> LNB | D11: =_xll.meDateFromTenor(B11,G11,) -> 45681 | F11: 0D | G11: 5Y | H11: GBP_3ML | I11: PAY | J11: 1000000 | K11: 0.01 | L11: 0 | M11: 7 | N11: =_xll.meLWOSwapCreateFromGenerator("GBPSWAP"&M11&"_"&G11,$H11,$I11,$J11,$B$8,$G11,$K11,$L11) -> GBPSWAP7_5Y@11:29 | O11: GBPYC | P11: =_xll.meLWOSwapPV(N11,O11) -> -20971.491 | Q11: =_xll.meLWOSwapParRate(N11,O11) -> 0.00576 | S11: ='GBP GLOBAL CURVE'!T30 -> 5Y | T11: ='GBP GLOBAL CURVE'!U30 -> 0.00576 | U11: =ABS(Q11-T11)*10000 -> 5.2041704e-14
B12: =_xll.meDateFromTenor('GBP GLOBAL CURVE'!$I$9,F12,"MOD_FOLLOWING",C12) -> 43854 | C12: =C11 -> LNB | D12: =_xll.meDateFromTenor(B12,G12,) -> 46046 | F12: 0D | G12: 6Y | H12: GBP_3ML | I12: PAY | J12: 1000000 | K12: 0.01 | L12: 0 | M12: 8 | N12: =_xll.meLWOSwapCreateFromGenerator("GBPSWAP"&M12&"_"&G12,$H12,$I12,$J12,$B$8,$G12,$K12,$L12) -> GBPSWAP8_6Y@17:11 | O12: GBPYC | P12: =_xll.meLWOSwapPV(N12,O12) -> -24117.332 | Q12: =_xll.meLWOSwapParRate(N12,O12) -> 0.00593 | S12: ='GBP GLOBAL CURVE'!T31 -> 6Y | T12: ='GBP GLOBAL CURVE'!U31 -> 0.00593 | U12: =ABS(Q12-T12)*10000 -> 1.3877788e-13
B13: =_xll.meDateFromTenor('GBP GLOBAL CURVE'!$I$9,F13,"MOD_FOLLOWING",C13) -> 43854 | C13: =C12 -> LNB | D13: =_xll.meDateFromTenor(B13,G13,) -> 46411 | F13: 0D | G13: 7Y | H13: GBP_3ML | I13: PAY | J13: 1000000 | K13: 0.01 | L13: 0 | M13: 9 | N13: =_xll.meLWOSwapCreateFromGenerator("GBPSWAP"&M13&"_"&G13,$H13,$I13,$J13,$B$8,$G13,$K13,$L13) -> GBPSWAP9_7Y@8:11 | O13: GBPYC | P13: =_xll.meLWOSwapPV(N13,O13) -> -26808.837 | Q13: =_xll.meLWOSwapParRate(N13,O13) -> 0.00611 | S13: ='GBP GLOBAL CURVE'!T32 -> 7Y | T13: ='GBP GLOBAL CURVE'!U32 -> 0.00611 | U13: =ABS(Q13-T13)*10000 -> 1.2143064e-13
B14: =_xll.meDateFromTenor('GBP GLOBAL CURVE'!$I$9,F14,"MOD_FOLLOWING",C14) -> 43854 | C14: =C13 -> LNB | D14: =_xll.meDateFromTenor(B14,G14,) -> 46776 | F14: 0D | G14: 8Y | H14: GBP_3ML | I14: PAY | J14: 1000000 | K14: 0.01 | L14: 0 | M14: 10 | N14: =_xll.meLWOSwapCreateFromGenerator("GBPSWAP"&M14&"_"&G14,$H14,$I14,$J14,$B$8,$G14,$K14,$L14) -> GBPSWAP10_8Y@12:11 | O14: GBPYC | P14: =_xll.meLWOSwapPV(N14,O14) -> -28973.71 | Q14: =_xll.meLWOSwapParRate(N14,O14) -> 0.00631 | S14: ='GBP GLOBAL CURVE'!T33 -> 8Y | T14: ='GBP GLOBAL CURVE'!U33 -> 0.00631 | U14: =ABS(Q14-T14)*10000 -> 8.6736174e-14
B15: =_xll.meDateFromTenor('GBP GLOBAL CURVE'!$I$9,F15,"MOD_FOLLOWING",C15) -> 43854 | C15: =C14 -> LNB | D15: =_xll.meDateFromTenor(B15,G15,) -> 47507 | F15: 0D | G15: 10Y | H15: GBP_3ML | I15: PAY | J15: 1000000 | K15: 0.01 | L15: 0 | M15: 11 | N15: =_xll.meLWOSwapCreateFromGenerator("GBPSWAP"&M15&"_"&G15,$H15,$I15,$J15,$B$8,$G15,$K15,$L15) -> GBPSWAP11_10Y@7:11 | O15: GBPYC | P15: =_xll.meLWOSwapPV(N15,O15) -> -31918.054 | Q15: =_xll.meLWOSwapParRate(N15,O15) -> 0.00673 | S15: ='GBP GLOBAL CURVE'!T34 -> 10Y | T15: ='GBP GLOBAL CURVE'!U34 -> 0.00673 | U15: =ABS(Q15-T15)*10000 -> 2.0816682e-13
B16: =_xll.meDateFromTenor('GBP GLOBAL CURVE'!$I$9,F16,"MOD_FOLLOWING",C16) -> 43854 | C16: =C15 -> LNB | D16: =_xll.meDateFromTenor(B16,G16,) -> 48237 | F16: 0D | G16: 12Y | H16: GBP_3ML | I16: PAY | J16: 1000000 | K16: 0.01 | L16: 0 | M16: 12 | N16: =_xll.meLWOSwapCreateFromGenerator("GBPSWAP"&M16&"_"&G16,$H16,$I16,$J16,$B$8,$G16,$K16,$L16) -> GBPSWAP12_12Y@10:11 | O16: GBPYC | P16: =_xll.meLWOSwapPV(N16,O16) -> -33536.104 | Q16: =_xll.meLWOSwapParRate(N16,O16) -> 0.00712 | S16: ='GBP GLOBAL CURVE'!T35 -> 12Y | T16: ='GBP GLOBAL CURVE'!U35 -> 0.00712 | U16: =ABS(Q16-T16)*10000 -> 2.2551405e-13
B17: =_xll.meDateFromTenor('GBP GLOBAL CURVE'!$I$9,F17,"MOD_FOLLOWING",C17) -> 43854 | C17: =C16 -> LNB | D17: =_xll.meDateFromTenor(B17,G17,) -> 49333 | F17: 0D | G17: 15Y | H17: GBP_3ML | I17: PAY | J17: 1000000 | K17: 0.01 | L17: 0 | M17: 13 | N17: =_xll.meLWOSwapCreateFromGenerator("GBPSWAP"&M17&"_"&G17,$H17,$I17,$J17,$B$8,$G17,$K17,$L17) -> GBPSWAP13_15Y@19:11 | O17: GBPYC | P17: =_xll.meLWOSwapPV(N17,O17) -> -35582.371 | Q17: =_xll.meLWOSwapParRate(N17,O17) -> 0.00753 | S17: ='GBP GLOBAL CURVE'!T36 -> 15Y | T17: ='GBP GLOBAL CURVE'!U36 -> 0.00753 | U17: =ABS(Q17-T17)*10000 -> 2.6020852e-14
B18: =_xll.meDateFromTenor('GBP GLOBAL CURVE'!$I$9,F18,"MOD_FOLLOWING",C18) -> 43854 | C18: =C17 -> LNB | D18: =_xll.meDateFromTenor(B18,G18,) -> 51159 | F18: 0D | G18: 20Y | H18: GBP_3ML | I18: PAY | J18: 1000000 | K18: 0.01 | L18: 0 | M18: 14 | N18: =_xll.meLWOSwapCreateFromGenerator("GBPSWAP"&M18&"_"&G18,$H18,$I18,$J18,$B$8,$G18,$K18,$L18) -> GBPSWAP14_20Y@15:11 | O18: GBPYC | P18: =_xll.meLWOSwapPV(N18,O18) -> -41536.723 | Q18: =_xll.meLWOSwapParRate(N18,O18) -> 0.0078 | S18: ='GBP GLOBAL CURVE'!T37 -> 20Y | T18: ='GBP GLOBAL CURVE'!U37 -> 0.0078 | U18: =ABS(Q18-T18)*10000 -> 2.4286129e-13
B19: =_xll.meDateFromTenor('GBP GLOBAL CURVE'!$I$9,F19,"MOD_FOLLOWING",C19) -> 43854 | C19: =C18 -> LNB | D19: =_xll.meDateFromTenor(B19,G19,) -> 52986 | F19: 0D | G19: 25Y | H19: GBP_3ML | I19: PAY | J19: 1000000 | K19: 0.01 | L19: 0 | M19: 15 | N19: =_xll.meLWOSwapCreateFromGenerator("GBPSWAP"&M19&"_"&G19,$H19,$I19,$J19,$B$8,$G19,$K19,$L19) -> GBPSWAP15_25Y@6:11 | O19: GBPYC | P19: =_xll.meLWOSwapPV(N19,O19) -> -50601.977 | Q19: =_xll.meLWOSwapParRate(N19,O19) -> 0.00782 | S19: ='GBP GLOBAL CURVE'!T38 -> 25Y | T19: ='GBP GLOBAL CURVE'!U38 -> 0.00782 | U19: =ABS(Q19-T19)*10000 -> 3.469447e-14
B20: =_xll.meDateFromTenor('GBP GLOBAL CURVE'!$I$9,F20,"MOD_FOLLOWING",C20) -> 43854 | C20: =C19 -> LNB | D20: =_xll.meDateFromTenor(B20,G20,) -> 54812 | F20: 0D | G20: 30Y | H20: GBP_3ML | I20: PAY | J20: 1000000 | K20: 0.01 | L20: 0 | M20: 16 | N20: =_xll.meLWOSwapCreateFromGenerator("GBPSWAP"&M20&"_"&G20,$H20,$I20,$J20,$B$8,$G20,$K20,$L20) -> GBPSWAP16_30Y@16:11 | O20: GBPYC | P20: =_xll.meLWOSwapPV(N20,O20) -> -61954.327 | Q20: =_xll.meLWOSwapParRate(N20,O20) -> 0.00774 | S20: ='GBP GLOBAL CURVE'!T39 -> 30Y | T20: ='GBP GLOBAL CURVE'!U39 -> 0.00774 | U20: =ABS(Q20-T20)*10000 -> 1.2143064e-13

Sheet RISK
B2: SwapNames | C2: Curves | D2: Tenor | E2: Include | G2: Risk
A3: 1 | B3: =IF($E3,PRICING!$N5,"") | C3: =IF($E3,"GBPYC","") | D3: =PRICING!$G5 -> 6M | E3: FALSE | G3: {=_xll.meUtilityResize(_xll.meLWOSwapDeltaLadder(_xll.meUtilityClean(B3:B18),_xll.meUtilityClean(C3:C18)),100,10)} -> GBP : Pillars | H3: GBP : Total | I3: GBP : Pillars | J3: GBP : Total
A4: =A3+1 -> 2 | B4: =IF($E4,PRICING!$N6,"") | C4: =IF($E4,"GBPYC","") | D4: =PRICING!$G6 -> 9M | E4: FALSE | G4: GBPYC.OIS.OUTRIGHTOISSWAP.ON | H4: 6.1918399e-07 | I4: GBPYC.STD.O_N | J4: 1.8189894e-09
A5: =A4+1 -> 3 | B5: =IF($E5,PRICING!$N7,"") | C5: =IF($E5,"GBPYC","") | D5: =PRICING!$G7 -> 1Y | E5: FALSE | G5: GBPYC.OIS.OUTRIGHTOISSWAP.1W | H5: -7.4578566e-08 | I5: GBPYC.STD.T_N | J5: 2.401066e-08
A6: =A5+1 -> 4 | B6: =IF($E6,PRICING!$N8,"") | C6: =IF($E6,"GBPYC","") | D6: =PRICING!$G8 -> 2Y | E6: FALSE | G6: GBPYC.OIS.OUTRIGHTOISSWAP.1M | H6: 5.9226295e-07 | I6: GBPYC.STD.LIBOR.1M | J6: -4.1836756e-08
A7: =A6+1 -> 5 | B7: =IF($E7,PRICING!$N9,"") | C7: =IF($E7,"GBPYC","") | D7: =PRICING!$G9 -> 3Y | E7: FALSE | G7: GBPYC.OIS.OUTRIGHTOISSWAP.2M | H7: -1.0899385e-06 | I7: GBPYC.STD.LIBOR.3M | J7: 0.16497424
A8: =A7+1 -> 6 | B8: =IF($E8,PRICING!$N10,"") | C8: =IF($E8,"GBPYC","") | D8: =PRICING!$G10 -> 4Y | E8: FALSE | G8: GBPYC.OIS.OUTRIGHTOISSWAP.3M | H8: -0.00011570082 | I8: GBPYC.STD.LIBOR.6M | J8: -2.9667717e-06
A9: =A8+1 -> 7 | B9: =IF($E9,PRICING!$N11,"") -> GBPSWAP7_5Y@11:29 | C9: =IF($E9,"GBPYC","") -> GBPYC | D9: =PRICING!$G11 -> 5Y | E9: TRUE | G9: GBPYC.OIS.OUTRIGHTOISSWAP.4M | H9: 1.8117862e-05 | I9: GBPYC.STD.LIBOR.12M | J9: 2.1827873e-09
A10: =A9+1 -> 8 | B10: =IF($E10,PRICING!$N12,"") | C10: =IF($E10,"GBPYC","") | D10: =PRICING!$G12 -> 6Y | E10: FALSE | G10: GBPYC.OIS.OUTRIGHTOISSWAP.5M | H10: -7.0809256e-05 | I10: GBPYC.STD.FUTURE.L 1 COMDTY.20200318.20200617 | J10: 0.099128288
A11: =A10+1 -> 9 | B11: =IF($E11,PRICING!$N13,"") | C11: =IF($E11,"GBPYC","") | D11: =PRICING!$G13 -> 7Y | E11: FALSE | G11: GBPYC.OIS.OUTRIGHTOISSWAP.6M | H11: 0.10289198 | I11: GBPYC.STD.FUTURE.L 2 COMDTY.20200617.20200916 | J11: 0.16696184
A12: =A11+1 -> 10 | B12: =IF($E12,PRICING!$N14,"") | C12: =IF($E12,"GBPYC","") | D12: =PRICING!$G14 -> 8Y | E12: FALSE | G12: GBPYC.OIS.OUTRIGHTOISSWAP.7M | H12: -0.0013713954 | I12: GBPYC.STD.FUTURE.L 3 COMDTY.20200916.20201216 | J12: 0.19157884
A13: =A12+1 -> 11 | B13: =IF($E13,PRICING!$N15,"") | C13: =IF($E13,"GBPYC","") | D13: =PRICING!$G15 -> 10Y | E13: FALSE | G13: GBPYC.OIS.OUTRIGHTOISSWAP.8M | H13: 0.005624882 | I13: GBPYC.STD.FUTURE.L 4 COMDTY.20201216.20210317 | J13: 0.067665813
A14: =A13+1 -> 12 | B14: =IF($E14,PRICING!$N16,"") | C14: =IF($E14,"GBPYC","") | D14: =PRICING!$G16 -> 12Y | E14: FALSE | G14: GBPYC.OIS.OUTRIGHTOISSWAP.9M | H14: -0.026291632 | I14: GBPYC.STD.3MLIBORSWAP.2Y | J14: 0.83428496
A15: =A14+1 -> 13 | B15: =IF($E15,PRICING!$N17,"") | C15: =IF($E15,"GBPYC","") | D15: =PRICING!$G17 -> 15Y | E15: FALSE | G15: GBPYC.OIS.OUTRIGHTOISSWAP.10M | H15: 0.1077627 | I15: GBPYC.STD.3MLIBORSWAP.3Y | J15: 1.2218857
... A18: =A17+1 -> 16 | B18: =IF($E18,PRICING!$N20,"") | C18: =IF($E18,"GBPYC","") | D18: =PRICING!$G20 -> 30Y | E18: FALSE | G18: GBPYC.OIS.BASISRATE.2Y | H18: -0.84333572 | I18: GBPYC.STD.3MLIBORSWAP.6Y | J18: -0.0034527919
G19: GBPYC.OIS.BASISRATE.3Y | H19: -1.2246925 | I19: GBPYC.STD.3MLIBORSWAP.7Y | J19: -0.037963742
G20: GBPYC.OIS.BASISRATE.4Y | H20: -1.7831317 | I20: GBPYC.STD.3MLIBORSWAP.8Y | J20: -0.0015248199
G21: GBPYC.OIS.BASISRATE.5Y | H21: -1.4895832 | I21: GBPYC.STD.3MLIBORSWAP.10Y | J21: 0.0050878141
G22: GBPYC.OIS.BASISRATE.7Y | H22: 0.041557604 | I22: GBPYC.STD.3MLIBORSWAP.12Y | J22: 0.0074419262
G23: GBPYC.OIS.BASISRATE.10Y | H23: -0.0083742227 | I23: GBPYC.STD.3MLIBORSWAP.15Y | J23: -0.0080294325
G24: GBPYC.OIS.BASISRATE.15Y | H24: 0.0019591924 | I24: GBPYC.STD.3MLIBORSWAP.20Y | J24: -0.00054982047
G25: GBPYC.OIS.BASISRATE.20Y | H25: -0.00079909732 | I25: GBPYC.STD.3MLIBORSWAP.25Y | J25: 0.0046456622
G26: GBPYC.OIS.BASISRATE.30Y | H26: 0.00012199343 | I26: GBPYC.STD.3MLIBORSWAP.30Y | J26: -0.0072261671
G27: GBPYC.OIS.BASISRATE.40Y | H27: -3.4738696e-05 | I27: GBPYC.STD.3MLIBORSWAP.40Y | J27: 0.0069806363
G28: GBPYC.OIS.BASISRATE.50Y | H28: 4.3975888e-05 | I28: GBPYC.STD.3MLIBORSWAP.50Y | J28: -4.3670298e-05
G29: GBPYC.OIS.BASISRATE.51Y | H29: -3.3962715e-05 | I29: GBPYC.STD.3MLIBORSWAP.51Y | J29: 3.3485048e-05
