Workbook

Sheet USD GLOBAL CURVE
C4: GLOBAL CURVE ENGINE | H4: MARKETDATAPROPERTIES | N4: OIS | T4: LIBOROISBASISSPREADS
C5: Key | D5: Value | H5: Key | I5: Value | N5: Term | O5: Rate | P5: StartDate | Q5: EndDate | R5: Use | T5: Term | U5: Rate
C6: CurveName | D6: USD_CURVE | H6: Currency | I6: USD | N6: ON | O6: 0.0191 | R6: TRUE | T6: 1Y | U6: 0.00275
C7: CurveCollection | D7: USDYC | H7: CurveType | I7: OIS | N7: 3M | O7: 0.020475 | R7: TRUE | T7: 2Y | U7: 0.002875
C8: CurveObject | D8: =_xll.meLWOCurveEngineCalibrate(D6,D7,C12:D15,D20,D26,D21,D27) -> USD_CURVE@10:31 | H8: CurveIndexFrequency | I8: DAILY | N8: 6M | O8: 0.021611 | R8: TRUE | T8: 3Y | U8: 0.00296875
H9: AsOfDate | I9: 43327 | T9: 4Y | U9: 0.0030625
T10: 5Y | U10: 0.003125
C11: CURVE ENGINE PARAMETERS | T11: 7Y | U11: 0.00318125
C12: FastRebuild | D12: TRUE | H12: Create Market Data Handle | T12: 10Y | U12: 0.003375
C13: Epsilon | D13: 1e-09 | H13: Handle Name | I13: USD_OIS_MARKETDATA | T13: 12Y | U13: 0.003463
C14: GradientEpsilon | D14: 1e-15 | H14: Market Data Handle | I14: =_xll.meLWOCurveMarketDataCreate(I13,H4,H6:I9,N4,N6:R20,T4,T6:U20) -> USD_OIS_MARKETDATA@7:31 | T14: 15Y | U14: 0.0035875
C15: Delta | D15: 1e-10 | T15: 20Y | U15: 0.0037625
T16: 25Y | U16: 0.00385
T17: 30Y | U17: 0.00395
T18: 40Y | U18: 0.00395
C19: CURVE GENERATORS | T19: 50Y | U19: 0.00395
C20: OIS | D20: =H44 -> USD_OIS_NEW_GENERATOR@6:31 | T20: 51Y | U20: 0.00395 | V20: Extrapolation Point
C21: 3ML | D21: =N44 -> USD_SWAP_NEW_GENERATOR@9:29
C25: CURVE MARKET DATA | H25: MARKETDATAPROPERTIES | K25: LIBORFIXINGS | N25: FUTURES | T25: SWAPS
C26: OIS | D26: =I14 -> USD_OIS_MARKETDATA@7:31 | H26: Key | I26: Value | K26: Term | L26: Rate | N26: Term | O26: StartDate | P26: EndDate | Q26: Rate | R26: Volatility | T26: Term | U26: Rate | V26: Use
C27: 3ML | D27: =I35 -> USD_3M_MARKETDATA@8:31 | H27: Currency | I27: USD | K27: 3M | L27: 0.0231175 | N27: ED1 Comdty | O27: 43362 | P27: 43453 | Q27: 97.64 | R27: 0.0145 | T27: 4Y | U27: 0.02868 | V27: TRUE
H28: CurveType | I28: SWAP | N28: ED2 Comdty | O28: 43453 | P28: 43544 | Q28: 97.39 | R28: 0.0145 | T28: 5Y | U28: 0.028729 | V28: TRUE
H29: CurveIndexFrequency | I29: QUARTERLY | N29: ED3 Comdty | O29: 43544 | P29: 43635 | Q29: 97.25 | R29: 0.0145 | T29: 7Y | U29: 0.02891 | V29: TRUE
H30: AsOfDate | I30: 43327 | N30: ED4 Comdty | O30: 43635 | P30: 43726 | Q30: 97.14 | R30: 0.0145 | T30: 8Y | U30: 0.029014 | V30: TRUE
C31: SELECT INTERPOLATION | N31: ED5 Comdty | O31: 43726 | P31: 43817 | Q31: 97.075 | R31: 0.0145 | T31: 9Y | U31: 0.029145 | V31: TRUE
N32: ED6 Comdty | O32: 43817 | P32: 43908 | Q32: 97.04 | R32: 0.0145 | T32: 10Y | U32: 0.02928 | V32: TRUE
C33: OIS CURVE | H33: Create Market Data Handle | N33: ED7 Comdty | O33: 43908 | P33: 43999 | Q33: 97.035 | R33: 0.0145 | T33: 12Y | U33: 0.029523 | V33: TRUE
C34: FN_SPLINEINTERPOLATION | H34: Handle Name | I34: USD_3M_MARKETDATA | N34: ED8 Comdty | O34: 43999 | P34: 44090 | Q34: 97.03 | R34: 0.0145 | T34: 15Y | U34: 0.029728 | V34: TRUE
H35: Market Data Handle | I35: =_xll.meLWOCurveMarketDataCreate(I34,H25,H27:I31,K25,K27:L31,N25,N27:R40,T25,T27:V40) -> USD_3M_MARKETDATA@8:31 | N35: ED9 Comdty | O35: 44090 | P35: 44181 | Q35: 97.025 | R35: 0.0145 | T35: 20Y | U35: 0.029833 | V35: TRUE
C36: SWAP CURVE | N36: ED10 Comdty | O36: 44181 | P36: 44272 | Q36: 97.02 | R36: 0.0145 | T36: 25Y | U36: 0.02975 | V36: TRUE
C37: FN_LINEARMONOTONEPARABOLICINTERPOLATION | N37: ED11 Comdty | O37: 44272 | P37: 44363 | Q37: 97.015 | R37: 0.0145 | T37: 30Y | U37: 0.029618 | V37: TRUE
N38: ED12 Comdty | O38: 44363 | P38: 44454 | Q38: 97.02 | R38: 0.0145 | T38: 40Y | U38: 0.029618 | V38: TRUE
T39: 50Y | U39: 0.029618 | V39: TRUE
T40: 51Y | U40: =U39 -> 0.029618 | V40: TRUE | W40: Extrapolation Point
H43: USD_OIS_NEW_GENERATOR | N43: USD_SWAP_NEW_GENERATOR
H44: =_xll.meLWOCurveGeneratorCreate(H43,H47,H48:I54,H56,H57:I73,H75,H76:I79,H81,H82:I85) -> USD_OIS_NEW_GENERATOR@6:31 | N44: =_xll.meLWOCurveGeneratorCreate(N43,N47,N48:O61,N63,N64:O66,N68,N69:O73,N75,N76:O76,N78,N79:O85,N87,N88:O100) -> USD_SWAP_NEW_GENERATOR@9:29
C46: INTERPOLATIONMETHODS
C47: FN_LINEARINTERPOLATION | H47: CURVEPROPERTIES | N47: CURVEPROPERTIES
C48: FN_SPLINEINTERPOLATION | H48: CurveType | I48: OIS | N48: CurveType | O48: SWAP
C49: FN_MONOTONESPLINEINTERPOLATION | H49: CurveIndexFrequency | I49: DAILY | N49: CurveIndexFrequency | O49: QUARTERLY
...

Sheet DISPLAY_CURVE
B2: Forward Curve Display Settings | E2: CurveIndices
B3: CurveCollection | C3: USDYC | E3: USDOIS
B4: Start | C4: 0Y | E4: USD3ML
B5: End | C5: 10Y
B6: Periodicity | C6: WEEKLY
B9: {=_xll.meLWOCurveForwardRatesTable($C$3,$E$3:$E$4,C4,C5,,,,C6)} -> Fixing Dates | C9: USDOIS | D9: USD3ML
B10: 43327 | C10: 0.0191 | D10: 0.023088467
B11: 43333 | C11: 0.019245755 | D11: 0.023175567
B12: 43340 | C12: 0.019456813 | D12: 0.023277184
B13: 43347 | C13: 0.019665569 | D13: 0.023378801
B14: 43354 | C14: 0.019872022 | D14: 0.023480418
B15: 43361 | C15: 0.020076171 | D15: 0.023582036
B16: 43368 | C16: 0.020278014 | D16: 0.02376116
B17: 43375 | C17: 0.02047755 | D17: 0.023953201
B18: 43382 | C18: 0.020674777 | D18: 0.024145243
B19: 43389 | C19: 0.020869693 | D19: 0.024337285
B20: 43396 | C20: 0.021062298 | D20: 0.024529327
B21: 43403 | C21: 0.021252589 | D21: 0.024721369
... B501: 46763 | C501: 0.025932331 | D501: 0.030070358

Sheet PRICING
B2: Trade Dates | F2: SWAPS: USD3ML | N2: Trade Booking & Pricing | S2: Curve Calibration / Repricing Check
D3: Unadjusted Date ! | H3: Swap Template
B4: EffectiveDate | C4: Calendar | D4: MaturityDate | F4: EffectiveLag | G4: Maturity | H4: Generator | I4: PayRec | J4: Notional | K4: FixedRate | L4: Spread | N4: CreateSwap | O4: CurveCollection | P4: PV | Q4: ParRate
B5: =_xll.meDateFromTenor('USD GLOBAL CURVE'!$I$9,F5,"MOD_FOLLOWING",C5) -> 43329 | C5: =VLOOKUP("PAYMENTCALENDAR",_xll.meLWOSwapGeneratorDisplay($H5),2,FALSE) -> NYB:LNB | D5: =_xll.meDateFromTenor(B5,G5,) -> 43694 | F5: 2D | G5: 1Y | H5: USD_3ML | I5: PAY | J5: 1000000 | K5: 0.01 | L5: 0 | M5: 1 | N5: =_xll.meLWOSwapCreateFromGenerator("USDSWAP"&M5&"_"&G5,$H5,$I5,$J5,$B$8,$G5,$K5,$L5) -> USDSWAP1_1Y@5:1 | O5: USDYC | P5: =_xll.meLWOSwapPV(N5,O5) -> 16097.643 | Q5: =_xll.meLWOSwapParRate(N5,O5) -> 0.026289384 | S5: Futures to 3Y then Swaps from 4Y inclusive
B6: =_xll.meDateFromTenor('USD GLOBAL CURVE'!$I$9,F6,"MOD_FOLLOWING",C6) -> 43329 | C6: =VLOOKUP("PAYMENTCALENDAR",_xll.meLWOSwapGeneratorDisplay($H6),2,FALSE) -> NYB:LNB | D6: =_xll.meDateFromTenor(B6,G6,) -> 44060 | F6: 2D | G6: 2Y | H6: USD_3ML | I6: PAY | J6: 1000000 | K6: 0.01 | L6: 0 | M6: 2 | N6: =_xll.meLWOSwapCreateFromGenerator("USDSWAP"&M6&"_"&G6,$H6,$I6,$J6,$B$8,$G6,$K6,$L6) -> USDSWAP2_2Y@11:1 | O6: USDYC | P6: =_xll.meLWOSwapPV(N6,O6) -> 34966.028 | Q6: =_xll.meLWOSwapParRate(N6,O6) -> 0.028018948
B7: =_xll.meDateFromTenor('USD GLOBAL CURVE'!$I$9,F7,"MOD_FOLLOWING",C7) -> 43329 | C7: =VLOOKUP("PAYMENTCALENDAR",_xll.meLWOSwapGeneratorDisplay($H7),2,FALSE) -> NYB:LNB | D7: =_xll.meDateFromTenor(B7,G7,) -> 44425 | F7: 2D | G7: 3Y | H7: USD_3ML | I7: PAY | J7: 1000000 | K7: 0.01 | L7: 0 | M7: 3 | N7: =_xll.meLWOSwapCreateFromGenerator("USDSWAP"&M7&"_"&G7,$H7,$I7,$J7,$B$8,$G7,$K7,$L7) -> USDSWAP3_3Y@9:1 | O7: USDYC | P7: =_xll.meLWOSwapPV(N7,O7) -> 53331.778 | Q7: =_xll.meLWOSwapParRate(N7,O7) -> 0.02856277 | S7: Tenor | T7: ParRate | U7: +/- Bps
B8: =_xll.meDateFromTenor('USD GLOBAL CURVE'!$I$9,F8,"MOD_FOLLOWING",C8) -> 43329 | C8: =VLOOKUP("PAYMENTCALENDAR",_xll.meLWOSwapGeneratorDisplay($H8),2,FALSE) -> NYB:LNB | D8: =_xll.meDateFromTenor(B8,G8,) -> 44790 | F8: 2D | G8: 4Y | H8: USD_3ML | I8: PAY | J8: 1000000 | K8: 0.01 | L8: 0 | M8: 4 | N8: =_xll.meLWOSwapCreateFromGenerator("USDSWAP"&M8&"_"&G8,$H8,$I8,$J8,$B$8,$G8,$K8,$L8) -> USDSWAP4_4Y@13:1 | O8: USDYC | P8: =_xll.meLWOSwapPV(N8,O8) -> 70647.406 | Q8: =_xll.meLWOSwapParRate(N8,O8) -> 0.02868 | S8: ='USD GLOBAL CURVE'!T27 -> 4Y | T8: ='USD GLOBAL CURVE'!U27 -> 0.02868 | U8: =ABS(Q8-T8)*10000 -> 3.5735304e-12
B9: =_xll.meDateFromTenor('USD GLOBAL CURVE'!$I$9,F9,"MOD_FOLLOWING",C9) -> 43329 | C9: =C8 -> NYB:LNB | D9: =_xll.meDateFromTenor(B9,G9,) -> 45155 | F9: 2D | G9: 5Y | H9: USD_3ML | I9: PAY | J9: 1000000 | K9: 0.01 | L9: 0 | M9: 5 | N9: =_xll.meLWOSwapCreateFromGenerator("USDSWAP"&M9&"_"&G9,$H9,$I9,$J9,$B$8,$G9,$K9,$L9) -> USDSWAP5_5Y@14:1 | O9: USDYC | P9: =_xll.meLWOSwapPV(N9,O9) -> 87430.508 | Q9: =_xll.meLWOSwapParRate(N9,O9) -> 0.028729 | S9: ='USD GLOBAL CURVE'!T28 -> 5Y | T9: ='USD GLOBAL CURVE'!U28 -> 0.028729 | U9: =ABS(Q9-T9)*10000 -> 1.8388069e-12
B10: =_xll.meDateFromTenor('USD GLOBAL CURVE'!$I$9,F10,"MOD_FOLLOWING",C10) -> 43329 | C10: =C9 -> NYB:LNB | D10: =_xll.meDateFromTenor(B10,G10,) -> 45886 | F10: 2D | G10: 7Y | H10: USD_3ML | I10: PAY | J10: 1000000 | K10: 0.01 | L10: 0 | M10: 6 | N10: =_xll.meLWOSwapCreateFromGenerator("USDSWAP"&M10&"_"&G10,$H10,$I10,$J10,$B$8,$G10,$K10,$L10) -> USDSWAP6_7Y@17:1 | O10: USDYC | P10: =_xll.meLWOSwapPV(N10,O10) -> 120569.48 | Q10: =_xll.meLWOSwapParRate(N10,O10) -> 0.02891 | S10: ='USD GLOBAL CURVE'!T29 -> 7Y | T10: ='USD GLOBAL CURVE'!U29 -> 0.02891 | U10: =ABS(Q10-T10)*10000 -> 3.3306691e-12
B11: =_xll.meDateFromTenor('USD GLOBAL CURVE'!$I$9,F11,"MOD_FOLLOWING",C11) -> 43329 | C11: =C10 -> NYB:LNB | D11: =_xll.meDateFromTenor(B11,G11,) -> 46251 | F11: 2D | G11: 8Y | H11: USD_3ML | I11: PAY | J11: 1000000 | K11: 0.01 | L11: 0 | M11: 7 | N11: =_xll.meLWOSwapCreateFromGenerator("USDSWAP"&M11&"_"&G11,$H11,$I11,$J11,$B$8,$G11,$K11,$L11) -> USDSWAP7_8Y@18:1 | O11: USDYC | P11: =_xll.meLWOSwapPV(N11,O11) -> 136783.07 | Q11: =_xll.meLWOSwapParRate(N11,O11) -> 0.029014 | S11: ='USD GLOBAL CURVE'!T30 -> 8Y | T11: ='USD GLOBAL CURVE'!U30 -> 0.029014 | U11: =ABS(Q11-T11)*10000 -> 2.8449465e-12
B12: =_xll.meDateFromTenor('USD GLOBAL CURVE'!$I$9,F12,"MOD_FOLLOWING",C12) -> 43329 | C12: =C11 -> NYB:LNB | D12: =_xll.meDateFromTenor(B12,G12,) -> 46616 | F12: 2D | G12: 9Y | H12: USD_3ML | I12: PAY | J12: 1000000 | K12: 0.01 | L12: 0 | M12: 8 | N12: =_xll.meLWOSwapCreateFromGenerator("USDSWAP"&M12&"_"&G12,$H12,$I12,$J12,$B$8,$G12,$K12,$L12) -> USDSWAP8_9Y@12:1 | O12: USDYC | P12: =_xll.meLWOSwapPV(N12,O12) -> 153023.75 | Q12: =_xll.meLWOSwapParRate(N12,O12) -> 0.029145 | S12: ='USD GLOBAL CURVE'!T31 -> 9Y | T12: ='USD GLOBAL CURVE'!U31 -> 0.029145 | U12: =ABS(Q12-T12)*10000 -> 2.2551405e-12
B13: =_xll.meDateFromTenor('USD GLOBAL CURVE'!$I$9,F13,"MOD_FOLLOWING",C13) -> 43329 | C13: =C12 -> NYB:LNB | D13: =_xll.meDateFromTenor(B13,G13,) -> 46982 | F13: 2D | G13: 10Y | H13: USD_3ML | I13: PAY | J13: 1000000 | K13: 0.01 | L13: 0 | M13: 9 | N13: =_xll.meLWOSwapCreateFromGenerator("USDSWAP"&M13&"_"&G13,$H13,$I13,$J13,$B$8,$G13,$K13,$L13) -> USDSWAP9_10Y@16:1 | O13: USDYC | P13: =_xll.meLWOSwapPV(N13,O13) -> 169109.21 | Q13: =_xll.meLWOSwapParRate(N13,O13) -> 0.02928 | S13: ='USD GLOBAL CURVE'!T32 -> 10Y | T13: ='USD GLOBAL CURVE'!U32 -> 0.02928 | U13: =ABS(Q13-T13)*10000 -> 2.0816682e-12
B14: =_xll.meDateFromTenor('USD GLOBAL CURVE'!$I$9,F14,"MOD_FOLLOWING",C14) -> 43329 | C14: =C13 -> NYB:LNB | D14: =_xll.meDateFromTenor(B14,G14,) -> 47712 | F14: 2D | G14: 12Y | H14: USD_3ML | I14: PAY | J14: 1000000 | K14: 0.01 | L14: 0 | M14: 10 | N14: =_xll.meLWOSwapCreateFromGenerator("USDSWAP"&M14&"_"&G14,$H14,$I14,$J14,$B$8,$G14,$K14,$L14) -> USDSWAP10_12Y@15:1 | O14: USDYC | P14: =_xll.meLWOSwapPV(N14,O14) -> 200520.59 | Q14: =_xll.meLWOSwapParRate(N14,O14) -> 0.029523 | S14: ='USD GLOBAL CURVE'!T33 -> 12Y | T14: ='USD GLOBAL CURVE'!U33 -> 0.029523 | U14: =ABS(Q14-T14)*10000 -> 1.6653345e-12
B15: =_xll.meDateFromTenor('USD GLOBAL CURVE'!$I$9,F15,"MOD_FOLLOWING",C15) -> 43329 | C15: =C14 -> NYB:LNB | D15: =_xll.meDateFromTenor(B15,G15,) -> 48808 | F15: 2D | G15: 15Y | H15: USD_3ML | I15: PAY | J15: 1000000 | K15: 0.01 | L15: 0 | M15: 11 | N15: =_xll.meLWOSwapCreateFromGenerator("USDSWAP"&M15&"_"&G15,$H15,$I15,$J15,$B$8,$G15,$K15,$L15) -> USDSWAP11_15Y@19:1 | O15: USDYC | P15: =_xll.meLWOSwapPV(N15,O15) -> 243978.84 | Q15: =_xll.meLWOSwapParRate(N15,O15) -> 0.029728 | S15: ='USD GLOBAL CURVE'!T34 -> 15Y | T15: ='USD GLOBAL CURVE'!U34 -> 0.029728 | U15: =ABS(Q15-T15)*10000 -> 1.7347235e-12
B16: =_xll.meDateFromTenor('USD GLOBAL CURVE'!$I$9,F16,"MOD_FOLLOWING",C16) -> 43329 | C16: =C15 -> NYB:LNB | D16: =_xll.meDateFromTenor(B16,G16,) -> 50634 | F16: 2D | G16: 20Y | H16: USD_3ML | I16: PAY | J16: 1000000 | K16: 0.01 | L16: 0 | M16: 12 | N16: =_xll.meLWOSwapCreateFromGenerator("USDSWAP"&M16&"_"&G16,$H16,$I16,$J16,$B$8,$G16,$K16,$L16) -> USDSWAP12_20Y@10:1 | O16: USDYC | P16: =_xll.meLWOSwapPV(N16,O16) -> 307916.53 | Q16: =_xll.meLWOSwapParRate(N16,O16) -> 0.029833 | S16: ='USD GLOBAL CURVE'!T35 -> 20Y | T16: ='USD GLOBAL CURVE'!U35 -> 0.029833 | U16: =ABS(Q16-T16)*10000 -> 8.3266727e-13
B17: =_xll.meDateFromTenor('USD GLOBAL CURVE'!$I$9,F17,"MOD_FOLLOWING",C17) -> 43329 | C17: =C16 -> NYB:LNB | D17: =_xll.meDateFromTenor(B17,G17,) -> 52460 | F17: 2D | G17: 25Y | H17: USD_3ML | I17: PAY | J17: 1000000 | K17: 0.01 | L17: 0 | M17: 13 | N17: =_xll.meLWOSwapCreateFromGenerator("USDSWAP"&M17&"_"&G17,$H17,$I17,$J17,$B$8,$G17,$K17,$L17) -> USDSWAP13_25Y@4:1 | O17: USDYC | P17: =_xll.meLWOSwapPV(N17,O17) -> 361637.82 | Q17: =_xll.meLWOSwapParRate(N17,O17) -> 0.02975 | S17: ='USD GLOBAL CURVE'!T36 -> 25Y | T17: ='USD GLOBAL CURVE'!U36 -> 0.02975 | U17: =ABS(Q17-T17)*10000 -> 2.1163626e-12
B18: =_xll.meDateFromTenor('USD GLOBAL CURVE'!$I$9,F18,"MOD_FOLLOWING",C18) -> 43329 | C18: =C17 -> NYB:LNB | D18: =_xll.meDateFromTenor(B18,G18,) -> 54287 | F18: 2D | G18: 30Y | H18: USD_3ML | I18: PAY | J18: 1000000 | K18: 0.01 | L18: 0 | M18: 14 | N18: =_xll.meLWOSwapCreateFromGenerator("USDSWAP"&M18&"_"&G18,$H18,$I18,$J18,$B$8,$G18,$K18,$L18) -> USDSWAP14_30Y@8:1 | O18: USDYC | P18: =_xll.meLWOSwapPV(N18,O18) -> 407671.32 | Q18: =_xll.meLWOSwapParRate(N18,O18) -> 0.029618 | S18: ='USD GLOBAL CURVE'!T37 -> 30Y | T18: ='USD GLOBAL CURVE'!U37 -> 0.029618 | U18: =ABS(Q18-T18)*10000 -> 1.0755286e-12
B19: =_xll.meDateFromTenor('USD GLOBAL CURVE'!$I$9,F19,"MOD_FOLLOWING",C19) -> 43329 | C19: =C18 -> NYB:LNB | D19: =_xll.meDateFromTenor(B19,G19,) -> 57939 | F19: 2D | G19: 40Y | H19: USD_3ML | I19: PAY | J19: 1000000 | K19: 0.01 | L19: 0 | M19: 15 | N19: =_xll.meLWOSwapCreateFromGenerator("USDSWAP"&M19&"_"&G19,$H19,$I19,$J19,$B$8,$G19,$K19,$L19) -> USDSWAP15_40Y@7:1 | O19: USDYC | P19: =_xll.meLWOSwapPV(N19,O19) -> 488351.62 | Q19: =_xll.meLWOSwapParRate(N19,O19) -> 0.029618 | S19: ='USD GLOBAL CURVE'!T38 -> 40Y | T19: ='USD GLOBAL CURVE'!U38 -> 0.029618 | U19: =ABS(Q19-T19)*10000 -> 1.0755286e-12
B20: =_xll.meDateFromTenor('USD GLOBAL CURVE'!$I$9,F20,"MOD_FOLLOWING",C20) -> 43329 | C20: =C19 -> NYB:LNB | D20: =_xll.meDateFromTenor(B20,G20,) -> 61592 | F20: 2D | G20: 50Y | H20: USD_3ML | I20: PAY | J20: 1000000 | K20: 0.01 | L20: 0 | M20: 16 | N20: =_xll.meLWOSwapCreateFromGenerator("USDSWAP"&M20&"_"&G20,$H20,$I20,$J20,$B$8,$G20,$K20,$L20) -> USDSWAP16_50Y@6:1 | O20: USDYC | P20: =_xll.meLWOSwapPV(N20,O20) -> 550732.27 | Q20: =_xll.meLWOSwapParRate(N20,O20) -> 0.029618 | S20: ='USD GLOBAL CURVE'!T39 -> 50Y | T20: ='USD GLOBAL CURVE'!U39 -> 0.029618 | U20: =ABS(Q20-T20)*10000 -> 1.5265567e-12

Sheet RISK
B2: SwapNames | C2: Curves | D2: Tenor | E2: Include | G2: Risk
A3: 1 | B3: =IF($E3,PRICING!$N5,"") | C3: =IF($E3,"USDYC","") | D3: =PRICING!$G5 -> 1Y | E3: FALSE | G3: {=_xll.meUtilityResize(_xll.meLWOSwapDeltaLadder(_xll.meUtilityClean(B3:B18),_xll.meUtilityClean(C3:C18)),100,10)} -> USD : Pillars | H3: USD : Total | I3: USD : Pillars | J3: USD : Total
A4: =A3+1 -> 2 | B4: =IF($E4,PRICING!$N6,"") | C4: =IF($E4,"USDYC","") | D4: =PRICING!$G6 -> 2Y | E4: FALSE | G4: USDYC.OIS.OUTRIGHTOISSWAP.ON | H4: -0.075986449 | I4: USDYC.STD.O_N | J4: 7.5669959e-08
A5: =A4+1 -> 3 | B5: =IF($E5,PRICING!$N7,"") | C5: =IF($E5,"USDYC","") | D5: =PRICING!$G7 -> 3Y | E5: FALSE | G5: USDYC.OIS.OUTRIGHTOISSWAP.1W | H5: -8.7427907e-06 | I5: USDYC.STD.T_N | J5: -1.1641532e-08
A6: =A5+1 -> 4 | B6: =IF($E6,PRICING!$N8,"") | C6: =IF($E6,"USDYC","") | D6: =PRICING!$G8 -> 4Y | E6: FALSE | G6: USDYC.OIS.OUTRIGHTOISSWAP.2W | H6: 6.2334584e-05 | I6: USDYC.STD.LIBOR.3M | J6: -1.2340996
A7: =A6+1 -> 5 | B7: =IF($E7,PRICING!$N9,"") | C7: =IF($E7,"USDYC","") | D7: =PRICING!$G9 -> 5Y | E7: FALSE | G7: USDYC.OIS.OUTRIGHTOISSWAP.3W | H7: -0.0002546265 | I7: USDYC.STD.FUTURE.ED1 COMDTY.20180919.20181219 | J7: -0.39189056
A8: =A7+1 -> 6 | B8: =IF($E8,PRICING!$N10,"") | C8: =IF($E8,"USDYC","") | D8: =PRICING!$G10 -> 7Y | E8: FALSE | G8: USDYC.OIS.OUTRIGHTOISSWAP.1M | H8: 0.00049443624 | I8: USDYC.STD.FUTURE.ED2 COMDTY.20181219.20190320 | J8: -1.1730092
A9: =A8+1 -> 7 | B9: =IF($E9,PRICING!$N11,"") -> USDSWAP7_8Y@18:1 | C9: =IF($E9,"USDYC","") -> USDYC | D9: =PRICING!$G11 -> 8Y | E9: TRUE | G9: USDYC.OIS.OUTRIGHTOISSWAP.2M | H9: -0.0018570223 | I9: USDYC.STD.FUTURE.ED3 COMDTY.20190320.20190619 | J9: -1.1907073
A10: =A9+1 -> 8 | B10: =IF($E10,PRICING!$N12,"") | C10: =IF($E10,"USDYC","") | D10: =PRICING!$G12 -> 9Y | E10: FALSE | G10: USDYC.OIS.OUTRIGHTOISSWAP.3M | H10: 0.016624641 | I10: USDYC.STD.FUTURE.ED4 COMDTY.20190619.20190918 | J10: -1.0556594
A11: =A10+1 -> 9 | B11: =IF($E11,PRICING!$N13,"") | C11: =IF($E11,"USDYC","") | D11: =PRICING!$G13 -> 10Y | E11: FALSE | G11: USDYC.OIS.OUTRIGHTOISSWAP.4M | H11: -0.05457293 | I11: USDYC.STD.FUTURE.ED5 COMDTY.20190918.20191218 | J11: -0.8259712
A12: =A11+1 -> 10 | B12: =IF($E12,PRICING!$N14,"") | C12: =IF($E12,"USDYC","") | D12: =PRICING!$G14 -> 12Y | E12: FALSE | G12: USDYC.OIS.OUTRIGHTOISSWAP.5M | H12: 0.23073204 | I12: USDYC.STD.FUTURE.ED6 COMDTY.20191218.20200318 | J12: -0.81758202
A13: =A12+1 -> 11 | B13: =IF($E13,PRICING!$N15,"") | C13: =IF($E13,"USDYC","") | D13: =PRICING!$G15 -> 15Y | E13: FALSE | G13: USDYC.OIS.OUTRIGHTOISSWAP.6M | H13: -0.64800565 | I13: USDYC.STD.FUTURE.ED7 COMDTY.20200318.20200617 | J13: -0.81053511
A14: =A13+1 -> 12 | B14: =IF($E14,PRICING!$N16,"") | C14: =IF($E14,"USDYC","") | D14: =PRICING!$G16 -> 20Y | E14: FALSE | G14: USDYC.OIS.OUTRIGHTOISSWAP.9M | H14: 0.19765086 | I14: USDYC.STD.FUTURE.ED8 COMDTY.20200617.20200916 | J14: -0.68174649
A15: =A14+1 -> 13 | B15: =IF($E15,PRICING!$N17,"") | C15: =IF($E15,"USDYC","") | D15: =PRICING!$G17 -> 25Y | E15: FALSE | G15: USDYC.OIS.BASISRATE.1Y | H15: 1.3974859 | I15: USDYC.STD.FUTURE.ED9 COMDTY.20200916.20201216 | J15: -0.41865794
... A18: =A17+1 -> 16 | B18: =IF($E18,PRICING!$N20,"") | C18: =IF($E18,"USDYC","") | D18: =PRICING!$G20 -> 50Y | E18: FALSE | G18: USDYC.OIS.BASISRATE.4Y | H18: 4.9790368 | I18: USDYC.STD.FUTURE.ED12 COMDTY.20210616.20210915 | J18: -0.28023095
G19: USDYC.OIS.BASISRATE.5Y | H19: 13.153986 | I19: USDYC.STD.3MLIBORSWAP.4Y | J19: -4.8932639
G20: USDYC.OIS.BASISRATE.7Y | H20: 26.147848 | I20: USDYC.STD.3MLIBORSWAP.5Y | J20: -12.914813
G21: USDYC.OIS.BASISRATE.10Y | H21: 3.4842125 | I21: USDYC.STD.3MLIBORSWAP.7Y | J21: -25.70526
G22: USDYC.OIS.BASISRATE.12Y | H22: -1.3143389 | I22: USDYC.STD.3MLIBORSWAP.8Y | J22: 719.39383
G23: USDYC.OIS.BASISRATE.15Y | H23: 0.23564891 | I23: USDYC.STD.3MLIBORSWAP.9Y | J23: -0.0077564677
G24: USDYC.OIS.BASISRATE.20Y | H24: -0.045689958 | I24: USDYC.STD.3MLIBORSWAP.10Y | J24: -3.4196283
G25: USDYC.OIS.BASISRATE.25Y | H25: 0.014885992 | I25: USDYC.STD.3MLIBORSWAP.12Y | J25: 1.2937365
G26: USDYC.OIS.BASISRATE.30Y | H26: -0.0018737803 | I26: USDYC.STD.3MLIBORSWAP.15Y | J26: -0.23759036
G27: USDYC.OIS.BASISRATE.40Y | H27: -0.0030434428 | I27: USDYC.STD.3MLIBORSWAP.20Y | J27: 0.053949378
G28: USDYC.OIS.BASISRATE.50Y | H28: -0.0010066811 | I28: USDYC.STD.3MLIBORSWAP.25Y | J28: -0.02726902
G29: USDYC.OIS.BASISRATE.51Y | H29: 0.0007840019 | I29: USDYC.STD.3MLIBORSWAP.30Y | J29: 0.020412551
I30: USDYC.STD.3MLIBORSWAP.40Y | J30: -0.017852054
I31: USDYC.STD.3MLIBORSWAP.50Y | J31: 0.00099028402
I32: USDYC.STD.3MLIBORSWAP.51Y | J32: -0.00077187142
