Workbook
Name BUMP_SIZE: [1]Settings!$B$6
Name CurveJacobian_DiscountFactors: [1]USD_CURVE_OIS_DF_JACOBIAN!$J$16:$P$24
Name CurveJacobian_FlatShift_DiscountFactors: [1]USD_CURVE_OIS_DF_JACOBIAN!$AF$4:$AG$11
Name Settings.COB: Settings!$C$2
Name Settings.GradientShiftSize: Settings!$C$6
Name Settings.MarketDataShiftSize: Settings!$C$5

Sheet Settings
B2: COB | C2: 43665 | E2: OIS CURVE TEMPLATE
B4: Parameters | F4: =E2 -> OIS CURVE TEMPLATE
B5: MarketDataShiftSize | C5: 0.0001 | F5: Create Template | G5: =_xll.meLWOCurveGeneratorCreate(G6,F9,F10:G17,F19,F20:G37) -> USD_OIS_CURVE@1:2
B6: GradientShiftSize | C6: 1e-06 | F6: Object Name | G6: USD_OIS_CURVE
F9: CURVEPROPERTIES
F10: CurveType | G10: OIS
F11: CurveIndexFrequency | G11: DAILY
F12: StaticDataTable | G12: OIS
F13: IndexName | G13: OIS:USDOIS
F14: Currency | G14: USD
F15: interpolation | G15: FN_SPLINEINTERPOLATION
F16: yieldgen.interpolation | G16: FN_SPLINEINTERPOLATION
F19: OIS
F20: calendar | G20: NYB
F21: daycount | G21: ACT/360
F22: frequency | G22: ANNUAL
F23: generatemethod | G23: DAILYCOMPOUNDING
F24: resetlag | G24: 2D
F25: firstrate | G25: SHORTMARKET
F26: slidingrule | G26: MOD_FOLLOWING
F27: eomday | G27: 31
F28: iseomroll | G28: TRUE
F29: shorttermconvention | G29: ARITHMETICAVERAGE
F30: longtermconvention | G30: NONE
F31: longterm | G31: 100Y
F32: longterm.generatemethod | G32: NONE
F33: Epsilon | G33: 1e-10
F34: MaxLoop | G34: 1000
F35: CompoundingMethod | G35: ARITHMETIC
F36: SmoothShortEnd | G36: TRUE

Sheet DiscountFactors
B2: UPDATE CURVE RESULTS - DISCOUNT FACTORS | F2: ENABLE
B3: {=IF(F3,_xll.meCurveResultsDiscountFactorsUpdate(B7:C10,B14:C20,B25:C32),"Disabled")} -> Curve Discount Factor Results Updated: USDYC:OIS:8 | F3: TRUE
B4: Time Taken: 0.000000 seconds
B6: CURVE LVB | E6: ENABLE | F6: DELETE / DELETE ALL
B7: CurveCollection | C7: USDYC | E7: FALSE | F7: =IF(E7,_xll.meCurveResultsDelete(C7,C8),"Disabled") -> Disabled
B8: CurveIndex | C8: OIS | E8: FALSE | F8: =IF(E8,_xll.meCurveResultsDeleteAll(),"Disabled") -> Disabled
B9: CurveTenor | C9: 1D
B10: CurveType | C10: OIS_CURVE
B13: DISCOUNT FACTOR LVB | E13: DISCOUNT FACTOR LVB
B14: AsOfDate | C14: =Settings.COB -> 43665 | E14: AsOfDate | F14: =C14 -> 43665
B15: SpotDate | C15: =_xll.meDateFromTenor(C14,D15,"FOLLOWING","NYB") -> 43669 | D15: 2d | E15: SpotDate | F15: =C15 -> 43669
B16: JoinDate | C16: =C14 -> 43665 | E16: JoinDate | F16: =F14 -> 43665
B17: Interpolation | C17: SPLINE | E17: InterpolationMethod | F17: SPLINE
B18: Daycount | C18: ACT/360 | E18: Daycount | F18: ACT/360
B19: FixingBusinessDayAdjustment | C19: MOD_FOLLOWING
B20: FixingCalendar | C20: NYB
B23: DISCOUNT FACTOR LVB | E23: FORWARD RATE LVB | H23: DISPLAY ALL DISCOUNT FACTORS | K23: DISPLAY DISCOUNT FACTORS | N23: DISPLAY IMPLIED FORWARD RATES
B24: PaymentDate | C24: DiscountFactor | E24: FixingDate | F24: ForwardRate | H24: PaymentDate | I24: DiscountFactor | K24: PaymentDate | L24: DiscountFactor | N24: FixingDate | O24: ForwardRate
B25: 43665 | C25: 1 | E25: 43665 | F25: =-LN(C25)/((E25-$F$14+1)/365.25) -> 0 | H25: {=_xll.meCurveResultsDiscountFactorsDisplayAll(C7,C8)} -> 43665 | I25: 1 | K25: 43658 | L25: {=_xll.meCurveResultsDiscountFactorsDisplay(C7,C8,K25:K32)} -> 0 | N25: 43658 | O25: {=_xll.meCurveResultsForwardRatesDisplay($C$7,$C$8,$N$25:$N$32)} -> 0
B26: 43668 | C26: 0.99993306 | E26: 43668 | F26: =-LN(C26)/((E26-$F$14+1)/365.25) -> 0.00611266 | H26: 43668 | I26: 0.99993306 | K26: 43661 | L26: 0 | N26: 43661 | O26: 0
B27: 43669 | C27: 0.99986612 | E27: 43669 | F27: =-LN(C27)/((E27-$F$14+1)/365.25) -> 0.009780256 | H27: 43669 | I27: 0.99986612 | K27: 43662 | L27: 0 | N27: 43662 | O27: 0
B28: 44035 | C28: 0.98215028 | E28: 44035 | F28: =-LN(C28)/((E28-$F$14+1)/365.25) -> 0.017731798 | H28: 44035 | I28: 0.98215028 | K28: 44028 | L28: 0.98241019 | N28: 44028 | O28: 0.013599679
B29: 44400 | C29: 0.96823759 | E29: 44400 | F29: =-LN(C29)/((E29-$F$14+1)/365.25) -> 0.016018286 | H29: 44400 | I29: 0.96823759 | K29: 44393 | L29: 0.96850712 | N29: 44393 | O29: 0.014314175
B30: 44767 | C30: 0.95413871 | E30: 44767 | F30: =-LN(C30)/((E30-$F$14+1)/365.25) -> 0.015545881 | H30: 44767 | I30: 0.95413871 | K30: 44760 | L30: 0.95440778 | N30: 44760 | O30: 0.014499
B31: 45131 | C31: 0.93988153 | E31: 45131 | F31: =-LN(C31)/((E31-$F$14+1)/365.25) -> 0.015436966 | H31: 45131 | I31: 0.93988153 | K31: 45124 | L31: 0.94016467 | N31: 45124 | O31: 0.015477278
B32: 45496 | C32: 0.92463829 | E32: 45496 | F32: =-LN(C32)/((E32-$F$14+1)/365.25) -> 0.015621346 | H32: 45496 | I32: 0.92463829 | K32: 45489 | L32: 0.92493509 | N32: 45489 | O32: 0.016503493

Sheet JacobianRiskMetrics
B2: RISK JACOBIAN | F2: DISPLAY JACOBIAN
B3: {=IF($C$14="FLAT_SHIFT",_xll.meCurveResultsJacobianUpdate($B$7:$C$10,DiscountFactors!$B$14:$C$20,DiscountFactors!$B$25:$C$32,$B$13:$C$15,$C$22,$C$23,$B$26:$C$34),_xll.meCurveResultsJacobianUpdate(B7:C10,DiscountFactors!$B$14:$C$20,DiscountFactors!$B$25:$C$32,B13:C15,G22:L22,G23:L23,F26:L34))} -> Curve Jacobian Results Updated: USDYC:OIS:10 | F3: {=_xll.meUtilityResize(_xll.meCurveResultsJacobianDisplay(C7,C8,"DISCOUNT_FACTORS"),50,50)} -> RiskType | G3: DISCOUNT_FACTORS
B4: Time Taken: 0.000000 seconds | F4: ShiftType | G4: PERTURBED
F5: GradientShiftSize | G5: 1e-06
B6: CURVE LVB
B7: CurveCollection | C7: USDYC | F7: OutrightInstrument | G7: TRUE | H7: TRUE | I7: TRUE | J7: TRUE | K7: TRUE | L7: TRUE
B8: CurveIndex | C8: OIS | F8: MarketDataShiftSize | G8: 0.0001 | H8: 0.0001 | I8: 0.0001 | J8: 0.0001 | K8: 0.0001 | L8: 0.0001
B9: CurveTenor | C9: 1D
B10: CurveType | C10: OIS_CURVE | G10: Instrument
F11: PaymentDate | G11: ON | H11: 1Y | I11: 2Y | J11: 3Y | K11: 4Y | L11: 5Y
B12: JACOBIAN LVB | F12: 43665 | G12: 0 | H12: 0 | I12: 0 | J12: 0 | K12: 0 | L12: 0
B13: RiskType | C13: DISCOUNT_FACTORS | F13: 43668 | G13: -8.3299941e-09 | H13: 0 | I13: 0 | J13: 0 | K13: 0 | L13: 0
B14: ShiftType | C14: PERTURBED | F14: 43669 | G14: -1.1106288e-08 | H14: 0 | I14: 0 | J14: 0 | K14: 0 | L14: 0
B15: GradientShiftSize | C15: =Settings.GradientShiftSize -> 1e-06 | F15: 44035 | G15: -1.0712937e-08 | H15: -9.9851366e-07 | I15: 9.2276187e-12 | J15: -5.3309579e-12 | K15: -5.8730798e-13 | L15: -8.8897778e-12
F16: 44400 | G16: -1.2856439e-08 | H16: 1.2321635e-08 | I16: -1.9741603e-06 | J16: -2.6609159e-11 | K16: 9.254042e-12 | L16: -1.8740121e-11
F17: 44767 | G17: -1.9783496e-08 | H17: 1.1692552e-08 | I17: 3.1102686e-08 | J17: -2.9399399e-06 | K17: 1.445899e-11 | L17: -3.2717384e-11
F18: 45131 | G18: -1.1488122e-08 | H18: 1.1349436e-08 | I18: 3.0296818e-08 | J18: 4.5805526e-08 | K18: -3.8991185e-06 | L18: -3.2661762e-11
F19: 45496 | G19: -5.1391458e-09 | H19: 1.1328921e-08 | I19: 3.0138413e-08 | J19: 4.5577564e-08 | K19: 6.5439773e-08 | L19: -4.8448026e-06
B21: JACOBIAN RISK METRICS | F21: JACOBIAN RISK METRICS
B22: OutrightInstruments | C22: TRUE | F22: OutrightInstruments | G22: TRUE | H22: TRUE | I22: TRUE | J22: TRUE | K22: TRUE | L22: TRUE
B23: MarketDataShiftSize | C23: 0.0001 | F23: MarketDataShiftSize | G23: 0.0001 | H23: 0.0001 | I23: 0.0001 | J23: 0.0001 | K23: 0.0001 | L23: 0.0001
C25: Instrument | G25: Instrument
B26: =IF($C$13="DISCOUNT_FACTORS","PaymentDate","FixingDate") -> PaymentDate | C26: TOTAL | D26: RiskTotals | F26: =IF($C$13="DISCOUNT_FACTORS","PaymentDate","FixingDate") -> PaymentDate | G26: ON | H26: 1Y | I26: 2Y | J26: 3Y | K26: 4Y | L26: 5Y | M26: RiskTotals
B27: 43665 | C27: 0 | D27: =C27*$C$23/$C$15 -> 0 | F27: 43665 | G27: 0 | H27: 0 | I27: 0 | J27: 0 | K27: 0 | L27: 0 | M27: =SUMPRODUCT(G27:L27,$G$23:$L$23)/$C$15 -> 0
B28: 43668 | C28: -8.3300009e-09 | D28: =C28*$C$23/$C$15 -> -8.3300009e-07 | F28: 43668 | G28: -8.3299941e-09 | H28: 0 | I28: 0 | J28: 0 | K28: 0 | L28: 0 | M28: =SUMPRODUCT(G28:L28,$G$23:$L$23)/$C$15 -> -8.3299941e-07
B29: 43669 | C29: -1.1106298e-08 | D29: =C29*$C$23/$C$15 -> -1.1106298e-06 | F29: 43669 | G29: -1.1106288e-08 | H29: 0 | I29: 0 | J29: 0 | K29: 0 | L29: 0 | M29: =SUMPRODUCT(G29:L29,$G$23:$L$23)/$C$15 -> -1.1106288e-06
B30: 44035 | C30: -1.0092912e-06 | D30: =C30*$C$23/$C$15 -> -0.00010092912 | F30: 44035 | G30: -1.0712937e-08 | H30: -9.9851366e-07 | I30: 9.2276187e-12 | J30: -5.3309579e-12 | K30: -5.8730798e-13 | L30: -8.8897778e-12 | M30: =SUMPRODUCT(G30:L30,$G$23:$L$23)/$C$15 -> -0.00010092322
B31: 44400 | C31: -1.9749384e-06 | D31: =C31*$C$23/$C$15 -> -0.00019749384 | F31: 44400 | G31: -1.2856439e-08 | H31: 1.2321635e-08 | I31: -1.9741603e-06 | J31: -2.6609159e-11 | K31: 9.254042e-12 | L31: -1.8740121e-11 | M31: =SUMPRODUCT(G31:L31,$G$23:$L$23)/$C$15 -> -0.00019747312
B32: 44767 | C32: -2.9173918e-06 | D32: =C32*$C$23/$C$15 -> -0.00029173918 | F32: 44767 | G32: -1.9783496e-08 | H32: 1.1692552e-08 | I32: 3.1102686e-08 | J32: -2.9399399e-06 | K32: 1.445899e-11 | L32: -3.2717384e-11 | M32: =SUMPRODUCT(G32:L32,$G$23:$L$23)/$C$15 -> -0.00029169464
B33: 45131 | C33: -3.8239585e-06 | D33: =C33*$C$23/$C$15 -> -0.00038239585 | F33: 45131 | G33: -1.1488122e-08 | H33: 1.1349436e-08 | I33: 3.0296818e-08 | J33: 4.5805526e-08 | K33: -3.8991185e-06 | L33: -3.2661762e-11 | M33: =SUMPRODUCT(G33:L33,$G$23:$L$23)/$C$15 -> -0.00038231875
B34: 45496 | C34: -4.7018197e-06 | D34: =C34*$C$23/$C$15 -> -0.00047018197 | F34: 45496 | G34: -5.1391458e-09 | H34: 1.1328921e-08 | I34: 3.0138413e-08 | J34: 4.5577564e-08 | K34: 6.5439773e-08 | L34: -4.8448026e-06 | M34: =SUMPRODUCT(G34:L34,$G$23:$L$23)/$C$15 -> -0.00046974571
B37: CALCULATE RISK TOTALS | F37: IMPLY NEW DISCOUNT FACTORS | K37: UPDATE CURVE DISCOUNT FACTORS
B38: RiskDate | C38: RiskTotal | D38: Check | F38: PaymentDate | G38: NewDiscountFactor | H38: DiscFact Chg | I38: Check | K38: Enable | L38: FALSE
B39: {=_xll.meCurveResultsJacobianRiskTotals(C7,C8,"DISCOUNT_FACTORS")} -> 43665 | C39: 0 | D39: =ABS(IF($C$14="FLAT_SHIFT",C39-D27,C39-M27))<0.0000000001 -> TRUE | F39: {=_xll.meCurveResultsJacobianImplyNewDiscountFactors(C7,C8)} -> 43665 | G39: 1 | H39: =G39-DiscountFactors!I25 -> 0 | I39: =ABS(H39-C39)<0.0000000001 -> TRUE
B40: 43668 | C40: -8.3299941e-07 | D40: =ABS(IF($C$14="FLAT_SHIFT",C40-D28,C40-M28))<0.0000000001 -> TRUE | F40: 43668 | G40: 0.99993223 | H40: =G40-DiscountFactors!I26 -> -8.3299941e-07 | I40: =ABS(H40-C40)<0.0000000001 -> TRUE
B41: 43669 | C41: -1.1106288e-06 | D41: =ABS(IF($C$14="FLAT_SHIFT",C41-D29,C41-M29))<0.0000000001 -> TRUE | F41: 43669 | G41: 0.99986501 | H41: =G41-DiscountFactors!I27 -> -1.1106288e-06 | I41: =ABS(H41-C41)<0.0000000001 -> TRUE | K41: {=IF($L$38,_xll.meCurveResultsDiscountFactorsUpdate(DiscountFactors!$B$7:$C$10,DiscountFactors!B14:C20,F39:G46),"Disabled")} -> Disabled
B42: 44035 | C42: -0.00010092322 | D42: =ABS(IF($C$14="FLAT_SHIFT",C42-D30,C42-M30))<0.0000000001 -> TRUE | F42: 44035 | G42: 0.98204936 | H42: =G42-DiscountFactors!I28 -> -0.00010092322 | I42: =ABS(H42-C42)<0.0000000001 -> TRUE | K42: Disabled
B43: 44400 | C43: -0.00019747312 | D43: =ABS(IF($C$14="FLAT_SHIFT",C43-D31,C43-M31))<0.0000000001 -> TRUE | F43: 44400 | G43: 0.96804012 | H43: =G43-DiscountFactors!I29 -> -0.00019747312 | I43: =ABS(H43-C43)<0.0000000001 -> TRUE
B44: 44767 | C44: -0.00029169464 | D44: =ABS(IF($C$14="FLAT_SHIFT",C44-D32,C44-M32))<0.0000000001 -> TRUE | F44: 44767 | G44: 0.95384701 | H44: =G44-DiscountFactors!I30 -> -0.00029169464 | I44: =ABS(H44-C44)<0.0000000001 -> TRUE
B45: 45131 | C45: -0.00038231875 | D45: =ABS(IF($C$14="FLAT_SHIFT",C45-D33,C45-M33))<0.0000000001 -> TRUE | F45: 45131 | G45: 0.93949921 | H45: =G45-DiscountFactors!I31 -> -0.00038231875 | I45: =ABS(H45-C45)<0.0000000001 -> TRUE
...

Sheet EX - Original Curve
M2: DISPLAY DISCOUNT FACTORS | Q2: DISCOUNT FACTOR RESULTS
C3: MARKETDATAPROPERTIES | F3: OIS
F4: Term | G4: Rate | H4: StartDate | I4: EndDate | J4: Use | M4: PaymentDate | N4: Term | O4: DiscountFactor | Q4: DISCOUNT FACTOR LVB
C5: Currency | D5: USD | F5: ON | G5: 0.024 | J5: TRUE | M5: {=_xll.meUtilityTermsToDates(Settings.COB,N5:N12)} -> 43665 | N5: {=_xll.meCurveDisplay(D28,D6)} -> 0 | O5: 1 | Q5: AsOfDate | R5: =D8 -> 43665
C6: CurveType | D6: OIS | F6: 1Y | G6: 0.017485 | J6: TRUE | M6: 43668 | N6: 0.0082191781 | O6: 0.99980004 | Q6: SpotDate | R6: =_xll.meDateFromTenor(R5,S6,"FOLLOWING","NYB") -> 43669 | S6: 2d
C7: CurveIndexFrequency | D7: DAILY | F7: 2Y | G7: 0.015765 | J7: TRUE | M7: 43669 | N7: 0.010958904 | O7: 0.99973339 | Q7: JoinDate | R7: =R5 -> 43665
C8: AsOfDate | D8: =Settings.COB -> 43665 | F8: 3Y | G8: 0.01532 | J8: TRUE | M8: 44035 | N8: 1.0136986 | O8: 0.98211974 | Q8: Interpolation | R8: SPLINE
F9: 4Y | G9: 0.01516 | J9: TRUE | M9: 44400 | N9: 2.0136986 | O9: 0.96826287 | Q9: Daycount | R9: ACT/360
F10: 5Y | G10: 0.01532 | J10: TRUE | M10: 44767 | N10: 3.0191781 | O10: 0.95413948 | Q10: FixingBusinessDayAdjustment | R10: MOD_FOLLOWING
C11: Create Market Data Handle | M11: 45131 | N11: 4.0164384 | O11: 0.94009844 | Q11: FixingCalendar | R11: NYB
C12: Handle Name | D12: USD_OIS_CURVE | M12: 45496 | N12: 5.0164384 | O12: 0.92498482
C13: Market Data Handle | D13: =_xll.meLWOCurveMarketDataCreate(D12,C3,C5:D8,F3,F5:J31) -> USD_OIS_CURVE@2:0
Q14: DISCOUNT FACTOR LVB
Q15: PaymentDate | R15: DiscountFactor
Q16: =M5 -> 43665 | R16: =O5 -> 1
Q17: =M6 -> 43668 | R17: =O6 -> 0.99980004
Q18: =M7 -> 43669 | R18: =O7 -> 0.99973339
C19: Curve Dictionary | Q19: =M8 -> 44035 | R19: =O8 -> 0.98211974
C20: Handle Name | D20: USD_OIS_ORIGINAL | Q20: =M9 -> 44400 | R20: =O9 -> 0.96826287
C21: Curve Generator | D21: =Settings!$G$5 -> USD_OIS_CURVE@1:2 | Q21: =M10 -> 44767 | R21: =O10 -> 0.95413948
C22: Domestic Curve Collection | D22: USDYC_ORIGINAL | Q22: =M11 -> 45131 | R22: =O11 -> 0.94009844
C23: Foreign Curve Collection | Q23: =M12 -> 45496 | R23: =O12 -> 0.92498482
C26: Curve Build
C27: Handle Name | D27: {=_xll.meLWOCurveCalibrate(D20,D21,D13,D22,D23)} -> USD_OIS_ORIGINAL@3:0
C28: Curve Collection | D28: USDYC_ORIGINAL
C29: Curve Index | D29: OIS:USDOIS
C30: Calibration Time Taken | D30: 0.00300 sec
C31: Curve Loaded | D31: =_xll.meLWOExists(D27,"CURVE") -> TRUE
C34: Test Analytical Curve Rebuild
C35: CurveBuild | D35: =_xll.meLWOCurveCalibrate(D36,$D$21,$D$13,$D$37) -> USD_OIS_ANALYTICAL@4:0
C36: Handle Name | D36: USD_OIS_ANALYTICAL
C37: CurveCollection | D37: USDYC_ANALYTICAL
C38: CurveIndex | D38: OIS

Sheet EX - Shifted Curve
F2: ShiftType | G2: MKTDATA-SHIFT | M2: MarketDataShiftSize | N2: =Settings.MarketDataShiftSize -> 0.0001
M3: GradientShiftSize | N3: =Settings.GradientShiftSize -> 1e-06
M5: DISPLAY DISCOUNT FACTORS
M6: PaymentDate | N6: Term | O6: DiscountFactor
C7: MARKETDATAPROPERTIES | F7: OIS | M7: {=_xll.meUtilityTermsToDates(Settings.COB,N7:N14)} -> 43665 | N7: {=_xll.meCurveDisplay(D32,D10)} -> 0 | O7: 1
F8: Term | G8: Rate | H8: StartDate | I8: EndDate | J8: Use | M8: 43668 | N8: 0.0082191781 | O8: 0.99979921
C9: Currency | D9: USD | F9: ON | G9: ='EX - Original Curve'!G5+IF($G$2="MKTDATA-SHIFT",$N$2,$N$3) -> 0.0241 | J9: TRUE | M9: 43669 | N9: 0.010958904 | O9: 0.99973228
C10: CurveType | D10: OIS | F10: 1Y | G10: ='EX - Original Curve'!G6+IF($G$2="MKTDATA-SHIFT",$N$2,$N$3) -> 0.017585 | J10: TRUE | M10: 44035 | N10: 1.0136986 | O10: 0.98201882
C11: CurveIndexFrequency | D11: DAILY | F11: 2Y | G11: ='EX - Original Curve'!G7+IF($G$2="MKTDATA-SHIFT",$N$2,$N$3) -> 0.015865 | J11: TRUE | M11: 44400 | N11: 2.0136986 | O11: 0.96806539
C12: AsOfDate | D12: =Settings.COB -> 43665 | F12: 3Y | G12: ='EX - Original Curve'!G8+IF($G$2="MKTDATA-SHIFT",$N$2,$N$3) -> 0.01542 | J12: TRUE | M12: 44767 | N12: 3.0191781 | O12: 0.95384778
F13: 4Y | G13: ='EX - Original Curve'!G9+IF($G$2="MKTDATA-SHIFT",$N$2,$N$3) -> 0.01526 | J13: TRUE | M13: 45131 | N13: 4.0164384 | O13: 0.93971612
F14: 5Y | G14: ='EX - Original Curve'!G10+IF($G$2="MKTDATA-SHIFT",$N$2,$N$3) -> 0.01542 | J14: TRUE | M14: 45496 | N14: 5.0164384 | O14: 0.92451476
C15: Create Market Data Handle
C16: Handle Name | D16: USD_OIS_CURVE | M16: NUMERICAL RISK METRICS
C17: Market Data Handle | D17: =_xll.meLWOCurveMarketDataCreate(D16,C7,C9:D12,F7,F9:J35) -> USD_OIS_CURVE@5:1 | M17: =M6 -> PaymentDate | N17: DF Change | O17: NewDF
M18: =M7 -> 43665 | N18: =O7-'EX - Original Curve'!O5 -> 0 | O18: =O7 -> 1
M19: =M8 -> 43668 | N19: =O8-'EX - Original Curve'!O6 -> -8.3299941e-07 | O19: =O8 -> 0.99979921
M20: =M9 -> 43669 | N20: =O9-'EX - Original Curve'!O7 -> -1.1106288e-06 | O20: =O9 -> 0.99973228
M21: =M10 -> 44035 | N21: =O10-'EX - Original Curve'!O8 -> -0.00010092322 | O21: =O10 -> 0.98201882
M22: =M11 -> 44400 | N22: =O11-'EX - Original Curve'!O9 -> -0.00019747312 | O22: =O11 -> 0.96806539
C23: Curve Dictionary | M23: =M12 -> 44767 | N23: =O12-'EX - Original Curve'!O10 -> -0.00029169464 | O23: =O12 -> 0.95384778
C24: Handle Name | D24: USD_OIS_SHIFTED | M24: =M13 -> 45131 | N24: =O13-'EX - Original Curve'!O11 -> -0.00038231875 | O24: =O13 -> 0.93971612
C25: Curve Generator | D25: =Settings!$G$5 -> USD_OIS_CURVE@1:2 | M25: =M14 -> 45496 | N25: =O14-'EX - Original Curve'!O12 -> -0.00047006386 | O25: =O14 -> 0.92451476
C26: Domestic Curve Collection | D26: USDYC_SHIFTED
C27: Foreign Curve Collection | M27: ANALYTICAL JACOBIAN RISK METRICS
M28: =M17 -> PaymentDate | N28: DF Change | O28: NewDF | P28: +/-
M29: =JacobianRiskMetrics!F39 -> 43665 | N29: =JacobianRiskMetrics!C39 -> 0 | O29: =JacobianRiskMetrics!G39 -> 1 | P29: =O29-O18 -> 0
C30: Curve Build | M30: =JacobianRiskMetrics!F40 -> 43668 | N30: =JacobianRiskMetrics!C40 -> -8.3299941e-07 | O30: =JacobianRiskMetrics!G40 -> 0.99993223 | P30: =O30-O19 -> 0.00013302004
C31: Handle Name | D31: {=_xll.meLWOCurveCalibrate(D24,D25,D17,D26,D27)} -> USD_OIS_SHIFTED@6:1 | M31: =JacobianRiskMetrics!F41 -> 43669 | N31: =JacobianRiskMetrics!C41 -> -1.1106288e-06 | O31: =JacobianRiskMetrics!G41 -> 0.99986501 | P31: =O31-O20 -> 0.00013273346
C32: Curve Collection | D32: USDYC_SHIFTED | M32: =JacobianRiskMetrics!F42 -> 44035 | N32: =JacobianRiskMetrics!C42 -> -0.00010092322 | O32: =JacobianRiskMetrics!G42 -> 0.98204936 | P32: =O32-O21 -> 3.054437e-05
C33: Curve Index | D33: OIS:USDOIS | M33: =JacobianRiskMetrics!F43 -> 44400 | N33: =JacobianRiskMetrics!C43 -> -0.00019747312 | O33: =JacobianRiskMetrics!G43 -> 0.96804012 | P33: =O33-O22 -> -2.5278366e-05
C34: Calibration Time Taken | D34: 0.00300 sec | M34: =JacobianRiskMetrics!F44 -> 44767 | N34: =JacobianRiskMetrics!C44 -> -0.00029169464 | O34: =JacobianRiskMetrics!G44 -> 0.95384701 | P34: =O34-O23 -> -7.6726429e-07
C35: Curve Loaded | D35: =_xll.meLWOExists(D31,"CURVE") -> TRUE | M35: =JacobianRiskMetrics!F45 -> 45131 | N35: =JacobianRiskMetrics!C45 -> -0.00038231875 | O35: =JacobianRiskMetrics!G45 -> 0.93949921 | P35: =O35-O24 -> -0.00021691124
M36: =JacobianRiskMetrics!F46 -> 45496 | N36: =JacobianRiskMetrics!C46 -> -0.00046974571 | O36: =JacobianRiskMetrics!G46 -> 0.92416855 | P36: =O36-O25 -> -0.00034621053

Sheet EX - Ultra-Fast Curve Rebuild
D2: ULTRA-FAST CURVE REBUILD | H2: JACOBIAN RISK DYNAMICS
D3: DEMO OF INTERNAL STEPS
H4: CURVE LVB
B5: Enable/Disable | D5: #1 LOAD / RESET ORIGINAL CURVE | H5: CurveCollection | I5: =E7 -> USDYC_ANALYTICAL
B6: 0 | D6: OriginalHandle | E6: {=IF(B6,_xll.meLWOCurveCalibrate('EX - Original Curve'!D36,'EX - Original Curve'!D21,'EX - Original Curve'!D13,'EX - Original Curve'!D37),"Disabled")} -> Disabled | H6: CurveIndex | I6: =JacobianRiskMetrics!C8 -> OIS
D7: CurveCollection | E7: {='EX - Original Curve'!D37} -> USDYC_ANALYTICAL | H7: CurveTenor | I7: =JacobianRiskMetrics!C9 -> 1D
D8: CurveIndex | E8: OIS | H8: CurveType | I8: =JacobianRiskMetrics!C10 -> OIS_CURVE
H10: JACOBIAN LVB
B11: Enable/Disable | D11: #2 UPDATE JACOBIAN RISK METRICS | H11: RiskType | I11: =JacobianRiskMetrics!C13 -> DISCOUNT_FACTORS
B12: 1 | D12: {=IF($B$12,IF($E$6=$E$6,_xll.meCurveResultsJacobianUpdate($H$5:$I$8,'EX - Original Curve'!$Q$5:$R$11,'EX - Original Curve'!$Q$16:$R$23,$H$11:$I$13,IF(I12="FLAT_SHIFT",I17,L17:Q17),IF(I12="FLAT_SHIFT",I18,L18:Q18),IF(I12="FLAT_SHIFT",H21:I29,K21:Q29)),"LOAD CURVE"),"Disabled")} -> Curve Jacobian Results Updated: USDYC_ANALYTICAL:OIS:1 | H12: ShiftType | I12: PERTURBED
D13: Time Taken: 0.000000 seconds | H13: GradientShiftSize | I13: =JacobianRiskMetrics!C15 -> 1e-06
D16: #3 IMPLY NEW DISCOUNT FACTORS | H16: JACOBIAN RISK METRICS - FLAT_SHIFT | K16: JACOBIAN RISK METRICS - PERTURBED
D17: BYPASSING CALIBRATION STEP | H17: OutrightInstrument | I17: TRUE | K17: OutrightInstrument | L17: TRUE | M17: TRUE | N17: TRUE | O17: TRUE | P17: TRUE | Q17: TRUE
D18: =D21 -> Disabled | H18: MarketDataShiftSize | I18: =JacobianRiskMetrics!C23 -> 0.0001 | K18: MarketDataShiftSize | L18: =JacobianRiskMetrics!G23 -> 0.0001 | M18: =JacobianRiskMetrics!H23 -> 0.0001 | N18: =JacobianRiskMetrics!I23 -> 0.0001 | O18: =JacobianRiskMetrics!J23 -> 0.0001 | P18: =JacobianRiskMetrics!K23 -> 0.0001 | Q18: =JacobianRiskMetrics!L23 -> 0.0001
B20: Enable/Disable | D20: #4 APPLY NEW DISCOUNT FACTORS TO CURVE | I20: Instrument | L20: Instrument
B21: 0 | D21: {=IF($B$21,IF($K$35=$K$35,_xll.meCurveResultsJacobianUpdate($H$5:$I$8,'EX - Original Curve'!$Q$5:$R$11,'EX - Ultra-Fast Curve Rebuild'!$K$35:$L$42,$H$11:$I$13,IF(I12="FLAT_SHIFT",I18,L18:Q18),IF(I12="FLAT_SHIFT",H21:I29,K21:Q29)),"LOAD CURVE"),"Disabled")} -> Disabled | H21: =IF($I$11="DISCOUNT_FACTORS","PaymentDate","FixingDate") -> PaymentDate | I21: TOTAL | K21: =IF($I$11="DISCOUNT_FACTORS","PaymentDate","FixingDate") -> PaymentDate | L21: ON | M21: 1Y | N21: 2Y | O21: 3Y | P21: 4Y | Q21: 5Y
D22: Disabled | H22: =JacobianRiskMetrics!B27 -> 43665 | I22: =JacobianRiskMetrics!C27 -> 0 | K22: =JacobianRiskMetrics!F27 -> 43665 | L22: =JacobianRiskMetrics!G27 -> 0 | M22: =JacobianRiskMetrics!H27 -> 0 | N22: =JacobianRiskMetrics!I27 -> 0 | O22: =JacobianRiskMetrics!J27 -> 0 | P22: =JacobianRiskMetrics!K27 -> 0 | Q22: =JacobianRiskMetrics!L27 -> 0
H23: =JacobianRiskMetrics!B28 -> 43668 | I23: =JacobianRiskMetrics!C28 -> -8.3300009e-09 | K23: =JacobianRiskMetrics!F28 -> 43668 | L23: -8.3299941e-09 | M23: =JacobianRiskMetrics!H28 -> 0 | N23: =JacobianRiskMetrics!I28 -> 0 | O23: =JacobianRiskMetrics!J28 -> 0 | P23: =JacobianRiskMetrics!K28 -> 0 | Q23: =JacobianRiskMetrics!L28 -> 0
H24: =JacobianRiskMetrics!B29 -> 43669 | I24: =JacobianRiskMetrics!C29 -> -1.1106298e-08 | K24: =JacobianRiskMetrics!F29 -> 43669 | L24: -1.1106288e-08 | M24: =JacobianRiskMetrics!H29 -> 0 | N24: =JacobianRiskMetrics!I29 -> 0 | O24: =JacobianRiskMetrics!J29 -> 0 | P24: =JacobianRiskMetrics!K29 -> 0 | Q24: =JacobianRiskMetrics!L29 -> 0
H25: =JacobianRiskMetrics!B30 -> 44035 | I25: =JacobianRiskMetrics!C30 -> -1.0092912e-06 | K25: =JacobianRiskMetrics!F30 -> 44035 | L25: -1.0712937e-08 | M25: =JacobianRiskMetrics!H30 -> -9.9851366e-07 | N25: =JacobianRiskMetrics!I30 -> 9.2276187e-12 | O25: =JacobianRiskMetrics!J30 -> -5.3309579e-12 | P25: =JacobianRiskMetrics!K30 -> -5.8730798e-13 | Q25: =JacobianRiskMetrics!L30 -> -8.8897778e-12
H26: =JacobianRiskMetrics!B31 -> 44400 | I26: =JacobianRiskMetrics!C31 -> -1.9749384e-06 | K26: =JacobianRiskMetrics!F31 -> 44400 | L26: -1.2856439e-08 | M26: =JacobianRiskMetrics!H31 -> 1.2321635e-08 | N26: =JacobianRiskMetrics!I31 -> -1.9741603e-06 | O26: =JacobianRiskMetrics!J31 -> -2.6609159e-11 | P26: =JacobianRiskMetrics!K31 -> 9.254042e-12 | Q26: =JacobianRiskMetrics!L31 -> -1.8740121e-11
H27: =JacobianRiskMetrics!B32 -> 44767 | I27: =JacobianRiskMetrics!C32 -> -2.9173918e-06 | K27: =JacobianRiskMetrics!F32 -> 44767 | L27: -1.9783496e-08 | M27: =JacobianRiskMetrics!H32 -> 1.1692552e-08 | N27: =JacobianRiskMetrics!I32 -> 3.1102686e-08 | O27: =JacobianRiskMetrics!J32 -> -2.9399399e-06 | P27: =JacobianRiskMetrics!K32 -> 1.445899e-11 | Q27: =JacobianRiskMetrics!L32 -> -3.2717384e-11
H28: =JacobianRiskMetrics!B33 -> 45131 | I28: =JacobianRiskMetrics!C33 -> -3.8239585e-06 | K28: =JacobianRiskMetrics!F33 -> 45131 | L28: -1.1488122e-08 | M28: =JacobianRiskMetrics!H33 -> 1.1349436e-08 | N28: =JacobianRiskMetrics!I33 -> 3.0296818e-08 | O28: =JacobianRiskMetrics!J33 -> 4.5805526e-08 | P28: =JacobianRiskMetrics!K33 -> -3.8991185e-06 | Q28: =JacobianRiskMetrics!L33 -> -3.2661762e-11
H29: =JacobianRiskMetrics!B34 -> 45496 | I29: =JacobianRiskMetrics!C34 -> -4.7018197e-06 | K29: =JacobianRiskMetrics!F34 -> 45496 | L29: =JacobianRiskMetrics!G34 -> -5.1391458e-09 | M29: =JacobianRiskMetrics!H34 -> 1.1328921e-08 | N29: =JacobianRiskMetrics!I34 -> 3.0138413e-08 | O29: =JacobianRiskMetrics!J34 -> 4.5577564e-08 | P29: =JacobianRiskMetrics!K34 -> 6.5439773e-08 | Q29: =JacobianRiskMetrics!L34 -> -4.8448026e-06
H32: ORIGINAL DISCOUNT FACTORS | K32: #3 NEW JACOBIAN IMPLIED CURVE | N32: ACTUAL NEW DISCOUNT FACTORS
H34: PaymentDate | I34: DiscountFactor | K34: PaymentDate | L34: ImpliedDiscFactor | N34: PaymentDate | O34: DiscountFactor | P34: +/-
H35: ='EX - Original Curve'!M5 -> 43665 | I35: ='EX - Original Curve'!O5 -> 1 | K35: {=IF($D$12=$D$12,_xll.meCurveResultsJacobianImplyNewDiscountFactors(I5,I6),"LOAD JACOBIAN")} -> 43665 | L35: 1 | N35: ='EX - Shifted Curve'!M7 -> 43665 | O35: ='EX - Shifted Curve'!O7 -> 1 | P35: =O35-L35 -> 0
H36: ='EX - Original Curve'!M6 -> 43668 | I36: ='EX - Original Curve'!O6 -> 0.99980004 | K36: 43668 | L36: 0.99979921 | N36: ='EX - Shifted Curve'!M8 -> 43668 | O36: ='EX - Shifted Curve'!O8 -> 0.99979921 | P36: =O36-L36 -> 0
H37: ='EX - Original Curve'!M7 -> 43669 | I37: ='EX - Original Curve'!O7 -> 0.99973339 | K37: 43669 | L37: 0.99973228 | N37: {='EX - Shifted Curve'!M9} -> 43669 | O37: ='EX - Shifted Curve'!O9 -> 0.99973228 | P37: =O37-L37 -> 0
H38: ='EX - Original Curve'!M8 -> 44035 | I38: ='EX - Original Curve'!O8 -> 0.98211974 | K38: 44035 | L38: 0.98201882 | N38: ='EX - Shifted Curve'!M10 -> 44035 | O38: ='EX - Shifted Curve'!O10 -> 0.98201882 | P38: =O38-L38 -> 0
H39: ='EX - Original Curve'!M9 -> 44400 | I39: ='EX - Original Curve'!O9 -> 0.96826287 | K39: 44400 | L39: 0.96806539 | N39: ='EX - Shifted Curve'!M11 -> 44400 | O39: ='EX - Shifted Curve'!O11 -> 0.96806539 | P39: =O39-L39 -> 0
H40: ='EX - Original Curve'!M10 -> 44767 | I40: ='EX - Original Curve'!O10 -> 0.95413948 | K40: 44767 | L40: 0.95384778 | N40: ='EX - Shifted Curve'!M12 -> 44767 | O40: ='EX - Shifted Curve'!O12 -> 0.95384778 | P40: =O40-L40 -> 0
H41: ='EX - Original Curve'!M11 -> 45131 | I41: ='EX - Original Curve'!O11 -> 0.94009844 | K41: 45131 | L41: 0.93971612 | N41: ='EX - Shifted Curve'!M13 -> 45131 | O41: ='EX - Shifted Curve'!O13 -> 0.93971612 | P41: =O41-L41 -> 0
H42: ='EX - Original Curve'!M12 -> 45496 | I42: ='EX - Original Curve'!O12 -> 0.92498482 | K42: 45496 | L42: 0.92451507 | N42: ='EX - Shifted Curve'!M14 -> 45496 | O42: ='EX - Shifted Curve'!O14 -> 0.92451476 | P42: =O42-L42 -> -3.1815246e-07
