Workbook
Name calibrationTerms: [1]CURVE_SMOOTHING!$A$9:OFFSET([1]CURVE_SMOOTHING!$A$9,[1]CURVE_SMOOTHING!$B$7-1,0)
Name CurveCollection: USD_OIS!#REF!
Name CurveCollection: USD_SOFR_CURVE!#REF!
Name enableGlobalCalibration: [2]Settings!$E$4
Name PaymentDates: [1]CURVE_SMOOTHING!$B$9:OFFSET([1]CURVE_SMOOTHING!$B$9,[1]CURVE_SMOOTHING!$B$7-1,0)
Name PolynomialOrder: [1]CURVE_SMOOTHING!$C$5
Name Settings.COB: SWAP_GENERATORS!#REF!
Name Settings.COB: [2]Settings!$C$4
Name Settings.PulseFrequency: [2]Settings!$O$2
Name SmoothedForwards: [1]CURVE_SMOOTHING!$E$9:OFFSET([1]CURVE_SMOOTHING!$E$9,[1]CURVE_SMOOTHING!$B$7-1,0)
Name USD_SOFR_CURVE_GENERATOR: SWAP_GENERATORS!#REF!
Name USD_SOFR_SWAP_GENERATOR: SWAP_GENERATORS!$D$5
Name USD_SOFR_SWAP_GENERATOR_UNDER_1Y: SWAP_GENERATORS!$J$5
Name xValues: [1]CURVE_SMOOTHING!$H$9:$H$28
Name yValues: [1]CURVE_SMOOTHING!$K$9:$K$28

Sheet USD_SOFR_CURVE
B3: Curve Generator Handle | C3: =_xll.meLWOCurveGeneratorCreate("CURVEGEN_USDSOFR",B5,B6:C13,B15,B16:C30) -> CURVEGEN_USDSOFR@34:3 | F3: MARKETDATAPROPERTIES | I3: OIS
I4: Term | J4: Rate | K4: StartDate | L4: EndDate | M4: Volatility
B5: CURVEPROPERTIES | F5: Currency | G5: USD | I5: ON | J5: 0.0157
B6: CurveType | C6: ARR | F6: CurveType | G6: ARR | I6: 1W | J6: 0.0155
B7: CurveIndexFrequency | C7: DAILY | F7: CurveIndexFrequency | G7: DAILY | I7: FUTURE1 | J7: 98.45 | K7: =_xll.meDateIMMNext($G$8) -> 43817 | L7: =_xll.meDateIMMNext(K7) -> 43908 | M7: 0 | N7: SOFR FUTURE
B8: StaticDataTable | C8: SOFR | F8: AsOfDate | G8: 43776 | I8: FUTURE2 | J8: 98.48464 | K8: =L7 -> 43908 | L8: =_xll.meDateIMMNext(K8) -> 43999 | M8: 0 | N8: SOFR FUTURE
B9: IndexName | C9: USDSOFR | I9: FUTURE3 | J9: 98.51928 | K9: =L8 -> 43999 | L9: =_xll.meDateIMMNext(K9) -> 44090 | M9: 0 | N9: SOFR FUTURE
B10: Currency | C10: USD | I10: FUTURE4 | J10: 98.55392 | K10: =L9 -> 44090 | L10: =_xll.meDateIMMNext(K10) -> 44181 | M10: 0 | N10: SOFR FUTURE
B11: interpolation | C11: FN_LINEARSPLINEINTERPOLATION | F11: Create Market Data Handle | I11: 2Y | J11: 0.0144608
B12: yieldgen.interpolation | C12: FN_LINEARSPLINEINTERPOLATION | F12: Handle Name | G12: USD_OIS_CURVE_MARKETDATA | I12: 5Y | J12: 0.0147765
B13: InterpolationJoinDate | C13: =L9 -> 44090 | F13: Market Data Handle | G13: =_xll.meLWOCurveMarketDataCreate(G12,F3,F5:G8,I3,I5:M30) -> USD_OIS_CURVE_MARKETDATA@35:3 | I13: 7Y | J13: 0.0153018
I14: 10Y | J14: 0.0161845
B15: OIS | I15: 12Y | J15: 0.0166681
B16: calendar | C16: NYB | I16: 15Y | J16: 0.017191
B17: daycount | C17: ACT/360 | I17: 20Y | J17: 0.0177368
B18: frequency | C18: ANNUAL | F18: Curve Dictionary | I18: 25Y | J18: 0.017928
B19: generatemethod | C19: DAILYCOMPOUNDING | F19: Handle Name | G19: CURVE_USDSOFR | I19: 30Y | J19: 0.0179398
B20: resetlag | C20: 2D | F20: Curve Generator | G20: =C3 -> CURVEGEN_USDSOFR@34:3 | I20: 40Y | J20: 0.0177338
B21: firstrate | C21: SHORTMARKET | F21: Domestic Curve Collection | G21: USDYC | I21: 50Y | J21: 0.0173572
B22: slidingrule | C22: MOD_FOLLOWING | F22: Foreign Curve Collection
B23: eomday | C23: 31
B24: iseomroll | C24: TRUE
B25: shorttermconvention | C25: ARITHMETICAVERAGE
B26: longterm.generatemethod | C26: NONE | F26: Curve Build
B27: Epsilon | C27: 1e-10 | F27: Handle Name | G27: {=_xll.meLWOCurveCalibrate(G19,G20,G13,G21,G22)} -> CURVE_USDSOFR@36:3
B28: MaxLoop | C28: 1000 | F28: Curve Collection | G28: USDYC
B29: CompoundingMethod | C29: ARITHMETIC | F29: Curve Index | G29: SOFR:USDSOFR
B30: SmoothShortEnd | C30: FALSE | F30: Calibration Time Taken | G30: 0.05800 sec
F31: Curve Loaded | G31: =_xll.meLWOExists(G27,"CURVE") -> TRUE

Sheet USD_OIS
B3: Curve Generator Handle | C3: =_xll.meLWOCurveGeneratorCreate("CURVEGEN_USDSOIS_WITH_SOFR_DF",B5,B6:C13,B15,B16:C30) -> CURVEGEN_USDSOIS_WITH_SOFR_DF@4:3 | F3: MARKETDATAPROPERTIES | I3: OIS
I4: Term | J4: Rate | K4: StartDate | L4: EndDate | M4: Volatility
B5: CURVEPROPERTIES | F5: Currency | G5: USD | I5: ON | J5: 0.0155
B6: CurveType | C6: OIS | F6: CurveType | G6: OIS | I6: 1W | J6: 0.0156546
B7: CurveIndexFrequency | C7: DAILY | F7: CurveIndexFrequency | G7: DAILY | I7: MPC1 | J7: 0.0152 | K7: 43817 | L7: 43908 | N7: FED FUND MPC SWAP
B8: StaticDataTable | C8: OIS | F8: AsOfDate | G8: 43776 | I8: MPC2 | J8: 0.0148 | K8: 43908 | L8: 43999 | N8: FED FUND MPC SWAP
B9: IndexName | C9: USDOIS | I9: MPC3 | J9: 0.0145 | K9: 43999 | L9: 44090 | N9: FED FUND MPC SWAP
B10: Currency | C10: USD | I10: MPC4 | J10: 0.01435 | K10: 44090 | L10: 44181 | N10: FED FUND MPC SWAP
B11: interpolation | C11: FN_SPLINEINTERPOLATION | F11: Create Market Data Handle | I11: 2Y | J11: 0.01433
B12: yieldgen.interpolation | C12: FN_SPLINEINTERPOLATION | F12: Handle Name | G12: USD_OIS_CURVE_MARKETDATA | I12: 5Y | J12: 0.0145344
B13: dfCurveName | C13: SOFR | F13: Market Data Handle | G13: =_xll.meLWOCurveMarketDataCreate(G12,F3,F5:G8,I3,I5:M30) -> USD_OIS_CURVE_MARKETDATA@5:3 | I13: 7Y | J13: 0.0150851
I14: 10Y | J14: 0.0159844
B15: OIS | I15: 12Y | J15: 0.0164793
B16: calendar | C16: NYB | I16: 15Y | J16: 0.0170123
B17: daycount | C17: ACT/360 | I17: 20Y | J17: 0.0175687
B18: frequency | C18: ANNUAL | F18: Curve Dictionary | I18: 25Y | J18: 0.013831423
B19: generatemethod | C19: DAILYCOMPOUNDING | F19: Handle Name | G19: CURVE_USDOIS | I19: 30Y | J19: 0.0177902
B20: resetlag | C20: 2D | F20: Curve Generator | G20: =C3 -> CURVEGEN_USDSOIS_WITH_SOFR_DF@4:3 | I20: 40Y | J20: 0.01757776
B21: firstrate | C21: SHORTMARKET | F21: Domestic Curve Collection | G21: USDYC | I21: 50Y | J21: 0.0172051
B22: slidingrule | C22: MOD_FOLLOWING | F22: Foreign Curve Collection
B23: eomday | C23: 31
B24: iseomroll | C24: TRUE
B25: shorttermconvention | C25: ARITHMETICAVERAGE
B26: longterm.generatemethod | C26: NONE | F26: Curve Build
B27: Epsilon | C27: 1e-10 | F27: Handle Name | G27: {=_xll.meLWOCurveCalibrate(G19,G20,G13,G21,G22)} -> CURVE_USDOIS@12:2
B28: MaxLoop | C28: 1000 | F28: Curve Collection | G28: USDYC
B29: CompoundingMethod | C29: ARITHMETIC | F29: Curve Index | G29: OIS:USDOIS
B30: SmoothShortEnd | C30: FALSE | F30: Calibration Time Taken | G30: 0.04500 sec
F31: Curve Loaded | G31: =_xll.meLWOExists(G27,"CURVE") -> TRUE

Sheet SWAP_GENERATORS
C4: USD SOFR SWAP GENERATOR TEMPLATE | I4: USD SOFR SWAP GENERATOR TEMPLATE
C5: Create Template | D5: =_xll.meLWOSwapGeneratorCreate(D6,C10:E37) -> USD_SOFR_SWAP@3:3 | I5: Create Template | J5: =_xll.meLWOSwapGeneratorCreate(J6,I10:K37) -> USD_SOFR_SWAP_UNDER_1Y@1:3
C6: Object Name | D6: USD_SOFR_SWAP | I6: Object Name | J6: USD_SOFR_SWAP_UNDER_1Y
C10: LEGTYPE | D10: Leg1:Fixed | E10: Leg2:Float | I10: LEGTYPE | J10: Leg1:Fixed | K10: Leg2:Float
C11: LEVERAGE | D11: 1 | E11: 1 | I11: LEVERAGE | J11: 1 | K11: 1
C12: FORECASTCURVE | E12: USDSOFR | I12: FORECASTCURVE | K12: USDSOFR
C13: DISCOUNTCURVE | D13: USDSOFR | E13: USDSOFR | I13: DISCOUNTCURVE | J13: USDSOFR | K13: USDSOFR
C14: COMPOUNDMETHOD | D14: NONE | E14: ARITHMETIC | I14: COMPOUNDMETHOD | J14: NONE | K14: GEOMETRIC
C15: NOTIONALEXCHANGE | D15: NONE | E15: NONE | I15: NOTIONALEXCHANGE | J15: NONE | K15: NONE
C16: VALUATIONCURRENCY | D16: USD | E16: USD | I16: VALUATIONCURRENCY | J16: USD | K16: USD
C17: CURRENCY | D17: USD | E17: USD | I17: CURRENCY | J17: USD | K17: USD
C18: ACCRUALFREQUENCY | D18: ANNUAL | E18: ANNUAL | I18: ACCRUALFREQUENCY | J18: ANNUAL | K18: ANNUAL
C19: ACCRUALBUSINESSDAYADJUSTMENT | D19: MOD_FOLLOWING | E19: MOD_FOLLOWING | I19: ACCRUALBUSINESSDAYADJUSTMENT | J19: MOD_FOLLOWING | K19: MOD_FOLLOWING
C20: ACCRUALCALENDAR | D20: NYB | E20: NYB | I20: ACCRUALCALENDAR | J20: NYB | K20: NYB
C21: ACCRUALDAYCOUNT | D21: ACT/360 | E21: ACT/360 | I21: ACCRUALDAYCOUNT | J21: ACT/360 | K21: ACT/360
C22: PAYMENTFREQUENCY | D22: ANNUAL | E22: ANNUAL | I22: PAYMENTFREQUENCY | J22: ANNUAL | K22: ANNUAL
C23: PAYMENTBUSINESSDAYADJUSTMENT | D23: MOD_FOLLOWING | E23: MOD_FOLLOWING | I23: PAYMENTBUSINESSDAYADJUSTMENT | J23: MOD_FOLLOWING | K23: MOD_FOLLOWING
C24: PAYMENTCALENDAR | D24: NYB | E24: NYB | I24: PAYMENTCALENDAR | J24: NYB | K24: NYB
C25: PAYMENTLAG | D25: 0D | E25: 0D | I25: PAYMENTLAG | J25: 0D | K25: 0D
C26: FIRSTSTUBDATE | I26: FIRSTSTUBDATE
C27: LASTSTUBDATE | I27: LASTSTUBDATE
C28: ROLLDAY | D28: NORMAL | E28: NORMAL | I28: ROLLDAY | J28: NORMAL | K28: NORMAL
C29: STUBTYPE | D29: SHORTSTART | E29: SHORTSTART | I29: STUBTYPE | J29: SHORTSTART | K29: SHORTSTART
C30: FIXINGBUSINESSDAYADJUSTMENT | E30: MOD_FOLLOWING | I30: FIXINGBUSINESSDAYADJUSTMENT | K30: MOD_FOLLOWING
C31: FIXINGCALENDAR | E31: NYB | I31: FIXINGCALENDAR | K31: NYB
C32: FIXINGLAG | E32: 0D | I32: FIXINGLAG | K32: 0D
C33: FIXINGADVANCEORARREAR | I33: FIXINGADVANCEORARREAR
C34: FIRSTSTUBCURVEINDEX | E34: NATURAL | I34: FIRSTSTUBCURVEINDEX | K34: NATURAL
C35: LASTSTUBCURVEINDEX | E35: NATURAL | I35: LASTSTUBCURVEINDEX | K35: NATURAL
B39: * Market Convention: OIS Swaps Under 1Y with Arithmetic Compounding Default to Simple or Geometric Compounding
C42: USD FED FUNDS SWAP GENERATOR TEMPLATE | I42: USD FED FUNDS SWAP GENERATOR TEMPLATE
C43: Create Template | D43: =_xll.meLWOSwapGeneratorCreate(D44,C48:E75) -> USD_OIS_SWAP@6:3 | I43: Create Template | J43: =_xll.meLWOSwapGeneratorCreate(J44,I48:K75) -> USD_OIS_SWAP_UNDER_1Y@2:3
C44: Object Name | D44: USD_OIS_SWAP | I44: Object Name | J44: USD_OIS_SWAP_UNDER_1Y
C48: LEGTYPE | D48: Leg1:Fixed | E48: Leg2:Float | I48: LEGTYPE | J48: Leg1:Fixed | K48: Leg2:Float
C49: LEVERAGE | D49: 1 | E49: 1 | I49: LEVERAGE | J49: 1 | K49: 1
C50: FORECASTCURVE | E50: USDOIS | I50: FORECASTCURVE | K50: USDOIS
C51: DISCOUNTCURVE | D51: USDSOFR | E51: USDSOFR | I51: DISCOUNTCURVE | J51: USDSOFR | K51: USDSOFR
C52: COMPOUNDMETHOD | D52: NONE | E52: ARITHMETIC | I52: COMPOUNDMETHOD | J52: NONE | K52: GEOMETRIC
C53: NOTIONALEXCHANGE | D53: NONE | E53: NONE | I53: NOTIONALEXCHANGE | J53: NONE | K53: NONE
C54: VALUATIONCURRENCY | D54: USD | E54: USD | I54: VALUATIONCURRENCY | J54: USD | K54: USD
...

Sheet REPRICING
B2: Trade Dates | F2: USD SOFR SWAPS | N2: Trade Booking & Pricing | R2: Bloomberg Calibration Data
D3: Unadjusted Date ! | H3: Swap Template
B4: EffectiveDate | C4: Calendar | D4: MaturityDate | F4: EffectiveDate | G4: Maturity | H4: Generator | I4: PayRec | J4: Notional | K4: FixedRate | L4: Libor Spread | N4: CreateSwap | O4: CurveCollection | P4: ParRate | R4: Tenor | S4: ParRate | T4: +/- Bps
B5: =_xll.meDateFromTenor(USD_SOFR_CURVE!$G$8,F5,"MOD_FOLLOWING",C5,"") -> 43781 | C5: NYB | D5: =_xll.meDateFromTenor(B5,G5,) -> 43782 | F5: 2D | G5: =R5 -> ON | H5: =USD_SOFR_SWAP_GENERATOR_UNDER_1Y -> USD_SOFR_SWAP_UNDER_1Y@1:3 | I5: RECEIVE | J5: 1000000 | K5: 0.01 | L5: 0 | M5: 1 | N5: =_xll.meLWOSwapCreateFromGenerator("USD_SOFR_SWAP_"&G5,H5,I5,J5,B5,D5,K5,L5) -> USD_SOFR_SWAP_ON@18:3 | O5: =USD_SOFR_CURVE!$G$28 -> USDYC | P5: =_xll.meLWOSwapParRate(N5,O5) -> 0.015495997 | R5: =USD_SOFR_CURVE!I5 -> ON | S5: =USD_SOFR_CURVE!J5 -> 0.0157 | T5: =(P5-S5)*10000 -> -2.0400313 | U5: <--- Fix
B6: =_xll.meDateFromTenor(USD_SOFR_CURVE!$G$8,F6,"MOD_FOLLOWING",C6,"") -> 43781 | C6: NYB | D6: =_xll.meDateFromTenor(B6,G6,) -> 43788 | F6: 2D | G6: =R6 -> 1W | H6: =USD_SOFR_SWAP_GENERATOR_UNDER_1Y -> USD_SOFR_SWAP_UNDER_1Y@1:3 | I6: RECEIVE | J6: 1000000 | K6: 0.01 | L6: 0 | M6: =M5+1 -> 2 | N6: =_xll.meLWOSwapCreateFromGenerator("USD_SOFR_SWAP_"&G6,H6,I6,J6,B6,D6,K6,L6) -> USD_SOFR_SWAP_1W@7:3 | O6: =USD_SOFR_CURVE!$G$28 -> USDYC | P6: =_xll.meLWOSwapParRate(N6,O6) -> 0.0155 | R6: =USD_SOFR_CURVE!I6 -> 1W | S6: =USD_SOFR_CURVE!J6 -> 0.0155 | T6: =(P6-S6)*10000 -> 5.9828878e-09
B7: =_xll.meDateFromTenor(USD_SOFR_CURVE!$G$8,F7,"MOD_FOLLOWING",C7,"") -> 43781 | C7: NYB | D7: =_xll.meDateFromTenor(B7,G7,) -> 44512 | F7: 2D | G7: =R7 -> 2Y | H7: =USD_SOFR_SWAP_GENERATOR -> USD_SOFR_SWAP@3:3 | I7: RECEIVE | J7: 1000000 | K7: 0.01 | L7: 0 | M7: =M6+1 -> 3 | N7: =_xll.meLWOSwapCreateFromGenerator("USD_SOFR_SWAP_"&G7,H7,I7,J7,B7,D7,K7,L7) -> USD_SOFR_SWAP_2Y@28:3 | O7: =USD_SOFR_CURVE!$G$28 -> USDYC | P7: =_xll.meLWOSwapParRate(N7,O7) -> 0.014460797 | R7: =USD_SOFR_CURVE!I11 -> 2Y | S7: =USD_SOFR_CURVE!J11 -> 0.0144608 | T7: =(P7-S7)*10000 -> -2.7956673e-05
B8: =_xll.meDateFromTenor(USD_SOFR_CURVE!$G$8,F8,"MOD_FOLLOWING",C8,"") -> 43781 | C8: NYB | D8: =_xll.meDateFromTenor(B8,G8,) -> 45608 | F8: 2D | G8: 5Y | H8: =USD_SOFR_SWAP_GENERATOR -> USD_SOFR_SWAP@3:3 | I8: RECEIVE | J8: 1000000 | K8: 0.01 | L8: 0 | M8: =M7+1 -> 4 | N8: =_xll.meLWOSwapCreateFromGenerator("USD_SOFR_SWAP_"&G8,H8,I8,J8,B8,D8,K8,L8) -> USD_SOFR_SWAP_5Y@37:0 | O8: =USD_SOFR_CURVE!$G$28 -> USDYC | P8: =_xll.meLWOSwapParRate(N8,O8) -> 0.014776499 | R8: =USD_SOFR_CURVE!I12 -> 5Y | S8: =USD_SOFR_CURVE!J12 -> 0.0147765 | T8: =(P8-S8)*10000 -> -1.1534595e-05
B9: =_xll.meDateFromTenor(USD_SOFR_CURVE!$G$8,F9,"MOD_FOLLOWING",C9,"") -> 43781 | C9: NYB | D9: =_xll.meDateFromTenor(B9,G9,) -> 46338 | F9: 2D | G9: =R9 -> 7Y | H9: =USD_SOFR_SWAP_GENERATOR -> USD_SOFR_SWAP@3:3 | I9: RECEIVE | J9: 1000000 | K9: 0.01 | L9: 0 | M9: =M8+1 -> 5 | N9: =_xll.meLWOSwapCreateFromGenerator("USD_SOFR_SWAP_"&G9,H9,I9,J9,B9,D9,K9,L9) -> USD_SOFR_SWAP_7Y@27:3 | O9: =USD_SOFR_CURVE!$G$28 -> USDYC | P9: =_xll.meLWOSwapParRate(N9,O9) -> 0.015301799 | R9: =USD_SOFR_CURVE!I13 -> 7Y | S9: =USD_SOFR_CURVE!J13 -> 0.0153018 | T9: =(P9-S9)*10000 -> -8.3644635e-06
B10: =_xll.meDateFromTenor(USD_SOFR_CURVE!$G$8,F10,"MOD_FOLLOWING",C10,"") -> 43781 | C10: NYB | D10: =_xll.meDateFromTenor(B10,G10,) -> 47434 | F10: 2D | G10: =R10 -> 10Y | H10: =USD_SOFR_SWAP_GENERATOR -> USD_SOFR_SWAP@3:3 | I10: RECEIVE | J10: 1000000 | K10: 0.01 | L10: 0 | M10: =M9+1 -> 6 | N10: =_xll.meLWOSwapCreateFromGenerator("USD_SOFR_SWAP_"&G10,H10,I10,J10,B10,D10,K10,L10) -> USD_SOFR_SWAP_10Y@32:3 | O10: =USD_SOFR_CURVE!$G$28 -> USDYC | P10: =_xll.meLWOSwapParRate(N10,O10) -> 0.016184499 | R10: =USD_SOFR_CURVE!I14 -> 10Y | S10: =USD_SOFR_CURVE!J14 -> 0.0161845 | T10: =(P10-S10)*10000 -> -6.0011415e-06
B11: =_xll.meDateFromTenor(USD_SOFR_CURVE!$G$8,F11,"MOD_FOLLOWING",C11,"") -> 43781 | C11: NYB | D11: =_xll.meDateFromTenor(B11,G11,) -> 48164 | F11: 2D | G11: =R11 -> 12Y | H11: =USD_SOFR_SWAP_GENERATOR -> USD_SOFR_SWAP@3:3 | I11: RECEIVE | J11: 1000000 | K11: 0.01 | L11: 0 | M11: =M10+1 -> 7 | N11: =_xll.meLWOSwapCreateFromGenerator("USD_SOFR_SWAP_"&G11,H11,I11,J11,B11,D11,K11,L11) -> USD_SOFR_SWAP_12Y@33:3 | O11: =USD_SOFR_CURVE!$G$28 -> USDYC | P11: =_xll.meLWOSwapParRate(N11,O11) -> 0.016668099 | R11: =USD_SOFR_CURVE!I15 -> 12Y | S11: =USD_SOFR_CURVE!J15 -> 0.0166681 | T11: =(P11-S11)*10000 -> -5.0907123e-06
B12: =_xll.meDateFromTenor(USD_SOFR_CURVE!$G$8,F12,"MOD_FOLLOWING",C12,"") -> 43781 | C12: NYB | D12: =_xll.meDateFromTenor(B12,G12,) -> 49260 | F12: 2D | G12: =R12 -> 15Y | H12: =USD_SOFR_SWAP_GENERATOR -> USD_SOFR_SWAP@3:3 | I12: RECEIVE | J12: 1000000 | K12: 0.01 | L12: 0 | M12: =M11+1 -> 8 | N12: =_xll.meLWOSwapCreateFromGenerator("USD_SOFR_SWAP_"&G12,H12,I12,J12,B12,D12,K12,L12) -> USD_SOFR_SWAP_15Y@16:3 | O12: =USD_SOFR_CURVE!$G$28 -> USDYC | P12: =_xll.meLWOSwapParRate(N12,O12) -> 0.017191 | R12: =USD_SOFR_CURVE!I16 -> 15Y | S12: =USD_SOFR_CURVE!J16 -> 0.017191 | T12: =(P12-S12)*10000 -> -4.1823002e-06
B13: =_xll.meDateFromTenor(USD_SOFR_CURVE!$G$8,F13,"MOD_FOLLOWING",C13,"") -> 43781 | C13: NYB | D13: =_xll.meDateFromTenor(B13,G13,) -> 51086 | F13: 2D | G13: =R13 -> 20Y | H13: =USD_SOFR_SWAP_GENERATOR -> USD_SOFR_SWAP@3:3 | I13: RECEIVE | J13: 1000000 | K13: 0.01 | L13: 0 | M13: =M12+1 -> 9 | N13: =_xll.meLWOSwapCreateFromGenerator("USD_SOFR_SWAP_"&G13,H13,I13,J13,B13,D13,K13,L13) -> USD_SOFR_SWAP_20Y@24:3 | O13: =USD_SOFR_CURVE!$G$28 -> USDYC | P13: =_xll.meLWOSwapParRate(N13,O13) -> 0.0177368 | R13: =USD_SOFR_CURVE!I17 -> 20Y | S13: =USD_SOFR_CURVE!J17 -> 0.0177368 | T13: =(P13-S13)*10000 -> -3.2817593e-06
B14: =_xll.meDateFromTenor(USD_SOFR_CURVE!$G$8,F14,"MOD_FOLLOWING",C14,"") -> 43781 | C14: NYB | D14: =_xll.meDateFromTenor(B14,G14,) -> 52913 | F14: 2D | G14: =R14 -> 25Y | H14: =USD_SOFR_SWAP_GENERATOR -> USD_SOFR_SWAP@3:3 | I14: RECEIVE | J14: 1000000 | K14: 0.01 | L14: 0 | M14: =M13+1 -> 10 | N14: =_xll.meLWOSwapCreateFromGenerator("USD_SOFR_SWAP_"&G14,H14,I14,J14,B14,D14,K14,L14) -> USD_SOFR_SWAP_25Y@10:3 | O14: =USD_SOFR_CURVE!$G$28 -> USDYC | P14: =_xll.meLWOSwapParRate(N14,O14) -> 0.017928 | R14: =USD_SOFR_CURVE!I18 -> 25Y | S14: =USD_SOFR_CURVE!J18 -> 0.017928 | T14: =(P14-S14)*10000 -> -2.7458034e-06
B15: =_xll.meDateFromTenor(USD_SOFR_CURVE!$G$8,F15,"MOD_FOLLOWING",C15,"") -> 43781 | C15: NYB | D15: =_xll.meDateFromTenor(B15,G15,) -> 54739 | F15: 2D | G15: =R15 -> 30Y | H15: =USD_SOFR_SWAP_GENERATOR -> USD_SOFR_SWAP@3:3 | I15: RECEIVE | J15: 1000000 | K15: 0.01 | L15: 0 | M15: =M14+1 -> 11 | N15: =_xll.meLWOSwapCreateFromGenerator("USD_SOFR_SWAP_"&G15,H15,I15,J15,B15,D15,K15,L15) -> USD_SOFR_SWAP_30Y@30:3 | O15: =USD_SOFR_CURVE!$G$28 -> USDYC | P15: =_xll.meLWOSwapParRate(N15,O15) -> 0.0179398 | R15: =USD_SOFR_CURVE!I19 -> 30Y | S15: =USD_SOFR_CURVE!J19 -> 0.0179398 | T15: =(P15-S15)*10000 -> -2.3906118e-06
B16: =_xll.meDateFromTenor(USD_SOFR_CURVE!$G$8,F16,"MOD_FOLLOWING",C16,"") -> 43781 | C16: NYB | D16: =_xll.meDateFromTenor(B16,G16,) -> 58391 | F16: 2D | G16: =R16 -> 40Y | H16: =USD_SOFR_SWAP_GENERATOR -> USD_SOFR_SWAP@3:3 | I16: RECEIVE | J16: 1000000 | K16: 0.01 | L16: 0 | M16: =M15+1 -> 12 | N16: =_xll.meLWOSwapCreateFromGenerator("USD_SOFR_SWAP_"&G16,H16,I16,J16,B16,D16,K16,L16) -> USD_SOFR_SWAP_40Y@31:3 | O16: =USD_SOFR_CURVE!$G$28 -> USDYC | P16: =_xll.meLWOSwapParRate(N16,O16) -> 0.0177338 | R16: =USD_SOFR_CURVE!I20 -> 40Y | S16: =USD_SOFR_CURVE!J20 -> 0.0177338 | T16: =(P16-S16)*10000 -> -1.9478501e-06
B17: =_xll.meDateFromTenor(USD_SOFR_CURVE!$G$8,F17,"MOD_FOLLOWING",C17,"") -> 43781 | C17: NYB | D17: =_xll.meDateFromTenor(B17,G17,) -> 62044 | F17: 2D | G17: =R17 -> 50Y | H17: =USD_SOFR_SWAP_GENERATOR -> USD_SOFR_SWAP@3:3 | I17: RECEIVE | J17: 1000000 | K17: 0.01 | L17: 0 | M17: =M16+1 -> 13 | N17: =_xll.meLWOSwapCreateFromGenerator("USD_SOFR_SWAP_"&G17,H17,I17,J17,B17,D17,K17,L17) -> USD_SOFR_SWAP_50Y@23:3 | O17: =USD_SOFR_CURVE!$G$28 -> USDYC | P17: =_xll.meLWOSwapParRate(N17,O17) -> 0.0173572 | R17: =USD_SOFR_CURVE!I21 -> 50Y | S17: =USD_SOFR_CURVE!J21 -> 0.0173572 | T17: =(P17-S17)*10000 -> -1.6841249e-06
B19: Trade Dates | F19: USD OIS SWAPS - WITH RISK-FREE SOFR DISCOUNTING | N19: Trade Booking & Pricing | R19: Bloomberg Calibration Data
D20: Unadjusted Date ! | H20: =H22 -> USD_OIS_SWAP_UNDER_1Y@2:3
B21: EffectiveDate | C21: Calendar | D21: MaturityDate | F21: EffectiveDate | G21: Maturity | H21: Generator | I21: PayRec | J21: Notional | K21: FixedRate | L21: Libor Spread | N21: CreateSwap | O21: CurveCollection | P21: ParRate | R21: Tenor | S21: ParRate | T21: +/- Bps
B22: =_xll.meDateFromTenor(USD_OIS!$G$8,F22,"MOD_FOLLOWING",C22,"") -> 43781 | C22: NYB | D22: =_xll.meDateFromTenor(B22,G22,) -> 43782 | F22: 2D | G22: =R22 -> ON | H22: =SWAP_GENERATORS!$J$43 -> USD_OIS_SWAP_UNDER_1Y@2:3 | I22: RECEIVE | J22: 1000000 | K22: 0.01 | L22: 0 | M22: 1 | N22: =_xll.meLWOSwapCreateFromGenerator("USD_OIS_SWAP_"&G22,H22,I22,J22,B22,D22,K22,L22) -> USD_OIS_SWAP_ON@25:3 | O22: =USD_OIS!$G$28 -> USDYC | P22: =_xll.meLWOSwapParRate(N22,O22) -> 0.01558275 | R22: =USD_OIS!I5 -> ON | S22: =USD_OIS!J5 -> 0.0155 | T22: =(P22-S22)*10000 -> 0.82750492 | U22: <--- Fix
B23: =_xll.meDateFromTenor(USD_OIS!$G$8,F23,"MOD_FOLLOWING",C23,"") -> 43781 | C23: NYB | D23: =_xll.meDateFromTenor(B23,G23,) -> 43788 | F23: 2D | G23: =R23 -> 1W | H23: =SWAP_GENERATORS!$J$43 -> USD_OIS_SWAP_UNDER_1Y@2:3 | I23: RECEIVE | J23: 1000000 | K23: 0.01 | L23: 0 | M23: =M22+1 -> 2 | N23: =_xll.meLWOSwapCreateFromGenerator("USD_OIS_SWAP_"&G23,H23,I23,J23,B23,D23,K23,L23) -> USD_OIS_SWAP_1W@8:3 | O23: =USD_OIS!$G$28 -> USDYC | P23: =_xll.meLWOSwapParRate(N23,O23) -> 0.0156546 | R23: =USD_OIS!I6 -> 1W | S23: =USD_OIS!J6 -> 0.0156546 | T23: =(P23-S23)*10000 -> 6.2301553e-09
B24: =_xll.meDateFromTenor(USD_OIS!$G$8,F24,"MOD_FOLLOWING",C24,"") -> 43781 | C24: NYB | D24: =_xll.meDateFromTenor(B24,G24,) -> 44512 | F24: 2D | G24: =R24 -> 2Y | H24: =SWAP_GENERATORS!$D$43 -> USD_OIS_SWAP@6:3 | I24: RECEIVE | J24: 1000000 | K24: 0.01 | L24: 0 | M24: =M23+1 -> 3 | N24: =_xll.meLWOSwapCreateFromGenerator("USD_OIS_SWAP_"&G24,H24,I24,J24,B24,D24,K24,L24) -> USD_OIS_SWAP_2Y@17:3 | O24: =USD_OIS!$G$28 -> USDYC | P24: =_xll.meLWOSwapParRate(N24,O24) -> 0.014329997 | R24: =USD_OIS!I11 -> 2Y | S24: =USD_OIS!J11 -> 0.01433 | T24: =(P24-S24)*10000 -> -2.749344e-05
B25: =_xll.meDateFromTenor(USD_OIS!$G$8,F25,"MOD_FOLLOWING",C25,"") -> 43781 | C25: NYB | D25: =_xll.meDateFromTenor(B25,G25,) -> 45608 | F25: 2D | G25: =R25 -> 5Y | H25: =SWAP_GENERATORS!$D$43 -> USD_OIS_SWAP@6:3 | I25: RECEIVE | J25: 1000000 | K25: 0.01 | L25: 0 | M25: =M24+1 -> 4 | N25: =_xll.meLWOSwapCreateFromGenerator("USD_OIS_SWAP_"&G25,H25,I25,J25,B25,D25,K25,L25) -> USD_OIS_SWAP_5Y@13:3 | O25: =USD_OIS!$G$28 -> USDYC | P25: =_xll.meLWOSwapParRate(N25,O25) -> 0.014534399 | R25: =USD_OIS!I12 -> 5Y | S25: =USD_OIS!J12 -> 0.0145344 | T25: =(P25-S25)*10000 -> -1.1330816e-05
B26: =_xll.meDateFromTenor(USD_OIS!$G$8,F26,"MOD_FOLLOWING",C26,"") -> 43781 | C26: NYB | D26: =_xll.meDateFromTenor(B26,G26,) -> 46338 | F26: 2D | G26: =R26 -> 7Y | H26: =SWAP_GENERATORS!$D$43 -> USD_OIS_SWAP@6:3 | I26: RECEIVE | J26: 1000000 | K26: 0.01 | L26: 0 | M26: =M25+1 -> 5 | N26: =_xll.meLWOSwapCreateFromGenerator("USD_OIS_SWAP_"&G26,H26,I26,J26,B26,D26,K26,L26) -> USD_OIS_SWAP_7Y@26:3 | O26: =USD_OIS!$G$28 -> USDYC | P26: =_xll.meLWOSwapParRate(N26,O26) -> 0.015085099 | R26: =USD_OIS!I13 -> 7Y | S26: =USD_OIS!J13 -> 0.0150851 | T26: =(P26-S26)*10000 -> -8.2120498e-06
B27: =_xll.meDateFromTenor(USD_OIS!$G$8,F27,"MOD_FOLLOWING",C27,"") -> 43781 | C27: NYB | D27: =_xll.meDateFromTenor(B27,G27,) -> 47434 | F27: 2D | G27: =R27 -> 10Y | H27: =SWAP_GENERATORS!$D$43 -> USD_OIS_SWAP@6:3 | I27: RECEIVE | J27: 1000000 | K27: 0.01 | L27: 0 | M27: =M26+1 -> 6 | N27: =_xll.meLWOSwapCreateFromGenerator("USD_OIS_SWAP_"&G27,H27,I27,J27,B27,D27,K27,L27) -> USD_OIS_SWAP_10Y@15:3 | O27: =USD_OIS!$G$28 -> USDYC | P27: =_xll.meLWOSwapParRate(N27,O27) -> 0.015984399 | R27: =USD_OIS!I14 -> 10Y | S27: =USD_OIS!J14 -> 0.0159844 | T27: =(P27-S27)*10000 -> -5.8935768e-06
B28: =_xll.meDateFromTenor(USD_OIS!$G$8,F28,"MOD_FOLLOWING",C28,"") -> 43781 | C28: NYB | D28: =_xll.meDateFromTenor(B28,G28,) -> 48164 | F28: 2D | G28: =R28 -> 12Y | H28: =SWAP_GENERATORS!$D$43 -> USD_OIS_SWAP@6:3 | I28: RECEIVE | J28: 1000000 | K28: 0.01 | L28: 0 | M28: =M27+1 -> 7 | N28: =_xll.meLWOSwapCreateFromGenerator("USD_OIS_SWAP_"&G28,H28,I28,J28,B28,D28,K28,L28) -> USD_OIS_SWAP_12Y@11:3 | O28: =USD_OIS!$G$28 -> USDYC | P28: =_xll.meLWOSwapParRate(N28,O28) -> 0.0164793 | R28: =USD_OIS!I15 -> 12Y | S28: =USD_OIS!J15 -> 0.0164793 | T28: =(P28-S28)*10000 -> -4.9979062e-06
B29: =_xll.meDateFromTenor(USD_OIS!$G$8,F29,"MOD_FOLLOWING",C29,"") -> 43781 | C29: NYB | D29: =_xll.meDateFromTenor(B29,G29,) -> 49260 | F29: 2D | G29: =R29 -> 15Y | H29: =SWAP_GENERATORS!$D$43 -> USD_OIS_SWAP@6:3 | I29: RECEIVE | J29: 1000000 | K29: 0.01 | L29: 0 | M29: =M28+1 -> 8 | N29: =_xll.meLWOSwapCreateFromGenerator("USD_OIS_SWAP_"&G29,H29,I29,J29,B29,D29,K29,L29) -> USD_OIS_SWAP_15Y@29:3 | O29: =USD_OIS!$G$28 -> USDYC | P29: =_xll.meLWOSwapParRate(N29,O29) -> 0.0170123 | R29: =USD_OIS!I16 -> 15Y | S29: =USD_OIS!J16 -> 0.0170123 | T29: =(P29-S29)*10000 -> -4.1002325e-06
B30: =_xll.meDateFromTenor(USD_OIS!$G$8,F30,"MOD_FOLLOWING",C30,"") -> 43781 | C30: NYB | D30: =_xll.meDateFromTenor(B30,G30,) -> 51086 | F30: 2D | G30: =R30 -> 20Y | H30: =SWAP_GENERATORS!$D$43 -> USD_OIS_SWAP@6:3 | I30: RECEIVE | J30: 1000000 | K30: 0.01 | L30: 0 | M30: =M29+1 -> 9 | N30: =_xll.meLWOSwapCreateFromGenerator("USD_OIS_SWAP_"&G30,H30,I30,J30,B30,D30,K30,L30) -> USD_OIS_SWAP_20Y@22:3 | O30: =USD_OIS!$G$28 -> USDYC | P30: =_xll.meLWOSwapParRate(N30,O30) -> 0.0175687 | R30: =USD_OIS!I17 -> 20Y | S30: =USD_OIS!J17 -> 0.0175687 | T30: =(P30-S30)*10000 -> -3.142827e-06
B31: =_xll.meDateFromTenor(USD_OIS!$G$8,F31,"MOD_FOLLOWING",C31,"") -> 43781 | C31: NYB | D31: =_xll.meDateFromTenor(B31,G31,) -> 52913 | F31: 2D | G31: =R31 -> 25Y | H31: =SWAP_GENERATORS!$D$43 -> USD_OIS_SWAP@6:3 | I31: RECEIVE | J31: 1000000 | K31: 0.01 | L31: 0 | M31: =M30+1 -> 10 | N31: =_xll.meLWOSwapCreateFromGenerator("USD_OIS_SWAP_"&G31,H31,I31,J31,B31,D31,K31,L31) -> USD_OIS_SWAP_25Y@20:3 | O31: =USD_OIS!$G$28 -> USDYC | P31: =_xll.meLWOSwapParRate(N31,O31) -> 0.013831423 | R31: =USD_OIS!I18 -> 25Y | S31: =USD_OIS!J18 -> 0.013831423 | T31: =(P31-S31)*10000 -> -2.615542e-06
B32: =_xll.meDateFromTenor(USD_OIS!$G$8,F32,"MOD_FOLLOWING",C32,"") -> 43781 | C32: NYB | D32: =_xll.meDateFromTenor(B32,G32,) -> 54739 | F32: 2D | G32: =R32 -> 30Y | H32: =SWAP_GENERATORS!$D$43 -> USD_OIS_SWAP@6:3 | I32: RECEIVE | J32: 1000000 | K32: 0.01 | L32: 0 | M32: =M31+1 -> 11 | N32: =_xll.meLWOSwapCreateFromGenerator("USD_OIS_SWAP_"&G32,H32,I32,J32,B32,D32,K32,L32) -> USD_OIS_SWAP_30Y@19:3 | O32: =USD_OIS!$G$28 -> USDYC | P32: =_xll.meLWOSwapParRate(N32,O32) -> 0.0177902 | R32: =USD_OIS!I19 -> 30Y | S32: =USD_OIS!J19 -> 0.0177902 | T32: =(P32-S32)*10000 -> -2.4273897e-06
B33: =_xll.meDateFromTenor(USD_OIS!$G$8,F33,"MOD_FOLLOWING",C33,"") -> 43781 | C33: NYB | D33: =_xll.meDateFromTenor(B33,G33,) -> 58391 | F33: 2D | G33: =R33 -> 40Y | H33: =SWAP_GENERATORS!$D$43 -> USD_OIS_SWAP@6:3 | I33: RECEIVE | J33: 1000000 | K33: 0.01 | L33: 0 | M33: =M32+1 -> 12 | N33: =_xll.meLWOSwapCreateFromGenerator("USD_OIS_SWAP_"&G33,H33,I33,J33,B33,D33,K33,L33) -> USD_OIS_SWAP_40Y@21:3 | O33: =USD_OIS!$G$28 -> USDYC | P33: =_xll.meLWOSwapParRate(N33,O33) -> 0.01757776 | R33: =USD_OIS!I20 -> 40Y | S33: =USD_OIS!J20 -> 0.01757776 | T33: =(P33-S33)*10000 -> -1.9622831e-06
B34: =_xll.meDateFromTenor(USD_OIS!$G$8,F34,"MOD_FOLLOWING",C34,"") -> 43781 | C34: NYB | D34: =_xll.meDateFromTenor(B34,G34,) -> 62044 | F34: 2D | G34: =R34 -> 50Y | H34: =SWAP_GENERATORS!$D$43 -> USD_OIS_SWAP@6:3 | I34: RECEIVE | J34: 1000000 | K34: 0.01 | L34: 0 | M34: =M33+1 -> 13 | N34: =_xll.meLWOSwapCreateFromGenerator("USD_OIS_SWAP_"&G34,H34,I34,J34,B34,D34,K34,L34) -> USD_OIS_SWAP_50Y@9:3 | O34: =USD_OIS!$G$28 -> USDYC | P34: =_xll.meLWOSwapParRate(N34,O34) -> 0.0172051 | R34: =USD_OIS!I21 -> 50Y | S34: =USD_OIS!J21 -> 0.0172051 | T34: =(P34-S34)*10000 -> -1.6962144e-06

Sheet RISK
B3: Trade | C3: =REPRICING!N8 -> USD_SOFR_SWAP_5Y@37:0
B4: CurveCollection | C4: USDYC
B5: OptimizeRisk | C5: TRUE
B6: RiskCutOffTenor | C6: 30Y
C9: Risk Results
C10: {=_xll.meUtilityResize(_xll.meLWOSwapDeltaLadder(C3,C4,,,,,,FALSE,,$C$6),100,100)} -> Pillars | D10: USD : Total | E10: USD : USD_SOFR_SWAP_5Y@37
C11: USDYC.SOFR.OUTRIGHTOISSWAP.ON | D11: 0.032603434 | E11: 0.032603434
C12: USDYC.SOFR.OUTRIGHTOISSWAP.1W | D12: -0.035498769 | E12: -0.035498769
C13: USDYC.SOFR.FUTURE.FUTURE1.20191218.20200318 | D13: -0.10805658 | E13: -0.10805658
C14: USDYC.SOFR.FUTURE.FUTURE2.20200318.20200617 | D14: -0.15877709 | E14: -0.15877709
C15: USDYC.SOFR.FUTURE.FUTURE3.20200617.20200916 | D15: -0.15887225 | E15: -0.15887225
C16: USDYC.SOFR.FUTURE.FUTURE4.20200916.20201216 | D16: -0.73022803 | E16: -0.73022803
C17: USDYC.SOFR.OUTRIGHTOISSWAP.2Y | D17: 4.2111367 | E17: 4.2111367
C18: USDYC.SOFR.OUTRIGHTOISSWAP.5Y | D18: -481.05513 | E18: -481.05513
C19: USDYC.SOFR.OUTRIGHTOISSWAP.7Y | D19: -0.52137852 | E19: -0.52137852
C20: USDYC.SOFR.OUTRIGHTOISSWAP.10Y | D20: 0.10495894 | E20: 0.10495894
C21: USDYC.SOFR.OUTRIGHTOISSWAP.12Y | D21: -0.036338375 | E21: -0.036338375
C22: USDYC.SOFR.OUTRIGHTOISSWAP.15Y | D22: 0.0056222212 | E22: 0.0056222212
... C25: USDYC.SOFR.OUTRIGHTOISSWAP.30Y | D25: 0.00036564234 | E25: 0.00036564234

Sheet FORWARDS
B2: CurveCollection | C2: USDYC | E2: {=_xll.meLWOCurveForwardRatesTable(C2,C3:C4)} -> Fixing Dates | F2: USDSOFR | G2: USDOIS
B3: CurveIndex | C3: USDSOFR | E3: 43776 | F3: 0.0157 | G3: 0.0155
C4: USDOIS | E4: 43808 | F4: 0.0155 | G4: 0.015325407
E5: 43837 | F5: 0.015423868 | G5: 0.0152
E6: 43868 | F6: 0.015305864 | G6: 0.0152
E7: 43899 | F7: 0.015187859 | G7: 0.0152
E8: 43928 | F8: 0.015077468 | G8: 0.0148
E9: 43958 | F9: 0.01496327 | G9: 0.0148
E10: 43990 | F10: 0.014841459 | G10: 0.0148
E11: 44019 | F11: 0.014731068 | G11: 0.0145
E12: 44050 | F12: 0.014613064 | G12: 0.0145
E13: 44082 | F13: 0.014491253 | G13: 0.0145
E14: 44111 | F14: 0.0144608 | G14: 0.01435
E15: 44144 | F15: 0.0144608 | G15: 0.01435
E16: 44172 | F16: 0.0144608 | G16: 0.01435
... E123: 47429 | F123: 0.019218469 | G123: 0.019153692
E124: #N/A | F124: #N/A | G124: #N/A
E125: #N/A | F125: #N/A | G125: #N/A
E126: #N/A | F126: #N/A | G126: #N/A
E127: #N/A | F127: #N/A | G127: #N/A
E128: #N/A | F128: #N/A | G128: #N/A
E129: #N/A | F129: #N/A | G129: #N/A
E130: #N/A | F130: #N/A | G130: #N/A
