Workbook

Sheet CURVE_GENERATOR
B2: USD SOFR CURVE GENERATOR TEMPLATE
C4: USD SOFR CURVE GENERATOR TEMPLATE | H4: USD SOFR CURVE GENERATOR TEMPLATE
C5: Create Template | D5: =_xll.meLWOCurveGeneratorCreate(D6,C9,C10:D19,C21,C22:D39,C41,C42:D45,C47,C48:D51) -> USD_SOFR_WITH_JACOBIAN@1:5 | H5: Create Template | I5: =_xll.meLWOCurveGeneratorCreate(I6,H9,H10:I19,H21,H22:I39,H41,H42:I45,H47,H48:I51) -> USD_SOFR_NO_JACOBIAN@2:5
C6: Object Name | D6: USD_SOFR_WITH_JACOBIAN | H6: Object Name | I6: USD_SOFR_NO_JACOBIAN
C9: CURVEPROPERTIES | H9: CURVEPROPERTIES
C10: CurveType | D10: ARR | H10: CurveType | I10: ARR
C11: CurveIndexFrequency | D11: DAILY | H11: CurveIndexFrequency | I11: DAILY
C12: StaticDataTable | D12: =$D$10 -> ARR | H12: StaticDataTable | I12: =$I$10 -> ARR
C13: IndexName | D13: =$D$10 -> ARR | H13: IndexName | I13: =$I$10 -> ARR
C14: Currency | D14: USD | H14: Currency | I14: USD
C15: interpolation | D15: FN_SPLINEINTERPOLATION | H15: interpolation | I15: FN_SPLINEINTERPOLATION
C16: yieldgen.interpolation | D16: FN_SPLINEINTERPOLATION | H16: yieldgen.interpolation | I16: FN_SPLINEINTERPOLATION
C17: JacobianBuildFrequency | D17: ONCE | H17: JacobianBuildFrequency | I17: NEVER
C18: JacobianShiftType | D18: FLAT_SHIFT | H18: JacobianShiftType | I18: FLAT_SHIFT
C19: JacobianRiskType | D19: DISCOUNT_FACTORS | H19: JacobianRiskType | I19: DISCOUNT_FACTORS
C21: OIS | H21: OIS
C22: calendar | D22: NYB | H22: calendar | I22: NYB
C23: daycount | D23: ACT/360 | H23: daycount | I23: ACT/360
C24: frequency | D24: ANNUAL | H24: frequency | I24: ANNUAL
C25: generatemethod | D25: DAILYCOMPOUNDING | H25: generatemethod | I25: DAILYCOMPOUNDING
C26: resetlag | D26: 2D | H26: resetlag | I26: 2D
C27: firstrate | D27: SHORTMARKET | H27: firstrate | I27: SHORTMARKET
C28: slidingrule | D28: MOD_FOLLOWING | H28: slidingrule | I28: MOD_FOLLOWING
C29: eomday | D29: 31 | H29: eomday | I29: 31
C30: iseomroll | D30: TRUE | H30: iseomroll | I30: TRUE
C31: shorttermconvention | D31: ARITHMETICAVERAGE | H31: shorttermconvention | I31: ARITHMETICAVERAGE
C32: longtermconvention | D32: LOBASIS | H32: longtermconvention | I32: LOBASIS
C33: longterm | D33: 1Y | H33: longterm | I33: 1Y
C34: longterm.generatemethod | D34: NONE | H34: longterm.generatemethod | I34: NONE
C35: Epsilon | D35: 1e-10 | H35: Epsilon | I35: 1e-10
C36: MaxLoop | D36: 1000 | H36: MaxLoop | I36: 1000
C37: CompoundingMethod | D37: ARITHMETIC | H37: CompoundingMethod | I37: ARITHMETIC
C38: SmoothShortEnd | D38: FALSE | H38: SmoothShortEnd | I38: FALSE
C41: LIBOROISBASIS | D41: OIS FLOAT LEG CONVENTIONS | H41: LIBOROISBASIS | I41: OIS FLOAT LEG CONVENTIONS
C42: Calendar | D42: LNB:NYB | H42: Calendar | I42: LNB:NYB
C43: Daycount | D43: ACT/360 | H43: Daycount | I43: ACT/360
C44: Frequency | D44: QUARTERLY | H44: Frequency | I44: QUARTERLY
C45: SlidingRule | D45: MOD_FOLLOWING | H45: SlidingRule | I45: MOD_FOLLOWING
C47: SWAPS | D47: LIBOR SWAP CONVENTIONS - FIXED LEG | H47: SWAPS | I47: LIBOR SWAP CONVENTIONS - FIXED LEG
C48: calendar | D48: LNB:NYB | H48: calendar | I48: LNB:NYB
...

Sheet USD_ARR_CURVE
C3: MARKETDATAPROPERTIES | F3: OIS | L3: LIBOROISBASISSPREADS | O3: SWAPS
F4: Term | G4: Rate | H4: StartDate | I4: EndDate | J4: Use | L4: Term | M4: Rate | O4: Term | P4: Rate
C5: Currency | D5: USD | F5: ON | G5: 0.0212 | J5: TRUE | L5: 1Y | M5: 0.0029625 | O5: 1Y | P5: 0.018587
C6: CurveType | D6: =CURVE_GENERATOR!$D$10 -> ARR | F6: 1W | G6: 0.021328 | J6: TRUE | L6: 2Y | M6: 0.00274375 | O6: 2Y | P6: 0.01634
C7: CurveIndexFrequency | D7: DAILY | F7: 2W | G7: 0.021333 | J7: TRUE | L7: 3Y | M7: 0.002575 | O7: 3Y | P7: 0.015436
C8: AsOfDate | D8: 43691 | F8: 3W | G8: 0.02137 | J8: TRUE | L8: 4Y | M8: 0.0024875 | O8: 4Y | P8: 0.014973
F9: 1M | G9: 0.021358 | J9: TRUE | L9: 5Y | M9: 0.00245 | O9: 5Y | P9: 0.014769
C10: Create Market Data Handle | F10: 2M | G10: 0.02002 | J10: TRUE | L10: 7Y | M10: 0.00239375 | O10: 7Y | P10: 0.014761
C11: Handle Name | D11: USD_ARR_MARKETDATA | F11: 3M | G11: 0.019096 | J11: TRUE | L11: 10Y | M11: 0.0023625 | O11: 10Y | P11: 0.015239
C12: Market Data Handle | D12: =_xll.meLWOCurveMarketDataCreate(D11,C3,C5:D8,F3,F5:J30,L3,L5:M30,O3,O5:P30) -> USD_ARR_MARKETDATA@3:37 | F12: 4M | G12: 0.01849 | J12: TRUE | L12: 12Y | M12: 0.00235 | O12: 12Y | P12: 0.015603
F13: 5M | G13: 0.017859 | J13: TRUE | L13: 15Y | M13: 0.00235 | O13: 15Y | P13: 0.016061
F14: 6M | G14: 0.01743 | J14: TRUE | L14: 20Y | M14: 0.00234375 | O14: 20Y | P14: 0.016491
F15: 9M | G15: 0.016211 | J15: TRUE | L15: 25Y | M15: 0.00234375 | O15: 25Y | P15: 0.016662
F16: 1Y | G16: 0.015407 | J16: TRUE | L16: 30Y | M16: 0.00235 | O16: 30Y | P16: 0.016695
C17: Curve Dictionary | L17: 40Y | M17: 0.00235 | O17: 40Y | P17: 0.016695
C18: Handle Name | D18: USD_ARR_CURVE | L18: 50Y | M18: 0.00235 | O18: 50Y | P18: 0.016695
C19: Curve Generator | D19: =CURVE_GENERATOR!$D$5 -> USD_SOFR_WITH_JACOBIAN@1:5
C20: Domestic Curve Collection | D20: USDYC
C21: Foreign Curve Collection
C25: Curve Build
C26: Handle Name | D26: {=_xll.meLWOCurveCalibrate(D18,D19,D12,D20,D21)} -> USD_ARR_CURVE@4:37
C27: Curve Collection | D27: USDYC
C28: Curve Index | D28: ARR
C29: Calibration Time Taken | D29: 0.03200 sec
C30: Curve Loaded | D30: =_xll.meLWOExists(D26,"CURVE") -> TRUE

Sheet APPLY_FLAT_SHIFT
C2: MarketDataShiftSize
C3: 1e-06
C7: MARKETDATAPROPERTIES | F7: OIS | L7: LIBOROISBASISSPREADS | O7: SWAPS
F8: Term | G8: Rate | H8: StartDate | I8: EndDate | J8: Use | L8: Term | M8: Rate | O8: Term | P8: Rate
C9: Currency | D9: USD | F9: ON | G9: =USD_ARR_CURVE!G5+$C$3 -> 0.021201 | J9: TRUE | L9: 1Y | M9: =USD_ARR_CURVE!M5 -> 0.0029625 | O9: 1Y | P9: =USD_ARR_CURVE!P5+$C$3 -> 0.018588
C10: CurveType | D10: =CURVE_GENERATOR!$D$10 -> ARR | F10: 1W | G10: =USD_ARR_CURVE!G6+$C$3 -> 0.021329 | J10: TRUE | L10: 2Y | M10: =USD_ARR_CURVE!M6 -> 0.00274375 | O10: 2Y | P10: =USD_ARR_CURVE!P6+$C$3 -> 0.016341
C11: CurveIndexFrequency | D11: DAILY | F11: 2W | G11: =USD_ARR_CURVE!G7+$C$3 -> 0.021334 | J11: TRUE | L11: 3Y | M11: =USD_ARR_CURVE!M7 -> 0.002575 | O11: 3Y | P11: =USD_ARR_CURVE!P7+$C$3 -> 0.015437
C12: AsOfDate | D12: 43691 | F12: 3W | G12: =USD_ARR_CURVE!G8+$C$3 -> 0.021371 | J12: TRUE | L12: 4Y | M12: =USD_ARR_CURVE!M8 -> 0.0024875 | O12: 4Y | P12: =USD_ARR_CURVE!P8+$C$3 -> 0.014974
F13: 1M | G13: =USD_ARR_CURVE!G9+$C$3 -> 0.021359 | J13: TRUE | L13: 5Y | M13: =USD_ARR_CURVE!M9 -> 0.00245 | O13: 5Y | P13: =USD_ARR_CURVE!P9+$C$3 -> 0.01477
C14: Create Market Data Handle | F14: 2M | G14: =USD_ARR_CURVE!G10+$C$3 -> 0.020021 | J14: TRUE | L14: 7Y | M14: =USD_ARR_CURVE!M10 -> 0.00239375 | O14: 7Y | P14: =USD_ARR_CURVE!P10+$C$3 -> 0.014762
C15: Handle Name | D15: USD_ARR_MARKETDATA_BUMPED | F15: 3M | G15: =USD_ARR_CURVE!G11+$C$3 -> 0.019097 | J15: TRUE | L15: 10Y | M15: =USD_ARR_CURVE!M11 -> 0.0023625 | O15: 10Y | P15: =USD_ARR_CURVE!P11+$C$3 -> 0.01524
C16: Market Data Handle | D16: =_xll.meLWOCurveMarketDataCreate(D15,C7,C9:D12,F7,F9:J34,L7,L9:M34,O7,O9:P34) -> USD_ARR_MARKETDATA_BUMPED@5:10 | F16: 4M | G16: =USD_ARR_CURVE!G12+$C$3 -> 0.018491 | J16: TRUE | L16: 12Y | M16: =USD_ARR_CURVE!M12 -> 0.00235 | O16: 12Y | P16: =USD_ARR_CURVE!P12+$C$3 -> 0.015604
F17: 5M | G17: =USD_ARR_CURVE!G13+$C$3 -> 0.01786 | J17: TRUE | L17: 15Y | M17: =USD_ARR_CURVE!M13 -> 0.00235 | O17: 15Y | P17: =USD_ARR_CURVE!P13+$C$3 -> 0.016062
F18: 6M | G18: =USD_ARR_CURVE!G14+$C$3 -> 0.017431 | J18: TRUE | L18: 20Y | M18: =USD_ARR_CURVE!M14 -> 0.00234375 | O18: 20Y | P18: =USD_ARR_CURVE!P14+$C$3 -> 0.016492
F19: 9M | G19: =USD_ARR_CURVE!G15+$C$3 -> 0.016212 | J19: TRUE | L19: 25Y | M19: =USD_ARR_CURVE!M15 -> 0.00234375 | O19: 25Y | P19: =USD_ARR_CURVE!P15+$C$3 -> 0.016663
F20: 1Y | G20: =USD_ARR_CURVE!G16+$C$3 -> 0.015408 | J20: TRUE | L20: 30Y | M20: =USD_ARR_CURVE!M16 -> 0.00235 | O20: 30Y | P20: =USD_ARR_CURVE!P16+$C$3 -> 0.016696
C21: Curve Dictionary | L21: 40Y | M21: =USD_ARR_CURVE!M17 -> 0.00235 | O21: 40Y | P21: =USD_ARR_CURVE!P17+$C$3 -> 0.016696
C22: Handle Name | D22: USD_ARR_CURVE_FLAT_SHIFT | L22: 50Y | M22: =USD_ARR_CURVE!M18 -> 0.00235 | O22: 50Y | P22: =USD_ARR_CURVE!P18+$C$3 -> 0.016696
C23: Curve Generator | D23: =CURVE_GENERATOR!$I$5 -> USD_SOFR_NO_JACOBIAN@2:5
C24: Domestic Curve Collection | D24: USDYC_FLAT_SHIFT
C25: Foreign Curve Collection
C29: Curve Build
C30: Handle Name | D30: {=_xll.meLWOCurveCalibrate(D22,D23,D16,D24,D25)} -> USD_ARR_CURVE_FLAT_SHIFT@6:10
C31: Curve Collection | D31: USDYC_FLAT_SHIFT
C32: Curve Index | D32: ARR
C33: Calibration Time Taken | D33: 0.03500 sec
C34: Curve Loaded | D34: =_xll.meLWOExists(D30,"CURVE") -> TRUE

Sheet JACOBIAN_RESULTS
B2: Analytical Curve Jacobian | E2: Original Discount Factors | H2: Bumped Discount Factors | K2: Numerical Discount Factor Change | P2: New Discount Factor Levels
B3: {=_xll.meCurveResultsJacobianDisplay(USD_ARR_CURVE!$D$27,USD_ARR_CURVE!$D$28)} -> RiskType | C3: DISCOUNT_FACTORS
B4: ShiftType | C4: FLAT_SHIFT | E4: CurveCollection | F4: =USD_ARR_CURVE!$D$27 -> USDYC | H4: CurveCollection | I4: =APPLY_FLAT_SHIFT!$D$31 -> USDYC_FLAT_SHIFT
B5: GradientShiftSize | C5: 1e-06 | E5: CurveIndex | F5: =USD_ARR_CURVE!$D$28 -> ARR | H5: CurveIndex | I5: =APPLY_FLAT_SHIFT!$D$32 -> ARR
N6: Total Difference | S6: Total Difference
B7: MarketDataShiftSize | C7: 0.0001 | N7: =SUM(N11:N220) -> 0 | S7: =SUM(S11:S220) -> 0
C9: Instrument
B10: PaymentDate | C10: Total | E10: {=_xll.meCurveDiscountFactorsDisplay(USD_ARR_CURVE!$D$27,USD_ARR_CURVE!$D$28)} -> PaymentDates | F10: DiscountFactors | H10: {=_xll.meCurveDiscountFactorsDisplay(APPLY_FLAT_SHIFT!$D$31,APPLY_FLAT_SHIFT!$D$32)} -> PaymentDates | I10: DiscountFactors | K10: Date | L10: Analytical | M10: Numerical | N10: +/- | P10: Date | Q10: Analytical | R10: Numerical | S10: +/-
B11: 43691 | C11: 0 | E11: 43691 | F11: 1 | H11: 43691 | I11: 1 | K11: =H11 -> 43691 | L11: =C11 -> 0 | M11: =I11-F11 -> 0 | N11: =L11-M11 -> 0 | P11: =E11 -> 43691 | Q11: =L11+F11 -> 1 | R11: =F11+M11 -> 1 | S11: =Q11-R11 -> 0
B12: 43692 | C12: -2.7774506e-09 | E12: 43692 | F12: 0.99994111 | H12: 43692 | I12: 0.99994111 | K12: =H12 -> 43692 | L12: =C12 -> -2.7774506e-09 | M12: =I12-F12 -> -2.7774506e-09 | N12: =L12-M12 -> 0 | P12: =E12 -> 43692 | Q12: =L12+F12 -> 0.99994111 | R12: =F12+M12 -> 0.99994111 | S12: =Q12-R12 -> 0
B13: 43693 | C13: -5.5545741e-09 | E13: 43693 | F13: 0.99988223 | H13: 43693 | I13: 0.99988223 | K13: =H13 -> 43693 | L13: =C13 -> -5.5545741e-09 | M13: =I13-F13 -> -5.5545741e-09 | N13: =L13-M13 -> 0 | P13: =E13 -> 43693 | Q13: =L13+F13 -> 0.99988223 | R13: =F13+M13 -> 0.99988223 | S13: =Q13-R13 -> 0
B14: 43700 | C14: -2.497831e-08 | E14: 43700 | F14: 0.99946774 | H14: 43700 | I14: 0.99946772 | K14: =H14 -> 43700 | L14: =C14 -> -2.497831e-08 | M14: =I14-F14 -> -2.497831e-08 | N14: =L14-M14 -> 0 | P14: =E14 -> 43700 | Q14: =L14+F14 -> 0.99946772 | R14: =F14+M14 -> 0.99946772 | S14: =Q14-R14 -> 0
B15: 43707 | C15: -4.4369841e-08 | E15: 43707 | F15: 0.9990534 | H15: 43707 | I15: 0.99905336 | K15: =H15 -> 43707 | L15: =C15 -> -4.4369841e-08 | M15: =I15-F15 -> -4.4369841e-08 | N15: =L15-M15 -> 0 | P15: =E15 -> 43707 | Q15: =L15+F15 -> 0.99905336 | R15: =F15+M15 -> 0.99905336 | S15: =Q15-R15 -> 0
B16: 43714 | C16: -6.372897e-08 | E16: 43714 | F16: 0.99863735 | H16: 43714 | I16: 0.99863728 | K16: =H16 -> 43714 | L16: =C16 -> -6.372897e-08 | M16: =I16-F16 -> -6.372897e-08 | N16: =L16-M16 -> 0 | P16: =E16 -> 43714 | Q16: =L16+F16 -> 0.99863728 | R16: =F16+M16 -> 0.99863728 | S16: =Q16-R16 -> 0
B17: 43724 | C17: -9.1329504e-08 | E17: 43724 | F17: 0.99804666 | H17: 43724 | I17: 0.99804657 | K17: =H17 -> 43724 | L17: =C17 -> -9.1329504e-08 | M17: =I17-F17 -> -9.1329504e-08 | N17: =L17-M17 -> 0 | P17: =E17 -> 43724 | Q17: =L17+F17 -> 0.99804657 | R17: =F17+M17 -> 0.99804657 | S17: =Q17-R17 -> 0
B18: 43754 | C18: -1.7381661e-07 | E18: 43754 | F18: 0.99650182 | H18: 43754 | I18: 0.99650165 | K18: =H18 -> 43754 | L18: =C18 -> -1.7381661e-07 | M18: =I18-F18 -> -1.7381661e-07 | N18: =L18-M18 -> 0 | P18: =E18 -> 43754 | Q18: =L18+F18 -> 0.99650165 | R18: =F18+M18 -> 0.99650165 | S18: =Q18-R18 -> 0
B19: 43787 | C19: -2.6402307e-07 | E19: 43787 | F19: 0.99492138 | H19: 43787 | I19: 0.99492111 | K19: =H19 -> 43787 | L19: =C19 -> -2.6402307e-07 | M19: =I19-F19 -> -2.6402307e-07 | N19: =L19-M19 -> 0 | P19: =E19 -> 43787 | Q19: =L19+F19 -> 0.99492111 | R19: =F19+M19 -> 0.99492111 | S19: =Q19-R19 -> 0
B20: 43815 | C20: -3.4016196e-07 | E20: 43815 | F20: 0.99365593 | H20: 43815 | I20: 0.99365559 | K20: =H20 -> 43815 | L20: =C20 -> -3.4016196e-07 | M20: =I20-F20 -> -3.4016196e-07 | N20: =L20-M20 -> 0 | P20: =E20 -> 43815 | Q20: =L20+F20 -> 0.99365559 | R20: =F20+M20 -> 0.99365559 | S20: =Q20-R20 -> 0
B21: 43846 | C21: -4.2408441e-07 | E21: 43846 | F21: 0.99235022 | H21: 43846 | I21: 0.9923498 | K21: =H21 -> 43846 | L21: =C21 -> -4.2408441e-07 | M21: =I21-F21 -> -4.2408441e-07 | N21: =L21-M21 -> 0 | P21: =E21 -> 43846 | Q21: =L21+F21 -> 0.9923498 | R21: =F21+M21 -> 0.9923498 | S21: =Q21-R21 -> 0
B22: 43879 | C22: -5.1293022e-07 | E22: 43879 | F22: 0.99095816 | H22: 43879 | I22: 0.99095765 | K22: =H22 -> 43879 | L22: =C22 -> -5.1293022e-07 | M22: =I22-F22 -> -5.1293022e-07 | N22: =L22-M22 -> 0 | P22: =E22 -> 43879 | Q22: =L22+F22 -> 0.99095765 | R22: =F22+M22 -> 0.99095765 | S22: =Q22-R22 -> 0
... B220: 61956 | C220: -2.436765e-05 | E220: 61956 | F220: 0.48878662 | H220: 61956 | I220: 0.48876226 | K220: =H220 -> 61956 | L220: =C220 -> -2.436765e-05 | M220: =I220-F220 -> -2.436765e-05 | N220: =L220-M220 -> 0 | P220: =E220 -> 61956 | Q220: =L220+F220 -> 0.48876226 | R220: =F220+M220 -> 0.48876226 | S220: =Q220-R220 -> 0
B221: #N/A | C221: #N/A | E221: #N/A | F221: #N/A | H221: #N/A | I221: #N/A | K221: =H221 -> #N/A | L221: =C221 -> #N/A | M221: =I221-F221 -> #N/A | N221: =C221-M221 -> #N/A | Q221: =L221+F221 -> #N/A | R221: =F221+M221 -> #N/A | S221: =G221-R221 -> #N/A

Sheet NO_BUMP
C3: MARKETDATAPROPERTIES | F3: OIS | L3: LIBOROISBASISSPREADS | O3: SWAPS
F4: Term | G4: Rate | H4: StartDate | I4: EndDate | J4: Use | L4: Term | M4: Rate | O4: Term | P4: Rate
C5: Currency | D5: USD | F5: ON | G5: 0.0212 | J5: TRUE | L5: 1Y | M5: 0.0029625 | O5: 1Y | P5: 0.018587
C6: CurveType | D6: =CURVE_GENERATOR!$D$10 -> ARR | F6: 1W | G6: 0.021328 | J6: TRUE | L6: 2Y | M6: 0.00274375 | O6: 2Y | P6: 0.01634
C7: CurveIndexFrequency | D7: DAILY | F7: 2W | G7: 0.021333 | J7: TRUE | L7: 3Y | M7: 0.002575 | O7: 3Y | P7: 0.015436
C8: AsOfDate | D8: 43691 | F8: 3W | G8: 0.02137 | J8: TRUE | L8: 4Y | M8: 0.0024875 | O8: 4Y | P8: 0.014973
F9: 1M | G9: 0.021358 | J9: TRUE | L9: 5Y | M9: 0.00245 | O9: 5Y | P9: 0.014769
C10: Create Market Data Handle | F10: 2M | G10: 0.02002 | J10: TRUE | L10: 7Y | M10: 0.00239375 | O10: 7Y | P10: 0.014761
C11: Handle Name | D11: MARKET_DATA_NO_BUMP | F11: 3M | G11: 0.019096 | J11: TRUE | L11: 10Y | M11: 0.0023625 | O11: 10Y | P11: 0.015239
C12: Market Data Handle | D12: =_xll.meLWOCurveMarketDataCreate(D11,C3,C5:D8,F3,F5:J30,L3,L5:M30,O3,O5:P30) -> MARKET_DATA_NO_BUMP@9:0 | F12: 4M | G12: 0.01849 | J12: TRUE | L12: 12Y | M12: 0.00235 | O12: 12Y | P12: 0.015603
F13: 5M | G13: 0.017859 | J13: TRUE | L13: 15Y | M13: 0.00235 | O13: 15Y | P13: 0.016061
F14: 6M | G14: 0.01743 | J14: TRUE | L14: 20Y | M14: 0.00234375 | O14: 20Y | P14: 0.016491
F15: 9M | G15: 0.016211 | J15: TRUE | L15: 25Y | M15: 0.00234375 | O15: 25Y | P15: 0.016662
F16: 1Y | G16: 0.015407 | J16: TRUE | L16: 30Y | M16: 0.00235 | O16: 30Y | P16: 0.016695
C17: Curve Dictionary | L17: 40Y | M17: 0.00235 | O17: 40Y | P17: 0.016695
C18: Handle Name | D18: USD_ARR_NO_BUMP | L18: 50Y | M18: 0.00235 | O18: 50Y | P18: 0.016695
C19: Curve Generator | D19: =CURVE_GENERATOR!$I$5 -> USD_SOFR_NO_JACOBIAN@4:0
C20: Domestic Curve Collection | D20: USDYC_NO_BUMP
C21: Foreign Curve Collection
C25: Curve Build
C26: Handle Name | D26: {=_xll.meLWOCurveCalibrate(D18,D19,D12,D20,D21)} -> USD_ARR_NO_BUMP@10:0
C27: Curve Collection | D27: USDYC_NO_BUMP
C28: Curve Index | D28: ARR
C29: Calibration Time Taken | D29: 0.28500 sec
C30: Curve Loaded | D30: =_xll.meLWOExists(D26,"CURVE") -> TRUE

Sheet BUMP
C3: MARKETDATAPROPERTIES | F3: OIS | L3: LIBOROISBASISSPREADS | O3: SWAPS
F4: Term | G4: Rate | H4: StartDate | I4: EndDate | J4: Use | L4: Term | M4: Rate | O4: Term | P4: Rate
C5: Currency | D5: USD | F5: ON | G5: 0.0212 | J5: TRUE | L5: 1Y | M5: 0.0029625 | O5: 1Y | P5: 0.018587
C6: CurveType | D6: =CURVE_GENERATOR!$D$10 -> ARR | F6: 1W | G6: 0.021328 | J6: TRUE | L6: 2Y | M6: 0.00274375 | O6: 2Y | P6: 0.01634
C7: CurveIndexFrequency | D7: DAILY | F7: 2W | G7: 0.021333 | J7: TRUE | L7: 3Y | M7: 0.002575 | O7: 3Y | P7: 0.015436
C8: AsOfDate | D8: 43691 | F8: 3W | G8: 0.02137 | J8: TRUE | L8: 4Y | M8: 0.0024875 | O8: 4Y | P8: 0.014973
F9: 1M | G9: 0.021358 | J9: TRUE | L9: 5Y | M9: 0.00245 | O9: 5Y | P9: 0.014769
C10: Create Market Data Handle | F10: 2M | G10: 0.02002 | J10: TRUE | L10: 7Y | M10: 0.00239375 | O10: 7Y | P10: 0.014761
C11: Handle Name | D11: USD_ARR_MARKETDATA | F11: 3M | G11: 0.019096 | J11: TRUE | L11: 10Y | M11: 0.0023625 | O11: 10Y | P11: 0.015239
C12: Market Data Handle | D12: =_xll.meLWOCurveMarketDataCreate(D11,C3,C5:D8,F3,F5:J30,L3,L5:M30,O3,O5:P30) -> USD_ARR_MARKETDATA@7:0 | F12: 4M | G12: 0.01849 | J12: TRUE | L12: 12Y | M12: 0.00235 | O12: 12Y | P12: 0.015603
F13: 5M | G13: 0.017859 | J13: TRUE | L13: 15Y | M13: 0.00235 | O13: 15Y | P13: 0.016061
F14: 6M | G14: 0.01743 | J14: TRUE | L14: 20Y | M14: 0.00234375 | O14: 20Y | P14: 0.016491
F15: 9M | G15: 0.016211 | J15: TRUE | L15: 25Y | M15: 0.00234375 | O15: 25Y | P15: 0.016662
F16: 1Y | G16: 0.015407 | J16: TRUE | L16: 30Y | M16: 0.00235 | O16: 30Y | P16: 0.016695
C17: Curve Dictionary | L17: 40Y | M17: 0.00235 | O17: 40Y | P17: 0.016695
C18: Handle Name | D18: USD_ARR_BUMPED | L18: 50Y | M18: 0.00235 | O18: 50Y | P18: 0.016695
C19: Curve Generator | D19: =CURVE_GENERATOR!$I$5 -> USD_SOFR_NO_JACOBIAN@4:0
C20: Domestic Curve Collection | D20: USDYC_BUMPED
C21: Foreign Curve Collection
C25: Curve Build
C26: Handle Name | D26: {=_xll.meLWOCurveCalibrate(D18,D19,D12,D20,D21)} -> USD_ARR_BUMPED@8:0
C27: Curve Collection | D27: USDYC_BUMPED
C28: Curve Index | D28: ARR
C29: Calibration Time Taken | D29: 0.28400 sec
C30: Curve Loaded | D30: =_xll.meLWOExists(D26,"CURVE") -> TRUE
D33: Bump Curve
C34: ShiftSize | D34: 1e-06
C35: BumpedCurve | D35: =_xll.meLWOCurveBumpAll(D26,D34,TRUE) -> USD_ARR_BUMPED@8:1

Sheet BUMP_RESULTS
L2: ShiftSize | M2: =BUMP!D34 -> 1e-06
B3: Curve | C3: =NO_BUMP!D26 -> USD_ARR_NO_BUMP@10:0 | L3: Curve | M3: =BUMP!$D$35 -> USD_ARR_BUMPED@8:1 | Y3: =C3 -> USD_ARR_NO_BUMP@10:0 | AC3: =$M$3 -> USD_ARR_BUMPED@8:1 | AG3: Bumped Change in Discount Factors | AL3: Compare Jacobian vs Manual Bump | AP3: Manual Change in Discount Factors | AU3: Compare Manual Bump vs Curve Bump Method
B5: {=_xll.meLWOCurveDisplay(C3)} -> CURVEPROPERTIES | E5: MARKETDATAPROPERTIES | J5: #N/A | L5: {=_xll.meLWOCurveDisplay(M3)} -> CURVEPROPERTIES | O5: MARKETDATAPROPERTIES | T5: #N/A | Y5: {=_xll.meCurveDiscountFactorsDisplay(NO_BUMP!$D$27,NO_BUMP!$D$28)} -> PaymentDates | Z5: DiscountFactors | AC5: {=_xll.meCurveDiscountFactorsDisplay(BUMP!$D$27,BUMP!$D$28)} -> PaymentDates | AD5: DiscountFactors | AG5: =Y5 -> PaymentDates | AH5: Original | AI5: Bumped | AJ5: Change | AL5: =JACOBIAN_RESULTS!B10 -> #Error: Jacobian Results for Curve Collection '#Error: OIS Curve Market Data is Missing' and/or Curve Index '#Error: OIS Curve Market Data is Missing' do not exist | AM5: =JACOBIAN_RESULTS!C10 -> #Error: Jacobian Results for Curve Collection '#Error: OIS Curve Market Data is Missing' and/or Curve Index '#Error: OIS Curve Market Data is Missing' do not exist | AN5: +/- | AP5: =JACOBIAN_RESULTS!K10 -> Date | AQ5: Numerical | AR5: Bumped | AS5: +/- | AU5: =JACOBIAN_RESULTS!P10 -> Date | AV5: Manual | AW5: Bumped | AX5: +/-
B6: CurveType | C6: ARR | E6: Currency | F6: USD | J6: #N/A | L6: CurveType | M6: ARR | O6: Currency | P6: USD | T6: #N/A | Y6: 43691 | Z6: 1 | AC6: 43691 | AD6: 1 | AE6: =AD6-Z6 -> 0 | AG6: =Y6 -> 43691 | AH6: =Z6 -> 1 | AI6: =AD6 -> 1 | AJ6: =AI6-AH6 -> 0 | AL6: =JACOBIAN_RESULTS!B11 -> #Error: Jacobian Results for Curve Collection '#Error: OIS Curve Market Data is Missing' and/or Curve Index '#Error: OIS Curve Market Data is Missing' do not exist | AM6: =JACOBIAN_RESULTS!C11 -> #Error: Jacobian Results for Curve Collection '#Error: OIS Curve Market Data is Missing' and/or Curve Index '#Error: OIS Curve Market Data is Missing' do not exist | AN6: =AM6-AJ6 -> #VALUE! | AP6: =JACOBIAN_RESULTS!K11 -> 43691 | AQ6: =JACOBIAN_RESULTS!M11 -> #VALUE! | AR6: =AJ6 -> 0 | AS6: =AR6-AQ6 -> #VALUE! | AU6: =JACOBIAN_RESULTS!P11 -> #Error: Invalid Variant Data: Unable to cast '#Error: Invalid Curve: CurveCollection '#Error: OIS Curve Market Data is Missing' does not exist' to double | AV6: =JACOBIAN_RESULTS!R11 -> 1 | AW6: =AI6 -> 1 | AX6: =AW6-AV6 -> 0
B7: CurveIndexFrequency | C7: DAILY | E7: CurveType | F7: ARR | J7: #N/A | L7: CurveIndexFrequency | M7: DAILY | O7: CurveType | P7: ARR | T7: #N/A | Y7: 43692 | Z7: 0.99994111 | AC7: 43692 | AD7: 0.99994111 | AE7: =AD7-Z7 -> -2.7774506e-09 | AG7: =Y7 -> 43692 | AH7: =Z7 -> 0.99994111 | AI7: =AD7 -> 0.99994111 | AJ7: =AI7-AH7 -> -2.7774506e-09 | AL7: =JACOBIAN_RESULTS!B12 -> #Error: Jacobian Results for Curve Collection '#Error: OIS Curve Market Data is Missing' and/or Curve Index '#Error: OIS Curve Market Data is Missing' do not exist | AM7: =JACOBIAN_RESULTS!C12 -> #Error: Jacobian Results for Curve Collection '#Error: OIS Curve Market Data is Missing' and/or Curve Index '#Error: OIS Curve Market Data is Missing' do not exist | AN7: =AM7-AJ7 -> #VALUE! | AP7: =JACOBIAN_RESULTS!K12 -> 43692 | AQ7: =JACOBIAN_RESULTS!M12 -> #VALUE! | AR7: =AJ7 -> -2.7774506e-09 | AS7: =AR7-AQ7 -> #VALUE! | AU7: =JACOBIAN_RESULTS!P12 -> #Error: Invalid Variant Data: Unable to cast '#Error: Invalid Curve: CurveCollection '#Error: OIS Curve Market Data is Missing' does not exist' to double | AV7: =JACOBIAN_RESULTS!R12 -> 0.99994111 | AW7: =AI7 -> 0.99994111 | AX7: =AW7-AV7 -> 0
B8: StaticDataTable | C8: ARR | E8: CurveIndexFrequency | F8: DAILY | J8: #N/A | L8: StaticDataTable | M8: ARR | O8: CurveIndexFrequency | P8: DAILY | T8: #N/A | Y8: 43693 | Z8: 0.99988223 | AC8: 43693 | AD8: 0.99988223 | AE8: =AD8-Z8 -> -5.5545741e-09 | AG8: =Y8 -> 43693 | AH8: =Z8 -> 0.99988223 | AI8: =AD8 -> 0.99988223 | AJ8: =AI8-AH8 -> -5.5545741e-09 | AL8: =JACOBIAN_RESULTS!B13 -> #Error: Jacobian Results for Curve Collection '#Error: OIS Curve Market Data is Missing' and/or Curve Index '#Error: OIS Curve Market Data is Missing' do not exist | AM8: =JACOBIAN_RESULTS!C13 -> #Error: Jacobian Results for Curve Collection '#Error: OIS Curve Market Data is Missing' and/or Curve Index '#Error: OIS Curve Market Data is Missing' do not exist | AN8: =AM8-AJ8 -> #VALUE! | AP8: =JACOBIAN_RESULTS!K13 -> 43693 | AQ8: =JACOBIAN_RESULTS!M13 -> #VALUE! | AR8: =AJ8 -> -5.5545741e-09 | AS8: =AR8-AQ8 -> #VALUE! | AU8: =JACOBIAN_RESULTS!P13 -> #Error: Invalid Variant Data: Unable to cast '#Error: Invalid Curve: CurveCollection '#Error: OIS Curve Market Data is Missing' does not exist' to double | AV8: =JACOBIAN_RESULTS!R13 -> 0.99988223 | AW8: =AI8 -> 0.99988223 | AX8: =AW8-AV8 -> 0
B9: IndexName | C9: ARR | E9: AsOfDate | F9: 43691 | J9: #N/A | L9: IndexName | M9: ARR | O9: AsOfDate | P9: 43691 | T9: #N/A | V9: Change in Market Rates | Y9: 43700 | Z9: 0.99946774 | AC9: 43700 | AD9: 0.99946772 | AE9: =AD9-Z9 -> -2.497831e-08 | AG9: =Y9 -> 43700 | AH9: =Z9 -> 0.99946774 | AI9: =AD9 -> 0.99946772 | AJ9: =AI9-AH9 -> -2.497831e-08 | AL9: =JACOBIAN_RESULTS!B14 -> #Error: Jacobian Results for Curve Collection '#Error: OIS Curve Market Data is Missing' and/or Curve Index '#Error: OIS Curve Market Data is Missing' do not exist | AM9: =JACOBIAN_RESULTS!C14 -> #Error: Jacobian Results for Curve Collection '#Error: OIS Curve Market Data is Missing' and/or Curve Index '#Error: OIS Curve Market Data is Missing' do not exist | AN9: =AM9-AJ9 -> #VALUE! | AP9: =JACOBIAN_RESULTS!K14 -> 43700 | AQ9: =JACOBIAN_RESULTS!M14 -> #VALUE! | AR9: =AJ9 -> -2.497831e-08 | AS9: =AR9-AQ9 -> #VALUE! | AU9: =JACOBIAN_RESULTS!P14 -> #Error: Invalid Variant Data: Unable to cast '#Error: Invalid Curve: CurveCollection '#Error: OIS Curve Market Data is Missing' does not exist' to double | AV9: =JACOBIAN_RESULTS!R14 -> 0.99946772 | AW9: =AI9 -> 0.99946772 | AX9: =AW9-AV9 -> 0
B10: Currency | C10: USD | J10: #N/A | L10: Currency | M10: USD | T10: #N/A | Y10: 43707 | Z10: 0.9990534 | AC10: 43707 | AD10: 0.99905336 | AE10: =AD10-Z10 -> -4.4369841e-08 | AG10: =Y10 -> 43707 | AH10: =Z10 -> 0.9990534 | AI10: =AD10 -> 0.99905336 | AJ10: =AI10-AH10 -> -4.4369841e-08 | AL10: =JACOBIAN_RESULTS!B15 -> #Error: Jacobian Results for Curve Collection '#Error: OIS Curve Market Data is Missing' and/or Curve Index '#Error: OIS Curve Market Data is Missing' do not exist | AM10: =JACOBIAN_RESULTS!C15 -> #Error: Jacobian Results for Curve Collection '#Error: OIS Curve Market Data is Missing' and/or Curve Index '#Error: OIS Curve Market Data is Missing' do not exist | AN10: =AM10-AJ10 -> #VALUE! | AP10: =JACOBIAN_RESULTS!K15 -> 43707 | AQ10: =JACOBIAN_RESULTS!M15 -> #VALUE! | AR10: =AJ10 -> -4.4369841e-08 | AS10: =AR10-AQ10 -> #VALUE! | AU10: =JACOBIAN_RESULTS!P15 -> #Error: Invalid Variant Data: Unable to cast '#Error: Invalid Curve: CurveCollection '#Error: OIS Curve Market Data is Missing' does not exist' to double | AV10: =JACOBIAN_RESULTS!R15 -> 0.99905336 | AW10: =AI10 -> 0.99905336 | AX10: =AW10-AV10 -> 0
B11: interpolation | C11: FN_SPLINEINTERPOLATION | E11: OIS | J11: #N/A | L11: interpolation | M11: FN_SPLINEINTERPOLATION | O11: OIS | T11: #N/A | V11: +/- | Y11: 43714 | Z11: 0.99863735 | AC11: 43714 | AD11: 0.99863728 | AE11: =AD11-Z11 -> -6.372897e-08 | AG11: =Y11 -> 43714 | AH11: =Z11 -> 0.99863735 | AI11: =AD11 -> 0.99863728 | AJ11: =AI11-AH11 -> -6.372897e-08 | AL11: =JACOBIAN_RESULTS!B16 -> #Error: Jacobian Results for Curve Collection '#Error: OIS Curve Market Data is Missing' and/or Curve Index '#Error: OIS Curve Market Data is Missing' do not exist | AM11: =JACOBIAN_RESULTS!C16 -> #Error: Jacobian Results for Curve Collection '#Error: OIS Curve Market Data is Missing' and/or Curve Index '#Error: OIS Curve Market Data is Missing' do not exist | AN11: =AM11-AJ11 -> #VALUE! | AP11: =JACOBIAN_RESULTS!K16 -> 43714 | AQ11: =JACOBIAN_RESULTS!M16 -> #VALUE! | AR11: =AJ11 -> -6.372897e-08 | AS11: =AR11-AQ11 -> #VALUE! | AU11: =JACOBIAN_RESULTS!P16 -> #Error: Invalid Variant Data: Unable to cast '#Error: Invalid Curve: CurveCollection '#Error: OIS Curve Market Data is Missing' does not exist' to double | AV11: =JACOBIAN_RESULTS!R16 -> 0.99863728 | AW11: =AI11 -> 0.99863728 | AX11: =AW11-AV11 -> 0
B12: yieldgen.interpolation | C12: FN_SPLINEINTERPOLATION | E12: ON | F12: 0.0212 | I12: TRUE | J12: #N/A | L12: yieldgen.interpolation | M12: FN_SPLINEINTERPOLATION | O12: ON | P12: 0.021201 | S12: TRUE | T12: #N/A | V12: =P12-F12 -> 1e-06 | Y12: 43724 | Z12: 0.99804666 | AC12: 43724 | AD12: 0.99804657 | AE12: =AD12-Z12 -> -9.1329504e-08 | AG12: =Y12 -> 43724 | AH12: =Z12 -> 0.99804666 | AI12: =AD12 -> 0.99804657 | AJ12: =AI12-AH12 -> -9.1329504e-08 | AL12: =JACOBIAN_RESULTS!B17 -> #Error: Jacobian Results for Curve Collection '#Error: OIS Curve Market Data is Missing' and/or Curve Index '#Error: OIS Curve Market Data is Missing' do not exist | AM12: =JACOBIAN_RESULTS!C17 -> #Error: Jacobian Results for Curve Collection '#Error: OIS Curve Market Data is Missing' and/or Curve Index '#Error: OIS Curve Market Data is Missing' do not exist | AN12: =AM12-AJ12 -> #VALUE! | AP12: =JACOBIAN_RESULTS!K17 -> 43724 | AQ12: =JACOBIAN_RESULTS!M17 -> #VALUE! | AR12: =AJ12 -> -9.1329504e-08 | AS12: =AR12-AQ12 -> #VALUE! | AU12: =JACOBIAN_RESULTS!P17 -> #Error: Invalid Variant Data: Unable to cast '#Error: Invalid Curve: CurveCollection '#Error: OIS Curve Market Data is Missing' does not exist' to double | AV12: =JACOBIAN_RESULTS!R17 -> 0.99804657 | AW12: =AI12 -> 0.99804657 | AX12: =AW12-AV12 -> 0
B13: JacobianBuildFrequency | C13: NEVER | E13: 1W | F13: 0.021328 | I13: TRUE | J13: #N/A | L13: JacobianBuildFrequency | M13: NEVER | O13: 1W | P13: 0.021329 | S13: TRUE | T13: #N/A | V13: =P13-F13 -> 1e-06 | Y13: 43754 | Z13: 0.99650182 | AC13: 43754 | AD13: 0.99650165 | AE13: =AD13-Z13 -> -1.7381661e-07 | AG13: =Y13 -> 43754 | AH13: =Z13 -> 0.99650182 | AI13: =AD13 -> 0.99650165 | AJ13: =AI13-AH13 -> -1.7381661e-07 | AL13: =JACOBIAN_RESULTS!B18 -> #Error: Jacobian Results for Curve Collection '#Error: OIS Curve Market Data is Missing' and/or Curve Index '#Error: OIS Curve Market Data is Missing' do not exist | AM13: =JACOBIAN_RESULTS!C18 -> #Error: Jacobian Results for Curve Collection '#Error: OIS Curve Market Data is Missing' and/or Curve Index '#Error: OIS Curve Market Data is Missing' do not exist | AN13: =AM13-AJ13 -> #VALUE! | AP13: =JACOBIAN_RESULTS!K18 -> 43754 | AQ13: =JACOBIAN_RESULTS!M18 -> #VALUE! | AR13: =AJ13 -> -1.7381661e-07 | AS13: =AR13-AQ13 -> #VALUE! | AU13: =JACOBIAN_RESULTS!P18 -> #Error: Invalid Variant Data: Unable to cast '#Error: Invalid Curve: CurveCollection '#Error: OIS Curve Market Data is Missing' does not exist' to double | AV13: =JACOBIAN_RESULTS!R18 -> 0.99650165 | AW13: =AI13 -> 0.99650165 | AX13: =AW13-AV13 -> 0
B14: JacobianShiftType | C14: FLAT_SHIFT | E14: 2W | F14: 0.021333 | I14: TRUE | J14: #N/A | L14: JacobianShiftType | M14: FLAT_SHIFT | O14: 2W | P14: 0.021334 | S14: TRUE | T14: #N/A | V14: =P14-F14 -> 1e-06 | Y14: 43787 | Z14: 0.99492138 | AC14: 43787 | AD14: 0.99492111 | AE14: =AD14-Z14 -> -2.6402307e-07 | AG14: =Y14 -> 43787 | AH14: =Z14 -> 0.99492138 | AI14: =AD14 -> 0.99492111 | AJ14: =AI14-AH14 -> -2.6402307e-07 | AL14: =JACOBIAN_RESULTS!B19 -> #Error: Jacobian Results for Curve Collection '#Error: OIS Curve Market Data is Missing' and/or Curve Index '#Error: OIS Curve Market Data is Missing' do not exist | AM14: =JACOBIAN_RESULTS!C19 -> #Error: Jacobian Results for Curve Collection '#Error: OIS Curve Market Data is Missing' and/or Curve Index '#Error: OIS Curve Market Data is Missing' do not exist | AN14: =AM14-AJ14 -> #VALUE! | AP14: =JACOBIAN_RESULTS!K19 -> 43787 | AQ14: =JACOBIAN_RESULTS!M19 -> #VALUE! | AR14: =AJ14 -> -2.6402307e-07 | AS14: =AR14-AQ14 -> #VALUE! | AU14: =JACOBIAN_RESULTS!P19 -> #Error: Invalid Variant Data: Unable to cast '#Error: Invalid Curve: CurveCollection '#Error: OIS Curve Market Data is Missing' does not exist' to double | AV14: =JACOBIAN_RESULTS!R19 -> 0.99492111 | AW14: =AI14 -> 0.99492111 | AX14: =AW14-AV14 -> 0
B15: JacobianRiskType | C15: DISCOUNT_FACTORS | E15: 3W | F15: 0.02137 | I15: TRUE | J15: #N/A | L15: JacobianRiskType | M15: DISCOUNT_FACTORS | O15: 3W | P15: 0.021371 | S15: TRUE | T15: #N/A | V15: =P15-F15 -> 1e-06 | Y15: 43815 | Z15: 0.99365593 | AC15: 43815 | AD15: 0.99365559 | AE15: =AD15-Z15 -> -3.4016196e-07 | AG15: =Y15 -> 43815 | AH15: =Z15 -> 0.99365593 | AI15: =AD15 -> 0.99365559 | AJ15: =AI15-AH15 -> -3.4016196e-07 | AL15: =JACOBIAN_RESULTS!B20 -> #Error: Jacobian Results for Curve Collection '#Error: OIS Curve Market Data is Missing' and/or Curve Index '#Error: OIS Curve Market Data is Missing' do not exist | AM15: =JACOBIAN_RESULTS!C20 -> #Error: Jacobian Results for Curve Collection '#Error: OIS Curve Market Data is Missing' and/or Curve Index '#Error: OIS Curve Market Data is Missing' do not exist | AN15: =AM15-AJ15 -> #VALUE! | AP15: =JACOBIAN_RESULTS!K20 -> 43815 | AQ15: =JACOBIAN_RESULTS!M20 -> #VALUE! | AR15: =AJ15 -> -3.4016196e-07 | AS15: =AR15-AQ15 -> #VALUE! | AU15: =JACOBIAN_RESULTS!P20 -> #Error: Invalid Variant Data: Unable to cast '#Error: Invalid Curve: CurveCollection '#Error: OIS Curve Market Data is Missing' does not exist' to double | AV15: =JACOBIAN_RESULTS!R20 -> 0.99365559 | AW15: =AI15 -> 0.99365559 | AX15: =AW15-AV15 -> 0
E16: 1M | F16: 0.021358 | I16: TRUE | J16: #N/A | O16: 1M | P16: 0.021359 | S16: TRUE | T16: #N/A | V16: =P16-F16 -> 1e-06 | Y16: 43846 | Z16: 0.99235022 | AC16: 43846 | AD16: 0.9923498 | AE16: =AD16-Z16 -> -4.2408441e-07 | AG16: =Y16 -> 43846 | AH16: =Z16 -> 0.99235022 | AI16: =AD16 -> 0.9923498 | AJ16: =AI16-AH16 -> -4.2408441e-07 | AL16: =JACOBIAN_RESULTS!B21 -> #Error: Jacobian Results for Curve Collection '#Error: OIS Curve Market Data is Missing' and/or Curve Index '#Error: OIS Curve Market Data is Missing' do not exist | AM16: =JACOBIAN_RESULTS!C21 -> #Error: Jacobian Results for Curve Collection '#Error: OIS Curve Market Data is Missing' and/or Curve Index '#Error: OIS Curve Market Data is Missing' do not exist | AN16: =AM16-AJ16 -> #VALUE! | AP16: =JACOBIAN_RESULTS!K21 -> 43846 | AQ16: =JACOBIAN_RESULTS!M21 -> #VALUE! | AR16: =AJ16 -> -4.2408441e-07 | AS16: =AR16-AQ16 -> #VALUE! | AU16: =JACOBIAN_RESULTS!P21 -> #Error: Invalid Variant Data: Unable to cast '#Error: Invalid Curve: CurveCollection '#Error: OIS Curve Market Data is Missing' does not exist' to double | AV16: =JACOBIAN_RESULTS!R21 -> 0.9923498 | AW16: =AI16 -> 0.9923498 | AX16: =AW16-AV16 -> 0
B17: OIS | E17: 2M | F17: 0.02002 | I17: TRUE | J17: #N/A | L17: OIS | O17: 2M | P17: 0.020021 | S17: TRUE | T17: #N/A | V17: =P17-F17 -> 1e-06 | Y17: 43879 | Z17: 0.99095816 | AC17: 43879 | AD17: 0.99095765 | AE17: =AD17-Z17 -> -5.1293022e-07 | AG17: =Y17 -> 43879 | AH17: =Z17 -> 0.99095816 | AI17: =AD17 -> 0.99095765 | AJ17: =AI17-AH17 -> -5.1293022e-07 | AL17: =JACOBIAN_RESULTS!B22 -> #Error: Jacobian Results for Curve Collection '#Error: OIS Curve Market Data is Missing' and/or Curve Index '#Error: OIS Curve Market Data is Missing' do not exist | AM17: =JACOBIAN_RESULTS!C22 -> #Error: Jacobian Results for Curve Collection '#Error: OIS Curve Market Data is Missing' and/or Curve Index '#Error: OIS Curve Market Data is Missing' do not exist | AN17: =AM17-AJ17 -> #VALUE! | AP17: =JACOBIAN_RESULTS!K22 -> 43879 | AQ17: =JACOBIAN_RESULTS!M22 -> #VALUE! | AR17: =AJ17 -> -5.1293022e-07 | AS17: =AR17-AQ17 -> #VALUE! | AU17: =JACOBIAN_RESULTS!P22 -> #Error: Invalid Variant Data: Unable to cast '#Error: Invalid Curve: CurveCollection '#Error: OIS Curve Market Data is Missing' does not exist' to double | AV17: =JACOBIAN_RESULTS!R22 -> 0.99095765 | AW17: =AI17 -> 0.99095765 | AX17: =AW17-AV17 -> 0
B18: calendar | C18: NYB | E18: 3M | F18: 0.019096 | I18: TRUE | J18: #N/A | L18: calendar | M18: NYB | O18: 3M | P18: 0.019097 | S18: TRUE | T18: #N/A | V18: =P18-F18 -> 1e-06 | Y18: 43969 | Z18: 0.98760781 | AC18: 43969 | AD18: 0.98760706 | AE18: =AD18-Z18 -> -7.5335684e-07 | AG18: =Y18 -> 43969 | AH18: =Z18 -> 0.98760781 | AI18: =AD18 -> 0.98760706 | AJ18: =AI18-AH18 -> -7.5335684e-07 | AL18: =JACOBIAN_RESULTS!B23 -> #Error: Jacobian Results for Curve Collection '#Error: OIS Curve Market Data is Missing' and/or Curve Index '#Error: OIS Curve Market Data is Missing' do not exist | AM18: =JACOBIAN_RESULTS!C23 -> #Error: Jacobian Results for Curve Collection '#Error: OIS Curve Market Data is Missing' and/or Curve Index '#Error: OIS Curve Market Data is Missing' do not exist | AN18: =AM18-AJ18 -> #VALUE! | AP18: =JACOBIAN_RESULTS!K23 -> 43969 | AQ18: =JACOBIAN_RESULTS!M23 -> #VALUE! | AR18: =AJ18 -> -7.5335684e-07 | AS18: =AR18-AQ18 -> #VALUE! | AU18: =JACOBIAN_RESULTS!P23 -> #Error: Invalid Variant Data: Unable to cast '#Error: Invalid Curve: CurveCollection '#Error: OIS Curve Market Data is Missing' does not exist' to double | AV18: =JACOBIAN_RESULTS!R23 -> 0.98760706 | AW18: =AI18 -> 0.98760706 | AX18: =AW18-AV18 -> 0
B19: daycount | C19: ACT/360 | E19: 4M | F19: 0.01849 | I19: TRUE | J19: #N/A | L19: daycount | M19: ACT/360 | O19: 4M | P19: 0.018491 | S19: TRUE | T19: #N/A | V19: =P19-F19 -> 1e-06 | Y19: 44060 | Z19: 0.98446069 | AC19: 44060 | AD19: 0.98445971 | AE19: =AD19-Z19 -> -9.8400746e-07 | AG19: =Y19 -> 44060 | AH19: =Z19 -> 0.98446069 | AI19: =AD19 -> 0.98445971 | AJ19: =AI19-AH19 -> -9.8400746e-07 | AL19: =JACOBIAN_RESULTS!B24 -> #Error: Jacobian Results for Curve Collection '#Error: OIS Curve Market Data is Missing' and/or Curve Index '#Error: OIS Curve Market Data is Missing' do not exist | AM19: =JACOBIAN_RESULTS!C24 -> #Error: Jacobian Results for Curve Collection '#Error: OIS Curve Market Data is Missing' and/or Curve Index '#Error: OIS Curve Market Data is Missing' do not exist | AN19: =AM19-AJ19 -> #VALUE! | AP19: =JACOBIAN_RESULTS!K24 -> 44060 | AQ19: =JACOBIAN_RESULTS!M24 -> #VALUE! | AR19: =AJ19 -> -9.8400746e-07 | AS19: =AR19-AQ19 -> #VALUE! | AU19: =JACOBIAN_RESULTS!P24 -> #Error: Invalid Variant Data: Unable to cast '#Error: Invalid Curve: CurveCollection '#Error: OIS Curve Market Data is Missing' does not exist' to double | AV19: =JACOBIAN_RESULTS!R24 -> 0.98445971 | AW19: =AI19 -> 0.98445971 | AX19: =AW19-AV19 -> 0
B20: frequency | C20: ANNUAL | E20: 5M | F20: 0.017859 | I20: TRUE | J20: #N/A | L20: frequency | M20: ANNUAL | O20: 5M | P20: 0.01786 | S20: TRUE | T20: #N/A | V20: =P20-F20 -> 1e-06 | Y20: 44151 | Z20: 0.98147777 | AC20: 44151 | AD20: 0.98147655 | AE20: =AD20-Z20 -> -1.2138611e-06 | AG20: =Y20 -> 44151 | AH20: =Z20 -> 0.98147777 | AI20: =AD20 -> 0.98147655 | AJ20: =AI20-AH20 -> -1.2138611e-06 | AL20: =JACOBIAN_RESULTS!B25 -> #Error: Jacobian Results for Curve Collection '#Error: OIS Curve Market Data is Missing' and/or Curve Index '#Error: OIS Curve Market Data is Missing' do not exist | AM20: =JACOBIAN_RESULTS!C25 -> #Error: Jacobian Results for Curve Collection '#Error: OIS Curve Market Data is Missing' and/or Curve Index '#Error: OIS Curve Market Data is Missing' do not exist | AN20: =AM20-AJ20 -> #VALUE! | AP20: =JACOBIAN_RESULTS!K25 -> 44151 | AQ20: =JACOBIAN_RESULTS!M25 -> #VALUE! | AR20: =AJ20 -> -1.2138611e-06 | AS20: =AR20-AQ20 -> #VALUE! | AU20: =JACOBIAN_RESULTS!P25 -> #Error: Invalid Variant Data: Unable to cast '#Error: Invalid Curve: CurveCollection '#Error: OIS Curve Market Data is Missing' does not exist' to double | AV20: =JACOBIAN_RESULTS!R25 -> 0.98147655 | AW20: =AI20 -> 0.98147655 | AX20: =AW20-AV20 -> 0
B21: generatemethod | C21: DAILYCOMPOUNDING | E21: 6M | F21: 0.01743 | I21: TRUE | J21: #N/A | L21: generatemethod | M21: DAILYCOMPOUNDING | O21: 6M | P21: 0.017431 | S21: TRUE | T21: #N/A | V21: =P21-F21 -> 1e-06 | Y21: 44243 | Z21: 0.97863352 | AC21: 44243 | AD21: 0.97863207 | AE21: =AD21-Z21 -> -1.4526777e-06 | AG21: =Y21 -> 44243 | AH21: =Z21 -> 0.97863352 | AI21: =AD21 -> 0.97863207 | AJ21: =AI21-AH21 -> -1.4526777e-06 | AL21: =JACOBIAN_RESULTS!B26 -> #Error: Jacobian Results for Curve Collection '#Error: OIS Curve Market Data is Missing' and/or Curve Index '#Error: OIS Curve Market Data is Missing' do not exist | AM21: =JACOBIAN_RESULTS!C26 -> #Error: Jacobian Results for Curve Collection '#Error: OIS Curve Market Data is Missing' and/or Curve Index '#Error: OIS Curve Market Data is Missing' do not exist | AN21: =AM21-AJ21 -> #VALUE! | AP21: =JACOBIAN_RESULTS!K26 -> 44243 | AQ21: =JACOBIAN_RESULTS!M26 -> #VALUE! | AR21: =AJ21 -> -1.4526777e-06 | AS21: =AR21-AQ21 -> #VALUE! | AU21: =JACOBIAN_RESULTS!P26 -> #Error: Invalid Variant Data: Unable to cast '#Error: Invalid Curve: CurveCollection '#Error: OIS Curve Market Data is Missing' does not exist' to double | AV21: =JACOBIAN_RESULTS!R26 -> 0.97863207 | AW21: =AI21 -> 0.97863207 | AX21: =AW21-AV21 -> 0
B22: resetlag | C22: 2D | E22: 9M | F22: 0.016211 | I22: TRUE | J22: #N/A | L22: resetlag | M22: 2D | O22: 9M | P22: 0.016212 | S22: TRUE | T22: #N/A | V22: =P22-F22 -> 1e-06 | Y22: 44333 | Z22: 0.97594952 | AC22: 44333 | AD22: 0.97594783 | AE22: =AD22-Z22 -> -1.6919543e-06 | AG22: =Y22 -> 44333 | AH22: =Z22 -> 0.97594952 | AI22: =AD22 -> 0.97594783 | AJ22: =AI22-AH22 -> -1.6919543e-06 | AL22: =JACOBIAN_RESULTS!B27 -> #Error: Jacobian Results for Curve Collection '#Error: OIS Curve Market Data is Missing' and/or Curve Index '#Error: OIS Curve Market Data is Missing' do not exist | AM22: =JACOBIAN_RESULTS!C27 -> #Error: Jacobian Results for Curve Collection '#Error: OIS Curve Market Data is Missing' and/or Curve Index '#Error: OIS Curve Market Data is Missing' do not exist | AN22: =AM22-AJ22 -> #VALUE! | AP22: =JACOBIAN_RESULTS!K27 -> 44333 | AQ22: =JACOBIAN_RESULTS!M27 -> #VALUE! | AR22: =AJ22 -> -1.6919543e-06 | AS22: =AR22-AQ22 -> #VALUE! | AU22: =JACOBIAN_RESULTS!P27 -> #Error: Invalid Variant Data: Unable to cast '#Error: Invalid Curve: CurveCollection '#Error: OIS Curve Market Data is Missing' does not exist' to double | AV22: =JACOBIAN_RESULTS!R27 -> 0.97594783 | AW22: =AI22 -> 0.97594783 | AX22: =AW22-AV22 -> 0
B23: firstrate | C23: SHORTMARKET | E23: 1Y | F23: 0.015407 | I23: TRUE | J23: #N/A | L23: firstrate | M23: SHORTMARKET | O23: 1Y | P23: 0.015408 | S23: TRUE | T23: #N/A | V23: =P23-F23 -> 1e-06 | Y23: 44424 | Z23: 0.97327288 | AC23: 44424 | AD23: 0.97327095 | AE23: =AD23-Z23 -> -1.9355031e-06 | AG23: =Y23 -> 44424 | AH23: =Z23 -> 0.97327288 | AI23: =AD23 -> 0.97327095 | AJ23: =AI23-AH23 -> -1.9355031e-06 | AL23: =JACOBIAN_RESULTS!B28 -> #Error: Jacobian Results for Curve Collection '#Error: OIS Curve Market Data is Missing' and/or Curve Index '#Error: OIS Curve Market Data is Missing' do not exist | AM23: =JACOBIAN_RESULTS!C28 -> #Error: Jacobian Results for Curve Collection '#Error: OIS Curve Market Data is Missing' and/or Curve Index '#Error: OIS Curve Market Data is Missing' do not exist | AN23: =AM23-AJ23 -> #VALUE! | AP23: =JACOBIAN_RESULTS!K28 -> 44424 | AQ23: =JACOBIAN_RESULTS!M28 -> #VALUE! | AR23: =AJ23 -> -1.9355031e-06 | AS23: =AR23-AQ23 -> #VALUE! | AU23: =JACOBIAN_RESULTS!P28 -> #Error: Invalid Variant Data: Unable to cast '#Error: Invalid Curve: CurveCollection '#Error: OIS Curve Market Data is Missing' does not exist' to double | AV23: =JACOBIAN_RESULTS!R28 -> 0.97327095 | AW23: =AI23 -> 0.97327095 | AX23: =AW23-AV23 -> 0
B24: slidingrule | C24: MOD_FOLLOWING | J24: #N/A | L24: slidingrule | M24: MOD_FOLLOWING | T24: #N/A | Y24: 44516 | Z24: 0.97055396 | AC24: 44516 | AD24: 0.97055178 | AE24: =AD24-Z24 -> -2.1774373e-06 | AG24: =Y24 -> 44516 | AH24: =Z24 -> 0.97055396 | AI24: =AD24 -> 0.97055178 | AJ24: =AI24-AH24 -> -2.1774373e-06 | AL24: =JACOBIAN_RESULTS!B29 -> #Error: Jacobian Results for Curve Collection '#Error: OIS Curve Market Data is Missing' and/or Curve Index '#Error: OIS Curve Market Data is Missing' do not exist | AM24: =JACOBIAN_RESULTS!C29 -> #Error: Jacobian Results for Curve Collection '#Error: OIS Curve Market Data is Missing' and/or Curve Index '#Error: OIS Curve Market Data is Missing' do not exist | AN24: =AM24-AJ24 -> #VALUE! | AP24: =JACOBIAN_RESULTS!K29 -> 44516 | AQ24: =JACOBIAN_RESULTS!M29 -> #VALUE! | AR24: =AJ24 -> -2.1774373e-06 | AS24: =AR24-AQ24 -> #VALUE! | AU24: =JACOBIAN_RESULTS!P29 -> #Error: Invalid Variant Data: Unable to cast '#Error: Invalid Curve: CurveCollection '#Error: OIS Curve Market Data is Missing' does not exist' to double | AV24: =JACOBIAN_RESULTS!R29 -> 0.97055178 | AW24: =AI24 -> 0.97055178 | AX24: =AW24-AV24 -> 0
B25: eomday | C25: 31 | E25: LIBOROISBASISSPREADS | J25: #N/A | L25: eomday | M25: 31 | O25: LIBOROISBASISSPREADS | T25: #N/A | V25: +/- | Y25: 44608 | Z25: 0.96780303 | AC25: 44608 | AD25: 0.96780061 | AE25: =AD25-Z25 -> -2.4138616e-06 | AG25: =Y25 -> 44608 | AH25: =Z25 -> 0.96780303 | AI25: =AD25 -> 0.96780061 | AJ25: =AI25-AH25 -> -2.4138616e-06 | AL25: =JACOBIAN_RESULTS!B30 -> #Error: Jacobian Results for Curve Collection '#Error: OIS Curve Market Data is Missing' and/or Curve Index '#Error: OIS Curve Market Data is Missing' do not exist | AM25: =JACOBIAN_RESULTS!C30 -> #Error: Jacobian Results for Curve Collection '#Error: OIS Curve Market Data is Missing' and/or Curve Index '#Error: OIS Curve Market Data is Missing' do not exist | AN25: =AM25-AJ25 -> #VALUE! | AP25: =JACOBIAN_RESULTS!K30 -> 44608 | AQ25: =JACOBIAN_RESULTS!M30 -> #VALUE! | AR25: =AJ25 -> -2.4138616e-06 | AS25: =AR25-AQ25 -> #VALUE! | AU25: =JACOBIAN_RESULTS!P30 -> #Error: Invalid Variant Data: Unable to cast '#Error: Invalid Curve: CurveCollection '#Error: OIS Curve Market Data is Missing' does not exist' to double | AV25: =JACOBIAN_RESULTS!R30 -> 0.96780061 | AW25: =AI25 -> 0.96780061 | AX25: =AW25-AV25 -> 0
B26: iseomroll | C26: TRUE | E26: 1Y | F26: 0.0029625 | J26: #N/A | L26: iseomroll | M26: TRUE | O26: 1Y | P26: 0.0029625 | T26: #N/A | V26: =P26-F26 -> 0 | Y26: 44697 | Z26: 0.96511634 | AC26: 44697 | AD26: 0.9651137 | AE26: =AD26-Z26 -> -2.6383856e-06 | AG26: =Y26 -> 44697 | AH26: =Z26 -> 0.96511634 | AI26: =AD26 -> 0.9651137 | AJ26: =AI26-AH26 -> -2.6383856e-06 | AL26: =JACOBIAN_RESULTS!B31 -> #Error: Jacobian Results for Curve Collection '#Error: OIS Curve Market Data is Missing' and/or Curve Index '#Error: OIS Curve Market Data is Missing' do not exist | AM26: =JACOBIAN_RESULTS!C31 -> #Error: Jacobian Results for Curve Collection '#Error: OIS Curve Market Data is Missing' and/or Curve Index '#Error: OIS Curve Market Data is Missing' do not exist | AN26: =AM26-AJ26 -> #VALUE! | AP26: =JACOBIAN_RESULTS!K31 -> 44697 | AQ26: =JACOBIAN_RESULTS!M31 -> #VALUE! | AR26: =AJ26 -> -2.6383856e-06 | AS26: =AR26-AQ26 -> #VALUE! | AU26: =JACOBIAN_RESULTS!P31 -> #Error: Invalid Variant Data: Unable to cast '#Error: Invalid Curve: CurveCollection '#Error: OIS Curve Market Data is Missing' does not exist' to double | AV26: =JACOBIAN_RESULTS!R31 -> 0.9651137 | AW26: =AI26 -> 0.9651137 | AX26: =AW26-AV26 -> 0
B27: shorttermconvention | C27: ARITHMETICAVERAGE | E27: 2Y | F27: 0.00274375 | J27: #N/A | L27: shorttermconvention | M27: ARITHMETICAVERAGE | O27: 2Y | P27: 0.00274375 | T27: #N/A | V27: =P27-F27 -> 0 | Y27: 44789 | Z27: 0.96233756 | AC27: 44789 | AD27: 0.96233469 | AE27: =AD27-Z27 -> -2.8682214e-06 | AG27: =Y27 -> 44789 | AH27: =Z27 -> 0.96233756 | AI27: =AD27 -> 0.96233469 | AJ27: =AI27-AH27 -> -2.8682214e-06 | AL27: =JACOBIAN_RESULTS!B32 -> #Error: Jacobian Results for Curve Collection '#Error: OIS Curve Market Data is Missing' and/or Curve Index '#Error: OIS Curve Market Data is Missing' do not exist | AM27: =JACOBIAN_RESULTS!C32 -> #Error: Jacobian Results for Curve Collection '#Error: OIS Curve Market Data is Missing' and/or Curve Index '#Error: OIS Curve Market Data is Missing' do not exist | AN27: =AM27-AJ27 -> #VALUE! | AP27: =JACOBIAN_RESULTS!K32 -> 44789 | AQ27: =JACOBIAN_RESULTS!M32 -> #VALUE! | AR27: =AJ27 -> -2.8682214e-06 | AS27: =AR27-AQ27 -> #VALUE! | AU27: =JACOBIAN_RESULTS!P32 -> #Error: Invalid Variant Data: Unable to cast '#Error: Invalid Curve: CurveCollection '#Error: OIS Curve Market Data is Missing' does not exist' to double | AV27: =JACOBIAN_RESULTS!R32 -> 0.96233469 | AW27: =AI27 -> 0.96233469 | AX27: =AW27-AV27 -> 0
B28: longtermconvention | C28: LOBASIS | E28: 3Y | F28: 0.002575 | J28: #N/A | L28: longtermconvention | M28: LOBASIS | O28: 3Y | P28: 0.002575 | T28: #N/A | V28: =P28-F28 -> 0 | Y28: 44881 | Z28: 0.95959012 | AC28: 44881 | AD28: 0.95958703 | AE28: =AD28-Z28 -> -3.0981817e-06 | AG28: =Y28 -> 44881 | AH28: =Z28 -> 0.95959012 | AI28: =AD28 -> 0.95958703 | AJ28: =AI28-AH28 -> -3.0981817e-06 | AL28: =JACOBIAN_RESULTS!B33 -> #Error: Jacobian Results for Curve Collection '#Error: OIS Curve Market Data is Missing' and/or Curve Index '#Error: OIS Curve Market Data is Missing' do not exist | AM28: =JACOBIAN_RESULTS!C33 -> #Error: Jacobian Results for Curve Collection '#Error: OIS Curve Market Data is Missing' and/or Curve Index '#Error: OIS Curve Market Data is Missing' do not exist | AN28: =AM28-AJ28 -> #VALUE! | AP28: =JACOBIAN_RESULTS!K33 -> 44881 | AQ28: =JACOBIAN_RESULTS!M33 -> #VALUE! | AR28: =AJ28 -> -3.0981817e-06 | AS28: =AR28-AQ28 -> #VALUE! | AU28: =JACOBIAN_RESULTS!P33 -> #Error: Invalid Variant Data: Unable to cast '#Error: Invalid Curve: CurveCollection '#Error: OIS Curve Market Data is Missing' does not exist' to double | AV28: =JACOBIAN_RESULTS!R33 -> 0.95958703 | AW28: =AI28 -> 0.95958703 | AX28: =AW28-AV28 -> 0
B29: longterm | C29: 1Y | E29: 4Y | F29: 0.0024875 | J29: #N/A | L29: longterm | M29: 1Y | O29: 4Y | P29: 0.0024875 | T29: #N/A | V29: =P29-F29 -> 0 | Y29: 44973 | Z29: 0.95687212 | AC29: 44973 | AD29: 0.95686879 | AE29: =AD29-Z29 -> -3.32849e-06 | AG29: =Y29 -> 44973 | AH29: =Z29 -> 0.95687212 | AI29: =AD29 -> 0.95686879 | AJ29: =AI29-AH29 -> -3.32849e-06 | AL29: =JACOBIAN_RESULTS!B34 -> #Error: Jacobian Results for Curve Collection '#Error: OIS Curve Market Data is Missing' and/or Curve Index '#Error: OIS Curve Market Data is Missing' do not exist | AM29: =JACOBIAN_RESULTS!C34 -> #Error: Jacobian Results for Curve Collection '#Error: OIS Curve Market Data is Missing' and/or Curve Index '#Error: OIS Curve Market Data is Missing' do not exist | AN29: =AM29-AJ29 -> #VALUE! | AP29: =JACOBIAN_RESULTS!K34 -> 44973 | AQ29: =JACOBIAN_RESULTS!M34 -> #VALUE! | AR29: =AJ29 -> -3.32849e-06 | AS29: =AR29-AQ29 -> #VALUE! | AU29: =JACOBIAN_RESULTS!P34 -> #Error: Invalid Variant Data: Unable to cast '#Error: Invalid Curve: CurveCollection '#Error: OIS Curve Market Data is Missing' does not exist' to double | AV29: =JACOBIAN_RESULTS!R34 -> 0.95686879 | AW29: =AI29 -> 0.95686879 | AX29: =AW29-AV29 -> 0
B30: longterm.generatemethod | C30: NONE | E30: 5Y | F30: 0.00245 | J30: #N/A | L30: longterm.generatemethod | M30: NONE | O30: 5Y | P30: 0.00245 | T30: #N/A | V30: =P30-F30 -> 0 | Y30: 45062 | Z30: 0.95425775 | AC30: 45062 | AD30: 0.95425419 | AE30: =AD30-Z30 -> -3.5510053e-06 | AG30: =Y30 -> 45062 | AH30: =Z30 -> 0.95425775 | AI30: =AD30 -> 0.95425419 | AJ30: =AI30-AH30 -> -3.5510053e-06 | AL30: =JACOBIAN_RESULTS!B35 -> #Error: Jacobian Results for Curve Collection '#Error: OIS Curve Market Data is Missing' and/or Curve Index '#Error: OIS Curve Market Data is Missing' do not exist | AM30: =JACOBIAN_RESULTS!C35 -> #Error: Jacobian Results for Curve Collection '#Error: OIS Curve Market Data is Missing' and/or Curve Index '#Error: OIS Curve Market Data is Missing' do not exist | AN30: =AM30-AJ30 -> #VALUE! | AP30: =JACOBIAN_RESULTS!K35 -> 45062 | AQ30: =JACOBIAN_RESULTS!M35 -> #VALUE! | AR30: =AJ30 -> -3.5510053e-06 | AS30: =AR30-AQ30 -> #VALUE! | AU30: =JACOBIAN_RESULTS!P35 -> #Error: Invalid Variant Data: Unable to cast '#Error: Invalid Curve: CurveCollection '#Error: OIS Curve Market Data is Missing' does not exist' to double | AV30: =JACOBIAN_RESULTS!R35 -> 0.95425419 | AW30: =AI30 -> 0.95425419 | AX30: =AW30-AV30 -> 0
B31: Epsilon | C31: 1e-10 | E31: 7Y | F31: 0.00239375 | J31: #N/A | L31: Epsilon | M31: 1e-10 | O31: 7Y | P31: 0.00239375 | T31: #N/A | V31: =P31-F31 -> 0 | Y31: 45154 | Z31: 0.95155568 | AC31: 45154 | AD31: 0.9515519 | AE31: =AD31-Z31 -> -3.7798205e-06 | AG31: =Y31 -> 45154 | AH31: =Z31 -> 0.95155568 | AI31: =AD31 -> 0.9515519 | AJ31: =AI31-AH31 -> -3.7798205e-06 | AL31: =JACOBIAN_RESULTS!B36 -> #Error: Jacobian Results for Curve Collection '#Error: OIS Curve Market Data is Missing' and/or Curve Index '#Error: OIS Curve Market Data is Missing' do not exist | AM31: =JACOBIAN_RESULTS!C36 -> #Error: Jacobian Results for Curve Collection '#Error: OIS Curve Market Data is Missing' and/or Curve Index '#Error: OIS Curve Market Data is Missing' do not exist | AN31: =AM31-AJ31 -> #VALUE! | AP31: =JACOBIAN_RESULTS!K36 -> 45154 | AQ31: =JACOBIAN_RESULTS!M36 -> #VALUE! | AR31: =AJ31 -> -3.7798205e-06 | AS31: =AR31-AQ31 -> #VALUE! | AU31: =JACOBIAN_RESULTS!P36 -> #Error: Invalid Variant Data: Unable to cast '#Error: Invalid Curve: CurveCollection '#Error: OIS Curve Market Data is Missing' does not exist' to double | AV31: =JACOBIAN_RESULTS!R36 -> 0.9515519 | AW31: =AI31 -> 0.9515519 | AX31: =AW31-AV31 -> 0
B32: MaxLoop | C32: 1000 | E32: 10Y | F32: 0.0023625 | J32: #N/A | L32: MaxLoop | M32: 1000 | O32: 10Y | P32: 0.0023625 | T32: #N/A | V32: =P32-F32 -> 0 | Y32: 45246 | Z32: 0.9488394 | AC32: 45246 | AD32: 0.9488354 | AE32: =AD32-Z32 -> -4.0064806e-06 | AG32: =Y32 -> 45246 | AH32: =Z32 -> 0.9488394 | AI32: =AD32 -> 0.9488354 | AJ32: =AI32-AH32 -> -4.0064806e-06 | AL32: =JACOBIAN_RESULTS!B37 -> #Error: Jacobian Results for Curve Collection '#Error: OIS Curve Market Data is Missing' and/or Curve Index '#Error: OIS Curve Market Data is Missing' do not exist | AM32: =JACOBIAN_RESULTS!C37 -> #Error: Jacobian Results for Curve Collection '#Error: OIS Curve Market Data is Missing' and/or Curve Index '#Error: OIS Curve Market Data is Missing' do not exist | AN32: =AM32-AJ32 -> #VALUE! | AP32: =JACOBIAN_RESULTS!K37 -> 45246 | AQ32: =JACOBIAN_RESULTS!M37 -> #VALUE! | AR32: =AJ32 -> -4.0064806e-06 | AS32: =AR32-AQ32 -> #VALUE! | AU32: =JACOBIAN_RESULTS!P37 -> #Error: Invalid Variant Data: Unable to cast '#Error: Invalid Curve: CurveCollection '#Error: OIS Curve Market Data is Missing' does not exist' to double | AV32: =JACOBIAN_RESULTS!R37 -> 0.9488354 | AW32: =AI32 -> 0.9488354 | AX32: =AW32-AV32 -> 0
B33: CompoundingMethod | C33: ARITHMETIC | E33: 12Y | F33: 0.00235 | J33: #N/A | L33: CompoundingMethod | M33: ARITHMETIC | O33: 12Y | P33: 0.00235 | T33: #N/A | V33: =P33-F33 -> 0 | Y33: 45338 | Z33: 0.94610279 | AC33: 45338 | AD33: 0.94609856 | AE33: =AD33-Z33 -> -4.2309424e-06 | AG33: =Y33 -> 45338 | AH33: =Z33 -> 0.94610279 | AI33: =AD33 -> 0.94609856 | AJ33: =AI33-AH33 -> -4.2309424e-06 | AL33: =JACOBIAN_RESULTS!B38 -> #Error: Jacobian Results for Curve Collection '#Error: OIS Curve Market Data is Missing' and/or Curve Index '#Error: OIS Curve Market Data is Missing' do not exist | AM33: =JACOBIAN_RESULTS!C38 -> #Error: Jacobian Results for Curve Collection '#Error: OIS Curve Market Data is Missing' and/or Curve Index '#Error: OIS Curve Market Data is Missing' do not exist | AN33: =AM33-AJ33 -> #VALUE! | AP33: =JACOBIAN_RESULTS!K38 -> 45338 | AQ33: =JACOBIAN_RESULTS!M38 -> #VALUE! | AR33: =AJ33 -> -4.2309424e-06 | AS33: =AR33-AQ33 -> #VALUE! | AU33: =JACOBIAN_RESULTS!P38 -> #Error: Invalid Variant Data: Unable to cast '#Error: Invalid Curve: CurveCollection '#Error: OIS Curve Market Data is Missing' does not exist' to double | AV33: =JACOBIAN_RESULTS!R38 -> 0.94609856 | AW33: =AI33 -> 0.94609856 | AX33: =AW33-AV33 -> 0
B34: SmoothShortEnd | C34: FALSE | E34: 15Y | F34: 0.00235 | J34: #N/A | L34: SmoothShortEnd | M34: FALSE | O34: 15Y | P34: 0.00235 | T34: #N/A | V34: =P34-F34 -> 0 | Y34: 45428 | Z34: 0.94340352 | AC34: 45428 | AD34: 0.94339907 | AE34: =AD34-Z34 -> -4.4486694e-06 | AG34: =Y34 -> 45428 | AH34: =Z34 -> 0.94340352 | AI34: =AD34 -> 0.94339907 | AJ34: =AI34-AH34 -> -4.4486694e-06 | AL34: =JACOBIAN_RESULTS!B39 -> #Error: Jacobian Results for Curve Collection '#Error: OIS Curve Market Data is Missing' and/or Curve Index '#Error: OIS Curve Market Data is Missing' do not exist | AM34: =JACOBIAN_RESULTS!C39 -> #Error: Jacobian Results for Curve Collection '#Error: OIS Curve Market Data is Missing' and/or Curve Index '#Error: OIS Curve Market Data is Missing' do not exist | AN34: =AM34-AJ34 -> #VALUE! | AP34: =JACOBIAN_RESULTS!K39 -> 45428 | AQ34: =JACOBIAN_RESULTS!M39 -> #VALUE! | AR34: =AJ34 -> -4.4486694e-06 | AS34: =AR34-AQ34 -> #VALUE! | AU34: =JACOBIAN_RESULTS!P39 -> #Error: Invalid Variant Data: Unable to cast '#Error: Invalid Curve: CurveCollection '#Error: OIS Curve Market Data is Missing' does not exist' to double | AV34: =JACOBIAN_RESULTS!R39 -> 0.94339907 | AW34: =AI34 -> 0.94339907 | AX34: =AW34-AV34 -> 0
E35: 20Y | F35: 0.00234375 | J35: #N/A | O35: 20Y | P35: 0.00234375 | T35: #N/A | V35: =P35-F35 -> 0 | Y35: 45520 | Z35: 0.94062055 | AC35: 45520 | AD35: 0.94061589 | AE35: =AD35-Z35 -> -4.6697081e-06 | AG35: =Y35 -> 45520 | AH35: =Z35 -> 0.94062055 | AI35: =AD35 -> 0.94061589 | AJ35: =AI35-AH35 -> -4.6697081e-06 | AL35: =JACOBIAN_RESULTS!B40 -> #Error: Jacobian Results for Curve Collection '#Error: OIS Curve Market Data is Missing' and/or Curve Index '#Error: OIS Curve Market Data is Missing' do not exist | AM35: =JACOBIAN_RESULTS!C40 -> #Error: Jacobian Results for Curve Collection '#Error: OIS Curve Market Data is Missing' and/or Curve Index '#Error: OIS Curve Market Data is Missing' do not exist | AN35: =AM35-AJ35 -> #VALUE! | AP35: =JACOBIAN_RESULTS!K40 -> 45520 | AQ35: =JACOBIAN_RESULTS!M40 -> #VALUE! | AR35: =AJ35 -> -4.6697081e-06 | AS35: =AR35-AQ35 -> #VALUE! | AU35: =JACOBIAN_RESULTS!P40 -> #Error: Invalid Variant Data: Unable to cast '#Error: Invalid Curve: CurveCollection '#Error: OIS Curve Market Data is Missing' does not exist' to double | AV35: =JACOBIAN_RESULTS!R40 -> 0.94061589 | AW35: =AI35 -> 0.94061589 | AX35: =AW35-AV35 -> 0
B36: LIBOROISBASIS | E36: 25Y | F36: 0.00234375 | J36: #N/A | L36: LIBOROISBASIS | O36: 25Y | P36: 0.00234375 | T36: #N/A | V36: =P36-F36 -> 0 | Y36: 45614 | Z36: 0.93775191 | AC36: 45614 | AD36: 0.93774702 | AE36: =AD36-Z36 -> -4.8943407e-06 | AG36: =Y36 -> 45614 | AH36: =Z36 -> 0.93775191 | AI36: =AD36 -> 0.93774702 | AJ36: =AI36-AH36 -> -4.8943407e-06 | AL36: =JACOBIAN_RESULTS!B41 -> #Error: Jacobian Results for Curve Collection '#Error: OIS Curve Market Data is Missing' and/or Curve Index '#Error: OIS Curve Market Data is Missing' do not exist | AM36: =JACOBIAN_RESULTS!C41 -> #Error: Jacobian Results for Curve Collection '#Error: OIS Curve Market Data is Missing' and/or Curve Index '#Error: OIS Curve Market Data is Missing' do not exist | AN36: =AM36-AJ36 -> #VALUE! | AP36: =JACOBIAN_RESULTS!K41 -> 45614 | AQ36: =JACOBIAN_RESULTS!M41 -> #VALUE! | AR36: =AJ36 -> -4.8943407e-06 | AS36: =AR36-AQ36 -> #VALUE! | AU36: =JACOBIAN_RESULTS!P41 -> #Error: Invalid Variant Data: Unable to cast '#Error: Invalid Curve: CurveCollection '#Error: OIS Curve Market Data is Missing' does not exist' to double | AV36: =JACOBIAN_RESULTS!R41 -> 0.93774702 | AW36: =AI36 -> 0.93774702 | AX36: =AW36-AV36 -> 0
B37: Calendar | C37: LNB:NYB | E37: 30Y | F37: 0.00235 | J37: #N/A | L37: Calendar | M37: LNB:NYB | O37: 30Y | P37: 0.00235 | T37: #N/A | V37: =P37-F37 -> 0 | Y37: 45706 | Z37: 0.93491751 | AC37: 45706 | AD37: 0.9349124 | AE37: =AD37-Z37 -> -5.1130527e-06 | AG37: =Y37 -> 45706 | AH37: =Z37 -> 0.93491751 | AI37: =AD37 -> 0.9349124 | AJ37: =AI37-AH37 -> -5.1130527e-06 | AL37: =JACOBIAN_RESULTS!B42 -> #Error: Jacobian Results for Curve Collection '#Error: OIS Curve Market Data is Missing' and/or Curve Index '#Error: OIS Curve Market Data is Missing' do not exist | AM37: =JACOBIAN_RESULTS!C42 -> #Error: Jacobian Results for Curve Collection '#Error: OIS Curve Market Data is Missing' and/or Curve Index '#Error: OIS Curve Market Data is Missing' do not exist | AN37: =AM37-AJ37 -> #VALUE! | AP37: =JACOBIAN_RESULTS!K42 -> 45706 | AQ37: =JACOBIAN_RESULTS!M42 -> #VALUE! | AR37: =AJ37 -> -5.1130527e-06 | AS37: =AR37-AQ37 -> #VALUE! | AU37: =JACOBIAN_RESULTS!P42 -> #Error: Invalid Variant Data: Unable to cast '#Error: Invalid Curve: CurveCollection '#Error: OIS Curve Market Data is Missing' does not exist' to double | AV37: =JACOBIAN_RESULTS!R42 -> 0.9349124 | AW37: =AI37 -> 0.9349124 | AX37: =AW37-AV37 -> 0
