Workbook
Name COB: [1]Settings!$C$2
Name Settings.COB: SETTINGS!$B$3
Name Settings.FrequencyLookupTable: [1]Settings!$B$206:$C$210

Sheet SETTINGS
B2: COB | E2: LIBOR FIXING DATA | K2: SPOT FX DATA
B3: =TODAY() -> 44063
E4: USD | H4: AUD
E5: 1M | F5: 0.0123444 | H5: 1M | I5: 0.0159 | K5: AUDUSD | L5: 0.75
E6: 3M | F6: 0.0129556 | H6: 3M | I6: 0.0171
E7: 6M | F7: 0.0145556 | H7: 6M | I7: 0.0186
E8: 12M | F8: 0.0172789

Sheet USD-BONDS
B2: USD Bonds
Q3: USD Bond Template
B5: Bond Price | D5: Handle | E5: BondDescription | F5: ISIN | G5: IsCleanPrice | H5: IssueDate | I5: AccrualStartDate | J5: FirstCouponDate | K5: LastCouponDate | L5: MaturityDate | M5: Coupon | N5: DayCount | O5: Frequency | Q5: BondLVB
A6: 1 | B6: 96.021 | D6: =_xll.meLWOBondCreate(E6,_xll.meUtilityLVBFromMultipleKeysValues($E$5:$G$5,E6:G6,,$Q$6:$Q$9,$R$6:$R$9),_xll.meUtilityLVBFromMultipleKeysValues($H$5:$O$5,H6:O6,,$Q$16:$Q$24,$R$16:$R$24)) -> MIZUHO-3.2%-26-MAR-25-USD@118:3 | E6: MIZUHO-3.2%-26-MAR-25-USD | F6: USJ46186BC59 | G6: TRUE | H6: 42089 | I6: =H6 -> 42089 | L6: 45742 | M6: 0.032 | N6: 30E/360 | O6: SEMI-ANNUAL | Q6: BondType | R6: FIXED
A7: =A6+1 -> 2 | B7: 94.55 | D7: =_xll.meLWOBondCreate(E7,_xll.meUtilityLVBFromMultipleKeysValues($E$5:$G$5,E7:G7,,$Q$6:$Q$9,$R$6:$R$9),_xll.meUtilityLVBFromMultipleKeysValues($H$5:$O$5,H7:O7,,$Q$16:$Q$24,$R$16:$R$24)) -> MIZUHO-1.61-27-JUL-21-USD@96:3 | E7: MIZUHO-1.61-27-JUL-21-USD | F7: XS1447582930 | G7: TRUE | H7: 42566 | I7: 42578 | L7: 44404 | M7: 0.0161 | N7: 30E/360 | O7: SEMI-ANNUAL | Q7: Currency | R7: USD
A8: =A7+1 -> 3 | B8: 100 | D8: =_xll.meLWOBondCreate(E8,_xll.meUtilityLVBFromMultipleKeysValues($E$5:$G$5,E8:G8,,$Q$6:$Q$9,$R$6:$R$9),_xll.meUtilityLVBFromMultipleKeysValues($H$5:$O$5,H8:O8,,$Q$16:$Q$24,$R$16:$R$24)) -> USD-DUMMY-BOND2@109:3 | E8: USD-DUMMY-BOND2 | F8: ISIN2 | G8: TRUE | H8: 42089 | I8: =H8 -> 42089 | L8: 45742 | M8: 0.032 | N8: 30E/360 | O8: SEMI-ANNUAL | Q8: YieldType | R8: YIELD-TO-MATURITY
A9: =A8+1 -> 4 | B9: 100 | D9: =_xll.meLWOBondCreate(E9,_xll.meUtilityLVBFromMultipleKeysValues($E$5:$G$5,E9:G9,,$Q$6:$Q$9,$R$6:$R$9),_xll.meUtilityLVBFromMultipleKeysValues($H$5:$O$5,H9:O9,,$Q$16:$Q$24,$R$16:$R$24)) -> USD-DUMMY-BOND3@121:3 | E9: USD-DUMMY-BOND3 | F9: ISIN3 | G9: TRUE | H9: 42089 | I9: =H9 -> 42089 | L9: 45742 | M9: 0.032 | N9: 30E/360 | O9: SEMI-ANNUAL | Q9: BondQuoteConvention | R9: QUOTE_IN_32NDS
A10: =A9+1 -> 5 | B10: 100 | D10: =_xll.meLWOBondCreate(E10,_xll.meUtilityLVBFromMultipleKeysValues($E$5:$G$5,E10:G10,,$Q$6:$Q$9,$R$6:$R$9),_xll.meUtilityLVBFromMultipleKeysValues($H$5:$O$5,H10:O10,,$Q$16:$Q$24,$R$16:$R$24)) -> USD-DUMMY-BOND4@125:3 | E10: USD-DUMMY-BOND4 | F10: ISIN4 | G10: TRUE | H10: 42089 | I10: =H10 -> 42089 | L10: 45742 | M10: 0.032 | N10: 30E/360 | O10: SEMI-ANNUAL | Q10: BondDescription
A11: =A10+1 -> 6 | B11: 100 | D11: =_xll.meLWOBondCreate(E11,_xll.meUtilityLVBFromMultipleKeysValues($E$5:$G$5,E11:G11,,$Q$6:$Q$9,$R$6:$R$9),_xll.meUtilityLVBFromMultipleKeysValues($H$5:$O$5,H11:O11,,$Q$16:$Q$24,$R$16:$R$24)) -> USD-DUMMY-BOND5@122:3 | E11: USD-DUMMY-BOND5 | F11: ISIN5 | G11: TRUE | H11: 42089 | I11: =H11 -> 42089 | L11: 45742 | M11: 0.032 | N11: 30E/360 | O11: SEMI-ANNUAL | Q11: ISIN
A12: =A11+1 -> 7 | B12: 100 | D12: =_xll.meLWOBondCreate(E12,_xll.meUtilityLVBFromMultipleKeysValues($E$5:$G$5,E12:G12,,$Q$6:$Q$9,$R$6:$R$9),_xll.meUtilityLVBFromMultipleKeysValues($H$5:$O$5,H12:O12,,$Q$16:$Q$24,$R$16:$R$24)) -> USD-DUMMY-BOND6@117:3 | E12: USD-DUMMY-BOND6 | F12: ISIN6 | G12: TRUE | H12: 42089 | I12: =H12 -> 42089 | L12: 45742 | M12: 0.032 | N12: 30E/360 | O12: SEMI-ANNUAL | Q12: IsCleanPrice
A13: =A12+1 -> 8 | B13: 100 | D13: =_xll.meLWOBondCreate(E13,_xll.meUtilityLVBFromMultipleKeysValues($E$5:$G$5,E13:G13,,$Q$6:$Q$9,$R$6:$R$9),_xll.meUtilityLVBFromMultipleKeysValues($H$5:$O$5,H13:O13,,$Q$16:$Q$24,$R$16:$R$24)) -> USD-DUMMY-BOND7@145:3 | E13: USD-DUMMY-BOND7 | F13: ISIN7 | G13: TRUE | H13: 42089 | I13: =H13 -> 42089 | L13: 45742 | M13: 0.032 | N13: 30E/360 | O13: SEMI-ANNUAL
A14: =A13+1 -> 9 | B14: 100 | D14: =_xll.meLWOBondCreate(E14,_xll.meUtilityLVBFromMultipleKeysValues($E$5:$G$5,E14:G14,,$Q$6:$Q$9,$R$6:$R$9),_xll.meUtilityLVBFromMultipleKeysValues($H$5:$O$5,H14:O14,,$Q$16:$Q$24,$R$16:$R$24)) -> USD-DUMMY-BOND8@144:3 | E14: USD-DUMMY-BOND8 | F14: ISIN8 | G14: TRUE | H14: 42089 | I14: =H14 -> 42089 | L14: 45742 | M14: 0.032 | N14: 30E/360 | O14: SEMI-ANNUAL
A15: =A14+1 -> 10 | B15: 100 | D15: =_xll.meLWOBondCreate(E15,_xll.meUtilityLVBFromMultipleKeysValues($E$5:$G$5,E15:G15,,$Q$6:$Q$9,$R$6:$R$9),_xll.meUtilityLVBFromMultipleKeysValues($H$5:$O$5,H15:O15,,$Q$16:$Q$24,$R$16:$R$24)) -> USD-DUMMY-BOND9@115:3 | E15: USD-DUMMY-BOND9 | F15: ISIN9 | G15: TRUE | H15: 42089 | I15: =H15 -> 42089 | L15: 45742 | M15: 0.032 | N15: 30E/360 | O15: SEMI-ANNUAL | Q15: ScheduleLVB
A16: =A15+1 -> 11 | B16: 100 | D16: =_xll.meLWOBondCreate(E16,_xll.meUtilityLVBFromMultipleKeysValues($E$5:$G$5,E16:G16,,$Q$6:$Q$9,$R$6:$R$9),_xll.meUtilityLVBFromMultipleKeysValues($H$5:$O$5,H16:O16,,$Q$16:$Q$24,$R$16:$R$24)) -> USD-DUMMY-BOND10@131:3 | E16: USD-DUMMY-BOND10 | F16: ISIN10 | G16: TRUE | H16: 42089 | I16: =H16 -> 42089 | L16: 45742 | M16: 0.032 | N16: 30E/360 | O16: SEMI-ANNUAL | Q16: PayReceive | R16: RECEIVE
A17: =A16+1 -> 12 | B17: 100 | D17: =_xll.meLWOBondCreate(E17,_xll.meUtilityLVBFromMultipleKeysValues($E$5:$G$5,E17:G17,,$Q$6:$Q$9,$R$6:$R$9),_xll.meUtilityLVBFromMultipleKeysValues($H$5:$O$5,H17:O17,,$Q$16:$Q$24,$R$16:$R$24)) -> USD-DUMMY-BOND11@134:3 | E17: USD-DUMMY-BOND11 | F17: ISIN11 | G17: TRUE | H17: 42089 | I17: =H17 -> 42089 | L17: 45742 | M17: 0.032 | N17: 30E/360 | O17: SEMI-ANNUAL | Q17: NotionalExchange | R17: START_AND_END
A18: =A17+1 -> 13 | B18: 100 | D18: =_xll.meLWOBondCreate(E18,_xll.meUtilityLVBFromMultipleKeysValues($E$5:$G$5,E18:G18,,$Q$6:$Q$9,$R$6:$R$9),_xll.meUtilityLVBFromMultipleKeysValues($H$5:$O$5,H18:O18,,$Q$16:$Q$24,$R$16:$R$24)) -> USD-DUMMY-BOND12@100:3 | E18: USD-DUMMY-BOND12 | F18: ISIN12 | G18: TRUE | H18: 42089 | I18: =H18 -> 42089 | L18: 45742 | M18: 0.032 | N18: 30E/360 | O18: SEMI-ANNUAL | Q18: FaceValue | R18: 1000000
A19: =A18+1 -> 14 | B19: 100 | D19: =_xll.meLWOBondCreate(E19,_xll.meUtilityLVBFromMultipleKeysValues($E$5:$G$5,E19:G19,,$Q$6:$Q$9,$R$6:$R$9),_xll.meUtilityLVBFromMultipleKeysValues($H$5:$O$5,H19:O19,,$Q$16:$Q$24,$R$16:$R$24)) -> USD-DUMMY-BOND13@139:3 | E19: USD-DUMMY-BOND13 | F19: ISIN13 | G19: TRUE | H19: 42089 | I19: =H19 -> 42089 | L19: 45742 | M19: 0.032 | N19: 30E/360 | O19: SEMI-ANNUAL | Q19: AccrualBusinessDayAdjustment | R19: MOD_FOLLOWING
A20: =A19+1 -> 15 | B20: 100 | D20: =_xll.meLWOBondCreate(E20,_xll.meUtilityLVBFromMultipleKeysValues($E$5:$G$5,E20:G20,,$Q$6:$Q$9,$R$6:$R$9),_xll.meUtilityLVBFromMultipleKeysValues($H$5:$O$5,H20:O20,,$Q$16:$Q$24,$R$16:$R$24)) -> USD-DUMMY-BOND14@116:3 | E20: USD-DUMMY-BOND14 | F20: ISIN14 | G20: TRUE | H20: 42089 | I20: =H20 -> 42089 | L20: 45742 | M20: 0.032 | N20: 30E/360 | O20: SEMI-ANNUAL | Q20: AccrualCalendar | R20: NYB
A21: =A20+1 -> 16 | B21: 100 | D21: =_xll.meLWOBondCreate(E21,_xll.meUtilityLVBFromMultipleKeysValues($E$5:$G$5,E21:G21,,$Q$6:$Q$9,$R$6:$R$9),_xll.meUtilityLVBFromMultipleKeysValues($H$5:$O$5,H21:O21,,$Q$16:$Q$24,$R$16:$R$24)) -> USD-DUMMY-BOND15@110:3 | E21: USD-DUMMY-BOND15 | F21: ISIN15 | G21: TRUE | H21: 42089 | I21: =H21 -> 42089 | L21: 45742 | M21: 0.032 | N21: 30E/360 | O21: SEMI-ANNUAL | Q21: PaymentBusinessDayAdjustment | R21: NO_CHANGE
A22: =A21+1 -> 17 | B22: 100 | D22: =_xll.meLWOBondCreate(E22,_xll.meUtilityLVBFromMultipleKeysValues($E$5:$G$5,E22:G22,,$Q$6:$Q$9,$R$6:$R$9),_xll.meUtilityLVBFromMultipleKeysValues($H$5:$O$5,H22:O22,,$Q$16:$Q$24,$R$16:$R$24)) -> USD-DUMMY-BOND16@97:3 | E22: USD-DUMMY-BOND16 | F22: ISIN16 | G22: TRUE | H22: 42089 | I22: =H22 -> 42089 | L22: 45742 | M22: 0.032 | N22: 30E/360 | O22: SEMI-ANNUAL | Q22: PaymentCalendar | R22: NYB
A23: =A22+1 -> 18 | B23: 100 | D23: =_xll.meLWOBondCreate(E23,_xll.meUtilityLVBFromMultipleKeysValues($E$5:$G$5,E23:G23,,$Q$6:$Q$9,$R$6:$R$9),_xll.meUtilityLVBFromMultipleKeysValues($H$5:$O$5,H23:O23,,$Q$16:$Q$24,$R$16:$R$24)) -> USD-DUMMY-BOND17@130:3 | E23: USD-DUMMY-BOND17 | F23: ISIN17 | G23: TRUE | H23: 42089 | I23: =H23 -> 42089 | L23: 45742 | M23: 0.032 | N23: 30E/360 | O23: SEMI-ANNUAL | Q23: PaymentLag | R23: 0D
A24: =A23+1 -> 19 | B24: 100 | D24: =_xll.meLWOBondCreate(E24,_xll.meUtilityLVBFromMultipleKeysValues($E$5:$G$5,E24:G24,,$Q$6:$Q$9,$R$6:$R$9),_xll.meUtilityLVBFromMultipleKeysValues($H$5:$O$5,H24:O24,,$Q$16:$Q$24,$R$16:$R$24)) -> USD-DUMMY-BOND18@135:3 | E24: USD-DUMMY-BOND18 | F24: ISIN18 | G24: TRUE | H24: 42089 | I24: =H24 -> 42089 | L24: 45742 | M24: 0.032 | N24: 30E/360 | O24: SEMI-ANNUAL | Q24: CalculationType | R24: TYPE1_STREET_CONVENTION
A25: =A24+1 -> 20 | B25: 100 | D25: =_xll.meLWOBondCreate(E25,_xll.meUtilityLVBFromMultipleKeysValues($E$5:$G$5,E25:G25,,$Q$6:$Q$9,$R$6:$R$9),_xll.meUtilityLVBFromMultipleKeysValues($H$5:$O$5,H25:O25,,$Q$16:$Q$24,$R$16:$R$24)) -> USD-DUMMY-BOND19@99:3 | E25: USD-DUMMY-BOND19 | F25: ISIN19 | G25: TRUE | H25: 42089 | I25: =H25 -> 42089 | L25: 45742 | M25: 0.032 | N25: 30E/360 | O25: SEMI-ANNUAL | Q25: IssueDate
A26: =A25+1 -> 21 | B26: 100 | D26: =_xll.meLWOBondCreate(E26,_xll.meUtilityLVBFromMultipleKeysValues($E$5:$G$5,E26:G26,,$Q$6:$Q$9,$R$6:$R$9),_xll.meUtilityLVBFromMultipleKeysValues($H$5:$O$5,H26:O26,,$Q$16:$Q$24,$R$16:$R$24)) -> USD-DUMMY-BOND20@111:3 | E26: USD-DUMMY-BOND20 | F26: ISIN20 | G26: TRUE | H26: 42089 | I26: =H26 -> 42089 | L26: 45742 | M26: 0.032 | N26: 30E/360 | O26: SEMI-ANNUAL | Q26: AccrualStartDate
A27: =A26+1 -> 22 | B27: 100 | D27: =_xll.meLWOBondCreate(E27,_xll.meUtilityLVBFromMultipleKeysValues($E$5:$G$5,E27:G27,,$Q$6:$Q$9,$R$6:$R$9),_xll.meUtilityLVBFromMultipleKeysValues($H$5:$O$5,H27:O27,,$Q$16:$Q$24,$R$16:$R$24)) -> USD-DUMMY-BOND21@95:3 | E27: USD-DUMMY-BOND21 | F27: ISIN21 | G27: TRUE | H27: 42089 | I27: =H27 -> 42089 | L27: 45742 | M27: 0.032 | N27: 30E/360 | O27: SEMI-ANNUAL | Q27: FirstCouponDate
A28: =A27+1 -> 23 | B28: 100 | D28: =_xll.meLWOBondCreate(E28,_xll.meUtilityLVBFromMultipleKeysValues($E$5:$G$5,E28:G28,,$Q$6:$Q$9,$R$6:$R$9),_xll.meUtilityLVBFromMultipleKeysValues($H$5:$O$5,H28:O28,,$Q$16:$Q$24,$R$16:$R$24)) -> USD-DUMMY-BOND22@140:3 | E28: USD-DUMMY-BOND22 | F28: ISIN22 | G28: TRUE | H28: 42089 | I28: =H28 -> 42089 | L28: 45742 | M28: 0.032 | N28: 30E/360 | O28: SEMI-ANNUAL | Q28: LastCouponDate
A29: =A28+1 -> 24 | B29: 100 | D29: =_xll.meLWOBondCreate(E29,_xll.meUtilityLVBFromMultipleKeysValues($E$5:$G$5,E29:G29,,$Q$6:$Q$9,$R$6:$R$9),_xll.meUtilityLVBFromMultipleKeysValues($H$5:$O$5,H29:O29,,$Q$16:$Q$24,$R$16:$R$24)) -> USD-DUMMY-BOND23@132:3 | E29: USD-DUMMY-BOND23 | F29: ISIN23 | G29: TRUE | H29: 42089 | I29: =H29 -> 42089 | L29: 45742 | M29: 0.032 | N29: 30E/360 | O29: SEMI-ANNUAL | Q29: MaturityDate
A30: =A29+1 -> 25 | B30: 100 | D30: =_xll.meLWOBondCreate(E30,_xll.meUtilityLVBFromMultipleKeysValues($E$5:$G$5,E30:G30,,$Q$6:$Q$9,$R$6:$R$9),_xll.meUtilityLVBFromMultipleKeysValues($H$5:$O$5,H30:O30,,$Q$16:$Q$24,$R$16:$R$24)) -> USD-DUMMY-BOND24@141:3 | E30: USD-DUMMY-BOND24 | F30: ISIN24 | G30: TRUE | H30: 42089 | I30: =H30 -> 42089 | L30: 45742 | M30: 0.032 | N30: 30E/360 | O30: SEMI-ANNUAL | Q30: Coupon
A31: =A30+1 -> 26 | B31: 100 | D31: =_xll.meLWOBondCreate(E31,_xll.meUtilityLVBFromMultipleKeysValues($E$5:$G$5,E31:G31,,$Q$6:$Q$9,$R$6:$R$9),_xll.meUtilityLVBFromMultipleKeysValues($H$5:$O$5,H31:O31,,$Q$16:$Q$24,$R$16:$R$24)) -> USD-DUMMY-BOND25@103:3 | E31: USD-DUMMY-BOND25 | F31: ISIN25 | G31: TRUE | H31: 42089 | I31: =H31 -> 42089 | L31: 45742 | M31: 0.032 | N31: 30E/360 | O31: SEMI-ANNUAL | Q31: DayCount
A32: =A31+1 -> 27 | B32: 100 | D32: =_xll.meLWOBondCreate(E32,_xll.meUtilityLVBFromMultipleKeysValues($E$5:$G$5,E32:G32,,$Q$6:$Q$9,$R$6:$R$9),_xll.meUtilityLVBFromMultipleKeysValues($H$5:$O$5,H32:O32,,$Q$16:$Q$24,$R$16:$R$24)) -> USD-DUMMY-BOND26@129:3 | E32: USD-DUMMY-BOND26 | F32: ISIN26 | G32: TRUE | H32: 42089 | I32: =H32 -> 42089 | L32: 45742 | M32: 0.032 | N32: 30E/360 | O32: SEMI-ANNUAL | Q32: Frequency

Sheet AUD-BONDS
B2: AUD Bonds
Q3: AUD Bond Template
B5: Bond Price | D5: Handle | E5: BondDescription | F5: ISIN | G5: IsCleanPrice | H5: IssueDate | I5: AccrualStartDate | J5: FirstCouponDate | K5: LastCouponDate | L5: MaturityDate | M5: Coupon | N5: DayCount | O5: Frequency | Q5: BondLVB
A6: 1 | B6: 95.483 | D6: =_xll.meLWOBondCreate(E6,_xll.meUtilityLVBFromMultipleKeysValues($E$5:$G$5,E6:G6,,$Q$6:$Q$9,$R$6:$R$9),_xll.meUtilityLVBFromMultipleKeysValues($H$5:$O$5,H6:O6,,$Q$16:$Q$24,$R$16:$R$24)) -> MIZUHO-3.92%-15-JAN-26 AUD@101:3 | E6: MIZUHO-3.92%-15-JAN-26 AUD | F6: XS1344710857 | G6: TRUE | H6: 42566 | I6: 42566 | L6: 46037 | M6: 0.0392 | N6: 30E/360 | O6: SEMI-ANNUAL | Q6: BondType | R6: FIXED
A7: =A6+1 -> 2 | B7: 100 | D7: =_xll.meLWOBondCreate(E7,_xll.meUtilityLVBFromMultipleKeysValues($E$5:$G$5,E7:G7,,$Q$6:$Q$9,$R$6:$R$9),_xll.meUtilityLVBFromMultipleKeysValues($H$5:$O$5,H7:O7,,$Q$16:$Q$24,$R$16:$R$24)) -> MIZUHO-2.62%27-JUL-21-AUD@98:3 | E7: MIZUHO-2.62%27-JUL-21-AUD | F7: XS1447583664 | G7: TRUE | H7: 42578 | I7: 42578 | L7: 44404 | M7: 0.0262 | N7: 30E/360 | O7: SEMI-ANNUAL | Q7: Currency | R7: AUD
A8: =A7+1 -> 3 | B8: 100 | D8: =_xll.meLWOBondCreate(E8,_xll.meUtilityLVBFromMultipleKeysValues($E$5:$G$5,E8:G8,,$Q$6:$Q$9,$R$6:$R$9),_xll.meUtilityLVBFromMultipleKeysValues($H$5:$O$5,H8:O8,,$Q$16:$Q$24,$R$16:$R$24)) -> AUD_DUMMY_BOND2@123:3 | E8: AUD_DUMMY_BOND2 | F8: ISIN2 | G8: TRUE | H8: 42566 | I8: 42566 | L8: 46037 | M8: 0.0392 | N8: 30E/360 | O8: SEMI-ANNUAL | Q8: YieldType | R8: YIELD-TO-MATURITY
A9: =A8+1 -> 4 | B9: 100 | D9: =_xll.meLWOBondCreate(E9,_xll.meUtilityLVBFromMultipleKeysValues($E$5:$G$5,E9:G9,,$Q$6:$Q$9,$R$6:$R$9),_xll.meUtilityLVBFromMultipleKeysValues($H$5:$O$5,H9:O9,,$Q$16:$Q$24,$R$16:$R$24)) -> AUD_DUMMY_BOND3@124:3 | E9: AUD_DUMMY_BOND3 | F9: ISIN3 | G9: TRUE | H9: 42566 | I9: 42566 | L9: 46037 | M9: 0.0392 | N9: 30E/360 | O9: SEMI-ANNUAL | Q9: BondQuoteConvention | R9: QUOTE_IN_32NDS
A10: =A9+1 -> 5 | B10: 100 | D10: =_xll.meLWOBondCreate(E10,_xll.meUtilityLVBFromMultipleKeysValues($E$5:$G$5,E10:G10,,$Q$6:$Q$9,$R$6:$R$9),_xll.meUtilityLVBFromMultipleKeysValues($H$5:$O$5,H10:O10,,$Q$16:$Q$24,$R$16:$R$24)) -> AUD_DUMMY_BOND4@94:3 | E10: AUD_DUMMY_BOND4 | F10: ISIN4 | G10: TRUE | H10: 42566 | I10: 42566 | L10: 46037 | M10: 0.0392 | N10: 30E/360 | O10: SEMI-ANNUAL | Q10: BondDescription
A11: =A10+1 -> 6 | B11: 100 | D11: =_xll.meLWOBondCreate(E11,_xll.meUtilityLVBFromMultipleKeysValues($E$5:$G$5,E11:G11,,$Q$6:$Q$9,$R$6:$R$9),_xll.meUtilityLVBFromMultipleKeysValues($H$5:$O$5,H11:O11,,$Q$16:$Q$24,$R$16:$R$24)) -> AUD_DUMMY_BOND5@108:3 | E11: AUD_DUMMY_BOND5 | F11: ISIN5 | G11: TRUE | H11: 42566 | I11: 42566 | L11: 46037 | M11: 0.0392 | N11: 30E/360 | O11: SEMI-ANNUAL | Q11: ISIN
A12: =A11+1 -> 7 | B12: 100 | D12: =_xll.meLWOBondCreate(E12,_xll.meUtilityLVBFromMultipleKeysValues($E$5:$G$5,E12:G12,,$Q$6:$Q$9,$R$6:$R$9),_xll.meUtilityLVBFromMultipleKeysValues($H$5:$O$5,H12:O12,,$Q$16:$Q$24,$R$16:$R$24)) -> AUD_DUMMY_BOND6@105:3 | E12: AUD_DUMMY_BOND6 | F12: ISIN6 | G12: TRUE | H12: 42566 | I12: 42566 | L12: 46037 | M12: 0.0392 | N12: 30E/360 | O12: SEMI-ANNUAL | Q12: IsCleanPrice
A13: =A12+1 -> 8 | B13: 100 | D13: =_xll.meLWOBondCreate(E13,_xll.meUtilityLVBFromMultipleKeysValues($E$5:$G$5,E13:G13,,$Q$6:$Q$9,$R$6:$R$9),_xll.meUtilityLVBFromMultipleKeysValues($H$5:$O$5,H13:O13,,$Q$16:$Q$24,$R$16:$R$24)) -> AUD_DUMMY_BOND7@114:3 | E13: AUD_DUMMY_BOND7 | F13: ISIN7 | G13: TRUE | H13: 42566 | I13: 42566 | L13: 46037 | M13: 0.0392 | N13: 30E/360 | O13: SEMI-ANNUAL
A14: =A13+1 -> 9 | B14: 100 | D14: =_xll.meLWOBondCreate(E14,_xll.meUtilityLVBFromMultipleKeysValues($E$5:$G$5,E14:G14,,$Q$6:$Q$9,$R$6:$R$9),_xll.meUtilityLVBFromMultipleKeysValues($H$5:$O$5,H14:O14,,$Q$16:$Q$24,$R$16:$R$24)) -> AUD_DUMMY_BOND8@112:3 | E14: AUD_DUMMY_BOND8 | F14: ISIN8 | G14: TRUE | H14: 42566 | I14: 42566 | L14: 46037 | M14: 0.0392 | N14: 30E/360 | O14: SEMI-ANNUAL
A15: =A14+1 -> 10 | B15: 100 | D15: =_xll.meLWOBondCreate(E15,_xll.meUtilityLVBFromMultipleKeysValues($E$5:$G$5,E15:G15,,$Q$6:$Q$9,$R$6:$R$9),_xll.meUtilityLVBFromMultipleKeysValues($H$5:$O$5,H15:O15,,$Q$16:$Q$24,$R$16:$R$24)) -> AUD_DUMMY_BOND9@138:3 | E15: AUD_DUMMY_BOND9 | F15: ISIN9 | G15: TRUE | H15: 42566 | I15: 42566 | L15: 46037 | M15: 0.0392 | N15: 30E/360 | O15: SEMI-ANNUAL | Q15: ScheduleLVB
A16: =A15+1 -> 11 | B16: 100 | D16: =_xll.meLWOBondCreate(E16,_xll.meUtilityLVBFromMultipleKeysValues($E$5:$G$5,E16:G16,,$Q$6:$Q$9,$R$6:$R$9),_xll.meUtilityLVBFromMultipleKeysValues($H$5:$O$5,H16:O16,,$Q$16:$Q$24,$R$16:$R$24)) -> AUD_DUMMY_BOND10@128:3 | E16: AUD_DUMMY_BOND10 | F16: ISIN10 | G16: TRUE | H16: 42566 | I16: 42566 | L16: 46037 | M16: 0.0392 | N16: 30E/360 | O16: SEMI-ANNUAL | Q16: PayReceive | R16: RECEIVE
A17: =A16+1 -> 12 | B17: 100 | D17: =_xll.meLWOBondCreate(E17,_xll.meUtilityLVBFromMultipleKeysValues($E$5:$G$5,E17:G17,,$Q$6:$Q$9,$R$6:$R$9),_xll.meUtilityLVBFromMultipleKeysValues($H$5:$O$5,H17:O17,,$Q$16:$Q$24,$R$16:$R$24)) -> AUD_DUMMY_BOND11@119:3 | E17: AUD_DUMMY_BOND11 | F17: ISIN11 | G17: TRUE | H17: 42566 | I17: 42566 | L17: 46037 | M17: 0.0392 | N17: 30E/360 | O17: SEMI-ANNUAL | Q17: NotionalExchange | R17: START_AND_END
A18: =A17+1 -> 13 | B18: 100 | D18: =_xll.meLWOBondCreate(E18,_xll.meUtilityLVBFromMultipleKeysValues($E$5:$G$5,E18:G18,,$Q$6:$Q$9,$R$6:$R$9),_xll.meUtilityLVBFromMultipleKeysValues($H$5:$O$5,H18:O18,,$Q$16:$Q$24,$R$16:$R$24)) -> AUD_DUMMY_BOND12@102:3 | E18: AUD_DUMMY_BOND12 | F18: ISIN12 | G18: TRUE | H18: 42566 | I18: 42566 | L18: 46037 | M18: 0.0392 | N18: 30E/360 | O18: SEMI-ANNUAL | Q18: FaceValue | R18: 1000000
A19: =A18+1 -> 14 | B19: 100 | D19: =_xll.meLWOBondCreate(E19,_xll.meUtilityLVBFromMultipleKeysValues($E$5:$G$5,E19:G19,,$Q$6:$Q$9,$R$6:$R$9),_xll.meUtilityLVBFromMultipleKeysValues($H$5:$O$5,H19:O19,,$Q$16:$Q$24,$R$16:$R$24)) -> AUD_DUMMY_BOND13@92:3 | E19: AUD_DUMMY_BOND13 | F19: ISIN13 | G19: TRUE | H19: 42566 | I19: 42566 | L19: 46037 | M19: 0.0392 | N19: 30E/360 | O19: SEMI-ANNUAL | Q19: AccrualBusinessDayAdjustment | R19: MOD_FOLLOWING
A20: =A19+1 -> 15 | B20: 100 | D20: =_xll.meLWOBondCreate(E20,_xll.meUtilityLVBFromMultipleKeysValues($E$5:$G$5,E20:G20,,$Q$6:$Q$9,$R$6:$R$9),_xll.meUtilityLVBFromMultipleKeysValues($H$5:$O$5,H20:O20,,$Q$16:$Q$24,$R$16:$R$24)) -> AUD_DUMMY_BOND14@107:3 | E20: AUD_DUMMY_BOND14 | F20: ISIN14 | G20: TRUE | H20: 42566 | I20: 42566 | L20: 46037 | M20: 0.0392 | N20: 30E/360 | O20: SEMI-ANNUAL | Q20: AccrualCalendar | R20: SYB
A21: =A20+1 -> 16 | B21: 100 | D21: =_xll.meLWOBondCreate(E21,_xll.meUtilityLVBFromMultipleKeysValues($E$5:$G$5,E21:G21,,$Q$6:$Q$9,$R$6:$R$9),_xll.meUtilityLVBFromMultipleKeysValues($H$5:$O$5,H21:O21,,$Q$16:$Q$24,$R$16:$R$24)) -> AUD_DUMMY_BOND15@91:3 | E21: AUD_DUMMY_BOND15 | F21: ISIN15 | G21: TRUE | H21: 42566 | I21: 42566 | L21: 46037 | M21: 0.0392 | N21: 30E/360 | O21: SEMI-ANNUAL | Q21: PaymentBusinessDayAdjustment | R21: NO_CHANGE
A22: =A21+1 -> 17 | B22: 100 | D22: =_xll.meLWOBondCreate(E22,_xll.meUtilityLVBFromMultipleKeysValues($E$5:$G$5,E22:G22,,$Q$6:$Q$9,$R$6:$R$9),_xll.meUtilityLVBFromMultipleKeysValues($H$5:$O$5,H22:O22,,$Q$16:$Q$24,$R$16:$R$24)) -> AUD_DUMMY_BOND16@126:3 | E22: AUD_DUMMY_BOND16 | F22: ISIN16 | G22: TRUE | H22: 42566 | I22: 42566 | L22: 46037 | M22: 0.0392 | N22: 30E/360 | O22: SEMI-ANNUAL | Q22: PaymentCalendar | R22: SYB
A23: =A22+1 -> 18 | B23: 100 | D23: =_xll.meLWOBondCreate(E23,_xll.meUtilityLVBFromMultipleKeysValues($E$5:$G$5,E23:G23,,$Q$6:$Q$9,$R$6:$R$9),_xll.meUtilityLVBFromMultipleKeysValues($H$5:$O$5,H23:O23,,$Q$16:$Q$24,$R$16:$R$24)) -> AUD_DUMMY_BOND17@136:3 | E23: AUD_DUMMY_BOND17 | F23: ISIN17 | G23: TRUE | H23: 42566 | I23: 42566 | L23: 46037 | M23: 0.0392 | N23: 30E/360 | O23: SEMI-ANNUAL | Q23: PaymentLag | R23: 0D
A24: =A23+1 -> 19 | B24: 100 | D24: =_xll.meLWOBondCreate(E24,_xll.meUtilityLVBFromMultipleKeysValues($E$5:$G$5,E24:G24,,$Q$6:$Q$9,$R$6:$R$9),_xll.meUtilityLVBFromMultipleKeysValues($H$5:$O$5,H24:O24,,$Q$16:$Q$24,$R$16:$R$24)) -> AUD_DUMMY_BOND18@133:3 | E24: AUD_DUMMY_BOND18 | F24: ISIN18 | G24: TRUE | H24: 42566 | I24: 42566 | L24: 46037 | M24: 0.0392 | N24: 30E/360 | O24: SEMI-ANNUAL | Q24: CalculationType | R24: TYPE23
A25: =A24+1 -> 20 | B25: 100 | D25: =_xll.meLWOBondCreate(E25,_xll.meUtilityLVBFromMultipleKeysValues($E$5:$G$5,E25:G25,,$Q$6:$Q$9,$R$6:$R$9),_xll.meUtilityLVBFromMultipleKeysValues($H$5:$O$5,H25:O25,,$Q$16:$Q$24,$R$16:$R$24)) -> AUD_DUMMY_BOND19@137:3 | E25: AUD_DUMMY_BOND19 | F25: ISIN19 | G25: TRUE | H25: 42566 | I25: 42566 | L25: 46037 | M25: 0.0392 | N25: 30E/360 | O25: SEMI-ANNUAL | Q25: IssueDate
A26: =A25+1 -> 21 | B26: 100 | D26: =_xll.meLWOBondCreate(E26,_xll.meUtilityLVBFromMultipleKeysValues($E$5:$G$5,E26:G26,,$Q$6:$Q$9,$R$6:$R$9),_xll.meUtilityLVBFromMultipleKeysValues($H$5:$O$5,H26:O26,,$Q$16:$Q$24,$R$16:$R$24)) -> AUD_DUMMY_BOND20@127:3 | E26: AUD_DUMMY_BOND20 | F26: ISIN20 | G26: TRUE | H26: 42566 | I26: 42566 | L26: 46037 | M26: 0.0392 | N26: 30E/360 | O26: SEMI-ANNUAL | Q26: AccrualStartDate
A27: =A26+1 -> 22 | B27: 100 | D27: =_xll.meLWOBondCreate(E27,_xll.meUtilityLVBFromMultipleKeysValues($E$5:$G$5,E27:G27,,$Q$6:$Q$9,$R$6:$R$9),_xll.meUtilityLVBFromMultipleKeysValues($H$5:$O$5,H27:O27,,$Q$16:$Q$24,$R$16:$R$24)) -> AUD_DUMMY_BOND21@120:3 | E27: AUD_DUMMY_BOND21 | F27: ISIN21 | G27: TRUE | H27: 42566 | I27: 42566 | L27: 46037 | M27: 0.0392 | N27: 30E/360 | O27: SEMI-ANNUAL | Q27: FirstCouponDate
A28: =A27+1 -> 23 | B28: 100 | D28: =_xll.meLWOBondCreate(E28,_xll.meUtilityLVBFromMultipleKeysValues($E$5:$G$5,E28:G28,,$Q$6:$Q$9,$R$6:$R$9),_xll.meUtilityLVBFromMultipleKeysValues($H$5:$O$5,H28:O28,,$Q$16:$Q$24,$R$16:$R$24)) -> AUD_DUMMY_BOND22@93:3 | E28: AUD_DUMMY_BOND22 | F28: ISIN22 | G28: TRUE | H28: 42566 | I28: 42566 | L28: 46037 | M28: 0.0392 | N28: 30E/360 | O28: SEMI-ANNUAL | Q28: LastCouponDate
A29: =A28+1 -> 24 | B29: 100 | D29: =_xll.meLWOBondCreate(E29,_xll.meUtilityLVBFromMultipleKeysValues($E$5:$G$5,E29:G29,,$Q$6:$Q$9,$R$6:$R$9),_xll.meUtilityLVBFromMultipleKeysValues($H$5:$O$5,H29:O29,,$Q$16:$Q$24,$R$16:$R$24)) -> AUD_DUMMY_BOND23@142:3 | E29: AUD_DUMMY_BOND23 | F29: ISIN23 | G29: TRUE | H29: 42566 | I29: 42566 | L29: 46037 | M29: 0.0392 | N29: 30E/360 | O29: SEMI-ANNUAL | Q29: MaturityDate
A30: =A29+1 -> 25 | B30: 100 | D30: =_xll.meLWOBondCreate(E30,_xll.meUtilityLVBFromMultipleKeysValues($E$5:$G$5,E30:G30,,$Q$6:$Q$9,$R$6:$R$9),_xll.meUtilityLVBFromMultipleKeysValues($H$5:$O$5,H30:O30,,$Q$16:$Q$24,$R$16:$R$24)) -> AUD_DUMMY_BOND24@113:3 | E30: AUD_DUMMY_BOND24 | F30: ISIN24 | G30: TRUE | H30: 42566 | I30: 42566 | L30: 46037 | M30: 0.0392 | N30: 30E/360 | O30: SEMI-ANNUAL | Q30: Coupon
A31: =A30+1 -> 26 | B31: 100 | D31: =_xll.meLWOBondCreate(E31,_xll.meUtilityLVBFromMultipleKeysValues($E$5:$G$5,E31:G31,,$Q$6:$Q$9,$R$6:$R$9),_xll.meUtilityLVBFromMultipleKeysValues($H$5:$O$5,H31:O31,,$Q$16:$Q$24,$R$16:$R$24)) -> AUD_DUMMY_BOND25@106:3 | E31: AUD_DUMMY_BOND25 | F31: ISIN25 | G31: TRUE | H31: 42566 | I31: 42566 | L31: 46037 | M31: 0.0392 | N31: 30E/360 | O31: SEMI-ANNUAL | Q31: DayCount
A32: =A31+1 -> 27 | B32: 100 | D32: =_xll.meLWOBondCreate(E32,_xll.meUtilityLVBFromMultipleKeysValues($E$5:$G$5,E32:G32,,$Q$6:$Q$9,$R$6:$R$9),_xll.meUtilityLVBFromMultipleKeysValues($H$5:$O$5,H32:O32,,$Q$16:$Q$24,$R$16:$R$24)) -> AUD_DUMMY_BOND26@143:3 | E32: AUD_DUMMY_BOND26 | F32: ISIN26 | G32: TRUE | H32: 42566 | I32: 42566 | L32: 46037 | M32: 0.0392 | N32: 30E/360 | O32: SEMI-ANNUAL | Q32: Frequency

Sheet EXAMPLE-ASW-PX
B2: Uridashi Bond Price | K2: =_xll.meLWOXccySwapCreate(J11,J12:L45,J49:K51) -> USD_AUD_XCCY_SWAP@203:5
B3: =O8 -> 101.03512 | F3: Create Asset Swap | G3: =_xll.meLWOSwapCreate(F11,F12:H45,FALSE) -> USD_ASSET_SWAP@173:5 | J3: Create Xccy Swap | K3: Leg1:Float | L3: USDYC | N3: Create Asset Swap | O3: =_xll.meLWOSwapCreate(N11,N12:P45,FALSE) -> AUD_ASSET_SWAP@232:5
K4: Leg2:Float | L4: AUDYC | N4: ValuationDate | O4: =_xll.meDateFromTenor(TODAY(),"2D","MOD_FOLLOWING","SYB") -> 44067 | P4: BondSettlementDate
F5: ValuationDate | G5: =_xll.meDateFromTenor(TODAY(),"2D","MOD_FOLLOWING","SYB") -> 44067 | K5: FXSPOT | L5: 0.7187 | N5: CurveCollection | O5: AUDYC
B6: ValuationSettings | F6: CurveCollection | G6: USDYC | K6: ValuationDate | L6: =G5 -> 44067 | N6: FxSpot | O6: 0.7187
D7: BondSettlementDate
F8: USD Asset Swap Spread | G8: =_xll.meLWOAssetSwapSpread(G3,'USD-BONDS'!$D$6,C13,F5:G6) -> 370.97754 | J8: Xccy Par Spread | K8: =_xll.meLWOXccySwapParSpread(K2,K3:L6,,L12) -> 330.93586 | N8: Uridashi Price | O8: =_xll.meLWOAssetSwapSpreadToCleanPrice(O3,K8,N4:O5) -> 101.03512
J10: *** Non-MTM Xccy Used to Convert Proxy Funding Currency to Uridashi Funding Currency ***
B11: BOND SPECIFICATION | C11: Proxy Bond | D11: Uridashi Bond | F11: USD_ASSET_SWAP | G11: Proxy Bond Leg | H11: Funding Leg | J11: USD_AUD_XCCY_SWAP | K11: USD Funding | L11: AUD Funding | N11: AUD_ASSET_SWAP
B12: ISIN | C12: USJ46186BC59 | D12: XS1344710857 | F12: LegType | G12: Leg1:FixedBond | H12: Leg2:Float | J12: LegType | K12: Leg1:Float | L12: Leg2:Float | N12: LegType | O12: Leg1:FixedBond | P12: Leg2:Float
B13: BondPrice | C13: ='USD-BONDS'!B6 -> 96.021 | D13: =O8 -> 101.03512 | F13: Notional | G13: 1000000 | H13: 1000000 | J13: Notional | K13: 1000000 | L13: =K13/L5 -> 1391401.1 | N13: Notional | O13: 1000000 | P13: 1000000
B14: Notional | C14: 1000000 | D14: 1000000 | F14: NotionalExchange | G14: NONE | H14: NONE | J14: NotionalExchange | K14: START_AND_END | L14: START_AND_END | N14: NotionalExchange | O14: NONE | P14: NONE
B15: PayReceive | C15: PAYER | D15: PAYER | F15: PayReceive | G15: PAY | H15: REC | J15: PayReceive | K15: PAY | L15: REC | N15: PayReceive | O15: =K15 -> PAY | P15: REC
B16: IssueDate | C16: ='USD-BONDS'!$H$6 -> 42089 | D16: ='AUD-BONDS'!$H$6 -> 42566 | F16: ForecastCurve | H16: USD3ML | J16: ForecastCurve | K16: USD3ML | L16: AUD3ML | N16: ForecastCurve | P16: AUD3ML
B17: EffectiveDate | C17: =_xll.meDateFromTenor(Settings.COB,"2D","MOD_FOLLOWING","NYB") -> 44067 | D17: =_xll.meDateFromTenor(Settings.COB,"2D","MOD_FOLLOWING","SYB") -> 44067 | F17: DiscountCurve | G17: USDOIS | H17: USDOIS | J17: DiscountCurve | K17: USDOIS | L17: AUDDF_USDCSA | N17: DiscountCurve | O17: AUDOIS | P17: AUDOIS
B18: LastCouponDate | C18: =_xll.meLWOBondLastCouponDate('USD-BONDS'!D6,Settings.COB) -> 43916 | D18: =_xll.meLWOBondLastCouponDate('AUD-BONDS'!D6,Settings.COB) -> 44027 | F18: Currency | G18: USD | H18: USD | J18: Currency | K18: USD | L18: AUD | N18: Currency | O18: AUD | P18: AUD
B19: MaturityDate | C19: ='USD-BONDS'!$L$6 -> 45742 | D19: ='AUD-BONDS'!$L$6 -> 46037 | F19: Leverage | G19: 1 | H19: 1 | J19: Leverage | K19: 1 | L19: 1 | N19: Leverage | O19: =L19 -> 1 | P19: 1
B20: CurveCollection | C20: USDYC | D20: AUDYC | F20: FixedRate | G20: 0.032 | J20: FixedRate | N20: FixedRate | O20: =D25 -> 0.0392
B21: ForecastCurve | C21: USD3ML | D21: AUD6ML | F21: FirstStubCurveIndex | H21: NATURAL | J21: FirstStubCurveIndex | K21: NATURAL | L21: NATURAL | N21: FirstStubCurveIndex | P21: NATURAL
B22: DiscountCurve | C22: USDOIS | D22: AUDOIS | F22: LastStubCurveIndex | H22: NATURAL | J22: LastStubCurveIndex | K22: NATURAL | L22: NATURAL | N22: LastStubCurveIndex | P22: NATURAL
B23: isCleanPrice | C23: TRUE | D23: TRUE | F23: FirstFixing | H23: =SETTINGS!F6 -> 0.0129556 | J23: FirstFixing | K23: =SETTINGS!F6 -> 0.0129556 | L23: =SETTINGS!I6 -> 0.0171 | N23: FirstFixing | P23: =SETTINGS!I6 -> 0.0171
B24: FixedFrequency | C24: SEMI-ANNUAL | D24: SEMI-ANNUAL | F24: LastFixing | J24: LastFixing | N24: LastFixing
B25: FixedRate | C25: ='USD-BONDS'!$M$6 -> 0.032 | D25: ='AUD-BONDS'!$M$6 -> 0.0392 | F25: FloatSpread | G25: 0 | H25: 0 | J25: FloatSpread | K25: =G8 -> 370.97754 | L25: 0 | N25: FloatSpread | P25: =K8 -> 330.93586
B26: FixedDayCount | C26: 30E/360 | D26: 30E/360 | F26: EffectiveDate | G26: =C18 -> 43916 | H26: =C17 -> 44067 | J26: EffectiveDate | K26: =H26 -> 44067 | L26: =P26 -> 44067 | M26: * | N26: EffectiveDate | O26: =D18 -> 44027 | P26: =D17 -> 44067 | Q26: *
B27: FixedBusinessDayAdjustment | C27: NO_CHANGE | D27: MOD_FOLLOWING | F27: MaturityDate | G27: =$C$19 -> 45742 | H27: =$C$19 -> 45742 | J27: MaturityDate | K27: =$C$19 -> 45742 | L27: =$D$19 -> 46037 | N27: MaturityDate | O27: =$D$19 -> 46037 | P27: =$D$19 -> 46037
B28: FixedCalendar | C28: NYB | D28: SYB | F28: Frequency | G28: SEMI-ANNUAL | H28: QUARTERLY | J28: Frequency | K28: QUARTERLY | L28: QUARTERLY | N28: Frequency | O28: SEMI-ANNUAL | P28: QUARTERLY
B29: FixedFirstStubDate | F29: Daycount | G29: 30E/360 | H29: ACT/360 | J29: Daycount | K29: ACT/360 | L29: ACT/365 | N29: Daycount | O29: 30E/360 | P29: ACT/365
B30: FixedLastStubDate | F30: FixingBusinessDayAdjustment | G30: NO_CHANGE | H30: NO_CHANGE | J30: FixingBusinessDayAdjustment | K30: NO_CHANGE | L30: NO_CHANGE | N30: FixingBusinessDayAdjustment | O30: NO_CHANGE | P30: NO_CHANGE
B31: FixedRollDay | C31: NORMAL | D31: NORMAL | F31: FixingCalendar | G31: NYB | H31: NYB | J31: FixingCalendar | K31: NYB | L31: SYB | N31: FixingCalendar | O31: SYB | P31: SYB
B32: FixedStubType | C32: ShortStart | D32: ShortStart | F32: AccrualBusinessDayAdjustment | G32: NO_CHANGE | H32: NO_CHANGE | J32: AccrualBusinessDayAdjustment | K32: NO_CHANGE | L32: NO_CHANGE | N32: AccrualBusinessDayAdjustment | O32: NO_CHANGE | P32: NO_CHANGE
B33: FixedPaymentLag | C33: 0D | D33: 0D | F33: AccrualCalendar | G33: NYB | H33: NYB | J33: AccrualCalendar | K33: NYB | L33: SYB | N33: AccrualCalendar | O33: SYB | P33: SYB
F34: PaymentBusinessDayAdjustment | G34: NO_CHANGE | H34: NO_CHANGE | J34: PaymentBusinessDayAdjustment | K34: NO_CHANGE | L34: NO_CHANGE | N34: PaymentBusinessDayAdjustment | O34: NO_CHANGE | P34: NO_CHANGE
F35: PaymentCalendar | G35: NYB | H35: NYB | J35: PaymentCalendar | K35: NYB | L35: SYB | N35: PaymentCalendar | O35: SYB | P35: SYB
F36: FirstStubDate | J36: FirstStubDate | N36: FirstStubDate
F37: LastStubDate | J37: LastStubDate | N37: LastStubDate
F38: RollDay | G38: NORMAL | H38: NORMAL | J38: RollDay | K38: NORMAL | L38: NORMAL | N38: RollDay | O38: NORMAL | P38: NORMAL
F39: FixingLag | H39: 0D | J39: FixingLag | K39: 0D | L39: 0D | N39: FixingLag | P39: 0D
F40: FirstFixingLag | J40: FirstFixingLag | N40: FirstFixingLag
F41: PaymentLag | G41: 0D | H41: 0D | J41: PaymentLag | K41: 0D | L41: 0D | N41: PaymentLag | O41: 0D | P41: 0D
F42: StubType | G42: ShortStart | H42: ShortStart | J42: StubType | K42: ShortStart | L42: ShortStart | N42: StubType | O42: ShortStart | P42: ShortStart
...

Sheet EXAMPLE-XCCY-ASW-PX
B2: Uridashi Bond Price
B3: =K10 -> 101.03479 | F3: Create Asset Swap | G3: =_xll.meLWOXccySwapCreate(F13,F14:H46,F50:G52,TRUE) -> PROXY_XCCY_ASSET_SWAP@175:2 | J3: Create Asset Swap | K3: =_xll.meLWOSwapCreate(J13,J14:L46,FALSE) -> URIDASHI_ASSET_SWAP@204:4
G4: Leg1:FixedBond | H4: USDYC | J4: CurveCollection | K4: AUDYC
G5: Leg2:Float | H5: AUDYC | J5: ValuationDate | K5: =B10 -> 44067
G6: FXSPOT | H6: =SETTINGS!L5 -> 0.75
G7: ValuationDate | H7: =B10 -> 44067
G8: ValuationCurrency | H8: =G51 -> USD
B9: Valuation Date (for Accrued Int)
B10: =_xll.meDateFromTenor(TODAY(),"2D","MOD_FOLLOWING","SYB") -> 44067 | F10: Xccy Asset Swap Spread | G10: =_xll.meLWOAssetSwapSpreadFromPrice(G3,C15,B10,C25,G4:H8) -> 330.94196 | J10: Uridashi Price | K10: =_xll.meLWOAssetSwapSpreadToCleanPrice(K3,L27,J4:K5) -> 101.03479
B13: BOND SPECIFICATION | C13: Proxy Bond | D13: Uridashi Bond | F13: PROXY_XCCY_ASSET_SWAP | G13: Proxy Bond Leg | H13: AUD Funding | J13: URIDASHI_ASSET_SWAP
B14: ISIN | C14: USJ46186BC59 | D14: XS1344710857 | F14: LegType | G14: Leg1:FixedBond | H14: Leg2:Float | J14: LegType | K14: Leg1:FixedBond | L14: Leg2:Float
B15: BondPrice | C15: ='USD-BONDS'!B6 -> 96.021 | D15: =K10 -> 101.03479 | F15: Notional | G15: 1000000 | H15: =G15/H6 -> 1333333.3 | J15: Notional | K15: 1000000 | L15: 1000000
B16: Notional | C16: 1000000 | D16: 1000000 | F16: NotionalExchange | G16: END | H16: END | J16: NotionalExchange | K16: NONE | L16: NONE
B17: PayReceive | C17: PAYER | D17: PAYER | F17: PayReceive | G17: PAY | H17: REC | J17: PayReceive | K17: PAY | L17: REC
B18: IssueDate | C18: ='USD-BONDS'!$H$6 -> 42089 | D18: ='AUD-BONDS'!$H$6 -> 42566 | F18: ForecastCurve | H18: AUD3ML | J18: ForecastCurve | L18: AUD3ML
B19: EffectiveDate | C19: =_xll.meDateFromTenor(Settings.COB,"2D","MOD_FOLLOWING","NYB") -> 44067 | D19: =_xll.meDateFromTenor(Settings.COB,"2D","MOD_FOLLOWING","SYB") -> 44067 | F19: DiscountCurve | G19: USDOIS | H19: AUDDF_USDCSA | J19: DiscountCurve | K19: AUDOIS | L19: AUDOIS
B20: LastCouponDate | C20: =_xll.meLWOBondLastCouponDate('USD-BONDS'!D6,Settings.COB) -> 43916 | D20: =_xll.meLWOBondLastCouponDate('AUD-BONDS'!D6,Settings.COB) -> 44027 | F20: Currency | G20: USD | H20: AUD | J20: Currency | K20: AUD | L20: AUD
B21: MaturityDate | C21: ='USD-BONDS'!$L$6 -> 45742 | D21: ='AUD-BONDS'!$L$6 -> 46037 | F21: Leverage | G21: 1 | H21: 1 | J21: Leverage | K21: =H21 -> 1 | L21: 1
B22: CurveCollection | C22: USDYC | D22: AUDYC | F22: FixedRate | G22: =C27 -> 0.032 | J22: FixedRate | K22: =D27 -> 0.0392
B23: ForecastCurve | C23: USD3ML | D23: AUD6ML | F23: FirstStubCurveIndex | H23: NATURAL | J23: FirstStubCurveIndex | L23: NATURAL
B24: DiscountCurve | C24: USDOIS | D24: AUDOIS | F24: LastStubCurveIndex | H24: NATURAL | J24: LastStubCurveIndex | L24: NATURAL
B25: isCleanPrice | C25: TRUE | D25: TRUE | F25: FirstFixing | H25: =SETTINGS!I6 -> 0.0171 | J25: FirstFixing | L25: =SETTINGS!I6 -> 0.0171
B26: FixedFrequency | C26: SEMI-ANNUAL | D26: SEMI-ANNUAL | F26: LastFixing | J26: LastFixing
B27: FixedRate | C27: ='USD-BONDS'!$M$6 -> 0.032 | D27: ='AUD-BONDS'!$M$6 -> 0.0392 | F27: FloatSpread | G27: 0 | H27: 0 | J27: FloatSpread | L27: =G10 -> 330.94196
B28: FixedDayCount | C28: 30E/360 | D28: 30E/360 | F28: EffectiveDate | G28: =C20 -> 43916 | H28: =C19 -> 44067 | I28: * | J28: EffectiveDate | K28: =D20 -> 44027 | L28: =D19 -> 44067 | M28: *
B29: FixedBusinessDayAdjustment | C29: NO_CHANGE | D29: MOD_FOLLOWING | F29: MaturityDate | G29: =$C$21 -> 45742 | H29: =L29 -> 46037 | J29: MaturityDate | K29: =$D$21 -> 46037 | L29: =K29 -> 46037
B30: FixedCalendar | C30: NYB | D30: SYB | F30: Frequency | G30: SEMI-ANNUAL | H30: QUARTERLY | J30: Frequency | K30: SEMI-ANNUAL | L30: QUARTERLY
B31: FixedFirstStubDate | F31: Daycount | G31: 30E/360 | H31: ACT/365 | J31: Daycount | K31: 30E/360 | L31: ACT/365
B32: FixedLastStubDate | F32: FixingBusinessDayAdjustment | G32: NO_CHANGE | H32: NO_CHANGE | J32: FixingBusinessDayAdjustment | K32: NO_CHANGE | L32: NO_CHANGE
B33: FixedRollDay | C33: NORMAL | D33: NORMAL | F33: FixingCalendar | G33: NYB | H33: SYB | J33: FixingCalendar | K33: SYB | L33: SYB
B34: FixedStubType | C34: ShortStart | D34: ShortStart | F34: AccrualBusinessDayAdjustment | G34: NO_CHANGE | H34: NO_CHANGE | J34: AccrualBusinessDayAdjustment | K34: NO_CHANGE | L34: NO_CHANGE
B35: FixedPaymentLag | C35: 0D | D35: 0D | F35: AccrualCalendar | G35: NYB | H35: SYB | J35: AccrualCalendar | K35: SYB | L35: SYB
B36: CalculationType | C36: Type1 | F36: PaymentBusinessDayAdjustment | G36: NO_CHANGE | H36: NO_CHANGE | J36: PaymentBusinessDayAdjustment | K36: NO_CHANGE | L36: NO_CHANGE
F37: PaymentCalendar | G37: NYB | H37: SYB | J37: PaymentCalendar | K37: SYB | L37: SYB
F38: FirstStubDate | J38: FirstStubDate
F39: LastStubDate | J39: LastStubDate
F40: RollDay | G40: NORMAL | H40: NORMAL | J40: RollDay | K40: NORMAL | L40: NORMAL
F41: FixingLag | H41: 0D | J41: FixingLag | L41: 0D
F42: FirstFixingLag | J42: FirstFixingLag
F43: PaymentLag | G43: 0D | H43: 0D | J43: PaymentLag | K43: 0D | L43: 0D
...

Sheet AUD-URIDASHI-PX
BT1: USD_ASW | BZ1: VALUATION SETTINGS | CC1: XCCY SETTINGS | EI1: XCCY_SWAP | HE1: AUD_ASW
E2: =E8 -> 370.96728 | BZ2: Leg1:Float | CA2: USDYC | CC2: MTM | CD2: FALSE
B3: USD BOND PROXY | D3: SETTLEMENT DATE (NYB) | G3: USD ASSET SWAP | J3: CURVE COLLECTION | AN3: USD ASSET SWAP | BU3: USD/AUD XCCY SWAP | BX3: USD/AUD XCCY SWAP | BZ3: Leg2:Float | CA3: AUDYC | CC3: ValuationCurrency | CD3: USD | DD3: USD/AUD XCCY SWAP | EJ3: AUD URIDASHI BOND | EK3: SETTLEMENT DATE (SYB) | EN3: BOND CALCULATIONS | ET3: AUD ASSET SWAP | EW3: CURVE COLLECTION | FZ3: AUD ASSET SWAP | HF3: BOND CASHFLOWS | HH3: SELECT BOND | HQ3: BOND INDEX
D4: =_xll.meDateFromTenor(Settings.COB,"2D","MOD_FOLLOWING","NYB") -> 44067 | J4: CurveCollection | K4: USDYC | BZ4: FXSPOT | CA4: =CD4 -> 0.75 | CC4: FxRate | CD4: =SETTINGS!$L$5 -> 0.75 | CE4: AUDUSD | EK4: =_xll.meDateFromTenor(Settings.COB,"2D","MOD_FOLLOWING","SYB") -> 44067 | EW4: AUDYC | HH4: XS1447583664 | HQ4: =MATCH(HH4,'AUD-BONDS'!$F$6:$F$32,0) -> 2
G5: PROXY BOND LEG (FIXED) | J5: ValuationDate | K5: =D4 -> 44067 | AN5: FUNDING LEG (FLOAT) | BZ5: ValuationDate | CA5: ='EXAMPLE-XCCY-ASW-PX'!B10 -> 44067 | CC5: NotionalFxResetLeg | ET5: PROXY BOND LEG (FIXED) | FZ5: FUNDING LEG (FLOAT)
BX6: USD FUNDING LEG | BZ6: ValuationCurrency | CA6: =BZ49 -> 0 | DD6: AUD FUNDING LEG
B7: ISIN | C7: PROXY PRICE | D7: USD_ASW | E7: USD_ASW_SPREAD | G7: LegType | H7: Notional | I7: NotionalExchange | J7: PayReceive | K7: ForecastCurve | L7: DiscountCurve | M7: Currency | N7: Leverage | O7: FixedRate | P7: FirstStubCurveIndex | Q7: LastStubCurveIndex | R7: FirstFixing | S7: LastFixing | T7: FloatSpread | U7: EffectiveDate | V7: MaturityDate | W7: Frequency | X7: Daycount | Y7: FixingBusinessDayAdjustment | Z7: FixingCalendar | AA7: AccrualBusinessDayAdjustment | AB7: AccrualCalendar | AC7: PaymentBusinessDayAdjustment | AD7: PaymentCalendar | AE7: FirstStubDate | AF7: LastStubDate | AG7: RollDay | AH7: FixingLag | AI7: FirstFixingLag | AJ7: PaymentLag | AK7: CalculationType | AL7: StubType | AN7: LegType | AO7: Notional | AP7: NotionalExchange | AQ7: PayReceive | AR7: ForecastCurve | AS7: DiscountCurve | AT7: Currency | AU7: Leverage | AV7: FixedRate | AW7: FirstStubCurveIndex | AX7: LastStubCurveIndex | AY7: FirstFixing | AZ7: LastFixing | BA7: FloatSpread | BB7: EffectiveDate | BC7: MaturityDate | BD7: Frequency | BE7: Daycount | BF7: FixingBusinessDayAdjustment | BG7: FixingCalendar | BH7: AccrualBusinessDayAdjustment | BI7: AccrualCalendar | BJ7: PaymentBusinessDayAdjustment | BK7: PaymentCalendar | BL7: FirstStubDate | BM7: LastStubDate | BN7: RollDay | BO7: FixingLag | BP7: FirstFixingLag | BQ7: PaymentLag | BR7: CalculationType | BS7: StubType | BU7: XCCY_SWAP | BV7: XCCY_PAR_SPREAD | BW7: 1 | BX7: LegType | BY7: Notional | BZ7: NotionalExchange | CA7: PayReceive | CB7: ForecastCurve | CC7: DiscountCurve | CD7: Currency | CE7: Leverage | CF7: FixedRate | CG7: FirstStubCurveIndex | CH7: LastStubCurveIndex | CI7: FirstFixing | CJ7: LastFixing | CK7: FloatSpread | CL7: EffectiveDate | CM7: MaturityDate | CN7: Frequency | CO7: Daycount | CP7: FixingBusinessDayAdjustment | CQ7: FixingCalendar | CR7: AccrualBusinessDayAdjustment | CS7: AccrualCalendar | CT7: PaymentBusinessDayAdjustment | CU7: PaymentCalendar | CV7: FirstStubDate | CW7: LastStubDate | CX7: RollDay | CY7: FixingLag | CZ7: FirstFixingLag | DA7: PaymentLag | DB7: StubType | DC7: 1 | DD7: LegType | DE7: Notional | DF7: NotionalExchange | DG7: PayReceive | DH7: ForecastCurve | DI7: DiscountCurve | DJ7: Currency | DK7: Leverage | DL7: FixedRate | DM7: FirstStubCurveIndex | DN7: LastStubCurveIndex | DO7: FirstFixing | DP7: LastFixing | DQ7: FloatSpread | DR7: EffectiveDate | DS7: MaturityDate | DT7: Frequency | DU7: Daycount | DV7: FixingBusinessDayAdjustment | DW7: FixingCalendar | DX7: AccrualBusinessDayAdjustment | DY7: AccrualCalendar | DZ7: PaymentBusinessDayAdjustment | EA7: PaymentCalendar | EB7: FirstStubDate | EC7: LastStubDate | ED7: RollDay | EE7: FixingLag | EF7: FirstFixingLag | EG7: PaymentLag | EH7: StubType | EJ7: ISIN | EK7: AUD_ASW | EL7: URISASHI PRICE | EN7: YIELD | EO7: CLEAN PX | EP7: DIRTY PX | EQ7: ACCRUED INT | ER7: ACCRUED DAYS | ET7: LegType | EU7: Notional | EV7: NotionalExchange | EW7: PayReceive | EX7: ForecastCurve | EY7: DiscountCurve | EZ7: Currency | FA7: Leverage | FB7: FixedRate | FC7: FirstStubCurveIndex | FD7: LastStubCurveIndex | FE7: FirstFixing | FF7: LastFixing | FG7: FloatSpread | FH7: EffectiveDate | FI7: MaturityDate | FJ7: Frequency | FK7: Daycount | FL7: FixingBusinessDayAdjustment | FM7: FixingCalendar | FN7: AccrualBusinessDayAdjustment | FO7: AccrualCalendar | FP7: PaymentBusinessDayAdjustment | FQ7: PaymentCalendar | FR7: FirstStubDate | FS7: LastStubDate | FT7: RollDay | FU7: FixingLag | FV7: FirstFixingLag | FW7: PaymentLag | FX7: StubType | FZ7: LegType | GA7: Notional | GB7: NotionalExchange | GC7: PayReceive | GD7: ForecastCurve | GE7: DiscountCurve | GF7: Currency | GG7: Leverage | GH7: FixedRate | GI7: FirstStubCurveIndex | GJ7: LastStubCurveIndex | GK7: FirstFixing | GL7: LastFixing | GM7: FloatSpread | GN7: EffectiveDate | GO7: MaturityDate | GP7: Frequency | GQ7: Daycount | GR7: FixingBusinessDayAdjustment | GS7: FixingCalendar | GT7: AccrualBusinessDayAdjustment | GU7: AccrualCalendar | GV7: PaymentBusinessDayAdjustment | GW7: PaymentCalendar | GX7: FirstStubDate | GY7: LastStubDate | GZ7: RollDay | HA7: FixingLag | HB7: FirstFixingLag | HC7: PaymentLag | HD7: StubType | HF7: {=_xll.meUtilityResize(_xll.meLWOBondDisplayCashflows(OFFSET('AUD-BONDS'!$D6,$HQ$4-1,0),$EK$4,OFFSET(EN$8,$HQ$4-1,0)),100,100)} -> #Error: No range or empty range specified | HG7: #Error: No range or empty range specified | HH7: #Error: No range or empty range specified | HI7: #Error: No range or empty range specified | HJ7: #Error: No range or empty range specified | HK7: #Error: No range or empty range specified | HL7: #Error: No range or empty range specified | HM7: #Error: No range or empty range specified | HN7: #Error: No range or empty range specified | HO7: #Error: No range or empty range specified | HP7: #Error: No range or empty range specified | HQ7: #Error: No range or empty range specified
A8: 1 | B8: ='USD-BONDS'!F6 -> USJ46186BC59 | C8: ='USD-BONDS'!B6 -> 96.021 | D8: =_xll.meLWOSwapCreate($D$7&"_"&B8,_xll.meUtilityLVBFromKeysAndMultipleValues($G$7:$AL$7,G8:AL8,AN8:BS8)) -> USD_ASW_USJ46186BC59@172:6 | E8: =_xll.meLWOAssetSwapSpread(D8,'USD-BONDS'!D6,C8,$J$4:$K$5) -> 370.96728 | F8: 1 | G8: Leg1:FixedBond | H8: 1000000 | I8: NONE | J8: PAY | L8: USDOIS | M8: USD | N8: 1 | O8: ='USD-BONDS'!M6 -> 0.032 | U8: =_xll.meLWOBondLastCouponDate('USD-BONDS'!D6,Settings.COB) -> 43916 | V8: ='USD-BONDS'!L6 -> 45742 | W8: ='USD-BONDS'!O6 -> SEMI-ANNUAL | X8: ='USD-BONDS'!N6 -> 30E/360 | Y8: NO_CHANGE | Z8: NYB | AA8: NO_CHANGE | AB8: NYB | AC8: NO_CHANGE | AD8: NYB | AG8: NORMAL | AJ8: 0D | AK8: TYPE1 | AL8: ShortStart | AM8: 1 | AN8: Leg2:Float | AO8: 1000000 | AP8: NONE | AQ8: REC | AR8: USD3ML | AS8: USDOIS | AT8: USD | AU8: 1 | AW8: NATURAL | AX8: NATURAL | AY8: =SETTINGS!$F$6 -> 0.0129556 | BA8: 0 | BB8: =_xll.meLWOBondLastCouponDate('USD-BONDS'!D6,Settings.COB) -> 43916 | BC8: ='USD-BONDS'!L6 -> 45742 | BD8: QUARTERLY | BE8: ACT/360 | BF8: NO_CHANGE | BG8: NYB | BH8: NO_CHANGE | BI8: NYB | BJ8: NO_CHANGE | BK8: NYB | BN8: NORMAL | BO8: 0D | BQ8: 0D | BS8: ShortStart | BT8: 1 | BU8: =_xll.meLWOXccySwapCreate($BU$7&"_"&B8,_xll.meUtilityLVBFromKeysAndMultipleValues($BX$7:$DB$7,BX8:DB8,DD8:EH8),$CC$2:$CD$5) -> XCCY_SWAP_USJ46186BC59@176:6 | BV8: =_xll.meLWOXccySwapParSpread(BU8,$BZ$2:$CA$6,,$BZ$3) -> 335.8653 | BW8: =BW7+1 -> 2 | BX8: Leg1:Float | BY8: 1000000 | BZ8: START_AND_END | CA8: PAY | CB8: USD3ML | CC8: USDOIS | CD8: USD | CE8: 1 | CG8: NATURAL | CH8: NATURAL | CI8: =SETTINGS!$F$6 -> 0.0129556 | CK8: =$E8 -> 370.96728 | CL8: =_xll.meLWOBondLastCouponDate('USD-BONDS'!D6,Settings.COB) -> 43916 | CM8: ='USD-BONDS'!L6 -> 45742 | CN8: QUARTERLY | CO8: ACT/360 | CP8: NO_CHANGE | CQ8: NYB | CR8: NO_CHANGE | CS8: NYB | CT8: NO_CHANGE | CU8: NYB | CX8: NORMAL | CY8: 0D | DA8: 0D | DB8: ShortStart | DC8: =DC7+1 -> 2 | DD8: Leg2:Float | DE8: =BY8/$CD$4 -> 1333333.3 | DF8: START_AND_END | DG8: REC | DH8: AUD3ML | DI8: AUDDF_USDCSA | DJ8: AUD | DK8: 1 | DM8: NATURAL | DN8: NATURAL | DO8: =SETTINGS!$I$6 -> 0.0171 | DQ8: 0 | DR8: =_xll.meLWOBondLastCouponDate('AUD-BONDS'!D6,Settings.COB) -> 44027 | DS8: ='AUD-BONDS'!L6 -> 46037 | DT8: QUARTERLY | DU8: ACT/365 | DV8: NO_CHANGE | DW8: SYB | DX8: NO_CHANGE | DY8: SYB | DZ8: NO_CHANGE | EA8: SYB | ED8: NORMAL | EE8: 0D | EG8: 0D | EH8: ShortStart | EI8: 1 | EJ8: ='AUD-BONDS'!F6 -> XS1344710857 | EK8: =_xll.meLWOSwapCreate($EK$7&"_"&EJ8,_xll.meUtilityLVBFromKeysAndMultipleValues($ET$7:$FX$7,ET8:FX8,FZ8:HD8)) -> #Error: Missing key 'CALCULATIONTYPE'. This key is mandatory and must be included in the Label Value Block , 'scheduleLVB'. | EL8: =_xll.meLWOAssetSwapSpreadToCleanPrice($EK8,$EK$4,$BV8,$EW$4) -> #Error: Swap #ERROR does not exist | EM8: 1 | EN8: =_xll.meLWOBondYield('AUD-BONDS'!D6,$EK$4,$EL8) -> #Error: Invalid input, numerical input required | EO8: =_xll.meLWOBondCleanPrice('AUD-BONDS'!$D6,$EK$4,$EN8) -> #Error: Invalid Vector Data: Input Contains Errors | EP8: =_xll.meLWOBondDirtyPrice('AUD-BONDS'!$D6,$EK$4,$EN8) -> #Error: Invalid Vector Data: Input Contains Errors | EQ8: =_xll.meLWOBondAccruedInterest('AUD-BONDS'!$D6,'AUD-URIDASHI-PX'!$EK$4) -> 4250 | ER8: =_xll.meLWOBondAccruedInterestDays('AUD-BONDS'!$D6,'AUD-URIDASHI-PX'!$EK$4) -> 39 | ES8: 1 | ET8: Leg1:FixedBond | EU8: =$DE8 -> 1333333.3 | EV8: NONE | EW8: PAY | EY8: AUDOIS | EZ8: AUD | FA8: 1 | FB8: ='AUD-BONDS'!M6 -> 0.0392 | FH8: =_xll.meLWOBondLastCouponDate('AUD-BONDS'!D6,Settings.COB) -> 44027 | FI8: ='AUD-BONDS'!L6 -> 46037 | FJ8: ='AUD-BONDS'!O6 -> SEMI-ANNUAL | FK8: ='AUD-BONDS'!N6 -> 30E/360 | FL8: NO_CHANGE | FM8: NYB | FN8: NO_CHANGE | FO8: NYB | FP8: NO_CHANGE | FQ8: NYB | FT8: NORMAL | FW8: 0D | FX8: ShortStart | FY8: 1 | FZ8: Leg2:Float | GA8: =$DE8 -> 1333333.3 | GB8: NONE | GC8: REC | GD8: AUD3ML | GE8: AUDOIS | GF8: AUD | GG8: 1 | GI8: NATURAL | GJ8: NATURAL | GK8: =SETTINGS!$I$6 -> 0.0171 | GM8: =$BV8 -> 335.8653 | GN8: =_xll.meLWOBondLastCouponDate('AUD-BONDS'!D6,Settings.COB) -> 44027 | GO8: ='AUD-BONDS'!L6 -> 46037 | GP8: QUARTERLY | GQ8: ACT/360 | GR8: NO_CHANGE | GS8: SYB | GT8: NO_CHANGE | GU8: SYB | GV8: NO_CHANGE | GW8: SYB | GZ8: NORMAL | HA8: 0D | HC8: 0D | HD8: ShortStart | HF8: #Error: No range or empty range specified | HG8: #Error: No range or empty range specified | HH8: #Error: No range or empty range specified | HI8: #Error: No range or empty range specified | HJ8: #Error: No range or empty range specified | HK8: #Error: No range or empty range specified | HL8: #Error: No range or empty range specified | HM8: #Error: No range or empty range specified | HN8: #Error: No range or empty range specified | HO8: #Error: No range or empty range specified | HP8: #Error: No range or empty range specified | HQ8: #Error: No range or empty range specified
A9: =A8+1 -> 2 | B9: ='USD-BONDS'!F7 -> XS1447582930 | C9: ='USD-BONDS'!B7 -> 94.55 | D9: =_xll.meLWOSwapCreate($D$7&"_"&B9,_xll.meUtilityLVBFromKeysAndMultipleValues($G$7:$AL$7,G9:AL9,AN9:BS9)) -> USD_ASW_XS1447582930@153:6 | E9: =_xll.meLWOAssetSwapSpread(D9,'USD-BONDS'!D7,C9,$J$4:$K$5) -> 698.9286 | F9: =F8+1 -> 2 | G9: Leg1:FixedBond | H9: 1000000 | I9: NONE | J9: PAY | L9: USDOIS | M9: USD | N9: 1 | O9: ='USD-BONDS'!M7 -> 0.0161 | U9: =_xll.meLWOBondLastCouponDate('USD-BONDS'!D7,Settings.COB) -> 44039 | V9: ='USD-BONDS'!L7 -> 44404 | W9: ='USD-BONDS'!O7 -> SEMI-ANNUAL | X9: ='USD-BONDS'!N7 -> 30E/360 | Y9: NO_CHANGE | Z9: NYB | AA9: NO_CHANGE | AB9: NYB | AC9: NO_CHANGE | AD9: NYB | AG9: NORMAL | AJ9: 0D | AK9: TYPE1 | AL9: ShortStart | AM9: =AM8+1 -> 2 | AN9: Leg2:Float | AO9: 1000000 | AP9: NONE | AQ9: REC | AR9: USD3ML | AS9: USDOIS | AT9: USD | AU9: 1 | AW9: NATURAL | AX9: NATURAL | AY9: =SETTINGS!$F$6 -> 0.0129556 | BA9: 0 | BB9: =_xll.meLWOBondLastCouponDate('USD-BONDS'!D7,Settings.COB) -> 44039 | BC9: ='USD-BONDS'!L7 -> 44404 | BD9: QUARTERLY | BE9: ACT/360 | BF9: NO_CHANGE | BG9: NYB | BH9: NO_CHANGE | BI9: NYB | BJ9: NO_CHANGE | BK9: NYB | BN9: NORMAL | BO9: 0D | BQ9: 0D | BS9: ShortStart | BT9: =BT8+1 -> 2 | BU9: =_xll.meLWOXccySwapCreate($BU$7&"_"&B9,_xll.meUtilityLVBFromKeysAndMultipleValues($BX$7:$DB$7,BX9:DB9,DD9:EH9),$CC$2:$CD$5) -> XCCY_SWAP_XS1447582930@199:6 | BV9: =_xll.meLWOXccySwapParSpread(BU9,$BZ$2:$CA$6,,$BZ$3) -> 703.51586 | BW9: =BW8+1 -> 3 | BX9: Leg1:Float | BY9: 1000000 | BZ9: START_AND_END | CA9: PAY | CB9: USD3ML | CC9: USDOIS | CD9: USD | CE9: 1 | CG9: NATURAL | CH9: NATURAL | CI9: =SETTINGS!$F$6 -> 0.0129556 | CK9: =$E9 -> 698.9286 | CL9: =_xll.meLWOBondLastCouponDate('USD-BONDS'!D7,Settings.COB) -> 44039 | CM9: ='USD-BONDS'!L7 -> 44404 | CN9: QUARTERLY | CO9: ACT/360 | CP9: NO_CHANGE | CQ9: NYB | CR9: NO_CHANGE | CS9: NYB | CT9: NO_CHANGE | CU9: NYB | CX9: NORMAL | CY9: 0D | DA9: 0D | DB9: ShortStart | DC9: =DC8+1 -> 3 | DD9: Leg2:Float | DE9: =BY9/$CD$4 -> 1333333.3 | DF9: START_AND_END | DG9: REC | DH9: AUD3ML | DI9: AUDDF_USDCSA | DJ9: AUD | DK9: 1 | DM9: NATURAL | DN9: NATURAL | DO9: =SETTINGS!$I$6 -> 0.0171 | DQ9: 0 | DR9: =_xll.meLWOBondLastCouponDate('AUD-BONDS'!D7,Settings.COB) -> 44039 | DS9: ='AUD-BONDS'!L7 -> 44404 | DT9: QUARTERLY | DU9: ACT/365 | DV9: NO_CHANGE | DW9: SYB | DX9: NO_CHANGE | DY9: SYB | DZ9: NO_CHANGE | EA9: SYB | ED9: NORMAL | EE9: 0D | EG9: 0D | EH9: ShortStart | EI9: =EI8+1 -> 2 | EJ9: ='AUD-BONDS'!F7 -> XS1447583664 | EK9: =_xll.meLWOSwapCreate($EK$7&"_"&EJ9,_xll.meUtilityLVBFromKeysAndMultipleValues($ET$7:$FX$7,ET9:FX9,FZ9:HD9)) -> #Error: Missing key 'CALCULATIONTYPE'. This key is mandatory and must be included in the Label Value Block , 'scheduleLVB'. | EL9: =_xll.meLWOAssetSwapSpreadToCleanPrice($EK9,$EK$4,$BV9,$EW$4) -> #Error: Swap #ERROR does not exist | EM9: =EM8+1 -> 2 | EN9: =_xll.meLWOBondYield('AUD-BONDS'!D7,$EK$4,$EL9) -> #Error: Invalid input, numerical input required | EO9: =_xll.meLWOBondCleanPrice('AUD-BONDS'!$D7,$EK$4,$EN9) -> #Error: Invalid Vector Data: Input Contains Errors | EP9: =_xll.meLWOBondDirtyPrice('AUD-BONDS'!$D7,$EK$4,$EN9) -> #Error: Invalid Vector Data: Input Contains Errors | EQ9: =_xll.meLWOBondAccruedInterest('AUD-BONDS'!$D7,'AUD-URIDASHI-PX'!$EK$4) -> 1970 | ER9: =_xll.meLWOBondAccruedInterestDays('AUD-BONDS'!$D7,'AUD-URIDASHI-PX'!$EK$4) -> 27 | ES9: =ES8+1 -> 2 | ET9: Leg1:FixedBond | EU9: =$DE9 -> 1333333.3 | EV9: NONE | EW9: PAY | EY9: AUDOIS | EZ9: AUD | FA9: 1 | FB9: ='AUD-BONDS'!M7 -> 0.0262 | FH9: =_xll.meLWOBondLastCouponDate('AUD-BONDS'!D7,Settings.COB) -> 44039 | FI9: ='AUD-BONDS'!L7 -> 44404 | FJ9: ='AUD-BONDS'!O7 -> SEMI-ANNUAL | FK9: ='AUD-BONDS'!N7 -> 30E/360 | FL9: NO_CHANGE | FM9: NYB | FN9: NO_CHANGE | FO9: NYB | FP9: NO_CHANGE | FQ9: NYB | FT9: NORMAL | FW9: 0D | FX9: ShortStart | FY9: =FY8+1 -> 2 | FZ9: Leg2:Float | GA9: =$DE9 -> 1333333.3 | GB9: NONE | GC9: REC | GD9: AUD3ML | GE9: AUDOIS | GF9: AUD | GG9: 1 | GI9: NATURAL | GJ9: NATURAL | GK9: =SETTINGS!$I$6 -> 0.0171 | GM9: =$BV9 -> 703.51586 | GN9: =_xll.meLWOBondLastCouponDate('AUD-BONDS'!D7,Settings.COB) -> 44039 | GO9: ='AUD-BONDS'!L7 -> 44404 | GP9: QUARTERLY | GQ9: ACT/360 | GR9: NO_CHANGE | GS9: SYB | GT9: NO_CHANGE | GU9: SYB | GV9: NO_CHANGE | GW9: SYB | GZ9: NORMAL | HA9: 0D | HC9: 0D | HD9: ShortStart | HF9: #Error: No range or empty range specified | HG9: #Error: No range or empty range specified | HH9: #Error: No range or empty range specified | HI9: #Error: No range or empty range specified | HJ9: #Error: No range or empty range specified | HK9: #Error: No range or empty range specified | HL9: #Error: No range or empty range specified | HM9: #Error: No range or empty range specified | HN9: #Error: No range or empty range specified | HO9: #Error: No range or empty range specified | HP9: #Error: No range or empty range specified | HQ9: #Error: No range or empty range specified
A10: =A9+1 -> 3 | B10: ='USD-BONDS'!F8 -> ISIN2 | C10: ='USD-BONDS'!B8 -> 100 | D10: =_xll.meLWOSwapCreate($D$7&"_"&B10,_xll.meUtilityLVBFromKeysAndMultipleValues($G$7:$AL$7,G10:AL10,AN10:BS10)) -> USD_ASW_ISIN2@152:6 | E10: =_xll.meLWOAssetSwapSpread(D10,'USD-BONDS'!D8,C10,$J$4:$K$5) -> 285.35446 | F10: =F9+1 -> 3 | G10: Leg1:FixedBond | H10: 1000000 | I10: NONE | J10: PAY | L10: USDOIS | M10: USD | N10: 1 | O10: ='USD-BONDS'!M8 -> 0.032 | U10: =_xll.meLWOBondLastCouponDate('USD-BONDS'!D8,Settings.COB) -> 43916 | V10: ='USD-BONDS'!L8 -> 45742 | W10: ='USD-BONDS'!O8 -> SEMI-ANNUAL | X10: ='USD-BONDS'!N8 -> 30E/360 | Y10: NO_CHANGE | Z10: NYB | AA10: NO_CHANGE | AB10: NYB | AC10: NO_CHANGE | AD10: NYB | AG10: NORMAL | AJ10: 0D | AK10: TYPE1 | AL10: ShortStart | AM10: =AM9+1 -> 3 | AN10: Leg2:Float | AO10: 1000000 | AP10: NONE | AQ10: REC | AR10: USD3ML | AS10: USDOIS | AT10: USD | AU10: 1 | AW10: NATURAL | AX10: NATURAL | AY10: =SETTINGS!$F$6 -> 0.0129556 | BA10: 0 | BB10: =_xll.meLWOBondLastCouponDate('USD-BONDS'!D8,Settings.COB) -> 43916 | BC10: ='USD-BONDS'!L8 -> 45742 | BD10: QUARTERLY | BE10: ACT/360 | BF10: NO_CHANGE | BG10: NYB | BH10: NO_CHANGE | BI10: NYB | BJ10: NO_CHANGE | BK10: NYB | BN10: NORMAL | BO10: 0D | BQ10: 0D | BS10: ShortStart | BT10: =BT9+1 -> 3 | BU10: =_xll.meLWOXccySwapCreate($BU$7&"_"&B10,_xll.meUtilityLVBFromKeysAndMultipleValues($BX$7:$DB$7,BX10:DB10,DD10:EH10),$CC$2:$CD$5) -> XCCY_SWAP_ISIN2@185:6 | BV10: =_xll.meLWOXccySwapParSpread(BU10,$BZ$2:$CA$6,,$BZ$3) -> 260.66732 | BW10: =BW9+1 -> 4 | BX10: Leg1:Float | BY10: 1000000 | BZ10: START_AND_END | CA10: PAY | CB10: USD3ML | CC10: USDOIS | CD10: USD | CE10: 1 | CG10: NATURAL | CH10: NATURAL | CI10: =SETTINGS!$F$6 -> 0.0129556 | CK10: =$E10 -> 285.35446 | CL10: =_xll.meLWOBondLastCouponDate('USD-BONDS'!D8,Settings.COB) -> 43916 | CM10: ='USD-BONDS'!L8 -> 45742 | CN10: QUARTERLY | CO10: ACT/360 | CP10: NO_CHANGE | CQ10: NYB | CR10: NO_CHANGE | CS10: NYB | CT10: NO_CHANGE | CU10: NYB | CX10: NORMAL | CY10: 0D | DA10: 0D | DB10: ShortStart | DC10: =DC9+1 -> 4 | DD10: Leg2:Float | DE10: =BY10/$CD$4 -> 1333333.3 | DF10: START_AND_END | DG10: REC | DH10: AUD3ML | DI10: AUDDF_USDCSA | DJ10: AUD | DK10: 1 | DM10: NATURAL | DN10: NATURAL | DO10: =SETTINGS!$I$6 -> 0.0171 | DQ10: 0 | DR10: =_xll.meLWOBondLastCouponDate('AUD-BONDS'!D8,Settings.COB) -> 44027 | DS10: ='AUD-BONDS'!L8 -> 46037 | DT10: QUARTERLY | DU10: ACT/365 | DV10: NO_CHANGE | DW10: SYB | DX10: NO_CHANGE | DY10: SYB | DZ10: NO_CHANGE | EA10: SYB | ED10: NORMAL | EE10: 0D | EG10: 0D | EH10: ShortStart | EI10: =EI9+1 -> 3 | EJ10: ='AUD-BONDS'!F8 -> ISIN2 | EK10: =_xll.meLWOSwapCreate($EK$7&"_"&EJ10,_xll.meUtilityLVBFromKeysAndMultipleValues($ET$7:$FX$7,ET10:FX10,FZ10:HD10)) -> #Error: Missing key 'CALCULATIONTYPE'. This key is mandatory and must be included in the Label Value Block , 'scheduleLVB'. | EL10: =_xll.meLWOAssetSwapSpreadToCleanPrice($EK10,$EK$4,$BV10,$EW$4) -> #Error: Swap #ERROR does not exist | EM10: =EM9+1 -> 3 | EN10: =_xll.meLWOBondYield('AUD-BONDS'!D8,$EK$4,$EL10) -> #Error: Invalid input, numerical input required | EO10: =_xll.meLWOBondCleanPrice('AUD-BONDS'!$D8,$EK$4,$EN10) -> #Error: Invalid Vector Data: Input Contains Errors | EP10: =_xll.meLWOBondDirtyPrice('AUD-BONDS'!$D8,$EK$4,$EN10) -> #Error: Invalid Vector Data: Input Contains Errors | EQ10: =_xll.meLWOBondAccruedInterest('AUD-BONDS'!$D8,'AUD-URIDASHI-PX'!$EK$4) -> 4250 | ER10: =_xll.meLWOBondAccruedInterestDays('AUD-BONDS'!$D8,'AUD-URIDASHI-PX'!$EK$4) -> 39 | ES10: =ES9+1 -> 3 | ET10: Leg1:FixedBond | EU10: =$DE10 -> 1333333.3 | EV10: NONE | EW10: PAY | EY10: AUDOIS | EZ10: AUD | FA10: 1 | FB10: ='AUD-BONDS'!M8 -> 0.0392 | FH10: =_xll.meLWOBondLastCouponDate('AUD-BONDS'!D8,Settings.COB) -> 44027 | FI10: ='AUD-BONDS'!L8 -> 46037 | FJ10: ='AUD-BONDS'!O8 -> SEMI-ANNUAL | FK10: ='AUD-BONDS'!N8 -> 30E/360 | FL10: NO_CHANGE | FM10: NYB | FN10: NO_CHANGE | FO10: NYB | FP10: NO_CHANGE | FQ10: NYB | FT10: NORMAL | FW10: 0D | FX10: ShortStart | FY10: =FY9+1 -> 3 | FZ10: Leg2:Float | GA10: =$DE10 -> 1333333.3 | GB10: NONE | GC10: REC | GD10: AUD3ML | GE10: AUDOIS | GF10: AUD | GG10: 1 | GI10: NATURAL | GJ10: NATURAL | GK10: =SETTINGS!$I$6 -> 0.0171 | GM10: =$BV10 -> 260.66732 | GN10: =_xll.meLWOBondLastCouponDate('AUD-BONDS'!D8,Settings.COB) -> 44027 | GO10: ='AUD-BONDS'!L8 -> 46037 | GP10: QUARTERLY | GQ10: ACT/360 | GR10: NO_CHANGE | GS10: SYB | GT10: NO_CHANGE | GU10: SYB | GV10: NO_CHANGE | GW10: SYB | GZ10: NORMAL | HA10: 0D | HC10: 0D | HD10: ShortStart | HF10: #Error: No range or empty range specified | HG10: #Error: No range or empty range specified | HH10: #Error: No range or empty range specified | HI10: #Error: No range or empty range specified | HJ10: #Error: No range or empty range specified | HK10: #Error: No range or empty range specified | HL10: #Error: No range or empty range specified | HM10: #Error: No range or empty range specified | HN10: #Error: No range or empty range specified | HO10: #Error: No range or empty range specified | HP10: #Error: No range or empty range specified | HQ10: #Error: No range or empty range specified
