Workbook
Name CDS_MKT_DATA: 'CREDIT MKT DATA'!$E$18:$J$25
Name CDS_SELECTION: 'CREDIT MKT DATA'!$E$18:$E$25
Name CREDIT_MODEL: 'CREDIT MODEL'!$C$4
Name CURRENT_IMM_DATE: 'CREDIT MODEL'!$C$14
Name EUR_CDS: EUR_TRADE_TEMPLATES!$C$4
Name EUR_CLN: EUR_TRADE_TEMPLATES!$G$4
Name EUR_CURVE: 'EUR OIS'!$D$28
Name Settings.COB: SETTINGS!$C$2
Name XccyStructure.CSA3: CUSTOM_STRUCTURE!$I$20
Name XccyStructure.Fee.Amount3: CUSTOM_STRUCTURE!$J$26
Name XccyStructure.Fee.Ccy3: CUSTOM_STRUCTURE!$J$24
Name XccyStructure.Fee.PayDate3: CUSTOM_STRUCTURE!$J$27
Name XccyStructure.Fee.PayRec3: CUSTOM_STRUCTURE!$J$25

Sheet SETTINGS
B2: COB | C2: =TODAY() -> 43923

Sheet CURVE MKT DATA
B3: ALL MKT DATA LOADED | E3: TOTAL | G3: EUR OIS | O3: EUR SWAP 6ML | T3: EUR SWAP 3ML | AB3: EUR BASIS 1ML | AG3: EUR BASIS 12ML | AL3: EUR XCCY BASIS
B4: =SUM(C7:C17)=SUM(D7:D17) -> TRUE | E4: =SUM(E7:E17) -> 0
B6: INSTRUMENT | C6: DATA POINTS | D6: LOADED | E6: MISSING | G6: TICKER | H6: TERM | I6: ECB Meeting Date | J6: ECB Swap Start | K6: ECB Swap End | L6: BBG | M6: Used % | O6: TICKER | P6: TERM | Q6: BBG | R6: Used % | T6: TICKER | U6: TERM | V6: TICKER | W6: START_DT | X6: END_DT | Y6: BBG | Z6: Used % | AB6: TICKER | AC6: TERM | AD6: BBG | AE6: Used % | AG6: TICKER | AH6: TERM | AI6: BBG | AJ6: Used % | AL6: TICKER | AM6: TERM | AN6: BBG | AO6: Used %
B7: EUR OIS | C7: =COUNTA(G7:G58) -> 52 | D7: =COUNT(L7:L58) -> 52 | E7: =C7-D7 -> 0 | G7: EONIA ICPL Index | H7: ON | L7: =IF(G7="","",IF(Settings.COB=TODAY(),_xll.BDP(G7,"LAST_PRICE"),_xll.BDH(G7,"LAST_PRICE",Settings.COB,Settings.COB))) -> -0.442 | M7: =L7/100 -> -0.00442 | O7: EE0001M Index | P7: 1M | Q7: =IF(O7="","",IF(Settings.COB=TODAY(),_xll.BDP(O7,"PX_LAST"),_xll.BDH(O7,"PX_LAST",Settings.COB,Settings.COB))) -> -0.38943 | R7: =Q7/100 -> -0.0038943 | T7: EE0001M Index | U7: 1M | Y7: =IF(T7="","",IF(Settings.COB=TODAY(),_xll.BDP(T7,"PX_LAST"),_xll.BDH(T7,"PX_LAST",Settings.COB,Settings.COB))) -> -0.38943 | Z7: =Y7/100 -> -0.0038943 | AB7: EUBSA1 CMPN Curncy | AC7: 1Y | AD7: =IF(AB7="","",IF(Settings.COB=TODAY(),_xll.BDP(AB7,"LAST_PRICE"),_xll.BDH(AB7,"LAST_PRICE",Settings.COB,Settings.COB))) -> 8.1 | AE7: =AD7/10000 -> 0.00081 | AG7: EUBSS1 ICPL Curncy | AH7: 1Y | AI7: =IF(AG7="","",IF(Settings.COB=TODAY(),_xll.BDP(AG7,"LAST_PRICE"),_xll.BDH(AG7,"LAST_PRICE",Settings.COB,Settings.COB))) -> 13.8 | AJ7: =AI7/10000 -> 0.00138 | AL7: EUR L160 Curncy | AM7: EURUSD Spot | AN7: =IF(AL7="","",IF(Settings.COB=TODAY(),_xll.BDP(AL7,"LAST_PRICE"),_xll.BDH(AL7,"LAST_PRICE",Settings.COB,Settings.COB))) -> 1.08635 | AO7: =AN7 -> 1.08635
B8: EUR SWAP 6ML | C8: =COUNTA(O7:O58) -> 32 | D8: =COUNT(Q7:Q58) -> 32 | E8: =C8-D8 -> 0 | G8: EUSF1A ICPL Curncy | H8: ECB1 | I8: =_xll.meDateECB(Settings.COB,TRUE) -> 43951 | J8: =_xll.meDateECBSwapStart(I8) -> 43957 | K8: =_xll.meDateECBSwapEnd(I8) -> 43991 | L8: =IF(G8="","",IF(Settings.COB=TODAY(),_xll.BDP(G8,"LAST_PRICE"),_xll.BDH(G8,"LAST_PRICE",Settings.COB,Settings.COB))) -> -0.456 | M8: =L8/100 -> -0.00456 | O8: EE0003M Index | P8: 3M | Q8: =IF(O8="","",IF(Settings.COB=TODAY(),_xll.BDP(O8,"PX_LAST"),_xll.BDH(O8,"PX_LAST",Settings.COB,Settings.COB))) -> -0.24114 | R8: =Q8/100 -> -0.0024114 | T8: EE0003M Index | U8: 3M | Y8: =IF(T8="","",IF(Settings.COB=TODAY(),_xll.BDP(T8,"PX_LAST"),_xll.BDH(T8,"PX_LAST",Settings.COB,Settings.COB))) -> -0.24114 | Z8: =Y8/100 -> -0.0024114 | AB8: EUBSA2 CMPN Curncy | AC8: 2Y | AD8: =IF(AB8="","",IF(Settings.COB=TODAY(),_xll.BDP(AB8,"LAST_PRICE"),_xll.BDH(AB8,"LAST_PRICE",Settings.COB,Settings.COB))) -> 7.65 | AE8: =AD8/10000 -> 0.000765 | AG8: EUBSS2 ICPL Curncy | AH8: 2Y | AI8: =IF(AG8="","",IF(Settings.COB=TODAY(),_xll.BDP(AG8,"LAST_PRICE"),_xll.BDH(AG8,"LAST_PRICE",Settings.COB,Settings.COB))) -> 11.1 | AJ8: =AI8/10000 -> 0.00111 | AL8: EURON Curncy | AM8: ON | AN8: =IF(AL8="","",IF(Settings.COB=TODAY(),_xll.BDP(AL8,"LAST_PRICE"),_xll.BDH(AL8,"LAST_PRICE",Settings.COB,Settings.COB))) -> 0.194 | AO8: =AN8 -> 0.194
B9: EUR SWAP 3ML | C9: =COUNTA(T7:T58) -> 28 | D9: =COUNT(Y7:Y58) -> 28 | E9: =C9-D9 -> 0 | G9: EUSF2A ICPL Curncy | H9: ECB2 | I9: =_xll.meDateECB(I8,TRUE) -> 43986 | J9: =_xll.meDateECBSwapStart(I9) -> 43992 | K9: =_xll.meDateECBSwapEnd(I9) -> 44033 | L9: =IF(G9="","",IF(Settings.COB=TODAY(),_xll.BDP(G9,"LAST_PRICE"),_xll.BDH(G9,"LAST_PRICE",Settings.COB,Settings.COB))) -> -0.468 | M9: =L9/100 -> -0.00468 | O9: EE0006M Index | P9: 6M | Q9: =IF(O9="","",IF(Settings.COB=TODAY(),_xll.BDP(O9,"PX_LAST"),_xll.BDH(O9,"PX_LAST",Settings.COB,Settings.COB))) -> -0.17786 | R9: =Q9/100 -> -0.0017786 | T9: EE0006M Index | U9: 6M | Y9: =IF(T9="","",IF(Settings.COB=TODAY(),_xll.BDP(T9,"PX_LAST"),_xll.BDH(T9,"PX_LAST",Settings.COB,Settings.COB))) -> -0.17786 | Z9: =Y9/100 -> -0.0017786 | AB9: EUBSA3 CMPN Curncy | AC9: 3Y | AD9: =IF(AB9="","",IF(Settings.COB=TODAY(),_xll.BDP(AB9,"LAST_PRICE"),_xll.BDH(AB9,"LAST_PRICE",Settings.COB,Settings.COB))) -> 7.5 | AE9: =AD9/10000 -> 0.00075 | AG9: EUBSS3 ICPL Curncy | AH9: 3Y | AI9: =IF(AG9="","",IF(Settings.COB=TODAY(),_xll.BDP(AG9,"LAST_PRICE"),_xll.BDH(AG9,"LAST_PRICE",Settings.COB,Settings.COB))) -> 9.9 | AJ9: =AI9/10000 -> 0.00099 | AL9: EURTN Curncy | AM9: TN | AN9: =IF(AL9="","",IF(Settings.COB=TODAY(),_xll.BDP(AL9,"LAST_PRICE"),_xll.BDH(AL9,"LAST_PRICE",Settings.COB,Settings.COB))) -> 0.6 | AO9: =AN9 -> 0.6
B10: Futures Dates | C10: =COUNTA(T11:T18)*2 -> 16 | D10: =COUNT(W11:X18) -> 16 | E10: =C10-D10 -> 0 | G10: EUSF3A ICPL Curncy | H10: ECB3 | I10: =_xll.meDateECB(I9,TRUE) -> 44028 | J10: =_xll.meDateECBSwapStart(I10) -> 44034 | K10: =_xll.meDateECBSwapEnd(I10) -> 44089 | L10: =IF(G10="","",IF(Settings.COB=TODAY(),_xll.BDP(G10,"LAST_PRICE"),_xll.BDH(G10,"LAST_PRICE",Settings.COB,Settings.COB))) -> -0.476 | M10: =L10/100 -> -0.00476 | O10: EE0012M Index | P10: 12M | Q10: =IF(O10="","",IF(Settings.COB=TODAY(),_xll.BDP(O10,"PX_LAST"),_xll.BDH(O10,"PX_LAST",Settings.COB,Settings.COB))) -> -0.16443 | R10: =Q10/100 -> -0.0016443 | T10: EE0012M Index | U10: 12M | Y10: =IF(T10="","",IF(Settings.COB=TODAY(),_xll.BDP(T10,"PX_LAST"),_xll.BDH(T10,"PX_LAST",Settings.COB,Settings.COB))) -> -0.16443 | Z10: =Y10/100 -> -0.0016443 | AB10: EUBSA4 CMPN Curncy | AC10: 4Y | AD10: =IF(AB10="","",IF(Settings.COB=TODAY(),_xll.BDP(AB10,"LAST_PRICE"),_xll.BDH(AB10,"LAST_PRICE",Settings.COB,Settings.COB))) -> 7.45 | AE10: =AD10/10000 -> 0.000745 | AG10: EUBSS4 ICPL Curncy | AH10: 4Y | AI10: =IF(AG10="","",IF(Settings.COB=TODAY(),_xll.BDP(AG10,"LAST_PRICE"),_xll.BDH(AG10,"LAST_PRICE",Settings.COB,Settings.COB))) -> 9.2 | AJ10: =AI10/10000 -> 0.00092 | AL10: EUR1W Curncy | AM10: 1W | AN10: =IF(AL10="","",IF(Settings.COB=TODAY(),_xll.BDP(AL10,"LAST_PRICE"),_xll.BDH(AL10,"LAST_PRICE",Settings.COB,Settings.COB))) -> 1.99 | AO10: =AN10 -> 1.99
B11: EUR BASIS 1ML | C11: =COUNTA(AB7:AB58) -> 15 | D11: =COUNT(AD7:AD58) -> 15 | E11: =C11-D11 -> 0 | G11: EUSF4A ICPL Curncy | H11: ECB4 | I11: =_xll.meDateECB(I10,TRUE) -> 44084 | J11: =_xll.meDateECBSwapStart(I11) -> 44090 | K11: =_xll.meDateECBSwapEnd(I11) -> 44138 | L11: =IF(G11="","",IF(Settings.COB=TODAY(),_xll.BDP(G11,"LAST_PRICE"),_xll.BDH(G11,"LAST_PRICE",Settings.COB,Settings.COB))) -> -0.495 | M11: =L11/100 -> -0.00495 | O11: EUFR0AG ICPL Curncy | P11: 1X7 | Q11: =IF(O11="","",IF(Settings.COB=TODAY(),_xll.BDP(O11,"LAST_PRICE"),_xll.BDH(O11,"LAST_PRICE",Settings.COB,Settings.COB))) -> -0.27 | R11: =Q11/100 -> -0.0027 | T11: ER1 Comdty | U11: ER1 | V11: =IF(Settings.COB=TODAY(),$U11,_xll.BDH(T11,"FUT_CUR_GEN_TICKER",Settings.COB,Settings.COB)) -> ER1 | W11: =DATEVALUE(_xll.BDP($V11&" Comdty","INT_RATE_FUT_START_DT")) -> 43999 | X11: =DATEVALUE(_xll.BDP($V11&" Comdty","INT_RATE_FUT_END_DT")) -> 44090 | Y11: =IF(T11="","",IF(Settings.COB=TODAY(),_xll.BDP(T11,"LAST_PRICE"),_xll.BDH(T11,"LAST_PRICE",Settings.COB,Settings.COB))) -> 100.345 | Z11: =Y11 -> 100.345 | AB11: EUBSA5 CMPN Curncy | AC11: 5Y | AD11: =IF(AB11="","",IF(Settings.COB=TODAY(),_xll.BDP(AB11,"LAST_PRICE"),_xll.BDH(AB11,"LAST_PRICE",Settings.COB,Settings.COB))) -> 7.4 | AE11: =AD11/10000 -> 0.00074 | AG11: EUBSS5 ICPL Curncy | AH11: 5Y | AI11: =IF(AG11="","",IF(Settings.COB=TODAY(),_xll.BDP(AG11,"LAST_PRICE"),_xll.BDH(AG11,"LAST_PRICE",Settings.COB,Settings.COB))) -> 8.8 | AJ11: =AI11/10000 -> 0.00088 | AL11: EUR2W Curncy | AM11: 2W | AN11: =IF(AL11="","",IF(Settings.COB=TODAY(),_xll.BDP(AL11,"LAST_PRICE"),_xll.BDH(AL11,"LAST_PRICE",Settings.COB,Settings.COB))) -> 3.86 | AO11: =AN11 -> 3.86
B12: EUR BASIS 12ML | C12: =COUNTA(AG7:AG58) -> 15 | D12: =COUNT(AI7:AI58) -> 15 | E12: =C12-D12 -> 0 | G12: EUSWE1 ICPL Curncy | H12: 12M | L12: =IF(G12="","",IF(Settings.COB=TODAY(),_xll.BDP(G12,"LAST_PRICE"),_xll.BDH(G12,"LAST_PRICE",Settings.COB,Settings.COB))) -> -0.487 | M12: =L12/100 -> -0.00487 | O12: EUFR0BH ICPL Curncy | P12: 2X8 | Q12: =IF(O12="","",IF(Settings.COB=TODAY(),_xll.BDP(O12,"LAST_PRICE"),_xll.BDH(O12,"LAST_PRICE",Settings.COB,Settings.COB))) -> -0.28 | R12: =Q12/100 -> -0.0028 | T12: ER2 Comdty | U12: ER2 | V12: =IF(Settings.COB=TODAY(),$U12,_xll.BDH(T12,"FUT_CUR_GEN_TICKER",Settings.COB,Settings.COB)) -> ER2 | W12: =DATEVALUE(_xll.BDP($V12&" Comdty","INT_RATE_FUT_START_DT")) -> 44090 | X12: =DATEVALUE(_xll.BDP($V12&" Comdty","INT_RATE_FUT_END_DT")) -> 44181 | Y12: =IF(T12="","",IF(Settings.COB=TODAY(),_xll.BDP(T12,"LAST_PRICE"),_xll.BDH(T12,"LAST_PRICE",Settings.COB,Settings.COB))) -> 100.375 | Z12: =Y12 -> 100.375 | AB12: EUBSA6 CMPN Curncy | AC12: 6Y | AD12: =IF(AB12="","",IF(Settings.COB=TODAY(),_xll.BDP(AB12,"LAST_PRICE"),_xll.BDH(AB12,"LAST_PRICE",Settings.COB,Settings.COB))) -> 7.4 | AE12: =AD12/10000 -> 0.00074 | AG12: EUBSS6 ICPL Curncy | AH12: 6Y | AI12: =IF(AG12="","",IF(Settings.COB=TODAY(),_xll.BDP(AG12,"LAST_PRICE"),_xll.BDH(AG12,"LAST_PRICE",Settings.COB,Settings.COB))) -> 8.6 | AJ12: =AI12/10000 -> 0.00086 | AL12: EUR3W Curncy | AM12: 3W | AN12: =IF(AL12="","",IF(Settings.COB=TODAY(),_xll.BDP(AL12,"LAST_PRICE"),_xll.BDH(AL12,"LAST_PRICE",Settings.COB,Settings.COB))) -> 6.22 | AO12: =AN12 -> 6.22
B13: EUR XCCY | C13: =COUNTA(AL7:AL58) -> 31 | D13: =COUNT(AN7:AN58) -> 31 | E13: =C13-D13 -> 0 | G13: EUSWE1F ICPL Curncy | H13: 18M | L13: =IF(G13="","",IF(Settings.COB=TODAY(),_xll.BDP(G13,"LAST_PRICE"),_xll.BDH(G13,"LAST_PRICE",Settings.COB,Settings.COB))) -> -0.494 | M13: =L13/100 -> -0.00494 | O13: EUFR0CI ICPL Curncy | P13: 3X9 | Q13: =IF(O13="","",IF(Settings.COB=TODAY(),_xll.BDP(O13,"LAST_PRICE"),_xll.BDH(O13,"LAST_PRICE",Settings.COB,Settings.COB))) -> -0.289 | R13: =Q13/100 -> -0.00289 | T13: ER3 Comdty | U13: ER3 | V13: =IF(Settings.COB=TODAY(),$U13,_xll.BDH(T13,"FUT_CUR_GEN_TICKER",Settings.COB,Settings.COB)) -> ER3 | W13: =DATEVALUE(_xll.BDP($V13&" Comdty","INT_RATE_FUT_START_DT")) -> 44181 | X13: =DATEVALUE(_xll.BDP($V13&" Comdty","INT_RATE_FUT_END_DT")) -> 44272 | Y13: =IF(T13="","",IF(Settings.COB=TODAY(),_xll.BDP(T13,"LAST_PRICE"),_xll.BDH(T13,"LAST_PRICE",Settings.COB,Settings.COB))) -> 100.395 | Z13: =Y13 -> 100.395 | AB13: EUBSA7 CMPN Curncy | AC13: 7Y | AD13: =IF(AB13="","",IF(Settings.COB=TODAY(),_xll.BDP(AB13,"LAST_PRICE"),_xll.BDH(AB13,"LAST_PRICE",Settings.COB,Settings.COB))) -> 7.3 | AE13: =AD13/10000 -> 0.00073 | AG13: EUBSS7 ICPL Curncy | AH13: 7Y | AI13: =IF(AG13="","",IF(Settings.COB=TODAY(),_xll.BDP(AG13,"LAST_PRICE"),_xll.BDH(AG13,"LAST_PRICE",Settings.COB,Settings.COB))) -> 8.4 | AJ13: =AI13/10000 -> 0.00084 | AL13: EUR1M Curncy | AM13: 1M | AN13: =IF(AL13="","",IF(Settings.COB=TODAY(),_xll.BDP(AL13,"LAST_PRICE"),_xll.BDH(AL13,"LAST_PRICE",Settings.COB,Settings.COB))) -> 9.84 | AO13: =AN13 -> 9.84
G14: EUSWE1 ICPL Curncy | H14: 1Y | L14: =IF(G14="","",IF(Settings.COB=TODAY(),_xll.BDP(G14,"LAST_PRICE"),_xll.BDH(G14,"LAST_PRICE",Settings.COB,Settings.COB))) -> -0.487 | M14: =L14/100 -> -0.00487 | O14: EUFR0DJ ICPL Curncy | P14: 4X10 | Q14: =IF(O14="","",IF(Settings.COB=TODAY(),_xll.BDP(O14,"LAST_PRICE"),_xll.BDH(O14,"LAST_PRICE",Settings.COB,Settings.COB))) -> -0.3 | R14: =Q14/100 -> -0.003 | T14: ER4 Comdty | U14: ER4 | V14: =IF(Settings.COB=TODAY(),$U14,_xll.BDH(T14,"FUT_CUR_GEN_TICKER",Settings.COB,Settings.COB)) -> ER4 | W14: =DATEVALUE(_xll.BDP($V14&" Comdty","INT_RATE_FUT_START_DT")) -> 44272 | X14: =DATEVALUE(_xll.BDP($V14&" Comdty","INT_RATE_FUT_END_DT")) -> 44363 | Y14: =IF(T14="","",IF(Settings.COB=TODAY(),_xll.BDP(T14,"LAST_PRICE"),_xll.BDH(T14,"LAST_PRICE",Settings.COB,Settings.COB))) -> 100.4 | Z14: =Y14 -> 100.4 | AB14: EUBSA8 CMPN Curncy | AC14: 8Y | AD14: =IF(AB14="","",IF(Settings.COB=TODAY(),_xll.BDP(AB14,"LAST_PRICE"),_xll.BDH(AB14,"LAST_PRICE",Settings.COB,Settings.COB))) -> 7.25 | AE14: =AD14/10000 -> 0.000725 | AG14: EUBSS8 ICPL Curncy | AH14: 8Y | AI14: =IF(AG14="","",IF(Settings.COB=TODAY(),_xll.BDP(AG14,"LAST_PRICE"),_xll.BDH(AG14,"LAST_PRICE",Settings.COB,Settings.COB))) -> 8.3 | AJ14: =AI14/10000 -> 0.00083 | AL14: EUR2M Curncy | AM14: 2M | AN14: =IF(AL14="","",IF(Settings.COB=TODAY(),_xll.BDP(AL14,"LAST_PRICE"),_xll.BDH(AL14,"LAST_PRICE",Settings.COB,Settings.COB))) -> 20.57 | AO14: =AN14 -> 20.57
G15: EUSWE2 ICPL Curncy | H15: 2Y | L15: =IF(G15="","",IF(Settings.COB=TODAY(),_xll.BDP(G15,"LAST_PRICE"),_xll.BDH(G15,"LAST_PRICE",Settings.COB,Settings.COB))) -> -0.492 | M15: =L15/100 -> -0.00492 | O15: EUFR0EK ICPL Curncy | P15: 5X11 | Q15: =IF(O15="","",IF(Settings.COB=TODAY(),_xll.BDP(O15,"LAST_PRICE"),_xll.BDH(O15,"LAST_PRICE",Settings.COB,Settings.COB))) -> -0.31 | R15: =Q15/100 -> -0.0031 | T15: ER5 Comdty | U15: ER5 | V15: =IF(Settings.COB=TODAY(),$U15,_xll.BDH(T15,"FUT_CUR_GEN_TICKER",Settings.COB,Settings.COB)) -> ER5 | W15: =DATEVALUE(_xll.BDP($V15&" Comdty","INT_RATE_FUT_START_DT")) -> 44363 | X15: =DATEVALUE(_xll.BDP($V15&" Comdty","INT_RATE_FUT_END_DT")) -> 44454 | Y15: =IF(T15="","",IF(Settings.COB=TODAY(),_xll.BDP(T15,"LAST_PRICE"),_xll.BDH(T15,"LAST_PRICE",Settings.COB,Settings.COB))) -> 100.39 | Z15: =Y15 -> 100.39 | AB15: EUBSA9 CMPN Curncy | AC15: 9Y | AD15: =IF(AB15="","",IF(Settings.COB=TODAY(),_xll.BDP(AB15,"LAST_PRICE"),_xll.BDH(AB15,"LAST_PRICE",Settings.COB,Settings.COB))) -> 7.15 | AE15: =AD15/10000 -> 0.000715 | AG15: EUBSS9 ICPL Curncy | AH15: 9Y | AI15: =IF(AG15="","",IF(Settings.COB=TODAY(),_xll.BDP(AG15,"LAST_PRICE"),_xll.BDH(AG15,"LAST_PRICE",Settings.COB,Settings.COB))) -> 8.2 | AJ15: =AI15/10000 -> 0.00082 | AL15: EUR3M Curncy | AM15: 3M | AN15: =IF(AL15="","",IF(Settings.COB=TODAY(),_xll.BDP(AL15,"LAST_PRICE"),_xll.BDH(AL15,"LAST_PRICE",Settings.COB,Settings.COB))) -> 29.46 | AO15: =AN15 -> 29.46
G16: EUSWE3 ICPL Curncy | H16: 3Y | L16: =IF(G16="","",IF(Settings.COB=TODAY(),_xll.BDP(G16,"LAST_PRICE"),_xll.BDH(G16,"LAST_PRICE",Settings.COB,Settings.COB))) -> -0.483 | M16: =L16/100 -> -0.00483 | O16: EUFR0F1 ICPL Curncy | P16: 6X12 | Q16: =IF(O16="","",IF(Settings.COB=TODAY(),_xll.BDP(O16,"LAST_PRICE"),_xll.BDH(O16,"LAST_PRICE",Settings.COB,Settings.COB))) -> -0.316 | R16: =Q16/100 -> -0.00316 | T16: ER6 Comdty | U16: ER6 | V16: =IF(Settings.COB=TODAY(),$U16,_xll.BDH(T16,"FUT_CUR_GEN_TICKER",Settings.COB,Settings.COB)) -> ER6 | W16: =DATEVALUE(_xll.BDP($V16&" Comdty","INT_RATE_FUT_START_DT")) -> 44454 | X16: =DATEVALUE(_xll.BDP($V16&" Comdty","INT_RATE_FUT_END_DT")) -> 44545 | Y16: =IF(T16="","",IF(Settings.COB=TODAY(),_xll.BDP(T16,"LAST_PRICE"),_xll.BDH(T16,"LAST_PRICE",Settings.COB,Settings.COB))) -> 100.38 | Z16: =Y16 -> 100.38 | AB16: EUBSA10 CMPN Curncy | AC16: 10Y | AD16: =IF(AB16="","",IF(Settings.COB=TODAY(),_xll.BDP(AB16,"LAST_PRICE"),_xll.BDH(AB16,"LAST_PRICE",Settings.COB,Settings.COB))) -> 7.05 | AE16: =AD16/10000 -> 0.000705 | AG16: EUBSS10 ICPL Curncy | AH16: 10Y | AI16: =IF(AG16="","",IF(Settings.COB=TODAY(),_xll.BDP(AG16,"LAST_PRICE"),_xll.BDH(AG16,"LAST_PRICE",Settings.COB,Settings.COB))) -> 8 | AJ16: =AI16/10000 -> 0.0008 | AL16: EUR4M Curncy | AM16: 4M | AN16: =IF(AL16="","",IF(Settings.COB=TODAY(),_xll.BDP(AL16,"LAST_PRICE"),_xll.BDH(AL16,"LAST_PRICE",Settings.COB,Settings.COB))) -> 38.4 | AO16: =AN16 -> 38.4
G17: EUSWE4 ICPL Curncy | H17: 4Y | L17: =IF(G17="","",IF(Settings.COB=TODAY(),_xll.BDP(G17,"LAST_PRICE"),_xll.BDH(G17,"LAST_PRICE",Settings.COB,Settings.COB))) -> -0.455 | M17: =L17/100 -> -0.00455 | O17: EUFR0G1A ICPL Curncy | P17: 7X13 | Q17: =IF(O17="","",IF(Settings.COB=TODAY(),_xll.BDP(O17,"LAST_PRICE"),_xll.BDH(O17,"LAST_PRICE",Settings.COB,Settings.COB))) -> -0.32 | R17: =Q17/100 -> -0.0032 | T17: ER7 Comdty | U17: ER7 | V17: =IF(Settings.COB=TODAY(),$U17,_xll.BDH(T17,"FUT_CUR_GEN_TICKER",Settings.COB,Settings.COB)) -> ER7 | W17: =DATEVALUE(_xll.BDP($V17&" Comdty","INT_RATE_FUT_START_DT")) -> 44545 | X17: =DATEVALUE(_xll.BDP($V17&" Comdty","INT_RATE_FUT_END_DT")) -> 44636 | Y17: =IF(T17="","",IF(Settings.COB=TODAY(),_xll.BDP(T17,"LAST_PRICE"),_xll.BDH(T17,"LAST_PRICE",Settings.COB,Settings.COB))) -> 100.37 | Z17: =Y17 -> 100.37 | AB17: EUBSA12 CMPN Curncy | AC17: 12Y | AD17: =IF(AB17="","",IF(Settings.COB=TODAY(),_xll.BDP(AB17,"LAST_PRICE"),_xll.BDH(AB17,"LAST_PRICE",Settings.COB,Settings.COB))) -> 8.15 | AE17: =AD17/10000 -> 0.000815 | AG17: EUBSS12 ICPL Curncy | AH17: 12Y | AI17: =IF(AG17="","",IF(Settings.COB=TODAY(),_xll.BDP(AG17,"LAST_PRICE"),_xll.BDH(AG17,"LAST_PRICE",Settings.COB,Settings.COB))) -> 7.8 | AJ17: =AI17/10000 -> 0.00078 | AL17: EUR5M Curncy | AM17: 5M | AN17: =IF(AL17="","",IF(Settings.COB=TODAY(),_xll.BDP(AL17,"LAST_PRICE"),_xll.BDH(AL17,"LAST_PRICE",Settings.COB,Settings.COB))) -> 47.59 | AO17: =AN17 -> 47.59
G18: EUSWE5 ICPL Curncy | H18: 5Y | L18: =IF(G18="","",IF(Settings.COB=TODAY(),_xll.BDP(G18,"LAST_PRICE"),_xll.BDH(G18,"LAST_PRICE",Settings.COB,Settings.COB))) -> -0.416 | M18: =L18/100 -> -0.00416 | O18: EUFR0H1B ICPL Curncy | P18: 8X14 | Q18: =IF(O18="","",IF(Settings.COB=TODAY(),_xll.BDP(O18,"LAST_PRICE"),_xll.BDH(O18,"LAST_PRICE",Settings.COB,Settings.COB))) -> -0.323 | R18: =Q18/100 -> -0.00323 | T18: ER8 Comdty | U18: ER8 | V18: =IF(Settings.COB=TODAY(),$U18,_xll.BDH(T18,"FUT_CUR_GEN_TICKER",Settings.COB,Settings.COB)) -> ER8 | W18: =DATEVALUE(_xll.BDP($V18&" Comdty","INT_RATE_FUT_START_DT")) -> 44636 | X18: =DATEVALUE(_xll.BDP($V18&" Comdty","INT_RATE_FUT_END_DT")) -> 44727 | Y18: =IF(T18="","",IF(Settings.COB=TODAY(),_xll.BDP(T18,"LAST_PRICE"),_xll.BDH(T18,"LAST_PRICE",Settings.COB,Settings.COB))) -> 100.365 | Z18: =Y18 -> 100.365 | AB18: EUBSA15 CMPN Curncy | AC18: 15Y | AD18: =IF(AB18="","",IF(Settings.COB=TODAY(),_xll.BDP(AB18,"LAST_PRICE"),_xll.BDH(AB18,"LAST_PRICE",Settings.COB,Settings.COB))) -> 6.65 | AE18: =AD18/10000 -> 0.000665 | AG18: EUBSS15 ICPL Curncy | AH18: 15Y | AI18: =IF(AG18="","",IF(Settings.COB=TODAY(),_xll.BDP(AG18,"LAST_PRICE"),_xll.BDH(AG18,"LAST_PRICE",Settings.COB,Settings.COB))) -> 7.3 | AJ18: =AI18/10000 -> 0.00073 | AL18: EUR6M Curncy | AM18: 6M | AN18: =IF(AL18="","",IF(Settings.COB=TODAY(),_xll.BDP(AL18,"LAST_PRICE"),_xll.BDH(AL18,"LAST_PRICE",Settings.COB,Settings.COB))) -> 55.75 | AO18: =AN18 -> 55.75
G19: EUSWE6 ICPL Curncy | H19: 6Y | L19: =IF(G19="","",IF(Settings.COB=TODAY(),_xll.BDP(G19,"LAST_PRICE"),_xll.BDH(G19,"LAST_PRICE",Settings.COB,Settings.COB))) -> -0.381 | M19: =L19/100 -> -0.00381 | O19: EUFR0I1C ICPL Curncy | P19: 9X15 | Q19: =IF(O19="","",IF(Settings.COB=TODAY(),_xll.BDP(O19,"LAST_PRICE"),_xll.BDH(O19,"LAST_PRICE",Settings.COB,Settings.COB))) -> -0.324 | R19: =Q19/100 -> -0.00324 | T19: EUSW3V3 ICPL Curncy | U19: 3Y | Y19: =IF(T19="","",IF(Settings.COB=TODAY(),_xll.BDP(T19,"LAST_PRICE"),_xll.BDH(T19,"LAST_PRICE",Settings.COB,Settings.COB))) -> -0.367 | Z19: =Y19/100 -> -0.00367 | AB19: EUBSA20 CMPN Curncy | AC19: 20Y | AD19: =IF(AB19="","",IF(Settings.COB=TODAY(),_xll.BDP(AB19,"LAST_PRICE"),_xll.BDH(AB19,"LAST_PRICE",Settings.COB,Settings.COB))) -> 6.1 | AE19: =AD19/10000 -> 0.00061 | AG19: EUBSS20 ICPL Curncy | AH19: 20Y | AI19: =IF(AG19="","",IF(Settings.COB=TODAY(),_xll.BDP(AG19,"LAST_PRICE"),_xll.BDH(AG19,"LAST_PRICE",Settings.COB,Settings.COB))) -> 6.8 | AJ19: =AI19/10000 -> 0.00068 | AL19: EUR9M Curncy | AM19: 9M | AN19: =IF(AL19="","",IF(Settings.COB=TODAY(),_xll.BDP(AL19,"LAST_PRICE"),_xll.BDH(AL19,"LAST_PRICE",Settings.COB,Settings.COB))) -> 86.04 | AO19: =AN19 -> 86.04
G20: EUSWE7 ICPL Curncy | H20: 7Y | L20: =IF(G20="","",IF(Settings.COB=TODAY(),_xll.BDP(G20,"LAST_PRICE"),_xll.BDH(G20,"LAST_PRICE",Settings.COB,Settings.COB))) -> -0.341 | M20: =L20/100 -> -0.00341 | O20: EUFR0J1D ICPL Curncy | P20: 10X16 | Q20: =IF(O20="","",IF(Settings.COB=TODAY(),_xll.BDP(O20,"LAST_PRICE"),_xll.BDH(O20,"LAST_PRICE",Settings.COB,Settings.COB))) -> -0.323 | R20: =Q20/100 -> -0.00323 | T20: EUSW4V3 ICPL Curncy | U20: 4Y | Y20: =IF(T20="","",IF(Settings.COB=TODAY(),_xll.BDP(T20,"LAST_PRICE"),_xll.BDH(T20,"LAST_PRICE",Settings.COB,Settings.COB))) -> -0.337 | Z20: =Y20/100 -> -0.00337 | AB20: EUBSA25 CMPN Curncy | AC20: 25Y | AD20: =IF(AB20="","",IF(Settings.COB=TODAY(),_xll.BDP(AB20,"LAST_PRICE"),_xll.BDH(AB20,"LAST_PRICE",Settings.COB,Settings.COB))) -> 5.75 | AE20: =AD20/10000 -> 0.000575 | AG20: EUBSS25 ICPL Curncy | AH20: 25Y | AI20: =IF(AG20="","",IF(Settings.COB=TODAY(),_xll.BDP(AG20,"LAST_PRICE"),_xll.BDH(AG20,"LAST_PRICE",Settings.COB,Settings.COB))) -> 6.5 | AJ20: =AI20/10000 -> 0.00065 | AL20: EUBSC ICPL Curncy | AM20: 3M | AN20: =IF(AL20="","",IF(Settings.COB=TODAY(),_xll.BDP(AL20,"LAST_PRICE"),_xll.BDH(AL20,"LAST_PRICE",Settings.COB,Settings.COB))) -> 63.625 | AO20: =AN20/10000 -> 0.0063625
G21: EUSWE8 ICPL Curncy | H21: 8Y | L21: =IF(G21="","",IF(Settings.COB=TODAY(),_xll.BDP(G21,"LAST_PRICE"),_xll.BDH(G21,"LAST_PRICE",Settings.COB,Settings.COB))) -> -0.298 | M21: =L21/100 -> -0.00298 | O21: EUFR0K1E ICPL Curncy | P21: 11X17 | Q21: =IF(O21="","",IF(Settings.COB=TODAY(),_xll.BDP(O21,"LAST_PRICE"),_xll.BDH(O21,"LAST_PRICE",Settings.COB,Settings.COB))) -> -0.322 | R21: =Q21/100 -> -0.00322 | T21: EUSW5V3 ICPL Curncy | U21: 5Y | Y21: =IF(T21="","",IF(Settings.COB=TODAY(),_xll.BDP(T21,"LAST_PRICE"),_xll.BDH(T21,"LAST_PRICE",Settings.COB,Settings.COB))) -> -0.297 | Z21: =Y21/100 -> -0.00297 | AB21: EUBSA30 CMPN Curncy | AC21: 30Y | AD21: =IF(AB21="","",IF(Settings.COB=TODAY(),_xll.BDP(AB21,"LAST_PRICE"),_xll.BDH(AB21,"LAST_PRICE",Settings.COB,Settings.COB))) -> 5.25 | AE21: =AD21/10000 -> 0.000525 | AG21: EUBSS30 ICPL Curncy | AH21: 30Y | AI21: =IF(AG21="","",IF(Settings.COB=TODAY(),_xll.BDP(AG21,"LAST_PRICE"),_xll.BDH(AG21,"LAST_PRICE",Settings.COB,Settings.COB))) -> 6.2 | AJ21: =AI21/10000 -> 0.00062 | AL21: EUBSF ICPL Curncy | AM21: 6M | AN21: =IF(AL21="","",IF(Settings.COB=TODAY(),_xll.BDP(AL21,"LAST_PRICE"),_xll.BDH(AL21,"LAST_PRICE",Settings.COB,Settings.COB))) -> 24.625 | AO21: =AN21/10000 -> 0.0024625
G22: EUSWE10 ICPL Curncy | H22: 10Y | L22: =IF(G22="","",IF(Settings.COB=TODAY(),_xll.BDP(G22,"LAST_PRICE"),_xll.BDH(G22,"LAST_PRICE",Settings.COB,Settings.COB))) -> -0.213 | M22: =L22/100 -> -0.00213 | O22: EUSA2 ICPL Curncy | P22: 2Y | Q22: =IF(O22="","",IF(Settings.COB=TODAY(),_xll.BDP(O22,"LAST_PRICE"),_xll.BDH(O22,"LAST_PRICE",Settings.COB,Settings.COB))) -> -0.304 | R22: =Q22/100 -> -0.00304 | T22: EUSW6V3 ICPL Curncy | U22: 6Y | Y22: =IF(T22="","",IF(Settings.COB=TODAY(),_xll.BDP(T22,"LAST_PRICE"),_xll.BDH(T22,"LAST_PRICE",Settings.COB,Settings.COB))) -> -0.26 | Z22: =Y22/100 -> -0.0026 | AD22: =IF(AB22="","",IF(Settings.COB=TODAY(),_xll.BDP(AB22,"LAST_PRICE"),_xll.BDH(AB22,"LAST_PRICE",Settings.COB,Settings.COB))) | AI22: =IF(AG22="","",IF(Settings.COB=TODAY(),_xll.BDP(AG22,"LAST_PRICE"),_xll.BDH(AG22,"LAST_PRICE",Settings.COB,Settings.COB))) | AL22: EUBSI ICPL Curncy | AM22: 9M | AN22: =IF(AL22="","",IF(Settings.COB=TODAY(),_xll.BDP(AL22,"LAST_PRICE"),_xll.BDH(AL22,"LAST_PRICE",Settings.COB,Settings.COB))) -> 4.75 | AO22: =AN22/10000 -> 0.000475
G23: EOBSVC1 ICPL Curncy | H23: 1Y | L23: =IF(G23="","",IF(Settings.COB=TODAY(),_xll.BDP(G23,"LAST_PRICE"),_xll.BDH(G23,"LAST_PRICE",Settings.COB,Settings.COB))) -> 12 | M23: =L23/10000 -> 0.0012 | O23: EUSA3 ICPL Curncy | P23: 3Y | Q23: =IF(O23="","",IF(Settings.COB=TODAY(),_xll.BDP(O23,"LAST_PRICE"),_xll.BDH(O23,"LAST_PRICE",Settings.COB,Settings.COB))) -> -0.292 | R23: =Q23/100 -> -0.00292 | T23: EUSW7V3 ICPL Curncy | U23: 7Y | Y23: =IF(T23="","",IF(Settings.COB=TODAY(),_xll.BDP(T23,"LAST_PRICE"),_xll.BDH(T23,"LAST_PRICE",Settings.COB,Settings.COB))) -> -0.218 | Z23: =Y23/100 -> -0.00218 | AD23: =IF(AB23="","",IF(Settings.COB=TODAY(),_xll.BDP(AB23,"LAST_PRICE"),_xll.BDH(AB23,"LAST_PRICE",Settings.COB,Settings.COB))) | AI23: =IF(AG23="","",IF(Settings.COB=TODAY(),_xll.BDP(AG23,"LAST_PRICE"),_xll.BDH(AG23,"LAST_PRICE",Settings.COB,Settings.COB))) | AL23: EUBS1 ICPL Curncy | AM23: 1Y | AN23: =IF(AL23="","",IF(Settings.COB=TODAY(),_xll.BDP(AL23,"LAST_PRICE"),_xll.BDH(AL23,"LAST_PRICE",Settings.COB,Settings.COB))) -> -0.5 | AO23: =AN23/10000 -> -5e-05
G24: EOBSVC2 ICPL Curncy | H24: 2Y | L24: =IF(G24="","",IF(Settings.COB=TODAY(),_xll.BDP(G24,"LAST_PRICE"),_xll.BDH(G24,"LAST_PRICE",Settings.COB,Settings.COB))) -> 11.8 | M24: =L24/10000 -> 0.00118 | O24: EUSA4 ICPL Curncy | P24: 4Y | Q24: =IF(O24="","",IF(Settings.COB=TODAY(),_xll.BDP(O24,"LAST_PRICE"),_xll.BDH(O24,"LAST_PRICE",Settings.COB,Settings.COB))) -> -0.262 | R24: =Q24/100 -> -0.00262 | T24: EUSW8V3 ICPL Curncy | U24: 8Y | Y24: =IF(T24="","",IF(Settings.COB=TODAY(),_xll.BDP(T24,"LAST_PRICE"),_xll.BDH(T24,"LAST_PRICE",Settings.COB,Settings.COB))) -> -0.174 | Z24: =Y24/100 -> -0.00174 | AD24: =IF(AB24="","",IF(Settings.COB=TODAY(),_xll.BDP(AB24,"LAST_PRICE"),_xll.BDH(AB24,"LAST_PRICE",Settings.COB,Settings.COB))) | AI24: =IF(AG24="","",IF(Settings.COB=TODAY(),_xll.BDP(AG24,"LAST_PRICE"),_xll.BDH(AG24,"LAST_PRICE",Settings.COB,Settings.COB))) | AL24: EUBS2 ICPL Curncy | AM24: 2Y | AN24: =IF(AL24="","",IF(Settings.COB=TODAY(),_xll.BDP(AL24,"LAST_PRICE"),_xll.BDH(AL24,"LAST_PRICE",Settings.COB,Settings.COB))) -> -11.125 | AO24: =AN24/10000 -> -0.0011125
G25: EOBSVC3 ICPL Curncy | H25: 3Y | L25: =IF(G25="","",IF(Settings.COB=TODAY(),_xll.BDP(G25,"LAST_PRICE"),_xll.BDH(G25,"LAST_PRICE",Settings.COB,Settings.COB))) -> 12.1 | M25: =L25/10000 -> 0.00121 | O25: EUSA5 ICPL Curncy | P25: 5Y | Q25: =IF(O25="","",IF(Settings.COB=TODAY(),_xll.BDP(O25,"LAST_PRICE"),_xll.BDH(O25,"LAST_PRICE",Settings.COB,Settings.COB))) -> -0.223 | R25: =Q25/100 -> -0.00223 | T25: EUSW9V3 ICPL Curncy | U25: 9Y | Y25: =IF(T25="","",IF(Settings.COB=TODAY(),_xll.BDP(T25,"LAST_PRICE"),_xll.BDH(T25,"LAST_PRICE",Settings.COB,Settings.COB))) -> -0.13 | Z25: =Y25/100 -> -0.0013 | AD25: =IF(AB25="","",IF(Settings.COB=TODAY(),_xll.BDP(AB25,"LAST_PRICE"),_xll.BDH(AB25,"LAST_PRICE",Settings.COB,Settings.COB))) | AI25: =IF(AG25="","",IF(Settings.COB=TODAY(),_xll.BDP(AG25,"LAST_PRICE"),_xll.BDH(AG25,"LAST_PRICE",Settings.COB,Settings.COB))) | AL25: EUBS3 ICPL Curncy | AM25: 3Y | AN25: =IF(AL25="","",IF(Settings.COB=TODAY(),_xll.BDP(AL25,"LAST_PRICE"),_xll.BDH(AL25,"LAST_PRICE",Settings.COB,Settings.COB))) -> -15.375 | AO25: =AN25/10000 -> -0.0015375
G26: EOBSVC4 ICPL Curncy | H26: 4Y | L26: =IF(G26="","",IF(Settings.COB=TODAY(),_xll.BDP(G26,"LAST_PRICE"),_xll.BDH(G26,"LAST_PRICE",Settings.COB,Settings.COB))) -> 12.3 | M26: =L26/10000 -> 0.00123 | O26: EUSA6 ICPL Curncy | P26: 6Y | Q26: =IF(O26="","",IF(Settings.COB=TODAY(),_xll.BDP(O26,"LAST_PRICE"),_xll.BDH(O26,"LAST_PRICE",Settings.COB,Settings.COB))) -> -0.19 | R26: =Q26/100 -> -0.0019 | T26: EUSW10V3 ICPL Curncy | U26: 10Y | Y26: =IF(T26="","",IF(Settings.COB=TODAY(),_xll.BDP(T26,"LAST_PRICE"),_xll.BDH(T26,"LAST_PRICE",Settings.COB,Settings.COB))) -> -0.086 | Z26: =Y26/100 -> -0.00086 | AD26: =IF(AB26="","",IF(Settings.COB=TODAY(),_xll.BDP(AB26,"LAST_PRICE"),_xll.BDH(AB26,"LAST_PRICE",Settings.COB,Settings.COB))) | AI26: =IF(AG26="","",IF(Settings.COB=TODAY(),_xll.BDP(AG26,"LAST_PRICE"),_xll.BDH(AG26,"LAST_PRICE",Settings.COB,Settings.COB))) | AL26: EUBS4 ICPL Curncy | AM26: 4Y | AN26: =IF(AL26="","",IF(Settings.COB=TODAY(),_xll.BDP(AL26,"LAST_PRICE"),_xll.BDH(AL26,"LAST_PRICE",Settings.COB,Settings.COB))) -> -18.5 | AO26: =AN26/10000 -> -0.00185
G27: EOBSVC5 ICPL Curncy | H27: 5Y | L27: =IF(G27="","",IF(Settings.COB=TODAY(),_xll.BDP(G27,"LAST_PRICE"),_xll.BDH(G27,"LAST_PRICE",Settings.COB,Settings.COB))) -> 12.4 | M27: =L27/10000 -> 0.00124 | O27: EUSA7 ICPL Curncy | P27: 7Y | Q27: =IF(O27="","",IF(Settings.COB=TODAY(),_xll.BDP(O27,"LAST_PRICE"),_xll.BDH(O27,"LAST_PRICE",Settings.COB,Settings.COB))) -> -0.153 | R27: =Q27/100 -> -0.00153 | T27: EUSW11V3 ICPL Curncy | U27: 11Y | Y27: =IF(T27="","",IF(Settings.COB=TODAY(),_xll.BDP(T27,"LAST_PRICE"),_xll.BDH(T27,"LAST_PRICE",Settings.COB,Settings.COB))) -> -0.043 | Z27: =Y27/100 -> -0.00043 | AD27: =IF(AB27="","",IF(Settings.COB=TODAY(),_xll.BDP(AB27,"LAST_PRICE"),_xll.BDH(AB27,"LAST_PRICE",Settings.COB,Settings.COB))) | AI27: =IF(AG27="","",IF(Settings.COB=TODAY(),_xll.BDP(AG27,"LAST_PRICE"),_xll.BDH(AG27,"LAST_PRICE",Settings.COB,Settings.COB))) | AL27: EUBS5 ICPL Curncy | AM27: 5Y | AN27: =IF(AL27="","",IF(Settings.COB=TODAY(),_xll.BDP(AL27,"LAST_PRICE"),_xll.BDH(AL27,"LAST_PRICE",Settings.COB,Settings.COB))) -> -20.5 | AO27: =AN27/10000 -> -0.00205
G28: EOBSVC6 ICPL Curncy | H28: 6Y | L28: =IF(G28="","",IF(Settings.COB=TODAY(),_xll.BDP(G28,"LAST_PRICE"),_xll.BDH(G28,"LAST_PRICE",Settings.COB,Settings.COB))) -> 12.5 | M28: =L28/10000 -> 0.00125 | O28: EUSA8 ICPL Curncy | P28: 8Y | Q28: =IF(O28="","",IF(Settings.COB=TODAY(),_xll.BDP(O28,"LAST_PRICE"),_xll.BDH(O28,"LAST_PRICE",Settings.COB,Settings.COB))) -> -0.114 | R28: =Q28/100 -> -0.00114 | T28: EUSW12V3 ICPL Curncy | U28: 12Y | Y28: =IF(T28="","",IF(Settings.COB=TODAY(),_xll.BDP(T28,"LAST_PRICE"),_xll.BDH(T28,"LAST_PRICE",Settings.COB,Settings.COB))) -> -0.002 | Z28: =Y28/100 -> -2e-05 | AD28: =IF(AB28="","",IF(Settings.COB=TODAY(),_xll.BDP(AB28,"LAST_PRICE"),_xll.BDH(AB28,"LAST_PRICE",Settings.COB,Settings.COB))) | AI28: =IF(AG28="","",IF(Settings.COB=TODAY(),_xll.BDP(AG28,"LAST_PRICE"),_xll.BDH(AG28,"LAST_PRICE",Settings.COB,Settings.COB))) | AL28: EUBS6 ICPL Curncy | AM28: 6Y | AN28: =IF(AL28="","",IF(Settings.COB=TODAY(),_xll.BDP(AL28,"LAST_PRICE"),_xll.BDH(AL28,"LAST_PRICE",Settings.COB,Settings.COB))) -> -21.5 | AO28: =AN28/10000 -> -0.00215
G29: EOBSVC7 ICPL Curncy | H29: 7Y | L29: =IF(G29="","",IF(Settings.COB=TODAY(),_xll.BDP(G29,"LAST_PRICE"),_xll.BDH(G29,"LAST_PRICE",Settings.COB,Settings.COB))) -> 12.6 | M29: =L29/10000 -> 0.00126 | O29: EUSA9 ICPL Curncy | P29: 9Y | Q29: =IF(O29="","",IF(Settings.COB=TODAY(),_xll.BDP(O29,"LAST_PRICE"),_xll.BDH(O29,"LAST_PRICE",Settings.COB,Settings.COB))) -> -0.075 | R29: =Q29/100 -> -0.00075 | T29: EUSW15V3 ICPL Curncy | U29: 15Y | Y29: =IF(T29="","",IF(Settings.COB=TODAY(),_xll.BDP(T29,"LAST_PRICE"),_xll.BDH(T29,"LAST_PRICE",Settings.COB,Settings.COB))) -> 0.095 | Z29: =Y29/100 -> 0.00095 | AD29: =IF(AB29="","",IF(Settings.COB=TODAY(),_xll.BDP(AB29,"LAST_PRICE"),_xll.BDH(AB29,"LAST_PRICE",Settings.COB,Settings.COB))) | AI29: =IF(AG29="","",IF(Settings.COB=TODAY(),_xll.BDP(AG29,"LAST_PRICE"),_xll.BDH(AG29,"LAST_PRICE",Settings.COB,Settings.COB))) | AL29: EUBS7 ICPL Curncy | AM29: 7Y | AN29: =IF(AL29="","",IF(Settings.COB=TODAY(),_xll.BDP(AL29,"LAST_PRICE"),_xll.BDH(AL29,"LAST_PRICE",Settings.COB,Settings.COB))) -> -22.125 | AO29: =AN29/10000 -> -0.0022125
G30: EOBSVC8 ICPL Curncy | H30: 8Y | L30: =IF(G30="","",IF(Settings.COB=TODAY(),_xll.BDP(G30,"LAST_PRICE"),_xll.BDH(G30,"LAST_PRICE",Settings.COB,Settings.COB))) -> 12.7 | M30: =L30/10000 -> 0.00127 | O30: EUSA10 ICPL Curncy | P30: 10Y | Q30: =IF(O30="","",IF(Settings.COB=TODAY(),_xll.BDP(O30,"LAST_PRICE"),_xll.BDH(O30,"LAST_PRICE",Settings.COB,Settings.COB))) -> -0.036 | R30: =Q30/100 -> -0.00036 | T30: EUSW20V3 ICPL Curncy | U30: 20Y | Y30: =IF(T30="","",IF(Settings.COB=TODAY(),_xll.BDP(T30,"LAST_PRICE"),_xll.BDH(T30,"LAST_PRICE",Settings.COB,Settings.COB))) -> 0.157 | Z30: =Y30/100 -> 0.00157 | AD30: =IF(AB30="","",IF(Settings.COB=TODAY(),_xll.BDP(AB30,"LAST_PRICE"),_xll.BDH(AB30,"LAST_PRICE",Settings.COB,Settings.COB))) | AI30: =IF(AG30="","",IF(Settings.COB=TODAY(),_xll.BDP(AG30,"LAST_PRICE"),_xll.BDH(AG30,"LAST_PRICE",Settings.COB,Settings.COB))) | AL30: EUBS8 ICPL Curncy | AM30: 8Y | AN30: =IF(AL30="","",IF(Settings.COB=TODAY(),_xll.BDP(AL30,"LAST_PRICE"),_xll.BDH(AL30,"LAST_PRICE",Settings.COB,Settings.COB))) -> -22.375 | AO30: =AN30/10000 -> -0.0022375
G31: EOBSVC9 ICPL Curncy | H31: 9Y | L31: =IF(G31="","",IF(Settings.COB=TODAY(),_xll.BDP(G31,"LAST_PRICE"),_xll.BDH(G31,"LAST_PRICE",Settings.COB,Settings.COB))) -> 12.8 | M31: =L31/10000 -> 0.00128 | O31: EUSA11 ICPL Curncy | P31: 11Y | Q31: =IF(O31="","",IF(Settings.COB=TODAY(),_xll.BDP(O31,"LAST_PRICE"),_xll.BDH(O31,"LAST_PRICE",Settings.COB,Settings.COB))) -> 0.002 | R31: =Q31/100 -> 2e-05 | T31: EUSW25V3 ICPL Curncy | U31: 25Y | Y31: =IF(T31="","",IF(Settings.COB=TODAY(),_xll.BDP(T31,"LAST_PRICE"),_xll.BDH(T31,"LAST_PRICE",Settings.COB,Settings.COB))) -> 0.143 | Z31: =Y31/100 -> 0.00143 | AD31: =IF(AB31="","",IF(Settings.COB=TODAY(),_xll.BDP(AB31,"LAST_PRICE"),_xll.BDH(AB31,"LAST_PRICE",Settings.COB,Settings.COB))) | AI31: =IF(AG31="","",IF(Settings.COB=TODAY(),_xll.BDP(AG31,"LAST_PRICE"),_xll.BDH(AG31,"LAST_PRICE",Settings.COB,Settings.COB))) | AL31: EUBS9 ICPL Curncy | AM31: 9Y | AN31: =IF(AL31="","",IF(Settings.COB=TODAY(),_xll.BDP(AL31,"LAST_PRICE"),_xll.BDH(AL31,"LAST_PRICE",Settings.COB,Settings.COB))) -> -22.375 | AO31: =AN31/10000 -> -0.0022375
G32: EOBSVC10 ICPL Curncy | H32: 10Y | L32: =IF(G32="","",IF(Settings.COB=TODAY(),_xll.BDP(G32,"LAST_PRICE"),_xll.BDH(G32,"LAST_PRICE",Settings.COB,Settings.COB))) -> 12.9 | M32: =L32/10000 -> 0.00129 | O32: EUSA12 ICPL Curncy | P32: 12Y | Q32: =IF(O32="","",IF(Settings.COB=TODAY(),_xll.BDP(O32,"LAST_PRICE"),_xll.BDH(O32,"LAST_PRICE",Settings.COB,Settings.COB))) -> 0.038 | R32: =Q32/100 -> 0.00038 | T32: EUSW30V3 ICPL Curncy | U32: 30Y | Y32: =IF(T32="","",IF(Settings.COB=TODAY(),_xll.BDP(T32,"LAST_PRICE"),_xll.BDH(T32,"LAST_PRICE",Settings.COB,Settings.COB))) -> 0.101 | Z32: =Y32/100 -> 0.00101 | AD32: =IF(AB32="","",IF(Settings.COB=TODAY(),_xll.BDP(AB32,"LAST_PRICE"),_xll.BDH(AB32,"LAST_PRICE",Settings.COB,Settings.COB))) | AI32: =IF(AG32="","",IF(Settings.COB=TODAY(),_xll.BDP(AG32,"LAST_PRICE"),_xll.BDH(AG32,"LAST_PRICE",Settings.COB,Settings.COB))) | AL32: EUBS10 ICPL Curncy | AM32: 10Y | AN32: =IF(AL32="","",IF(Settings.COB=TODAY(),_xll.BDP(AL32,"LAST_PRICE"),_xll.BDH(AL32,"LAST_PRICE",Settings.COB,Settings.COB))) -> -22.375 | AO32: =AN32/10000 -> -0.0022375
G33: EOBSVC11 ICPL Curncy | H33: 11Y | L33: =IF(G33="","",IF(Settings.COB=TODAY(),_xll.BDP(G33,"LAST_PRICE"),_xll.BDH(G33,"LAST_PRICE",Settings.COB,Settings.COB))) -> 13 | M33: =L33/10000 -> 0.0013 | O33: EUSA15 ICPL Curncy | P33: 15Y | Q33: =IF(O33="","",IF(Settings.COB=TODAY(),_xll.BDP(O33,"LAST_PRICE"),_xll.BDH(O33,"LAST_PRICE",Settings.COB,Settings.COB))) -> 0.125 | R33: =Q33/100 -> 0.00125 | T33: EUSW40V3 ICPL Curncy | U33: 40Y | Y33: =IF(T33="","",IF(Settings.COB=TODAY(),_xll.BDP(T33,"LAST_PRICE"),_xll.BDH(T33,"LAST_PRICE",Settings.COB,Settings.COB))) -> 0.033 | Z33: =Y33/100 -> 0.00033 | AD33: =IF(AB33="","",IF(Settings.COB=TODAY(),_xll.BDP(AB33,"LAST_PRICE"),_xll.BDH(AB33,"LAST_PRICE",Settings.COB,Settings.COB))) | AI33: =IF(AG33="","",IF(Settings.COB=TODAY(),_xll.BDP(AG33,"LAST_PRICE"),_xll.BDH(AG33,"LAST_PRICE",Settings.COB,Settings.COB))) | AL33: EUBS12 ICPL Curncy | AM33: 12Y | AN33: =IF(AL33="","",IF(Settings.COB=TODAY(),_xll.BDP(AL33,"LAST_PRICE"),_xll.BDH(AL33,"LAST_PRICE",Settings.COB,Settings.COB))) -> -22 | AO33: =AN33/10000 -> -0.0022
G34: EOBSVC12 ICPL Curncy | H34: 12Y | L34: =IF(G34="","",IF(Settings.COB=TODAY(),_xll.BDP(G34,"LAST_PRICE"),_xll.BDH(G34,"LAST_PRICE",Settings.COB,Settings.COB))) -> 13 | M34: =L34/10000 -> 0.0013 | O34: EUSA20 ICPL Curncy | P34: 20Y | Q34: =IF(O34="","",IF(Settings.COB=TODAY(),_xll.BDP(O34,"LAST_PRICE"),_xll.BDH(O34,"LAST_PRICE",Settings.COB,Settings.COB))) -> 0.176 | R34: =Q34/100 -> 0.00176 | T34: EUSW50V3 ICPL Curncy | U34: 50Y | Y34: =IF(T34="","",IF(Settings.COB=TODAY(),_xll.BDP(T34,"LAST_PRICE"),_xll.BDH(T34,"LAST_PRICE",Settings.COB,Settings.COB))) -> -0.033 | Z34: =Y34/100 -> -0.00033 | AD34: =IF(AB34="","",IF(Settings.COB=TODAY(),_xll.BDP(AB34,"LAST_PRICE"),_xll.BDH(AB34,"LAST_PRICE",Settings.COB,Settings.COB))) | AI34: =IF(AG34="","",IF(Settings.COB=TODAY(),_xll.BDP(AG34,"LAST_PRICE"),_xll.BDH(AG34,"LAST_PRICE",Settings.COB,Settings.COB))) | AL34: EUBS15 ICPL Curncy | AM34: 15Y | AN34: =IF(AL34="","",IF(Settings.COB=TODAY(),_xll.BDP(AL34,"LAST_PRICE"),_xll.BDH(AL34,"LAST_PRICE",Settings.COB,Settings.COB))) -> -19.625 | AO34: =AN34/10000 -> -0.0019625
G35: EOBSVC15 ICPL Curncy | H35: 15Y | L35: =IF(G35="","",IF(Settings.COB=TODAY(),_xll.BDP(G35,"LAST_PRICE"),_xll.BDH(G35,"LAST_PRICE",Settings.COB,Settings.COB))) -> 13 | M35: =L35/10000 -> 0.0013 | O35: EUSA25 ICPL Curncy | P35: 25Y | Q35: =IF(O35="","",IF(Settings.COB=TODAY(),_xll.BDP(O35,"LAST_PRICE"),_xll.BDH(O35,"LAST_PRICE",Settings.COB,Settings.COB))) -> 0.155 | R35: =Q35/100 -> 0.00155 | AD35: =IF(AB35="","",IF(Settings.COB=TODAY(),_xll.BDP(AB35,"LAST_PRICE"),_xll.BDH(AB35,"LAST_PRICE",Settings.COB,Settings.COB))) | AI35: =IF(AG35="","",IF(Settings.COB=TODAY(),_xll.BDP(AG35,"LAST_PRICE"),_xll.BDH(AG35,"LAST_PRICE",Settings.COB,Settings.COB))) | AL35: EUBS20 ICPL Curncy | AM35: 20Y | AN35: =IF(AL35="","",IF(Settings.COB=TODAY(),_xll.BDP(AL35,"LAST_PRICE"),_xll.BDH(AL35,"LAST_PRICE",Settings.COB,Settings.COB))) -> -13.75 | AO35: =AN35/10000 -> -0.001375
G36: EOBSVC20 ICPL Curncy | H36: 20Y | L36: =IF(G36="","",IF(Settings.COB=TODAY(),_xll.BDP(G36,"LAST_PRICE"),_xll.BDH(G36,"LAST_PRICE",Settings.COB,Settings.COB))) -> 12.9 | M36: =L36/10000 -> 0.00129 | O36: EUSA30 ICPL Curncy | P36: 30Y | Q36: =IF(O36="","",IF(Settings.COB=TODAY(),_xll.BDP(O36,"LAST_PRICE"),_xll.BDH(O36,"LAST_PRICE",Settings.COB,Settings.COB))) -> 0.108 | R36: =Q36/100 -> 0.00108 | Y36: =IF(T36="","",IF(Settings.COB=TODAY(),_xll.BDP(T36,"LAST_PRICE"),_xll.BDH(T36,"LAST_PRICE",Settings.COB,Settings.COB))) | AD36: =IF(AB36="","",IF(Settings.COB=TODAY(),_xll.BDP(AB36,"LAST_PRICE"),_xll.BDH(AB36,"LAST_PRICE",Settings.COB,Settings.COB))) | AI36: =IF(AG36="","",IF(Settings.COB=TODAY(),_xll.BDP(AG36,"LAST_PRICE"),_xll.BDH(AG36,"LAST_PRICE",Settings.COB,Settings.COB))) | AL36: EUBS25 ICPL Curncy | AM36: 25Y | AN36: =IF(AL36="","",IF(Settings.COB=TODAY(),_xll.BDP(AL36,"LAST_PRICE"),_xll.BDH(AL36,"LAST_PRICE",Settings.COB,Settings.COB))) -> -8.125 | AO36: =AN36/10000 -> -0.0008125
G37: EOBSVC25 ICPL Curncy | H37: 25Y | L37: =IF(G37="","",IF(Settings.COB=TODAY(),_xll.BDP(G37,"LAST_PRICE"),_xll.BDH(G37,"LAST_PRICE",Settings.COB,Settings.COB))) -> 12.8 | M37: =L37/10000 -> 0.00128 | O37: EUSA40 ICPL Curncy | P37: 40Y | Q37: =IF(O37="","",IF(Settings.COB=TODAY(),_xll.BDP(O37,"LAST_PRICE"),_xll.BDH(O37,"LAST_PRICE",Settings.COB,Settings.COB))) -> 0.034 | R37: =Q37/100 -> 0.00034 | Y37: =IF(T37="","",IF(Settings.COB=TODAY(),_xll.BDP(T37,"LAST_PRICE"),_xll.BDH(T37,"LAST_PRICE",Settings.COB,Settings.COB))) | AD37: =IF(AB37="","",IF(Settings.COB=TODAY(),_xll.BDP(AB37,"LAST_PRICE"),_xll.BDH(AB37,"LAST_PRICE",Settings.COB,Settings.COB))) | AI37: =IF(AG37="","",IF(Settings.COB=TODAY(),_xll.BDP(AG37,"LAST_PRICE"),_xll.BDH(AG37,"LAST_PRICE",Settings.COB,Settings.COB))) | AL37: EUBS30 ICPL Curncy | AM37: 30Y | AN37: =IF(AL37="","",IF(Settings.COB=TODAY(),_xll.BDP(AL37,"LAST_PRICE"),_xll.BDH(AL37,"LAST_PRICE",Settings.COB,Settings.COB))) -> -4.25 | AO37: =AN37/10000 -> -0.000425
G38: EOBSVC30 ICPL Curncy | H38: 30Y | L38: =IF(G38="","",IF(Settings.COB=TODAY(),_xll.BDP(G38,"LAST_PRICE"),_xll.BDH(G38,"LAST_PRICE",Settings.COB,Settings.COB))) -> 12.7 | M38: =L38/10000 -> 0.00127 | O38: EUSA50 ICPL Curncy | P38: 50Y | Q38: =IF(O38="","",IF(Settings.COB=TODAY(),_xll.BDP(O38,"LAST_PRICE"),_xll.BDH(O38,"LAST_PRICE",Settings.COB,Settings.COB))) -> -0.037 | R38: =Q38/100 -> -0.00037 | Y38: =IF(T38="","",IF(Settings.COB=TODAY(),_xll.BDP(T38,"LAST_PRICE"),_xll.BDH(T38,"LAST_PRICE",Settings.COB,Settings.COB))) | AD38: =IF(AB38="","",IF(Settings.COB=TODAY(),_xll.BDP(AB38,"LAST_PRICE"),_xll.BDH(AB38,"LAST_PRICE",Settings.COB,Settings.COB))) | AI38: =IF(AG38="","",IF(Settings.COB=TODAY(),_xll.BDP(AG38,"LAST_PRICE"),_xll.BDH(AG38,"LAST_PRICE",Settings.COB,Settings.COB)))
G39: EOBSVC40 ICPL Curncy | H39: 40Y | L39: =IF(G39="","",IF(Settings.COB=TODAY(),_xll.BDP(G39,"LAST_PRICE"),_xll.BDH(G39,"LAST_PRICE",Settings.COB,Settings.COB))) -> 12.2 | M39: =L39/10000 -> 0.00122 | Q39: =IF(O39="","",IF(Settings.COB=TODAY(),_xll.BDP(O39,"LAST_PRICE"),_xll.BDH(O39,"LAST_PRICE",Settings.COB,Settings.COB))) | Y39: =IF(T39="","",IF(Settings.COB=TODAY(),_xll.BDP(T39,"LAST_PRICE"),_xll.BDH(T39,"LAST_PRICE",Settings.COB,Settings.COB))) | AD39: =IF(AB39="","",IF(Settings.COB=TODAY(),_xll.BDP(AB39,"LAST_PRICE"),_xll.BDH(AB39,"LAST_PRICE",Settings.COB,Settings.COB))) | AI39: =IF(AG39="","",IF(Settings.COB=TODAY(),_xll.BDP(AG39,"LAST_PRICE"),_xll.BDH(AG39,"LAST_PRICE",Settings.COB,Settings.COB)))
G40: EOBSVC50 ICPL Curncy | H40: 50Y | L40: =IF(G40="","",IF(Settings.COB=TODAY(),_xll.BDP(G40,"LAST_PRICE"),_xll.BDH(G40,"LAST_PRICE",Settings.COB,Settings.COB))) -> 11.6 | M40: =L40/10000 -> 0.00116 | Q40: =IF(O40="","",IF(Settings.COB=TODAY(),_xll.BDP(O40,"LAST_PRICE"),_xll.BDH(O40,"LAST_PRICE",Settings.COB,Settings.COB))) | Y40: =IF(T40="","",IF(Settings.COB=TODAY(),_xll.BDP(T40,"LAST_PRICE"),_xll.BDH(T40,"LAST_PRICE",Settings.COB,Settings.COB))) | AD40: =IF(AB40="","",IF(Settings.COB=TODAY(),_xll.BDP(AB40,"LAST_PRICE"),_xll.BDH(AB40,"LAST_PRICE",Settings.COB,Settings.COB))) | AI40: =IF(AG40="","",IF(Settings.COB=TODAY(),_xll.BDP(AG40,"LAST_PRICE"),_xll.BDH(AG40,"LAST_PRICE",Settings.COB,Settings.COB)))
G41: EUSW1V3 ICPL Curncy | H41: 1Y | L41: =IF(G41="","",IF(Settings.COB=TODAY(),_xll.BDP(G41,"LAST_PRICE"),_xll.BDH(G41,"LAST_PRICE",Settings.COB,Settings.COB))) -> -0.371 | M41: =L41/100 -> -0.00371
G42: EUSW2V3 ICPL Curncy | H42: 2Y | L42: =IF(G42="","",IF(Settings.COB=TODAY(),_xll.BDP(G42,"LAST_PRICE"),_xll.BDH(G42,"LAST_PRICE",Settings.COB,Settings.COB))) -> -0.38 | M42: =L42/100 -> -0.0038
G43: EUSW3V3 ICPL Curncy | H43: 3Y | L43: =IF(G43="","",IF(Settings.COB=TODAY(),_xll.BDP(G43,"LAST_PRICE"),_xll.BDH(G43,"LAST_PRICE",Settings.COB,Settings.COB))) -> -0.367 | M43: =L43/100 -> -0.00367
...

Sheet EUR OIS
C4: MARKETDATAPROPERTIES | F4: OIS | L4: LIBOROISBASISSPREADS | O4: SWAPS
F5: Term | G5: Rate | H5: StartDate | I5: EndDate | J5: Use | L5: Term | M5: Rate | O5: Term | P5: Rate
C6: Currency | D6: EUR | F6: ='CURVE MKT DATA'!H7 -> ON | G6: ='CURVE MKT DATA'!M7 -> -0.00442 | J6: TRUE | L6: ='CURVE MKT DATA'!H23 -> 1Y | M6: ='CURVE MKT DATA'!M23 -> 0.0012 | O6: ='CURVE MKT DATA'!H41 -> 1Y | P6: ='CURVE MKT DATA'!M41 -> -0.00371
C7: CurveType | D7: OIS | F7: ='CURVE MKT DATA'!H8 -> ECB1 | G7: ='CURVE MKT DATA'!M8 -> -0.00456 | H7: ='CURVE MKT DATA'!J8 -> 43957 | I7: ='CURVE MKT DATA'!K8 -> 43991 | J7: TRUE | L7: ='CURVE MKT DATA'!H24 -> 2Y | M7: ='CURVE MKT DATA'!M24 -> 0.00118 | O7: ='CURVE MKT DATA'!H42 -> 2Y | P7: ='CURVE MKT DATA'!M42 -> -0.0038
C8: CurveIndexFrequency | D8: DAILY | F8: ='CURVE MKT DATA'!H9 -> ECB2 | G8: ='CURVE MKT DATA'!M9 -> -0.00468 | H8: ='CURVE MKT DATA'!J9 -> 43992 | I8: ='CURVE MKT DATA'!K9 -> 44033 | J8: TRUE | L8: ='CURVE MKT DATA'!H25 -> 3Y | M8: ='CURVE MKT DATA'!M25 -> 0.00121 | O8: ='CURVE MKT DATA'!H43 -> 3Y | P8: ='CURVE MKT DATA'!M43 -> -0.00367
C9: AsOfDate | D9: =Settings.COB -> 43923 | F9: ='CURVE MKT DATA'!H10 -> ECB3 | G9: ='CURVE MKT DATA'!M10 -> -0.00476 | H9: ='CURVE MKT DATA'!J10 -> 44034 | I9: ='CURVE MKT DATA'!K10 -> 44089 | J9: TRUE | L9: ='CURVE MKT DATA'!H26 -> 4Y | M9: ='CURVE MKT DATA'!M26 -> 0.00123 | O9: ='CURVE MKT DATA'!H44 -> 4Y | P9: ='CURVE MKT DATA'!M44 -> -0.00337
F10: ='CURVE MKT DATA'!H11 -> ECB4 | G10: ='CURVE MKT DATA'!M11 -> -0.00495 | H10: ='CURVE MKT DATA'!J11 -> 44090 | I10: ='CURVE MKT DATA'!K11 -> 44138 | J10: TRUE | L10: ='CURVE MKT DATA'!H27 -> 5Y | M10: ='CURVE MKT DATA'!M27 -> 0.00124 | O10: ='CURVE MKT DATA'!H45 -> 5Y | P10: ='CURVE MKT DATA'!M45 -> -0.00297
L11: ='CURVE MKT DATA'!H28 -> 6Y | M11: ='CURVE MKT DATA'!M28 -> 0.00125 | O11: ='CURVE MKT DATA'!H46 -> 6Y | P11: ='CURVE MKT DATA'!M46 -> -0.0026
C12: Create Market Data Handle | L12: ='CURVE MKT DATA'!H29 -> 7Y | M12: ='CURVE MKT DATA'!M29 -> 0.00126 | O12: ='CURVE MKT DATA'!H47 -> 7Y | P12: ='CURVE MKT DATA'!M47 -> -0.00218
C13: Handle Name | D13: EUR_OIS_CURVE_MARKETDATA | L13: ='CURVE MKT DATA'!H30 -> 8Y | M13: ='CURVE MKT DATA'!M30 -> 0.00127 | O13: ='CURVE MKT DATA'!H48 -> 8Y | P13: ='CURVE MKT DATA'!M48 -> -0.00174
C14: Market Data Handle | D14: =_xll.meLWOCurveMarketDataCreate(D13,C4,C6:D9,F4,F6:J31,L4,L6:M31,O4,O6:P31) -> EUR_OIS_CURVE_MARKETDATA@2:4 | L14: ='CURVE MKT DATA'!H31 -> 9Y | M14: ='CURVE MKT DATA'!M31 -> 0.00128 | O14: ='CURVE MKT DATA'!H49 -> 9Y | P14: ='CURVE MKT DATA'!M49 -> -0.0013
L15: ='CURVE MKT DATA'!H32 -> 10Y | M15: ='CURVE MKT DATA'!M32 -> 0.00129 | O15: ='CURVE MKT DATA'!H50 -> 10Y | P15: ='CURVE MKT DATA'!M50 -> -0.00086
L16: ='CURVE MKT DATA'!H33 -> 11Y | M16: ='CURVE MKT DATA'!M33 -> 0.0013 | O16: ='CURVE MKT DATA'!H51 -> 11Y | P16: ='CURVE MKT DATA'!M51 -> -0.00043
L17: ='CURVE MKT DATA'!H34 -> 12Y | M17: ='CURVE MKT DATA'!M34 -> 0.0013 | O17: ='CURVE MKT DATA'!H52 -> 12Y | P17: ='CURVE MKT DATA'!M52 -> -2e-05
L18: ='CURVE MKT DATA'!H35 -> 15Y | M18: ='CURVE MKT DATA'!M35 -> 0.0013 | O18: ='CURVE MKT DATA'!H53 -> 15Y | P18: ='CURVE MKT DATA'!M53 -> 0.00095
L19: ='CURVE MKT DATA'!H36 -> 20Y | M19: ='CURVE MKT DATA'!M36 -> 0.00129 | O19: ='CURVE MKT DATA'!H54 -> 20Y | P19: ='CURVE MKT DATA'!M54 -> 0.00157
C20: Curve Dictionary | L20: ='CURVE MKT DATA'!H37 -> 25Y | M20: ='CURVE MKT DATA'!M37 -> 0.00128 | O20: ='CURVE MKT DATA'!H55 -> 25Y | P20: ='CURVE MKT DATA'!M55 -> 0.00143
C21: Handle Name | D21: EUR_OIS_CURVE | L21: ='CURVE MKT DATA'!H38 -> 30Y | M21: ='CURVE MKT DATA'!M38 -> 0.00127 | O21: ='CURVE MKT DATA'!H56 -> 30Y | P21: ='CURVE MKT DATA'!M56 -> 0.00101
C22: Curve Generator | D22: EUR_OIS | L22: ='CURVE MKT DATA'!H39 -> 40Y | M22: ='CURVE MKT DATA'!M39 -> 0.00122 | O22: ='CURVE MKT DATA'!H57 -> 40Y | P22: ='CURVE MKT DATA'!M57 -> 0.00033
C23: Domestic Curve Collection | D23: EURYC | L23: ='CURVE MKT DATA'!H40 -> 50Y | M23: ='CURVE MKT DATA'!M40 -> 0.00116 | O23: ='CURVE MKT DATA'!H58 -> 50Y | P23: ='CURVE MKT DATA'!M58 -> -0.00033
C24: Foreign Curve Collection | L24: 55Y | M24: =M23 -> 0.00116 | O24: 55Y | P24: =P23 -> -0.00033 | R24: Extrapolated
C27: Curve Build
C28: Handle Name | D28: {=_xll.meLWOCurveCalibrate(D21,D22,D14,D23,D24)} -> EUR_OIS_CURVE@9:4
C29: Curve Collection | D29: EURYC
C30: Curve Index | D30: OIS:EUROIS:EURDF:EURDF_EURCSA:EURDF_NOCSA
C31: Calibration Time Taken | D31: 0.02100 sec
C32: Curve Loaded | D32: =_xll.meLWOExists(D28,"CURVE") -> TRUE

Sheet EUR SWAP 3ML
C4: MARKETDATAPROPERTIES | F4: LIBORFIXINGS | I4: FUTURES | O4: SWAPS
C5: Currency | D5: EUR | F5: Term | G5: Rate | I5: Term | J5: StartDate | K5: EndDate | L5: Rate | M5: Volatility | O5: Term | P5: Rate | Q5: Use
C6: CurveType | D6: SWAP | F6: ='CURVE MKT DATA'!U7 -> 1M | G6: ='CURVE MKT DATA'!Z7 -> -0.0038943 | I6: ='CURVE MKT DATA'!V11 -> ER1 | J6: ='CURVE MKT DATA'!W11 -> 43999 | K6: ='CURVE MKT DATA'!X11 -> 44090 | L6: ='CURVE MKT DATA'!Z11 -> 100.345 | M6: 0.005 | O6: ='CURVE MKT DATA'!U19 -> 3Y | P6: ='CURVE MKT DATA'!Z19 -> -0.00367 | Q6: TRUE
C7: CurveIndexFrequency | D7: QUARTERLY | F7: ='CURVE MKT DATA'!U8 -> 3M | G7: ='CURVE MKT DATA'!Z8 -> -0.0024114 | I7: ='CURVE MKT DATA'!V12 -> ER2 | J7: ='CURVE MKT DATA'!W12 -> 44090 | K7: ='CURVE MKT DATA'!X12 -> 44181 | L7: ='CURVE MKT DATA'!Z12 -> 100.375 | M7: 0.005 | O7: ='CURVE MKT DATA'!U20 -> 4Y | P7: ='CURVE MKT DATA'!Z20 -> -0.00337 | Q7: TRUE
C8: AsOfDate | D8: =Settings.COB -> 43923 | F8: ='CURVE MKT DATA'!U9 -> 6M | G8: ='CURVE MKT DATA'!Z9 -> -0.0017786 | I8: ='CURVE MKT DATA'!V13 -> ER3 | J8: ='CURVE MKT DATA'!W13 -> 44181 | K8: ='CURVE MKT DATA'!X13 -> 44272 | L8: ='CURVE MKT DATA'!Z13 -> 100.395 | M8: 0.005 | O8: ='CURVE MKT DATA'!U21 -> 5Y | P8: ='CURVE MKT DATA'!Z21 -> -0.00297 | Q8: TRUE
F9: ='CURVE MKT DATA'!U10 -> 12M | G9: ='CURVE MKT DATA'!Z10 -> -0.0016443 | I9: ='CURVE MKT DATA'!V14 -> ER4 | J9: ='CURVE MKT DATA'!W14 -> 44272 | K9: ='CURVE MKT DATA'!X14 -> 44363 | L9: ='CURVE MKT DATA'!Z14 -> 100.4 | M9: 0.005 | O9: ='CURVE MKT DATA'!U22 -> 6Y | P9: ='CURVE MKT DATA'!Z22 -> -0.0026 | Q9: TRUE
O10: ='CURVE MKT DATA'!U23 -> 7Y | P10: ='CURVE MKT DATA'!Z23 -> -0.00218 | Q10: TRUE
O11: ='CURVE MKT DATA'!U24 -> 8Y | P11: ='CURVE MKT DATA'!Z24 -> -0.00174 | Q11: TRUE
C12: Create Market Data Handle | O12: ='CURVE MKT DATA'!U25 -> 9Y | P12: ='CURVE MKT DATA'!Z25 -> -0.0013 | Q12: TRUE
C13: Handle Name | D13: EUR_SWAP_3M_CURVE_MARKETDATA | O13: ='CURVE MKT DATA'!U26 -> 10Y | P13: ='CURVE MKT DATA'!Z26 -> -0.00086 | Q13: TRUE
C14: Market Data Handle | D14: =_xll.meLWOCurveMarketDataCreate(D13,C4,C5:D10,F4,F6:G10,I4,I6:M31,O4,O6:Q31) -> EUR_SWAP_3M_CURVE_MARKETDATA@10:2 | O14: ='CURVE MKT DATA'!U27 -> 11Y | P14: ='CURVE MKT DATA'!Z27 -> -0.00043 | Q14: TRUE
O15: ='CURVE MKT DATA'!U28 -> 12Y | P15: ='CURVE MKT DATA'!Z28 -> -2e-05 | Q15: TRUE
O16: ='CURVE MKT DATA'!U29 -> 15Y | P16: ='CURVE MKT DATA'!Z29 -> 0.00095 | Q16: TRUE
O17: ='CURVE MKT DATA'!U30 -> 20Y | P17: ='CURVE MKT DATA'!Z30 -> 0.00157 | Q17: TRUE
O18: ='CURVE MKT DATA'!U31 -> 25Y | P18: ='CURVE MKT DATA'!Z31 -> 0.00143 | Q18: TRUE
O19: ='CURVE MKT DATA'!U32 -> 30Y | P19: ='CURVE MKT DATA'!Z32 -> 0.00101 | Q19: TRUE
C20: Curve Dictionary | O20: ='CURVE MKT DATA'!U33 -> 40Y | P20: ='CURVE MKT DATA'!Z33 -> 0.00033 | Q20: TRUE
C21: Handle Name | D21: EUR_SWAP_3M_CURVE | O21: ='CURVE MKT DATA'!U34 -> 50Y | P21: ='CURVE MKT DATA'!Z34 -> -0.00033 | Q21: TRUE
C22: Curve Generator | D22: EUR_SWAP_3M | O22: 55Y | P22: =P21 -> -0.00033 | Q22: TRUE | R22: Extrapolated
C23: Domestic Curve Collection | D23: EURYC
C24: Foreign Curve Collection
C27: Curve Build
C28: Handle Name | D28: {=IF('EUR OIS'!$D$32,_xll.meLWOCurveCalibrate(D21,D22,D14,D23,D24),"LOAD DEPENDENCY CURVE")} -> EUR_SWAP_3M_CURVE@11:2
C29: Curve Collection | D29: EURYC
C30: Curve Index | D30: STD:EUR3ML
C31: Calibration Time Taken | D31: 0.00900 sec
C32: Curve Loaded | D32: =_xll.meLWOExists(D28,"CURVE") -> TRUE

Sheet EUR SWAP 6ML
C4: MARKETDATAPROPERTIES | F4: LIBORFIXINGS | I4: FRAS | L4: SWAPS
C5: Currency | D5: EUR | F5: Term | G5: Rate | I5: Term | J5: Rate | L5: Term | M5: Rate | N5: Use
C6: CurveType | D6: SWAP | F6: ='CURVE MKT DATA'!P7 -> 1M | G6: ='CURVE MKT DATA'!R7 -> -0.0038943 | I6: ='CURVE MKT DATA'!P11 -> 1X7 | J6: ='CURVE MKT DATA'!R11 -> -0.0027 | L6: ='CURVE MKT DATA'!P22 -> 2Y | M6: ='CURVE MKT DATA'!R22 -> -0.00304 | N6: TRUE
C7: CurveIndexFrequency | D7: SEMI-ANNUAL | F7: ='CURVE MKT DATA'!P8 -> 3M | G7: ='CURVE MKT DATA'!R8 -> -0.0024114 | I7: ='CURVE MKT DATA'!P12 -> 2X8 | J7: ='CURVE MKT DATA'!R12 -> -0.0028 | L7: ='CURVE MKT DATA'!P23 -> 3Y | M7: ='CURVE MKT DATA'!R23 -> -0.00292 | N7: TRUE
C8: AsOfDate | D8: =Settings.COB -> 43923 | F8: ='CURVE MKT DATA'!P9 -> 6M | G8: ='CURVE MKT DATA'!R9 -> -0.0017786 | I8: ='CURVE MKT DATA'!P13 -> 3X9 | J8: ='CURVE MKT DATA'!R13 -> -0.00289 | L8: ='CURVE MKT DATA'!P24 -> 4Y | M8: ='CURVE MKT DATA'!R24 -> -0.00262 | N8: TRUE
F9: ='CURVE MKT DATA'!P10 -> 12M | G9: ='CURVE MKT DATA'!R10 -> -0.0016443 | I9: ='CURVE MKT DATA'!P14 -> 4X10 | J9: ='CURVE MKT DATA'!R14 -> -0.003 | L9: ='CURVE MKT DATA'!P25 -> 5Y | M9: ='CURVE MKT DATA'!R25 -> -0.00223 | N9: TRUE
I10: ='CURVE MKT DATA'!P15 -> 5X11 | J10: ='CURVE MKT DATA'!R15 -> -0.0031 | L10: ='CURVE MKT DATA'!P26 -> 6Y | M10: ='CURVE MKT DATA'!R26 -> -0.0019 | N10: TRUE
I11: ='CURVE MKT DATA'!P16 -> 6X12 | J11: ='CURVE MKT DATA'!R16 -> -0.00316 | L11: ='CURVE MKT DATA'!P27 -> 7Y | M11: ='CURVE MKT DATA'!R27 -> -0.00153 | N11: TRUE
C12: Create Market Data Handle | I12: ='CURVE MKT DATA'!P17 -> 7X13 | J12: ='CURVE MKT DATA'!R17 -> -0.0032 | L12: ='CURVE MKT DATA'!P28 -> 8Y | M12: ='CURVE MKT DATA'!R28 -> -0.00114 | N12: TRUE
C13: Handle Name | D13: EUR_SWAP_6M_CURVE_MARKETDATA | I13: ='CURVE MKT DATA'!P18 -> 8X14 | J13: ='CURVE MKT DATA'!R18 -> -0.00323 | L13: ='CURVE MKT DATA'!P29 -> 9Y | M13: ='CURVE MKT DATA'!R29 -> -0.00075 | N13: TRUE
C14: Market Data Handle | D14: =_xll.meLWOCurveMarketDataCreate(D13,C4,C5:D10,F4,F6:G10,I4,I6:J31,L4,L6:N31) -> EUR_SWAP_6M_CURVE_MARKETDATA@6:2 | I14: ='CURVE MKT DATA'!P19 -> 9X15 | J14: ='CURVE MKT DATA'!R19 -> -0.00324 | L14: ='CURVE MKT DATA'!P30 -> 10Y | M14: ='CURVE MKT DATA'!R30 -> -0.00036 | N14: TRUE
I15: ='CURVE MKT DATA'!P20 -> 10X16 | J15: ='CURVE MKT DATA'!R20 -> -0.00323 | L15: ='CURVE MKT DATA'!P31 -> 11Y | M15: ='CURVE MKT DATA'!R31 -> 2e-05 | N15: TRUE
I16: ='CURVE MKT DATA'!P21 -> 11X17 | J16: ='CURVE MKT DATA'!R21 -> -0.00322 | L16: ='CURVE MKT DATA'!P32 -> 12Y | M16: ='CURVE MKT DATA'!R32 -> 0.00038 | N16: TRUE
L17: ='CURVE MKT DATA'!P33 -> 15Y | M17: ='CURVE MKT DATA'!R33 -> 0.00125 | N17: TRUE
L18: ='CURVE MKT DATA'!P34 -> 20Y | M18: ='CURVE MKT DATA'!R34 -> 0.00176 | N18: TRUE
L19: ='CURVE MKT DATA'!P35 -> 25Y | M19: ='CURVE MKT DATA'!R35 -> 0.00155 | N19: TRUE
C20: Curve Dictionary | L20: ='CURVE MKT DATA'!P36 -> 30Y | M20: ='CURVE MKT DATA'!R36 -> 0.00108 | N20: TRUE
C21: Handle Name | D21: EUR_SWAP_6M_CURVE | L21: ='CURVE MKT DATA'!P37 -> 40Y | M21: ='CURVE MKT DATA'!R37 -> 0.00034 | N21: TRUE
C22: Curve Generator | D22: EUR_SWAP_6M | L22: ='CURVE MKT DATA'!P38 -> 50Y | M22: ='CURVE MKT DATA'!R38 -> -0.00037 | N22: TRUE
C23: Domestic Curve Collection | D23: EURYC | L23: 55Y | M23: =M22 -> -0.00037 | N23: TRUE | O23: Extrapolated
C24: Foreign Curve Collection
C27: Curve Build
C28: Handle Name | D28: {=IF('EUR SWAP 3ML'!$D$32,_xll.meLWOCurveCalibrate(D21,D22,D14,D23,D24),"LOAD DEPENDENCY CURVE")} -> EUR_SWAP_6M_CURVE@23:2
C29: Curve Collection | D29: EURYC
C30: Curve Index | D30: EUR6ML
C31: Calibration Time Taken | D31: 0.00800 sec
C32: Curve Loaded | D32: =_xll.meLWOExists(D28,"CURVE") -> TRUE

Sheet CREDIT MKT DATA
D1: … BOND_GENERATORS | M1: … Bond Dates
U2: Valuation Date | V2: Settlement Date
O3: ITALIAN_BTPS_TYPE523 | U3: =Settings.COB -> 43923 | V3: =_xll.meDateFromTenor(U3,$W$3,"MOD_FOLLOWING","TGT") -> 43927 | W3: 2D
B5: BOND_GENERATOR | D5: CREDIT MARKET DATA | E5: CALC_TYP | F5: SECURITY_DES | G5: ID_ISIN | H5: ISSUE_DT | I5: INT_ACC_DT | K5: FIRST_CPN_DT | L5: PENULTIMATE_CPN_DT | M5: CPN | N5: MATURITY | R5: YAS_BOND_PX | S5: YAS_BOND_YLD | X5: Check MLIB vs BB
B6: AUD_FUTURE_10Y_NOTIONAL_BOND | D6: Bond Identifier | E6: CalcType | F6: BondDescription | G6: ISIN | H6: IssueDate | I6: AccrualStartDate | J6: RollDay | K6: FirstCouponDate | L6: LastCouponDate | M6: Coupon | N6: MaturityDate | O6: CreateBond | Q6: Tenor | R6: Price | S6: Yield | U6: MLIB_PX | V6: MLIB_YLD | X6: +/- | Y6: +/-
B7: AUD_FUTURE_3Y_NOTIONAL_BOND | D7: GTITL2Y Corp | E7: =_xll.BDP($D7,E$5) -> 523 | F7: =_xll.BDP($D7,F$5) -> BTPS 2.3 10/15/21 | G7: =_xll.BDP($D7,G$5) -> IT0005348443 | H7: =_xll.BDP($D7,H$5) -> 15/10/2018 | I7: =_xll.BDP($D7,I$5) -> 15/10/2018 | K7: =_xll.BDP($D7,K$5) -> 15/04/2019 | L7: =_xll.BDP($D7,L$5) -> 15/04/2021 | M7: =_xll.BDP($D7,M$5)% -> 0.023 | N7: =_xll.BDP($D7,N$5) -> 15/10/2021 | O7: =_xll.meLWOBondCreateFromGeneratorLVB(F7,$O$3,_xll.meUtilityLVBFromKeysValues($F$6:$N$6,F7:N7)) -> BTPS 2.3 10/15/21@18:2 | Q7: =YEAR(N7)-YEAR(Settings.COB)&"Y" -> 1Y | R7: =_xll.BDP($D7,R$5) -> 102.992 | S7: =_xll.BDP($D7,S$5)% -> 0.00331174 | U7: =_xll.meLWOBondQuote($O7,$V$3,$S7) -> 102.992 | V7: =_xll.meLWOBondYield($O7,$V$3,$U7) -> 0.0033117412 | X7: =U7-R7 -> 0 | Y7: =V7-S7 -> 1.2340993e-09
B8: AUSTRALIAN_GOVT_TYPE23_CLEAN | D8: GTITL3Y Corp | E8: =_xll.BDP($D8,E$5) -> 523 | F8: =_xll.BDP($D8,F$5) -> BTPS 0.05 01/15/23 | G8: =_xll.BDP($D8,G$5) -> IT0005384497 | H8: =_xll.BDP($D8,H$5) -> 16/09/2019 | I8: =_xll.BDP($D8,I$5) -> 16/09/2019 | K8: =_xll.BDP($D8,K$5) -> 15/01/2020 | L8: =_xll.BDP($D8,L$5) -> 15/07/2022 | M8: =_xll.BDP($D8,M$5)% -> 0.0005 | N8: =_xll.BDP($D8,N$5) -> 15/01/2023 | O8: =_xll.meLWOBondCreateFromGeneratorLVB(F8,$O$3,_xll.meUtilityLVBFromKeysValues($F$6:$N$6,F8:N8)) -> BTPS 0.05 01/15/23@21:2 | Q8: =YEAR(N8)-YEAR(Settings.COB)&"Y" -> 3Y | R8: =_xll.BDP($D8,R$5) -> 98.72 | S8: =_xll.BDP($D8,S$5)% -> 0.00515354 | U8: =_xll.meLWOBondQuote($O8,$V$3,$S8) -> 98.72 | V8: =_xll.meLWOBondYield($O8,$V$3,$U8) -> 0.0051537883 | X8: =U8-R8 -> 0 | Y8: =V8-S8 -> 2.4830346e-07
B9: AUSTRALIAN_GOVT_TYPE23_DIRTY | D9: GTITL5Y Corp | E9: =_xll.BDP($D9,E$5) -> 523 | F9: =_xll.BDP($D9,F$5) -> BTPS 0.35 02/01/25 | G9: =_xll.BDP($D9,G$5) -> IT0005386245 | H9: =_xll.BDP($D9,H$5) -> 01/10/2019 | I9: =_xll.BDP($D9,I$5) -> 01/10/2019 | K9: =_xll.BDP($D9,K$5) -> 01/02/2020 | L9: =_xll.BDP($D9,L$5) -> 01/08/2024 | M9: =_xll.BDP($D9,M$5)% -> 0.0035 | N9: =_xll.BDP($D9,N$5) -> 01/02/2025 | O9: =_xll.meLWOBondCreateFromGeneratorLVB(F9,$O$3,_xll.meUtilityLVBFromKeysValues($F$6:$N$6,F9:N9)) -> BTPS 0.35 02/01/25@22:2 | Q9: =YEAR(N9)-YEAR(Settings.COB)&"Y" -> 5Y | R9: =_xll.BDP($D9,R$5) -> 97.537 | S9: =_xll.BDP($D9,S$5)% -> 0.00873667 | U9: =_xll.meLWOBondQuote($O9,$V$3,$S9) -> 97.537 | V9: =_xll.meLWOBondYield($O9,$V$3,$U9) -> 0.0087366385 | X9: =U9-R9 -> 0 | Y9: =V9-S9 -> -3.1511248e-08
B10: EUR_FLOATER_TYPE21 | D10: GTITL7Y Corp | E10: =_xll.BDP($D10,E$5) -> 523 | F10: =_xll.BDP($D10,F$5) -> BTPS 0.85 01/15/27 | G10: =_xll.BDP($D10,G$5) -> IT0005390874 | H10: =_xll.BDP($D10,H$5) -> 15/11/2019 | I10: =_xll.BDP($D10,I$5) -> 15/11/2019 | K10: =_xll.BDP($D10,K$5) -> 15/01/2020 | L10: =_xll.BDP($D10,L$5) -> 15/07/2026 | M10: =_xll.BDP($D10,M$5)% -> 0.0085 | N10: =_xll.BDP($D10,N$5) -> 15/01/2027 | O10: =_xll.meLWOBondCreateFromGeneratorLVB(F10,$O$3,_xll.meUtilityLVBFromKeysValues($F$6:$N$6,F10:N10)) -> BTPS 0.85 01/15/27@19:2 | Q10: =YEAR(N10)-YEAR(Settings.COB)&"Y" -> 7Y | R10: =_xll.BDP($D10,R$5) -> 98.366 | S10: =_xll.BDP($D10,S$5)% -> 0.01103936 | U10: =_xll.meLWOBondQuote($O10,$V$3,$S10) -> 98.366 | V10: =_xll.meLWOBondYield($O10,$V$3,$U10) -> 0.011039439 | X10: =U10-R10 -> 0 | Y10: =V10-S10 -> 7.9421544e-08
B11: EUR_FLOATER_TYPE21_ACTACT | D11: GTITL10Y Corp | E11: =_xll.BDP($D11,E$5) -> 523 | F11: =_xll.BDP($D11,F$5) -> BTPS 1.35 04/01/30 | G11: =_xll.BDP($D11,G$5) -> IT0005383309 | H11: =_xll.BDP($D11,H$5) -> 02/09/2019 | I11: =_xll.BDP($D11,I$5) -> 01/09/2019 | K11: =_xll.BDP($D11,K$5) -> 01/10/2019 | L11: =_xll.BDP($D11,L$5) -> 01/10/2029 | M11: =_xll.BDP($D11,M$5)% -> 0.0135 | N11: =_xll.BDP($D11,N$5) -> 01/04/2030 | O11: =_xll.meLWOBondCreateFromGeneratorLVB(F11,$O$3,_xll.meUtilityLVBFromKeysValues($F$6:$N$6,F11:N11)) -> BTPS 1.35 04/01/30@20:2 | Q11: =YEAR(N11)-YEAR(Settings.COB)&"Y" -> 10Y | R11: =_xll.BDP($D11,R$5) -> 99.027 | S11: =_xll.BDP($D11,S$5)% -> 0.01460293 | U11: =_xll.meLWOBondQuote($O11,$V$3,$S11) -> 99.027 | V11: =_xll.meLWOBondYield($O11,$V$3,$U11) -> 0.014602908 | X11: =U11-R11 -> 0 | Y11: =V11-S11 -> -2.1794211e-08
B12: EUR_FLOATER_TYPE21_ACTACT_UNADJUSTED | D12: GTITL15Y Corp | E12: =_xll.BDP($D12,E$5) -> 523 | F12: =_xll.BDP($D12,F$5) -> BTPS 3.35 03/01/35 | G12: =_xll.BDP($D12,G$5) -> IT0005358806 | H12: =_xll.BDP($D12,H$5) -> 22/01/2019 | I12: =_xll.BDP($D12,I$5) -> 01/09/2018 | K12: =_xll.BDP($D12,K$5) -> 01/03/2019 | L12: =_xll.BDP($D12,L$5) -> 01/09/2034 | M12: =_xll.BDP($D12,M$5)% -> 0.0335 | N12: =_xll.BDP($D12,N$5) -> 01/03/2035 | O12: =_xll.meLWOBondCreateFromGeneratorLVB(F12,$O$3,_xll.meUtilityLVBFromKeysValues($F$6:$N$6,F12:N12)) -> BTPS 3.35 03/01/35@16:2 | Q12: =YEAR(N12)-YEAR(Settings.COB)&"Y" -> 15Y | R12: =_xll.BDP($D12,R$5) -> 119.22 | S12: =_xll.BDP($D12,S$5)% -> 0.01875177 | U12: =_xll.meLWOBondQuote($O12,$V$3,$S12) -> 119.22 | V12: =_xll.meLWOBondYield($O12,$V$3,$U12) -> 0.018751702 | X12: =U12-R12 -> 0 | Y12: =V12-S12 -> -6.8246898e-08
