Workbook
Name COB: Settings!$C$2
Name CurveCollection: USD3ML!$D$9
Name CurveCollection: USD6ML!$D$9
Name isUSD3MLLoaded: USD3ML!$D$31
Name isUSD6MLLoaded: USD6ML!$D$31
Name isUSDOISLoaded: USDOIS!$D$31
Name USD_TRS_3ML: TRS_GENERATOR!$C$3

Sheet Settings
B2: Settings | C2: 43627

Sheet USDOIS
C3: MARKETDATAPROPERTIES | F3: OIS | L3: LIBOROISBASISSPREADS | O3: SWAPS
F4: Term | G4: Rate | H4: StartDate | I4: EndDate | J4: Use | L4: Term | M4: Rate | O4: Term | P4: Rate
C5: Currency | D5: USD | F5: ON | G5: 0.01723 | J5: TRUE | L5: 4Y | M5: 0.0036875 | O5: 4Y | P5: 0.02723
C6: CurveType | D6: OIS | F6: 1W | G6: 0.01689 | J6: TRUE | L6: 5Y | M6: 0.00368775 | O6: 5Y | P6: 0.027488
C7: CurveIndexFrequency | D7: DAILY | F7: 2W | G7: 0.016892 | J7: TRUE | L7: 7Y | M7: 0.0037875 | O7: 7Y | P7: 0.02782
C8: AsOfDate | D8: =COB -> 43627 | F8: 3W | G8: 0.01677 | J8: TRUE | L8: 10Y | M8: 0.00394375 | O8: 10Y | P8: 0.028299
F9: 1M | G9: 0.01688 | J9: TRUE | L9: 12Y | M9: 0.004025 | O9: 12Y | P9: 0.028604
F10: 2M | G10: 0.016909 | J10: TRUE | L10: 15Y | M10: 0.0041625 | O10: 15Y | P10: 0.028877
C11: Create Market Data Handle | F11: 3M | G11: 0.017464 | J11: TRUE | L11: 20Y | M11: 0.0043125 | O11: 20Y | P11: 0.029084
C12: Handle Name | D12: USD_OIS_CURVE_MARKETDATA | F12: 4M | G12: 0.017862 | J12: TRUE | L12: 25Y | M12: 0.0044149 | O12: 25Y | P12: 0.029009
C13: Market Data Handle | D13: =_xll.meLWOCurveMarketDataCreate(D12,C3,C5:D8,F3,F5:J30,L3,L5:M30,O3,O5:P30) -> USD_OIS_CURVE_MARKETDATA@7:8 | F13: 5M | G13: 0.018084 | J13: TRUE | L13: 30Y | M13: 0.0045 | O13: 30Y | P13: 0.028846
F14: 6M | G14: 0.018352 | J14: TRUE
F15: 9M | G15: 0.01919 | J15: TRUE
F16: 1Y | G16: 0.019885 | J16: TRUE
F17: 2Y | G17: 0.021926 | J17: TRUE
C19: Curve Dictionary
C20: Handle Name | D20: USD_OIS_CURVE
C21: Curve Generator | D21: USD_OIS_LOB_3Y
C22: Domestic Curve Collection | D22: USDYC
C23: Foreign Curve Collection
C26: Curve Build
C27: Handle Name | D27: {=_xll.meLWOCurveCalibrate(D20,D21,D13,D22,D23)} -> USD_OIS_CURVE@11:4
C28: Curve Collection | D28: USDYC
C29: Curve Index | D29: OIS:USDOIS:USDDF:USDDF_USDCSA:USDDF_NOCSA
C30: Calibration Time Taken | D30: 0.01800 sec
C31: Curve Loaded | D31: =LEFT(D27,3)=LEFT(D20,3) -> TRUE

Sheet USD3ML
C3: MARKETDATAPROPERTIES | F3: LIBORFIXINGS | I3: FUTURES | O3: SWAPS
C4: Currency | D4: USD | F4: Term | G4: Rate | I4: Term | J4: StartDate | K4: EndDate | L4: Rate | M4: Volatility | O4: Term | P4: Rate | Q4: Use
C5: CurveType | D5: SWAP | F5: 3M | G5: 0.024495 | I5: EDM8 | J5: 46925 | K5: 47016 | L5: 97.5525 | M5: 0.008 | O5: 3Y | P5: 0.019316 | Q5: TRUE
C6: CurveIndexFrequency | D6: QUARTERLY | I6: EDU8 | J6: 47016 | K6: 47107 | L6: 97.845 | M6: 0.008 | O6: 4Y | P6: 0.019283 | Q6: TRUE
C7: AsOfDate | D7: =COB -> 43627 | I7: EDZ8 | J7: 47107 | K7: 47198 | L7: 97.955 | M7: 0.008 | O7: 5Y | P7: 0.019493 | Q7: TRUE
I8: EDH9 | J8: 47198 | K8: 47289 | L8: 98.12 | M8: 0.008 | O8: 7Y | P8: 0.020207 | Q8: TRUE
I9: EDM9 | J9: 43635 | K9: 43726 | L9: 98.18 | M9: 0.008 | O9: 8Y | P9: 0.020594 | Q9: TRUE
I10: EDU9 | J10: 43726 | K10: 43817 | L10: 98.23 | M10: 0.008 | O10: 9Y | P10: 0.020979 | Q10: TRUE
C11: Create Market Data Handle | I11: EDZ9 | J11: 43817 | K11: 43908 | L11: 98.24 | M11: 0.008 | O11: 10Y | P11: 0.02135 | Q11: TRUE
C12: Handle Name | D12: USD_SWAP_3M_CURVE_MARKETDATA | I12: EDH0 | J12: 43908 | K12: 43999 | L12: 98.26 | M12: 0.008 | O12: 12Y | P12: 0.022001 | Q12: TRUE
C13: Market Data Handle | D13: =_xll.meLWOCurveMarketDataCreate(D12,C3,C4:D9,F3,F5:G9,I3,I5:M30,O3,O5:Q30) -> USD_SWAP_3M_CURVE_MARKETDATA@8:8 | O13: 15Y | P13: 0.022679 | Q13: TRUE
O14: 20Y | P14: 0.023306 | Q14: TRUE
O15: 25Y | P15: 0.023512 | Q15: TRUE
O16: 30Y | P16: 0.02359 | Q16: TRUE
O17: 40Y | P17: 0.023421 | Q17: TRUE
O18: 50Y | P18: 0.02313 | Q18: TRUE
C19: Curve Dictionary
C20: Handle Name | D20: USD_SWAP_3M_CURVE
C21: Curve Generator | D21: USD_SWAP_3M
C22: Domestic Curve Collection | D22: USDYC
C23: Foreign Curve Collection
C26: Curve Build
C27: Handle Name | D27: {=IF(isUSDOISLoaded,_xll.meLWOCurveCalibrate(D20,D21,D13,D22),"#WAIT")} -> USD_SWAP_3M_CURVE@20:0
C28: Curve Collection | D28: USDYC
C29: Curve Index | D29: STD:USD3ML
C30: Calibration Time Taken | D30: 0.17700 sec
C31: Curve Loaded | D31: =LEFT(D27,3)=LEFT(D20,3) -> TRUE

Sheet USD6ML
C3: MARKETDATAPROPERTIES | F3: BASISSWAPS
C4: Currency | D4: USD | F4: Term | G4: Rate | H4: Use
C5: CurveType | D5: TENORBASIS | F5: 1Y | G5: 0.0005795 | H5: TRUE
C6: CurveIndexFrequency | D6: SEMI-ANNUAL | F6: 2Y | G6: 0.00065 | H6: TRUE
C7: AsOfDate | D7: =COB -> 43627 | F7: 3Y | G7: 0.0006875 | H7: TRUE
F8: 4Y | G8: 0.0007125 | H8: TRUE
F9: 5Y | G9: 0.0007375 | H9: TRUE
F10: 6Y | G10: 0.0007815 | H10: TRUE
C11: Create Market Data Handle | F11: 7Y | G11: 0.000825 | H11: TRUE
C12: Handle Name | D12: USD_BASIS_6M_CURVE_MARKETDATA | F12: 8Y | G12: 0.0008584 | H12: TRUE
C13: Market Data Handle | D13: =_xll.meLWOCurveMarketDataCreate(D12,C3,C4:D9,F3,F5:H30) -> USD_BASIS_6M_CURVE_MARKETDATA@9:6 | F13: 9Y | G13: 0.0008864 | H13: TRUE
F14: 10Y | G14: 0.000913 | H14: TRUE
F15: 12Y | G15: 0.0009625 | H15: TRUE
F16: 15Y | G16: 0.001025 | H16: TRUE
F17: 20Y | G17: 0.001025 | H17: TRUE
F18: 25Y | G18: 0.0010875 | H18: TRUE
C19: Curve Dictionary | F19: 30Y | G19: 0.0011 | H19: TRUE
C20: Handle Name | D20: USD_BASIS_6M
C21: Curve Generator | D21: USD_BASIS_3X6
C22: Domestic Curve Collection | D22: USDYC
C23: Foreign Curve Collection
C26: Curve Build
C27: Handle Name | D27: {=IF(isUSD3MLLoaded,_xll.meLWOCurveCalibrate(D20,D21,D13,D22),"#WAIT")} -> USD_BASIS_6M@21:4
C28: Curve Collection | D28: USDYC
C29: Curve Index | D29: 3M6MBasis:USD6ML
C30: Calibration Time Taken | D30: 0.00600 sec
C31: Curve Loaded | D31: =LEFT(D27,3)=LEFT(D20,3) -> TRUE

Sheet CREDITMODEL
B2: CREATE MODEL | C2: =C4 -> CREDITMODEL1@15:3
B3: ModelName | C3: CREDITMODEL1 | E3: =E8 -> 43636
B4: CreateModel | C4: =_xll.meLWOCreditModelCreate(C3,B6,B7:C21,B22,B24:C31) -> CREDITMODEL1@15:3 | M4: +/-
M5: =SUM(F8:H15)-SUM(K8:M15) -> 0
B6: MODEL_PROPERTIES | E6: MODEL CALIBRATION | J6: CHECK CALIBRATION RESULTS
B7: AsOfDate | C7: =COB -> 43627 | E7: Tenor | F7: HazardRate | G7: SurvivalProbability | H7: DefaultProbability | J7: Tenor | K7: HazardRate | L7: SurvivalProbability | M7: DefaultProbability
B8: SpotLag | C8: 5D | E8: {=_xll.meUtilityResize(_xll.meLWOCreditModelCalibrationParameters(C4),20,10)} -> 43636 | F8: 0.0037133333 | G8: 0.99990717 | H8: 9.2829024e-05 | J8: =E8 -> 43636 | K8: =IF(J8="","",_xll.meLWOCreditModelHazardRate($C$4,J8)) -> 0.0037133333 | L8: =IF(J8="","",_xll.meLWOCreditModelSurvivalProbability($C$4,J8)) -> 0.99990717 | M8: =1-L8 -> 9.2829024e-05
B9: SpotBusinessDayAdjustment | C9: FOLLOWING | E9: 43819 | F9: 0.0030429309 | G9: 0.99836169 | H9: 0.0016383131 | J9: =E9 -> 43819 | K9: =IF(J9="","",_xll.meLWOCreditModelHazardRate($C$4,J9)) -> 0.0030429309 | L9: =IF(J9="","",_xll.meLWOCreditModelSurvivalProbability($C$4,J9)) -> 0.99836169 | M9: =1-L9 -> 0.0016383131
B10: SpotCalendar | C10: NYB | E10: 44186 | F10: 0.0036284327 | G10: 0.99467558 | H10: 0.0053244169 | J10: =E10 -> 44186 | K10: =IF(J10="","",_xll.meLWOCreditModelHazardRate($C$4,J10)) -> 0.0036284327 | L10: =IF(J10="","",_xll.meLWOCreditModelSurvivalProbability($C$4,J10)) -> 0.99467558 | M10: =1-L10 -> 0.0053244169
B11: AccrualStartDate | C11: =C7 -> 43627 | E11: 44550 | F11: 0.0040107947 | G11: 0.99064998 | H11: 0.0093500154 | J11: =E11 -> 44550 | K11: =IF(J11="","",_xll.meLWOCreditModelHazardRate($C$4,J11)) -> 0.0040107947 | L11: =IF(J11="","",_xll.meLWOCreditModelSurvivalProbability($C$4,J11)) -> 0.99064998 | M11: =1-L11 -> 0.0093500154
B12: IMMReferenceDate | C12: 43454 | D12: <--- Last IMM Date | E12: 44915 | F12: 0.0044228359 | G12: 0.98621759 | H12: 0.013782406 | J12: =E12 -> 44915 | K12: =IF(J12="","",_xll.meLWOCreditModelHazardRate($C$4,J12)) -> 0.0044228359 | L12: =IF(J12="","",_xll.meLWOCreditModelSurvivalProbability($C$4,J12)) -> 0.98621759 | M12: =1-L12 -> 0.013782406
B13: Currency | C13: USD | E13: 45280 | F13: 0.0039971465 | G13: 0.98222887 | H13: 0.017771125 | J13: =E13 -> 45280 | K13: =IF(J13="","",_xll.meLWOCreditModelHazardRate($C$4,J13)) -> 0.0039971465 | L13: =IF(J13="","",_xll.meLWOCreditModelSurvivalProbability($C$4,J13)) -> 0.98222887 | M13: =1-L13 -> 0.017771125
B14: RecoveryRate | C14: 0.4 | E14: 46013 | F14: 0.0063138977 | G14: 0.96968236 | H14: 0.03031764 | J14: =E14 -> 46013 | K14: =IF(J14="","",_xll.meLWOCreditModelHazardRate($C$4,J14)) -> 0.0063138977 | L14: =IF(J14="","",_xll.meLWOCreditModelSurvivalProbability($C$4,J14)) -> 0.96968236 | M14: =1-L14 -> 0.03031764
B15: IncludeAccruedInterest | C15: TRUE | E15: 47107 | F15: 0.0069698966 | G15: 0.94935975 | H15: 0.050640248 | J15: =E15 -> 47107 | K15: =IF(J15="","",_xll.meLWOCreditModelHazardRate($C$4,J15)) -> 0.0069698966 | L15: =IF(J15="","",_xll.meLWOCreditModelSurvivalProbability($C$4,J15)) -> 0.94935975 | M15: =1-L15 -> 0.050640248
B16: CDSCurveCollection | C16: USDYC
B17: BondCurveCollection | C17: USDYC
B18: SwapGenerator | C18: USD_CDS_IMM
B19: CreditIndex | C19: US9128282R06
B20: Interpolation | C20: PiecewiseConstant
B21: Extrapolation | C21: Flat
B22: CDS_MARKETDATA | E22: CALIBRATION REPRICING CHECK
B23: Tenor | C23: CDS Spread | E23: Tenor | F23: SpotLag | G23: EffectiveDate | H23: MaturityDate | I23: PayRec | J23: CDS | K23: PV | L23: ParSpread | M23: +/-
B24: 6M | C24: 0.002228 | E24: =B24 -> 6M | F24: 5D | G24: =_xll.meDateFromTenor($C$7,$C$8,$C$9,$C$10) -> 43634 | H24: =_xll.meDateFromTenor($C$12,E24,) -> 43636 | I24: PAY | J24: =_xll.meLWOSwapCreateFromGenerator("CDS_"&E24,$C$18,"PAY",1,G24,H24,C24,0) -> CDS_6M@14:4 | K24: =_xll.meLWOCreditDefaultSwapPV(J24,$C$4) -> -4.8820777e-16 | L24: =_xll.meLWOCreditDefaultSwapParSpread(J24,$C$4) -> 0.002228 | M24: =L24-C24 -> -8.7921857e-14
B25: 1Y | C25: 0.00183013 | E25: =B25 -> 1Y | F25: 5D | G25: =_xll.meDateFromTenor($C$7,$C$8,$C$9,$C$10) -> 43634 | H25: =_xll.meDateFromTenor($C$12,E25,) -> 43819 | I25: PAY | J25: =_xll.meLWOSwapCreateFromGenerator("CDS_"&E25,$C$18,"PAY",1,G25,H25,C25,0) -> CDS_1Y@17:4 | K25: =_xll.meLWOCreditDefaultSwapPV(J25,$C$4) -> -3.3467261e-14 | L25: =_xll.meLWOCreditDefaultSwapParSpread(J25,$C$4) -> 0.00183013 | M25: =L25-C25 -> -6.5657766e-14
B26: 2Y | C26: 0.0020593 | E26: =B26 -> 2Y | F26: 5D | G26: =_xll.meDateFromTenor($C$7,$C$8,$C$9,$C$10) -> 43634 | H26: =_xll.meDateFromTenor($C$12,E26,) -> 44185 | I26: PAY | J26: =_xll.meLWOSwapCreateFromGenerator("CDS_"&E26,$C$18,"PAY",1,G26,H26,C26,0) -> CDS_2Y@18:4 | K26: =_xll.meLWOCreditDefaultSwapPV(J26,$C$4) -> 1.0408341e-16 | L26: =_xll.meLWOCreditDefaultSwapParSpread(J26,$C$4) -> 0.0020593 | M26: =L26-C26 -> 6.9388939e-17
B27: 3Y | C27: 0.00219438 | E27: =B27 -> 3Y | F27: 5D | G27: =_xll.meDateFromTenor($C$7,$C$8,$C$9,$C$10) -> 43634 | H27: =_xll.meDateFromTenor($C$12,E27,) -> 44550 | I27: PAY | J27: =_xll.meLWOSwapCreateFromGenerator("CDS_"&E27,$C$18,"PAY",1,G27,H27,C27,0) -> CDS_3Y@12:4 | K27: =_xll.meLWOCreditDefaultSwapPV(J27,$C$4) -> 3.9725168e-16 | L27: =_xll.meLWOCreditDefaultSwapParSpread(J27,$C$4) -> 0.00219438 | M27: =L27-C27 -> 1.6176296e-16
B28: 4Y | C28: 0.00232063 | E28: =B28 -> 4Y | F28: 5D | G28: =_xll.meDateFromTenor($C$7,$C$8,$C$9,$C$10) -> 43634 | H28: =_xll.meDateFromTenor($C$12,E28,) -> 44915 | I28: PAY | J28: =_xll.meLWOSwapCreateFromGenerator("CDS_"&E28,$C$18,"PAY",1,G28,H28,C28,0) -> CDS_4Y@16:4 | K28: =_xll.meLWOCreditDefaultSwapPV(J28,$C$4) -> -3.2786274e-16 | L28: =_xll.meLWOCreditDefaultSwapParSpread(J28,$C$4) -> 0.00232063 | M28: =L28-C28 -> -9.6710834e-17
B29: 5Y | C29: 0.002337 | E29: =B29 -> 5Y | F29: 5D | G29: =_xll.meDateFromTenor($C$7,$C$8,$C$9,$C$10) -> 43634 | H29: =_xll.meDateFromTenor($C$12,E29,) -> 45280 | I29: PAY | J29: =_xll.meLWOSwapCreateFromGenerator("CDS_"&E29,$C$18,"PAY",1,G29,H29,C29,0) -> CDS_5Y@19:4 | K29: =_xll.meLWOCreditDefaultSwapPV(J29,$C$4) -> 7.4593109e-17 | L29: =_xll.meLWOCreditDefaultSwapParSpread(J29,$C$4) -> 0.002337 | M29: =L29-C29 -> 1.7780916e-17
B30: 7Y | C30: 0.00275507 | E30: =B30 -> 7Y | F30: 5D | G30: =_xll.meDateFromTenor($C$7,$C$8,$C$9,$C$10) -> 43634 | H30: =_xll.meDateFromTenor($C$12,E30,) -> 46011 | I30: PAY | J30: =_xll.meLWOSwapCreateFromGenerator("CDS_"&E30,$C$18,"PAY",1,G30,H30,C30,0) -> CDS_7Y@13:4 | K30: =_xll.meLWOCreditDefaultSwapPV(J30,$C$4) -> -3.2220511e-12 | L30: =_xll.meLWOCreditDefaultSwapParSpread(J30,$C$4) -> 0.00275507 | M30: =L30-C30 -> -5.3405154e-13
B31: 10Y | C31: 0.00316097 | E31: =B31 -> 10Y | F31: 5D | G31: =_xll.meDateFromTenor($C$7,$C$8,$C$9,$C$10) -> 43634 | H31: =_xll.meDateFromTenor($C$12,E31,) -> 47107 | I31: PAY | J31: =_xll.meLWOSwapCreateFromGenerator("CDS_"&E31,$C$18,"PAY",1,G31,H31,C31,0) -> CDS_10Y@10:4 | K31: =_xll.meLWOCreditDefaultSwapPV(J31,$C$4) -> -1.4260794e-11 | L31: =_xll.meLWOCreditDefaultSwapParSpread(J31,$C$4) -> 0.00316097 | M31: =L31-C31 -> -1.6913086e-12
E34: RISKY DISCOUNT FACTORS
E35: DF | F35: RiskyDF | G35: Manual | H35: +/-
E36: {=_xll.meCurveDiscountFactors(E8:E15,C16,"OIS")} -> 0.99957601 | F36: {=_xll.meLWOCreditModelRiskyDiscountFactors($C$4,E8:E15)} -> 0.99948322 | G36: =G8*E36 -> 0.99948322 | H36: =F36-G36 -> 0
E37: 0.990279 | F37: 0.98865661 | G37: =G9*E37 -> 0.98865661 | H37: =F37-G37 -> 0
E38: 0.96766699 | F38: 0.96251473 | G38: =G10*E38 -> 0.96251473 | H38: =F38-G38 -> 0
E39: 0.94404045 | F39: 0.93521366 | G39: =G11*E39 -> 0.93521366 | H39: =F39-G39 -> 0
E40: 0.92126101 | F40: 0.90856381 | G40: =G12*E40 -> 0.90856381 | H40: =F40-G40 -> 0
E41: 0.89908818 | F41: 0.88311037 | G41: =G13*E41 -> 0.88311037 | H41: =F41-G41 -> 0
E42: 0.85588536 | F42: 0.82993693 | G42: =G14*E42 -> 0.82993693 | H42: =F42-G42 -> 0
E43: 0.79459205 | F43: 0.75435371 | G43: =G15*E43 -> 0.75435371 | H43: =F43-G43 -> 0

Sheet BOND
B2: Valuation Date | C2: Settlement Date | L2: Bond Generator
B3: =COB -> 43627 | C3: =_xll.meDateFromTenor($B$3,$D$3,"MOD_FOLLOWING","NYB") -> 43629 | D3: 2D | L3: US_TREASURY_TYPE1
M6: YLD_YTM_ASK
B7: Bond Identifier | C7: BondDescription | D7: ISIN | E7: IssueDate | F7: AccrualStartDate | G7: RollDay | H7: FirstCouponDate | I7: LastCouponDate | J7: Coupon | K7: MaturityDate | L7: CreateBond | M7: BloombergYield | N7: CleanPrice | O7: DirtyPrice
B8: 912828Q2 Govt | C8: US912828Q293 | D8: US912828Q293 | E8: 42460 | F8: 42460 | G8: =IF(DAY(K8+1)=1, "EOM","") -> EOM | H8: 42643 | I8: 44834 | J8: 0.015 | K8: 45016 | L8: =_xll.meLWOBondCreateFromGeneratorLVB(C8,$L$3,_xll.meUtilityLVBFromKeysValues($C$7:$K$7,C8:K8)) -> US912828Q293@3:4 | M8: 1.9086728 | N8: =_xll.meLWOBondCleanPrice($L8,$C$3,$M8%) -> 98.508843 | O8: =_xll.meLWOBondDirtyPrice($L8,$C$3,$M8%) -> 98.812121

Sheet TRS_GENERATOR
B2: GeneratorName | C2: USD_TRS_3ML
B3: Create Generator | C3: =_xll.meLWOSwapGeneratorCreate(C2,$B$6:$D$32) -> USD_TRS_3ML@2:3
B6: LEGTYPE | C6: Leg1:Premium | D6: Leg2:Float
B7: LEVERAGE | C7: 1 | D7: 1
B8: FORECASTCURVE | D8: USD3ML
B9: COMPOUNDMETHOD | C9: NONE | D9: NONE
B10: NOTIONALEXCHANGE | C10: NONE | D10: NONE
B11: DISCOUNTCURVE | C11: USDOIS | D11: USDOIS
B12: VALUATIONCURRENCY | C12: USD | D12: USD
B13: CURRENCY | C13: USD | D13: USD
B14: ACCRUALFREQUENCY | C14: Semi-Annual | D14: Quarterly
B15: ACCRUALBUSINESSDAYADJUSTMENT | C15: FOLLOWING | D15: FOLLOWING
B16: ACCRUALCALENDAR | C16: NYB:LNB | D16: NYB:LNB
B17: ACCRUALDAYCOUNT | C17: ACT/360 | D17: ACT/360
B18: PAYMENTFREQUENCY | C18: Semi-Annual | D18: Quarterly
B19: PAYMENTBUSINESSDAYADJUSTMENT | C19: FOLLOWING | D19: FOLLOWING
B20: PAYMENTCALENDAR | C20: NYB:LNB | D20: NYB:LNB
B21: PAYMENTLAG | C21: 0D | D21: 0D
B22: FIRSTSTUBDATE
B23: LASTSTUBDATE
B24: ROLLDAY | C24: NORMAL | D24: NORMAL
B25: STUBTYPE | C25: ShortStart | D25: ShortStart
B26: FIXINGBUSINESSDAYADJUSTMENT | C26: FOLLOWING
B27: FIXINGCALENDAR | C27: NYB:LNB
B28: FIXINGLAG | C28: 2D
B29: FIXINGADVANCEORARREAR
B30: FIRSTSTUBCURVEINDEX
B31: LASTSTUBCURVEINDEX
B32: PAYMENTTRIGGER | C32: PayOnSurvival | D32: PayOnSurvival

Sheet USD_TRS
B2: CREATE TRS | E2: =E3 -> LEG1:PREMIUM Leg Schedule & Cashflows
B3: SwapName | C3: TRS_0.15_FEB2028 | E3: {=_xll.meUtilityResize(IF(ISNUMBER(C24),_xll.meLWOSwapDisplayCashflows($C$4,C21),"#WAIT"),100,30)} -> LEG1:PREMIUM Leg Schedule & Cashflows
B4: CreateTRS | C4: =_xll.meLWOSwapCreateFromGeneratorLVB(C3,C19,B7:C15) -> TRS_0.15_FEB2028@4:7 | E4: AccrualStart | F4: AccrualEnd | G4: AccrualDays | H4: AccrualYearFractions | I4: PaymentDate | J4: Notional | K4: NotionalExchange | L4: Leverage | M4: CDSSpread | N4: SurvivalProbability | O4: MarginalDefaultProbability | P4: PremiumCoupon | Q4: AccrualOnDefaultCoupon | R4: RiskyCoupon | S4: DiscountFactor | T4: CouponPV
E5: 43631 | F5: 43815 | G5: 184 | H5: 0.51111111 | I5: 43815 | J5: 10000000 | K5: 0 | L5: 1 | M5: 0.015 | N5: 0.99839544 | O5: 0.0015632991 | P5: 76543.651 | Q5: 59.926467 | R5: 76609.904 | S5: 0.99049835 | T5: 75881.984
B6: TRS TRADE PARAMETERS | E6: 43815 | F6: 43997 | G6: 182 | H6: 0.50555556 | I6: 43997 | J6: 10000000 | K6: 0 | L6: 1 | M6: 0.015 | N6: 0.99657217 | O6: 0.001823269 | P6: 75573.39 | Q6: 69.132282 | R6: 75649.901 | S6: 0.97978562 | T6: 74120.685
A7: PayReceivePremium | B7: PayReceive | C7: RECEIVE | E7: 43997 | F7: 44180 | G7: 183 | H7: 0.50833333 | I7: 44180 | J7: 10000000 | K7: 0 | L7: 1 | M7: 0.015 | N7: 0.99473574 | O7: 0.0018364367 | P7: 75848.6 | Q7: 70.014149 | R7: 75926.046 | S7: 0.96805726 | T7: 73500.76
A8: Notional | B8: Notional | C8: 10000000 | E8: 44180 | F8: 44362 | G8: 182 | H8: 0.50555556 | I8: 44362 | J8: 10000000 | K8: 0 | L8: 1 | M8: 0.015 | N8: 0.9927271 | O8: 0.0020086354 | P8: 75281.805 | Q8: 76.16076 | R8: 75366.092 | S8: 0.95619322 | T8: 72064.546
A9: EffectiveDate | B9: EffectiveDate | C9: =TODAY()+4 -> 43631 | E9: LEG2:FLOAT Leg Schedule & Cashflows
A10: MaturityDate | B10: MaturityDate | C10: =_xll.meDateFromTenor(C9,"2Y") -> 44362 | E10: FixingDate | F10: AccrualStart | G10: AccrualEnd | H10: AccrualDays | I10: AccrualYearFractions | J10: PaymentDate | K10: Notional | L10: NotionalExchange | M10: Leverage | N10: FloatSpread | O10: FloatRate | P10: SurvivalProbability | Q10: MarginalDefaultProbability | R10: Coupon | S10: RiskyCoupon | T10: DiscountFactor | U10: CouponPV
B11: BondName | C11: =BOND!L8 -> US912828Q293@3:4 | E11: 43633 | F11: 43631 | G11: 43724 | H11: 93 | I11: 0.25833333 | J11: 43724 | K11: -10000000 | L11: 0 | M11: 1 | N11: 0 | O11: 0.020945771 | P11: 0.99918044 | Q11: 0.00081956481 | R11: -54065.563 | S11: -54065.563 | T11: 0.99530423 | U11: -53811.684
A12: FixedRate (Override) | B12: RateOrSpread1 | E12: 43724 | F12: 43724 | G12: 43815 | H12: 91 | I12: 0.25277778 | J12: 43815 | K12: -10000000 | L12: 0 | M12: 1 | N12: 0 | O12: 0.017748369 | P12: 0.99841218 | Q12: 0.00076825942 | R12: -44792.697 | S12: -44792.697 | T12: 0.99049835 | U12: -44367.093
A13: FloatSpread (bps) | B13: RateOrSpread2 | C13: 0 | E13: 43815 | F13: 43815 | G13: 43906 | H13: 91 | I13: 0.25277778 | J13: 43906 | K13: -10000000 | L13: 0 | M13: 1 | N13: 0 | O13: 0.017577203 | P13: 0.99749686 | Q13: 0.00091531101 | R13: -44320.046 | S13: -44320.046 | T13: 0.98533348 | U13: -43670.025
B14: AssetPerformance | C14: PayAtMaturity | E14: 43906 | F14: 43906 | G14: 43997 | H14: 91 | I14: 0.25277778 | J14: 43997 | K14: -10000000 | L14: 0 | M14: 1 | N14: 0 | O14: 0.017379879 | P14: 0.99658239 | Q14: 0.00091447188 | R14: -43782.328 | S14: -43782.328 | T14: 0.97978562 | U14: -42897.295
A15: BondDirtyPriceAtEffectiveDate | B15: FirstFixing1 | C15: =BOND!O8 -> 98.812121 | E15: 43997 | F15: 43997 | G15: 44089 | H15: 92 | I15: 0.25555556 | J15: 44089 | K15: -10000000 | L15: 0 | M15: 1 | N15: 0 | O15: 0.017736303 | P15: 0.99565872 | Q15: 0.0009236688 | R15: -45129.335 | S15: -45129.335 | T15: 0.97394426 | U15: -43953.457
E16: 44089 | F16: 44089 | G16: 44180 | H16: 91 | I16: 0.25277778 | J16: 44180 | K16: -10000000 | L16: 0 | M16: 1 | N16: 0 | O16: 0.01827809 | P16: 0.99474594 | Q16: 0.00091278673 | R16: -45960.195 | S16: -45960.195 | T16: 0.96805726 | U16: -44492.101
E17: 44180 | F17: 44180 | G17: 44270 | H17: 90 | I17: 0.25 | J17: 44270 | K17: -10000000 | L17: 0 | M17: 1 | N17: 0 | O17: 0.0187006 | P17: 0.99374901 | Q17: 0.00099693053 | R17: -46459.256 | S17: -46459.256 | T17: 0.9621913 | U17: -44702.692
B18: MODEL INPUTS | E18: 44270 | F18: 44270 | G18: 44362 | H18: 92 | I18: 0.25555556 | J18: 44362 | K18: -10000000 | L18: 0 | M18: 1 | N18: 0 | O18: 0.019005543 | P18: 0.99273095 | Q18: 0.0010180519 | R18: -48216.666 | S18: -48216.666 | T18: 0.95619322 | U18: -46104.45
B19: SwapGenerator | C19: =USD_TRS_3ML -> USD_TRS_3ML@2:3
B20: IRCurve | C20: USDYC
B21: CreditModel | C21: =CREDITMODEL!$C$4 -> CREDITMODEL1@15:3
B23: PRICE RESULTS
B24: Total PV | C24: =_xll.meLWOTotalReturnSwapPV($C$4,$C$21) -> -68430.821
B25: Leg1:Premium | C25: =_xll.meLWOTotalReturnSwapPV($C$4,$C$21,B25) -> 295567.98
B26: Leg2:Float | C26: =_xll.meLWOTotalReturnSwapPV($C$4,$C$21,B26) -> -363998.8
B27: ParRate | C27: =_xll.meLWOTotalReturnSwapParRate(C4,C21) -> 0.018474626
B28: ParSpread | C28: =_xll.meLWOTotalReturnSwapParSpread(C4,C21) -> -34.648186
B30: CASHFLOW DISPLAY INPUTS
B31: =TRS_GENERATOR!C6 -> Leg1:Premium | C31: =C21 -> CREDITMODEL1@15:3
B32: =TRS_GENERATOR!D6 -> Leg2:Float | C32: =C20 -> USDYC

Sheet BESPOKE TRS
B2: CREATE GENERATOR | F2: CREATE TRS | G2: =G4 -> TRS_USD_CT10@6:4
B3: GeneratorName | C3: USD_TREASURY | F3: SwapName | G3: TRS_USD_CT10 | K3: {=_xll.meUtilityResize(_xll.meLWOSwapDisplayCashflows(G4,G17),100,30)} -> LEG1:PREMIUM Leg Schedule & Cashflows
B4: Create Generator | C4: =_xll.meLWOSwapGeneratorCreate(C3,$B$7:$D$33) -> USD_TREASURY@1:4 | F4: CreateTRS | G4: =_xll.meLWOSwapCreateFromGenerator(G3,G15,G7,G8,G9,G10,G11,G12) -> TRS_USD_CT10@6:4 | K4: AccrualStart | L4: AccrualEnd | M4: AccrualDays | N4: AccrualYearFractions | O4: PaymentDate | P4: Notional | Q4: NotionalExchange | R4: Leverage | S4: CDSSpread | T4: SurvivalProbability | U4: MarginalDefaultProbability | V4: PremiumCoupon | W4: AccrualOnDefaultCoupon | X4: RiskyCoupon | Y4: DiscountFactor | Z4: CouponPV
O5: 43629 | Q5: -10000000 | R5: 1 | W5: 0 | X5: -10000000 | Y5: 0.99990428 | Z5: -9999042.8
B6: GENERATOR TEMPLATE | F6: TRS TRADE PARAMETERS | K6: 43629 | L6: 43810 | M6: 181 | N6: 0.50277778 | O6: 43810 | P6: 10000000 | Q6: 0 | R6: 1 | S6: 0.0275 | T6: 0.99843764 | U6: 0.0015417321 | V6: 138047.87 | W6: 106.58294 | X6: 138154.45 | Y6: 0.99077167 | Z6: 136879.52
B7: LEGTYPE | C7: Leg1:Premium | D7: Leg2:Float | F7: PayReceivePremium | G7: RECEIVE | K7: 43810 | L7: 43993 | M7: 183 | N7: 0.50833333 | O7: 43993 | P7: 10000000 | Q7: 0 | R7: 1 | S7: 0.0275 | T7: 0.99661235 | U7: 0.0018252864 | V7: 139318.1 | W7: 127.57992 | X7: 139445.68 | Y7: 0.98003555 | Z7: 136661.73
B8: LEVERAGE | C8: 1 | D8: 1 | F8: Notional | G8: 10000000 | K8: 43993 | L8: 44176 | M8: 183 | N8: 0.50833333 | O8: 44176 | P8: 10000000 | Q8: 0 | R8: 1 | S8: 0.0275 | T8: 0.99477584 | U8: 0.0018365107 | V8: 139061.37 | W8: 128.36445 | X8: 139189.74 | Y8: 0.96831733 | Z8: 134779.83
B9: FORECASTCURVE | D9: USD6ML | F9: EffectiveDate | G9: =_xll.meDateFromTenor(COB,H9,"FOLLOWING","NYB") -> 43629 | H9: 2D | K9: 44176 | L9: 44358 | M9: 182 | N9: 0.50555556 | O9: 44358 | P9: 10000000 | Q9: 0 | R9: 1 | S9: 0.0275 | T9: 0.99277134 | U9: 0.0020044987 | V9: 138022.79 | W9: 139.3405 | X9: 138162.13 | Y9: 0.95645368 | Z9: 132145.68
B10: COMPOUNDMETHOD | C10: NONE | D10: NONE | F10: MaturityDate | G10: =_xll.meDateFromTenor(COB,H10) -> 47280 | H10: 10Y | I10: Unadjusted | K10: 44358 | L10: 44543 | M10: 185 | N10: 0.51388889 | O10: 44543 | P10: 10000000 | Q10: 0 | R10: 1 | S10: 0.0275 | T10: 0.99072725 | U10: 0.0020440965 | V10: 140009.02 | W10: 144.43529 | X10: 140153.46 | Y10: 0.94448867 | Z10: 132373.35
B11: NOTIONALEXCHANGE | C11: START_AND_END | D11: START_AND_END | F11: FixedRate | G11: 0.0275 | K11: 44543 | L11: 44725 | M11: 182 | N11: 0.50555556 | O11: 44725 | P11: 10000000 | Q11: 0 | R11: 1 | S11: 0.0275 | T11: 0.98852239 | U11: 0.0022048608 | V11: 137432.07 | W11: 153.26845 | X11: 137585.34 | Y11: 0.93297559 | Z11: 128363.76
B12: DISCOUNTCURVE | C12: USDOIS | D12: USDOIS | F12: FloatSpread (bps) | G12: 239.34 | K12: 44725 | L12: 44907 | M12: 182 | N12: 0.50555556 | O12: 44907 | P12: 10000000 | Q12: 0 | R12: 1 | S12: 0.0275 | T12: 0.98631453 | U12: 0.0022078561 | V12: 137125.12 | W12: 153.47667 | X12: 137278.59 | Y12: 0.92174917 | Z12: 126536.43
B13: VALUATIONCURRENCY | C13: USD | D13: USD | K13: 44907 | L13: 45089 | M13: 182 | N13: 0.50555556 | O13: 45089 | P13: 10000000 | Q13: 0 | R13: 1 | S13: 0.0275 | T13: 0.98431411 | U13: 0.0020004233 | V13: 136847 | W13: 139.0572 | X13: 136986.06 | Y13: 0.91069471 | Z13: 124752.48
B14: CURRENCY | C14: USD | D14: USD | F14: MODEL INPUTS | K14: 45089 | L14: 45271 | M14: 182 | N14: 0.50555556 | O14: 45271 | P14: 10000000 | Q14: 0 | R14: 1 | S14: 0.0275 | T14: 0.98232703 | U14: 0.0019870735 | V14: 136570.74 | W14: 138.12921 | X14: 136708.87 | Y14: 0.89963501 | Z14: 122988.09
B15: ACCRUALFREQUENCY | C15: SEMI-ANNUAL | D15: SEMI-ANNUAL | F15: SwapGenerator | G15: =C4 -> USD_TREASURY@1:4 | K15: 45271 | L15: 45454 | M15: 183 | N15: 0.50833333 | O15: 45454 | P15: 10000000 | Q15: 0 | R15: 1 | S15: 0.0275 | T15: 0.97923596 | U15: 0.0030910734 | V15: 136889.03 | W15: 216.05315 | X15: 137105.08 | Y15: 0.88856258 | Z15: 121826.44
B16: ACCRUALBUSINESSDAYADJUSTMENT | C16: FOLLOWING | D16: FOLLOWING | F16: IRCurve | G16: =USD3ML!D28 -> USDYC | K16: 45454 | L16: 45637 | M16: 183 | N16: 0.50833333 | O16: 45637 | P16: 10000000 | Q16: 0 | R16: 1 | S16: 0.0275 | T16: 0.97609808 | U16: 0.0031378828 | V16: 136450.38 | W16: 219.32493 | X16: 136669.7 | Y16: 0.87767107 | Z16: 119951.04
B17: ACCRUALCALENDAR | C17: NYB | D17: NYB | F17: CreditModel | G17: =CREDITMODEL!$C$4 -> CREDITMODEL1@15:3 | K17: 45637 | L17: 45819 | M17: 182 | N17: 0.50555556 | O17: 45819 | P17: 10000000 | Q17: 0 | R17: 1 | S17: 0.0275 | T17: 0.97298731 | U17: 0.003110763 | V17: 135272.26 | W17: 216.24124 | X17: 135488.51 | Y17: 0.86703714 | Z17: 117473.57
B18: ACCRUALDAYCOUNT | C18: ACT/360 | D18: ACT/360 | K18: 45819 | L18: 46002 | M18: 183 | N18: 0.50833333 | O18: 46002 | P18: 10000000 | Q18: 0 | R18: 1 | S18: 0.0275 | T18: 0.96986945 | U18: 0.0031178595 | V18: 135579.67 | W18: 217.92539 | X18: 135797.59 | Y18: 0.8565135 | Z18: 116312.47
B19: PAYMENTFREQUENCY | C19: SEMI-ANNUAL | D19: SEMI-ANNUAL | F19: PRICE RESULTS | K19: 46002 | L19: 46184 | M19: 182 | N19: 0.50555556 | O19: 46184 | P19: 10000000 | Q19: 0 | R19: 1 | S19: 0.0275 | T19: 0.96647734 | U19: 0.0033921136 | V19: 134367.2 | W19: 235.79901 | X19: 134603 | Y19: 0.84616761 | Z19: 113896.7
B20: PAYMENTBUSINESSDAYADJUSTMENT | C20: FOLLOWING | D20: FOLLOWING | F20: Total PV | G20: =_xll.meLWOTotalReturnSwapPV($G$4,$G$17) -> -1603864 | K20: 46184 | L20: 46367 | M20: 183 | N20: 0.50833333 | O20: 46367 | P20: 10000000 | Q20: 0 | R20: 1 | S20: 0.0275 | T20: 0.96305914 | U20: 0.0034182 | V20: 134627.64 | W20: 238.91794 | X20: 134866.56 | Y20: 0.83583303 | Z20: 112725.93
B21: PAYMENTCALENDAR | C21: NYB | D21: NYB:LNB | F21: Leg1:Premium | G21: =_xll.meLWOTotalReturnSwapPV($G$4,$G$17,F21) -> -156897.49 | K21: 46367 | L21: 46549 | M21: 182 | N21: 0.50555556 | O21: 46549 | P21: 10000000 | Q21: 0 | R21: 1 | S21: 0.0275 | T21: 0.95967161 | U21: 0.0033875308 | V21: 133421.01 | W21: 235.48044 | X21: 133656.49 | Y21: 0.82560893 | Z21: 110347.99
B22: PAYMENTLAG | C22: 0D | D22: 0D | F22: Leg2:Float | G22: =_xll.meLWOTotalReturnSwapPV($G$4,$G$17,F22) -> -1446966.5 | K22: 46549 | L22: 46734 | M22: 185 | N22: 0.51388889 | O22: 46734 | P22: 10000000 | Q22: 0 | R22: 1 | S22: 0.0275 | T22: 0.95624045 | U22: 0.0034311577 | V22: 135135.37 | W22: 242.44465 | X22: 135377.81 | Y22: 0.81527035 | Z22: 110369.52
B23: FIRSTSTUBDATE | F23: ParRate | G23: =_xll.meLWOTotalReturnSwapParRate(G4,G17) -> 0.045772253 | K23: 46734 | L23: 46916 | M23: 182 | N23: 0.50555556 | O23: 46916 | P23: 10000000 | Q23: 0 | R23: 1 | S23: 0.0275 | T23: 0.95287691 | U23: 0.0033635463 | V23: 132476.36 | W23: 233.81318 | X23: 132710.17 | Y23: 0.80515253 | Z23: 106851.93
B24: LASTSTUBDATE | F24: ParSpread | G24: =_xll.meLWOTotalReturnSwapParSpread(G4,G17) -> 56.361586 | K24: 46916 | L24: 47098 | M24: 182 | N24: 0.50555556 | O24: 47098 | P24: 10000000 | Q24: 0 | R24: 1 | S24: 0.0275 | T24: 0.94952519 | U24: 0.0033517151 | V24: 132010.38 | W24: 232.99075 | X24: 132243.37 | Y24: 0.79508831 | Z24: 105145.16
B25: ROLLDAY | C25: NORMAL | D25: NORMAL | K25: 47098 | L25: 47280 | M25: 182 | N25: 0.50555556 | O25: 47280 | P25: 10000000 | Q25: 10000000 | R25: 1 | S25: 0.0275 | T25: 0.94618526 | U25: 0.0033399255 | V25: 131546.03 | W25: 232.17121 | X25: 9593630.9 | Y25: 0.78507959 | Z25: 7531763.7
B26: STUBTYPE | C26: SHORTSTART | D26: SHORTSTART | K26: LEG2:FLOAT Leg Schedule & Cashflows
B27: FIXINGBUSINESSDAYADJUSTMENT | K27: FixingDate | L27: AccrualStart | M27: AccrualEnd | N27: AccrualDays | O27: AccrualYearFractions | P27: PaymentDate | Q27: Notional | R27: NotionalExchange | S27: Leverage | T27: FloatSpread | U27: FloatRate | V27: SurvivalProbability | W27: MarginalDefaultProbability | X27: Coupon | Y27: RiskyCoupon | Z27: DiscountFactor | AA27: CouponPV
B28: FIXINGCALENDAR | P28: 43629 | R28: 10000000 | S28: 1 | V28: 0.99997937 | W28: 2.0629417e-05 | X28: 9999793.7 | Y28: 9999793.7 | Z28: 0.99990428 | AA28: 9998836.6
B29: FIXINGLAG | K29: 43629 | L29: 43629 | M29: 43810 | N29: 181 | O29: 0.50277778 | P29: 43810 | Q29: -10000000 | R29: 0 | S29: 1 | T29: 239.34 | U29: 0.020137443 | V29: 0.99845065 | W29: 0.0015287168 | X29: -221238.12 | Y29: -221238.12 | Z29: 0.99077167 | AA29: -219196.46
B30: FIXINGADVANCEORARREAR | K30: 43810 | L30: 43810 | M30: 43993 | N30: 183 | O30: 0.50833333 | P30: 43993 | Q30: -10000000 | R30: 0 | S30: 1 | T30: 239.34 | U30: 0.019744761 | V30: 0.99661076 | W30: 0.0018398983 | X30: -221281.18 | Y30: -221281.18 | Z30: 0.98003555 | AA30: -216863.42
B31: FIRSTSTUBCURVEINDEX | K31: 43993 | L31: 43993 | M31: 44176 | N31: 183 | O31: 0.50833333 | P31: 44176 | Q31: -10000000 | R31: 0 | S31: 1 | T31: 239.34 | U31: 0.019155264 | V31: 0.99477425 | W31: 0.0018365078 | X31: -217892.46 | Y31: -217892.46 | Z31: 0.96831733 | AA31: -210989.04
B32: LASTSTUBCURVEINDEX | K32: 44176 | L32: 44176 | M32: 44358 | N32: 182 | O32: 0.50555556 | P32: 44358 | Q32: -10000000 | R32: 0 | S32: 1 | T32: 239.34 | U32: 0.019230323 | V32: 0.99275921 | W32: 0.0020150398 | X32: -216639.55 | Y32: -216639.55 | Z32: 0.95645368 | AA32: -207205.7
B33: PAYMENTTRIGGER | D33: PayOnSurvival | K33: 44358 | L33: 44358 | M33: 44543 | N33: 185 | O33: 0.51388889 | P33: 44543 | Q33: -10000000 | R33: 0 | S33: 1 | T33: 239.34 | U33: 0.019927722 | V33: 0.99071514 | W33: 0.0020440716 | X33: -223307.7 | Y33: -223307.7 | Z33: 0.94448867 | AA33: -210911.59
K34: 44543 | L34: 44543 | M34: 44725 | N34: 182 | O34: 0.50555556 | P34: 44725 | Q34: -10000000 | R34: 0 | S34: 1 | T34: 239.34 | U34: 0.020074539 | V34: 0.98850238 | W34: 0.0022127536 | X34: -219929.54 | Y34: -219929.54 | Z34: 0.93297559 | AA34: -205188.89
K35: 44725 | L35: 44725 | M35: 44907 | N35: 182 | O35: 0.50555556 | P35: 44907 | Q35: -10000000 | R35: 0 | S35: 1 | T35: 239.34 | U35: 0.01965006 | V35: 0.98629457 | W35: 0.0022078115 | X35: -217321.76 | Y35: -217321.76 | Z35: 0.92174917 | AA35: -200316.15
K36: 44907 | L36: 44907 | M36: 45089 | N36: 182 | O36: 0.50555556 | P36: 45089 | Q36: -10000000 | R36: 0 | S36: 1 | T36: 239.34 | U36: 0.019742339 | V36: 0.9843035 | W36: 0.0019910715 | X36: -217342.25 | Y36: -217342.25 | Z36: 0.91069471 | AA36: -197932.43
K37: 45089 | L37: 45089 | M37: 45271 | N37: 182 | O37: 0.50555556 | P37: 45271 | Q37: -10000000 | R37: 0 | S37: 1 | T37: 239.34 | U37: 0.020482605 | V37: 0.98231645 | W37: 0.0019870521 | X37: -220579.76 | Y37: -220579.76 | Z37: 0.89963501 | AA37: -198441.28
K38: 45271 | L38: 45271 | M38: 45454 | N38: 183 | O38: 0.50833333 | P38: 45454 | Q38: -10000000 | R38: 0 | S38: 1 | T38: 239.34 | U38: 0.021283753 | V38: 0.97916869 | W38: 0.003147754 | X38: -225068.69 | Y38: -225068.69 | Z38: 0.88856258 | AA38: -199987.62
K39: 45454 | L39: 45454 | M39: 45637 | N39: 183 | O39: 0.50833333 | P39: 45637 | Q39: -10000000 | R39: 0 | S39: 1 | T39: 239.34 | U39: 0.022006524 | V39: 0.97603103 | W39: 0.0031376673 | X39: -227933.5 | Y39: -227933.5 | Z39: 0.87767107 | AA39: -200050.64
K40: 45637 | L40: 45637 | M40: 45819 | N40: 182 | O40: 0.50555556 | P40: 45819 | Q40: -10000000 | R40: 0 | S40: 1 | T40: 239.34 | U40: 0.022651494 | V40: 0.97292048 | W40: 0.0031105494 | X40: -229137.9 | Y40: -229137.9 | Z40: 0.86703714 | AA40: -198671.07
K41: 45819 | L41: 45819 | M41: 46002 | N41: 183 | O41: 0.50833333 | P41: 46002 | Q41: -10000000 | R41: 0 | S41: 1 | T41: 239.34 | U41: 0.023226036 | V41: 0.96980283 | W41: 0.0031176454 | X41: -232491.01 | Y41: -232491.01 | Z41: 0.8565135 | AA41: -199131.69
...
