Workbook
Name COB: CZK_CURVES!$H$34
Name ExistsCZK12M: CZK_CURVES!$AI$48
Name ExistsCZK1M: CZK_CURVES!$AR$48
Name ExistsCZK3M: CZK_CURVES!$Z$48
Name ExistsCZK6M: CZK_CURVES!$Q$62
Name ExistsCZKOIS: CZK_CURVES!$H$52

Sheet TEMPLATES
B2: HandleName | C2: EM_CZK_OIS_UNDER_1Y | F2: HandleName | G2: EM_CZK_OIS | J2: HandleName | K2: EM_CZK_6M | N2: HandleName | O2: EM_CZK_3M | R2: HandleName | S2: EM_CZK_1M | V2: HandleName | W2: EM_CZK_12M
B3: CreateSwapGenerator | C3: =_xll.meLWOSwapGeneratorCreate(C2,B6:D31) -> EM_CZK_OIS_UNDER_1Y:1 | F3: CreateSwapGenerator | G3: =_xll.meLWOSwapGeneratorCreate(G2,F6:H31) -> EM_CZK_OIS:1 | J3: CreateSwapGenerator | K3: =_xll.meLWOSwapGeneratorCreate(K2,J6:L31) -> EM_CZK_6M:1 | N3: CreateSwapGenerator | O3: =_xll.meLWOSwapGeneratorCreate(O2,N6:P31) -> EM_CZK_3M:1 | R3: CreateSwapGenerator | S3: =_xll.meLWOSwapGeneratorCreate(S2,R6:T31) -> EM_CZK_1M:1 | V3: CreateSwapGenerator | W3: =_xll.meLWOSwapGeneratorCreate(W2,V6:X31) -> EM_CZK_12M:1
B6: LEGTYPE | C6: Leg1:Fixed | D6: Leg2:Float | F6: LEGTYPE | G6: Leg1:Fixed | H6: Leg2:Float | J6: LEGTYPE | K6: Leg1:Fixed | L6: Leg2:Float | N6: LEGTYPE | O6: Leg1:Float | P6: Leg2:Float | R6: LEGTYPE | S6: Leg1:Float | T6: Leg2:Float | V6: LEGTYPE | W6: Leg1:Float | X6: Leg2:Float
B7: LEVERAGE | C7: 1 | D7: 1 | F7: LEVERAGE | G7: 1 | H7: 1 | J7: LEVERAGE | K7: 1 | L7: 1 | N7: LEVERAGE | O7: 1 | P7: 1 | R7: LEVERAGE | S7: 1 | T7: 1 | V7: LEVERAGE | W7: 1 | X7: 1
B8: FORECASTCURVE | D8: CZKOIS | F8: FORECASTCURVE | H8: CZKOIS | J8: FORECASTCURVE | L8: PRB6M | N8: FORECASTCURVE | O8: PRB6M | P8: PRB3M | R8: FORECASTCURVE | S8: PRB3M | T8: PRB1M | V8: FORECASTCURVE | W8: PRB3M | X8: PRB12M
B9: COMPOUNDMETHOD | C9: NONE | D9: GEOMETRIC | F9: COMPOUNDMETHOD | G9: NONE | H9: ARITHMETIC | J9: COMPOUNDMETHOD | K9: NONE | L9: NONE | N9: COMPOUNDMETHOD | O9: NONE | P9: NONE | R9: COMPOUNDMETHOD | S9: NONE | T9: NONE | V9: COMPOUNDMETHOD | W9: NONE | X9: NONE
B10: NOTIONALEXCHANGE | C10: NONE | D10: NONE | F10: NOTIONALEXCHANGE | G10: NONE | H10: NONE | J10: NOTIONALEXCHANGE | K10: NONE | L10: NONE | N10: NOTIONALEXCHANGE | O10: NONE | P10: NONE | R10: NOTIONALEXCHANGE | S10: NONE | T10: NONE | V10: NOTIONALEXCHANGE | W10: NONE | X10: NONE
B11: DISCOUNTCURVE | C11: CZKOIS | D11: CZKOIS | F11: DISCOUNTCURVE | G11: CZKOIS | H11: CZKOIS | J11: DISCOUNTCURVE | K11: CZKOIS | L11: CZKOIS | N11: DISCOUNTCURVE | O11: CZKOIS | P11: CZKOIS | R11: DISCOUNTCURVE | S11: CZKOIS | T11: CZKOIS | V11: DISCOUNTCURVE | W11: CZKOIS | X11: CZKOIS
B12: VALUATIONCURRENCY | C12: CZK | D12: CZK | F12: VALUATIONCURRENCY | G12: CZK | H12: CZK | J12: VALUATIONCURRENCY | K12: CZK | L12: CZK | N12: VALUATIONCURRENCY | O12: CZK | P12: CZK | R12: VALUATIONCURRENCY | S12: CZK | T12: CZK | V12: VALUATIONCURRENCY | W12: CZK | X12: CZK
B13: CURRENCY | C13: CZK | D13: CZK | F13: CURRENCY | G13: CZK | H13: CZK | J13: CURRENCY | K13: CZK | L13: CZK | N13: CURRENCY | O13: CZK | P13: CZK | R13: CURRENCY | S13: CZK | T13: CZK | V13: CURRENCY | W13: CZK | X13: CZK
B14: ACCRUALFREQUENCY | C14: ANNUAL | D14: ANNUAL | F14: ACCRUALFREQUENCY | G14: ANNUAL | H14: ANNUAL | J14: ACCRUALFREQUENCY | K14: ANNUAL | L14: SEMI-ANNUAL | N14: ACCRUALFREQUENCY | O14: SEMI-ANNUAL | P14: QUARTERLY | R14: ACCRUALFREQUENCY | S14: QUARTERLY | T14: MONTHLY | V14: ACCRUALFREQUENCY | W14: QUARTERLY | X14: ANNUAL
B15: ACCRUALBUSINESSDAYADJUSTMENT | C15: MOD_FOLLOWING | D15: MOD_FOLLOWING | F15: ACCRUALBUSINESSDAYADJUSTMENT | G15: MOD_FOLLOWING | H15: MOD_FOLLOWING | J15: ACCRUALBUSINESSDAYADJUSTMENT | K15: MOD_FOLLOWING | L15: MOD_FOLLOWING | N15: ACCRUALBUSINESSDAYADJUSTMENT | O15: MOD_FOLLOWING | P15: MOD_FOLLOWING | R15: ACCRUALBUSINESSDAYADJUSTMENT | S15: MOD_FOLLOWING | T15: MOD_FOLLOWING | V15: ACCRUALBUSINESSDAYADJUSTMENT | W15: MOD_FOLLOWING | X15: MOD_FOLLOWING
B16: ACCRUALCALENDAR | C16: PRB | D16: PRB | F16: ACCRUALCALENDAR | G16: PRB | H16: PRB | J16: ACCRUALCALENDAR | K16: PRB | L16: PRB | N16: ACCRUALCALENDAR | O16: PRB | P16: PRB | R16: ACCRUALCALENDAR | S16: PRB | T16: PRB | V16: ACCRUALCALENDAR | W16: PRB | X16: PRB
B17: ACCRUALDAYCOUNT | C17: ACT/360 | D17: ACT/360 | F17: ACCRUALDAYCOUNT | G17: ACT/360 | H17: ACT/360 | J17: ACCRUALDAYCOUNT | K17: ACT/360 | L17: ACT/360 | N17: ACCRUALDAYCOUNT | O17: ACT/360 | P17: ACT/360 | R17: ACCRUALDAYCOUNT | S17: ACT/360 | T17: ACT/360 | V17: ACCRUALDAYCOUNT | W17: ACT/360 | X17: ACT/360
B18: PAYMENTFREQUENCY | F18: PAYMENTFREQUENCY | J18: PAYMENTFREQUENCY | N18: PAYMENTFREQUENCY | R18: PAYMENTFREQUENCY | V18: PAYMENTFREQUENCY
B19: PAYMENTBUSINESSDAYADJUSTMENT | C19: MOD_FOLLOWING | D19: MOD_FOLLOWING | F19: PAYMENTBUSINESSDAYADJUSTMENT | G19: MOD_FOLLOWING | H19: MOD_FOLLOWING | J19: PAYMENTBUSINESSDAYADJUSTMENT | K19: MOD_FOLLOWING | L19: MOD_FOLLOWING | N19: PAYMENTBUSINESSDAYADJUSTMENT | O19: MOD_FOLLOWING | P19: MOD_FOLLOWING | R19: PAYMENTBUSINESSDAYADJUSTMENT | S19: MOD_FOLLOWING | T19: MOD_FOLLOWING | V19: PAYMENTBUSINESSDAYADJUSTMENT | W19: MOD_FOLLOWING | X19: MOD_FOLLOWING
B20: PAYMENTCALENDAR | C20: PRB | D20: PRB | F20: PAYMENTCALENDAR | G20: PRB | H20: PRB | J20: PAYMENTCALENDAR | K20: PRB | L20: PRB | N20: PAYMENTCALENDAR | O20: PRB | P20: PRB | R20: PAYMENTCALENDAR | S20: PRB | T20: PRB | V20: PAYMENTCALENDAR | W20: PRB | X20: PRB
B21: PAYMENTLAG | C21: 0D | D21: 0D | F21: PAYMENTLAG | G21: 0D | H21: 0D | J21: PAYMENTLAG | K21: 0D | L21: 0D | N21: PAYMENTLAG | O21: 0D | P21: 0D | R21: PAYMENTLAG | S21: 0D | T21: 0D | V21: PAYMENTLAG | W21: 0D | X21: 0D
B22: FIRSTSTUBDATE | F22: FIRSTSTUBDATE | J22: FIRSTSTUBDATE | N22: FIRSTSTUBDATE | R22: FIRSTSTUBDATE | V22: FIRSTSTUBDATE
B23: LASTSTUBDATE | F23: LASTSTUBDATE | J23: LASTSTUBDATE | N23: LASTSTUBDATE | R23: LASTSTUBDATE | V23: LASTSTUBDATE
B24: ROLLDAY | C24: NORMAL | D24: NORMAL | F24: ROLLDAY | G24: NORMAL | H24: NORMAL | J24: ROLLDAY | K24: NORMAL | L24: NORMAL | N24: ROLLDAY | O24: NORMAL | P24: NORMAL | R24: ROLLDAY | S24: NORMAL | T24: NORMAL | V24: ROLLDAY | W24: NORMAL | X24: NORMAL
B25: STUBTYPE | C25: SHORTSTART | D25: SHORTSTART | F25: STUBTYPE | G25: SHORTSTART | H25: SHORTSTART | J25: STUBTYPE | K25: SHORTSTART | L25: SHORTSTART | N25: STUBTYPE | O25: SHORTSTART | P25: SHORTSTART | R25: STUBTYPE | S25: SHORTSTART | T25: SHORTSTART | V25: STUBTYPE | W25: SHORTSTART | X25: SHORTSTART
B26: FIXINGBUSINESSDAYADJUSTMENT | D26: MOD_FOLLOWING | F26: FIXINGBUSINESSDAYADJUSTMENT | H26: MOD_FOLLOWING | J26: FIXINGBUSINESSDAYADJUSTMENT | L26: MOD_FOLLOWING | N26: FIXINGBUSINESSDAYADJUSTMENT | O26: MOD_FOLLOWING | P26: MOD_FOLLOWING | R26: FIXINGBUSINESSDAYADJUSTMENT | S26: MOD_FOLLOWING | T26: MOD_FOLLOWING | V26: FIXINGBUSINESSDAYADJUSTMENT | W26: MOD_FOLLOWING | X26: MOD_FOLLOWING
B27: FIXINGCALENDAR | D27: PRB | F27: FIXINGCALENDAR | H27: PRB | J27: FIXINGCALENDAR | L27: PRB | N27: FIXINGCALENDAR | O27: PRB | P27: PRB | R27: FIXINGCALENDAR | S27: PRB | T27: PRB | V27: FIXINGCALENDAR | W27: PRB | X27: PRB
B28: FIXINGLAG | D28: 0D | F28: FIXINGLAG | H28: 0D | J28: FIXINGLAG | L28: 0D | N28: FIXINGLAG | O28: 0D | P28: 0D | R28: FIXINGLAG | S28: 0D | T28: 0D | V28: FIXINGLAG | W28: 0D | X28: 0D
B29: FIXINGADVANCEORARREAR | F29: FIXINGADVANCEORARREAR | J29: FIXINGADVANCEORARREAR | N29: FIXINGADVANCEORARREAR | R29: FIXINGADVANCEORARREAR | V29: FIXINGADVANCEORARREAR
B30: FIRSTSTUBCURVEINDEX | D30: NATURAL | F30: FIRSTSTUBCURVEINDEX | H30: NATURAL | J30: FIRSTSTUBCURVEINDEX | L30: NATURAL | N30: FIRSTSTUBCURVEINDEX | O30: NATURAL | P30: NATURAL | R30: FIRSTSTUBCURVEINDEX | S30: NATURAL | T30: NATURAL | V30: FIRSTSTUBCURVEINDEX | W30: NATURAL | X30: NATURAL
B31: LASTSTUBCURVEINDEX | D31: NATURAL | F31: LASTSTUBCURVEINDEX | H31: NATURAL | J31: LASTSTUBCURVEINDEX | L31: NATURAL | N31: LASTSTUBCURVEINDEX | O31: NATURAL | P31: NATURAL | R31: LASTSTUBCURVEINDEX | S31: NATURAL | T31: NATURAL | V31: LASTSTUBCURVEINDEX | W31: NATURAL | X31: NATURAL

Sheet CZK_CURVES
B2: CREATE CURVE GENERATOR | G2: MARKET DATA | P2: MARKET DATA | Y2: MARKET DATA | AH2: MARKET DATA | AQ2: MARKET DATA
G3: Term | H3: Rate | I3: Use | P3: Term | Q3: Rate | R3: Use | Y3: Term | Z3: Rate | AA3: Use | AH3: Term | AI3: Rate | AJ3: Use | AQ3: Term | AR3: Rate | AS3: Use
G4: ON | H4: 0.0007 | I4: TRUE | P4: ON | Q4: 0.0025 | R4: TRUE | Y4: ON | Z4: 0.0032 | AA4: TRUE | AH4: 1Y | AI4: 0.01 | AJ4: TRUE | AQ4: 1Y | AR4: 0.0035 | AS4: TRUE
C5: OIS CURVE | G5: 1W | H5: 0.0012 | I5: TRUE | L5: SWAP CURVE | P5: 1M | Q5: 0.003 | R5: TRUE | U5: TENOR BASIS CURVE | Y5: 1M | Z5: 0.003 | AA5: TRUE | AD5: TENOR BASIS CURVE | AH5: 2Y | AI5: 0.01 | AJ5: TRUE | AM5: TENOR BASIS CURVE | AQ5: 2Y | AR5: 0.0035 | AS5: TRUE
C6: Enable: CreateCurveGenerator | D6: TRUE | G6: 2W | H6: 0.0016 | I6: TRUE | L6: Enable: CreateCurveGenerator | M6: TRUE | P6: 3M | Q6: 0.0034 | R6: TRUE | U6: Enable: CreateCurveGenerator | V6: TRUE | Y6: 3M | Z6: 0.0034 | AA6: TRUE | AD6: Enable: CreateCurveGenerator | AE6: TRUE | AH6: 3Y | AI6: 0.01 | AJ6: TRUE | AM6: Enable: CreateCurveGenerator | AN6: TRUE | AQ6: 3Y | AR6: 0.0035 | AS6: TRUE
C7: Generator Name | D7: EM_CZK_CURVE_OIS | G7: 1M | H7: 0.0012 | I7: TRUE | L7: Generator Name | M7: EM_CZK_SWAP_6M | P7: 6M | Q7: 0.0036 | R7: TRUE | U7: Generator Name | V7: EM_CZK_BASIS_3M | Y7: 1x4 | Z7: 0.00348 | AA7: TRUE | AD7: Generator Name | AE7: EM_CZK_BASIS_12M | AH7: 4Y | AI7: 0.01 | AJ7: TRUE | AM7: Generator Name | AN7: EM_CZK_BASIS_1M | AQ7: 4Y | AR7: 0.0035 | AS7: TRUE
C8: Create Curve Generator | D8: =IF(D$6,_xll.meLWOCurveGeneratorCreate(D$7,"CURVEPROPERTIES",C12:D18,"OIS",C23:D37),"Disabled") -> EM_CZK_CURVE_OIS:10 | G8: 2M | H8: 0.0012 | I8: TRUE | L8: Create Curve Generator | M8: =IF(M$6,_xll.meLWOCurveGeneratorCreate(M$7,"CURVEPROPERTIES",L12:M27,"MONEYMARKET",L30:M32,"LIBORFIXINGS",L35:M39,"FRAS",L42:M45,"SWAPS",L48:M65,"BASISSWAPS",L68:M99),"Disabled") -> EM_CZK_SWAP_6M:9 | P8: 1x7 | Q8: 0.00368 | R8: TRUE | U8: Create Curve Generator | V8: =IF(V$6,_xll.meLWOCurveGeneratorCreate(V$7,"CURVEPROPERTIES",U12:V22,"MONEYMARKET",U25:V27,"LIBORFIXINGS",U30:V34,"FRAS",U37:V41,"BASISSWAPS",U43:V84),"Disabled") -> EM_CZK_BASIS_3M:8 | Y8: 2x5 | Z8: 0.00348 | AA8: TRUE | AD8: Create Curve Generator | AE8: =IF(AE$6,_xll.meLWOCurveGeneratorCreate(AE$7,AD11,AD12:AE21,AD26,AD27:AE65),"Disabled") -> EM_CZK_BASIS_12M:7 | AH8: 5Y | AI8: 0.01 | AJ8: TRUE | AM8: Create Curve Generator | AN8: =IF(AN$6,_xll.meLWOCurveGeneratorCreate(AN$7,AM11,AM12:AN21,"LIBORFIXINGS",AM32:AN36,"BASISSWAPS",AM39:AN80),"Disabled") -> EM_CZK_BASIS_1M:6 | AQ8: 5Y | AR8: 0.0035 | AS8: TRUE
G9: 3M | H9: 0.0013 | I9: TRUE | P9: 2x8 | Q9: 0.0038 | R9: TRUE | Y9: 3x6 | Z9: 0.0035 | AA9: TRUE | AH9: 6Y | AI9: 0.01 | AJ9: TRUE | AQ9: 6Y | AR9: 0.0035 | AS9: TRUE
G10: 6M | H10: 0.0013 | I10: TRUE | P10: 3x9 | Q10: 0.004 | R10: TRUE | Y10: 6x9 | Z10: 0.00368 | AA10: TRUE | AH10: 7Y | AI10: 0.01 | AJ10: TRUE | AQ10: 7Y | AR10: 0.0035 | AS10: TRUE
C11: CURVEPROPERTIES | G11: 9M | H11: 0.0014 | I11: TRUE | L11: CURVEPROPERTIES | P11: 4x10 | Q11: 0.00413 | R11: TRUE | U11: CURVEPROPERTIES | Y11: 1Y | Z11: 0.00045 | AA11: TRUE | AD11: CURVEPROPERTIES | AH11: 8Y | AI11: 0.01 | AJ11: TRUE | AM11: CURVEPROPERTIES | AQ11: 8Y | AR11: 0.0035 | AS11: TRUE
C12: CurveType | D12: OIS | G12: 1Y | H12: 0.0016 | I12: TRUE | L12: CurveType | M12: SWAP | P12: 5x11 | Q12: 0.00418 | R12: TRUE | U12: Currency | V12: CZK | Y12: 2Y | Z12: 0.000525 | AA12: TRUE | AD12: Currency | AE12: CZK | AH12: 9Y | AI12: 0.01 | AJ12: TRUE | AM12: Currency | AN12: CZK | AQ12: 9Y | AR12: 0.0035 | AS12: TRUE
C13: CurveIndexFrequency | D13: DAILY | G13: 2Y | H13: 0.00141 | I13: TRUE | L13: CurveIndexFrequency | M13: SEMI-ANNUAL | P13: 1Y | Q13: 0.00045 | R13: TRUE | U13: CurveType | V13: TENORBASIS | Y13: 3Y | Z13: 0.000575 | AA13: TRUE | AD13: CurveType | AE13: TENORBASIS | AH13: 10Y | AI13: 0.01 | AJ13: TRUE | AM13: CurveType | AN13: TENORBASIS | AQ13: 10Y | AR13: 0.0035 | AS13: TRUE
C14: StaticDataTable | D14: OIS | G14: 3Y | H14: 0.00138 | I14: TRUE | L14: StaticDataTable | M14: STD | P14: 2Y | Q14: 0 | R14: TRUE | U14: CurveIndexFrequency | V14: QUARTERLY | Y14: 4Y | Z14: 0.000675 | AA14: TRUE | AD14: CurveIndexFrequency | AE14: ANNUAL | AH14: 12Y | AI14: 0.01 | AJ14: TRUE | AM14: CurveIndexFrequency | AN14: MONTHLY | AQ14: 12Y | AR14: 0.0035 | AS14: TRUE
C15: IndexName | D15: OIS:CZKOIS | G15: 4Y | H15: 0.00152 | I15: TRUE | L15: IndexName | M15: ="STD:"&"PRB"&"6M" -> STD:PRB6M | P15: 3Y | Q15: 0 | R15: TRUE | U15: StaticDataTable | V15: 3M6MBasis | Y15: 5Y | Z15: 0.000775 | AA15: TRUE | AD15: StaticDataTable | AE15: 3M12MBasis | AH15: 15Y | AI15: 0.01 | AJ15: TRUE | AM15: StaticDataTable | AN15: 1M3MBasis | AQ15: 15Y | AR15: 0.0035 | AS15: TRUE
C16: Currency | D16: CZK | G16: 5Y | H16: 0.00178 | I16: TRUE | L16: Currency | M16: CZK | P16: 4Y | Q16: 0 | R16: TRUE | U16: IndexName | V16: 3M6MBasis:PRB3M | Y16: 6Y | Z16: 0.000875 | AA16: TRUE | AD16: IndexName | AE16: 3M12MBasis:PRB12M | AH16: 20Y | AI16: 0.01 | AJ16: TRUE | AM16: IndexName | AN16: 1M3MBasis:PRB1M | AQ16: 20Y | AR16: 0.0035 | AS16: TRUE
C17: interpolation | D17: FN_SPLINEINTERPOLATION | G17: 6Y | H17: 0.00214 | I17: TRUE | L17: interpolation | M17: SPLINE | P17: 5Y | Q17: 0 | R17: TRUE | U17: interpolation | V17: FN_SPLINEINTERPOLATION | Y17: 7Y | Z17: 0.000995 | AA17: TRUE | AD17: interpolation | AE17: FN_SPLINEINTERPOLATION | AM17: interpolation | AN17: FN_SPLINEINTERPOLATION
C18: yieldgen.interpolation | D18: FN_SPLINEINTERPOLATION | G18: 7Y | H18: 0.00257 | I18: TRUE | L18: yieldgen.interpolation | M18: SPLINE | P18: 6Y | Q18: 0 | R18: TRUE | U18: yieldgen.interpolation | V18: FN_SPLINEINTERPOLATION | Y18: 8Y | Z18: 0.00112 | AA18: TRUE | AD18: yieldgen.interpolation | AE18: FN_SPLINEINTERPOLATION | AM18: yieldgen.interpolation | AN18: FN_SPLINEINTERPOLATION
G19: 8Y | H19: 0.00304 | I19: TRUE | L19: future.interpolation | M19: SPLINE | P19: 7Y | Q19: 0 | R19: TRUE | U19: basis.interpolation | V19: FN_SPLINEINTERPOLATION | Y19: 9Y | Z19: 0.00127 | AA19: TRUE | AD19: basis.interpolation | AE19: FN_SPLINEINTERPOLATION | AM19: basis.interpolation | AN19: FN_SPLINEINTERPOLATION
G20: 9Y | H20: 0.00351 | I20: TRUE | L20: isfrause | M20: TRUE | P20: 8Y | Q20: 0 | R20: TRUE | U20: isFwdBasis | V20: FALSE | Y20: 10Y | Z20: 0.001395 | AA20: TRUE | AD20: isFwdBasis | AE20: FALSE | AM20: isFwdBasis | AN20: FALSE
G21: 10Y | H21: 0.00401 | I21: TRUE | L21: isfutureuse | M21: FALSE | P21: 9Y | Q21: 0 | R21: TRUE | U21: isFRAUse | V21: TRUE | Y21: 12Y | Z21: 0.001485 | AA21: TRUE | AD21: dfCurveName | AE21: OIS | AM21: dfCurveName | AN21: OIS
C22: OIS | G22: 12Y | H22: 0.00494 | I22: TRUE | L22: Frequency | M22: SIMPLE | P22: 10Y | Q22: 0 | R22: TRUE | U22: dfCurveName | V22: OIS | Y22: 15Y | Z22: 0.00131 | AA22: TRUE
C23: calendar | D23: PRB | G23: 15Y | H23: 0.0061 | I23: TRUE | L23: AlwaysCalcJoinDate | M23: FALSE | P23: 12Y | Q23: 0 | R23: TRUE | Y23: 20Y | Z23: 0.00121 | AA23: TRUE
C24: daycount | D24: ACT/360 | G24: 20Y | H24: 0.00704 | I24: TRUE | L24: FastRebuild | M24: TRUE | P24: 15Y | Q24: 0 | R24: TRUE | U24: MONEYMARKET
C25: frequency | D25: ANNUAL | G25: 25Y | H25: 0.00717 | I25: TRUE | L25: DfCurveName | M25: OIS | P25: 20Y | Q25: 0 | R25: TRUE | U25: calendar | V25: PRB
C26: generatemethod | D26: DAILYCOMPOUNDING | G26: 30Y | H26: 0.00701 | I26: TRUE | L26: IsSwapTenorAdjust | M26: TRUE | P26: 1Y | Q26: 0.00365 | R26: TRUE | U26: daycount | V26: ACT/360 | Y26: MarketDataProperties | AD26: BASISSWAPS | AH26: MarketDataProperties | AM26: MONEYMARKET | AQ26: MarketDataProperties
C27: resetlag | D27: 2D | G27: 40Y | H27: 0.00663 | I27: TRUE | L27: TenorSwapName | M27: 3M6MBasis | P27: 2Y | Q27: 0.0055 | R27: TRUE | U27: slidingrule | V27: FOLLOWING | Y27: Currency | Z27: CZK | AD27: MarketName | AE27: 3M12MBasis | AH27: Currency | AI27: CZK | AM27: calendar | AN27: PRB | AQ27: Currency | AR27: CZK
C28: firstrate | D28: SHORTMARKET | G28: 50Y | H28: 0.00628 | I28: TRUE | P28: 3Y | Q28: 0.006875 | R28: TRUE | Y28: CurveType | Z28: TENORBASIS | AD28: IsLeg1Spread | AE28: FALSE | AH28: CurveType | AI28: TENORBASIS | AM28: daycount | AN28: ACT/360 | AQ28: CurveType | AR28: TENORBASIS
C29: slidingrule | D29: MOD_FOLLOWING | L29: MONEYMARKET | P29: 4Y | Q29: 0.007975 | R29: TRUE | U29: LIBORFIXINGS | Y29: CurveIndexFrequency | Z29: QUARTERLY | AD29: Leg1cashlet.calendar | AE29: PRB | AH29: CurveIndexFrequency | AI29: ANNUAL | AM29: slidingrule | AN29: FOLLOWING | AQ29: CurveIndexFrequency | AR29: MONTHLY
C30: eomday | D30: 31 | G30: MarketDataProperties | L30: calendar | M30: PRB | P30: 5Y | Q30: 0.00895 | R30: TRUE | U30: calendar | V30: PRB | Y30: AsOfDate | Z30: =COB -> 44075 | AD30: Leg1cashlet.daycount | AE30: ACT/360 | AH30: AsOfDate | AI30: =COB -> 44075 | AQ30: AsOfDate | AR30: =COB -> 44075
C31: iseomroll | D31: TRUE | G31: Currency | H31: CZK | L31: daycount | M31: ACT/360 | P31: 6Y | Q31: 0.009675 | R31: TRUE | U31: daycount | V31: ACT/360 | AD31: Leg1cashlet.frequency | AE31: ANNUAL | AM31: LIBORFIXINGS
C32: shorttermconvention | D32: ARITHMETICAVERAGE | G32: CurveType | H32: OIS | L32: slidingrule | M32: FOLLOWING | P32: 7Y | Q32: 0.010125 | R32: TRUE | U32: frequency | V32: simple | Y32: Create Market Data Handle | AD32: Leg1cashlet.slidingrule | AE32: MOD_FOLLOWING | AH32: Create Market Data Handle | AM32: calendar | AN32: PRB | AQ32: Create Market Data Handle
C33: longterm.generatemethod | D33: NONE | G33: CurveIndexFrequency | H33: DAILY | P33: 8Y | Q33: 0.010475 | R33: TRUE | U33: resetlag | V33: 2D | Y33: Handle Name | Z33: CZK_3M_MKT | AD33: Leg1cashlet.spotlag | AE33: 2D | AH33: Handle Name | AI33: CZK_12M_MKT | AM33: daycount | AN33: ACT/360 | AQ33: Handle Name | AR33: CZK_1M_MKT
C34: Epsilon | D34: 1e-10 | G34: AsOfDate | H34: 44075 | L34: LIBORFIXINGS | P34: 9Y | Q34: 0.01085 | R34: TRUE | U34: slidingrule | V34: MOD_FOLLOWING | Y34: Market Data Handle | Z34: =_xll.meLWOCurveMarketDataCreate(Z33,Y26,Y27:Z30,"LIBORFIXINGS",Y6:AA6,"FRAS",Y7:AA10,"BASISSWAPS",Y11:AA23) -> CZK_3M_MKT:1 | AD34: Leg1forecast | AE34: CZKOIS | AF34: <-- Initial Guess | AH34: Market Data Handle | AI34: =_xll.meLWOCurveMarketDataCreate(AI33,AH26,AH27:AI30,"BASISSWAPS",AH4:AJ20) -> CZK_12M_MKT:1 | AM34: frequency | AN34: simple | AQ34: Market Data Handle | AR34: =_xll.meLWOCurveMarketDataCreate(AR33,AQ26,AQ27:AR30,"BASISSWAPS",AQ4:AS20) -> CZK_1M_MKT:1
C35: MaxLoop | D35: 1000 | L35: calendar | M35: PRB | P35: 10Y | Q35: 0.0111 | R35: TRUE | AD35: Leg1discount | AE35: CZKOIS | AM35: resetlag | AN35: 2D
C36: CompoundingMethod | D36: ARITHMETIC | G36: Create Market Data Handle | L36: daycount | M36: ACT/360 | P36: 12Y | Q36: 0.01135 | R36: TRUE | U36: FRAS | Y36: Curve Dictionary | AD36: Leg1index.accessary | AE36: 12M | AH36: Curve Dictionary | AM36: slidingrule | AN36: MOD_FOLLOWING | AQ36: Curve Dictionary
C37: SmoothShortEnd | D37: FALSE | G37: Handle Name | H37: =H31&"_"&H32&"_MKT" -> CZK_OIS_MKT | L37: frequency | M37: simple | P37: 15Y | Q37: 0.0126 | R37: TRUE | U37: Calendar | V37: PRB | Y37: Handle Name | Z37: CZK_BASIS_3M_CURVE | AD37: Leg1index.payment.calendar | AE37: PRB | AH37: Handle Name | AI37: CZK_BASIS_12M_CURVE | AQ37: Handle Name | AR37: CZK_BASIS_1M_CURVE
G38: Market Data Handle | H38: =_xll.meLWOCurveMarketDataCreate(H37,"MarketDataProperties",G31:H34,"OIS",G4:I28) -> CZK_OIS_MKT:1 | L38: resetlag | M38: 2D | P38: 20Y | Q38: 0.01255 | R38: TRUE | U38: DayCount | V38: ACT/360 | Y38: Curve Generator | Z38: =V8 -> EM_CZK_BASIS_3M:8 | AD38: Leg1index.resetlag | AE38: 2D | AH38: Curve Generator | AI38: =AE8 -> EM_CZK_BASIS_12M:7 | AM38: BASISSWAPS | AQ38: Curve Generator | AR38: =AN8 -> EM_CZK_BASIS_1M:6
L39: slidingrule | M39: MOD_FOLLOWING | U39: ResetLag | V39: 2d | Y39: Domestic Curve Collection | Z39: CZKYC | AD39: Leg1index.slidingrule | AE39: MOD_FOLLOWING | AH39: Domestic Curve Collection | AI39: CZKYC | AM39: MarketName | AN39: 1M3MBasis | AQ39: Domestic Curve Collection | AR39: CZKYC
G40: Curve Dictionary | P40: MarketDataProperties | U40: SlidingRule | V40: MOD_FOLLOWING | Y40: Foreign Curve Collection | AD40: Leg2cashlet.calendar | AE40: PRB | AH40: Foreign Curve Collection | AM40: IsLeg1Spread | AN40: FALSE | AQ40: Foreign Curve Collection
G41: Handle Name | H41: =H31&"_"&H32&"_CURVE" -> CZK_OIS_CURVE | L41: FRAS | P41: Currency | Q41: CZK | AD41: Leg2cashlet.daycount | AE41: ACT/360 | AM41: Leg1cashlet.calendar | AN41: PRB
...

Sheet CZK SWAPS
B3: Trade Dates | F3: SWAPS: CZK_OIS | N3: Trade Booking & Pricing | R3: Curve Calibration Check
D4: Unadjusted Date ! | H4: Swap Template
B5: EffectiveDate | C5: Calendar | D5: MaturityDate | F5: EffectiveDate | G5: Maturity | H5: Generator | I5: PayRec | J5: Notional | K5: FixedRate | L5: Spread | N5: CreateSwap | O5: CurveCollection | P5: ParRate | R5: Term | S5: Rate | T5: +/- Bps
B6: =_xll.meDateFromTenor(COB,F6,"MOD_FOLLOWING",$C6,"") -> 44075 | C6: PRB | D6: =_xll.meDateFromTenor(B6,G6,) -> 44076 | F6: 0D | G6: =CZK_CURVES!G4 -> ON | H6: =TEMPLATES!$C$3 -> EM_CZK_OIS_UNDER_1Y:1 | I6: PAY | J6: 1000000 | K6: 0.01 | L6: 0 | M6: 1 | N6: =_xll.meLWOSwapCreateFromGenerator("CZK_SWAP"&M6,H6,I6,J6,B6,D6,K6,L6) -> CZK_SWAP1:10 | O6: CZKYC | P6: =_xll.meLWOSwapParRate(N6,O6) -> 0.0007 | R6: =CZK_CURVES!G4 -> ON | S6: =CZK_CURVES!H4 -> 0.0007 | T6: =(P6-S6)*10000 -> -3.5382287e-10
B7: =_xll.meDateFromTenor(COB,F7,"MOD_FOLLOWING",$C7,"") -> 44077 | C7: PRB | D7: =_xll.meDateFromTenor(B7,G7,) -> 44084 | F7: 2D | G7: =CZK_CURVES!G5 -> 1W | H7: =TEMPLATES!$C$3 -> EM_CZK_OIS_UNDER_1Y:1 | I7: PAY | J7: 1000000 | K7: 0.01 | L7: 0 | M7: =M6+1 -> 2 | N7: =_xll.meLWOSwapCreateFromGenerator("CZK_SWAP"&M7,H7,I7,J7,B7,D7,K7,L7) -> CZK_SWAP2:10 | O7: CZKYC | P7: =_xll.meLWOSwapParRate(N7,O7) -> 0.0012 | R7: =CZK_CURVES!G5 -> 1W | S7: =CZK_CURVES!H5 -> 0.0012 | T7: =(P7-S7)*10000 -> -3.5579178e-11
B8: =_xll.meDateFromTenor(COB,F8,"MOD_FOLLOWING",$C8,"") -> 44077 | C8: PRB | D8: =_xll.meDateFromTenor(B8,G8,) -> 44091 | F8: 2D | G8: =CZK_CURVES!G6 -> 2W | H8: =TEMPLATES!$C$3 -> EM_CZK_OIS_UNDER_1Y:1 | I8: PAY | J8: 1000000 | K8: 0.01 | L8: 0 | M8: =M7+1 -> 3 | N8: =_xll.meLWOSwapCreateFromGenerator("CZK_SWAP"&M8,H8,I8,J8,B8,D8,K8,L8) -> CZK_SWAP3:10 | O8: CZKYC | P8: =_xll.meLWOSwapParRate(N8,O8) -> 0.0016 | R8: =CZK_CURVES!G6 -> 2W | S8: =CZK_CURVES!H6 -> 0.0016 | T8: =(P8-S8)*10000 -> -1.8066494e-10
B9: =_xll.meDateFromTenor(COB,F9,"MOD_FOLLOWING",$C9,"") -> 44077 | C9: PRB | D9: =_xll.meDateFromTenor(B9,G9,) -> 44107 | F9: 2D | G9: =CZK_CURVES!G7 -> 1M | H9: =TEMPLATES!$C$3 -> EM_CZK_OIS_UNDER_1Y:1 | I9: PAY | J9: 1000000 | K9: 0.01 | L9: 0 | M9: =M8+1 -> 4 | N9: =_xll.meLWOSwapCreateFromGenerator("CZK_SWAP"&M9,H9,I9,J9,B9,D9,K9,L9) -> CZK_SWAP4:10 | O9: CZKYC | P9: =_xll.meLWOSwapParRate(N9,O9) -> 0.0012 | R9: =CZK_CURVES!G7 -> 1M | S9: =CZK_CURVES!H7 -> 0.0012 | T9: =(P9-S9)*10000 -> -1.4620033e-10
B10: =_xll.meDateFromTenor(COB,F10,"MOD_FOLLOWING",$C10,"") -> 44077 | C10: PRB | D10: =_xll.meDateFromTenor(B10,G10,) -> 44138 | F10: 2D | G10: =CZK_CURVES!G8 -> 2M | H10: =TEMPLATES!$C$3 -> EM_CZK_OIS_UNDER_1Y:1 | I10: PAY | J10: 1000000 | K10: 0.01 | L10: 0 | M10: =M9+1 -> 5 | N10: =_xll.meLWOSwapCreateFromGenerator("CZK_SWAP"&M10,H10,I10,J10,B10,D10,K10,L10) -> CZK_SWAP5:10 | O10: CZKYC | P10: =_xll.meLWOSwapParRate(N10,O10) -> 0.0012 | R10: =CZK_CURVES!G8 -> 2M | S10: =CZK_CURVES!H8 -> 0.0012 | T10: =(P10-S10)*10000 -> -9.1736514e-11
B11: =_xll.meDateFromTenor(COB,F11,"MOD_FOLLOWING",$C11,"") -> 44077 | C11: PRB | D11: =_xll.meDateFromTenor(B11,G11,) -> 44168 | F11: 2D | G11: =CZK_CURVES!G9 -> 3M | H11: =TEMPLATES!$C$3 -> EM_CZK_OIS_UNDER_1Y:1 | I11: PAY | J11: 1000000 | K11: 0.01 | L11: 0 | M11: =M10+1 -> 6 | N11: =_xll.meLWOSwapCreateFromGenerator("CZK_SWAP"&M11,H11,I11,J11,B11,D11,K11,L11) -> CZK_SWAP6:10 | O11: CZKYC | P11: =_xll.meLWOSwapParRate(N11,O11) -> 0.0013 | R11: =CZK_CURVES!G9 -> 3M | S11: =CZK_CURVES!H9 -> 0.0013 | T11: =(P11-S11)*10000 -> -4.2192812e-11
B12: =_xll.meDateFromTenor(COB,F12,"MOD_FOLLOWING",$C12,"") -> 44077 | C12: PRB | D12: =_xll.meDateFromTenor(B12,G12,) -> 44258 | F12: 2D | G12: =CZK_CURVES!G10 -> 6M | H12: =TEMPLATES!$C$3 -> EM_CZK_OIS_UNDER_1Y:1 | I12: PAY | J12: 1000000 | K12: 0.01 | L12: 0 | M12: =M11+1 -> 7 | N12: =_xll.meLWOSwapCreateFromGenerator("CZK_SWAP"&M12,H12,I12,J12,B12,D12,K12,L12) -> CZK_SWAP7:10 | O12: CZKYC | P12: =_xll.meLWOSwapParRate(N12,O12) -> 0.0013 | R12: =CZK_CURVES!G10 -> 6M | S12: =CZK_CURVES!H10 -> 0.0013 | T12: =(P12-S12)*10000 -> -3.6273068e-11
B13: =_xll.meDateFromTenor(COB,F13,"MOD_FOLLOWING",$C13,"") -> 44077 | C13: PRB | D13: =_xll.meDateFromTenor(B13,G13,) -> 44350 | F13: 2D | G13: =CZK_CURVES!G11 -> 9M | H13: =TEMPLATES!$C$3 -> EM_CZK_OIS_UNDER_1Y:1 | I13: PAY | J13: 1000000 | K13: 0.01 | L13: 0 | M13: =M12+1 -> 8 | N13: =_xll.meLWOSwapCreateFromGenerator("CZK_SWAP"&M13,H13,I13,J13,B13,D13,K13,L13) -> CZK_SWAP8:10 | O13: CZKYC | P13: =_xll.meLWOSwapParRate(N13,O13) -> 0.0014 | R13: =CZK_CURVES!G11 -> 9M | S13: =CZK_CURVES!H11 -> 0.0014 | T13: =(P13-S13)*10000 -> -3.4169716e-11
B14: =_xll.meDateFromTenor(COB,F14,"MOD_FOLLOWING",$C14,"") -> 44077 | C14: PRB | D14: =_xll.meDateFromTenor(B14,G14,) -> 44442 | F14: 2D | G14: =CZK_CURVES!G12 -> 1Y | H14: =TEMPLATES!$G$3 -> EM_CZK_OIS:1 | I14: PAY | J14: 1000000 | K14: 0.01 | L14: 0 | M14: =M13+1 -> 9 | N14: =_xll.meLWOSwapCreateFromGenerator("CZK_SWAP"&M14,H14,I14,J14,B14,D14,K14,L14) -> CZK_SWAP9:10 | O14: CZKYC | P14: =_xll.meLWOSwapParRate(N14,O14) -> 0.0016 | R14: =CZK_CURVES!G12 -> 1Y | S14: =CZK_CURVES!H12 -> 0.0016 | T14: =(P14-S14)*10000 -> -3.9996968e-07
B15: =_xll.meDateFromTenor(COB,F15,"MOD_FOLLOWING",$C15,"") -> 44077 | C15: PRB | D15: =_xll.meDateFromTenor(B15,G15,) -> 44807 | F15: 2D | G15: =CZK_CURVES!G13 -> 2Y | H15: =TEMPLATES!$G$3 -> EM_CZK_OIS:1 | I15: PAY | J15: 1000000 | K15: 0.01 | L15: 0 | M15: =M14+1 -> 10 | N15: =_xll.meLWOSwapCreateFromGenerator("CZK_SWAP"&M15,H15,I15,J15,B15,D15,K15,L15) -> CZK_SWAP10:10 | O15: CZKYC | P15: =_xll.meLWOSwapParRate(N15,O15) -> 0.0014099998 | R15: =CZK_CURVES!G13 -> 2Y | S15: =CZK_CURVES!H13 -> 0.00141 | T15: =(P15-S15)*10000 -> -2.4246579e-06
B16: =_xll.meDateFromTenor(COB,F16,"MOD_FOLLOWING",$C16,"") -> 44077 | C16: PRB | D16: =_xll.meDateFromTenor(B16,G16,) -> 45172 | F16: 2D | G16: =CZK_CURVES!G14 -> 3Y | H16: =TEMPLATES!$G$3 -> EM_CZK_OIS:1 | I16: PAY | J16: 1000000 | K16: 0.01 | L16: 0 | M16: =M15+1 -> 11 | N16: =_xll.meLWOSwapCreateFromGenerator("CZK_SWAP"&M16,H16,I16,J16,B16,D16,K16,L16) -> CZK_SWAP11:9 | O16: CZKYC | P16: =_xll.meLWOSwapParRate(N16,O16) -> 0.0013799998 | R16: =CZK_CURVES!G14 -> 3Y | S16: =CZK_CURVES!H14 -> 0.00138 | T16: =(P16-S16)*10000 -> -2.3386817e-06
B17: =_xll.meDateFromTenor(COB,F17,"MOD_FOLLOWING",$C17,"") -> 44077 | C17: PRB | D17: =_xll.meDateFromTenor(B17,G17,) -> 45538 | F17: 2D | G17: =CZK_CURVES!G15 -> 4Y | H17: =TEMPLATES!$G$3 -> EM_CZK_OIS:1 | I17: PAY | J17: 1000000 | K17: 0.01 | L17: 0 | M17: =M16+1 -> 12 | N17: =_xll.meLWOSwapCreateFromGenerator("CZK_SWAP"&M17,H17,I17,J17,B17,D17,K17,L17) -> CZK_SWAP12:9 | O17: CZKYC | P17: =_xll.meLWOSwapParRate(N17,O17) -> 0.0015199998 | R17: =CZK_CURVES!G15 -> 4Y | S17: =CZK_CURVES!H15 -> 0.00152 | T17: =(P17-S17)*10000 -> -1.6216796e-06
B18: =_xll.meDateFromTenor(COB,F18,"MOD_FOLLOWING",$C18,"") -> 44077 | C18: PRB | D18: =_xll.meDateFromTenor(B18,G18,) -> 45903 | F18: 2D | G18: =CZK_CURVES!G16 -> 5Y | H18: =TEMPLATES!$G$3 -> EM_CZK_OIS:1 | I18: PAY | J18: 1000000 | K18: 0.01 | L18: 0 | M18: =M17+1 -> 13 | N18: =_xll.meLWOSwapCreateFromGenerator("CZK_SWAP"&M18,H18,I18,J18,B18,D18,K18,L18) -> CZK_SWAP13:9 | O18: CZKYC | P18: =_xll.meLWOSwapParRate(N18,O18) -> 0.0017799999 | R18: =CZK_CURVES!G16 -> 5Y | S18: =CZK_CURVES!H16 -> 0.00178 | T18: =(P18-S18)*10000 -> -1.3655726e-06
B19: =_xll.meDateFromTenor(COB,F19,"MOD_FOLLOWING",$C19,"") -> 44077 | C19: PRB | D19: =_xll.meDateFromTenor(B19,G19,) -> 46268 | F19: 2D | G19: =CZK_CURVES!G17 -> 6Y | H19: =TEMPLATES!$G$3 -> EM_CZK_OIS:1 | I19: PAY | J19: 1000000 | K19: 0.01 | L19: 0 | M19: =M18+1 -> 14 | N19: =_xll.meLWOSwapCreateFromGenerator("CZK_SWAP"&M19,H19,I19,J19,B19,D19,K19,L19) -> CZK_SWAP14:9 | O19: CZKYC | P19: =_xll.meLWOSwapParRate(N19,O19) -> 0.0021399999 | R19: =CZK_CURVES!G17 -> 6Y | S19: =CZK_CURVES!H17 -> 0.00214 | T19: =(P19-S19)*10000 -> -1.121147e-06
B20: =_xll.meDateFromTenor(COB,F20,"MOD_FOLLOWING",$C20,"") -> 44077 | C20: PRB | D20: =_xll.meDateFromTenor(B20,G20,) -> 46633 | F20: 2D | G20: =CZK_CURVES!G18 -> 7Y | H20: =TEMPLATES!$G$3 -> EM_CZK_OIS:1 | I20: PAY | J20: 1000000 | K20: 0.01 | L20: 0 | M20: =M19+1 -> 15 | N20: =_xll.meLWOSwapCreateFromGenerator("CZK_SWAP"&M20,H20,I20,J20,B20,D20,K20,L20) -> CZK_SWAP15:9 | O20: CZKYC | P20: =_xll.meLWOSwapParRate(N20,O20) -> 0.0025699999 | R20: =CZK_CURVES!G18 -> 7Y | S20: =CZK_CURVES!H18 -> 0.00257 | T20: =(P20-S20)*10000 -> -9.6584634e-07
B21: =_xll.meDateFromTenor(COB,F21,"MOD_FOLLOWING",$C21,"") -> 44077 | C21: PRB | D21: =_xll.meDateFromTenor(B21,G21,) -> 46999 | F21: 2D | G21: =CZK_CURVES!G19 -> 8Y | H21: =TEMPLATES!$G$3 -> EM_CZK_OIS:1 | I21: PAY | J21: 1000000 | K21: 0.01 | L21: 0 | M21: =M20+1 -> 16 | N21: =_xll.meLWOSwapCreateFromGenerator("CZK_SWAP"&M21,H21,I21,J21,B21,D21,K21,L21) -> CZK_SWAP16:9 | O21: CZKYC | P21: =_xll.meLWOSwapParRate(N21,O21) -> 0.0030399999 | R21: =CZK_CURVES!G19 -> 8Y | S21: =CZK_CURVES!H19 -> 0.00304 | T21: =(P21-S21)*10000 -> -8.5751925e-07
B22: =_xll.meDateFromTenor(COB,F22,"MOD_FOLLOWING",$C22,"") -> 44077 | C22: PRB | D22: =_xll.meDateFromTenor(B22,G22,) -> 47364 | F22: 2D | G22: =CZK_CURVES!G20 -> 9Y | H22: =TEMPLATES!$G$3 -> EM_CZK_OIS:1 | I22: PAY | J22: 1000000 | K22: 0.01 | L22: 0 | M22: =M21+1 -> 17 | N22: =_xll.meLWOSwapCreateFromGenerator("CZK_SWAP"&M22,H22,I22,J22,B22,D22,K22,L22) -> CZK_SWAP17:9 | O22: CZKYC | P22: =_xll.meLWOSwapParRate(N22,O22) -> 0.0035099999 | R22: =CZK_CURVES!G20 -> 9Y | S22: =CZK_CURVES!H20 -> 0.00351 | T22: =(P22-S22)*10000 -> -7.488435e-07
B23: =_xll.meDateFromTenor(COB,F23,"MOD_FOLLOWING",$C23,"") -> 44077 | C23: PRB | D23: =_xll.meDateFromTenor(B23,G23,) -> 47729 | F23: 2D | G23: =CZK_CURVES!G21 -> 10Y | H23: =TEMPLATES!$G$3 -> EM_CZK_OIS:1 | I23: PAY | J23: 1000000 | K23: 0.01 | L23: 0 | M23: =M22+1 -> 18 | N23: =_xll.meLWOSwapCreateFromGenerator("CZK_SWAP"&M23,H23,I23,J23,B23,D23,K23,L23) -> CZK_SWAP18:9 | O23: CZKYC | P23: =_xll.meLWOSwapParRate(N23,O23) -> 0.0040099999 | R23: =CZK_CURVES!G21 -> 10Y | S23: =CZK_CURVES!H21 -> 0.00401 | T23: =(P23-S23)*10000 -> -6.8581637e-07
B24: =_xll.meDateFromTenor(COB,F24,"MOD_FOLLOWING",$C24,"") -> 44077 | C24: PRB | D24: =_xll.meDateFromTenor(B24,G24,) -> 48460 | F24: 2D | G24: =CZK_CURVES!G22 -> 12Y | H24: =TEMPLATES!$G$3 -> EM_CZK_OIS:1 | I24: PAY | J24: 1000000 | K24: 0.01 | L24: 0 | M24: =M23+1 -> 19 | N24: =_xll.meLWOSwapCreateFromGenerator("CZK_SWAP"&M24,H24,I24,J24,B24,D24,K24,L24) -> CZK_SWAP19:9 | O24: CZKYC | P24: =_xll.meLWOSwapParRate(N24,O24) -> 0.0049399999 | R24: =CZK_CURVES!G22 -> 12Y | S24: =CZK_CURVES!H22 -> 0.00494 | T24: =(P24-S24)*10000 -> -5.7349626e-07
B25: =_xll.meDateFromTenor(COB,F25,"MOD_FOLLOWING",$C25,"") -> 44077 | C25: PRB | D25: =_xll.meDateFromTenor(B25,G25,) -> 49555 | F25: 2D | G25: =CZK_CURVES!G23 -> 15Y | H25: =TEMPLATES!$G$3 -> EM_CZK_OIS:1 | I25: PAY | J25: 1000000 | K25: 0.01 | L25: 0 | M25: =M24+1 -> 20 | N25: =_xll.meLWOSwapCreateFromGenerator("CZK_SWAP"&M25,H25,I25,J25,B25,D25,K25,L25) -> CZK_SWAP20:9 | O25: CZKYC | P25: =_xll.meLWOSwapParRate(N25,O25) -> 0.0061 | R25: =CZK_CURVES!G23 -> 15Y | S25: =CZK_CURVES!H23 -> 0.0061 | T25: =(P25-S25)*10000 -> -4.6463109e-07
... B30: =_xll.meDateFromTenor(COB,F30,"MOD_FOLLOWING",$C30,"") -> 44077 | C30: PRB | D30: =_xll.meDateFromTenor(B30,G30,) -> 62339 | F30: 2D | G30: =CZK_CURVES!G28 -> 50Y | H30: =TEMPLATES!$G$3 -> EM_CZK_OIS:1 | I30: PAY | J30: 1000000 | K30: 0.01 | L30: 0 | M30: =M29+1 -> 25 | N30: =_xll.meLWOSwapCreateFromGenerator("CZK_SWAP"&M30,H30,I30,J30,B30,D30,K30,L30) -> CZK_SWAP25:9 | O30: CZKYC | P30: =_xll.meLWOSwapParRate(N30,O30) -> 0.00628 | R30: =CZK_CURVES!G28 -> 50Y | S30: =CZK_CURVES!H28 -> 0.00628 | T30: =(P30-S30)*10000 -> -1.5862353e-07
B33: Trade Dates | F33: SWAPS: CZK_SWAP_6M | N33: Trade Booking & Pricing | R33: Curve Calibration Check
D34: Unadjusted Date ! | H34: Swap Template
B35: EffectiveDate | C35: Calendar | D35: MaturityDate | F35: EffectiveDate | G35: Maturity | H35: Generator | I35: PayRec | J35: Notional | K35: FixedRate | L35: Spread | N35: CreateSwap | O35: CurveCollection | P35: ParRate | R35: Term | S35: Rate | T35: +/- Bps
B36: =_xll.meDateFromTenor(COB,F36,"MOD_FOLLOWING",$C36,"") -> 44077 | C36: PRB | D36: =_xll.meDateFromTenor(B36,G36,) -> 44807 | F36: 2D | G36: =CZK_CURVES!P27 -> 2Y | H36: =TEMPLATES!$K$3 -> EM_CZK_6M:1 | I36: PAY | J36: 1000000 | K36: 0.01 | L36: 0 | M36: =M30+1 -> 26 | N36: =_xll.meLWOSwapCreateFromGenerator("CZK_SWAP"&M36,H36,I36,J36,B36,D36,K36,L36) -> CZK_SWAP26:9 | O36: CZKYC | P36: =_xll.meLWOSwapParRate(N36,O36) -> 0.0055 | R36: =CZK_CURVES!P27 -> 2Y | S36: =CZK_CURVES!Q27 -> 0.0055 | T36: =(P36-S36)*10000 -> -2.1163011e-08
B37: =_xll.meDateFromTenor(COB,F37,"MOD_FOLLOWING",$C37,"") -> 44077 | C37: PRB | D37: =_xll.meDateFromTenor(B37,G37,) -> 45172 | F37: 2D | G37: =CZK_CURVES!P28 -> 3Y | H37: =TEMPLATES!$K$3 -> EM_CZK_6M:1 | I37: PAY | J37: 1000000 | K37: 0.01 | L37: 0 | M37: =M36+1 -> 27 | N37: =_xll.meLWOSwapCreateFromGenerator("CZK_SWAP"&M37,H37,I37,J37,B37,D37,K37,L37) -> CZK_SWAP27:9 | O37: CZKYC | P37: =_xll.meLWOSwapParRate(N37,O37) -> 0.0068750001 | R37: =CZK_CURVES!P28 -> 3Y | S37: =CZK_CURVES!Q28 -> 0.006875 | T37: =(P37-S37)*10000 -> 6.8427325e-07
B38: =_xll.meDateFromTenor(COB,F38,"MOD_FOLLOWING",$C38,"") -> 44077 | C38: PRB | D38: =_xll.meDateFromTenor(B38,G38,) -> 45538 | F38: 2D | G38: =CZK_CURVES!P29 -> 4Y | H38: =TEMPLATES!$K$3 -> EM_CZK_6M:1 | I38: PAY | J38: 1000000 | K38: 0.01 | L38: 0 | M38: =M37+1 -> 28 | N38: =_xll.meLWOSwapCreateFromGenerator("CZK_SWAP"&M38,H38,I38,J38,B38,D38,K38,L38) -> CZK_SWAP28:9 | O38: CZKYC | P38: =_xll.meLWOSwapParRate(N38,O38) -> 0.0079750001 | R38: =CZK_CURVES!P29 -> 4Y | S38: =CZK_CURVES!Q29 -> 0.007975 | T38: =(P38-S38)*10000 -> 5.2019236e-07
B39: =_xll.meDateFromTenor(COB,F39,"MOD_FOLLOWING",$C39,"") -> 44077 | C39: PRB | D39: =_xll.meDateFromTenor(B39,G39,) -> 45903 | F39: 2D | G39: =CZK_CURVES!P30 -> 5Y | H39: =TEMPLATES!$K$3 -> EM_CZK_6M:1 | I39: PAY | J39: 1000000 | K39: 0.01 | L39: 0 | M39: =M38+1 -> 29 | N39: =_xll.meLWOSwapCreateFromGenerator("CZK_SWAP"&M39,H39,I39,J39,B39,D39,K39,L39) -> CZK_SWAP29:9 | O39: CZKYC | P39: =_xll.meLWOSwapParRate(N39,O39) -> 0.00895 | R39: =CZK_CURVES!P30 -> 5Y | S39: =CZK_CURVES!Q30 -> 0.00895 | T39: =(P39-S39)*10000 -> 4.1620152e-07
B40: =_xll.meDateFromTenor(COB,F40,"MOD_FOLLOWING",$C40,"") -> 44077 | C40: PRB | D40: =_xll.meDateFromTenor(B40,G40,) -> 46268 | F40: 2D | G40: =CZK_CURVES!P31 -> 6Y | H40: =TEMPLATES!$K$3 -> EM_CZK_6M:1 | I40: PAY | J40: 1000000 | K40: 0.01 | L40: 0 | M40: =M39+1 -> 30 | N40: =_xll.meLWOSwapCreateFromGenerator("CZK_SWAP"&M40,H40,I40,J40,B40,D40,K40,L40) -> CZK_SWAP30:9 | O40: CZKYC | P40: =_xll.meLWOSwapParRate(N40,O40) -> 0.009675 | R40: =CZK_CURVES!P31 -> 6Y | S40: =CZK_CURVES!Q31 -> 0.009675 | T40: =(P40-S40)*10000 -> 3.4749393e-07
B41: =_xll.meDateFromTenor(COB,F41,"MOD_FOLLOWING",$C41,"") -> 44077 | C41: PRB | D41: =_xll.meDateFromTenor(B41,G41,) -> 46633 | F41: 2D | G41: =CZK_CURVES!P32 -> 7Y | H41: =TEMPLATES!$K$3 -> EM_CZK_6M:1 | I41: PAY | J41: 1000000 | K41: 0.01 | L41: 0 | M41: =M40+1 -> 31 | N41: =_xll.meLWOSwapCreateFromGenerator("CZK_SWAP"&M41,H41,I41,J41,B41,D41,K41,L41) -> CZK_SWAP31:9 | O41: CZKYC | P41: =_xll.meLWOSwapParRate(N41,O41) -> 0.010125 | R41: =CZK_CURVES!P32 -> 7Y | S41: =CZK_CURVES!Q32 -> 0.010125 | T41: =(P41-S41)*10000 -> 2.944984e-07
B42: =_xll.meDateFromTenor(COB,F42,"MOD_FOLLOWING",$C42,"") -> 44077 | C42: PRB | D42: =_xll.meDateFromTenor(B42,G42,) -> 46999 | F42: 2D | G42: =CZK_CURVES!P33 -> 8Y | H42: =TEMPLATES!$K$3 -> EM_CZK_6M:1 | I42: PAY | J42: 1000000 | K42: 0.01 | L42: 0 | M42: =M41+1 -> 32 | N42: =_xll.meLWOSwapCreateFromGenerator("CZK_SWAP"&M42,H42,I42,J42,B42,D42,K42,L42) -> CZK_SWAP32:9 | O42: CZKYC | P42: =_xll.meLWOSwapParRate(N42,O42) -> 0.010475 | R42: =CZK_CURVES!P33 -> 8Y | S42: =CZK_CURVES!Q33 -> 0.010475 | T42: =(P42-S42)*10000 -> 2.5811169e-07
B43: =_xll.meDateFromTenor(COB,F43,"MOD_FOLLOWING",$C43,"") -> 44077 | C43: PRB | D43: =_xll.meDateFromTenor(B43,G43,) -> 47364 | F43: 2D | G43: =CZK_CURVES!P34 -> 9Y | H43: =TEMPLATES!$K$3 -> EM_CZK_6M:1 | I43: PAY | J43: 1000000 | K43: 0.01 | L43: 0 | M43: =M42+1 -> 33 | N43: =_xll.meLWOSwapCreateFromGenerator("CZK_SWAP"&M43,H43,I43,J43,B43,D43,K43,L43) -> CZK_SWAP33:9 | O43: CZKYC | P43: =_xll.meLWOSwapParRate(N43,O43) -> 0.01085 | R43: =CZK_CURVES!P34 -> 9Y | S43: =CZK_CURVES!Q34 -> 0.01085 | T43: =(P43-S43)*10000 -> 2.2899471e-07
B44: =_xll.meDateFromTenor(COB,F44,"MOD_FOLLOWING",$C44,"") -> 44077 | C44: PRB | D44: =_xll.meDateFromTenor(B44,G44,) -> 47729 | F44: 2D | G44: =CZK_CURVES!P35 -> 10Y | H44: =TEMPLATES!$K$3 -> EM_CZK_6M:1 | I44: PAY | J44: 1000000 | K44: 0.01 | L44: 0 | M44: =M43+1 -> 34 | N44: =_xll.meLWOSwapCreateFromGenerator("CZK_SWAP"&M44,H44,I44,J44,B44,D44,K44,L44) -> CZK_SWAP34:9 | O44: CZKYC | P44: =_xll.meLWOSwapParRate(N44,O44) -> 0.0111 | R44: =CZK_CURVES!P35 -> 10Y | S44: =CZK_CURVES!Q35 -> 0.0111 | T44: =(P44-S44)*10000 -> 2.0476369e-07
B45: =_xll.meDateFromTenor(COB,F45,"MOD_FOLLOWING",$C45,"") -> 44077 | C45: PRB | D45: =_xll.meDateFromTenor(B45,G45,) -> 48460 | F45: 2D | G45: =CZK_CURVES!P36 -> 12Y | H45: =TEMPLATES!$K$3 -> EM_CZK_6M:1 | I45: PAY | J45: 1000000 | K45: 0.01 | L45: 0 | M45: =M44+1 -> 35 | N45: =_xll.meLWOSwapCreateFromGenerator("CZK_SWAP"&M45,H45,I45,J45,B45,D45,K45,L45) -> CZK_SWAP35:9 | O45: CZKYC | P45: =_xll.meLWOSwapParRate(N45,O45) -> 0.01135 | R45: =CZK_CURVES!P36 -> 12Y | S45: =CZK_CURVES!Q36 -> 0.01135 | T45: =(P45-S45)*10000 -> 1.7057352e-07
B46: =_xll.meDateFromTenor(COB,F46,"MOD_FOLLOWING",$C46,"") -> 44077 | C46: PRB | D46: =_xll.meDateFromTenor(B46,G46,) -> 49555 | F46: 2D | G46: =CZK_CURVES!P37 -> 15Y | H46: =TEMPLATES!$K$3 -> EM_CZK_6M:1 | I46: PAY | J46: 1000000 | K46: 0.01 | L46: 0 | M46: =M45+1 -> 36 | N46: =_xll.meLWOSwapCreateFromGenerator("CZK_SWAP"&M46,H46,I46,J46,B46,D46,K46,L46) -> CZK_SWAP36:9 | O46: CZKYC | P46: =_xll.meLWOSwapParRate(N46,O46) -> 0.0126 | R46: =CZK_CURVES!P37 -> 15Y | S46: =CZK_CURVES!Q37 -> 0.0126 | T46: =(P46-S46)*10000 -> 1.3747187e-07
B47: =_xll.meDateFromTenor(COB,F47,"MOD_FOLLOWING",$C47,"") -> 44077 | C47: PRB | D47: =_xll.meDateFromTenor(B47,G47,) -> 51382 | F47: 2D | G47: =CZK_CURVES!P38 -> 20Y | H47: =TEMPLATES!$K$3 -> EM_CZK_6M:1 | I47: PAY | J47: 1000000 | K47: 0.01 | L47: 0 | M47: =M46+1 -> 37 | N47: =_xll.meLWOSwapCreateFromGenerator("CZK_SWAP"&M47,H47,I47,J47,B47,D47,K47,L47) -> CZK_SWAP37:9 | O47: CZKYC | P47: =_xll.meLWOSwapParRate(N47,O47) -> 0.012546776 | R47: =CZK_CURVES!P38 -> 20Y | S47: =CZK_CURVES!Q38 -> 0.01255 | T47: =(P47-S47)*10000 -> -0.032236452 | U47: <--- Fix
B50: Trade Dates | F50: SWAPS: CZK_BASIS_3M | N50: Trade Booking & Pricing | R50: Curve Calibration Check
...
